File: exposed_flourocarbon_10cm_10mmpm_12nm_250esh_6.csv
"Test Name","Test Mode","Test Type","Control","Test Speed 1","Test Speed 2","Test Speed 3","Change Point 1","Change Point 2","Disp. Origin","Break and Limit Action","Sensitivity:","Level:"
"","Single","Tensile","Stroke",10,1,1,"Off","Off","Start","Stop",0,1

"Title","Sub title","Comment"
"","",""

"Shape:","Batch Size:","SubBatch Size:"
"Plate",1,1
"Name:","Thickness","Width","Gauge Length",
"Size Unit:","mm","mm","mm",
" 1 - 1","1.0000","1.0000","100.0000",

"Name",
"Parameter",
"Units",
" 1 - 1",

" 1- 1"
"Time","Force","Stroke",
"sec","N","mm",
"0.00",-.003,0,
"0.15",-.001,2.733333E-02,
"0.30",.011,.055,
"0.45",.036,8.266667E-02,
"0.60",.061,.1106667,
"0.75",.088,.1383333,
"0.90",.113,.166,
"1.05",.14,.194,
"1.20",.161,.2216667,
"1.35",.187,.2496667,
"1.50",.211,.2773333,
"1.65",.235,.305,
"1.80",.258,.333,
"1.95",.284,.3606667,
"2.10",.31,.3876667,
"2.25",.333,.4143333,
"2.40",.358,.441,
"2.55",.378,.4673333,
"2.70",.4,.4933333,
"2.85",.422,.5193334,
"3.00",.443,.5453333,
"3.15",.464,.571,
"3.30",.486,.5966667,
"3.45",.511,.622,
"3.60",.529,.6476667,
"3.75",.55,.673,
"3.90",.572,.6983333,
"4.05",.593,.7236667,
"4.20",.614,.7486666,
"4.35",.634,.774,
"4.50",.655,.799,
"4.65",.676,.824,
"4.80",.692,.8493333,
"4.95",.713,.8743333,
"5.10",.732,.8996667,
"5.25",.752,.9243333,
"5.40",.771,.9496667,
"5.55",.791,.9746667,
"5.70",.81,.9996667,
"5.85",.827,1.024667,
"6.00",.844,1.05,
"6.15",.863,1.075,
"6.30",.882,1.1,
"6.45",.901,1.125,
"6.60",.921,1.149667,
"6.75",.935,1.175,
"6.90",.953,1.2,
"7.05",.97,1.225,
"7.20",.987,1.25,
"7.35",1.007,1.275,
"7.50",1.023,1.3,
"7.65",1.038,1.325,
"7.80",1.054,1.35,
"7.95",1.072,1.375,
"8.10",1.088,1.4,
"8.25",1.108,1.425,
"8.40",1.122,1.45,
"8.55",1.136,1.475,
"8.70",1.155,1.5,
"8.85",1.171,1.525,
"9.00",1.188,1.55,
"9.15",1.2,1.575,
"9.30",1.213,1.6,
"9.45",1.23,1.625,
"9.60",1.247,1.65,
"9.75",1.262,1.675,
"9.90",1.276,1.7,
"10.05",1.289,1.725333,
"10.20",1.305,1.750333,
"10.35",1.319,1.775333,
"10.50",1.336,1.8,
"10.65",1.35,1.825,
"10.80",1.365,1.85,
"10.95",1.38,1.875,
"11.10",1.391,1.9,
"11.25",1.406,1.925333,
"11.40",1.421,1.95,
"11.55",1.435,1.975333,
"11.70",1.451,2,
"11.85",1.463,2.025,
"12.00",1.477,2.05,
"12.15",1.489,2.075,
"12.30",1.503,2.1,
"12.45",1.518,2.125,
"12.60",1.532,2.15,
"12.75",1.542,2.175,
"12.90",1.554,2.2,
"13.05",1.57,2.225,
"13.20",1.588,2.25,
"13.35",1.599,2.275,
"13.50",1.612,2.3,
"13.65",1.626,2.325,
"13.80",1.639,2.35,
"13.95",1.653,2.375,
"14.10",1.666,2.4,
"14.25",1.679,2.424667,
"14.40",1.694,2.449667,
"14.55",1.707,2.475,
"14.70",1.722,2.5,
"14.85",1.733,2.524667,
"15.00",1.745,2.55,
"15.15",1.757,2.575,
"15.30",1.772,2.6,
"15.45",1.786,2.625,
"15.60",1.799,2.649667,
"15.75",1.813,2.675,
"15.90",1.823,2.699667,
"16.05",1.836,2.725,
"16.20",1.85,2.75,
"16.35",1.865,2.774667,
"16.50",1.88,2.8,
"16.65",1.891,2.825,
"16.80",1.904,2.85,
"16.95",1.916,2.875,
"17.10",1.928,2.9,
"17.25",1.943,2.925,
"17.40",1.956,2.95,
"17.55",1.969,2.975,
"17.70",1.979,3,
"17.85",1.993,3.025,
"18.00",2.006,3.05,
"18.15",2.02,3.075,
"18.30",2.033,3.1,
"18.45",2.047,3.124667,
"18.60",2.061,3.149667,
"18.75",2.075,3.175,
"18.90",2.087,3.2,
"19.05",2.099,3.225,
"19.20",2.112,3.25,
"19.35",2.127,3.275,
"19.50",2.139,3.3,
"19.65",2.152,3.325,
"19.80",2.166,3.35,
"19.95",2.176,3.375,
"20.10",2.191,3.4,
"20.25",2.201,3.425,
"20.40",2.218,3.45,
"20.55",2.233,3.475,
"20.70",2.242,3.5,
"20.85",2.252,3.525,
"21.00",2.266,3.55,
"21.15",2.277,3.575,
"21.30",2.293,3.6,
"21.45",2.304,3.625,
"21.60",2.318,3.65,
"21.75",2.331,3.675,
"21.90",2.346,3.7,
"22.05",2.357,3.725,
"22.20",2.37,3.75,
"22.35",2.384,3.775,
"22.50",2.398,3.8,
"22.65",2.41,3.825,
"22.80",2.425,3.85,
"22.95",2.439,3.875,
"23.10",2.452,3.9,
"23.25",2.465,3.925,
"23.40",2.477,3.95,
"23.55",2.491,3.975,
"23.70",2.505,4,
"23.85",2.514,4.025,
"24.00",2.527,4.05,
"24.15",2.538,4.075,
"24.30",2.553,4.1,
"24.45",2.568,4.125,
"24.60",2.58,4.15,
"24.75",2.593,4.175,
"24.90",2.608,4.2,
"25.05",2.618,4.225,
"25.20",2.633,4.25,
"25.35",2.645,4.275,
"25.50",2.661,4.3,
"25.65",2.672,4.325,
"25.80",2.687,4.35,
"25.95",2.701,4.375333,
"26.10",2.712,4.4,
"26.25",2.725,4.425,
"26.40",2.739,4.450333,
"26.55",2.752,4.475,
"26.70",2.765,4.5,
"26.85",2.779,4.525333,
"27.00",2.792,4.550333,
"27.15",2.803,4.575333,
"27.30",2.815,4.6,
"27.45",2.829,4.625,
"27.60",2.844,4.65,
"27.75",2.856,4.675,
"27.90",2.868,4.7,
"28.05",2.882,4.725333,
"28.20",2.898,4.750333,
"28.35",2.911,4.775333,
"28.50",2.927,4.800333,
"28.65",2.941,4.825333,
"28.80",2.953,4.850333,
"28.95",2.965,4.875333,
"29.10",2.979,4.9,
"29.25",2.992,4.925,
"29.40",3.006,4.95,
"29.55",3.02,4.975,
"29.70",3.036,5.000333,
"29.85",3.049,5.025333,
"30.00",3.062,5.050333,
"30.15",3.072,5.075333,
"30.30",3.089,5.100333,
"30.45",3.105,5.125333,
"30.60",3.121,5.15,
"30.75",3.133,5.175,
"30.90",3.147,5.2,
"31.05",3.161,5.225,
"31.20",3.173,5.25,
"31.35",3.185,5.275333,
"31.50",3.199,5.300333,
"31.65",3.213,5.325333,
"31.80",3.228,5.350333,
"31.95",3.241,5.375,
"32.10",3.254,5.4,
"32.25",3.27,5.425,
"32.40",3.285,5.45,
"32.55",3.296,5.475,
"32.70",3.31,5.500333,
"32.85",3.325,5.525,
"33.00",3.339,5.55,
"33.15",3.353,5.575,
"33.30",3.365,5.6,
"33.45",3.377,5.625,
"33.60",3.386,5.65,
"33.75",3.399,5.675,
"33.90",3.411,5.7,
"34.05",3.417,5.725,
"34.20",3.43,5.75,
"34.35",3.444,5.775,
"34.50",3.46,5.8,
"34.65",3.473,5.825,
"34.80",3.488,5.85,
"34.95",3.497,5.875,
"35.10",3.478,5.9,
"35.25",3.471,5.925,
"35.40",3.491,5.95,
"35.55",3.503,5.975333,
"35.70",3.517,6.000333,
"35.85",3.532,6.025333,
"36.00",3.551,6.05,
"36.15",3.567,6.075,
"36.30",3.581,6.1,
"36.45",3.597,6.125,
"36.60",3.613,6.15,
"36.75",3.629,6.175,
"36.90",3.645,6.2,
"37.05",3.662,6.225333,
"37.20",3.677,6.250333,
"37.35",3.693,6.275333,
"37.50",3.709,6.300333,
"37.65",3.727,6.325333,
"37.80",3.742,6.350333,
"37.95",3.736,6.375333,
"38.10",3.713,6.4,
"38.25",3.724,6.425,
"38.40",3.74,6.45,
"38.55",3.756,6.475,
"38.70",3.774,6.5,
"38.85",3.791,6.525,
"39.00",3.806,6.55,
"39.15",3.822,6.575,
"39.30",3.841,6.6,
"39.45",3.859,6.625333,
"39.60",3.875,6.650333,
"39.75",3.89,6.675333,
"39.90",3.907,6.7,
"40.05",3.923,6.725333,
"40.20",3.939,6.750333,
"40.35",3.958,6.775,
"40.50",3.972,6.800333,
"40.65",3.988,6.825,
"40.80",4.006,6.85,
"40.95",4.02,6.875,
"41.10",4.033,6.9,
"41.25",4.052,6.925333,
"41.40",4.069,6.950333,
"41.55",4.085,6.975333,
"41.70",4.098,7.000333,
"41.85",4.115,7.025,
"42.00",4.132,7.050333,
"42.15",4.148,7.075,
"42.30",4.164,7.1,
"42.45",4.179,7.125,
"42.60",4.193,7.15,
"42.75",4.211,7.175,
"42.90",4.227,7.2,
"43.05",4.244,7.225,
"43.20",4.261,7.25,
"43.35",4.28,7.275,
"43.50",4.297,7.3,
"43.65",4.311,7.325,
"43.80",4.326,7.35,
"43.95",4.341,7.375333,
"44.10",4.357,7.4,
"44.25",4.376,7.425,
"44.40",4.394,7.45,
"44.55",4.411,7.475,
"44.70",4.427,7.5,
"44.85",4.441,7.525,
"45.00",4.455,7.55,
"45.15",4.38,7.575,
"45.30",4.302,7.6,
"45.45",4.322,7.625,
"45.60",4.343,7.65,
"45.75",4.364,7.675333,
"45.90",4.385,7.7,
"46.05",4.405,7.725,
"46.20",4.426,7.750333,
"46.35",4.447,7.775333,
"46.50",4.467,7.800333,
"46.65",4.487,7.825,
"46.80",4.505,7.85,
"46.95",4.525,7.875333,
"47.10",4.546,7.900333,
"47.25",4.565,7.925333,
"47.40",4.585,7.950333,
"47.55",4.601,7.975,
"47.70",4.623,8,
"47.85",4.641,8.025,
"48.00",4.659,8.05,
"48.15",4.679,8.075334,
"48.30",4.698,8.1,
"48.45",4.716,8.125,
"48.60",4.732,8.15,
"48.75",4.753,8.175,
"48.90",4.77,8.2,
"49.05",4.787,8.225,
"49.20",4.805,8.25,
"49.35",4.824,8.275,
"49.50",4.841,8.3,
"49.65",4.862,8.325,
"49.80",4.879,8.35,
"49.95",4.894,8.375,
"50.10",4.913,8.4,
"50.25",4.931,8.425,
"50.40",4.949,8.45,
"50.55",4.968,8.475,
"50.70",4.99,8.5,
"50.85",5.005,8.525,
"51.00",5.022,8.55,
"51.15",5.04,8.575,
"51.30",5.057,8.6,
"51.45",5.076,8.625,
"51.60",5.096,8.65,
"51.75",5.111,8.675,
"51.90",5.128,8.7,
"52.05",5.149,8.725333,
"52.20",5.167,8.75,
"52.35",5.187,8.775,
"52.50",5.205,8.8,
"52.65",5.22,8.825,
"52.80",5.235,8.85,
"52.95",5.257,8.875,
"53.10",5.276,8.9,
"53.25",5.293,8.925,
"53.40",5.312,8.95,
"53.55",5.33,8.975,
"53.70",5.348,9,
"53.85",5.364,9.025,
"54.00",5.382,9.05,
"54.15",5.401,9.075334,
"54.30",5.423,9.100333,
"54.45",5.44,9.125334,
"54.60",5.459,9.15,
"54.75",5.476,9.175,
"54.90",5.494,9.2,
"55.05",5.511,9.225,
"55.20",5.53,9.250334,
"55.35",5.551,9.275,
"55.50",5.568,9.300333,
"55.65",5.585,9.325334,
"55.80",5.603,9.350333,
"55.95",5.62,9.375334,
"56.10",5.64,9.400333,
"56.25",5.658,9.425,
"56.40",5.678,9.45,
"56.55",5.694,9.475,
"56.70",5.715,9.5,
"56.85",5.732,9.525,
"57.00",5.751,9.55,
"57.15",5.769,9.575,
"57.30",5.789,9.6,
"57.45",5.809,9.625,
"57.60",5.827,9.65,
"57.75",5.845,9.675,
"57.90",5.864,9.7,
"58.05",5.883,9.725,
"58.20",5.902,9.75,
"58.35",5.923,9.775,
"58.50",5.942,9.8,
"58.65",5.962,9.825,
"58.80",5.98,9.85,
"58.95",5.999,9.875,
"59.10",6.016,9.9,
"59.25",6.033,9.925,
"59.40",6.052,9.95,
"59.55",6.07,9.975,
"59.70",6.088,10,
"59.85",6.108,10.025,
"60.00",6.128,10.05033,
"60.15",6.147,10.07533,
"60.30",6.166,10.1,
"60.45",6.184,10.125,
"60.60",6.201,10.15,
"60.75",6.217,10.175,
"60.90",6.236,10.2,
"61.05",6.254,10.225,
"61.20",6.272,10.25,
"61.35",6.29,10.275,
"61.50",6.308,10.3,
"61.65",6.325,10.325,
"61.80",6.341,10.35,
"61.95",6.357,10.37533,
"62.10",6.377,10.4,
"62.25",6.395,10.425,
"62.40",6.41,10.45,
"62.55",6.358,10.475,
"62.70",6.299,10.5,
"62.85",6.314,10.525,
"63.00",6.334,10.55,
"63.15",6.357,10.575,
"63.30",6.383,10.6,
"63.45",6.407,10.625,
"63.60",6.428,10.65,
"63.75",6.451,10.675,
"63.90",6.473,10.70033,
"64.05",6.497,10.725,
"64.20",6.516,10.75,
"64.35",6.536,10.775,
"64.50",6.549,10.8,
"64.65",6.481,10.825,
"64.80",6.435,10.85,
"64.95",6.459,10.875,
"65.10",6.487,10.9,
"65.25",6.511,10.925,
"65.40",6.539,10.95,
"65.55",6.567,10.975,
"65.70",6.595,11,
"65.85",6.623,11.025,
"66.00",6.648,11.05033,
"66.15",6.673,11.07533,
"66.30",6.7,11.1,
"66.45",6.727,11.12533,
"66.60",6.751,11.15,
"66.75",6.773,11.17533,
"66.90",6.799,11.2,
"67.05",6.823,11.225,
"67.20",6.847,11.25,
"67.35",6.871,11.275,
"67.50",6.893,11.3,
"67.65",6.915,11.325,
"67.80",6.936,11.35,
"67.95",6.961,11.37533,
"68.10",6.984,11.4,
"68.25",7.006,11.425,
"68.40",7.029,11.45,
"68.55",7.049,11.475,
"68.70",7.072,11.5,
"68.85",7.093,11.525,
"69.00",7.113,11.55,
"69.15",7.136,11.575,
"69.30",7.16,11.6,
"69.45",7.183,11.625,
"69.60",7.204,11.65,
"69.75",7.226,11.675,
"69.90",7.245,11.7,
"70.05",7.267,11.725,
"70.20",7.289,11.75033,
"70.35",7.312,11.775,
"70.50",7.331,11.8,
"70.65",7.354,11.825,
"70.80",7.376,11.85,
"70.95",7.396,11.875,
"71.10",7.419,11.9,
"71.25",7.438,11.925,
"71.40",7.46,11.95,
"71.55",7.479,11.975,
"71.70",7.499,12,
"71.85",7.521,12.025,
"72.00",7.543,12.05,
"72.15",7.564,12.075,
"72.30",7.587,12.1,
"72.45",7.609,12.125,
"72.60",7.63,12.15,
"72.75",7.651,12.175,
"72.90",7.672,12.2,
"73.05",7.695,12.225,
"73.20",7.719,12.25,
"73.35",7.741,12.275,
"73.50",7.763,12.3,
"73.65",7.784,12.325,
"73.80",7.807,12.35,
"73.95",7.83,12.375,
"74.10",7.851,12.4,
"74.25",7.875,12.425,
"74.40",7.898,12.45,
"74.55",7.921,12.475,
"74.70",7.945,12.5,
"74.85",7.968,12.525,
"75.00",7.989,12.55,
"75.15",8.014,12.575,
"75.30",8.038,12.6,
"75.45",8.064,12.625,
"75.60",8.09,12.65,
"75.75",8.111,12.675,
"75.90",8.132,12.7,
"76.05",8.156,12.725,
"76.20",8.179,12.75,
"76.35",8.203,12.775,
"76.50",8.225,12.8,
"76.65",8.248,12.825,
"76.80",8.274,12.85,
"76.95",8.299,12.875,
"77.10",8.324,12.9,
"77.25",8.344,12.925,
"77.40",8.369,12.95,
"77.55",8.397,12.975,
"77.70",8.417,13.00033,
"77.85",8.442,13.025,
"78.00",8.465,13.05033,
"78.15",8.49,13.07533,
"78.30",8.514,13.1,
"78.45",8.534,13.125,
"78.60",8.558,13.15,
"78.75",8.582,13.175,
"78.90",8.605,13.2,
"79.05",8.627,13.225,
"79.20",8.65,13.25,
"79.35",8.675,13.275,
"79.50",8.582,13.30033,
"79.65",8.478,13.325,
"79.80",8.492,13.35,
"79.95",8.517,13.375,
"80.10",8.542,13.40033,
"80.25",8.572,13.425,
"80.40",8.605,13.45,
"80.55",8.633,13.47533,
"80.70",8.659,13.50033,
"80.85",8.676,13.52533,
"81.00",8.693,13.55033,
"81.15",8.71,13.57533,
"81.30",8.738,13.6,
"81.45",8.771,13.62533,
"81.60",8.802,13.65033,
"81.75",8.829,13.67533,
"81.90",8.86,13.70033,
"82.05",8.887,13.72533,
"82.20",8.916,13.75033,
"82.35",8.946,13.77533,
"82.50",8.975,13.80033,
"82.65",9.002,13.825,
"82.80",9.028,13.85033,
"82.95",9.056,13.875,
"83.10",9.083,13.90033,
"83.25",9.111,13.92533,
"83.40",9.137,13.95033,
"83.55",9.166,13.97533,
"83.70",9.191,14.00033,
"83.85",9.218,14.02533,
"84.00",9.242,14.05,
"84.15",9.269,14.075,
"84.30",9.296,14.1,
"84.45",9.325,14.125,
"84.60",9.349,14.15,
"84.75",9.376,14.175,
"84.90",9.404,14.2,
"85.05",9.428,14.225,
"85.20",9.455,14.25,
"85.35",9.483,14.275,
"85.50",9.512,14.30033,
"85.65",9.536,14.325,
"85.80",9.561,14.35,
"85.95",9.588,14.375,
"86.10",9.613,14.4,
"86.25",9.639,14.425,
"86.40",9.664,14.45,
"86.55",9.692,14.475,
"86.70",9.715,14.5,
"86.85",9.741,14.525,
"87.00",9.764,14.55,
"87.15",9.793,14.57533,
"87.30",9.82,14.6,
"87.45",9.844,14.62533,
"87.60",9.866,14.65033,
"87.75",9.891,14.67533,
"87.90",9.912,14.70033,
"88.05",9.936,14.72533,
"88.20",9.961,14.75033,
"88.35",9.988,14.775,
"88.50",10.013,14.8,
"88.65",10.031,14.825,
"88.80",9.994,14.85,
"88.95",9.831,14.87533,
"89.10",9.831,14.90033,
"89.25",9.862,14.925,
"89.40",9.897,14.95,
"89.55",9.93,14.975,
"89.70",9.967,15.00033,
"89.85",10,15.02533,
"90.00",10.035,15.05033,
"90.15",10.07,15.07533,
"90.30",10.106,15.1,
"90.45",10.143,15.125,
"90.60",10.174,15.15,
"90.75",10.205,15.175,
"90.90",10.236,15.2,
"91.05",10.268,15.225,
"91.20",10.299,15.25,
"91.35",10.335,15.275,
"91.50",10.365,15.30033,
"91.65",10.396,15.325,
"91.80",10.427,15.35,
"91.95",10.459,15.375,
"92.10",10.487,15.4,
"92.25",10.518,15.425,
"92.40",10.55,15.45,
"92.55",10.579,15.475,
"92.70",10.607,15.5,
"92.85",10.638,15.525,
"93.00",10.667,15.55,
"93.15",10.698,15.575,
"93.30",10.73,15.6,
"93.45",10.759,15.625,
"93.60",10.788,15.65,
"93.75",10.815,15.675,
"93.90",10.841,15.7,
"94.05",10.87,15.725,
"94.20",10.9,15.75033,
"94.35",10.928,15.775,
"94.50",10.955,15.8,
"94.65",10.984,15.825,
"94.80",11.011,15.85,
"94.95",11.039,15.875,
"95.10",11.066,15.9,
"95.25",11.097,15.92533,
"95.40",11.125,15.95033,
"95.55",11.156,15.97533,
"95.70",11.186,16,
"95.85",11.213,16.025,
"96.00",11.24,16.05,
"96.15",11.269,16.07533,
"96.30",11.3,16.10033,
"96.45",11.329,16.12533,
"96.60",11.358,16.15,
"96.75",11.386,16.175,
"96.90",11.416,16.2,
"97.05",11.444,16.225,
"97.20",11.474,16.25,
"97.35",11.505,16.275,
"97.50",11.536,16.3,
"97.65",11.561,16.325,
"97.80",11.59,16.35,
"97.95",11.619,16.375,
"98.10",11.651,16.4,
"98.25",11.684,16.425,
"98.40",11.715,16.45,
"98.55",11.743,16.475,
"98.70",11.771,16.5,
"98.85",11.8,16.525,
"99.00",11.83,16.55,
"99.15",11.86,16.575,
"99.30",11.891,16.6,
"99.45",11.921,16.625,
"99.60",11.952,16.65,
"99.75",11.979,16.675,
"99.90",12.007,16.7,
"100.05",12.037,16.725,
"100.20",12.067,16.75,
"100.35",12.1,16.775,
"100.50",12.131,16.8,
"100.65",12.16,16.825,
"100.80",12.185,16.85,
"100.95",12.216,16.875,
"101.10",12.246,16.9,
"101.25",12.274,16.925,
"101.40",12.306,16.95,
"101.55",12.333,16.975,
"101.70",12.364,17,
"101.85",12.393,17.025,
"102.00",12.423,17.05,
"102.15",12.456,17.075,
"102.30",12.487,17.1,
"102.45",12.517,17.125,
"102.60",12.544,17.15,
"102.75",12.573,17.175,
"102.90",12.604,17.2,
"103.05",12.633,17.225,
"103.20",12.665,17.25,
"103.35",12.695,17.275,
"103.50",12.724,17.3,
"103.65",12.747,17.325,
"103.80",12.759,17.35,
"103.95",12.765,17.375,
"104.10",12.784,17.4,
"104.25",12.812,17.425,
"104.40",12.841,17.45,
"104.55",12.867,17.47533,
"104.70",12.898,17.5,
"104.85",12.924,17.525,
"105.00",12.953,17.55,
"105.15",12.982,17.57533,
"105.30",13.011,17.6,
"105.45",13.037,17.625,
"105.60",13.059,17.65,
"105.75",13.081,17.675,
"105.90",13.108,17.7,
"106.05",13.134,17.72533,
"106.20",13.159,17.75033,
"106.35",13.189,17.77533,
"106.50",13.216,17.80033,
"106.65",13.247,17.82533,
"106.80",13.278,17.85033,
"106.95",13.31,17.87533,
"107.10",13.34,17.9,
"107.25",13.374,17.925,
"107.40",13.407,17.95033,
"107.55",13.441,17.97533,
"107.70",13.474,18.00033,
"107.85",13.503,18.025,
"108.00",13.534,18.05,
"108.15",13.568,18.075,
"108.30",13.603,18.1,
"108.45",13.636,18.125,
"108.60",13.666,18.15,
"108.75",13.696,18.175,
"108.90",13.726,18.2,
"109.05",13.759,18.225,
"109.20",13.789,18.25,
"109.35",13.825,18.275,
"109.50",13.857,18.3,
"109.65",13.886,18.325,
"109.80",13.917,18.35,
"109.95",13.947,18.375,
"110.10",13.977,18.4,
"110.25",14.007,18.425,
"110.40",14.039,18.45,
"110.55",14.072,18.475,
"110.70",14.103,18.5,
"110.85",14.131,18.525,
"111.00",14.159,18.55,
"111.15",14.192,18.57533,
"111.30",14.226,18.6,
"111.45",14.257,18.62533,
"111.60",14.288,18.65,
"111.75",14.316,18.675,
"111.90",14.346,18.7,
"112.05",14.375,18.725,
"112.20",14.402,18.75,
"112.35",14.434,18.775,
"112.50",14.467,18.8,
"112.65",14.498,18.825,
"112.80",14.529,18.85,
"112.95",14.56,18.875,
"113.10",14.591,18.9,
"113.25",14.62,18.925,
"113.40",14.653,18.95,
"113.55",14.68,18.975,
"113.70",14.708,19,
"113.85",14.735,19.025,
"114.00",14.763,19.05,
"114.15",14.797,19.075,
"114.30",14.83,19.1,
"114.45",14.86,19.125,
"114.60",14.892,19.15,
"114.75",14.918,19.175,
"114.90",14.949,19.2,
"115.05",14.979,19.225,
"115.20",15.007,19.25033,
"115.35",15.039,19.275,
"115.50",15.072,19.30033,
"115.65",15.099,19.325,
"115.80",15.13,19.35,
"115.95",15.155,19.375,
"116.10",15.177,19.4,
"116.25",15.207,19.425,
"116.40",15.234,19.45,
"116.55",15.262,19.475,
"116.70",15.292,19.5,
"116.85",15.322,19.525,
"117.00",15.351,19.55,
"117.15",15.383,19.575,
"117.30",15.416,19.6,
"117.45",15.447,19.625,
"117.60",15.474,19.65,
"117.75",15.505,19.675,
"117.90",15.537,19.7,
"118.05",15.569,19.725,
"118.20",15.603,19.75,
"118.35",15.634,19.775,
"118.50",15.665,19.8,
"118.65",15.692,19.825,
"118.80",15.723,19.85,
"118.95",15.753,19.875,
"119.10",15.784,19.9,
"119.25",15.817,19.925,
"119.40",15.85,19.95,
"119.55",15.88,19.97533,
"119.70",15.909,20.00033,
"119.85",15.934,20.02533,
"120.00",15.96,20.05033,
"120.15",15.992,20.07533,
"120.30",16.024,20.1,
"120.45",16.052,20.125,
"120.60",16.085,20.15033,
"120.75",16.115,20.175,
"120.90",16.143,20.2,
"121.05",16.17,20.225,
"121.20",16.202,20.25,
"121.35",16.233,20.275,
"121.50",16.261,20.3,
"121.65",16.29,20.32533,
"121.80",16.318,20.35,
"121.95",16.345,20.375,
"122.10",16.375,20.4,
"122.25",16.407,20.425,
"122.40",16.435,20.45033,
"122.55",16.466,20.47533,
"122.70",16.495,20.5,
"122.85",16.524,20.525,
"123.00",16.558,20.55,
"123.15",16.589,20.57533,
"123.30",16.618,20.6,
"123.45",16.648,20.625,
"123.60",16.681,20.65033,
"123.75",16.707,20.675,
"123.90",16.737,20.7,
"124.05",16.766,20.725,
"124.20",16.798,20.75,
"124.35",16.827,20.775,
"124.50",16.859,20.8,
"124.65",16.888,20.825,
"124.80",16.916,20.85,
"124.95",16.945,20.875,
"125.10",16.973,20.9,
"125.25",17.002,20.925,
"125.40",17.03,20.95,
"125.55",17.062,20.975,
"125.70",17.092,21,
"125.85",17.118,21.025,
"126.00",17.15,21.05,
"126.15",17.179,21.075,
"126.30",17.21,21.1,
"126.45",17.237,21.125,
"126.60",17.266,21.15,
"126.75",17.294,21.175,
"126.90",17.322,21.2,
"127.05",17.35,21.225,
"127.20",17.38,21.25,
"127.35",17.409,21.275,
"127.50",17.439,21.3,
"127.65",17.468,21.325,
"127.80",17.495,21.35,
"127.95",17.521,21.375,
"128.10",17.551,21.4,
"128.25",17.579,21.425,
"128.40",17.611,21.45,
"128.55",17.637,21.475,
"128.70",17.661,21.5,
"128.85",17.686,21.525,
"129.00",17.713,21.55,
"129.15",17.741,21.575,
"129.30",17.767,21.6,
"129.45",17.792,21.625,
"129.60",17.818,21.65,
"129.75",17.841,21.675,
"129.90",17.864,21.7,
"130.05",17.891,21.725,
"130.20",17.921,21.75033,
"130.35",17.946,21.77533,
"130.50",17.974,21.80033,
"130.65",17.999,21.82533,
"130.80",18.025,21.85033,
"130.95",18.049,21.875,
"131.10",18.075,21.9,
"131.25",18.1,21.925,
"131.40",18.127,21.95,
"131.55",18.154,21.975,
"131.70",18.175,22,
"131.85",18.2,22.025,
"132.00",18.223,22.05,
"132.15",18.251,22.075,
"132.30",18.279,22.1,
"132.45",18.305,22.125,
"132.60",18.329,22.15,
"132.75",18.35,22.175,
"132.90",18.375,22.2,
"133.05",18.399,22.225,
"133.20",18.428,22.25,
"133.35",18.455,22.275,
"133.50",18.477,22.30033,
"133.65",18.5,22.325,
"133.80",18.52,22.35,
"133.95",18.542,22.375,
"134.10",18.568,22.4,
"134.25",18.595,22.425,
"134.40",18.622,22.45,
"134.55",18.646,22.475,
"134.70",18.675,22.50033,
"134.85",18.7,22.52533,
"135.00",18.725,22.55033,
"135.15",18.75,22.575,
"135.30",18.78,22.6,
"135.45",18.807,22.62533,
"135.60",18.835,22.65033,
"135.75",18.86,22.67533,
"135.90",18.884,22.70033,
"136.05",18.909,22.725,
"136.20",18.934,22.75,
"136.35",18.964,22.775,
"136.50",18.99,22.8,
"136.65",19.015,22.825,
"136.80",19.04,22.85,
"136.95",19.068,22.875,
"137.10",19.092,22.9,
"137.25",19.121,22.925,
"137.40",19.149,22.95,
"137.55",19.174,22.975,
"137.70",19.198,23,
"137.85",19.224,23.025,
"138.00",19.252,23.05,
"138.15",19.278,23.075,
"138.30",19.305,23.1,
"138.45",19.332,23.125,
"138.60",19.357,23.15,
"138.75",19.385,23.175,
"138.90",19.408,23.2,
"139.05",19.432,23.225,
"139.20",19.458,23.25,
"139.35",19.485,23.275,
"139.50",19.511,23.3,
"139.65",19.537,23.325,
"139.80",19.562,23.35,
"139.95",19.582,23.375,
"140.10",19.608,23.4,
"140.25",19.636,23.425,
"140.40",19.665,23.45,
"140.55",19.689,23.47533,
"140.70",19.714,23.50033,
"140.85",19.738,23.525,
"141.00",19.759,23.55033,
"141.15",19.781,23.575,
"141.30",19.809,23.6,
"141.45",19.835,23.625,
"141.60",19.86,23.65,
"141.75",19.881,23.67533,
"141.90",19.904,23.70033,
"142.05",19.93,23.72533,
"142.20",19.954,23.75,
"142.35",19.981,23.775,
"142.50",20,23.8,
"142.65",20.021,23.825,
"142.80",20.047,23.85,
"142.95",20.068,23.875,
"143.10",20.092,23.9,
"143.25",20.115,23.925,
"143.40",20.14,23.95,
"143.55",20.162,23.975,
"143.70",20.179,24,
"143.85",20.199,24.025,
"144.00",20.221,24.05,
"144.15",20.244,24.075,
"144.30",20.268,24.1,
"144.45",20.293,24.125,
"144.60",20.316,24.15,
"144.75",20.33,24.175,
"144.90",20.352,24.2,
"145.05",20.373,24.225,
"145.20",20.391,24.25,
"145.35",20.418,24.275,
"145.50",20.441,24.3,
"145.65",20.457,24.325,
"145.80",20.479,24.35,
"145.95",20.496,24.375,
"146.10",20.517,24.4,
"146.25",20.539,24.425,
"146.40",20.562,24.45,
"146.55",20.579,24.475,
"146.70",20.597,24.5,
"146.85",20.613,24.525,
"147.00",20.63,24.55,
"147.15",20.649,24.575,
"147.30",20.666,24.6,
"147.45",20.681,24.625,
"147.60",20.695,24.65,
"147.75",20.706,24.675,
"147.90",20.721,24.7,
"148.05",20.74,24.725,
"148.20",20.76,24.75,
"148.35",20.778,24.775,
"148.50",20.797,24.8,
"148.65",20.817,24.825,
"148.80",20.834,24.85,
"148.95",20.851,24.875,
"149.10",20.872,24.9,
"149.25",20.896,24.925,
"149.40",20.914,24.95,
"149.55",20.938,24.975,
"149.70",20.955,25,
"149.85",20.97,25.025,
"150.00",20.989,25.05,
"150.15",21.009,25.075,
"150.30",21.03,25.1,
"150.45",21.052,25.12533,
"150.60",21.073,25.15033,
"150.75",21.092,25.175,
"150.90",21.108,25.2,
"151.05",21.127,25.22533,
"151.20",21.145,25.25,
"151.35",21.163,25.275,
"151.50",21.185,25.30033,
"151.65",21.202,25.325,
"151.80",21.221,25.35,
"151.95",21.236,25.375,
"152.10",21.255,25.4,
"152.25",21.276,25.425,
"152.40",21.297,25.45,
"152.55",21.311,25.475,
"152.70",21.329,25.5,
"152.85",21.344,25.525,
"153.00",21.363,25.55,
"153.15",21.38,25.575,
"153.30",21.401,25.6,
"153.45",21.416,25.625,
"153.60",21.434,25.65,
"153.75",21.447,25.675,
"153.90",21.465,25.7,
"154.05",21.48,25.725,
"154.20",21.5,25.75,
"154.35",21.519,25.775,
"154.50",21.538,25.8,
"154.65",21.555,25.825,
"154.80",21.571,25.85,
"154.95",21.589,25.875,
"155.10",21.604,25.9,
"155.25",21.624,25.925,
"155.40",21.643,25.95,
"155.55",21.664,25.975,
"155.70",21.683,26.00033,
"155.85",21.697,26.025,
"156.00",21.716,26.05033,
"156.15",21.731,26.07533,
"156.30",21.753,26.10033,
"156.45",21.773,26.12533,
"156.60",21.79,26.15,
"156.75",21.804,26.17533,
"156.90",21.823,26.20033,
"157.05",21.84,26.225,
"157.20",21.858,26.25,
"157.35",21.876,26.27533,
"157.50",21.895,26.30033,
"157.65",21.91,26.32533,
"157.80",21.926,26.35033,
"157.95",21.943,26.37533,
"158.10",21.959,26.40033,
"158.25",21.98,26.425,
"158.40",21.998,26.45,
"158.55",22.013,26.475,
"158.70",22.024,26.5,
"158.85",22.041,26.525,
"159.00",22.056,26.55,
"159.15",22.075,26.575,
"159.30",22.096,26.6,
"159.45",22.112,26.625,
"159.60",22.132,26.65,
"159.75",22.145,26.675,
"159.90",22.16,26.7,
"160.05",22.176,26.725,
"160.20",22.194,26.75033,
"160.35",22.215,26.775,
"160.50",22.233,26.8,
"160.65",22.247,26.825,
"160.80",22.265,26.85,
"160.95",22.28,26.875,
"161.10",22.297,26.9,
"161.25",22.313,26.925,
"161.40",22.33,26.95033,
"161.55",22.347,26.975,
"161.70",22.359,27,
"161.85",22.374,27.025,
"162.00",22.392,27.05033,
"162.15",22.407,27.07533,
"162.30",22.424,27.10033,
"162.45",22.441,27.125,
"162.60",22.454,27.15,
"162.75",22.465,27.175,
"162.90",22.481,27.2,
"163.05",22.496,27.22533,
"163.20",22.512,27.25033,
"163.35",22.527,27.275,
"163.50",22.541,27.30033,
"163.65",22.553,27.32533,
"163.80",22.565,27.35,
"163.95",22.579,27.37533,
"164.10",22.597,27.4,
"164.25",22.616,27.425,
"164.40",22.637,27.45,
"164.55",22.654,27.475,
"164.70",22.668,27.5,
"164.85",22.684,27.525,
"165.00",22.701,27.55,
"165.15",22.722,27.57533,
"165.30",22.741,27.60033,
"165.45",22.761,27.62533,
"165.60",22.779,27.65033,
"165.75",22.796,27.67533,
"165.90",22.813,27.70033,
"166.05",22.826,27.72533,
"166.20",22.845,27.75033,
"166.35",22.865,27.77533,
"166.50",22.88,27.80033,
"166.65",22.893,27.825,
"166.80",22.907,27.85,
"166.95",22.92,27.875,
"167.10",22.933,27.9,
"167.25",22.949,27.925,
"167.40",22.964,27.95,
"167.55",22.976,27.975,
"167.70",22.988,28,
"167.85",23,28.025,
"168.00",23.015,28.05,
"168.15",23.035,28.075,
"168.30",23.048,28.10033,
"168.45",23.066,28.125,
"168.60",23.083,28.15,
"168.75",23.096,28.175,
"168.90",23.107,28.2,
"169.05",23.124,28.225,
"169.20",23.144,28.25,
"169.35",23.165,28.275,
"169.50",23.182,28.30033,
"169.65",23.201,28.325,
"169.80",23.21,28.35,
"169.95",23.224,28.375,
"170.10",23.24,28.4,
"170.25",23.261,28.425,
"170.40",23.282,28.45,
"170.55",23.301,28.475,
"170.70",23.319,28.5,
"170.85",23.338,28.525,
"171.00",23.357,28.55,
"171.15",23.375,28.575,
"171.30",23.398,28.6,
"171.45",23.418,28.62533,
"171.60",23.437,28.65033,
"171.75",23.452,28.675,
"171.90",23.472,28.7,
"172.05",23.492,28.725,
"172.20",23.513,28.75,
"172.35",23.53,28.775,
"172.50",23.545,28.80033,
"172.65",23.563,28.825,
"172.80",23.581,28.85033,
"172.95",23.598,28.87533,
"173.10",23.616,28.90033,
"173.25",23.637,28.925,
"173.40",23.657,28.95,
"173.55",23.676,28.975,
"173.70",23.691,29,
"173.85",23.707,29.025,
"174.00",23.727,29.05,
"174.15",23.745,29.07533,
"174.30",23.764,29.1,
"174.45",23.784,29.125,
"174.60",23.807,29.15,
"174.75",23.819,29.175,
"174.90",23.837,29.20033,
"175.05",23.853,29.22533,
"175.20",23.871,29.25033,
"175.35",23.894,29.275,
"175.50",23.911,29.30033,
"175.65",23.929,29.325,
"175.80",23.947,29.35,
"175.95",23.962,29.375,
"176.10",23.979,29.4,
"176.25",24,29.425,
"176.40",24.02,29.45,
"176.55",24.04,29.475,
"176.70",24.05,29.5,
"176.85",24.07,29.525,
"177.00",24.09,29.55033,
"177.15",24.11,29.57533,
"177.30",24.13,29.6,
"177.45",24.15,29.625,
"177.60",24.17,29.65,
"177.75",24.18,29.675,
"177.90",24.2,29.7,
"178.05",24.22,29.725,
"178.20",24.24,29.75,
"178.35",24.26,29.775,
"178.50",24.28,29.8,
"178.65",24.3,29.825,
"178.80",24.31,29.85,
"178.95",24.33,29.875,
"179.10",24.36,29.9,
"179.25",24.38,29.925,
"179.40",24.4,29.95,
"179.55",24.42,29.975,
"179.70",24.44,30,
"179.85",24.46,30.025,
"180.00",24.47,30.05033,
"180.15",24.49,30.07533,
"180.30",24.51,30.10033,
"180.45",24.54,30.12533,
"180.60",24.56,30.15033,
"180.75",24.57,30.175,
"180.90",24.59,30.2,
"181.05",24.61,30.225,
"181.20",24.62,30.25,
"181.35",24.64,30.275,
"181.50",24.66,30.3,
"181.65",24.69,30.325,
"181.80",24.7,30.35,
"181.95",24.72,30.375,
"182.10",24.74,30.4,
"182.25",24.76,30.425,
"182.40",24.79,30.45,
"182.55",24.8,30.475,
"182.70",24.82,30.5,
"182.85",24.83,30.525,
"183.00",24.85,30.55,
"183.15",24.87,30.575,
"183.30",24.9,30.6,
"183.45",24.92,30.625,
"183.60",24.94,30.65033,
"183.75",24.95,30.675,
"183.90",24.97,30.7,
"184.05",24.99,30.72533,
"184.20",25.01,30.75033,
"184.35",25.03,30.77533,
"184.50",25.05,30.80033,
"184.65",25.07,30.825,
"184.80",25.09,30.85,
"184.95",25.11,30.875,
"185.10",25.13,30.9,
"185.25",25.15,30.925,
"185.40",25.17,30.95,
"185.55",25.19,30.975,
"185.70",25.21,31,
"185.85",25.22,31.025,
"186.00",25.24,31.05,
"186.15",25.26,31.07533,
"186.30",25.28,31.1,
"186.45",25.3,31.125,
"186.60",25.32,31.15,
"186.75",25.34,31.175,
"186.90",25.35,31.2,
"187.05",25.37,31.225,
"187.20",25.39,31.25,
"187.35",25.41,31.275,
"187.50",25.43,31.30033,
"187.65",25.45,31.325,
"187.80",25.46,31.35,
"187.95",25.48,31.375,
"188.10",25.5,31.4,
"188.25",25.52,31.425,
"188.40",25.53,31.45,
"188.55",25.55,31.475,
"188.70",25.57,31.5,
"188.85",25.58,31.525,
"189.00",25.6,31.55033,
"189.15",25.62,31.57533,
"189.30",25.64,31.6,
"189.45",25.66,31.62533,
"189.60",25.69,31.65,
"189.75",25.7,31.675,
"189.90",25.72,31.70033,
"190.05",25.74,31.72533,
"190.20",25.76,31.75033,
"190.35",25.78,31.775,
"190.50",25.8,31.8,
"190.65",25.82,31.825,
"190.80",25.83,31.85,
"190.95",25.85,31.875,
"191.10",25.86,31.9,
"191.25",25.88,31.925,
"191.40",25.9,31.95,
"191.55",25.92,31.975,
"191.70",25.93,32,
"191.85",25.94,32.025,
"192.00",25.96,32.05033,
"192.15",25.97,32.075,
"192.30",25.97,32.1,
"192.35",25.97,32.10833,