File: exposed_monofilament_10.3cm_10mmpm_12nm_250esh_5.csv
"Test Name","Test Mode","Test Type","Control","Test Speed 1","Test Speed 2","Test Speed 3","Change Point 1","Change Point 2","Disp. Origin","Break and Limit Action","Sensitivity:","Level:"
"","Single","Tensile","Stroke",10,1,1,"Off","Off","Start","Stop",0,1

"Title","Sub title","Comment"
"","",""

"Shape:","Batch Size:","SubBatch Size:"
"Plate",1,1
"Name:","Thickness","Width","Gauge Length",
"Size Unit:","mm","mm","mm",
" 1 - 1","1.0000","1.0000","100.0000",

"Name",
"Parameter",
"Units",
" 1 - 1",

" 1- 1"
"Time","Force","Stroke",
"sec","N","mm",
"0.00",-.001,0,
"0.20",-.001,.035,
"0.40",.003,.072,
"0.60",.017,.1093333,
"0.80",.031,.1463333,
"1.00",.047,.1833333,
"1.20",.062,.2203333,
"1.40",.073,.2573333,
"1.60",.09,.2943333,
"1.80",.102,.3313333,
"2.00",.118,.368,
"2.20",.133,.404,
"2.40",.148,.4396667,
"2.60",.163,.4746667,
"2.80",.176,.5093333,
"3.00",.188,.544,
"3.20",.201,.5783333,
"3.40",.214,.6123334,
"3.60",.226,.6463333,
"3.80",.241,.68,
"4.00",.254,.714,
"4.20",.266,.7473333,
"4.40",.279,.781,
"4.60",.291,.8143333,
"4.80",.308,.848,
"5.00",.321,.8813334,
"5.20",.333,.915,
"5.40",.346,.9483333,
"5.60",.357,.9816667,
"5.80",.373,1.015,
"6.00",.384,1.048333,
"6.20",.399,1.082,
"6.40",.413,1.115333,
"6.60",.428,1.148667,
"6.80",.44,1.182,
"7.00",.456,1.215333,
"7.20",.47,1.249,
"7.40",.482,1.282,
"7.60",.497,1.315333,
"7.80",.511,1.348667,
"8.00",.523,1.382333,
"8.20",.536,1.415333,
"8.40",.551,1.448667,
"8.60",.565,1.482,
"8.80",.579,1.515333,
"9.00",.592,1.548667,
"9.20",.606,1.582,
"9.40",.62,1.615333,
"9.60",.63,1.648667,
"9.80",.646,1.682,
"10.00",.661,1.715,
"10.20",.675,1.748333,
"10.40",.687,1.781667,
"10.60",.701,1.815333,
"10.80",.718,1.848333,
"11.00",.729,1.882,
"11.20",.745,1.915333,
"11.40",.761,1.948667,
"11.60",.776,1.981667,
"11.80",.79,2.015333,
"12.00",.805,2.048667,
"12.20",.818,2.082,
"12.40",.834,2.115333,
"12.60",.847,2.148667,
"12.80",.863,2.182,
"13.00",.878,2.215333,
"13.20",.891,2.248667,
"13.40",.904,2.282,
"13.60",.923,2.315333,
"13.80",.937,2.348667,
"14.00",.953,2.382,
"14.20",.968,2.415333,
"14.40",.983,2.448667,
"14.60",.998,2.482,
"14.80",1.015,2.515333,
"15.00",1.03,2.548667,
"15.20",1.046,2.582333,
"15.40",1.061,2.615333,
"15.60",1.077,2.648667,
"15.80",1.091,2.682,
"16.00",1.109,2.715333,
"16.20",1.125,2.748667,
"16.40",1.14,2.782,
"16.60",1.155,2.815333,
"16.80",1.176,2.848333,
"17.00",1.19,2.882,
"17.20",1.205,2.915333,
"17.40",1.225,2.948667,
"17.60",1.239,2.982,
"17.80",1.257,3.015333,
"18.00",1.274,3.048667,
"18.20",1.29,3.082,
"18.40",1.308,3.115,
"18.60",1.326,3.148667,
"18.80",1.344,3.182,
"19.00",1.362,3.215333,
"19.20",1.377,3.248667,
"19.40",1.394,3.282,
"19.60",1.413,3.315333,
"19.80",1.429,3.348667,
"20.00",1.448,3.382,
"20.20",1.466,3.415333,
"20.40",1.485,3.448667,
"20.60",1.503,3.482,
"20.80",1.522,3.515333,
"21.00",1.54,3.548667,
"21.20",1.562,3.582333,
"21.40",1.58,3.615667,
"21.60",1.597,3.649,
"21.80",1.621,3.682333,
"22.00",1.639,3.715667,
"22.20",1.658,3.748667,
"22.40",1.674,3.782333,
"22.60",1.701,3.815667,
"22.80",1.719,3.849,
"23.00",1.737,3.882333,
"23.20",1.757,3.915667,
"23.40",1.775,3.948667,
"23.60",1.797,3.982,
"23.80",1.82,4.015333,
"24.00",1.84,4.049,
"24.20",1.861,4.082334,
"24.40",1.878,4.115334,
"24.60",1.902,4.149,
"24.80",1.925,4.182,
"25.00",1.943,4.215333,
"25.20",1.967,4.248667,
"25.40",1.985,4.282,
"25.60",2.006,4.315333,
"25.80",2.032,4.348667,
"26.00",2.054,4.382333,
"26.20",2.075,4.415333,
"26.40",2.101,4.449,
"26.60",2.121,4.482333,
"26.80",2.147,4.515333,
"27.00",2.167,4.548666,
"27.20",2.191,4.582334,
"27.40",2.213,4.615667,
"27.60",2.239,4.649,
"27.80",2.261,4.682,
"28.00",2.286,4.715333,
"28.20",2.311,4.748667,
"28.40",2.332,4.782,
"28.60",2.359,4.815667,
"28.80",2.384,4.848667,
"29.00",2.409,4.882333,
"29.20",2.433,4.915667,
"29.40",2.459,4.948667,
"29.60",2.485,4.982333,
"29.80",2.511,5.015333,
"30.00",2.536,5.048666,
"30.20",2.562,5.082,
"30.40",2.589,5.115667,
"30.60",2.615,5.149,
"30.80",2.639,5.182,
"31.00",2.664,5.215333,
"31.20",2.691,5.248667,
"31.40",2.713,5.282,
"31.60",2.742,5.315333,
"31.80",2.768,5.349,
"32.00",2.796,5.382,
"32.20",2.828,5.415333,
"32.40",2.849,5.448667,
"32.60",2.877,5.482,
"32.80",2.909,5.515333,
"33.00",2.934,5.548666,
"33.20",2.964,5.582,
"33.40",2.991,5.615334,
"33.60",3.022,5.648667,
"33.80",3.051,5.682,
"34.00",3.08,5.715333,
"34.20",3.107,5.748667,
"34.40",3.14,5.782,
"34.60",3.168,5.815333,
"34.80",3.198,5.848667,
"35.00",3.228,5.882,
"35.20",3.261,5.915333,
"35.40",3.29,5.948667,
"35.60",3.321,5.981667,
"35.80",3.354,6.015333,
"36.00",3.385,6.048666,
"36.20",3.415,6.082,
"36.40",3.446,6.115334,
"36.60",3.476,6.148667,
"36.80",3.507,6.182,
"37.00",3.537,6.215333,
"37.20",3.57,6.248667,
"37.40",3.599,6.282,
"37.60",3.63,6.315333,
"37.80",3.663,6.348667,
"38.00",3.695,6.382,
"38.20",3.728,6.415333,
"38.40",3.76,6.448667,
"38.60",3.792,6.482,
"38.80",3.826,6.515333,
"39.00",3.849,6.548666,
"39.20",3.876,6.582,
"39.40",3.914,6.615334,
"39.60",3.947,6.648667,
"39.80",3.982,6.682,
"40.00",4.016,6.715333,
"40.20",4.05,6.749,
"40.40",4.086,6.782333,
"40.60",4.119,6.815667,
"40.80",4.154,6.849,
"41.00",4.192,6.882333,
"41.20",4.225,6.915333,
"41.40",4.258,6.948667,
"41.60",4.292,6.982333,
"41.80",4.325,7.015333,
"42.00",4.364,7.048666,
"42.20",4.399,7.082,
"42.40",4.434,7.115334,
"42.60",4.47,7.149,
"42.80",4.503,7.182,
"43.00",4.538,7.215667,
"43.20",4.572,7.249,
"43.40",4.607,7.282333,
"43.60",4.645,7.315667,
"43.80",4.68,7.348667,
"44.00",4.716,7.382,
"44.20",4.748,7.415333,
"44.40",4.783,7.448667,
"44.60",4.816,7.482,
"44.80",4.856,7.515333,
"45.00",4.891,7.548666,
"45.20",4.926,7.582334,
"45.40",4.961,7.615667,
"45.60",4.999,7.649,
"45.80",5.03,7.682,
"46.00",5.069,7.715333,
"46.20",5.103,7.749,
"46.40",5.136,7.782333,
"46.60",5.176,7.815333,
"46.80",5.212,7.848667,
"47.00",5.242,7.882,
"47.20",5.278,7.915333,
"47.40",5.313,7.948667,
"47.60",5.348,7.982,
"47.80",5.38,8.015333,
"48.00",5.414,8.048667,
"48.20",5.447,8.082,
"48.40",5.485,8.115334,
"48.60",5.517,8.148666,
"48.80",5.553,8.182,
"49.00",5.584,8.215333,
"49.20",5.616,8.248667,
"49.40",5.649,8.282,
"49.60",5.681,8.315333,
"49.80",5.715,8.348666,
"50.00",5.752,8.382,
"50.20",5.783,8.415334,
"50.40",5.815,8.448667,
"50.60",5.845,8.482,
"50.80",5.877,8.515333,
"51.00",5.911,8.548667,
"51.20",5.944,8.582,
"51.40",5.974,8.615334,
"51.60",6.006,8.648666,
"51.80",6.037,8.682,
"52.00",6.068,8.715333,
"52.20",6.102,8.748667,
"52.40",6.134,8.782,
"52.60",6.166,8.815666,
"52.80",6.2,8.848666,
"53.00",6.228,8.882,
"53.20",6.258,8.915667,
"53.40",6.291,8.949,
"53.60",6.321,8.982,
"53.80",6.357,9.015333,
"54.00",6.388,9.049,
"54.20",6.416,9.082,
"54.40",6.444,9.115334,
"54.60",6.476,9.148666,
"54.80",6.509,9.182,
"55.00",6.54,9.215333,
"55.20",6.569,9.248667,
"55.40",6.597,9.282,
"55.60",6.629,9.315333,
"55.80",6.657,9.348666,
"56.00",6.69,9.382,
"56.20",6.72,9.415334,
"56.40",6.748,9.448667,
"56.60",6.777,9.482,
"56.80",6.808,9.515333,
"57.00",6.837,9.548667,
"57.20",6.868,9.582,
"57.40",6.895,9.615334,
"57.60",6.924,9.648666,
"57.80",6.953,9.682,
"58.00",6.984,9.715333,
"58.20",7.009,9.749,
"58.40",7.036,9.782,
"58.60",7.066,9.815666,
"58.80",7.096,9.849,
"59.00",7.123,9.882334,
"59.20",7.145,9.915667,
"59.40",7.168,9.948667,
"59.60",7.193,9.982333,
"59.80",7.218,10.01533,
"60.00",7.237,10.04867,
"60.20",7.257,10.082,
"60.40",7.265,10.11567,
"60.60",7.237,10.149,
"60.80",7.098,10.182,
"61.00",7.079,10.21567,
"61.20",7.097,10.249,
"61.40",7.127,10.282,
"61.60",7.163,10.31567,
"61.80",7.199,10.349,
"62.00",7.237,10.382,
"62.20",7.272,10.41533,
"62.40",7.306,10.44867,
"62.60",7.343,10.482,
"62.80",7.381,10.51533,
"63.00",7.412,10.54867,
"63.20",7.446,10.58233,
"63.40",7.478,10.61533,
"63.60",7.511,10.64867,
"63.80",7.545,10.682,
"64.00",7.577,10.71533,
"64.20",7.604,10.749,
"64.40",7.633,10.782,
"64.60",7.662,10.81533,
"64.80",7.694,10.84867,
"65.00",7.722,10.88233,
"65.20",7.751,10.91533,
"65.40",7.777,10.94867,
"65.60",7.805,10.982,
"65.80",7.832,11.01533,
"66.00",7.859,11.04867,
"66.20",7.883,11.082,
"66.40",7.911,11.11533,
"66.60",7.938,11.14867,
"66.80",7.965,11.182,
"67.00",7.99,11.21533,
"67.20",8.015,11.24867,
"67.40",8.04,11.282,
"67.60",8.066,11.31533,
"67.80",8.093,11.34867,
"68.00",8.121,11.382,
"68.20",8.144,11.41533,
"68.40",8.168,11.44867,
"68.60",8.194,11.482,
"68.80",8.218,11.51533,
"69.00",8.242,11.54867,
"69.20",8.264,11.582,
"69.40",8.287,11.61533,
"69.60",8.31,11.64867,
"69.80",8.335,11.682,
"70.00",8.359,11.71533,
"70.20",8.383,11.74867,
"70.40",8.408,11.782,
"70.60",8.427,11.81567,
"70.80",8.455,11.849,
"71.00",8.479,11.882,
"71.20",8.505,11.91533,
"71.40",8.53,11.94867,
"71.60",8.554,11.982,
"71.80",8.576,12.01533,
"72.00",8.603,12.04867,
"72.20",8.623,12.082,
"72.40",8.649,12.11533,
"72.60",8.675,12.149,
"72.80",8.702,12.18233,
"73.00",8.725,12.21567,
"73.20",8.745,12.249,
"73.40",8.769,12.28233,
"73.60",8.793,12.31533,
"73.80",8.816,12.349,
"74.00",8.835,12.38233,
"74.20",8.857,12.41533,
"74.40",8.875,12.44867,
"74.60",8.899,12.48233,
"74.80",8.921,12.51533,
"75.00",8.946,12.54867,
"75.20",8.962,12.58233,
"75.40",8.982,12.61567,
"75.60",9.005,12.64867,
"75.80",9.026,12.682,
"76.00",9.047,12.71533,
"76.20",9.067,12.74867,
"76.40",9.087,12.782,
"76.60",9.11,12.81533,
"76.80",9.13,12.84867,
"77.00",9.152,12.882,
"77.20",9.174,12.91533,
"77.40",9.196,12.94867,
"77.60",9.215,12.982,
"77.80",9.241,13.01533,
"78.00",9.262,13.04867,
"78.20",9.286,13.082,
"78.40",9.306,13.11533,
"78.60",9.331,13.14867,
"78.80",9.354,13.182,
"79.00",9.375,13.21533,
"79.20",9.395,13.24867,
"79.40",9.416,13.282,
"79.60",9.439,13.31533,
"79.80",9.462,13.34867,
"80.00",9.482,13.382,
"80.20",9.5,13.41533,
"80.40",9.521,13.44867,
"80.60",9.542,13.48233,
"80.80",9.564,13.51567,
"81.00",9.586,13.549,
"81.20",9.606,13.582,
"81.40",9.628,13.61567,
"81.60",9.647,13.649,
"81.80",9.668,13.682,
"82.00",9.69,13.71533,
"82.20",9.71,13.74867,
"82.40",9.733,13.782,
"82.60",9.754,13.81533,
"82.80",9.774,13.84867,
"83.00",9.799,13.882,
"83.20",9.817,13.91533,
"83.40",9.841,13.94867,
"83.60",9.865,13.982,
"83.80",9.888,14.01533,
"84.00",9.907,14.04867,
"84.20",9.931,14.082,
"84.40",9.951,14.11533,
"84.60",9.972,14.14867,
"84.80",9.997,14.182,
"85.00",10.02,14.21533,
"85.20",10.041,14.24867,
"85.40",10.058,14.282,
"85.60",10.08,14.31533,
"85.80",10.103,14.34867,
"86.00",10.123,14.382,
"86.20",10.146,14.41533,
"86.40",10.164,14.44867,
"86.60",10.185,14.482,
"86.80",10.205,14.51533,
"87.00",10.228,14.54867,
"87.20",10.247,14.582,
"87.40",10.267,14.61533,
"87.60",10.287,14.64867,
"87.80",10.307,14.682,
"88.00",10.329,14.71533,
"88.20",10.346,14.74867,
"88.40",10.366,14.782,
"88.60",10.387,14.81533,
"88.80",10.409,14.84867,
"89.00",10.43,14.88233,
"89.20",10.447,14.91567,
"89.40",10.467,14.94867,
"89.60",10.488,14.982,
"89.80",10.507,15.01567,
"90.00",10.53,15.04867,
"90.20",10.551,15.082,
"90.40",10.568,15.11533,
"90.60",10.586,15.14867,
"90.80",10.611,15.182,
"91.00",10.63,15.21567,
"91.20",10.646,15.249,
"91.40",10.665,15.28233,
"91.60",10.683,15.31567,
"91.80",10.706,15.349,
"92.00",10.722,15.38233,
"92.20",10.741,15.41567,
"92.40",10.762,15.449,
"92.60",10.785,15.48233,
"92.80",10.804,15.51567,
"93.00",10.823,15.549,
"93.20",10.841,15.58233,
"93.40",10.859,15.61567,
"93.60",10.878,15.649,
"93.80",10.901,15.68233,
"94.00",10.917,15.71567,
"94.20",10.933,15.74867,
"94.40",10.949,15.782,
"94.60",10.97,15.81533,
"94.80",10.991,15.849,
"95.00",11.009,15.88233,
"95.20",11.03,15.91567,
"95.40",11.047,15.949,
"95.60",11.063,15.98233,
"95.80",11.086,16.01567,
"96.00",11.107,16.049,
"96.20",11.123,16.08233,
"96.40",11.142,16.11567,
"96.60",11.16,16.149,
"96.80",11.18,16.18233,
"97.00",11.2,16.21567,
"97.20",11.219,16.249,
"97.40",11.234,16.28233,
"97.60",11.256,16.31567,
"97.80",11.279,16.349,
"98.00",11.293,16.382,
"98.20",11.312,16.41533,
"98.40",11.332,16.44867,
"98.60",11.35,16.482,
"98.80",11.372,16.51533,
"99.00",11.388,16.549,
"99.20",11.406,16.58233,
"99.40",11.425,16.61567,
"99.60",11.443,16.649,
"99.80",11.466,16.68233,
"100.00",11.483,16.71533,
"100.20",11.502,16.74867,
"100.40",11.519,16.782,
"100.60",11.538,16.81533,
"100.80",11.56,16.84867,
"101.00",11.577,16.88233,
"101.20",11.596,16.91533,
"101.40",11.61,16.94867,
"101.60",11.63,16.98233,
"101.80",11.647,17.01533,
"102.00",11.664,17.04867,
"102.20",11.681,17.082,
"102.40",11.702,17.11567,
"102.60",11.722,17.149,
"102.80",11.742,17.18233,
"103.00",11.758,17.21567,
"103.20",11.772,17.249,
"103.40",11.792,17.28233,
"103.60",11.814,17.31567,
"103.80",11.831,17.349,
"104.00",11.85,17.38233,
"104.20",11.867,17.41567,
"104.40",11.882,17.449,
"104.60",11.898,17.48233,
"104.80",11.92,17.51567,
"105.00",11.94,17.549,
"105.20",11.956,17.58233,
"105.40",11.971,17.61567,
"105.60",11.992,17.649,
"105.80",12.01,17.682,
"106.00",12.027,17.71533,
"106.20",12.044,17.749,
"106.40",12.06,17.78233,
"106.60",12.074,17.81567,
"106.80",12.092,17.84867,
"107.00",12.107,17.88233,
"107.20",12.126,17.91567,
"107.40",12.138,17.94867,
"107.60",12.159,17.98233,
"107.80",12.181,18.01533,
"108.00",12.193,18.04867,
"108.20",12.209,18.08233,
"108.40",12.226,18.11567,
"108.60",12.244,18.149,
"108.80",12.264,18.182,
"109.00",12.28,18.21533,
"109.20",12.298,18.24867,
"109.40",12.309,18.282,
"109.60",12.328,18.31567,
"109.80",12.348,18.34867,
"110.00",12.366,18.38233,
"110.20",12.384,18.41533,
"110.40",12.398,18.44867,
"110.60",12.415,18.482,
"110.80",12.432,18.51567,
"111.00",12.453,18.549,
"111.20",12.467,18.58233,
"111.40",12.484,18.61567,
"111.60",12.496,18.649,
"111.80",12.513,18.68233,
"112.00",12.529,18.71567,
"112.20",12.541,18.749,
"112.40",12.555,18.78233,
"112.60",12.57,18.81567,
"112.80",12.586,18.849,
"113.00",12.598,18.88233,
"113.20",12.611,18.91567,
"113.40",12.626,18.949,
"113.60",12.64,18.98233,
"113.80",12.656,19.01533,
"114.00",12.673,19.04867,
"114.20",12.685,19.08233,
"114.40",12.697,19.11567,
"114.60",12.715,19.149,
"114.80",12.735,19.18233,
"115.00",12.752,19.21567,
"115.20",12.769,19.249,
"115.40",12.783,19.282,
"115.60",12.796,19.31533,
"115.80",12.817,19.34867,
"116.00",12.832,19.382,
"116.20",12.847,19.41533,
"116.40",12.861,19.449,
"116.60",12.878,19.482,
"116.80",12.895,19.51533,
"117.00",12.914,19.54867,
"117.20",12.929,19.582,
"117.40",12.945,19.61533,
"117.60",12.961,19.64867,
"117.80",12.98,19.682,
"118.00",12.996,19.71533,
"118.20",13.016,19.74867,
"118.40",13.031,19.782,
"118.60",13.051,19.81533,
"118.80",13.067,19.84867,
"119.00",13.084,19.882,
"119.20",13.097,19.91533,
"119.40",13.115,19.949,
"119.60",13.13,19.98233,
"119.80",13.149,20.01533,
"120.00",13.166,20.04867,
"120.20",13.177,20.08233,
"120.40",13.194,20.11533,
"120.60",13.211,20.149,
"120.80",13.226,20.182,
"121.00",13.242,20.21567,
"121.20",13.257,20.24867,
"121.40",13.268,20.282,
"121.60",13.286,20.31533,
"121.80",13.3,20.34867,
"122.00",13.319,20.382,
"122.20",13.335,20.41533,
"122.40",13.349,20.44867,
"122.60",13.367,20.482,
"122.80",13.386,20.51533,
"123.00",13.398,20.54867,
"123.20",13.417,20.582,
"123.40",13.43,20.615,
"123.60",13.446,20.64833,
"123.80",13.464,20.68167,
"124.00",13.479,20.71533,
"124.20",13.493,20.74867,
"124.40",13.506,20.782,
"124.60",13.518,20.81533,
"124.80",13.537,20.84867,
"125.00",13.555,20.882,
"125.20",13.57,20.91533,
"125.40",13.579,20.94867,
"125.60",13.593,20.982,
"125.80",13.612,21.01533,
"126.00",13.628,21.04867,
"126.20",13.64,21.082,
"126.40",13.653,21.11533,
"126.60",13.666,21.14867,
"126.80",13.682,21.182,
"127.00",13.694,21.21533,
"127.20",13.709,21.24867,
"127.40",13.716,21.282,
"127.60",13.728,21.31533,
"127.80",13.745,21.34867,
"128.00",13.759,21.382,
"128.20",13.768,21.41533,
"128.40",13.781,21.44867,
"128.60",13.794,21.482,
"128.80",13.81,21.51533,
"129.00",13.823,21.54867,
"129.20",13.834,21.58233,
"129.40",13.844,21.61533,
"129.60",13.86,21.649,
"129.80",13.875,21.682,
"130.00",13.889,21.71533,
"130.20",13.899,21.74867,
"130.40",13.911,21.782,
"130.60",13.923,21.81567,
"130.80",13.939,21.84867,
"131.00",13.949,21.882,
"131.20",13.963,21.91567,
"131.40",13.971,21.94867,
"131.60",13.982,21.982,
"131.80",13.998,22.01533,
"132.00",14.007,22.04867,
"132.20",14.018,22.082,
"132.40",14.03,22.11533,
"132.60",14.041,22.14867,
"132.80",14.055,22.182,
"133.00",14.072,22.21533,
"133.20",14.088,22.24867,
"133.40",14.099,22.282,
"133.60",14.12,22.31567,
"133.80",14.143,22.349,
"134.00",14.158,22.38233,
"134.20",14.174,22.41567,
"134.40",14.192,22.449,
"134.60",14.206,22.48233,
"134.80",14.228,22.51567,
"135.00",14.245,22.549,
"135.20",14.258,22.58233,
"135.40",14.274,22.61567,
"135.60",14.284,22.649,
"135.80",14.3,22.682,
"136.00",14.319,22.71533,
"136.20",14.331,22.74867,
"136.40",14.343,22.782,
"136.60",14.354,22.81533,
"136.80",14.375,22.84867,
"137.00",14.389,22.882,
"137.20",14.405,22.91533,
"137.40",14.422,22.94867,
"137.60",14.434,22.982,
"137.80",14.45,23.01533,
"138.00",14.467,23.04867,
"138.20",14.477,23.082,
"138.40",14.492,23.11533,
"138.60",14.504,23.14867,
"138.80",14.52,23.182,
"139.00",14.533,23.21533,
"139.20",14.544,23.249,
"139.40",14.558,23.28233,
"139.60",14.573,23.31533,
"139.80",14.587,23.34867,
"140.00",14.602,23.382,
"140.20",14.613,23.41533,
"140.40",14.626,23.44867,
"140.60",14.639,23.482,
"140.80",14.659,23.51533,
"141.00",14.672,23.54867,
"141.20",14.687,23.582,
"141.40",14.701,23.61533,
"141.60",14.712,23.64867,
"141.80",14.726,23.682,
"142.00",14.741,23.71533,
"142.20",14.751,23.74867,
"142.40",14.762,23.782,
"142.60",14.772,23.81533,
"142.80",14.788,23.84867,
"143.00",14.796,23.882,
"143.20",14.809,23.91567,
"143.40",14.819,23.94867,
"143.60",14.833,23.98233,
"143.80",14.85,24.01533,
"144.00",14.862,24.04867,
"144.20",14.872,24.082,
"144.40",14.881,24.11533,
"144.60",14.893,24.14867,
"144.80",14.908,24.182,
"145.00",14.923,24.21533,
"145.20",14.937,24.24867,
"145.40",14.946,24.28233,
"145.60",14.959,24.31533,
"145.80",14.973,24.34867,
"146.00",14.989,24.382,
"146.20",15,24.41533,
"146.40",15.012,24.44867,
"146.60",15.023,24.482,
"146.80",15.04,24.51533,
"147.00",15.048,24.54867,
"147.20",15.062,24.58233,
"147.40",15.073,24.61533,
"147.60",15.082,24.64867,
"147.80",15.096,24.68233,
"148.00",15.105,24.71567,
"148.20",15.117,24.749,
"148.40",15.125,24.782,
"148.60",15.137,24.81567,
"148.80",15.152,24.84867,
"149.00",15.167,24.882,
"149.20",15.177,24.91567,
"149.40",15.184,24.949,
"149.60",15.196,24.98233,
"149.80",15.211,25.01533,
"150.00",15.221,25.04867,
"150.20",15.232,25.082,
"150.40",15.241,25.11533,
"150.60",15.251,25.14867,
"150.80",15.263,25.182,
"151.00",15.278,25.21533,
"151.20",15.288,25.24867,
"151.40",15.297,25.282,
"151.60",15.309,25.31533,
"151.80",15.323,25.34867,
"152.00",15.34,25.382,
"152.20",15.35,25.41533,
"152.40",15.367,25.44867,
"152.60",15.383,25.482,
"152.80",15.396,25.51533,
"153.00",15.418,25.54867,
"153.20",15.431,25.58233,
"153.40",15.449,25.61567,
"153.60",15.465,25.649,
"153.80",15.482,25.682,
"154.00",15.497,25.71567,
"154.20",15.508,25.74867,
"154.40",15.523,25.782,
"154.60",15.537,25.81533,
"154.80",15.555,25.84867,
"155.00",15.568,25.882,
"155.20",15.586,25.91533,
"155.40",15.599,25.94867,
"155.60",15.608,25.982,
"155.80",15.625,26.01533,
"156.00",15.639,26.04867,
"156.20",15.649,26.082,
"156.40",15.661,26.11533,
"156.60",15.671,26.14867,
"156.80",15.682,26.182,
"157.00",15.693,26.21533,
"157.20",15.703,26.24867,
"157.40",15.716,26.282,
"157.60",15.724,26.31533,
"157.80",15.738,26.34867,
"158.00",15.748,26.382,
"158.20",15.755,26.41533,
"158.40",15.764,26.44867,
"158.60",15.773,26.482,
"158.80",15.786,26.51533,
"159.00",15.796,26.54867,
"159.20",15.802,26.582,
"159.40",15.805,26.61567,
"159.60",15.815,26.64867,
"159.80",15.827,26.68233,
"160.00",15.836,26.71567,
"160.20",15.841,26.74867,
"160.40",15.849,26.782,
"160.60",15.857,26.81567,
"160.80",15.868,26.84867,
"161.00",15.877,26.882,
"161.20",15.892,26.91567,
"161.40",15.897,26.94867,
"161.60",15.909,26.982,
"161.80",15.919,27.01533,
"162.00",15.935,27.04867,
"162.20",15.946,27.082,
"162.40",15.958,27.11533,
"162.60",15.973,27.14867,
"162.80",15.99,27.182,
"163.00",15.999,27.21567,
"163.20",16.012,27.249,
"163.40",16.025,27.28233,
"163.60",16.039,27.31567,
"163.80",16.051,27.349,
"164.00",16.066,27.38233,
"164.20",16.072,27.41567,
"164.40",16.081,27.449,
"164.60",16.095,27.482,
"164.80",16.11,27.51567,
"165.00",16.123,27.549,
"165.20",16.132,27.58233,
"165.40",16.142,27.61567,
"165.60",16.151,27.649,
"165.80",16.166,27.682,
"166.00",16.177,27.71533,
"166.20",16.188,27.74867,
"166.40",16.197,27.782,
"166.60",16.211,27.81533,
"166.80",16.225,27.84867,
"167.00",16.234,27.882,
"167.20",16.241,27.91533,
"167.40",16.25,27.94867,
"167.60",16.262,27.982,
"167.80",16.273,28.01533,
"168.00",16.281,28.04867,
"168.20",16.293,28.082,
"168.40",16.303,28.11533,
"168.60",16.315,28.149,
"168.80",16.333,28.182,
"169.00",16.34,28.21533,
"169.20",16.348,28.24867,
"169.40",16.353,28.282,
"169.60",16.364,28.31533,
"169.80",16.378,28.34867,
"170.00",16.389,28.382,
"170.20",16.398,28.41533,
"170.40",16.405,28.44867,
"170.60",16.418,28.482,
"170.80",16.435,28.51533,
"171.00",16.45,28.549,
"171.20",16.463,28.58233,
"171.40",16.478,28.61567,
"171.60",16.493,28.649,
"171.80",16.508,28.682,
"172.00",16.522,28.71533,
"172.20",16.534,28.74867,
"172.40",16.549,28.782,
"172.60",16.563,28.81533,
"172.80",16.578,28.84867,
"173.00",16.59,28.88233,
"173.20",16.6,28.91567,
"173.40",16.61,28.949,
"173.60",16.621,28.982,
"173.80",16.636,29.01533,
"174.00",16.644,29.04867,
"174.20",16.654,29.082,
"174.40",16.66,29.11533,
"174.60",16.673,29.14867,
"174.80",16.684,29.182,
"175.00",16.695,29.21533,
"175.20",16.704,29.24867,
"175.40",16.713,29.282,
"175.60",16.723,29.31533,
"175.80",16.734,29.34867,
"176.00",16.744,29.382,
"176.20",16.753,29.41533,
"176.40",16.761,29.44867,
"176.60",16.77,29.482,
"176.80",16.786,29.51533,
"177.00",16.795,29.54867,
"177.20",16.803,29.582,
"177.40",16.816,29.61533,
"177.60",16.826,29.64867,
"177.80",16.846,29.682,
"178.00",16.857,29.71533,
"178.20",16.865,29.74867,
"178.40",16.875,29.782,
"178.60",16.884,29.81533,
"178.80",16.897,29.84867,
"179.00",16.907,29.882,
"179.20",16.914,29.91533,
"179.40",16.922,29.94867,
"179.60",16.929,29.982,
"179.80",16.943,30.01533,
"180.00",16.953,30.04867,
"180.20",16.957,30.082,
"180.40",16.964,30.11533,
"180.60",16.972,30.149,
"180.80",16.98,30.182,
"181.00",16.991,30.21533,
"181.20",17,30.249,
"181.40",17.005,30.282,
"181.60",17.013,30.31567,
"181.80",17.023,30.34867,
"182.00",17.035,30.382,
"182.20",17.045,30.41533,
"182.40",17.052,30.44867,
"182.60",17.065,30.48233,
"182.80",17.081,30.51533,
"183.00",17.089,30.54867,
"183.20",17.1,30.58233,
"183.40",17.111,30.61567,
"183.60",17.124,30.649,
"183.80",17.14,30.682,
"184.00",17.151,30.71533,
"184.20",17.157,30.74867,
"184.40",17.171,30.782,
"184.60",17.18,30.81533,
"184.80",17.198,30.84867,
"185.00",17.211,30.882,
"185.20",17.221,30.91533,
"185.40",17.231,30.94867,
"185.60",17.241,30.982,
"185.80",17.252,31.01533,
"186.00",17.267,31.04867,
"186.20",17.276,31.082,
"186.40",17.284,31.11533,
"186.60",17.291,31.14867,
"186.80",17.307,31.182,
"187.00",17.319,31.21533,
"187.20",17.328,31.24867,
"187.40",17.338,31.282,
"187.60",17.351,31.31533,
"187.80",17.364,31.34867,
"188.00",17.372,31.382,
"188.20",17.379,31.41533,
"188.40",17.39,31.44867,
"188.60",17.398,31.482,
"188.80",17.411,31.51533,
"189.00",17.423,31.54867,
"189.20",17.429,31.582,
"189.40",17.434,31.61533,
"189.60",17.442,31.64867,
"189.80",17.453,31.68233,
"190.00",17.463,31.71533,
"190.20",17.469,31.74867,
"190.40",17.473,31.782,
"190.60",17.48,31.81533,
"190.80",17.489,31.84867,
"191.00",17.499,31.882,
"191.20",17.505,31.91533,
"191.40",17.514,31.94867,
"191.60",17.52,31.982,
"191.80",17.527,32.01534,
"192.00",17.539,32.04867,
"192.20",17.547,32.082,
"192.40",17.552,32.11533,
"192.60",17.563,32.14867,
"192.80",17.57,32.182,
"193.00",17.578,32.21533,
"193.20",17.586,32.24866,
"193.40",17.591,32.282,
"193.60",17.602,32.31533,
"193.80",17.61,32.34867,
"194.00",17.616,32.382,
"194.20",17.621,32.415,
"194.40",17.622,32.44833,
"194.60",17.626,32.48167,
"194.80",17.633,32.51534,
"195.00",17.638,32.54867,
"195.20",17.639,32.582,
"195.40",17.639,32.61533,
"195.60",17.647,32.64867,
"195.80",17.655,32.68167,
"196.00",17.661,32.71533,
"196.20",17.669,32.74866,
"196.40",17.675,32.782,
"196.60",17.679,32.81533,
"196.80",17.686,32.84867,
"197.00",17.695,32.882,
"197.20",17.7,32.91533,
"197.40",17.705,32.94867,
"197.60",17.715,32.982,
"197.80",17.724,33.01534,
"198.00",17.734,33.04867,
"198.20",17.741,33.082,
"198.40",17.746,33.11533,
"198.60",17.759,33.14867,
"198.80",17.769,33.182,
"199.00",17.776,33.21533,
"199.20",17.782,33.249,
"199.40",17.788,33.282,
"199.60",17.799,33.31567,
"199.80",17.81,33.34867,
"200.00",17.82,33.382,
"200.20",17.827,33.41533,
"200.40",17.834,33.44867,
"200.60",17.841,33.482,
"200.80",17.848,33.51534,
"201.00",17.859,33.54867,
"201.20",17.862,33.582,
"201.40",17.869,33.61533,
"201.60",17.876,33.64867,
"201.80",17.886,33.682,
"202.00",17.893,33.71533,
"202.20",17.903,33.74866,
"202.40",17.912,33.782,
"202.60",17.923,33.81533,
"202.80",17.934,33.84867,
"203.00",17.943,33.882,
"203.20",17.949,33.91533,
"203.40",17.959,33.94867,
"203.60",17.97,33.982,
"203.80",17.988,34.01534,
"204.00",17.994,34.04867,
"204.20",18.003,34.082,
"204.40",18.015,34.11533,
"204.60",18.026,34.14867,
"204.80",18.039,34.182,
"205.00",18.054,34.21533,
"205.20",18.065,34.24866,
"205.40",18.073,34.282,
"205.60",18.088,34.31533,
"205.80",18.098,34.34867,
"206.00",18.108,34.382,
"206.20",18.116,34.41533,
"206.40",18.119,34.44867,
"206.60",18.131,34.482,
"206.80",18.141,34.51534,
"207.00",18.149,34.54867,
"207.20",18.157,34.582,
"207.40",18.166,34.61533,
"207.60",18.175,34.64867,
"207.80",18.187,34.682,
"208.00",18.197,34.71533,
"208.20",18.204,34.749,
"208.40",18.214,34.78233,
"208.60",18.223,34.81567,
"208.80",18.232,34.84867,
"209.00",18.242,34.88233,
"209.20",18.249,34.91567,
"209.40",18.254,34.94867,
"209.60",18.265,34.982,
"209.80",18.275,35.01534,
"210.00",18.285,35.04867,
"210.20",18.293,35.082,
"210.40",18.298,35.11533,
"210.60",18.306,35.14867,
"210.80",18.314,35.182,
"211.00",18.329,35.21533,
"211.20",18.336,35.24866,
"211.40",18.342,35.282,
"211.60",18.35,35.31567,
"211.80",18.36,35.34867,
"212.00",18.365,35.38233,
"212.20",18.371,35.41567,
"212.40",18.376,35.449,
"212.60",18.383,35.48233,
"212.80",18.387,35.51534,
"213.00",18.391,35.54867,
"213.20",18.392,35.582,
"213.40",18.394,35.61533,
"213.60",18.403,35.64867,
"213.80",18.412,35.682,
"214.00",18.417,35.71533,
"214.20",18.421,35.74866,
"214.40",18.427,35.782,
"214.60",18.436,35.81533,
"214.80",18.444,35.84867,
"215.00",18.457,35.882,
"215.20",18.459,35.91533,
"215.40",18.466,35.94867,
"215.60",18.472,35.982,
"215.80",18.481,36.01534,
"216.00",18.489,36.04867,
"216.20",18.497,36.082,
"216.40",18.503,36.11533,
"216.60",18.513,36.14867,
"216.80",18.526,36.182,
"217.00",18.54,36.21533,
"217.20",18.547,36.24866,
"217.40",18.556,36.282,
"217.60",18.569,36.31533,
"217.80",18.584,36.34867,
"218.00",18.593,36.382,
"218.20",18.602,36.41533,
"218.40",18.611,36.44867,
"218.60",18.621,36.482,
"218.80",18.632,36.51534,
"219.00",18.644,36.54867,
"219.20",18.648,36.582,
"219.40",18.652,36.61533,
"219.60",18.66,36.64867,
"219.80",18.673,36.682,
"220.00",18.68,36.71533,
"220.20",18.686,36.74866,
"220.40",18.692,36.782,
"220.60",18.696,36.81533,
"220.80",18.708,36.84867,
"221.00",18.717,36.882,
"221.20",18.724,36.91533,
"221.40",18.727,36.94867,
"221.60",18.734,36.982,
"221.80",18.743,37.01534,
"222.00",18.75,37.04867,
"222.20",18.758,37.082,
"222.40",18.761,37.11533,
"222.60",18.766,37.14867,
"222.80",18.771,37.182,
"223.00",18.778,37.21533,
"223.20",18.78,37.24866,
"223.40",18.786,37.282,
"223.60",18.788,37.31533,
"223.80",18.797,37.34867,
"224.00",18.801,37.382,
"224.20",18.8,37.41533,
"224.40",18.799,37.44867,
"224.60",18.802,37.482,
"224.80",18.807,37.51534,
"225.00",18.808,37.54867,
"225.20",18.807,37.582,
"225.40",18.806,37.61533,
"225.60",18.807,37.64867,
"225.80",18.813,37.682,
"226.00",18.819,37.71533,
"226.20",18.824,37.74866,
"226.40",18.828,37.782,
"226.60",18.835,37.81533,
"226.80",18.847,37.84867,
"227.00",18.854,37.882,
"227.20",18.861,37.91533,
"227.40",18.871,37.94867,
"227.60",18.88,37.982,
"227.80",18.895,38.01534,
"228.00",18.906,38.04867,
"228.20",18.912,38.082,
"228.40",18.92,38.11533,
"228.60",18.93,38.14867,
"228.80",18.942,38.182,
"229.00",18.949,38.21533,
"229.20",18.956,38.24866,
"229.40",18.963,38.282,
"229.60",18.973,38.31533,
"229.80",18.988,38.34867,
"230.00",18.996,38.38167,
"230.20",19.009,38.415,
"230.40",19.02,38.44833,
"230.60",19.033,38.482,
"230.80",19.051,38.51534,
"231.00",19.067,38.54867,
"231.20",19.082,38.582,
"231.40",19.092,38.61533,
"231.60",19.101,38.64867,
"231.80",19.116,38.682,
"232.00",19.129,38.71533,
"232.20",19.143,38.74866,
"232.40",19.147,38.782,
"232.60",19.154,38.81533,
"232.80",19.165,38.84833,
"233.00",19.171,38.882,
"233.20",19.176,38.91533,
"233.40",19.183,38.94867,
"233.60",19.191,38.98167,
"233.80",19.201,39.015,
"234.00",19.204,39.04833,
"234.20",19.21,39.082,
"234.40",19.213,39.11533,
"234.60",19.219,39.14867,
"234.80",19.225,39.18167,
"235.00",19.229,39.215,
"235.20",19.229,39.24866,
"235.40",19.233,39.282,
"235.60",19.241,39.315,
"235.80",19.251,39.34833,
"236.00",19.256,39.38167,
"236.20",19.264,39.41533,
"236.40",19.272,39.44867,
"236.60",19.277,39.482,
"236.80",19.287,39.51534,
"237.00",19.295,39.54867,
"237.20",19.303,39.582,
"237.40",19.307,39.61533,
"237.60",19.319,39.64867,
"237.80",19.327,39.682,
"238.00",19.334,39.71533,
"238.20",19.337,39.74866,
"238.40",19.344,39.782,
"238.60",19.349,39.81533,
"238.80",19.36,39.84867,
"239.00",19.365,39.882,
"239.20",19.368,39.91567,
"239.40",19.371,39.94867,
"239.60",19.38,39.982,
"239.80",19.386,40.01534,
"240.00",19.394,40.04867,
"240.20",19.399,40.082,
"240.40",19.402,40.11533,
"240.60",19.412,40.14867,
"240.80",19.421,40.182,
"241.00",19.429,40.21533,
"241.20",19.44,40.249,
"241.40",19.445,40.282,
"241.60",19.454,40.31533,
"241.80",19.462,40.34867,
"242.00",19.47,40.382,
"242.20",19.476,40.41533,
"242.40",19.481,40.44867,
"242.60",19.489,40.482,
"242.80",19.5,40.51534,
"243.00",19.505,40.54867,
"243.20",19.508,40.582,
"243.40",19.511,40.61533,
"243.60",19.516,40.64867,
"243.80",19.525,40.682,
"244.00",19.529,40.71533,
"244.20",19.531,40.74866,
"244.40",19.537,40.782,
"244.60",19.543,40.81533,
"244.80",19.551,40.84833,
"245.00",19.561,40.882,
"245.20",19.569,40.915,
"245.40",19.576,40.94867,
"245.60",19.58,40.98167,
"245.80",19.592,41.015,
"246.00",19.601,41.04833,
"246.20",19.608,41.08167,
"246.40",19.616,41.11533,
"246.60",19.624,41.14867,
"246.80",19.63,41.182,
"247.00",19.638,41.21533,
"247.20",19.642,41.24866,
"247.40",19.648,41.282,
"247.60",19.654,41.31533,
"247.80",19.664,41.34867,
"248.00",19.669,41.382,
"248.20",19.673,41.41533,
"248.40",19.676,41.44867,
"248.60",19.683,41.482,
"248.80",19.693,41.51534,
"249.00",19.698,41.54867,
"249.20",19.698,41.582,
"249.40",19.701,41.61567,
"249.60",19.709,41.649,
"249.80",19.717,41.68233,
"250.00",19.721,41.71567,
"250.20",19.724,41.749,
"250.40",19.726,41.782,
"250.60",19.728,41.81567,
"250.80",19.731,41.84867,
"251.00",19.733,41.882,
"251.15",19.73,41.907,