File: exposed_flourocarbon_10cm_10mmpm_12nm_250esh_5.csv
"Test Name","Test Mode","Test Type","Control","Test Speed 1","Test Speed 2","Test Speed 3","Change Point 1","Change Point 2","Disp. Origin","Break and Limit Action","Sensitivity:","Level:"
"","Single","Tensile","Stroke",10,1,1,"Off","Off","Start","Stop",0,1

"Title","Sub title","Comment"
"","",""

"Shape:","Batch Size:","SubBatch Size:"
"Plate",1,1
"Name:","Thickness","Width","Gauge Length",
"Size Unit:","mm","mm","mm",
" 1 - 1","1.0000","1.0000","100.0000",

"Name",
"Parameter",
"Units",
" 1 - 1",

" 1- 1"
"Time","Force","Stroke",
"sec","N","mm",
"0.00",-.003,0,
"0.15",0,.028,
"0.30",.023,.056,
"0.45",.05,8.366667E-02,
"0.60",.076,.1116667,
"0.75",.103,.1393333,
"0.90",.13,.1673333,
"1.05",.158,.195,
"1.20",.184,.2226667,
"1.35",.21,.2506667,
"1.50",.238,.2783333,
"1.65",.266,.306,
"1.80",.291,.334,
"1.95",.316,.3616666,
"2.10",.343,.3886667,
"2.25",.367,.4156667,
"2.40",.392,.4423333,
"2.55",.417,.4686667,
"2.70",.444,.495,
"2.85",.47,.521,
"3.00",.492,.5466667,
"3.15",.515,.5726667,
"3.30",.539,.5983334,
"3.45",.562,.6236667,
"3.60",.584,.6493334,
"3.75",.608,.6746667,
"3.90",.631,.7,
"4.05",.651,.7253333,
"4.20",.671,.7503334,
"4.35",.697,.7756667,
"4.50",.719,.801,
"4.65",.741,.826,
"4.80",.76,.851,
"4.95",.783,.8763334,
"5.10",.804,.9013333,
"5.25",.823,.9266667,
"5.40",.843,.9516667,
"5.55",.866,.9766667,
"5.70",.884,1.001667,
"5.85",.905,1.026667,
"6.00",.925,1.051667,
"6.15",.944,1.077,
"6.30",.965,1.102,
"6.45",.984,1.127,
"6.60",1.001,1.152,
"6.75",1.023,1.177,
"6.90",1.04,1.202,
"7.05",1.059,1.227,
"7.20",1.076,1.252,
"7.35",1.093,1.277,
"7.50",1.113,1.302,
"7.65",1.133,1.327,
"7.80",1.151,1.352,
"7.95",1.167,1.377,
"8.10",1.183,1.402,
"8.25",1.199,1.427,
"8.40",1.218,1.452,
"8.55",1.235,1.477,
"8.70",1.254,1.502,
"8.85",1.271,1.527,
"9.00",1.287,1.552,
"9.15",1.303,1.577,
"9.30",1.321,1.602,
"9.45",1.335,1.626667,
"9.60",1.353,1.651667,
"9.75",1.368,1.677,
"9.90",1.381,1.702,
"10.05",1.397,1.727,
"10.20",1.414,1.752,
"10.35",1.428,1.777,
"10.50",1.446,1.802,
"10.65",1.463,1.827,
"10.80",1.477,1.852,
"10.95",1.493,1.877,
"11.10",1.506,1.901667,
"11.25",1.521,1.926667,
"11.40",1.536,1.952,
"11.55",1.551,1.977,
"11.70",1.569,2.002,
"11.85",1.582,2.026667,
"12.00",1.597,2.051667,
"12.15",1.61,2.076667,
"12.30",1.624,2.101667,
"12.45",1.638,2.127,
"12.60",1.653,2.152,
"12.75",1.671,2.177,
"12.90",1.686,2.202,
"13.05",1.695,2.227,
"13.20",1.712,2.252,
"13.35",1.729,2.277,
"13.50",1.74,2.302,
"13.65",1.756,2.327,
"13.80",1.769,2.352,
"13.95",1.781,2.377,
"14.10",1.794,2.401667,
"14.25",1.809,2.427,
"14.40",1.825,2.451667,
"14.55",1.837,2.476667,
"14.70",1.852,2.501667,
"14.85",1.866,2.527,
"15.00",1.88,2.552,
"15.15",1.895,2.576667,
"15.30",1.91,2.602,
"15.45",1.923,2.627,
"15.60",1.937,2.652,
"15.75",1.953,2.677,
"15.90",1.963,2.702,
"16.05",1.978,2.727,
"16.20",1.989,2.752,
"16.35",2.003,2.777,
"16.50",2.017,2.801667,
"16.65",2.032,2.826667,
"16.80",2.047,2.851667,
"16.95",2.059,2.876667,
"17.10",2.074,2.901667,
"17.25",2.086,2.926667,
"17.40",2.1,2.951667,
"17.55",2.112,2.976667,
"17.70",2.127,3.001667,
"17.85",2.142,3.026667,
"18.00",2.157,3.051667,
"18.15",2.168,3.077,
"18.30",2.183,3.102,
"18.45",2.198,3.127,
"18.60",2.213,3.151667,
"18.75",2.225,3.176667,
"18.90",2.24,3.201667,
"19.05",2.251,3.227,
"19.20",2.265,3.252,
"19.35",2.282,3.277,
"19.50",2.295,3.301667,
"19.65",2.307,3.326667,
"19.80",2.322,3.352,
"19.95",2.335,3.377,
"20.10",2.349,3.401667,
"20.25",2.362,3.427,
"20.40",2.373,3.451667,
"20.55",2.39,3.476667,
"20.70",2.403,3.501667,
"20.85",2.415,3.527,
"21.00",2.429,3.552,
"21.15",2.443,3.576667,
"21.30",2.456,3.602,
"21.45",2.47,3.627,
"21.60",2.485,3.652,
"21.75",2.499,3.677,
"21.90",2.514,3.702,
"22.05",2.526,3.727,
"22.20",2.541,3.752,
"22.35",2.554,3.777,
"22.50",2.568,3.802,
"22.65",2.583,3.827,
"22.80",2.595,3.852,
"22.95",2.61,3.877,
"23.10",2.625,3.902,
"23.25",2.639,3.927,
"23.40",2.652,3.952,
"23.55",2.666,3.977,
"23.70",2.682,4.002,
"23.85",2.697,4.027,
"24.00",2.651,4.052,
"24.15",2.584,4.077,
"24.30",2.596,4.102,
"24.45",2.609,4.127,
"24.60",2.626,4.152,
"24.75",2.641,4.177,
"24.90",2.656,4.202,
"25.05",2.674,4.226666,
"25.20",2.69,4.251667,
"25.35",2.708,4.277,
"25.50",2.723,4.301666,
"25.65",2.739,4.327,
"25.80",2.752,4.352,
"25.95",2.769,4.377,
"26.10",2.784,4.402,
"26.25",2.795,4.427,
"26.40",2.811,4.452,
"26.55",2.828,4.477,
"26.70",2.842,4.502,
"26.85",2.856,4.527,
"27.00",2.871,4.552,
"27.15",2.883,4.577,
"27.30",2.898,4.602,
"27.45",2.914,4.627,
"27.60",2.928,4.652,
"27.75",2.943,4.677,
"27.90",2.958,4.702,
"28.05",2.973,4.727,
"28.20",2.987,4.752,
"28.35",2.998,4.777,
"28.50",3.012,4.801666,
"28.65",3.027,4.826666,
"28.80",3.043,4.852,
"28.95",3.059,4.877,
"29.10",3.072,4.902,
"29.25",3.086,4.927,
"29.40",3.099,4.951666,
"29.55",3.112,4.976666,
"29.70",3.128,5.001667,
"29.85",3.145,5.026667,
"30.00",3.157,5.052,
"30.15",3.171,5.077,
"30.30",3.185,5.102,
"30.45",3.198,5.127,
"30.60",3.215,5.152,
"30.75",3.228,5.177,
"30.90",3.241,5.202,
"31.05",3.255,5.227,
"31.20",3.268,5.252,
"31.35",3.282,5.277,
"31.50",3.298,5.302,
"31.65",3.314,5.327,
"31.80",3.328,5.352,
"31.95",3.339,5.377,
"32.10",3.351,5.402,
"32.25",3.365,5.427,
"32.40",3.38,5.452,
"32.55",3.392,5.477,
"32.70",3.404,5.502,
"32.85",3.416,5.527,
"33.00",3.428,5.552,
"33.15",3.442,5.577,
"33.30",3.457,5.602,
"33.45",3.47,5.627,
"33.60",3.484,5.652,
"33.75",3.499,5.677,
"33.90",3.512,5.702,
"34.05",3.524,5.727,
"34.20",3.534,5.752,
"34.35",3.533,5.777,
"34.50",3.535,5.802,
"34.65",3.553,5.827,
"34.80",3.57,5.852,
"34.95",3.587,5.877,
"35.10",3.604,5.902,
"35.25",3.621,5.927,
"35.40",3.633,5.952,
"35.55",3.65,5.977,
"35.70",3.669,6.002,
"35.85",3.682,6.027,
"36.00",3.697,6.052,
"36.15",3.709,6.077,
"36.30",3.72,6.102,
"36.45",3.734,6.127,
"36.60",3.751,6.151667,
"36.75",3.766,6.177,
"36.90",3.781,6.202,
"37.05",3.796,6.226666,
"37.20",3.809,6.251667,
"37.35",3.824,6.277,
"37.50",3.839,6.301666,
"37.65",3.853,6.327,
"37.80",3.868,6.352,
"37.95",3.886,6.377,
"38.10",3.898,6.402,
"38.25",3.915,6.427,
"38.40",3.932,6.452,
"38.55",3.945,6.477,
"38.70",3.962,6.502,
"38.85",3.978,6.527,
"39.00",3.993,6.552,
"39.15",4.01,6.577,
"39.30",4.025,6.602,
"39.45",4.044,6.627,
"39.60",4.058,6.651667,
"39.75",4.074,6.676666,
"39.90",4.09,6.701666,
"40.05",4.105,6.726666,
"40.20",4.122,6.752,
"40.35",4.141,6.776667,
"40.50",4.155,6.802,
"40.65",4.169,6.827,
"40.80",4.182,6.852,
"40.95",4.197,6.877,
"41.10",4.211,6.902,
"41.25",4.23,6.927,
"41.40",4.247,6.951666,
"41.55",4.263,6.976666,
"41.70",4.278,7.002,
"41.85",4.294,7.027,
"42.00",4.311,7.052,
"42.15",4.326,7.077,
"42.30",4.342,7.102,
"42.45",4.358,7.127,
"42.60",4.377,7.152,
"42.75",4.393,7.177,
"42.90",4.409,7.202,
"43.05",4.424,7.227,
"43.20",4.442,7.252,
"43.35",4.459,7.277,
"43.50",4.477,7.302,
"43.65",4.494,7.327,
"43.80",4.51,7.352,
"43.95",4.528,7.377,
"44.10",4.545,7.402,
"44.25",4.562,7.427,
"44.40",4.579,7.452,
"44.55",4.595,7.477,
"44.70",4.613,7.502,
"44.85",4.63,7.527,
"45.00",4.648,7.552,
"45.15",4.665,7.577,
"45.30",4.683,7.602,
"45.45",4.702,7.627,
"45.60",4.719,7.652,
"45.75",4.735,7.677,
"45.90",4.753,7.702,
"46.05",4.771,7.727,
"46.20",4.788,7.752,
"46.35",4.806,7.777,
"46.50",4.823,7.802,
"46.65",4.842,7.827,
"46.80",4.86,7.852,
"46.95",4.877,7.877,
"47.10",4.894,7.902,
"47.25",4.91,7.927,
"47.40",4.927,7.952,
"47.55",4.945,7.976666,
"47.70",4.966,8.002,
"47.85",4.987,8.026999,
"48.00",5.003,8.052,
"48.15",5.02,8.077,
"48.30",5.035,8.102,
"48.45",5.053,8.127,
"48.60",5.071,8.151999,
"48.75",5.089,8.177,
"48.90",5.106,8.202,
"49.05",5.127,8.227,
"49.20",5.142,8.252,
"49.35",5.162,8.276999,
"49.50",5.18,8.302,
"49.65",5.199,8.327,
"49.80",5.217,8.352,
"49.95",5.234,8.377,
"50.10",5.254,8.401999,
"50.25",5.276,8.427,
"50.40",5.293,8.452,
"50.55",5.31,8.476666,
"50.70",5.327,8.502,
"50.85",5.347,8.526999,
"51.00",5.368,8.552,
"51.15",5.383,8.577,
"51.30",5.407,8.602,
"51.45",5.427,8.627,
"51.60",5.446,8.651999,
"51.75",5.466,8.677,
"51.90",5.484,8.701667,
"52.05",5.502,8.726666,
"52.20",5.519,8.751666,
"52.35",5.538,8.776667,
"52.50",5.559,8.802,
"52.65",5.581,8.827,
"52.80",5.599,8.852,
"52.95",5.62,8.877,
"53.10",5.638,8.901999,
"53.25",5.656,8.927,
"53.40",5.675,8.952,
"53.55",5.698,8.977,
"53.70",5.716,9.002,
"53.85",5.736,9.026999,
"54.00",5.756,9.052,
"54.15",5.776,9.077,
"54.30",5.796,9.102,
"54.45",5.817,9.127,
"54.60",5.839,9.151999,
"54.75",5.86,9.177,
"54.90",5.88,9.202,
"55.05",5.898,9.226666,
"55.20",5.92,9.252,
"55.35",5.938,9.276999,
"55.50",5.962,9.302,
"55.65",5.983,9.326667,
"55.80",6.003,9.352,
"55.95",6.024,9.377,
"56.10",6.041,9.401667,
"56.25",6.065,9.427,
"56.40",6.084,9.451667,
"56.55",6.108,9.476666,
"56.70",6.127,9.502,
"56.85",6.149,9.526667,
"57.00",6.169,9.552,
"57.15",6.189,9.576667,
"57.30",6.21,9.602,
"57.45",6.234,9.627,
"57.60",6.255,9.651999,
"57.75",6.276,9.677,
"57.90",6.296,9.701667,
"58.05",6.317,9.726666,
"58.20",6.338,9.751666,
"58.35",6.357,9.776667,
"58.50",6.378,9.801666,
"58.65",6.402,9.826667,
"58.80",6.423,9.852,
"58.95",6.446,9.877,
"59.10",6.466,9.901999,
"59.25",6.487,9.927,
"59.40",6.51,9.952,
"59.55",6.532,9.977,
"59.70",6.555,10.002,
"59.85",6.576,10.027,
"60.00",6.596,10.052,
"60.15",6.618,10.077,
"60.30",6.642,10.102,
"60.45",6.663,10.127,
"60.60",6.687,10.152,
"60.75",6.709,10.177,
"60.90",6.73,10.202,
"61.05",6.75,10.227,
"61.20",6.772,10.252,
"61.35",6.791,10.277,
"61.50",6.814,10.302,
"61.65",6.838,10.327,
"61.80",6.86,10.35233,
"61.95",6.883,10.377,
"62.10",6.904,10.402,
"62.25",6.926,10.42733,
"62.40",6.952,10.45233,
"62.55",6.974,10.477,
"62.70",6.993,10.50233,
"62.85",7.015,10.527,
"63.00",7.038,10.552,
"63.15",7.059,10.577,
"63.30",7.082,10.602,
"63.45",7.106,10.627,
"63.60",7.127,10.652,
"63.75",7.15,10.677,
"63.90",7.171,10.702,
"64.05",7.195,10.72667,
"64.20",7.217,10.752,
"64.35",7.24,10.77667,
"64.50",7.263,10.80167,
"64.65",7.287,10.82667,
"64.80",7.306,10.85167,
"64.95",7.33,10.877,
"65.10",7.356,10.902,
"65.25",7.379,10.927,
"65.40",7.402,10.952,
"65.55",7.426,10.977,
"65.70",7.447,11.002,
"65.85",7.471,11.027,
"66.00",7.494,11.052,
"66.15",7.519,11.077,
"66.30",7.542,11.102,
"66.45",7.567,11.127,
"66.60",7.592,11.152,
"66.75",7.618,11.177,
"66.90",7.641,11.202,
"67.05",7.661,11.227,
"67.20",7.685,11.252,
"67.35",7.708,11.277,
"67.50",7.733,11.302,
"67.65",7.76,11.327,
"67.80",7.786,11.352,
"67.95",7.808,11.377,
"68.10",7.832,11.402,
"68.25",7.856,11.427,
"68.40",7.88,11.452,
"68.55",7.904,11.477,
"68.70",7.93,11.502,
"68.85",7.955,11.527,
"69.00",7.979,11.552,
"69.15",8.003,11.577,
"69.30",8.024,11.602,
"69.45",8.049,11.627,
"69.60",8.075,11.652,
"69.75",8.101,11.677,
"69.90",8.126,11.702,
"70.05",8.151,11.727,
"70.20",8.175,11.752,
"70.35",8.201,11.777,
"70.50",8.228,11.802,
"70.65",8.253,11.827,
"70.80",8.279,11.852,
"70.95",8.302,11.877,
"71.10",8.326,11.90167,
"71.25",8.353,11.927,
"71.40",8.378,11.952,
"71.55",8.405,11.97667,
"71.70",8.433,12.00167,
"71.85",8.458,12.02667,
"72.00",8.483,12.052,
"72.15",8.507,12.077,
"72.30",8.533,12.102,
"72.45",8.56,12.127,
"72.60",8.588,12.15167,
"72.75",8.614,12.17667,
"72.90",8.638,12.20167,
"73.05",8.662,12.227,
"73.20",8.688,12.25167,
"73.35",8.715,12.27667,
"73.50",8.741,12.30167,
"73.65",8.771,12.32667,
"73.80",8.799,12.35167,
"73.95",8.823,12.377,
"74.10",8.848,12.402,
"74.25",8.875,12.427,
"74.40",8.9,12.452,
"74.55",8.926,12.47667,
"74.70",8.952,12.50167,
"74.85",8.979,12.52667,
"75.00",9.004,12.55167,
"75.15",9.031,12.57667,
"75.30",9.059,12.602,
"75.45",9.087,12.627,
"75.60",9.114,12.652,
"75.75",9.138,12.677,
"75.90",9.167,12.702,
"76.05",9.193,12.727,
"76.20",9.22,12.75167,
"76.35",9.248,12.77667,
"76.50",9.277,12.80167,
"76.65",9.303,12.82667,
"76.80",9.331,12.85167,
"76.95",9.355,12.877,
"77.10",9.381,12.90167,
"77.25",9.408,12.92667,
"77.40",9.436,12.95167,
"77.55",9.464,12.97667,
"77.70",9.492,13.00167,
"77.85",9.52,13.02667,
"78.00",9.544,13.05167,
"78.15",9.572,13.077,
"78.30",9.563,13.102,
"78.45",9.552,13.127,
"78.60",9.572,13.152,
"78.75",9.605,13.177,
"78.90",9.636,13.202,
"79.05",9.664,13.22667,
"79.20",9.694,13.25167,
"79.35",9.723,13.277,
"79.50",9.755,13.302,
"79.65",9.76,13.327,
"79.80",9.7,13.352,
"79.95",9.702,13.377,
"80.10",9.73,13.402,
"80.25",9.76,13.427,
"80.40",9.794,13.452,
"80.55",9.83,13.477,
"80.70",9.861,13.502,
"80.85",9.897,13.527,
"81.00",9.927,13.552,
"81.15",9.959,13.577,
"81.30",9.994,13.60167,
"81.45",10.027,13.62667,
"81.60",10.058,13.65167,
"81.75",10.09,13.67667,
"81.90",10.12,13.70167,
"82.05",10.15,13.72667,
"82.20",10.179,13.75167,
"82.35",10.21,13.77667,
"82.50",10.243,13.802,
"82.65",10.275,13.827,
"82.80",10.305,13.852,
"82.95",10.333,13.877,
"83.10",10.362,13.902,
"83.25",10.392,13.927,
"83.40",10.421,13.952,
"83.55",10.451,13.977,
"83.70",10.483,14.002,
"83.85",10.514,14.027,
"84.00",10.546,14.052,
"84.15",10.573,14.077,
"84.30",10.603,14.102,
"84.45",10.636,14.127,
"84.60",10.665,14.15167,
"84.75",10.695,14.177,
"84.90",10.726,14.20167,
"85.05",10.755,14.22667,
"85.20",10.788,14.25167,
"85.35",10.817,14.27667,
"85.50",10.85,14.30167,
"85.65",10.88,14.32667,
"85.80",10.911,14.35167,
"85.95",10.94,14.37667,
"86.10",10.967,14.402,
"86.25",11,14.427,
"86.40",11.034,14.452,
"86.55",11.066,14.477,
"86.70",11.099,14.502,
"86.85",11.129,14.527,
"87.00",11.16,14.552,
"87.15",11.189,14.577,
"87.30",11.22,14.602,
"87.45",11.254,14.627,
"87.60",11.287,14.65167,
"87.75",11.319,14.67667,
"87.90",11.35,14.70167,
"88.05",11.383,14.72667,
"88.20",11.413,14.752,
"88.35",11.446,14.777,
"88.50",11.478,14.802,
"88.65",11.512,14.827,
"88.80",11.543,14.852,
"88.95",11.573,14.877,
"89.10",11.603,14.902,
"89.25",11.636,14.927,
"89.40",11.669,14.952,
"89.55",11.698,14.97667,
"89.70",11.733,15.002,
"89.85",11.768,15.02667,
"90.00",11.799,15.052,
"90.15",11.831,15.077,
"90.30",11.864,15.102,
"90.45",11.897,15.12667,
"90.60",11.93,15.15167,
"90.75",11.964,15.177,
"90.90",11.995,15.202,
"91.05",12.026,15.22667,
"91.20",12.061,15.25167,
"91.35",12.092,15.277,
"91.50",12.125,15.30167,
"91.65",12.16,15.32667,
"91.80",12.193,15.352,
"91.95",12.224,15.377,
"92.10",12.256,15.40167,
"92.25",12.262,15.427,
"92.40",12.265,15.452,
"92.55",12.295,15.47667,
"92.70",12.332,15.502,
"92.85",12.366,15.527,
"93.00",12.397,15.552,
"93.15",12.428,15.57667,
"93.30",12.461,15.602,
"93.45",12.498,15.627,
"93.60",12.532,15.65167,
"93.75",12.567,15.677,
"93.90",12.6,15.70167,
"94.05",12.634,15.727,
"94.20",12.671,15.75167,
"94.35",12.705,15.777,
"94.50",12.743,15.802,
"94.65",12.778,15.827,
"94.80",12.811,15.852,
"94.95",12.845,15.877,
"95.10",12.883,15.90167,
"95.25",12.918,15.927,
"95.40",12.955,15.952,
"95.55",12.992,15.97667,
"95.70",13.03,16.00167,
"95.85",13.062,16.02667,
"96.00",13.097,16.05167,
"96.15",13.132,16.07667,
"96.30",13.168,16.10167,
"96.45",13.205,16.12667,
"96.60",13.242,16.15167,
"96.75",13.277,16.177,
"96.90",13.311,16.20167,
"97.05",13.345,16.22667,
"97.20",13.38,16.25167,
"97.35",13.414,16.27667,
"97.50",13.452,16.30167,
"97.65",13.489,16.32667,
"97.80",13.527,16.35167,
"97.95",13.56,16.377,
"98.10",13.596,16.40167,
"98.25",13.627,16.42667,
"98.40",13.664,16.45167,
"98.55",13.703,16.47667,
"98.70",13.74,16.50167,
"98.85",13.776,16.527,
"99.00",13.811,16.552,
"99.15",13.844,16.577,
"99.30",13.88,16.602,
"99.45",13.916,16.627,
"99.60",13.949,16.652,
"99.75",13.982,16.677,
"99.90",14.017,16.70167,
"100.05",14.052,16.727,
"100.20",14.088,16.752,
"100.35",14.126,16.777,
"100.50",14.163,16.80167,
"100.65",14.197,16.82667,
"100.80",14.232,16.85167,
"100.95",14.265,16.87667,
"101.10",14.3,16.90167,
"101.25",14.335,16.927,
"101.40",14.373,16.952,
"101.55",14.413,16.97667,
"101.70",14.445,17.002,
"101.85",14.48,17.027,
"102.00",14.514,17.052,
"102.15",14.548,17.077,
"102.30",14.584,17.102,
"102.45",14.622,17.127,
"102.60",14.659,17.15167,
"102.75",14.697,17.177,
"102.90",14.735,17.202,
"103.05",14.768,17.22667,
"103.20",14.801,17.25167,
"103.35",14.834,17.27667,
"103.50",14.871,17.30167,
"103.65",14.911,17.32667,
"103.80",14.945,17.35167,
"103.95",14.981,17.37667,
"104.10",15.017,17.40167,
"104.25",15.052,17.427,
"104.40",15.089,17.452,
"104.55",15.125,17.47667,
"104.70",15.16,17.50167,
"104.85",15.196,17.527,
"105.00",15.229,17.552,
"105.15",15.256,17.577,
"105.30",15.286,17.602,
"105.45",15.318,17.627,
"105.60",15.346,17.65167,
"105.75",15.373,17.677,
"105.90",15.404,17.702,
"106.05",15.436,17.727,
"106.20",15.469,17.752,
"106.35",15.506,17.777,
"106.50",15.544,17.80167,
"106.65",15.575,17.82667,
"106.80",15.608,17.85167,
"106.95",15.641,17.877,
"107.10",15.676,17.902,
"107.25",15.713,17.927,
"107.40",15.746,17.952,
"107.55",15.782,17.97667,
"107.70",15.819,18.00167,
"107.85",15.853,18.027,
"108.00",15.89,18.052,
"108.15",15.923,18.077,
"108.30",15.957,18.102,
"108.45",15.991,18.127,
"108.60",16.028,18.15167,
"108.75",16.063,18.17667,
"108.90",16.096,18.20167,
"109.05",16.127,18.22667,
"109.20",16.157,18.252,
"109.35",16.194,18.277,
"109.50",16.225,18.302,
"109.65",16.258,18.32667,
"109.80",16.29,18.352,
"109.95",16.32,18.37667,
"110.10",16.353,18.402,
"110.25",16.384,18.427,
"110.40",16.42,18.452,
"110.55",16.454,18.477,
"110.70",16.483,18.502,
"110.85",16.507,18.527,
"111.00",16.535,18.552,
"111.15",16.566,18.577,
"111.30",16.598,18.60167,
"111.45",16.63,18.62667,
"111.60",16.665,18.65167,
"111.75",16.698,18.67667,
"111.90",16.725,18.70167,
"112.05",16.759,18.72667,
"112.20",16.792,18.75167,
"112.35",16.822,18.77667,
"112.50",16.856,18.80167,
"112.65",16.891,18.82667,
"112.80",16.921,18.85167,
"112.95",16.951,18.87667,
"113.10",16.979,18.90167,
"113.25",17.012,18.92667,
"113.40",17.045,18.95167,
"113.55",17.077,18.97667,
"113.70",17.111,19.002,
"113.85",17.142,19.02667,
"114.00",17.175,19.05167,
"114.15",17.204,19.077,
"114.30",17.237,19.102,
"114.45",17.27,19.127,
"114.60",17.305,19.15167,
"114.75",17.337,19.17667,
"114.90",17.37,19.20167,
"115.05",17.406,19.227,
"115.20",17.438,19.252,
"115.35",17.472,19.277,
"115.50",17.509,19.302,
"115.65",17.544,19.327,
"115.80",17.576,19.352,
"115.95",17.611,19.377,
"116.10",17.643,19.40167,
"116.25",17.677,19.427,
"116.40",17.71,19.45167,
"116.55",17.744,19.47667,
"116.70",17.779,19.502,
"116.85",17.811,19.52667,
"117.00",17.843,19.552,
"117.15",17.876,19.577,
"117.30",17.91,19.602,
"117.45",17.942,19.627,
"117.60",17.973,19.65167,
"117.75",18.006,19.67667,
"117.90",18.036,19.70167,
"118.05",18.064,19.727,
"118.20",18.092,19.75167,
"118.35",18.12,19.777,
"118.50",18.151,19.802,
"118.65",18.183,19.82667,
"118.80",18.208,19.85167,
"118.95",18.223,19.87667,
"119.10",18.238,19.90167,
"119.25",18.261,19.927,
"119.40",18.288,19.952,
"119.55",18.321,19.97667,
"119.70",18.353,20.00167,
"119.85",18.381,20.027,
"120.00",18.417,20.052,
"120.15",18.449,20.077,
"120.30",18.482,20.102,
"120.45",18.514,20.127,
"120.60",18.547,20.15167,
"120.75",18.577,20.177,
"120.90",18.608,20.202,
"121.05",18.639,20.22667,
"121.20",18.669,20.25167,
"121.35",18.702,20.277,
"121.50",18.735,20.30167,
"121.65",18.77,20.327,
"121.80",18.802,20.352,
"121.95",18.83,20.377,
"122.10",18.861,20.402,
"122.25",18.891,20.427,
"122.40",18.923,20.452,
"122.55",18.958,20.477,
"122.70",18.99,20.502,
"122.85",19.021,20.527,
"123.00",19.049,20.55167,
"123.15",19.078,20.57667,
"123.30",19.105,20.60167,
"123.45",19.13,20.62667,
"123.60",19.15,20.65167,
"123.75",19.172,20.677,
"123.90",19.193,20.702,
"124.05",19.216,20.727,
"124.20",19.24,20.752,
"124.35",19.263,20.777,
"124.50",19.293,20.802,
"124.65",19.323,20.82667,
"124.80",19.351,20.85167,
"124.95",19.377,20.87667,
"125.10",19.407,20.90167,
"125.25",19.435,20.927,
"125.40",19.468,20.952,
"125.55",19.499,20.977,
"125.70",19.53,21.002,
"125.85",19.559,21.027,
"126.00",19.591,21.052,
"126.15",19.62,21.077,
"126.30",19.647,21.102,
"126.45",19.677,21.127,
"126.60",19.709,21.152,
"126.75",19.735,21.177,
"126.90",19.762,21.202,
"127.05",19.789,21.227,
"127.20",19.818,21.252,
"127.35",19.843,21.277,
"127.50",19.873,21.302,
"127.65",19.904,21.327,
"127.80",19.932,21.352,
"127.95",19.96,21.377,
"128.10",19.986,21.40167,
"128.25",20.011,21.427,
"128.40",20.034,21.452,
"128.55",20.064,21.47667,
"128.70",20.093,21.502,
"128.85",20.12,21.527,
"129.00",20.144,21.552,
"129.15",20.168,21.57667,
"129.30",20.195,21.60167,
"129.45",20.221,21.627,
"129.60",20.249,21.652,
"129.75",20.274,21.677,
"129.90",20.299,21.702,
"130.05",20.324,21.727,
"130.20",20.347,21.752,
"130.35",20.374,21.777,
"130.50",20.401,21.802,
"130.65",20.429,21.827,
"130.80",20.456,21.852,
"130.95",20.477,21.877,
"131.10",20.504,21.90167,
"131.25",20.531,21.927,
"131.40",20.559,21.952,
"131.55",20.588,21.977,
"131.70",20.612,22.002,
"131.85",20.634,22.027,
"132.00",20.656,22.052,
"132.15",20.677,22.077,
"132.30",20.697,22.102,
"132.45",20.723,22.127,
"132.60",20.75,22.15167,
"132.75",20.772,22.177,
"132.90",20.793,22.20167,
"133.05",20.813,22.22667,
"133.20",20.833,22.25167,
"133.35",20.859,22.277,
"133.50",20.882,22.302,
"133.65",20.903,22.327,
"133.80",20.924,22.352,
"133.95",20.948,22.377,
"134.10",20.968,22.40167,
"134.25",20.991,22.427,
"134.40",21.018,22.45167,
"134.55",21.045,22.47667,
"134.70",21.068,22.50167,
"134.85",21.09,22.52667,
"135.00",21.114,22.55167,
"135.15",21.137,22.57667,
"135.30",21.161,22.602,
"135.45",21.184,22.627,
"135.60",21.21,22.652,
"135.75",21.234,22.677,
"135.90",21.256,22.702,
"136.05",21.276,22.727,
"136.20",21.301,22.752,
"136.35",21.325,22.777,
"136.50",21.346,22.80167,
"136.65",21.37,22.82667,
"136.80",21.392,22.852,
"136.95",21.412,22.877,
"137.10",21.434,22.90167,
"137.25",21.455,22.927,
"137.40",21.474,22.952,
"137.55",21.5,22.977,
"137.70",21.525,23.00167,
"137.85",21.544,23.02667,
"138.00",21.56,23.05167,
"138.15",21.582,23.07667,
"138.30",21.601,23.10167,
"138.45",21.624,23.12667,
"138.60",21.645,23.15167,
"138.75",21.668,23.177,
"138.90",21.689,23.20167,
"139.05",21.71,23.22667,
"139.20",21.726,23.25167,
"139.35",21.747,23.277,
"139.50",21.77,23.302,
"139.65",21.792,23.327,
"139.80",21.812,23.352,
"139.95",21.833,23.377,
"140.10",21.85,23.40167,
"140.25",21.872,23.427,
"140.40",21.891,23.452,
"140.55",21.917,23.47667,
"140.70",21.936,23.502,
"140.85",21.957,23.527,
"141.00",21.975,23.552,
"141.15",21.993,23.57667,
"141.30",22.015,23.60167,
"141.45",22.037,23.627,
"141.60",22.061,23.65167,
"141.75",22.083,23.677,
"141.90",22.103,23.70167,
"142.05",22.121,23.727,
"142.20",22.142,23.752,
"142.35",22.161,23.777,
"142.50",22.184,23.802,
"142.65",22.21,23.827,
"142.80",22.231,23.852,
"142.95",22.252,23.877,
"143.10",22.268,23.902,
"143.25",22.288,23.927,
"143.40",22.305,23.95167,
"143.55",22.326,23.97667,
"143.70",22.348,24.002,
"143.85",22.371,24.027,
"144.00",22.389,24.052,
"144.15",22.407,24.07667,
"144.30",22.424,24.102,
"144.45",22.442,24.127,
"144.60",22.463,24.15167,
"144.75",22.484,24.177,
"144.90",22.505,24.202,
"145.05",22.524,24.227,
"145.20",22.541,24.252,
"145.35",22.561,24.277,
"145.50",22.58,24.30167,
"145.65",22.6,24.327,
"145.80",22.618,24.352,
"145.95",22.634,24.377,
"146.10",22.648,24.402,
"146.25",22.668,24.427,
"146.40",22.688,24.452,
"146.55",22.712,24.477,
"146.70",22.731,24.502,
"146.85",22.749,24.527,
"147.00",22.764,24.552,
"147.15",22.78,24.577,
"147.30",22.801,24.602,
"147.45",22.824,24.627,
"147.60",22.846,24.652,
"147.75",22.868,24.677,
"147.90",22.888,24.702,
"148.05",22.908,24.727,
"148.20",22.924,24.752,
"148.35",22.939,24.777,
"148.50",22.963,24.802,
"148.65",22.986,24.827,
"148.80",23.007,24.852,
"148.95",23.025,24.877,
"149.10",23.039,24.902,
"149.25",23.058,24.927,
"149.40",23.079,24.95167,
"149.55",23.1,24.97667,
"149.70",23.119,25.002,
"149.85",23.141,25.027,
"150.00",23.159,25.052,
"150.15",23.179,25.07667,
"150.30",23.2,25.10167,
"150.45",23.222,25.127,
"150.60",23.244,25.15167,
"150.75",23.267,25.177,
"150.90",23.285,25.202,
"151.05",23.303,25.227,
"151.20",23.326,25.252,
"151.35",23.348,25.277,
"151.50",23.37,25.302,
"151.65",23.393,25.32667,
"151.80",23.414,25.352,
"151.95",23.435,25.377,
"152.10",23.453,25.40167,
"152.25",23.475,25.427,
"152.40",23.495,25.45167,
"152.55",23.52,25.47667,
"152.70",23.542,25.50167,
"152.85",23.561,25.527,
"153.00",23.584,25.552,
"153.15",23.605,25.577,
"153.30",23.625,25.602,
"153.45",23.649,25.627,
"153.60",23.673,25.65167,
"153.75",23.698,25.677,
"153.90",23.723,25.702,
"154.05",23.743,25.727,
"154.20",23.763,25.752,
"154.35",23.784,25.77667,
"154.50",23.807,25.802,
"154.65",23.83,25.827,
"154.80",23.85,25.852,
"154.95",23.874,25.877,
"155.10",23.898,25.902,
"155.25",23.919,25.927,
"155.40",23.938,25.952,
"155.55",23.962,25.977,
"155.70",23.98,26.002,
"155.85",24,26.027,
"156.00",24.02,26.052,
"156.15",24.04,26.077,
"156.30",24.07,26.102,
"156.45",24.09,26.12667,
"156.60",24.11,26.15167,
"156.75",24.13,26.17667,
"156.90",24.15,26.20167,
"157.05",24.17,26.22667,
"157.20",24.19,26.25167,
"157.35",24.21,26.27667,
"157.50",24.24,26.30167,
"157.65",24.26,26.32667,
"157.80",24.28,26.35167,
"157.95",24.3,26.377,
"158.10",24.32,26.402,
"158.25",24.34,26.427,
"158.40",24.36,26.452,
"158.55",24.38,26.477,
"158.70",24.41,26.502,
"158.85",24.43,26.527,
"159.00",24.45,26.552,
"159.15",24.47,26.577,
"159.30",24.49,26.602,
"159.45",24.51,26.627,
"159.60",24.53,26.65167,
"159.75",24.55,26.67667,
"159.90",24.57,26.70167,
"160.05",24.59,26.72667,
"160.20",24.61,26.75167,
"160.35",24.63,26.77667,
"160.50",24.65,26.80167,
"160.65",24.67,26.82667,
"160.80",24.69,26.85167,
"160.95",24.71,26.87667,
"161.10",24.73,26.90167,
"161.25",24.75,26.927,
"161.40",24.78,26.95167,
"161.55",24.8,26.97667,
"161.70",24.82,27.00167,
"161.85",24.84,27.02667,
"162.00",24.86,27.052,
"162.15",24.87,27.077,
"162.30",24.9,27.102,
"162.45",24.92,27.127,
"162.60",24.94,27.152,
"162.75",24.96,27.177,
"162.90",24.98,27.202,
"163.05",25,27.227,
"163.20",25.01,27.252,
"163.35",25.03,27.277,
"163.50",25.05,27.30167,
"163.65",25.07,27.32667,
"163.80",25.09,27.352,
"163.95",25.12,27.377,
"164.10",25.14,27.402,
"164.25",25.15,27.427,
"164.40",25.17,27.452,
"164.55",25.19,27.477,
"164.70",25.22,27.50167,
"164.85",25.24,27.527,
"165.00",25.26,27.552,
"165.15",25.28,27.577,
"165.30",25.3,27.602,
"165.45",25.32,27.627,
"165.60",25.34,27.652,
"165.75",25.36,27.677,
"165.90",25.39,27.702,
"166.05",25.41,27.727,
"166.20",25.43,27.752,
"166.35",25.45,27.777,
"166.50",25.48,27.802,
"166.65",25.5,27.827,
"166.80",25.52,27.852,
"166.95",25.54,27.877,
"167.10",25.55,27.90167,
"167.25",25.57,27.927,
"167.40",25.6,27.952,
"167.55",25.62,27.97667,
"167.70",25.64,28.002,
"167.85",25.66,28.027,
"168.00",25.68,28.052,
"168.15",25.7,28.077,
"168.30",25.72,28.102,
"168.45",25.74,28.127,
"168.60",25.77,28.152,
"168.75",25.79,28.177,
"168.90",25.81,28.202,
"169.05",25.83,28.227,
"169.20",25.84,28.25167,
"169.35",25.86,28.27667,
"169.50",25.88,28.302,
"169.65",25.9,28.327,
"169.80",25.92,28.352,
"169.95",25.94,28.377,
"170.10",25.96,28.402,
"170.25",25.98,28.427,
"170.40",26,28.452,
"170.55",26.03,28.477,
"170.70",26.05,28.502,
"170.85",26.06,28.527,
"171.00",26.08,28.552,
"171.15",26.1,28.577,
"171.30",26.13,28.602,
"171.45",26.15,28.627,
"171.60",26.17,28.652,
"171.75",26.19,28.677,
"171.90",26.21,28.702,
"172.05",26.22,28.727,
"172.20",26.24,28.752,
"172.35",26.26,28.777,
"172.50",26.28,28.802,
"172.65",26.3,28.827,
"172.80",26.31,28.852,
"172.95",26.33,28.877,
"173.10",26.34,28.902,
"173.25",26.36,28.927,
"173.40",26.38,28.952,
"173.55",26.39,28.97667,
"173.70",26.41,29.002,
"173.85",26.43,29.027,
"174.00",26.45,29.052,
"174.15",26.47,29.077,
"174.30",26.49,29.102,
"174.45",26.51,29.127,
"174.60",26.53,29.152,
"174.75",26.55,29.177,
"174.90",26.57,29.202,
"175.05",26.58,29.227,
"175.20",26.6,29.252,
"175.35",26.63,29.277,
"175.50",26.65,29.302,
"175.65",26.67,29.327,
"175.80",26.69,29.352,
"175.95",26.71,29.377,
"176.10",26.73,29.402,
"176.25",26.75,29.427,
"176.40",26.77,29.452,
"176.55",26.8,29.477,
"176.70",26.82,29.50167,
"176.85",26.84,29.527,
"177.00",26.85,29.552,
"177.15",26.87,29.57667,
"177.30",26.89,29.602,
"177.45",26.91,29.627,
"177.60",26.94,29.65167,
"177.75",26.96,29.677,
"177.90",26.98,29.702,
"178.05",27,29.727,
"178.20",27.01,29.752,
"178.35",27.03,29.777,
"178.50",27.05,29.802,
"178.65",27.07,29.827,
"178.80",27.1,29.852,
"178.95",27.11,29.877,
"179.10",27.13,29.902,
"179.25",27.15,29.927,
"179.40",27.16,29.952,
"179.55",27.18,29.977,
"179.70",27.2,30.002,
"179.85",27.21,30.027,
"180.00",27.23,30.052,
"180.15",27.24,30.077,
"180.30",27.25,30.102,
"180.45",27.27,30.127,
"180.60",27.27,30.15167,
"180.70",27.273,30.16867,