File: exposed_flourocarbon_10cm_10mmpm_12nm_250esh_7.csv
"Test Name","Test Mode","Test Type","Control","Test Speed 1","Test Speed 2","Test Speed 3","Change Point 1","Change Point 2","Disp. Origin","Break and Limit Action","Sensitivity:","Level:"
"","Single","Tensile","Stroke",10,1,1,"Off","Off","Start","Stop",0,1

"Title","Sub title","Comment"
"","",""

"Shape:","Batch Size:","SubBatch Size:"
"Plate",1,1
"Name:","Thickness","Width","Gauge Length",
"Size Unit:","mm","mm","mm",
" 1 - 1","1.0000","1.0000","100.0000",

"Name",
"Parameter",
"Units",
" 1 - 1",

" 1- 1"
"Time","Force","Stroke",
"sec","N","mm",
"0.00",-.001,0,
"0.15",.002,.028,
"0.30",.018,5.566667E-02,
"0.45",.04,8.333334E-02,
"0.60",.068,.111,
"0.75",.093,.139,
"0.90",.119,.1666667,
"1.05",.144,.1946667,
"1.20",.173,.2223333,
"1.35",.199,.25,
"1.50",.222,.278,
"1.65",.247,.3056667,
"1.80",.271,.3333333,
"1.95",.3,.361,
"2.10",.327,.388,
"2.25",.348,.4146667,
"2.40",.372,.4413333,
"2.55",.397,.4676667,
"2.70",.421,.494,
"2.85",.444,.52,
"3.00",.468,.5456667,
"3.15",.491,.5716667,
"3.30",.513,.597,
"3.45",.534,.6226667,
"3.60",.558,.648,
"3.75",.582,.6736667,
"3.90",.603,.699,
"4.05",.626,.724,
"4.20",.645,.7493333,
"4.35",.667,.7746667,
"4.50",.689,.7996666,
"4.65",.708,.825,
"4.80",.732,.85,
"4.95",.751,.875,
"5.10",.769,.9003333,
"5.25",.792,.9253333,
"5.40",.813,.9503334,
"5.55",.831,.9753333,
"5.70",.851,1.000333,
"5.85",.874,1.025333,
"6.00",.893,1.050333,
"6.15",.912,1.075667,
"6.30",.93,1.100667,
"6.45",.951,1.125667,
"6.60",.97,1.150667,
"6.75",.987,1.175667,
"6.90",1.004,1.200667,
"7.05",1.025,1.225667,
"7.20",1.046,1.250667,
"7.35",1.064,1.275667,
"7.50",1.081,1.300667,
"7.65",1.099,1.325667,
"7.80",1.118,1.350333,
"7.95",1.134,1.375667,
"8.10",1.15,1.400667,
"8.25",1.166,1.425667,
"8.40",1.185,1.450667,
"8.55",1.204,1.475667,
"8.70",1.221,1.500667,
"8.85",1.24,1.525667,
"9.00",1.255,1.550333,
"9.15",1.274,1.575667,
"9.30",1.29,1.600667,
"9.45",1.305,1.625667,
"9.60",1.321,1.650667,
"9.75",1.337,1.675667,
"9.90",1.355,1.700667,
"10.05",1.37,1.725667,
"10.20",1.384,1.750667,
"10.35",1.402,1.775667,
"10.50",1.417,1.800667,
"10.65",1.432,1.825667,
"10.80",1.453,1.850667,
"10.95",1.468,1.875667,
"11.10",1.484,1.900667,
"11.25",1.498,1.925667,
"11.40",1.512,1.951,
"11.55",1.528,1.976,
"11.70",1.545,2.000667,
"11.85",1.559,2.025667,
"12.00",1.57,2.050667,
"12.15",1.587,2.075667,
"12.30",1.601,2.100667,
"12.45",1.617,2.125667,
"12.60",1.63,2.151,
"12.75",1.648,2.175667,
"12.90",1.663,2.201,
"13.05",1.678,2.226,
"13.20",1.691,2.251,
"13.35",1.703,2.276,
"13.50",1.717,2.301,
"13.65",1.734,2.326,
"13.80",1.748,2.350667,
"13.95",1.761,2.375667,
"14.10",1.777,2.400667,
"14.25",1.79,2.425667,
"14.40",1.801,2.450667,
"14.55",1.819,2.475667,
"14.70",1.832,2.500667,
"14.85",1.845,2.525667,
"15.00",1.859,2.550667,
"15.15",1.874,2.575667,
"15.30",1.891,2.601,
"15.45",1.902,2.626,
"15.60",1.917,2.651,
"15.75",1.931,2.676,
"15.90",1.945,2.701,
"16.05",1.958,2.726,
"16.20",1.973,2.751,
"16.35",1.987,2.776,
"16.50",2.002,2.801,
"16.65",2.016,2.825667,
"16.80",2.027,2.851,
"16.95",2.041,2.875667,
"17.10",2.054,2.901,
"17.25",2.067,2.926,
"17.40",2.083,2.951,
"17.55",2.096,2.976,
"17.70",2.109,3.001,
"17.85",2.123,3.026,
"18.00",2.134,3.051,
"18.15",2.148,3.076,
"18.30",2.159,3.100667,
"18.45",2.174,3.126,
"18.60",2.187,3.151,
"18.75",2.2,3.175667,
"18.90",2.213,3.201,
"19.05",2.228,3.226,
"19.20",2.241,3.251,
"19.35",2.253,3.276,
"19.50",2.266,3.301,
"19.65",2.28,3.326,
"19.80",2.293,3.350667,
"19.95",2.305,3.375667,
"20.10",2.319,3.400667,
"20.25",2.333,3.426,
"20.40",2.346,3.450667,
"20.55",2.359,3.476,
"20.70",2.374,3.500667,
"20.85",2.387,3.526,
"21.00",2.399,3.551,
"21.15",2.414,3.576,
"21.30",2.426,3.601,
"21.45",2.44,3.626,
"21.60",2.451,3.650667,
"21.75",2.467,3.675667,
"21.90",2.476,3.700667,
"22.05",2.491,3.725667,
"22.20",2.504,3.750667,
"22.35",2.517,3.775667,
"22.50",2.533,3.801,
"22.65",2.544,3.826,
"22.80",2.549,3.850667,
"22.95",2.552,3.875667,
"23.10",2.567,3.900667,
"23.25",2.58,3.925667,
"23.40",2.594,3.950667,
"23.55",2.608,3.975667,
"23.70",2.622,4.000667,
"23.85",2.634,4.025666,
"24.00",2.648,4.050666,
"24.15",2.661,4.076,
"24.30",2.675,4.100667,
"24.45",2.687,4.126,
"24.60",2.702,4.151,
"24.75",2.714,4.176,
"24.90",2.729,4.201,
"25.05",2.742,4.226,
"25.20",2.755,4.251,
"25.35",2.771,4.275666,
"25.50",2.782,4.300666,
"25.65",2.795,4.325666,
"25.80",2.81,4.351,
"25.95",2.822,4.375667,
"26.10",2.837,4.401,
"26.25",2.85,4.426,
"26.40",2.863,4.451,
"26.55",2.876,4.476,
"26.70",2.892,4.501,
"26.85",2.905,4.526,
"27.00",2.918,4.551,
"27.15",2.931,4.576,
"27.30",2.944,4.601,
"27.45",2.957,4.626,
"27.60",2.97,4.650666,
"27.75",2.984,4.676,
"27.90",2.999,4.700666,
"28.05",3.014,4.726,
"28.20",3.026,4.751,
"28.35",3.038,4.776,
"28.50",3.053,4.801,
"28.65",3.067,4.826,
"28.80",3.08,4.851,
"28.95",3.094,4.876,
"29.10",3.106,4.901,
"29.25",3.119,4.926,
"29.40",3.133,4.951,
"29.55",3.147,4.976,
"29.70",3.161,5.000667,
"29.85",3.176,5.025666,
"30.00",3.191,5.051,
"30.15",3.198,5.075666,
"30.30",3.21,5.100667,
"30.45",3.22,5.126,
"30.60",3.231,5.151,
"30.75",3.244,5.176,
"30.90",3.257,5.201,
"31.05",3.268,5.226,
"31.20",3.279,5.251,
"31.35",3.28,5.276,
"31.50",3.288,5.301,
"31.65",3.305,5.326,
"31.80",3.32,5.351,
"31.95",3.334,5.376,
"32.10",3.35,5.401,
"32.25",3.361,5.426,
"32.40",3.374,5.451,
"32.55",3.386,5.476,
"32.70",3.401,5.501,
"32.85",3.413,5.526,
"33.00",3.43,5.551,
"33.15",3.443,5.576,
"33.30",3.459,5.601,
"33.45",3.468,5.626,
"33.60",3.478,5.651,
"33.75",3.492,5.676,
"33.90",3.507,5.701,
"34.05",3.521,5.726,
"34.20",3.535,5.751,
"34.35",3.542,5.776,
"34.50",3.512,5.801,
"34.65",3.442,5.826,
"34.80",3.453,5.850667,
"34.95",3.472,5.875667,
"35.10",3.49,5.900666,
"35.25",3.507,5.926,
"35.40",3.526,5.951,
"35.55",3.541,5.976,
"35.70",3.559,6.001,
"35.85",3.577,6.026,
"36.00",3.588,6.051,
"36.15",3.599,6.076,
"36.30",3.61,6.101,
"36.45",3.619,6.126,
"36.60",3.623,6.151,
"36.75",3.633,6.175666,
"36.90",3.651,6.200666,
"37.05",3.671,6.226,
"37.20",3.69,6.251,
"37.35",3.708,6.276,
"37.50",3.726,6.301,
"37.65",3.743,6.326,
"37.80",3.76,6.351,
"37.95",3.776,6.376,
"38.10",3.793,6.401,
"38.25",3.808,6.426,
"38.40",3.829,6.451,
"38.55",3.846,6.476,
"38.70",3.863,6.501,
"38.85",3.877,6.526,
"39.00",3.896,6.551,
"39.15",3.911,6.576,
"39.30",3.925,6.601,
"39.45",3.94,6.626,
"39.60",3.957,6.651,
"39.75",3.974,6.676,
"39.90",3.993,6.701,
"40.05",4.008,6.726,
"40.20",4.024,6.751,
"40.35",4.039,6.776,
"40.50",4.057,6.800666,
"40.65",4.072,6.826,
"40.80",4.089,6.851,
"40.95",4.106,6.876,
"41.10",4.123,6.901,
"41.25",4.138,6.926,
"41.40",4.153,6.951,
"41.55",4.168,6.975667,
"41.70",4.185,7.000667,
"41.85",4.198,7.026,
"42.00",4.213,7.051,
"42.15",4.231,7.076,
"42.30",4.248,7.100667,
"42.45",4.262,7.126,
"42.60",4.28,7.151,
"42.75",4.293,7.176,
"42.90",4.309,7.201,
"43.05",4.325,7.226,
"43.20",4.341,7.251,
"43.35",4.356,7.276,
"43.50",4.374,7.301,
"43.65",4.39,7.326,
"43.80",4.405,7.351,
"43.95",4.422,7.376,
"44.10",4.439,7.401,
"44.25",4.453,7.426,
"44.40",4.47,7.451,
"44.55",4.486,7.476,
"44.70",4.503,7.501,
"44.85",4.52,7.526,
"45.00",4.538,7.551,
"45.15",4.555,7.576,
"45.30",4.57,7.601,
"45.45",4.587,7.626,
"45.60",4.603,7.651,
"45.75",4.62,7.676,
"45.90",4.636,7.701,
"46.05",4.653,7.726,
"46.20",4.67,7.751,
"46.35",4.684,7.776,
"46.50",4.7,7.801,
"46.65",4.717,7.825666,
"46.80",4.733,7.850667,
"46.95",4.745,7.876,
"47.10",4.765,7.900666,
"47.25",4.783,7.926,
"47.40",4.799,7.951,
"47.55",4.815,7.976,
"47.70",4.832,8.000667,
"47.85",4.848,8.026,
"48.00",4.865,8.050667,
"48.15",4.884,8.075667,
"48.30",4.898,8.100667,
"48.45",4.915,8.125667,
"48.60",4.931,8.150667,
"48.75",4.95,8.175667,
"48.90",4.968,8.201,
"49.05",4.983,8.226,
"49.20",4.999,8.251,
"49.35",5.017,8.276,
"49.50",5.035,8.301001,
"49.65",5.054,8.326,
"49.80",5.071,8.351,
"49.95",5.088,8.376,
"50.10",5.107,8.401,
"50.25",5.123,8.426001,
"50.40",5.139,8.451,
"50.55",5.152,8.476,
"50.70",5.171,8.501,
"50.85",5.19,8.526,
"51.00",5.21,8.550667,
"51.15",5.227,8.576,
"51.30",5.244,8.600667,
"51.45",5.264,8.625667,
"51.60",5.281,8.651,
"51.75",5.301,8.675667,
"51.90",5.32,8.700667,
"52.05",5.336,8.725667,
"52.20",5.352,8.750667,
"52.35",5.37,8.776,
"52.50",5.39,8.801001,
"52.65",5.41,8.826,
"52.80",5.428,8.851,
"52.95",5.448,8.876,
"53.10",5.466,8.901,
"53.25",5.484,8.926001,
"53.40",5.5,8.951,
"53.55",5.522,8.976,
"53.70",5.542,9.000667,
"53.85",5.562,9.026,
"54.00",5.579,9.050667,
"54.15",5.596,9.076,
"54.30",5.613,9.100667,
"54.45",5.633,9.125667,
"54.60",5.65,9.150667,
"54.75",5.672,9.175667,
"54.90",5.692,9.200667,
"55.05",5.711,9.226,
"55.20",5.729,9.251,
"55.35",5.752,9.276,
"55.50",5.769,9.301001,
"55.65",5.79,9.325667,
"55.80",5.809,9.350667,
"55.95",5.828,9.375667,
"56.10",5.847,9.400667,
"56.25",5.868,9.425667,
"56.40",5.884,9.450667,
"56.55",5.905,9.475667,
"56.70",5.927,9.500667,
"56.85",5.946,9.525667,
"57.00",5.966,9.550667,
"57.15",5.986,9.576,
"57.30",6.006,9.601,
"57.45",6.024,9.626,
"57.60",6.043,9.651,
"57.75",6.064,9.676001,
"57.90",6.085,9.701,
"58.05",6.104,9.725667,
"58.20",6.122,9.750667,
"58.35",6.141,9.775667,
"58.50",6.16,9.800667,
"58.65",6.18,9.826,
"58.80",6.2,9.850667,
"58.95",6.222,9.876,
"59.10",6.227,9.901,
"59.25",6.014,9.926001,
"59.40",5.956,9.951,
"59.55",5.982,9.976,
"59.70",6.008,10.00067,
"59.85",6.042,10.02567,
"60.00",6.07,10.05067,
"60.15",6.098,10.07567,
"60.30",6.125,10.101,
"60.45",6.154,10.126,
"60.60",6.18,10.151,
"60.75",6.205,10.176,
"60.90",6.232,10.201,
"61.05",6.259,10.226,
"61.20",6.284,10.251,
"61.35",6.308,10.276,
"61.50",6.33,10.301,
"61.65",6.356,10.326,
"61.80",6.378,10.351,
"61.95",6.402,10.376,
"62.10",6.425,10.401,
"62.25",6.449,10.426,
"62.40",6.471,10.451,
"62.55",6.493,10.476,
"62.70",6.516,10.50067,
"62.85",6.536,10.52567,
"63.00",6.559,10.551,
"63.15",6.582,10.576,
"63.30",6.6,10.601,
"63.45",6.623,10.626,
"63.60",6.645,10.651,
"63.75",6.667,10.67567,
"63.90",6.688,10.70067,
"64.05",6.707,10.72567,
"64.20",6.728,10.75067,
"64.35",6.748,10.77567,
"64.50",6.77,10.80067,
"64.65",6.792,10.826,
"64.80",6.814,10.85067,
"64.95",6.836,10.876,
"65.10",6.859,10.901,
"65.25",6.873,10.926,
"65.40",6.894,10.951,
"65.55",6.916,10.976,
"65.70",6.938,11.001,
"65.85",6.962,11.026,
"66.00",6.98,11.05067,
"66.15",7,11.07567,
"66.30",7.019,11.10067,
"66.45",7.039,11.12567,
"66.60",7.057,11.15067,
"66.75",7.077,11.17567,
"66.90",7.093,11.20067,
"67.05",7.101,11.226,
"67.20",7.101,11.251,
"67.35",7.097,11.27567,
"67.50",6.99,11.301,
"67.65",6.958,11.326,
"67.80",6.97,11.35067,
"67.95",6.987,11.376,
"68.10",7.004,11.40067,
"68.25",7.025,11.426,
"68.40",7.047,11.451,
"68.55",7.071,11.476,
"68.70",7.097,11.501,
"68.85",7.122,11.526,
"69.00",7.143,11.551,
"69.15",7.166,11.576,
"69.30",7.19,11.601,
"69.45",7.216,11.626,
"69.60",7.243,11.651,
"69.75",7.265,11.67567,
"69.90",7.289,11.70067,
"70.05",7.315,11.72567,
"70.20",7.338,11.751,
"70.35",7.36,11.776,
"70.50",7.384,11.801,
"70.65",7.405,11.826,
"70.80",7.428,11.851,
"70.95",7.451,11.876,
"71.10",7.473,11.901,
"71.25",7.492,11.926,
"71.40",7.505,11.951,
"71.55",7.246,11.976,
"71.70",7.009,12.00067,
"71.85",7.027,12.026,
"72.00",7.061,12.05067,
"72.15",7.099,12.076,
"72.30",7.136,12.10067,
"72.45",7.171,12.12567,
"72.60",7.209,12.151,
"72.75",7.247,12.176,
"72.90",7.283,12.201,
"73.05",7.318,12.226,
"73.20",7.35,12.251,
"73.35",7.384,12.276,
"73.50",7.419,12.30067,
"73.65",7.45,12.326,
"73.80",7.485,12.351,
"73.95",7.515,12.376,
"74.10",7.544,12.401,
"74.25",7.573,12.426,
"74.40",7.606,12.45067,
"74.55",7.633,12.47567,
"74.70",7.664,12.501,
"74.85",7.694,12.526,
"75.00",7.721,12.55067,
"75.15",7.747,12.576,
"75.30",7.771,12.601,
"75.45",7.796,12.62567,
"75.60",7.823,12.651,
"75.75",7.848,12.67567,
"75.90",7.875,12.70067,
"76.05",7.903,12.72567,
"76.20",7.927,12.75067,
"76.35",7.952,12.77567,
"76.50",7.976,12.80067,
"76.65",8.002,12.82567,
"76.80",8.024,12.85067,
"76.95",8.049,12.87567,
"77.10",8.072,12.90067,
"77.25",8.098,12.926,
"77.40",8.122,12.951,
"77.55",8.143,12.976,
"77.70",8.169,13.00067,
"77.85",8.192,13.02567,
"78.00",8.214,13.05067,
"78.15",8.236,13.07567,
"78.30",8.259,13.10067,
"78.45",8.28,13.12567,
"78.60",8.307,13.15067,
"78.75",8.33,13.17567,
"78.90",8.354,13.201,
"79.05",8.377,13.22567,
"79.20",8.399,13.25067,
"79.35",8.421,13.27567,
"79.50",8.444,13.30067,
"79.65",8.467,13.32567,
"79.80",8.494,13.35067,
"79.95",8.516,13.37567,
"80.10",8.54,13.40067,
"80.25",8.564,13.42567,
"80.40",8.585,13.45067,
"80.55",8.607,13.47567,
"80.70",8.631,13.50067,
"80.85",8.656,13.52567,
"81.00",8.681,13.55067,
"81.15",8.702,13.576,
"81.30",8.724,13.60067,
"81.45",8.748,13.626,
"81.60",8.772,13.651,
"81.75",8.796,13.676,
"81.90",8.82,13.701,
"82.05",8.844,13.72567,
"82.20",8.868,13.75067,
"82.35",8.889,13.776,
"82.50",8.914,13.801,
"82.65",8.94,13.82567,
"82.80",8.963,13.851,
"82.95",8.986,13.876,
"83.10",9.006,13.901,
"83.25",9.029,13.926,
"83.40",9.055,13.951,
"83.55",9.081,13.976,
"83.70",9.103,14.00067,
"83.85",9.128,14.02567,
"84.00",9.153,14.05067,
"84.15",9.175,14.07567,
"84.30",9.197,14.10067,
"84.45",9.224,14.12567,
"84.60",9.251,14.15067,
"84.75",9.277,14.176,
"84.90",9.302,14.201,
"85.05",9.324,14.226,
"85.20",9.351,14.251,
"85.35",9.376,14.276,
"85.50",9.398,14.301,
"85.65",9.426,14.326,
"85.80",9.454,14.35067,
"85.95",9.478,14.37567,
"86.10",9.501,14.40067,
"86.25",9.523,14.42567,
"86.40",9.547,14.45067,
"86.55",9.571,14.476,
"86.70",9.594,14.501,
"86.85",9.617,14.52567,
"87.00",9.643,14.55067,
"87.15",9.664,14.57567,
"87.30",9.692,14.60067,
"87.45",9.715,14.62567,
"87.60",9.741,14.651,
"87.75",9.769,14.67567,
"87.90",9.793,14.70067,
"88.05",9.817,14.72567,
"88.20",9.841,14.75067,
"88.35",9.865,14.776,
"88.50",9.892,14.801,
"88.65",9.919,14.826,
"88.80",9.943,14.85067,
"88.95",9.966,14.876,
"89.10",9.991,14.90067,
"89.25",10.014,14.926,
"89.40",10.04,14.951,
"89.55",10.066,14.976,
"89.70",10.089,15.00067,
"89.85",10.118,15.026,
"90.00",10.141,15.05067,
"90.15",10.167,15.07567,
"90.30",10.191,15.10067,
"90.45",10.219,15.12567,
"90.60",10.243,15.15067,
"90.75",10.27,15.17567,
"90.90",10.298,15.20067,
"91.05",10.326,15.22567,
"91.20",10.349,15.25067,
"91.35",10.371,15.27567,
"91.50",10.396,15.30067,
"91.65",10.422,15.32567,
"91.80",10.449,15.35067,
"91.95",10.474,15.37567,
"92.10",10.501,15.40067,
"92.25",10.525,15.42567,
"92.40",10.55,15.45067,
"92.55",10.574,15.47567,
"92.70",10.602,15.50067,
"92.85",10.627,15.52567,
"93.00",10.654,15.55067,
"93.15",10.679,15.57567,
"93.30",10.702,15.60067,
"93.45",10.731,15.62567,
"93.60",10.757,15.65067,
"93.75",10.786,15.67567,
"93.90",10.813,15.70067,
"94.05",10.836,15.72567,
"94.20",10.861,15.75067,
"94.35",10.884,15.77567,
"94.50",10.91,15.80067,
"94.65",10.938,15.82567,
"94.80",10.968,15.85067,
"94.95",10.995,15.876,
"95.10",11.018,15.90067,
"95.25",11.046,15.92567,
"95.40",11.07,15.95067,
"95.55",10.851,15.97567,
"95.70",10.482,16.00067,
"95.85",10.489,16.02567,
"96.00",10.527,16.05067,
"96.15",10.571,16.07567,
"96.30",10.615,16.10067,
"96.45",10.659,16.12567,
"96.60",10.705,16.151,
"96.75",10.75,16.17567,
"96.90",10.793,16.201,
"97.05",10.84,16.226,
"97.20",10.882,16.25067,
"97.35",10.922,16.27567,
"97.50",10.967,16.301,
"97.65",11.01,16.32567,
"97.80",11.05,16.35067,
"97.95",11.088,16.37567,
"98.10",11.126,16.40067,
"98.25",11.162,16.42567,
"98.40",11.2,16.45067,
"98.55",11.233,16.47567,
"98.70",11.27,16.50067,
"98.85",11.304,16.52567,
"99.00",11.337,16.55067,
"99.15",11.371,16.57567,
"99.30",11.404,16.60067,
"99.45",11.436,16.62567,
"99.60",11.466,16.65067,
"99.75",11.501,16.67533,
"99.90",11.536,16.70067,
"100.05",11.567,16.72567,
"100.20",11.597,16.75067,
"100.35",11.627,16.77567,
"100.50",11.658,16.80067,
"100.65",11.69,16.82567,
"100.80",11.723,16.85067,
"100.95",11.755,16.87567,
"101.10",11.783,16.90067,
"101.25",11.812,16.92567,
"101.40",11.842,16.95067,
"101.55",11.872,16.97567,
"101.70",11.904,17.00067,
"101.85",11.932,17.02567,
"102.00",11.962,17.05067,
"102.15",11.995,17.07567,
"102.30",12.019,17.10067,
"102.45",12.052,17.12567,
"102.60",12.082,17.15067,
"102.75",12.112,17.17567,
"102.90",12.141,17.201,
"103.05",12.175,17.22567,
"103.20",12.205,17.251,
"103.35",12.233,17.276,
"103.50",12.266,17.301,
"103.65",12.296,17.326,
"103.80",12.328,17.35067,
"103.95",12.358,17.37567,
"104.10",12.386,17.40067,
"104.25",12.416,17.42567,
"104.40",12.447,17.45067,
"104.55",12.477,17.47567,
"104.70",12.511,17.50067,
"104.85",12.544,17.52567,
"105.00",12.574,17.55067,
"105.15",12.604,17.576,
"105.30",12.633,17.601,
"105.45",12.665,17.626,
"105.60",12.697,17.651,
"105.75",12.729,17.67567,
"105.90",12.764,17.70067,
"106.05",12.795,17.72567,
"106.20",12.823,17.75067,
"106.35",12.853,17.77567,
"106.50",12.884,17.80067,
"106.65",12.917,17.82567,
"106.80",12.948,17.85067,
"106.95",12.981,17.87567,
"107.10",13.015,17.901,
"107.25",13.043,17.926,
"107.40",13.075,17.95067,
"107.55",13.109,17.976,
"107.70",13.141,18.00067,
"107.85",13.174,18.02567,
"108.00",13.205,18.05067,
"108.15",13.236,18.07567,
"108.30",13.267,18.10067,
"108.45",13.298,18.12567,
"108.60",13.332,18.15067,
"108.75",13.365,18.17567,
"108.90",13.397,18.20067,
"109.05",13.427,18.226,
"109.20",13.461,18.251,
"109.35",13.487,18.276,
"109.50",13.521,18.301,
"109.65",13.551,18.32567,
"109.80",13.588,18.35067,
"109.95",13.62,18.37567,
"110.10",13.653,18.40067,
"110.25",13.684,18.42567,
"110.40",13.714,18.45067,
"110.55",13.746,18.47567,
"110.70",13.781,18.501,
"110.85",13.814,18.52567,
"111.00",13.848,18.55067,
"111.15",13.879,18.57567,
"111.30",13.908,18.60067,
"111.45",13.941,18.62567,
"111.60",13.971,18.65067,
"111.75",14.006,18.67567,
"111.90",14.037,18.70067,
"112.05",14.069,18.72567,
"112.20",14.102,18.75067,
"112.35",14.135,18.77567,
"112.50",14.168,18.80067,
"112.65",14.202,18.82567,
"112.80",14.236,18.85067,
"112.95",14.27,18.876,
"113.10",14.302,18.90067,
"113.25",14.334,18.926,
"113.40",14.366,18.951,
"113.55",14.403,18.976,
"113.70",14.436,19.00067,
"113.85",14.471,19.02567,
"114.00",14.503,19.05067,
"114.15",14.532,19.07567,
"114.30",14.568,19.10067,
"114.45",14.599,19.12567,
"114.60",14.632,19.151,
"114.75",14.669,19.17567,
"114.90",14.704,19.201,
"115.05",14.736,19.226,
"115.20",14.767,19.251,
"115.35",14.801,19.27567,
"115.50",14.833,19.30067,
"115.65",14.866,19.32567,
"115.80",14.899,19.35067,
"115.95",14.934,19.376,
"116.10",14.966,19.401,
"116.25",14.997,19.426,
"116.40",15.031,19.45067,
"116.55",15.063,19.476,
"116.70",15.098,19.501,
"116.85",15.13,19.52567,
"117.00",15.165,19.551,
"117.15",15.196,19.576,
"117.30",15.228,19.60067,
"117.45",15.262,19.626,
"117.60",15.292,19.651,
"117.75",15.329,19.67567,
"117.90",15.362,19.701,
"118.05",15.394,19.72567,
"118.20",15.425,19.75067,
"118.35",15.458,19.77567,
"118.50",15.494,19.801,
"118.65",15.527,19.826,
"118.80",15.559,19.851,
"118.95",15.593,19.876,
"119.10",15.624,19.901,
"119.25",15.656,19.926,
"119.40",15.686,19.951,
"119.55",15.719,19.976,
"119.70",15.752,20.001,
"119.85",15.786,20.026,
"120.00",15.819,20.051,
"120.15",15.853,20.076,
"120.30",15.882,20.10067,
"120.45",15.912,20.12567,
"120.60",15.941,20.15067,
"120.75",15.975,20.17567,
"120.90",16.005,20.201,
"121.05",16.035,20.226,
"121.20",16.068,20.251,
"121.35",16.097,20.276,
"121.50",16.125,20.301,
"121.65",16.155,20.326,
"121.80",16.186,20.35067,
"121.95",16.215,20.376,
"122.10",16.243,20.40067,
"122.25",16.269,20.426,
"122.40",16.295,20.45067,
"122.55",16.322,20.476,
"122.70",16.35,20.501,
"122.85",16.375,20.526,
"123.00",16.402,20.551,
"123.15",16.424,20.576,
"123.30",16.446,20.601,
"123.45",16.469,20.626,
"123.60",16.492,20.651,
"123.75",16.502,20.67567,
"123.90",16.517,20.70067,
"124.05",16.532,20.726,
"124.20",16.55,20.751,
"124.35",16.57,20.776,
"124.50",16.591,20.801,
"124.65",16.616,20.826,
"124.80",16.641,20.851,
"124.95",16.665,20.876,
"125.10",16.693,20.901,
"125.25",16.716,20.926,
"125.40",16.742,20.951,
"125.55",16.771,20.976,
"125.70",16.8,21.001,
"125.85",16.83,21.02567,
"126.00",16.862,21.05067,
"126.15",16.892,21.076,
"126.30",16.919,21.10067,
"126.45",16.95,21.126,
"126.60",16.978,21.15067,
"126.75",17.012,21.17567,
"126.90",17.044,21.201,
"127.05",17.079,21.226,
"127.20",17.11,21.251,
"127.35",17.139,21.276,
"127.50",17.17,21.301,
"127.65",17.208,21.326,
"127.80",17.24,21.351,
"127.95",17.274,21.376,
"128.10",17.306,21.40067,
"128.25",17.336,21.42567,
"128.40",17.368,21.45067,
"128.55",17.401,21.47567,
"128.70",17.439,21.50067,
"128.85",17.471,21.52567,
"129.00",17.502,21.55067,
"129.15",17.533,21.57567,
"129.30",17.561,21.60067,
"129.45",17.592,21.62567,
"129.60",17.627,21.65067,
"129.75",17.659,21.67567,
"129.90",17.695,21.70067,
"130.05",17.727,21.72567,
"130.20",17.76,21.75067,
"130.35",17.79,21.776,
"130.50",17.82,21.801,
"130.65",17.853,21.826,
"130.80",17.886,21.85067,
"130.95",17.918,21.87567,
"131.10",17.951,21.901,
"131.25",17.981,21.926,
"131.40",18.011,21.951,
"131.55",18.038,21.976,
"131.70",18.07,22.001,
"131.85",18.105,22.026,
"132.00",18.133,22.051,
"132.15",18.161,22.076,
"132.30",18.195,22.101,
"132.45",18.224,22.126,
"132.60",18.253,22.151,
"132.75",18.286,22.17567,
"132.90",18.316,22.201,
"133.05",18.345,22.226,
"133.20",18.374,22.251,
"133.35",18.403,22.276,
"133.50",18.437,22.301,
"133.65",18.466,22.326,
"133.80",18.496,22.351,
"133.95",18.527,22.376,
"134.10",18.555,22.40067,
"134.25",18.584,22.42567,
"134.40",18.611,22.45067,
"134.55",18.639,22.476,
"134.70",18.67,22.50067,
"134.85",18.699,22.526,
"135.00",18.732,22.551,
"135.15",18.759,22.576,
"135.30",18.785,22.601,
"135.45",18.813,22.626,
"135.60",18.843,22.651,
"135.75",18.873,22.67567,
"135.90",18.904,22.70067,
"136.05",18.933,22.72567,
"136.20",18.957,22.75067,
"136.35",18.986,22.77567,
"136.50",19.015,22.80067,
"136.65",19.047,22.826,
"136.80",19.075,22.851,
"136.95",19.107,22.876,
"137.10",19.135,22.901,
"137.25",19.158,22.926,
"137.40",19.185,22.951,
"137.55",19.215,22.976,
"137.70",19.244,23.001,
"137.85",19.274,23.026,
"138.00",19.302,23.051,
"138.15",19.328,23.07567,
"138.30",19.357,23.10067,
"138.45",19.383,23.126,
"138.60",19.411,23.151,
"138.75",19.445,23.176,
"138.90",19.474,23.201,
"139.05",19.497,23.226,
"139.20",19.519,23.251,
"139.35",19.547,23.276,
"139.50",19.576,23.301,
"139.65",19.605,23.326,
"139.80",19.636,23.351,
"139.95",19.663,23.37567,
"140.10",19.69,23.40067,
"140.25",19.718,23.426,
"140.40",19.743,23.451,
"140.55",19.766,23.476,
"140.70",19.795,23.501,
"140.85",19.824,23.526,
"141.00",19.851,23.551,
"141.15",19.878,23.576,
"141.30",19.903,23.601,
"141.45",19.927,23.626,
"141.60",19.951,23.651,
"141.75",19.98,23.67567,
"141.90",20.007,23.701,
"142.05",20.033,23.72567,
"142.20",20.06,23.75067,
"142.35",20.083,23.77567,
"142.50",20.111,23.80067,
"142.65",20.138,23.82567,
"142.80",20.166,23.85067,
"142.95",20.186,23.876,
"143.10",20.207,23.90067,
"143.25",20.226,23.92567,
"143.40",20.245,23.951,
"143.55",20.264,23.97567,
"143.70",20.286,24.00067,
"143.85",20.308,24.02567,
"144.00",20.328,24.05067,
"144.15",20.345,24.07567,
"144.30",20.36,24.10067,
"144.45",20.376,24.12567,
"144.60",20.393,24.15067,
"144.75",20.416,24.17567,
"144.90",20.439,24.201,
"145.05",20.46,24.226,
"145.20",20.481,24.251,
"145.35",20.503,24.276,
"145.50",20.521,24.301,
"145.65",20.543,24.326,
"145.80",20.565,24.35067,
"145.95",20.59,24.37567,
"146.10",20.613,24.401,
"146.25",20.634,24.426,
"146.40",20.653,24.451,
"146.55",20.673,24.476,
"146.70",20.697,24.501,
"146.85",20.715,24.526,
"147.00",20.738,24.551,
"147.15",20.759,24.576,
"147.30",20.78,24.601,
"147.45",20.806,24.626,
"147.60",20.829,24.651,
"147.75",20.852,24.67567,
"147.90",20.87,24.70067,
"148.05",20.892,24.72567,
"148.20",20.915,24.751,
"148.35",20.934,24.77567,
"148.50",20.956,24.80067,
"148.65",20.979,24.82567,
"148.80",21.002,24.85067,
"148.95",21.025,24.876,
"149.10",21.042,24.901,
"149.25",21.056,24.926,
"149.40",21.079,24.95067,
"149.55",21.1,24.97567,
"149.70",21.123,25.00067,
"149.85",21.144,25.026,
"150.00",21.168,25.051,
"150.15",21.189,25.076,
"150.30",21.208,25.10067,
"150.45",21.226,25.126,
"150.60",21.248,25.151,
"150.75",21.272,25.176,
"150.90",21.298,25.201,
"151.05",21.319,25.22567,
"151.20",21.34,25.251,
"151.35",21.357,25.27567,
"151.50",21.378,25.301,
"151.65",21.403,25.326,
"151.80",21.423,25.351,
"151.95",21.445,25.37567,
"152.10",21.466,25.40067,
"152.25",21.482,25.426,
"152.40",21.506,25.451,
"152.55",21.529,25.476,
"152.70",21.552,25.501,
"152.85",21.574,25.526,
"153.00",21.592,25.551,
"153.15",21.61,25.576,
"153.30",21.629,25.601,
"153.45",21.649,25.626,
"153.60",21.673,25.651,
"153.75",21.696,25.676,
"153.90",21.714,25.701,
"154.05",21.732,25.726,
"154.20",21.75,25.751,
"154.35",21.768,25.776,
"154.50",21.787,25.801,
"154.65",21.807,25.826,
"154.80",21.83,25.851,
"154.95",21.851,25.876,
"155.10",21.866,25.901,
"155.25",21.884,25.926,
"155.40",21.902,25.951,
"155.55",21.922,25.976,
"155.70",21.942,26.001,
"155.85",21.963,26.026,
"156.00",21.984,26.051,
"156.15",22.007,26.076,
"156.30",22.021,26.101,
"156.45",22.039,26.126,
"156.60",22.058,26.151,
"156.75",22.076,26.176,
"156.90",22.097,26.201,
"157.05",22.118,26.226,
"157.20",22.133,26.251,
"157.35",22.148,26.276,
"157.50",22.17,26.301,
"157.65",22.188,26.326,
"157.80",22.211,26.351,
"157.95",22.227,26.376,
"158.10",22.242,26.401,
"158.25",22.258,26.426,
"158.40",22.279,26.45067,
"158.55",22.297,26.476,
"158.70",22.32,26.501,
"158.85",22.338,26.52567,
"159.00",22.357,26.551,
"159.15",22.372,26.57567,
"159.30",22.388,26.60067,
"159.45",22.408,26.62567,
"159.60",22.429,26.65067,
"159.75",22.451,26.67567,
"159.90",22.473,26.70067,
"160.05",22.492,26.72567,
"160.20",22.509,26.75067,
"160.35",22.527,26.77567,
"160.50",22.543,26.80067,
"160.65",22.566,26.826,
"160.80",22.589,26.851,
"160.95",22.607,26.876,
"161.10",22.627,26.901,
"161.25",22.647,26.926,
"161.40",22.662,26.951,
"161.55",22.68,26.976,
"161.70",22.699,27.001,
"161.85",22.718,27.02567,
"162.00",22.736,27.051,
"162.15",22.748,27.076,
"162.30",22.764,27.10067,
"162.45",22.776,27.12567,
"162.60",22.792,27.15067,
"162.75",22.807,27.17567,
"162.90",22.822,27.20067,
"163.05",22.83,27.226,
"163.20",22.836,27.251,
"163.35",22.845,27.276,
"163.50",22.849,27.301,
"163.65",22.853,27.326,
"163.80",22.854,27.35067,
"163.95",22.853,27.37567,
"164.10",22.856,27.40067,
"164.25",22.858,27.42567,
"164.40",22.852,27.451,
"164.55",22.853,27.476,
"164.70",22.857,27.501,
"164.85",22.852,27.526,
"165.00",22.844,27.551,
"165.15",22.836,27.576,
"165.30",22.832,27.60067,
"165.45",22.828,27.62567,
"165.60",22.83,27.65067,
"165.75",22.839,27.67567,
"165.90",22.848,27.701,
"166.05",22.856,27.72567,
"166.20",22.865,27.75067,
"166.35",22.877,27.77567,
"166.50",22.888,27.80067,
"166.65",22.904,27.82567,
"166.80",22.926,27.85067,
"166.95",22.94,27.876,
"167.10",22.961,27.90067,
"167.25",22.983,27.926,
"167.40",23.005,27.951,
"167.55",23.027,27.976,
"167.70",23.048,28.00067,
"167.85",23.071,28.02567,
"168.00",23.095,28.051,
"168.15",23.118,28.07567,
"168.30",23.138,28.10067,
"168.45",23.156,28.12567,
"168.60",23.177,28.15067,
"168.75",23.205,28.17567,
"168.90",23.228,28.201,
"169.05",23.247,28.226,
"169.20",23.265,28.251,
"169.35",23.274,28.27567,
"169.50",23.29,28.301,
"169.65",23.307,28.32567,
"169.80",23.325,28.35067,
"169.95",23.343,28.37567,
"170.10",23.357,28.40067,
"170.25",23.372,28.42567,
"170.40",23.385,28.45067,
"170.55",23.402,28.47567,
"170.70",23.418,28.501,
"170.85",23.434,28.52567,
"171.00",23.448,28.55067,
"171.15",23.459,28.57567,
"171.30",23.471,28.60067,
"171.45",23.485,28.62567,
"171.60",23.497,28.651,
"171.75",23.507,28.67567,
"171.90",23.517,28.70067,
"172.05",23.523,28.72567,
"172.20",23.525,28.75067,
"172.35",23.529,28.776,
"172.50",23.534,28.801,
"172.65",23.535,28.826,
"172.80",23.524,28.851,
"172.85",23.518,28.85933,