File: exposed_monofilament_10cm_10mmpm_12nm_250esh_6.csv
"Test Name","Test Mode","Test Type","Control","Test Speed 1","Test Speed 2","Test Speed 3","Change Point 1","Change Point 2","Disp. Origin","Break and Limit Action","Sensitivity:","Level:"
"","Single","Tensile","Stroke",10,1,1,"Off","Off","Start","Stop",0,1

"Title","Sub title","Comment"
"","",""

"Shape:","Batch Size:","SubBatch Size:"
"Plate",1,1
"Name:","Thickness","Width","Gauge Length",
"Size Unit:","mm","mm","mm",
" 1 - 1","1.0000","1.0000","100.0000",

"Name",
"Parameter",
"Units",
" 1 - 1",

" 1- 1"
"Time","Force","Stroke",
"sec","N","mm",
"0.00",-.002,0,
"0.20",0,3.733333E-02,
"0.40",.011,7.433334E-02,
"0.60",.023,.1113333,
"0.80",.037,.1483333,
"1.00",.052,.1853333,
"1.20",.066,.2223333,
"1.40",.078,.2596667,
"1.60",.091,.2966667,
"1.80",.107,.3336667,
"2.00",.121,.3703333,
"2.20",.131,.4063333,
"2.40",.144,.442,
"2.60",.163,.477,
"2.80",.172,.512,
"3.00",.184,.5466667,
"3.20",.196,.581,
"3.40",.21,.615,
"3.60",.222,.649,
"3.80",.236,.6826667,
"4.00",.249,.7166667,
"4.20",.258,.7503333,
"4.40",.271,.7836667,
"4.60",.281,.8173333,
"4.80",.295,.851,
"5.00",.309,.8843333,
"5.20",.322,.918,
"5.40",.334,.9513333,
"5.60",.345,.9846666,
"5.80",.355,1.018,
"6.00",.369,1.051333,
"6.20",.38,1.085,
"6.40",.394,1.118333,
"6.60",.408,1.151667,
"6.80",.418,1.185,
"7.00",.429,1.218333,
"7.20",.439,1.251667,
"7.40",.456,1.285,
"7.60",.468,1.318333,
"7.80",.482,1.351667,
"8.00",.495,1.385,
"8.20",.508,1.418333,
"8.40",.52,1.451667,
"8.60",.53,1.485,
"8.80",.544,1.518,
"9.00",.559,1.551333,
"9.20",.57,1.585,
"9.40",.586,1.618333,
"9.60",.596,1.651333,
"9.80",.61,1.685,
"10.00",.623,1.718,
"10.20",.635,1.751333,
"10.40",.65,1.784667,
"10.60",.661,1.818,
"10.80",.673,1.851667,
"11.00",.688,1.884667,
"11.20",.701,1.918333,
"11.40",.712,1.951667,
"11.60",.726,1.985,
"11.80",.739,2.018333,
"12.00",.754,2.051667,
"12.20",.764,2.085,
"12.40",.779,2.118333,
"12.60",.792,2.151667,
"12.80",.805,2.185,
"13.00",.821,2.218333,
"13.20",.833,2.251667,
"13.40",.845,2.285,
"13.60",.861,2.318333,
"13.80",.876,2.351667,
"14.00",.89,2.385333,
"14.20",.904,2.418667,
"14.40",.915,2.452,
"14.60",.931,2.485,
"14.80",.945,2.518667,
"15.00",.957,2.551667,
"15.20",.97,2.585,
"15.40",.985,2.618333,
"15.60",1,2.651667,
"15.80",1.016,2.685,
"16.00",1.031,2.718333,
"16.20",1.047,2.751667,
"16.40",1.059,2.785,
"16.60",1.074,2.818333,
"16.80",1.088,2.851667,
"17.00",1.105,2.885,
"17.20",1.118,2.918333,
"17.40",1.133,2.951667,
"17.60",1.148,2.985,
"17.80",1.163,3.018333,
"18.00",1.178,3.051667,
"18.20",1.195,3.085,
"18.40",1.208,3.118333,
"18.60",1.224,3.151667,
"18.80",1.241,3.185,
"19.00",1.256,3.218333,
"19.20",1.271,3.251667,
"19.40",1.288,3.285,
"19.60",1.304,3.318333,
"19.80",1.321,3.351667,
"20.00",1.336,3.385,
"20.20",1.35,3.418333,
"20.40",1.369,3.451667,
"20.60",1.385,3.485,
"20.80",1.401,3.518333,
"21.00",1.417,3.551667,
"21.20",1.437,3.585,
"21.40",1.452,3.618667,
"21.60",1.469,3.652,
"21.80",1.49,3.685333,
"22.00",1.506,3.718333,
"22.20",1.523,3.751667,
"22.40",1.537,3.785,
"22.60",1.556,3.818667,
"22.80",1.575,3.852,
"23.00",1.591,3.885,
"23.20",1.61,3.918333,
"23.40",1.628,3.951667,
"23.60",1.645,3.985,
"23.80",1.666,4.018333,
"24.00",1.687,4.051666,
"24.20",1.704,4.085,
"24.40",1.723,4.118333,
"24.60",1.74,4.152,
"24.80",1.763,4.185333,
"25.00",1.78,4.218667,
"25.20",1.799,4.252,
"25.40",1.815,4.285333,
"25.60",1.837,4.318333,
"25.80",1.856,4.351666,
"26.00",1.876,4.385,
"26.20",1.895,4.418333,
"26.40",1.914,4.451666,
"26.60",1.936,4.485,
"26.80",1.956,4.518666,
"27.00",1.979,4.551666,
"27.20",1.998,4.585,
"27.40",2.021,4.618667,
"27.60",2.042,4.651667,
"27.80",2.062,4.685,
"28.00",2.084,4.718333,
"28.20",2.103,4.751667,
"28.40",2.127,4.785,
"28.60",2.148,4.818333,
"28.80",2.171,4.851666,
"29.00",2.192,4.885,
"29.20",2.216,4.918333,
"29.40",2.24,4.951666,
"29.60",2.261,4.985,
"29.80",2.285,5.018333,
"30.00",2.306,5.051666,
"30.20",2.33,5.085,
"30.40",2.354,5.118333,
"30.60",2.376,5.151667,
"30.80",2.398,5.185,
"31.00",2.423,5.218333,
"31.20",2.446,5.251667,
"31.40",2.472,5.285,
"31.60",2.495,5.318333,
"31.80",2.518,5.351666,
"32.00",2.545,5.384666,
"32.20",2.57,5.418,
"32.40",2.596,5.451333,
"32.60",2.621,5.485,
"32.80",2.646,5.518333,
"33.00",2.67,5.551333,
"33.20",2.698,5.585,
"33.40",2.721,5.618333,
"33.60",2.747,5.651667,
"33.80",2.774,5.685,
"34.00",2.8,5.718333,
"34.20",2.825,5.751667,
"34.40",2.851,5.785,
"34.60",2.879,5.818333,
"34.80",2.906,5.851666,
"35.00",2.933,5.885,
"35.20",2.958,5.918333,
"35.40",2.984,5.951666,
"35.60",3.012,5.985,
"35.80",3.038,6.018333,
"36.00",3.07,6.051666,
"36.20",3.094,6.085,
"36.40",3.123,6.118333,
"36.60",3.15,6.151667,
"36.80",3.18,6.185,
"37.00",3.209,6.218333,
"37.20",3.242,6.251667,
"37.40",3.267,6.285,
"37.60",3.295,6.318333,
"37.80",3.32,6.351666,
"38.00",3.347,6.385,
"38.20",3.363,6.418333,
"38.40",3.386,6.451666,
"38.60",3.417,6.485,
"38.80",3.447,6.518333,
"39.00",3.477,6.551666,
"39.20",3.507,6.585,
"39.40",3.535,6.618333,
"39.60",3.564,6.651667,
"39.80",3.592,6.685,
"40.00",3.619,6.718333,
"40.20",3.643,6.751667,
"40.40",3.674,6.785,
"40.60",3.705,6.818333,
"40.80",3.735,6.851666,
"41.00",3.768,6.885,
"41.20",3.797,6.918333,
"41.40",3.832,6.951666,
"41.60",3.861,6.985,
"41.80",3.883,7.018333,
"42.00",3.917,7.051666,
"42.20",3.949,7.085,
"42.40",3.981,7.118333,
"42.60",4.016,7.151333,
"42.80",4.045,7.184667,
"43.00",4.078,7.218,
"43.20",4.111,7.251333,
"43.40",4.148,7.285,
"43.60",4.178,7.318333,
"43.80",4.209,7.351666,
"44.00",4.24,7.385,
"44.20",4.274,7.418333,
"44.40",4.304,7.451666,
"44.60",4.339,7.484666,
"44.80",4.372,7.518333,
"45.00",4.402,7.551666,
"45.20",4.436,7.585,
"45.40",4.468,7.618333,
"45.60",4.498,7.651667,
"45.80",4.529,7.685,
"46.00",4.563,7.718333,
"46.20",4.595,7.751667,
"46.40",4.629,7.785,
"46.60",4.659,7.818333,
"46.80",4.691,7.851666,
"47.00",4.722,7.885,
"47.20",4.755,7.918333,
"47.40",4.787,7.951666,
"47.60",4.819,7.985,
"47.80",4.851,8.018333,
"48.00",4.88,8.051667,
"48.20",4.912,8.085,
"48.40",4.941,8.118334,
"48.60",4.974,8.151667,
"48.80",5.002,8.185333,
"49.00",5.031,8.218333,
"49.20",5.061,8.251667,
"49.40",5.087,8.285,
"49.60",5.114,8.318334,
"49.80",5.143,8.351666,
"50.00",5.171,8.385,
"50.20",5.191,8.418334,
"50.40",5.161,8.451667,
"50.60",5.147,8.485001,
"50.80",5.171,8.518333,
"51.00",5.203,8.551667,
"51.20",5.234,8.585,
"51.40",5.268,8.618667,
"51.60",5.298,8.652,
"51.80",5.331,8.685333,
"52.00",5.363,8.718333,
"52.20",5.396,8.751667,
"52.40",5.426,8.785,
"52.60",5.458,8.818334,
"52.80",5.491,8.851666,
"53.00",5.522,8.885,
"53.20",5.553,8.918334,
"53.40",5.582,8.951667,
"53.60",5.614,8.985001,
"53.80",5.646,9.018333,
"54.00",5.679,9.051667,
"54.20",5.709,9.085,
"54.40",5.74,9.118334,
"54.60",5.767,9.151667,
"54.80",5.8,9.185,
"55.00",5.832,9.218333,
"55.20",5.859,9.251667,
"55.40",5.89,9.285,
"55.60",5.918,9.318334,
"55.80",5.948,9.351666,
"56.00",5.978,9.385,
"56.20",6.008,9.418334,
"56.40",6.037,9.451667,
"56.60",6.065,9.485001,
"56.80",6.094,9.518333,
"57.00",6.124,9.551667,
"57.20",6.153,9.585,
"57.40",6.182,9.618334,
"57.60",6.211,9.651667,
"57.80",6.237,9.685,
"58.00",6.266,9.718333,
"58.20",6.296,9.751667,
"58.40",6.321,9.785,
"58.60",6.35,9.818334,
"58.80",6.379,9.851666,
"59.00",6.41,9.885,
"59.20",6.435,9.918334,
"59.40",6.462,9.951667,
"59.60",6.488,9.985001,
"59.80",6.515,10.018,
"60.00",6.542,10.05133,
"60.20",6.572,10.085,
"60.40",6.601,10.11833,
"60.60",6.627,10.15167,
"60.80",6.653,10.185,
"61.00",6.681,10.218,
"61.20",6.708,10.25133,
"61.40",6.734,10.28467,
"61.60",6.758,10.31833,
"61.80",6.785,10.35167,
"62.00",6.815,10.385,
"62.20",6.841,10.41833,
"62.40",6.869,10.45167,
"62.60",6.893,10.485,
"62.80",6.921,10.51833,
"63.00",6.947,10.55167,
"63.20",6.971,10.585,
"63.40",6.998,10.61833,
"63.60",7.025,10.65167,
"63.80",7.052,10.685,
"64.00",7.08,10.71833,
"64.20",7.105,10.75167,
"64.40",7.133,10.785,
"64.60",7.156,10.81833,
"64.80",7.183,10.85167,
"65.00",7.209,10.885,
"65.20",7.235,10.91833,
"65.40",7.259,10.95167,
"65.60",7.282,10.985,
"65.80",7.307,11.01833,
"66.00",7.334,11.05167,
"66.20",7.361,11.085,
"66.40",7.385,11.11833,
"66.60",7.409,11.15167,
"66.80",7.433,11.185,
"67.00",7.459,11.218,
"67.20",7.485,11.25167,
"67.40",7.51,11.285,
"67.60",7.532,11.31833,
"67.80",7.556,11.35167,
"68.00",7.584,11.385,
"68.20",7.608,11.41833,
"68.40",7.631,11.45167,
"68.60",7.656,11.485,
"68.80",7.682,11.518,
"69.00",7.705,11.55133,
"69.20",7.729,11.58467,
"69.40",7.752,11.618,
"69.60",7.777,11.65167,
"69.80",7.802,11.685,
"70.00",7.825,11.718,
"70.20",7.85,11.75133,
"70.40",7.872,11.78467,
"70.60",7.897,11.818,
"70.80",7.919,11.85133,
"71.00",7.943,11.88467,
"71.20",7.968,11.918,
"71.40",7.992,11.95167,
"71.60",8.016,11.985,
"71.80",8.038,12.01833,
"72.00",8.063,12.05133,
"72.20",8.085,12.08467,
"72.40",8.111,12.118,
"72.60",8.133,12.15133,
"72.80",8.157,12.18467,
"73.00",8.179,12.218,
"73.20",8.203,12.25167,
"73.40",8.226,12.285,
"73.60",8.25,12.31833,
"73.80",8.275,12.35167,
"74.00",8.299,12.385,
"74.20",8.32,12.41833,
"74.40",8.346,12.45167,
"74.60",8.366,12.485,
"74.80",8.389,12.51833,
"75.00",8.412,12.55167,
"75.20",8.435,12.585,
"75.40",8.456,12.61833,
"75.60",8.474,12.65167,
"75.80",8.496,12.685,
"76.00",8.52,12.71833,
"76.20",8.544,12.75167,
"76.40",8.566,12.785,
"76.60",8.585,12.81833,
"76.80",8.61,12.85167,
"77.00",8.631,12.885,
"77.20",8.652,12.91833,
"77.40",8.675,12.95167,
"77.60",8.698,12.985,
"77.80",8.718,13.01833,
"78.00",8.738,13.05167,
"78.20",8.762,13.085,
"78.40",8.78,13.11833,
"78.60",8.8,13.15167,
"78.80",8.822,13.185,
"79.00",8.844,13.21833,
"79.20",8.865,13.25167,
"79.40",8.883,13.285,
"79.60",8.903,13.31833,
"79.80",8.925,13.35167,
"80.00",8.946,13.385,
"80.20",8.965,13.41833,
"80.40",8.985,13.45167,
"80.60",9.004,13.485,
"80.80",9.022,13.51833,
"81.00",9.044,13.55167,
"81.20",9.063,13.585,
"81.40",9.082,13.61833,
"81.60",9.098,13.65167,
"81.80",9.118,13.685,
"82.00",9.14,13.71833,
"82.20",9.159,13.75167,
"82.40",9.18,13.785,
"82.60",9.196,13.81833,
"82.80",9.218,13.85167,
"83.00",9.24,13.885,
"83.20",9.261,13.91833,
"83.40",9.283,13.95167,
"83.60",9.303,13.985,
"83.80",9.323,14.01833,
"84.00",9.346,14.05167,
"84.20",9.365,14.085,
"84.40",9.387,14.11833,
"84.60",9.408,14.15167,
"84.80",9.431,14.185,
"85.00",9.451,14.21833,
"85.20",9.471,14.25167,
"85.40",9.491,14.285,
"85.60",9.51,14.31833,
"85.80",9.532,14.35133,
"86.00",9.551,14.38467,
"86.20",9.573,14.418,
"86.40",9.593,14.45167,
"86.60",9.613,14.485,
"86.80",9.632,14.51833,
"87.00",9.651,14.55167,
"87.20",9.673,14.585,
"87.40",9.692,14.61833,
"87.60",9.709,14.65133,
"87.80",9.728,14.685,
"88.00",9.747,14.71833,
"88.20",9.768,14.75167,
"88.40",9.785,14.785,
"88.60",9.806,14.81833,
"88.80",9.827,14.85167,
"89.00",9.844,14.885,
"89.20",9.863,14.91833,
"89.40",9.878,14.95167,
"89.60",9.897,14.98467,
"89.80",9.918,15.01833,
"90.00",9.937,15.05167,
"90.20",9.957,15.085,
"90.40",9.973,15.11833,
"90.60",9.989,15.15167,
"90.80",10.008,15.185,
"91.00",10.028,15.218,
"91.20",10.048,15.25167,
"91.40",10.066,15.285,
"91.60",10.084,15.31833,
"91.80",10.1,15.35167,
"92.00",10.121,15.385,
"92.20",10.14,15.41833,
"92.40",10.16,15.45167,
"92.60",10.177,15.485,
"92.80",10.195,15.51833,
"93.00",10.216,15.55167,
"93.20",10.236,15.585,
"93.40",10.253,15.61833,
"93.60",10.271,15.65167,
"93.80",10.292,15.685,
"94.00",10.312,15.71833,
"94.20",10.333,15.75167,
"94.40",10.348,15.785,
"94.60",10.368,15.81833,
"94.80",10.389,15.85167,
"95.00",10.409,15.885,
"95.20",10.428,15.91833,
"95.40",10.443,15.95167,
"95.60",10.46,15.985,
"95.80",10.479,16.01833,
"96.00",10.5,16.05167,
"96.20",10.52,16.085,
"96.40",10.537,16.11833,
"96.60",10.554,16.15167,
"96.80",10.573,16.185,
"97.00",10.592,16.21833,
"97.20",10.611,16.25167,
"97.40",10.628,16.285,
"97.60",10.642,16.31833,
"97.80",10.664,16.35167,
"98.00",10.68,16.385,
"98.20",10.7,16.41833,
"98.40",10.718,16.45167,
"98.60",10.737,16.485,
"98.80",10.753,16.51833,
"99.00",10.773,16.55167,
"99.20",10.792,16.585,
"99.40",10.805,16.61833,
"99.60",10.823,16.65167,
"99.80",10.843,16.685,
"100.00",10.861,16.71833,
"100.20",10.879,16.75167,
"100.40",10.896,16.785,
"100.60",10.913,16.81833,
"100.80",10.934,16.85167,
"101.00",10.956,16.885,
"101.20",10.971,16.91833,
"101.40",10.989,16.95167,
"101.60",11.005,16.985,
"101.80",11.023,17.01867,
"102.00",11.043,17.05167,
"102.20",11.061,17.08533,
"102.40",11.076,17.11867,
"102.60",11.097,17.152,
"102.80",11.11,17.18533,
"103.00",11.13,17.21833,
"103.20",11.148,17.25167,
"103.40",11.163,17.285,
"103.60",11.181,17.31867,
"103.80",11.201,17.352,
"104.00",11.22,17.38533,
"104.20",11.235,17.41833,
"104.40",11.252,17.45167,
"104.60",11.268,17.485,
"104.80",11.285,17.51833,
"105.00",11.304,17.55167,
"105.20",11.321,17.585,
"105.40",11.337,17.61833,
"105.60",11.353,17.65167,
"105.80",11.368,17.685,
"106.00",11.386,17.71833,
"106.20",11.403,17.75167,
"106.40",11.415,17.785,
"106.60",11.432,17.81833,
"106.80",11.45,17.85167,
"107.00",11.466,17.885,
"107.20",11.481,17.91833,
"107.40",11.496,17.95167,
"107.60",11.515,17.985,
"107.80",11.53,18.01833,
"108.00",11.545,18.05167,
"108.20",11.563,18.085,
"108.40",11.577,18.11833,
"108.60",11.593,18.15167,
"108.80",11.609,18.185,
"109.00",11.629,18.21833,
"109.20",11.643,18.25167,
"109.40",11.657,18.285,
"109.60",11.673,18.31833,
"109.80",11.691,18.35167,
"110.00",11.707,18.385,
"110.20",11.724,18.41833,
"110.40",11.738,18.45167,
"110.60",11.753,18.485,
"110.80",11.77,18.51833,
"111.00",11.787,18.55167,
"111.20",11.807,18.585,
"111.40",11.822,18.61833,
"111.60",11.834,18.65167,
"111.80",11.849,18.685,
"112.00",11.87,18.71833,
"112.20",11.884,18.75167,
"112.40",11.897,18.785,
"112.60",11.912,18.81833,
"112.80",11.93,18.85167,
"113.00",11.946,18.885,
"113.20",11.961,18.91833,
"113.40",11.975,18.95167,
"113.60",11.991,18.985,
"113.80",12.006,19.01833,
"114.00",12.023,19.05167,
"114.20",12.035,19.085,
"114.40",12.049,19.11833,
"114.60",12.065,19.15167,
"114.80",12.08,19.185,
"115.00",12.097,19.21833,
"115.20",12.111,19.25167,
"115.40",12.125,19.285,
"115.60",12.138,19.31833,
"115.80",12.156,19.35167,
"116.00",12.172,19.385,
"116.20",12.191,19.41833,
"116.40",12.204,19.45167,
"116.60",12.218,19.48533,
"116.80",12.234,19.51867,
"117.00",12.251,19.55167,
"117.20",12.269,19.585,
"117.40",12.281,19.61867,
"117.60",12.297,19.65167,
"117.80",12.313,19.68533,
"118.00",12.325,19.71833,
"118.20",12.342,19.75167,
"118.40",12.358,19.785,
"118.60",12.372,19.81833,
"118.80",12.387,19.85167,
"119.00",12.405,19.885,
"119.20",12.42,19.91833,
"119.40",12.432,19.95167,
"119.60",12.447,19.985,
"119.80",12.465,20.01833,
"120.00",12.482,20.05167,
"120.20",12.497,20.085,
"120.40",12.509,20.11833,
"120.60",12.526,20.15167,
"120.80",12.538,20.185,
"121.00",12.558,20.21833,
"121.20",12.576,20.25167,
"121.40",12.59,20.285,
"121.60",12.605,20.31833,
"121.80",12.62,20.35167,
"122.00",12.641,20.38467,
"122.20",12.655,20.41833,
"122.40",12.671,20.45167,
"122.60",12.685,20.485,
"122.80",12.702,20.51833,
"123.00",12.718,20.55167,
"123.20",12.733,20.585,
"123.40",12.749,20.61833,
"123.60",12.764,20.65167,
"123.80",12.779,20.685,
"124.00",12.796,20.71833,
"124.20",12.812,20.75167,
"124.40",12.825,20.785,
"124.60",12.839,20.818,
"124.80",12.855,20.85167,
"125.00",12.87,20.88467,
"125.20",12.885,20.91833,
"125.40",12.897,20.95167,
"125.60",12.911,20.985,
"125.80",12.927,21.01833,
"126.00",12.943,21.05133,
"126.20",12.959,21.085,
"126.40",12.972,21.11833,
"126.60",12.986,21.15167,
"126.80",12.999,21.185,
"127.00",13.017,21.21833,
"127.20",13.03,21.25167,
"127.40",13.043,21.285,
"127.60",13.057,21.31833,
"127.80",13.068,21.35167,
"128.00",13.087,21.385,
"128.20",13.1,21.41833,
"128.40",13.113,21.45167,
"128.60",13.13,21.485,
"128.80",13.142,21.51833,
"129.00",13.157,21.55167,
"129.20",13.171,21.585,
"129.40",13.182,21.61833,
"129.60",13.196,21.65167,
"129.80",13.212,21.685,
"130.00",13.227,21.71833,
"130.20",13.242,21.75167,
"130.40",13.252,21.785,
"130.60",13.264,21.81833,
"130.80",13.278,21.85167,
"131.00",13.296,21.885,
"131.20",13.309,21.91833,
"131.40",13.322,21.95167,
"131.60",13.332,21.985,
"131.80",13.348,22.01833,
"132.00",13.363,22.05167,
"132.20",13.375,22.085,
"132.40",13.39,22.11833,
"132.60",13.404,22.15167,
"132.80",13.42,22.18533,
"133.00",13.434,22.21833,
"133.20",13.447,22.25167,
"133.40",13.461,22.28533,
"133.60",13.476,22.31867,
"133.80",13.491,22.35167,
"134.00",13.504,22.385,
"134.20",13.518,22.41833,
"134.40",13.531,22.45167,
"134.60",13.544,22.485,
"134.80",13.557,22.51833,
"135.00",13.574,22.55167,
"135.20",13.586,22.585,
"135.40",13.598,22.61833,
"135.60",13.613,22.65167,
"135.80",13.626,22.685,
"136.00",13.644,22.71833,
"136.20",13.661,22.75167,
"136.40",13.672,22.785,
"136.60",13.685,22.81833,
"136.80",13.699,22.85167,
"137.00",13.714,22.885,
"137.20",13.731,22.91833,
"137.40",13.744,22.95167,
"137.60",13.759,22.985,
"137.80",13.772,23.01833,
"138.00",13.786,23.05167,
"138.20",13.802,23.085,
"138.40",13.816,23.11833,
"138.60",13.83,23.15167,
"138.80",13.846,23.185,
"139.00",13.862,23.218,
"139.20",13.875,23.25133,
"139.40",13.886,23.28467,
"139.60",13.902,23.31833,
"139.80",13.916,23.35167,
"140.00",13.932,23.385,
"140.20",13.945,23.41833,
"140.40",13.956,23.45167,
"140.60",13.971,23.485,
"140.80",13.981,23.51833,
"141.00",13.997,23.55167,
"141.20",14.01,23.585,
"141.40",14.022,23.61833,
"141.60",14.033,23.65167,
"141.80",14.044,23.685,
"142.00",14.059,23.71833,
"142.20",14.072,23.75167,
"142.40",14.082,23.785,
"142.60",14.093,23.81833,
"142.80",14.106,23.85167,
"143.00",14.123,23.885,
"143.20",14.134,23.91833,
"143.40",14.146,23.95167,
"143.60",14.16,23.985,
"143.80",14.17,24.01833,
"144.00",14.186,24.05167,
"144.20",14.197,24.085,
"144.40",14.209,24.11833,
"144.60",14.22,24.15167,
"144.80",14.235,24.185,
"145.00",14.248,24.21833,
"145.20",14.259,24.25167,
"145.40",14.271,24.28533,
"145.60",14.282,24.31833,
"145.80",14.297,24.352,
"146.00",14.315,24.38533,
"146.20",14.326,24.41833,
"146.40",14.338,24.45167,
"146.60",14.347,24.485,
"146.80",14.357,24.51833,
"147.00",14.374,24.55167,
"147.20",14.387,24.585,
"147.40",14.397,24.61867,
"147.60",14.411,24.65167,
"147.80",14.421,24.685,
"148.00",14.432,24.71833,
"148.20",14.444,24.75167,
"148.40",14.455,24.785,
"148.60",14.468,24.81833,
"148.80",14.479,24.852,
"149.00",14.495,24.885,
"149.20",14.505,24.91833,
"149.40",14.516,24.952,
"149.60",14.528,24.98533,
"149.80",14.544,25.01867,
"150.00",14.56,25.052,
"150.20",14.573,25.085,
"150.40",14.582,25.11833,
"150.60",14.587,25.15167,
"150.80",14.601,25.185,
"151.00",14.617,25.21833,
"151.20",14.632,25.25167,
"151.40",14.649,25.28533,
"151.60",14.658,25.31833,
"151.80",14.67,25.35167,
"152.00",14.686,25.385,
"152.20",14.699,25.41833,
"152.40",14.709,25.45167,
"152.60",14.721,25.485,
"152.80",14.735,25.51833,
"153.00",14.747,25.55167,
"153.20",14.761,25.585,
"153.40",14.771,25.61833,
"153.60",14.784,25.65167,
"153.80",14.797,25.685,
"154.00",14.814,25.71833,
"154.20",14.826,25.75167,
"154.40",14.836,25.785,
"154.60",14.846,25.81833,
"154.80",14.861,25.85167,
"155.00",14.876,25.885,
"155.20",14.889,25.91833,
"155.40",14.897,25.95167,
"155.60",14.91,25.985,
"155.80",14.923,26.01867,
"156.00",14.938,26.052,
"156.20",14.951,26.08533,
"156.40",14.961,26.11867,
"156.60",14.971,26.152,
"156.80",14.983,26.18533,
"157.00",14.996,26.21833,
"157.20",15.008,26.25167,
"157.40",15.022,26.28533,
"157.60",15.03,26.31833,
"157.80",15.044,26.352,
"158.00",15.055,26.385,
"158.20",15.067,26.41833,
"158.40",15.075,26.45167,
"158.60",15.087,26.485,
"158.80",15.1,26.51833,
"159.00",15.111,26.55167,
"159.20",15.123,26.585,
"159.40",15.136,26.61833,
"159.60",15.143,26.65167,
"159.80",15.157,26.68533,
"160.00",15.171,26.71833,
"160.20",15.178,26.75167,
"160.40",15.192,26.785,
"160.60",15.2,26.81833,
"160.80",15.211,26.85167,
"161.00",15.225,26.885,
"161.20",15.241,26.91833,
"161.40",15.254,26.95167,
"161.60",15.263,26.985,
"161.80",15.277,27.01833,
"162.00",15.292,27.05167,
"162.20",15.303,27.085,
"162.40",15.314,27.11833,
"162.60",15.324,27.15167,
"162.80",15.336,27.18467,
"163.00",15.35,27.218,
"163.20",15.362,27.25133,
"163.40",15.372,27.285,
"163.60",15.386,27.31833,
"163.80",15.4,27.35167,
"164.00",15.414,27.385,
"164.20",15.423,27.41833,
"164.40",15.435,27.45167,
"164.60",15.443,27.485,
"164.80",15.456,27.51833,
"165.00",15.467,27.55167,
"165.20",15.478,27.585,
"165.40",15.485,27.61867,
"165.60",15.493,27.65167,
"165.80",15.505,27.685,
"166.00",15.519,27.71833,
"166.20",15.529,27.75167,
"166.40",15.537,27.785,
"166.60",15.545,27.81833,
"166.80",15.553,27.85167,
"167.00",15.567,27.885,
"167.20",15.578,27.91833,
"167.40",15.588,27.952,
"167.60",15.596,27.985,
"167.80",15.608,28.01833,
"168.00",15.62,28.05167,
"168.20",15.63,28.085,
"168.40",15.641,28.11833,
"168.60",15.651,28.15167,
"168.80",15.665,28.185,
"169.00",15.679,28.21833,
"169.20",15.689,28.25167,
"169.40",15.698,28.285,
"169.60",15.711,28.31833,
"169.80",15.721,28.35167,
"170.00",15.735,28.385,
"170.20",15.744,28.418,
"170.40",15.753,28.45167,
"170.60",15.763,28.485,
"170.80",15.778,28.51833,
"171.00",15.791,28.55167,
"171.20",15.801,28.585,
"171.40",15.809,28.61833,
"171.60",15.817,28.65133,
"171.80",15.827,28.685,
"172.00",15.839,28.718,
"172.20",15.851,28.75167,
"172.40",15.861,28.785,
"172.60",15.871,28.81833,
"172.80",15.88,28.85167,
"173.00",15.894,28.885,
"173.20",15.902,28.91833,
"173.40",15.911,28.95167,
"173.60",15.924,28.985,
"173.80",15.936,29.01833,
"174.00",15.947,29.05167,
"174.20",15.959,29.085,
"174.40",15.966,29.11833,
"174.60",15.976,29.15167,
"174.80",15.985,29.18467,
"175.00",16,29.218,
"175.20",16.008,29.25167,
"175.40",16.015,29.285,
"175.60",16.021,29.318,
"175.80",16.03,29.35167,
"176.00",16.043,29.38467,
"176.20",16.053,29.41833,
"176.40",16.063,29.45167,
"176.60",16.068,29.485,
"176.80",16.076,29.51833,
"177.00",16.088,29.55133,
"177.20",16.101,29.585,
"177.40",16.107,29.61833,
"177.60",16.115,29.65167,
"177.80",16.125,29.685,
"178.00",16.138,29.71833,
"178.20",16.145,29.75167,
"178.40",16.155,29.785,
"178.60",16.166,29.81833,
"178.80",16.176,29.85167,
"179.00",16.189,29.885,
"179.20",16.201,29.91833,
"179.40",16.209,29.95167,
"179.60",16.22,29.985,
"179.80",16.232,30.01833,
"180.00",16.245,30.05167,
"180.20",16.258,30.085,
"180.40",16.267,30.11833,
"180.60",16.277,30.15167,
"180.80",16.292,30.185,
"181.00",16.304,30.218,
"181.20",16.315,30.25167,
"181.40",16.327,30.28467,
"181.60",16.336,30.318,
"181.80",16.347,30.35133,
"182.00",16.359,30.38467,
"182.20",16.372,30.41833,
"182.40",16.382,30.45167,
"182.60",16.39,30.48467,
"182.80",16.396,30.518,
"183.00",16.409,30.55133,
"183.20",16.418,30.585,
"183.40",16.426,30.61833,
"183.60",16.435,30.65133,
"183.80",16.444,30.68467,
"184.00",16.456,30.718,
"184.20",16.464,30.75167,
"184.40",16.474,30.785,
"184.60",16.481,30.81833,
"184.80",16.493,30.85133,
"185.00",16.504,30.88467,
"185.20",16.512,30.91833,
"185.40",16.518,30.95167,
"185.60",16.529,30.985,
"185.80",16.538,31.01833,
"186.00",16.551,31.05167,
"186.20",16.561,31.085,
"186.40",16.569,31.11833,
"186.60",16.577,31.15167,
"186.80",16.585,31.185,
"187.00",16.597,31.218,
"187.20",16.606,31.25167,
"187.40",16.616,31.285,
"187.60",16.626,31.31833,
"187.80",16.634,31.35167,
"188.00",16.645,31.385,
"188.20",16.656,31.41833,
"188.40",16.663,31.45133,
"188.60",16.676,31.485,
"188.80",16.685,31.51833,
"189.00",16.694,31.55167,
"189.20",16.705,31.585,
"189.40",16.713,31.61833,
"189.60",16.722,31.65167,
"189.80",16.734,31.685,
"190.00",16.745,31.71833,
"190.20",16.752,31.75167,
"190.40",16.76,31.785,
"190.60",16.767,31.81833,
"190.80",16.777,31.85167,
"191.00",16.788,31.885,
"191.20",16.795,31.91833,
"191.40",16.803,31.95167,
"191.60",16.811,31.985,
"191.80",16.821,32.01833,
"192.00",16.83,32.05167,
"192.20",16.84,32.085,
"192.40",16.848,32.11833,
"192.60",16.854,32.15166,
"192.80",16.862,32.185,
"193.00",16.869,32.218,
"193.20",16.88,32.25133,
"193.40",16.889,32.285,
"193.60",16.898,32.31833,
"193.80",16.909,32.35167,
"194.00",16.92,32.385,
"194.20",16.927,32.41833,
"194.40",16.937,32.45167,
"194.60",16.949,32.485,
"194.80",16.961,32.51833,
"195.00",16.974,32.55167,
"195.20",16.983,32.585,
"195.40",16.99,32.61833,
"195.60",17.004,32.65166,
"195.80",17.015,32.685,
"196.00",17.028,32.718,
"196.20",17.041,32.75167,
"196.40",17.049,32.785,
"196.60",17.057,32.81833,
"196.80",17.069,32.85133,
"197.00",17.081,32.885,
"197.20",17.09,32.91833,
"197.40",17.095,32.95167,
"197.60",17.107,32.985,
"197.80",17.114,33.01833,
"198.00",17.126,33.05167,
"198.20",17.136,33.085,
"198.40",17.142,33.11833,
"198.60",17.149,33.15166,
"198.80",17.156,33.185,
"199.00",17.166,33.21833,
"199.20",17.177,33.25167,
"199.40",17.18,33.285,
"199.60",17.187,33.318,
"199.80",17.197,33.35167,
"200.00",17.204,33.38467,
"200.20",17.21,33.41833,
"200.40",17.215,33.45133,
"200.60",17.221,33.48466,
"200.80",17.226,33.51833,
"201.00",17.237,33.55133,
"201.20",17.242,33.58467,
"201.40",17.249,33.618,
"201.60",17.254,33.65166,
"201.80",17.262,33.68467,
"202.00",17.271,33.718,
"202.20",17.28,33.75167,
"202.40",17.286,33.785,
"202.60",17.291,33.81833,
"202.80",17.3,33.85167,
"203.00",17.312,33.88467,
"203.20",17.316,33.91833,
"203.40",17.321,33.95167,
"203.60",17.33,33.985,
"203.80",17.341,34.01833,
"204.00",17.352,34.05167,
"204.20",17.363,34.085,
"204.40",17.368,34.118,
"204.60",17.375,34.15133,
"204.80",17.385,34.185,
"205.00",17.395,34.218,
"205.20",17.403,34.25133,
"205.40",17.41,34.285,
"205.60",17.415,34.318,
"205.80",17.428,34.35167,
"206.00",17.438,34.385,
"206.20",17.448,34.41833,
"206.40",17.455,34.45167,
"206.60",17.458,34.485,
"206.80",17.467,34.518,
"207.00",17.475,34.55133,
"207.20",17.485,34.58467,
"207.40",17.492,34.618,
"207.60",17.497,34.65133,
"207.80",17.509,34.68467,
"208.00",17.519,34.718,
"208.20",17.526,34.75133,
"208.40",17.536,34.785,
"208.60",17.548,34.81833,
"208.80",17.556,34.85167,
"209.00",17.566,34.885,
"209.20",17.573,34.91833,
"209.40",17.578,34.95167,
"209.60",17.584,34.985,
"209.80",17.596,35.01833,
"210.00",17.606,35.05167,
"210.20",17.612,35.085,
"210.40",17.616,35.11833,
"210.60",17.62,35.15166,
"210.80",17.628,35.185,
"211.00",17.635,35.218,
"211.20",17.64,35.25133,
"211.40",17.642,35.285,
"211.60",17.65,35.31833,
"211.80",17.657,35.35167,
"212.00",17.663,35.38467,
"212.20",17.671,35.418,
"212.40",17.677,35.45133,
"212.60",17.683,35.485,
"212.80",17.687,35.51833,
"213.00",17.695,35.55167,
"213.20",17.703,35.585,
"213.40",17.708,35.61833,
"213.60",17.717,35.65133,
"213.80",17.723,35.685,
"214.00",17.734,35.71833,
"214.20",17.738,35.75167,
"214.40",17.745,35.785,
"214.60",17.749,35.81833,
"214.80",17.758,35.85167,
"215.00",17.765,35.88467,
"215.20",17.774,35.918,
"215.40",17.776,35.95167,
"215.60",17.785,35.985,
"215.80",17.792,36.01833,
"216.00",17.803,36.05167,
"216.20",17.811,36.085,
"216.40",17.817,36.11833,
"216.60",17.822,36.15166,
"216.80",17.832,36.185,
"217.00",17.843,36.218,
"217.20",17.852,36.25133,
"217.40",17.858,36.285,
"217.60",17.864,36.31833,
"217.80",17.874,36.35167,
"218.00",17.883,36.385,
"218.20",17.89,36.41833,
"218.40",17.896,36.45167,
"218.60",17.905,36.485,
"218.80",17.909,36.51833,
"219.00",17.92,36.55167,
"219.20",17.929,36.585,
"219.40",17.936,36.61833,
"219.60",17.943,36.65166,
"219.80",17.95,36.685,
"220.00",17.96,36.718,
"220.20",17.971,36.75167,
"220.40",17.976,36.785,
"220.60",17.983,36.81833,
"220.80",17.991,36.85167,
"221.00",18.001,36.885,
"221.20",18.009,36.91833,
"221.40",18.017,36.95167,
"221.60",18.022,36.985,
"221.80",18.029,37.01833,
"222.00",18.041,37.05167,
"222.20",18.05,37.08467,
"222.40",18.052,37.118,
"222.60",18.056,37.15133,
"222.80",18.062,37.185,
"223.00",18.074,37.218,
"223.20",18.081,37.25167,
"223.40",18.089,37.285,
"223.60",18.098,37.31833,
"223.80",18.108,37.35167,
"224.00",18.12,37.38467,
"224.20",18.129,37.41833,
"224.40",18.137,37.45167,
"224.60",18.146,37.485,
"224.80",18.155,37.51833,
"225.00",18.164,37.55133,
"225.20",18.165,37.58467,
"225.40",18.171,37.61833,
"225.60",18.18,37.65166,
"225.80",18.187,37.685,
"226.00",18.197,37.71833,
"226.20",18.209,37.75167,
"226.40",18.216,37.785,
"226.60",18.221,37.81833,
"226.80",18.228,37.85167,
"227.00",18.235,37.88467,
"227.20",18.245,37.918,
"227.40",18.252,37.95167,
"227.60",18.258,37.985,
"227.80",18.267,38.01833,
"228.00",18.273,38.05167,
"228.20",18.282,38.085,
"228.40",18.286,38.11833,
"228.60",18.292,38.15166,
"228.80",18.302,38.185,
"229.00",18.311,38.21833,
"229.20",18.32,38.25167,
"229.40",18.325,38.285,
"229.60",18.331,38.318,
"229.80",18.339,38.35133,
"230.00",18.347,38.385,
"230.20",18.354,38.41833,
"230.40",18.36,38.45167,
"230.60",18.366,38.485,
"230.80",18.374,38.51833,
"231.00",18.381,38.55167,
"231.20",18.389,38.585,
"231.40",18.395,38.61867,
"231.60",18.4,38.65166,
"231.80",18.406,38.685,
"232.00",18.416,38.71833,
"232.20",18.423,38.75167,
"232.40",18.43,38.785,
"232.60",18.435,38.81833,
"232.80",18.443,38.85167,
"233.00",18.451,38.885,
"233.20",18.458,38.91833,
"233.40",18.463,38.95167,
"233.60",18.467,38.985,
"233.80",18.475,39.01833,
"234.00",18.485,39.05167,
"234.20",18.489,39.085,
"234.40",18.491,39.11833,
"234.60",18.496,39.15166,
"234.80",18.501,39.185,
"235.00",18.51,39.218,
"235.20",18.513,39.25167,
"235.40",18.518,39.285,
"235.60",18.518,39.31833,
"235.80",18.523,39.35133,
"236.00",18.531,39.38467,
"236.20",18.538,39.418,
"236.40",18.542,39.45133,
"236.60",18.545,39.48466,
"236.80",18.553,39.518,
"237.00",18.558,39.55133,
"237.20",18.563,39.585,
"237.40",18.571,39.61833,
"237.60",18.576,39.65166,
"237.80",18.579,39.685,
"238.00",18.586,39.71833,
"238.20",18.595,39.75167,
"238.40",18.601,39.785,
"238.60",18.606,39.81833,
"238.80",18.613,39.85167,
"239.00",18.619,39.885,
"239.20",18.624,39.91833,
"239.40",18.628,39.95167,
"239.60",18.633,39.985,
"239.80",18.64,40.01833,
"240.00",18.649,40.05167,
"240.20",18.653,40.085,
"240.40",18.657,40.11833,
"240.60",18.66,40.15166,
"240.80",18.666,40.185,
"241.00",18.677,40.21833,
"241.20",18.685,40.25167,
"241.40",18.689,40.28533,
"241.60",18.698,40.31866,
"241.80",18.702,40.352,
"242.00",18.711,40.385,
"242.20",18.72,40.41833,
"242.40",18.726,40.452,
"242.60",18.733,40.485,
"242.80",18.74,40.51833,
"243.00",18.747,40.55167,
"243.20",18.755,40.585,
"243.40",18.761,40.61867,
"243.60",18.767,40.652,
"243.80",18.777,40.68533,
"244.00",18.785,40.71867,
"244.20",18.789,40.752,
"244.40",18.794,40.785,
"244.60",18.8,40.81866,
"244.80",18.809,40.85167,
"245.00",18.822,40.885,
"245.20",18.828,40.91833,
"245.40",18.836,40.95167,
"245.60",18.841,40.985,
"245.80",18.852,41.01833,
"246.00",18.864,41.05167,
"246.20",18.875,41.085,
"246.40",18.886,41.11833,
"246.60",18.896,41.15166,
"246.80",18.901,41.18533,
"247.00",18.911,41.21867,
"247.20",18.926,41.25167,
"247.40",18.933,41.28533,
"247.60",18.937,41.31833,
"247.80",18.942,41.35167,
"248.00",18.953,41.385,
"248.20",18.959,41.41833,
"248.40",18.963,41.45167,
"248.60",18.968,41.485,
"248.80",18.977,41.51867,
"249.00",18.985,41.55167,
"249.20",18.991,41.585,
"249.40",18.993,41.61833,
"249.60",18.995,41.65166,
"249.80",19.004,41.685,
"250.00",19.015,41.71833,
"250.20",19.018,41.75167,
"250.40",19.021,41.785,
"250.60",19.028,41.81833,
"250.80",19.038,41.85167,
"251.00",19.045,41.885,
"251.20",19.052,41.91833,
"251.40",19.054,41.95167,
"251.60",19.06,41.985,
"251.80",19.067,42.01833,
"252.00",19.073,42.05133,
"252.20",19.08,42.08467,
"252.40",19.083,42.11833,
"252.60",19.085,42.15133,
"252.80",19.089,42.18467,
"253.00",19.097,42.218,
"253.20",19.102,42.25167,
"253.40",19.104,42.285,
"253.60",19.109,42.31833,
"253.80",19.117,42.35167,
"254.00",19.12,42.385,
"254.20",19.123,42.418,
"254.40",19.125,42.45167,
"254.60",19.133,42.485,
"254.80",19.139,42.51833,
"255.00",19.147,42.55167,
"255.20",19.15,42.585,
"255.40",19.154,42.61833,
"255.60",19.161,42.65166,
"255.80",19.167,42.685,
"256.00",19.173,42.71833,
"256.20",19.179,42.75167,
"256.40",19.185,42.785,
"256.60",19.19,42.81833,
"256.80",19.198,42.85167,
"257.00",19.207,42.885,
"257.20",19.214,42.91833,
"257.40",19.218,42.95167,
"257.60",19.221,42.985,
"257.80",19.227,43.01833,
"258.00",19.237,43.05167,
"258.20",19.242,43.085,
"258.40",19.247,43.11833,
"258.60",19.253,43.15166,
"258.80",19.26,43.185,
"259.00",19.269,43.21833,
"259.20",19.275,43.25167,
"259.40",19.279,43.285,
"259.60",19.284,43.31833,
"259.80",19.294,43.352,
"260.00",19.301,43.385,
"260.20",19.308,43.41833,
"260.40",19.313,43.45167,
"260.60",19.319,43.48533,
"260.80",19.327,43.51867,
"261.00",19.338,43.55167,
"261.20",19.348,43.585,
"261.40",19.354,43.61833,
"261.60",19.364,43.65166,
"261.80",19.369,43.685,
"262.00",19.378,43.71833,
"262.20",19.391,43.75167,
"262.40",19.395,43.785,
"262.60",19.401,43.81833,
"262.80",19.408,43.85167,
"263.00",19.418,43.885,
"263.20",19.423,43.91833,
"263.40",19.43,43.95167,
"263.60",19.434,43.985,
"263.80",19.441,44.01833,
"264.00",19.448,44.05167,
"264.20",19.454,44.085,
"264.40",19.458,44.11833,
"264.60",19.462,44.15166,
"264.80",19.469,44.185,
"265.00",19.477,44.21833,
"265.20",19.484,44.25167,
"265.40",19.487,44.285,
"265.60",19.49,44.31833,
"265.80",19.498,44.35167,
"266.00",19.507,44.385,
"266.20",19.512,44.41833,
"266.40",19.517,44.45167,
"266.60",19.524,44.485,
"266.80",19.528,44.51833,
"267.00",19.535,44.55167,
"267.20",19.543,44.585,
"267.40",19.547,44.61833,
"267.60",19.554,44.65166,
"267.80",19.56,44.685,
"268.00",19.569,44.71833,
"268.20",19.575,44.75167,
"268.40",19.582,44.785,
"268.60",19.587,44.81833,
"268.80",19.593,44.85167,
"269.00",19.604,44.885,
"269.20",19.604,44.91833,
"269.40",19.611,44.95167,
"269.60",19.616,44.985,
"269.80",19.621,45.01833,
"270.00",19.629,45.05167,
"270.20",19.634,45.085,
"270.40",19.639,45.11833,
"270.60",19.64,45.15166,
"270.80",19.643,45.185,
"271.00",19.65,45.21833,
"271.20",19.658,45.25167,
"271.40",19.662,45.285,
"271.60",19.666,45.31833,
"271.80",19.671,45.35167,
"272.00",19.68,45.38467,
"272.20",19.685,45.418,
"272.40",19.689,45.45167,
"272.60",19.693,45.48466,
"272.80",19.702,45.51833,
"273.00",19.711,45.55167,
"273.20",19.716,45.585,
"273.40",19.722,45.61833,
"273.60",19.726,45.65166,
"273.80",19.734,45.685,
"274.00",19.744,45.71833,
"274.20",19.75,45.75167,
"274.40",19.752,45.785,
"274.60",19.758,45.81833,
"274.80",19.768,45.85167,
"275.00",19.778,45.885,
"275.20",19.783,45.91833,
"275.40",19.787,45.95167,
"275.60",19.794,45.985,
"275.80",19.8,46.01833,
"276.00",19.811,46.05167,
"276.20",19.818,46.085,
"276.40",19.825,46.11833,
"276.60",19.833,46.152,
"276.80",19.84,46.18533,
"277.00",19.849,46.21867,
"277.20",19.855,46.252,
"277.40",19.858,46.28533,
"277.60",19.863,46.31866,
"277.80",19.869,46.352,
"278.00",19.879,46.38533,
"278.20",19.886,46.41833,
"278.40",19.889,46.45167,
"278.60",19.893,46.485,
"278.80",19.902,46.51833,
"279.00",19.91,46.55167,
"279.20",19.917,46.58533,
"279.40",19.92,46.61833,
"279.60",19.924,46.65166,
"279.80",19.929,46.685,
"280.00",19.941,46.71833,
"280.20",19.942,46.75167,
"280.40",19.943,46.785,
"280.60",19.945,46.81833,
"280.80",19.95,46.85167,
"281.00",19.958,46.885,
"281.20",19.963,46.91833,
"281.40",19.966,46.95167,
"281.60",19.967,46.985,
"281.80",19.972,47.01833,
"282.00",19.978,47.05167,
"282.20",19.983,47.085,
"282.40",19.986,47.11833,
"282.60",19.99,47.15166,
"282.80",19.996,47.185,
"283.00",20.001,47.21833,
"283.20",20.007,47.25167,
"283.40",20.008,47.285,
"283.60",20.011,47.31833,
"283.80",20.019,47.35167,
"284.00",20.025,47.385,
"284.20",20.034,47.41833,
"284.40",20.034,47.45133,
"284.60",20.038,47.485,
"284.80",20.042,47.51833,
"285.00",20.049,47.55167,
"285.20",20.054,47.585,
"285.40",20.06,47.61833,
"285.60",20.06,47.65166,
"285.80",20.068,47.685,
"286.00",20.075,47.71833,
"286.20",20.081,47.75167,
"286.40",20.085,47.785,
"286.60",20.087,47.81833,
"286.80",20.093,47.85167,
"287.00",20.101,47.885,
"287.20",20.108,47.91833,
"287.40",20.111,47.952,
"287.60",20.112,47.985,
"287.80",20.117,48.01867,
"288.00",20.125,48.052,
"288.20",20.128,48.085,
"288.40",20.132,48.11833,
"288.60",20.133,48.15166,
"288.80",20.144,48.185,
"289.00",20.148,48.21833,
"289.20",20.151,48.25167,
"289.40",20.153,48.285,
"289.60",20.154,48.31833,
"289.80",20.161,48.35167,
"289.90",20.163,48.36833,