File: exposed_monofilament_10cm_10mmpm_24nm_250esh_10.csv
"Test Name","Test Mode","Test Type","Control","Test Speed 1","Test Speed 2","Test Speed 3","Change Point 1","Change Point 2","Disp. Origin","Break and Limit Action","Sensitivity:","Level:"
"","Single","Tensile","Stroke",10,1,1,"Off","Off","Start","Stop",0,1

"Title","Sub title","Comment"
"","",""

"Shape:","Batch Size:","SubBatch Size:"
"Plate",1,1
"Name:","Thickness","Width","Gauge Length",
"Size Unit:","mm","mm","mm",
" 1 - 1","1.0000","1.0000","100.0000",

"Name",
"Parameter",
"Units",
" 1 - 1",

" 1- 1"
"Time","Force","Stroke",
"sec","N","mm",
"0.00",-.002,0,
"0.20",0,3.733334E-02,
"0.40",.013,7.433333E-02,
"0.60",.022,.1116667,
"0.80",.036,.1486667,
"1.00",.047,.1856667,
"1.20",.06,.2226667,
"1.40",.074,.26,
"1.60",.085,.297,
"1.80",.102,.334,
"2.00",.115,.371,
"2.20",.127,.4066667,
"2.40",.138,.4426666,
"2.60",.153,.4776667,
"2.80",.164,.5123333,
"3.00",.174,.5470001,
"3.20",.189,.5813333,
"3.40",.202,.6153334,
"3.60",.212,.6493334,
"3.80",.225,.6833333,
"4.00",.236,.7173334,
"4.20",.25,.7506667,
"4.40",.261,.7843333,
"4.60",.274,.818,
"4.80",.286,.8513334,
"5.00",.297,.8850001,
"5.20",.311,.9183334,
"5.40",.321,.9516667,
"5.60",.335,.9853334,
"5.80",.345,1.018667,
"6.00",.357,1.052,
"6.20",.37,1.085333,
"6.40",.385,1.118667,
"6.60",.397,1.152,
"6.80",.41,1.185333,
"7.00",.421,1.218667,
"7.20",.437,1.252,
"7.40",.446,1.285333,
"7.60",.461,1.319,
"7.80",.476,1.352333,
"8.00",.489,1.385667,
"8.20",.501,1.419,
"8.40",.515,1.452333,
"8.60",.529,1.485667,
"8.80",.542,1.519,
"9.00",.553,1.552333,
"9.20",.569,1.585667,
"9.40",.581,1.619,
"9.60",.595,1.652333,
"9.80",.61,1.685667,
"10.00",.62,1.719,
"10.20",.635,1.752,
"10.40",.649,1.785667,
"10.60",.664,1.818667,
"10.80",.677,1.852,
"11.00",.691,1.885667,
"11.20",.703,1.918667,
"11.40",.717,1.952333,
"11.60",.732,1.985667,
"11.80",.746,2.018667,
"12.00",.758,2.052,
"12.20",.772,2.085333,
"12.40",.784,2.118667,
"12.60",.8,2.152,
"12.80",.814,2.185333,
"13.00",.83,2.218667,
"13.20",.844,2.252,
"13.40",.859,2.285667,
"13.60",.874,2.319,
"13.80",.888,2.352333,
"14.00",.905,2.385333,
"14.20",.918,2.418667,
"14.40",.932,2.452,
"14.60",.945,2.485333,
"14.80",.96,2.518667,
"15.00",.975,2.552,
"15.20",.989,2.585333,
"15.40",1.005,2.619,
"15.60",1.022,2.652,
"15.80",1.038,2.685333,
"16.00",1.054,2.719,
"16.20",1.068,2.752,
"16.40",1.088,2.785333,
"16.60",1.099,2.818667,
"16.80",1.116,2.852333,
"17.00",1.133,2.885333,
"17.20",1.15,2.918667,
"17.40",1.164,2.952333,
"17.60",1.179,2.985667,
"17.80",1.197,3.018667,
"18.00",1.212,3.052333,
"18.20",1.23,3.085333,
"18.40",1.247,3.118667,
"18.60",1.262,3.152,
"18.80",1.279,3.185333,
"19.00",1.294,3.218667,
"19.20",1.312,3.252,
"19.40",1.327,3.285333,
"19.60",1.347,3.318667,
"19.80",1.365,3.352,
"20.00",1.381,3.385667,
"20.20",1.399,3.419,
"20.40",1.417,3.452333,
"20.60",1.437,3.485667,
"20.80",1.454,3.519,
"21.00",1.472,3.552,
"21.20",1.489,3.585333,
"21.40",1.506,3.618667,
"21.60",1.528,3.652,
"21.80",1.545,3.685333,
"22.00",1.563,3.718667,
"22.20",1.582,3.752,
"22.40",1.602,3.785333,
"22.60",1.621,3.818667,
"22.80",1.638,3.852,
"23.00",1.657,3.885333,
"23.20",1.677,3.918667,
"23.40",1.694,3.952333,
"23.60",1.716,3.985333,
"23.80",1.737,4.019,
"24.00",1.754,4.052333,
"24.20",1.773,4.085667,
"24.40",1.797,4.119,
"24.60",1.816,4.152333,
"24.80",1.836,4.185333,
"25.00",1.857,4.218667,
"25.20",1.879,4.252,
"25.40",1.898,4.285333,
"25.60",1.918,4.318666,
"25.80",1.943,4.352,
"26.00",1.962,4.385333,
"26.20",1.984,4.418666,
"26.40",2.005,4.452333,
"26.60",2.025,4.485333,
"26.80",2.049,4.518666,
"27.00",2.07,4.552,
"27.20",2.092,4.585333,
"27.40",2.113,4.618667,
"27.60",2.136,4.652,
"27.80",2.16,4.685333,
"28.00",2.18,4.718667,
"28.20",2.203,4.752,
"28.40",2.226,4.785333,
"28.60",2.248,4.818666,
"28.80",2.271,4.852,
"29.00",2.296,4.885333,
"29.20",2.319,4.918666,
"29.40",2.343,4.952,
"29.60",2.37,4.985333,
"29.80",2.393,5.018666,
"30.00",2.416,5.052,
"30.20",2.441,5.085333,
"30.40",2.465,5.118667,
"30.60",2.488,5.152,
"30.80",2.514,5.185333,
"31.00",2.536,5.218667,
"31.20",2.561,5.252,
"31.40",2.586,5.285333,
"31.60",2.613,5.318666,
"31.80",2.638,5.352,
"32.00",2.663,5.385666,
"32.20",2.689,5.418666,
"32.40",2.714,5.452333,
"32.60",2.741,5.485333,
"32.80",2.769,5.519,
"33.00",2.792,5.552,
"33.20",2.82,5.585333,
"33.40",2.846,5.618667,
"33.60",2.874,5.652,
"33.80",2.904,5.685667,
"34.00",2.93,5.718667,
"34.20",2.956,5.752333,
"34.40",2.982,5.785666,
"34.60",3.01,5.819,
"34.80",3.039,5.852333,
"35.00",3.067,5.885333,
"35.20",3.092,5.918666,
"35.40",3.12,5.952,
"35.60",3.149,5.985333,
"35.80",3.177,6.018666,
"36.00",3.204,6.052,
"36.20",3.231,6.085667,
"36.40",3.256,6.119,
"36.60",3.286,6.152,
"36.80",3.314,6.185333,
"37.00",3.343,6.218667,
"37.20",3.371,6.252,
"37.40",3.386,6.285333,
"37.60",3.393,6.319,
"37.80",3.424,6.352333,
"38.00",3.457,6.385333,
"38.20",3.486,6.419,
"38.40",3.518,6.452333,
"38.60",3.548,6.485666,
"38.80",3.581,6.519,
"39.00",3.611,6.552333,
"39.20",3.64,6.585333,
"39.40",3.671,6.619,
"39.60",3.7,6.652333,
"39.80",3.729,6.685667,
"40.00",3.754,6.719,
"40.20",3.787,6.752333,
"40.40",3.819,6.785333,
"40.60",3.849,6.819,
"40.80",3.88,6.852333,
"41.00",3.911,6.885333,
"41.20",3.942,6.918666,
"41.40",3.974,6.952333,
"41.60",4.006,6.985333,
"41.80",4.037,7.018666,
"42.00",4.072,7.052333,
"42.20",4.101,7.085333,
"42.40",4.13,7.119,
"42.60",4.164,7.152333,
"42.80",4.195,7.185333,
"43.00",4.226,7.218667,
"43.20",4.255,7.252,
"43.40",4.273,7.285333,
"43.60",4.295,7.318666,
"43.80",4.329,7.352,
"44.00",4.361,7.385333,
"44.20",4.393,7.418666,
"44.40",4.427,7.452333,
"44.60",4.461,7.485333,
"44.80",4.493,7.518666,
"45.00",4.523,7.552,
"45.20",4.555,7.585333,
"45.40",4.586,7.618667,
"45.60",4.622,7.652,
"45.80",4.653,7.685667,
"46.00",4.685,7.719,
"46.20",4.718,7.752333,
"46.40",4.749,7.785666,
"46.60",4.781,7.818666,
"46.80",4.816,7.852333,
"47.00",4.845,7.885333,
"47.20",4.875,7.918666,
"47.40",4.904,7.952,
"47.60",4.938,7.985333,
"47.80",4.971,8.018666,
"48.00",5.003,8.052333,
"48.20",5.034,8.085667,
"48.40",5.064,8.118999,
"48.60",5.096,8.152333,
"48.80",5.129,8.185666,
"49.00",5.161,8.219,
"49.20",5.191,8.252,
"49.40",5.223,8.285666,
"49.60",5.253,8.319,
"49.80",5.285,8.352333,
"50.00",5.315,8.385667,
"50.20",5.347,8.419,
"50.40",5.377,8.452333,
"50.60",5.409,8.485333,
"50.80",5.442,8.519,
"51.00",5.474,8.552,
"51.20",5.503,8.585333,
"51.40",5.537,8.618999,
"51.60",5.568,8.652333,
"51.80",5.6,8.685666,
"52.00",5.628,8.719,
"52.20",5.658,8.752,
"52.40",5.688,8.785666,
"52.60",5.721,8.819,
"52.80",5.749,8.852333,
"53.00",5.78,8.885667,
"53.20",5.808,8.919,
"53.40",5.838,8.952333,
"53.60",5.868,8.985666,
"53.80",5.9,9.019,
"54.00",5.931,9.052333,
"54.20",5.958,9.085667,
"54.40",5.986,9.118999,
"54.60",6.015,9.152333,
"54.80",6.045,9.185666,
"55.00",6.073,9.218666,
"55.20",6.103,9.252,
"55.40",6.131,9.285666,
"55.60",6.16,9.319,
"55.80",6.19,9.352333,
"56.00",6.216,9.385667,
"56.20",6.244,9.419,
"56.40",6.273,9.452333,
"56.60",6.3,9.485666,
"56.80",6.329,9.519,
"57.00",6.359,9.552333,
"57.20",6.383,9.585667,
"57.40",6.41,9.618999,
"57.60",6.437,9.652333,
"57.80",6.469,9.685666,
"58.00",6.493,9.719,
"58.20",6.519,9.752333,
"58.40",6.546,9.785666,
"58.60",6.571,9.818666,
"58.80",6.598,9.852,
"59.00",6.623,9.885667,
"59.20",6.651,9.919,
"59.40",6.675,9.952333,
"59.60",6.701,9.985666,
"59.80",6.729,10.019,
"60.00",6.751,10.05233,
"60.20",6.776,10.08567,
"60.40",6.802,10.119,
"60.60",6.828,10.15233,
"60.80",6.856,10.18567,
"61.00",6.879,10.21867,
"61.20",6.904,10.25233,
"61.40",6.929,10.28567,
"61.60",6.954,10.319,
"61.80",6.978,10.35233,
"62.00",7,10.38567,
"62.20",7.019,10.419,
"62.40",7.044,10.45233,
"62.60",7.07,10.48567,
"62.80",7.092,10.519,
"63.00",7.115,10.55233,
"63.20",7.135,10.58567,
"63.40",7.152,10.61867,
"63.60",7.172,10.65233,
"63.80",7.194,10.68567,
"64.00",7.215,10.719,
"64.20",7.235,10.752,
"64.40",7.258,10.78567,
"64.60",7.28,10.81867,
"64.80",7.302,10.85233,
"65.00",7.325,10.88533,
"65.20",7.345,10.91867,
"65.40",7.369,10.95233,
"65.60",7.395,10.98567,
"65.80",7.417,11.019,
"66.00",7.439,11.05233,
"66.20",7.463,11.08533,
"66.40",7.486,11.119,
"66.60",7.51,11.15233,
"66.80",7.53,11.18567,
"67.00",7.545,11.21867,
"67.20",7.569,11.252,
"67.40",7.595,11.28533,
"67.60",7.618,11.31867,
"67.80",7.645,11.352,
"68.00",7.667,11.38533,
"68.20",7.691,11.419,
"68.40",7.713,11.45233,
"68.60",7.734,11.48567,
"68.80",7.76,11.519,
"69.00",7.785,11.55233,
"69.20",7.807,11.58567,
"69.40",7.825,11.619,
"69.60",7.852,11.65233,
"69.80",7.875,11.68567,
"70.00",7.896,11.719,
"70.20",7.918,11.75233,
"70.40",7.942,11.78567,
"70.60",7.965,11.819,
"70.80",7.989,11.85233,
"71.00",8.009,11.88567,
"71.20",8.03,11.919,
"71.40",8.055,11.95233,
"71.60",8.074,11.98567,
"71.80",8.097,12.019,
"72.00",8.118,12.05233,
"72.20",8.142,12.08567,
"72.40",8.163,12.11933,
"72.60",8.188,12.15233,
"72.80",8.207,12.18567,
"73.00",8.231,12.219,
"73.20",8.253,12.25233,
"73.40",8.274,12.28567,
"73.60",8.299,12.319,
"73.80",8.321,12.35233,
"74.00",8.345,12.38567,
"74.20",8.367,12.419,
"74.40",8.39,12.45233,
"74.60",8.413,12.48567,
"74.80",8.433,12.519,
"75.00",8.45,12.55233,
"75.20",8.47,12.58567,
"75.40",8.492,12.619,
"75.60",8.517,12.65233,
"75.80",8.538,12.68567,
"76.00",8.56,12.719,
"76.20",8.581,12.75233,
"76.40",8.606,12.78567,
"76.60",8.629,12.81867,
"76.80",8.65,12.85233,
"77.00",8.669,12.88567,
"77.20",8.69,12.919,
"77.40",8.713,12.95233,
"77.60",8.734,12.98567,
"77.80",8.756,13.01867,
"78.00",8.778,13.052,
"78.20",8.795,13.08533,
"78.40",8.816,13.11867,
"78.60",8.836,13.152,
"78.80",8.857,13.18533,
"79.00",8.885,13.21867,
"79.20",8.902,13.252,
"79.40",8.922,13.28533,
"79.60",8.944,13.31867,
"79.80",8.966,13.352,
"80.00",8.987,13.38533,
"80.20",9.006,13.419,
"80.40",9.029,13.45233,
"80.60",9.052,13.48533,
"80.80",9.071,13.51867,
"81.00",9.093,13.552,
"81.20",9.113,13.58533,
"81.40",9.138,13.61867,
"81.60",9.159,13.65233,
"81.80",9.182,13.68567,
"82.00",9.204,13.719,
"82.20",9.221,13.752,
"82.40",9.24,13.78567,
"82.60",9.263,13.81867,
"82.80",9.284,13.85233,
"83.00",9.306,13.88567,
"83.20",9.326,13.91867,
"83.40",9.344,13.952,
"83.60",9.366,13.98533,
"83.80",9.387,14.01867,
"84.00",9.408,14.05233,
"84.20",9.426,14.08533,
"84.40",9.447,14.119,
"84.60",9.467,14.152,
"84.80",9.487,14.18533,
"85.00",9.507,14.21867,
"85.20",9.528,14.25233,
"85.40",9.547,14.28533,
"85.60",9.566,14.31867,
"85.80",9.587,14.35233,
"86.00",9.608,14.38533,
"86.20",9.624,14.41867,
"86.40",9.64,14.452,
"86.60",9.66,14.48533,
"86.80",9.679,14.51867,
"87.00",9.693,14.552,
"87.20",9.712,14.58533,
"87.40",9.728,14.61867,
"87.60",9.751,14.652,
"87.80",9.769,14.68567,
"88.00",9.786,14.719,
"88.20",9.802,14.75233,
"88.40",9.818,14.78567,
"88.60",9.834,14.819,
"88.80",9.851,14.85233,
"89.00",9.862,14.88567,
"89.20",9.879,14.91867,
"89.40",9.895,14.95233,
"89.60",9.908,14.98533,
"89.80",9.927,15.019,
"90.00",9.94,15.05233,
"90.20",9.958,15.08567,
"90.40",9.972,15.119,
"90.60",9.986,15.15233,
"90.80",10.002,15.18567,
"91.00",10.016,15.219,
"91.20",10.031,15.25233,
"91.40",10.047,15.28567,
"91.60",10.063,15.319,
"91.80",10.082,15.352,
"92.00",10.097,15.38533,
"92.20",10.11,15.419,
"92.40",10.127,15.45233,
"92.60",10.144,15.48533,
"92.80",10.161,15.51867,
"93.00",10.179,15.552,
"93.20",10.197,15.58533,
"93.40",10.215,15.619,
"93.60",10.234,15.65233,
"93.80",10.258,15.68567,
"94.00",10.275,15.719,
"94.20",10.295,15.75233,
"94.40",10.315,15.78567,
"94.60",10.333,15.819,
"94.80",10.353,15.85233,
"95.00",10.372,15.88533,
"95.20",10.386,15.91867,
"95.40",10.407,15.952,
"95.60",10.426,15.98533,
"95.80",10.445,16.01867,
"96.00",10.462,16.052,
"96.20",10.477,16.08533,
"96.40",10.497,16.11867,
"96.60",10.517,16.152,
"96.80",10.534,16.18533,
"97.00",10.551,16.21867,
"97.20",10.563,16.252,
"97.40",10.582,16.28567,
"97.60",10.599,16.319,
"97.80",10.621,16.35233,
"98.00",10.639,16.38567,
"98.20",10.651,16.419,
"98.40",10.671,16.45233,
"98.60",10.687,16.48533,
"98.80",10.707,16.519,
"99.00",10.728,16.55233,
"99.20",10.746,16.58567,
"99.40",10.761,16.619,
"99.60",10.78,16.65233,
"99.80",10.803,16.68533,
"100.00",10.819,16.719,
"100.20",10.839,16.752,
"100.40",10.86,16.78567,
"100.60",10.881,16.81867,
"100.80",10.902,16.85233,
"101.00",10.917,16.88533,
"101.20",10.936,16.91867,
"101.40",10.956,16.95233,
"101.60",10.976,16.98567,
"101.80",10.994,17.019,
"102.00",11.015,17.05233,
"102.20",11.03,17.08567,
"102.40",11.049,17.119,
"102.60",11.068,17.152,
"102.80",11.085,17.18533,
"103.00",11.104,17.21867,
"103.20",11.121,17.252,
"103.40",11.137,17.28533,
"103.60",11.157,17.31867,
"103.80",11.177,17.352,
"104.00",11.193,17.38567,
"104.20",11.209,17.419,
"104.40",11.226,17.45233,
"104.60",11.244,17.48567,
"104.80",11.262,17.519,
"105.00",11.277,17.55233,
"105.20",11.293,17.58567,
"105.40",11.308,17.619,
"105.60",11.326,17.652,
"105.80",11.342,17.68567,
"106.00",11.359,17.719,
"106.20",11.373,17.75233,
"106.40",11.391,17.78567,
"106.60",11.406,17.81867,
"106.80",11.422,17.85233,
"107.00",11.439,17.88567,
"107.20",11.453,17.919,
"107.40",11.468,17.95233,
"107.60",11.485,17.98567,
"107.80",11.504,18.019,
"108.00",11.519,18.05233,
"108.20",11.53,18.08567,
"108.40",11.546,18.119,
"108.60",11.562,18.15233,
"108.80",11.579,18.18567,
"109.00",11.596,18.219,
"109.20",11.606,18.25233,
"109.40",11.62,18.28567,
"109.60",11.637,18.319,
"109.80",11.656,18.35233,
"110.00",11.667,18.38567,
"110.20",11.682,18.419,
"110.40",11.697,18.45233,
"110.60",11.715,18.48567,
"110.80",11.731,18.519,
"111.00",11.748,18.55233,
"111.20",11.757,18.58533,
"111.40",11.774,18.61867,
"111.60",11.787,18.652,
"111.80",11.803,18.68567,
"112.00",11.816,18.719,
"112.20",11.83,18.75233,
"112.40",11.843,18.78567,
"112.60",11.858,18.81867,
"112.80",11.877,18.852,
"113.00",11.888,18.88533,
"113.20",11.9,18.91867,
"113.40",11.913,18.95233,
"113.60",11.928,18.98533,
"113.80",11.948,19.019,
"114.00",11.963,19.05233,
"114.20",11.977,19.08567,
"114.40",11.988,19.119,
"114.60",12.008,19.15233,
"114.80",12.025,19.18567,
"115.00",12.039,19.219,
"115.20",12.056,19.252,
"115.40",12.071,19.28567,
"115.60",12.087,19.31867,
"115.80",12.105,19.352,
"116.00",12.12,19.38567,
"116.20",12.135,19.41867,
"116.40",12.153,19.452,
"116.60",12.171,19.48533,
"116.80",12.188,19.51867,
"117.00",12.205,19.552,
"117.20",12.216,19.58533,
"117.40",12.233,19.619,
"117.60",12.25,19.65233,
"117.80",12.266,19.68567,
"118.00",12.28,19.719,
"118.20",12.297,19.75233,
"118.40",12.31,19.78567,
"118.60",12.33,19.819,
"118.80",12.346,19.85233,
"119.00",12.363,19.88567,
"119.20",12.378,19.919,
"119.40",12.393,19.95233,
"119.60",12.411,19.98567,
"119.80",12.43,20.019,
"120.00",12.445,20.05233,
"120.20",12.463,20.08567,
"120.40",12.481,20.119,
"120.60",12.5,20.152,
"120.80",12.518,20.18533,
"121.00",12.535,20.21867,
"121.20",12.551,20.252,
"121.40",12.569,20.28533,
"121.60",12.584,20.31867,
"121.80",12.602,20.352,
"122.00",12.617,20.38567,
"122.20",12.633,20.41867,
"122.40",12.646,20.452,
"122.60",12.663,20.48533,
"122.80",12.68,20.51867,
"123.00",12.697,20.552,
"123.20",12.712,20.58533,
"123.40",12.725,20.61867,
"123.60",12.743,20.652,
"123.80",12.763,20.68567,
"124.00",12.778,20.719,
"124.20",12.793,20.75233,
"124.40",12.807,20.78567,
"124.60",12.824,20.819,
"124.80",12.839,20.85233,
"125.00",12.854,20.88567,
"125.20",12.869,20.919,
"125.40",12.882,20.95233,
"125.60",12.898,20.98567,
"125.80",12.913,21.019,
"126.00",12.93,21.05233,
"126.20",12.941,21.08567,
"126.40",12.954,21.119,
"126.60",12.97,21.15233,
"126.80",12.983,21.18567,
"127.00",12.992,21.219,
"127.20",13.007,21.25233,
"127.40",13.018,21.28567,
"127.60",13.03,21.319,
"127.80",13.047,21.35233,
"128.00",13.059,21.38567,
"128.20",13.072,21.419,
"128.40",13.083,21.45233,
"128.60",13.099,21.48567,
"128.80",13.114,21.519,
"129.00",13.13,21.55233,
"129.20",13.139,21.58567,
"129.40",13.151,21.619,
"129.60",13.166,21.65233,
"129.80",13.178,21.68567,
"130.00",13.189,21.719,
"130.20",13.205,21.75233,
"130.40",13.22,21.78567,
"130.60",13.237,21.819,
"130.80",13.253,21.85233,
"131.00",13.266,21.88533,
"131.20",13.282,21.91867,
"131.40",13.298,21.952,
"131.60",13.317,21.98533,
"131.80",13.335,22.01867,
"132.00",13.351,22.05233,
"132.20",13.369,22.08533,
"132.40",13.386,22.119,
"132.60",13.401,22.152,
"132.80",13.42,22.18567,
"133.00",13.439,22.219,
"133.20",13.453,22.25233,
"133.40",13.466,22.28567,
"133.60",13.483,22.319,
"133.80",13.499,22.35233,
"134.00",13.514,22.38567,
"134.20",13.525,22.419,
"134.40",13.538,22.45233,
"134.60",13.549,22.48567,
"134.80",13.564,22.519,
"135.00",13.577,22.55233,
"135.20",13.589,22.58567,
"135.40",13.602,22.619,
"135.60",13.614,22.65233,
"135.80",13.631,22.68567,
"136.00",13.64,22.719,
"136.20",13.652,22.75233,
"136.40",13.667,22.786,
"136.60",13.68,22.819,
"136.80",13.693,22.85233,
"137.00",13.703,22.88567,
"137.20",13.711,22.919,
"137.40",13.728,22.95233,
"137.60",13.74,22.986,
"137.80",13.756,23.01933,
"138.00",13.765,23.05267,
"138.20",13.779,23.086,
"138.40",13.79,23.11933,
"138.60",13.802,23.15233,
"138.80",13.816,23.186,
"139.00",13.828,23.219,
"139.20",13.841,23.25233,
"139.40",13.853,23.28567,
"139.60",13.866,23.319,
"139.80",13.882,23.35233,
"140.00",13.893,23.38567,
"140.20",13.904,23.419,
"140.40",13.917,23.45233,
"140.60",13.93,23.48567,
"140.80",13.944,23.519,
"141.00",13.958,23.55233,
"141.20",13.974,23.58567,
"141.40",13.989,23.619,
"141.60",14.01,23.65233,
"141.80",14.027,23.68567,
"142.00",14.04,23.719,
"142.20",14.052,23.75233,
"142.40",14.067,23.78567,
"142.60",14.084,23.81867,
"142.80",14.1,23.852,
"143.00",14.114,23.88533,
"143.20",14.129,23.919,
"143.40",14.139,23.95233,
"143.60",14.154,23.98567,
"143.80",14.17,24.019,
"144.00",14.184,24.05233,
"144.20",14.197,24.08567,
"144.40",14.209,24.119,
"144.60",14.224,24.15233,
"144.80",14.24,24.18567,
"145.00",14.254,24.219,
"145.20",14.27,24.25233,
"145.40",14.286,24.28567,
"145.60",14.301,24.319,
"145.80",14.321,24.35233,
"146.00",14.334,24.38567,
"146.20",14.346,24.41867,
"146.40",14.36,24.45233,
"146.60",14.377,24.48567,
"146.80",14.392,24.519,
"147.00",14.405,24.55233,
"147.20",14.415,24.58567,
"147.40",14.429,24.619,
"147.60",14.441,24.65233,
"147.80",14.456,24.68567,
"148.00",14.469,24.719,
"148.20",14.479,24.75233,
"148.40",14.49,24.78567,
"148.60",14.507,24.819,
"148.80",14.521,24.85233,
"149.00",14.532,24.88567,
"149.20",14.545,24.919,
"149.40",14.556,24.95233,
"149.60",14.567,24.98567,
"149.80",14.583,25.019,
"150.00",14.596,25.05233,
"150.20",14.607,25.08567,
"150.40",14.62,25.119,
"150.60",14.635,25.15233,
"150.80",14.647,25.18567,
"151.00",14.656,25.219,
"151.20",14.668,25.25233,
"151.40",14.682,25.28567,
"151.60",14.697,25.319,
"151.80",14.71,25.35233,
"152.00",14.721,25.386,
"152.20",14.733,25.419,
"152.40",14.743,25.45233,
"152.60",14.759,25.48567,
"152.80",14.771,25.519,
"153.00",14.783,25.55233,
"153.20",14.797,25.58567,
"153.40",14.808,25.619,
"153.60",14.818,25.65233,
"153.80",14.833,25.68567,
"154.00",14.848,25.719,
"154.20",14.861,25.75233,
"154.40",14.87,25.78567,
"154.60",14.884,25.819,
"154.80",14.895,25.85233,
"155.00",14.91,25.88567,
"155.20",14.922,25.919,
"155.40",14.931,25.95233,
"155.60",14.944,25.98567,
"155.80",14.957,26.019,
"156.00",14.966,26.05233,
"156.20",14.975,26.08533,
"156.40",14.988,26.11867,
"156.60",15.005,26.152,
"156.80",15.015,26.18567,
"157.00",15.028,26.21867,
"157.20",15.039,26.25233,
"157.40",15.047,26.28567,
"157.60",15.064,26.319,
"157.80",15.076,26.35233,
"158.00",15.088,26.38567,
"158.20",15.097,26.419,
"158.40",15.106,26.45233,
"158.60",15.12,26.48567,
"158.80",15.133,26.519,
"159.00",15.145,26.55233,
"159.20",15.155,26.58567,
"159.40",15.165,26.619,
"159.60",15.177,26.65233,
"159.80",15.192,26.68567,
"160.00",15.201,26.719,
"160.20",15.215,26.75233,
"160.40",15.226,26.78567,
"160.60",15.239,26.819,
"160.80",15.251,26.85233,
"161.00",15.264,26.88533,
"161.20",15.275,26.919,
"161.40",15.289,26.95233,
"161.60",15.305,26.98567,
"161.80",15.317,27.01867,
"162.00",15.328,27.052,
"162.20",15.339,27.08533,
"162.40",15.351,27.11867,
"162.60",15.367,27.152,
"162.80",15.382,27.18567,
"163.00",15.396,27.21867,
"163.20",15.404,27.252,
"163.40",15.418,27.28533,
"163.60",15.431,27.319,
"163.80",15.44,27.352,
"164.00",15.456,27.38533,
"164.20",15.466,27.41867,
"164.40",15.475,27.45233,
"164.60",15.492,27.48533,
"164.80",15.502,27.519,
"165.00",15.513,27.55233,
"165.20",15.528,27.58567,
"165.40",15.541,27.619,
"165.60",15.553,27.65233,
"165.80",15.564,27.68567,
"166.00",15.576,27.719,
"166.20",15.588,27.75233,
"166.40",15.6,27.78567,
"166.60",15.614,27.819,
"166.80",15.628,27.85233,
"167.00",15.638,27.88567,
"167.20",15.648,27.919,
"167.40",15.658,27.95233,
"167.60",15.672,27.98567,
"167.80",15.688,28.019,
"168.00",15.698,28.05233,
"168.20",15.708,28.08567,
"168.40",15.721,28.119,
"168.60",15.732,28.15233,
"168.80",15.748,28.18567,
"169.00",15.756,28.219,
"169.20",15.767,28.25233,
"169.40",15.782,28.28567,
"169.60",15.789,28.31867,
"169.80",15.805,28.35233,
"170.00",15.819,28.38567,
"170.20",15.824,28.419,
"170.40",15.839,28.45233,
"170.60",15.852,28.48567,
"170.80",15.868,28.519,
"171.00",15.875,28.55233,
"171.20",15.889,28.58533,
"171.40",15.897,28.619,
"171.60",15.91,28.65233,
"171.80",15.92,28.68567,
"172.00",15.933,28.719,
"172.20",15.939,28.75233,
"172.40",15.949,28.78533,
"172.60",15.962,28.81867,
"172.80",15.972,28.85233,
"173.00",15.983,28.88533,
"173.20",15.995,28.919,
"173.40",16.005,28.95233,
"173.60",16.016,28.98533,
"173.80",16.029,29.01867,
"174.00",16.037,29.05233,
"174.20",16.046,29.08567,
"174.40",16.055,29.119,
"174.60",16.069,29.152,
"174.80",16.078,29.18567,
"175.00",16.086,29.219,
"175.20",16.097,29.252,
"175.40",16.11,29.28533,
"175.60",16.121,29.31867,
"175.80",16.131,29.352,
"176.00",16.139,29.38533,
"176.20",16.147,29.41867,
"176.40",16.157,29.45233,
"176.60",16.169,29.48567,
"176.80",16.181,29.519,
"177.00",16.19,29.552,
"177.20",16.198,29.58533,
"177.40",16.208,29.61867,
"177.60",16.219,29.652,
"177.80",16.232,29.68567,
"178.00",16.245,29.719,
"178.20",16.257,29.752,
"178.40",16.27,29.78567,
"178.60",16.282,29.81867,
"178.80",16.295,29.85233,
"179.00",16.307,29.88567,
"179.20",16.317,29.919,
"179.40",16.329,29.95233,
"179.60",16.34,29.98533,
"179.80",16.354,30.01867,
"180.00",16.362,30.052,
"180.20",16.373,30.08533,
"180.40",16.383,30.119,
"180.60",16.4,30.15233,
"180.80",16.416,30.18567,
"181.00",16.428,30.21867,
"181.20",16.438,30.252,
"181.40",16.45,30.28533,
"181.60",16.464,30.31867,
"181.80",16.477,30.352,
"182.00",16.488,30.38533,
"182.20",16.497,30.41867,
"182.40",16.504,30.45233,
"182.60",16.521,30.48533,
"182.80",16.531,30.51867,
"183.00",16.542,30.552,
"183.20",16.547,30.58533,
"183.40",16.556,30.61867,
"183.60",16.568,30.652,
"183.80",16.582,30.68533,
"184.00",16.594,30.71867,
"184.20",16.604,30.75233,
"184.40",16.614,30.78567,
"184.60",16.626,30.81867,
"184.80",16.639,30.85233,
"185.00",16.65,30.88533,
"185.20",16.657,30.91867,
"185.40",16.671,30.95233,
"185.60",16.682,30.98533,
"185.80",16.689,31.019,
"186.00",16.702,31.052,
"186.20",16.709,31.08533,
"186.40",16.717,31.11867,
"186.60",16.731,31.152,
"186.80",16.741,31.18533,
"187.00",16.747,31.21867,
"187.20",16.755,31.252,
"187.40",16.763,31.28567,
"187.60",16.776,31.319,
"187.80",16.788,31.35233,
"188.00",16.801,31.38567,
"188.20",16.805,31.419,
"188.40",16.812,31.45233,
"188.60",16.824,31.48567,
"188.80",16.838,31.51867,
"189.00",16.847,31.552,
"189.20",16.858,31.58567,
"189.40",16.869,31.619,
"189.60",16.877,31.65233,
"189.80",16.887,31.68567,
"190.00",16.9,31.719,
"190.20",16.905,31.75233,
"190.40",16.916,31.78567,
"190.60",16.925,31.819,
"190.80",16.934,31.85233,
"191.00",16.945,31.88567,
"191.20",16.954,31.919,
"191.40",16.961,31.95233,
"191.60",16.973,31.98567,
"191.80",16.984,32.019,
"192.00",16.989,32.052,
"192.20",16.995,32.08533,
"192.40",17.005,32.119,
"192.60",17.015,32.152,
"192.80",17.028,32.18533,
"193.00",17.036,32.21867,
"193.20",17.04,32.252,
"193.40",17.049,32.28534,
"193.60",17.061,32.31867,
"193.80",17.07,32.352,
"194.00",17.079,32.38533,
"194.20",17.086,32.41867,
"194.40",17.094,32.452,
"194.60",17.102,32.48533,
"194.80",17.113,32.51867,
"195.00",17.118,32.552,
"195.20",17.126,32.58567,
"195.40",17.139,32.619,
"195.60",17.149,32.652,
"195.80",17.158,32.68533,
"196.00",17.171,32.719,
"196.20",17.177,32.752,
"196.40",17.187,32.78567,
"196.60",17.199,32.81867,
"196.80",17.213,32.852,
"197.00",17.219,32.88533,
"197.20",17.228,32.91867,
"197.40",17.237,32.952,
"197.60",17.25,32.98533,
"197.80",17.263,33.01867,
"198.00",17.272,33.052,
"198.20",17.283,33.08567,
"198.40",17.294,33.119,
"198.60",17.302,33.152,
"198.80",17.313,33.18533,
"199.00",17.321,33.21867,
"199.20",17.332,33.252,
"199.40",17.341,33.28534,
"199.60",17.35,33.319,
"199.80",17.361,33.35233,
"200.00",17.364,33.38567,
"200.20",17.374,33.419,
"200.40",17.381,33.45234,
"200.60",17.398,33.48567,
"200.80",17.407,33.519,
"201.00",17.416,33.552,
"201.20",17.425,33.58533,
"201.40",17.436,33.61867,
"201.60",17.45,33.652,
"201.80",17.461,33.68533,
"202.00",17.47,33.71867,
"202.20",17.478,33.752,
"202.40",17.489,33.78567,
"202.60",17.501,33.81867,
"202.80",17.512,33.852,
"203.00",17.521,33.88533,
"203.20",17.527,33.91867,
"203.40",17.535,33.95234,
"203.60",17.546,33.98567,
"203.80",17.559,34.019,
"204.00",17.568,34.05233,
"204.20",17.576,34.08533,
"204.40",17.588,34.119,
"204.60",17.602,34.152,
"204.80",17.611,34.18533,
"205.00",17.625,34.21867,
"205.20",17.634,34.252,
"205.40",17.646,34.28534,
"205.60",17.658,34.31867,
"205.80",17.668,34.352,
"206.00",17.68,34.38533,
"206.20",17.687,34.41867,
"206.40",17.702,34.452,
"206.60",17.712,34.48533,
"206.80",17.724,34.51867,
"207.00",17.733,34.552,
"207.20",17.741,34.58533,
"207.40",17.751,34.61867,
"207.60",17.762,34.652,
"207.80",17.774,34.68567,
"208.00",17.781,34.719,
"208.20",17.792,34.75233,
"208.40",17.796,34.78567,
"208.60",17.804,34.81867,
"208.80",17.816,34.852,
"209.00",17.823,34.88567,
"209.20",17.831,34.919,
"209.40",17.839,34.95234,
"209.60",17.849,34.98533,
"209.80",17.861,35.01867,
"210.00",17.871,35.05233,
"210.20",17.88,35.08567,
"210.40",17.894,35.119,
"210.60",17.906,35.152,
"210.80",17.915,35.18533,
"211.00",17.927,35.21867,
"211.20",17.934,35.252,
"211.40",17.945,35.28534,
"211.60",17.956,35.31867,
"211.80",17.964,35.352,
"212.00",17.972,35.38533,
"212.20",17.979,35.41867,
"212.40",17.987,35.45234,
"212.60",17.997,35.48533,
"212.80",18.007,35.51867,
"213.00",18.012,35.552,
"213.20",18.017,35.58533,
"213.40",18.024,35.61867,
"213.60",18.031,35.652,
"213.80",18.039,35.68567,
"214.00",18.045,35.719,
"214.20",18.049,35.752,
"214.40",18.058,35.78534,
"214.60",18.066,35.81867,
"214.80",18.079,35.85233,
"215.00",18.091,35.88533,
"215.20",18.1,35.91867,
"215.40",18.107,35.95234,
"215.60",18.117,35.98567,
"215.80",18.129,36.019,
"216.00",18.136,36.05233,
"216.20",18.143,36.08533,
"216.40",18.15,36.11867,
"216.60",18.161,36.152,
"216.80",18.169,36.18567,
"217.00",18.175,36.219,
"217.20",18.182,36.25233,
"217.40",18.19,36.28567,
"217.60",18.201,36.319,
"217.80",18.213,36.35233,
"218.00",18.22,36.38567,
"218.20",18.226,36.419,
"218.40",18.232,36.45234,
"218.60",18.241,36.48567,
"218.80",18.251,36.519,
"219.00",18.26,36.55233,
"219.20",18.266,36.58533,
"219.40",18.268,36.619,
"219.60",18.277,36.652,
"219.80",18.283,36.68533,
"220.00",18.286,36.719,
"220.20",18.29,36.752,
"220.40",18.293,36.78534,
"220.60",18.301,36.81867,
"220.80",18.31,36.85233,
"221.00",18.312,36.88533,
"221.20",18.317,36.91867,
"221.40",18.323,36.952,
"221.60",18.336,36.98567,
"221.80",18.342,37.01867,
"222.00",18.345,37.052,
"222.20",18.349,37.08567,
"222.40",18.354,37.119,
"222.60",18.365,37.15233,
"222.80",18.372,37.18567,
"223.00",18.376,37.21867,
"223.20",18.378,37.252,
"223.40",18.384,37.28534,
"223.60",18.39,37.31867,
"223.80",18.4,37.35233,
"224.00",18.407,37.38567,
"224.20",18.413,37.419,
"224.40",18.423,37.45234,
"224.60",18.431,37.48533,
"224.80",18.442,37.519,
"225.00",18.448,37.55233,
"225.20",18.456,37.58533,
"225.40",18.464,37.61867,
"225.60",18.472,37.652,
"225.80",18.481,37.68533,
"226.00",18.488,37.71867,
"226.20",18.491,37.752,
"226.40",18.496,37.78534,
"226.60",18.508,37.81867,
"226.80",18.517,37.85233,
"227.00",18.525,37.88567,
"227.20",18.534,37.919,
"227.40",18.541,37.95234,
"227.60",18.552,37.98567,
"227.80",18.565,38.019,
"228.00",18.576,38.05233,
"228.20",18.584,38.08567,
"228.40",18.595,38.119,
"228.60",18.607,38.15233,
"228.80",18.616,38.18567,
"229.00",18.628,38.21867,
"229.20",18.634,38.252,
"229.40",18.643,38.28534,
"229.60",18.653,38.31867,
"229.80",18.661,38.352,
"230.00",18.669,38.38567,
"230.20",18.677,38.41867,
"230.40",18.684,38.45234,
"230.60",18.691,38.48533,
"230.80",18.701,38.51867,
"231.00",18.705,38.552,
"231.20",18.711,38.58567,
"231.40",18.718,38.619,
"231.60",18.723,38.652,
"231.80",18.732,38.68533,
"232.00",18.738,38.719,
"232.20",18.742,38.75233,
"232.40",18.748,38.78567,
"232.60",18.758,38.81867,
"232.80",18.766,38.852,
"233.00",18.772,38.88533,
"233.20",18.776,38.919,
"233.40",18.783,38.952,
"233.60",18.792,38.98533,
"233.80",18.801,39.01867,
"234.00",18.806,39.05233,
"234.20",18.813,39.08567,
"234.40",18.821,39.119,
"234.60",18.827,39.15233,
"234.80",18.834,39.18567,
"235.00",18.842,39.21867,
"235.20",18.847,39.252,
"235.40",18.855,39.28567,
"235.60",18.865,39.319,
"235.80",18.872,39.35233,
"236.00",18.878,39.38567,
"236.20",18.884,39.419,
"236.40",18.895,39.45234,
"236.60",18.906,39.48533,
"236.80",18.912,39.51867,
"237.00",18.917,39.552,
"237.20",18.921,39.58567,
"237.40",18.93,39.619,
"237.60",18.935,39.65233,
"237.80",18.948,39.68533,
"238.00",18.956,39.71867,
"238.20",18.96,39.752,
"238.40",18.967,39.78567,
"238.60",18.982,39.81867,
"238.80",18.991,39.852,
"239.00",19,39.88533,
"239.20",19.007,39.91867,
"239.40",19.014,39.952,
"239.60",19.022,39.98533,
"239.80",19.031,40.01867,
"240.00",19.039,40.052,
"240.20",19.044,40.08533,
"240.40",19.055,40.11867,
"240.60",19.064,40.152,
"240.80",19.074,40.18567,
"241.00",19.077,40.21867,
"241.20",19.087,40.252,
"241.40",19.091,40.28534,
"241.60",19.103,40.319,
"241.80",19.109,40.352,
"242.00",19.113,40.38533,
"242.20",19.117,40.41867,
"242.40",19.124,40.452,
"242.60",19.128,40.48533,
"242.80",19.138,40.519,
"243.00",19.143,40.55233,
"243.20",19.15,40.58567,
"243.40",19.152,40.619,
"243.60",19.159,40.65233,
"243.80",19.165,40.68567,
"244.00",19.17,40.719,
"244.20",19.173,40.75233,
"244.40",19.176,40.78534,
"244.60",19.182,40.81867,
"244.80",19.19,40.852,
"245.00",19.196,40.88533,
"245.20",19.201,40.91867,
"245.40",19.207,40.95234,
"245.60",19.214,40.98567,
"245.80",19.219,41.019,
"246.00",19.222,41.05233,
"246.20",19.224,41.08567,
"246.40",19.227,41.119,
"246.60",19.235,41.15233,
"246.80",19.239,41.18533,
"247.00",19.237,41.21867,
"247.20",19.24,41.252,
"247.40",19.242,41.28534,
"247.60",19.247,41.31867,
"247.80",19.254,41.352,
"248.00",19.256,41.38533,
"248.20",19.258,41.41867,
"248.40",19.26,41.452,
"248.60",19.268,41.48533,
"248.80",19.275,41.51867,
"249.00",19.28,41.552,
"249.20",19.287,41.58533,
"249.40",19.292,41.61867,
"249.60",19.298,41.652,
"249.80",19.31,41.68533,
"250.00",19.318,41.71867,
"250.20",19.324,41.752,
"250.40",19.33,41.78534,
"250.60",19.34,41.81867,
"250.80",19.351,41.852,
"251.00",19.359,41.88533,
"251.20",19.369,41.91867,
"251.40",19.377,41.952,
"251.60",19.393,41.98533,
"251.80",19.405,42.01867,
"252.00",19.413,42.052,
"252.20",19.42,42.08533,
"252.40",19.43,42.11867,
"252.60",19.442,42.152,
"252.80",19.45,42.18533,
"253.00",19.458,42.21867,
"253.20",19.463,42.252,
"253.40",19.47,42.28534,
"253.60",19.478,42.31867,
"253.80",19.484,42.352,
"254.00",19.493,42.38533,
"254.20",19.497,42.41867,
"254.40",19.501,42.45234,
"254.60",19.505,42.48533,
"254.80",19.513,42.51867,
"255.00",19.516,42.552,
"255.20",19.522,42.58533,
"255.40",19.527,42.61867,
"255.60",19.534,42.652,
"255.80",19.542,42.68567,
"256.00",19.543,42.719,
"256.20",19.544,42.75233,
"256.40",19.547,42.78567,
"256.60",19.553,42.81867,
"256.80",19.555,42.85233,
"257.00",19.556,42.88567,
"257.20",19.558,42.91867,
"257.40",19.559,42.952,
"257.60",19.562,42.98533,
"257.80",19.566,43.01867,
"258.00",19.568,43.05233,
"258.20",19.57,43.08567,
"258.40",19.569,43.119,
"258.60",19.577,43.15233,
"258.80",19.58,43.18567,
"259.00",19.582,43.21867,
"259.20",19.585,43.25233,
"259.40",19.586,43.28567,
"259.60",19.591,43.319,
"259.80",19.595,43.35233,
"260.00",19.597,43.38533,
"260.20",19.598,43.419,
"260.40",19.599,43.45234,
"260.60",19.604,43.48567,
"260.80",19.607,43.519,
"261.00",19.608,43.552,
"261.20",19.611,43.58533,
"261.40",19.617,43.619,
"261.60",19.621,43.65233,
"261.80",19.626,43.68533,
"262.00",19.628,43.719,
"262.20",19.628,43.752,
"262.40",19.63,43.78567,
"262.60",19.637,43.81867,
"262.80",19.644,43.85233,
"263.00",19.647,43.88533,
"263.20",19.647,43.91867,
"263.40",19.653,43.952,
"263.60",19.657,43.98533,
"263.80",19.667,44.01867,
"264.00",19.671,44.052,
"264.20",19.674,44.08533,
"264.40",19.679,44.11867,
"264.60",19.683,44.152,
"264.80",19.695,44.18533,
"265.00",19.701,44.21867,
"265.20",19.708,44.252,
"265.40",19.713,44.28534,
"265.60",19.725,44.31867,
"265.80",19.733,44.352,
"266.00",19.737,44.38533,
"266.20",19.744,44.41867,
"266.40",19.75,44.45234,
"266.60",19.759,44.48533,
"266.80",19.768,44.519,
"267.00",19.771,44.55233,
"267.20",19.774,44.58533,
"267.40",19.78,44.61867,
"267.60",19.787,44.652,
"267.80",19.797,44.68533,
"268.00",19.807,44.71867,
"268.20",19.81,44.75233,
"268.40",19.816,44.78567,
"268.60",19.825,44.81867,
"268.80",19.834,44.852,
"269.00",19.842,44.88533,
"269.20",19.849,44.91867,
"269.40",19.859,44.952,
"269.60",19.869,44.98533,
"269.80",19.874,45.01867,
"270.00",19.887,45.052,
"270.20",19.894,45.08533,
"270.40",19.902,45.11867,
"270.60",19.913,45.152,
"270.80",19.922,45.18533,
"271.00",19.927,45.21867,
"271.20",19.931,45.252,
"271.40",19.939,45.28534,
"271.60",19.943,45.319,
"271.80",19.952,45.35233,
"272.00",19.955,45.38567,
"272.20",19.958,45.419,
"272.40",19.967,45.45234,
"272.60",19.974,45.48533,
"272.80",19.981,45.51867,
"273.00",19.987,45.552,
"273.20",19.996,45.58567,
"273.40",20.002,45.619,
"273.60",20.009,45.65233,
"273.80",20.013,45.68567,
"274.00",20.018,45.719,
"274.20",20.022,45.75233,
"274.40",20.031,45.78567,
"274.60",20.034,45.81867,
"274.80",20.041,45.852,
"275.00",20.05,45.88533,
"275.20",20.058,45.919,
"275.40",20.064,45.95234,
"275.60",20.074,45.98567,
"275.80",20.081,46.019,
"276.00",20.088,46.05233,
"276.20",20.095,46.08567,
"276.40",20.105,46.119,
"276.60",20.115,46.15233,
"276.80",20.126,46.18567,
"277.00",20.13,46.21867,
"277.20",20.138,46.25233,
"277.40",20.142,46.28534,
"277.60",20.153,46.31867,
"277.80",20.162,46.35233,
"278.00",20.169,46.38567,
"278.20",20.174,46.419,
"278.40",20.18,46.45234,
"278.60",20.19,46.48533,
"278.80",20.196,46.51867,
"279.00",20.202,46.552,
"279.20",20.207,46.58533,
"279.40",20.213,46.619,
"279.60",20.218,46.65233,
"279.80",20.231,46.68533,
"280.00",20.233,46.71867,
"280.20",20.235,46.75233,
"280.40",20.243,46.78567,
"280.60",20.254,46.819,
"280.80",20.26,46.852,
"281.00",20.264,46.88533,
"281.20",20.27,46.919,
"281.40",20.282,46.952,
"281.60",20.285,46.98533,
"281.80",20.293,47.01867,
"282.00",20.297,47.05233,
"282.20",20.303,47.08533,
"282.40",20.312,47.11867,
"282.60",20.32,47.152,
"282.80",20.328,47.18533,
"283.00",20.336,47.21867,
"283.20",20.339,47.252,
"283.30",20.337,47.26867,