File: exposed_monofilament_10.3cm_10mmpm_12nm_250esh_4.csv
"Test Name","Test Mode","Test Type","Control","Test Speed 1","Test Speed 2","Test Speed 3","Change Point 1","Change Point 2","Disp. Origin","Break and Limit Action","Sensitivity:","Level:"
"","Single","Tensile","Stroke",10,1,1,"Off","Off","Start","Stop",0,1

"Title","Sub title","Comment"
"","",""

"Shape:","Batch Size:","SubBatch Size:"
"Plate",1,1
"Name:","Thickness","Width","Gauge Length",
"Size Unit:","mm","mm","mm",
" 1 - 1","1.0000","1.0000","100.0000",

"Name",
"Parameter",
"Units",
" 1 - 1",

" 1- 1"
"Time","Force","Stroke",
"sec","N","mm",
"0.00",0,0,
"0.20",.005,3.733334E-02,
"0.40",.018,7.433333E-02,
"0.60",.031,.1116667,
"0.80",.046,.1486667,
"1.00",.061,.186,
"1.20",.075,.223,
"1.40",.088,.26,
"1.60",.106,.297,
"1.80",.119,.333,
"2.00",.134,.3686667,
"2.20",.149,.4036667,
"2.40",.162,.4386667,
"2.60",.174,.4733333,
"2.80",.189,.5076667,
"3.00",.201,.5416667,
"3.20",.216,.5756667,
"3.40",.227,.6096667,
"3.60",.243,.6433334,
"3.80",.256,.677,
"4.00",.27,.7106667,
"4.20",.283,.744,
"4.40",.296,.7776667,
"4.60",.309,.8113334,
"4.80",.322,.8446667,
"5.00",.334,.878,
"5.20",.349,.9116667,
"5.40",.362,.9450001,
"5.60",.376,.9786667,
"5.80",.391,1.011667,
"6.00",.4,1.045333,
"6.20",.414,1.078333,
"6.40",.429,1.111667,
"6.60",.44,1.145,
"6.80",.454,1.178667,
"7.00",.466,1.212,
"7.20",.483,1.245333,
"7.40",.498,1.278667,
"7.60",.511,1.312,
"7.80",.523,1.345333,
"8.00",.535,1.378667,
"8.20",.548,1.412,
"8.40",.562,1.445333,
"8.60",.579,1.478667,
"8.80",.591,1.512,
"9.00",.604,1.545333,
"9.20",.615,1.578667,
"9.40",.63,1.612,
"9.60",.645,1.645333,
"9.80",.659,1.678667,
"10.00",.674,1.712333,
"10.20",.685,1.745333,
"10.40",.7,1.778667,
"10.60",.714,1.812333,
"10.80",.728,1.845333,
"11.00",.741,1.879,
"11.20",.755,1.912333,
"11.40",.769,1.945667,
"11.60",.786,1.979,
"11.80",.799,2.012,
"12.00",.811,2.045333,
"12.20",.828,2.078667,
"12.40",.843,2.112,
"12.60",.856,2.145333,
"12.80",.869,2.179,
"13.00",.886,2.212,
"13.20",.902,2.245333,
"13.40",.914,2.278667,
"13.60",.931,2.312,
"13.80",.946,2.345333,
"14.00",.958,2.378667,
"14.20",.976,2.412,
"14.40",.989,2.445333,
"14.60",1.005,2.478667,
"14.80",1.022,2.512,
"15.00",1.035,2.545333,
"15.20",1.051,2.578667,
"15.40",1.07,2.612,
"15.60",1.083,2.645333,
"15.80",1.101,2.678667,
"16.00",1.116,2.712,
"16.20",1.131,2.745333,
"16.40",1.146,2.778667,
"16.60",1.163,2.812,
"16.80",1.179,2.845333,
"17.00",1.193,2.878667,
"17.20",1.211,2.912,
"17.40",1.229,2.945333,
"17.60",1.244,2.978667,
"17.80",1.26,3.012,
"18.00",1.278,3.045333,
"18.20",1.293,3.078667,
"18.40",1.312,3.112,
"18.60",1.328,3.145333,
"18.80",1.345,3.178667,
"19.00",1.362,3.212,
"19.20",1.38,3.245333,
"19.40",1.398,3.278667,
"19.60",1.417,3.312,
"19.80",1.434,3.345333,
"20.00",1.451,3.378667,
"20.20",1.47,3.412,
"20.40",1.488,3.445333,
"20.60",1.506,3.478667,
"20.80",1.525,3.512,
"21.00",1.542,3.545333,
"21.20",1.561,3.578667,
"21.40",1.579,3.612,
"21.60",1.6,3.645333,
"21.80",1.619,3.678667,
"22.00",1.639,3.712,
"22.20",1.659,3.745333,
"22.40",1.679,3.778667,
"22.60",1.701,3.812,
"22.80",1.719,3.845333,
"23.00",1.738,3.878667,
"23.20",1.761,3.912,
"23.40",1.781,3.945333,
"23.60",1.802,3.978667,
"23.80",1.82,4.012,
"24.00",1.842,4.045333,
"24.20",1.862,4.078667,
"24.40",1.887,4.112,
"24.60",1.907,4.145333,
"24.80",1.926,4.178667,
"25.00",1.948,4.212,
"25.20",1.973,4.245333,
"25.40",1.992,4.278666,
"25.60",2.015,4.312,
"25.80",2.037,4.345333,
"26.00",2.059,4.378666,
"26.20",2.084,4.412,
"26.40",2.106,4.445333,
"26.60",2.129,4.478666,
"26.80",2.15,4.512,
"27.00",2.173,4.545333,
"27.20",2.2,4.578667,
"27.40",2.224,4.612,
"27.60",2.245,4.645333,
"27.80",2.269,4.678667,
"28.00",2.295,4.712333,
"28.20",2.318,4.745333,
"28.40",2.343,4.778666,
"28.60",2.368,4.812,
"28.80",2.392,4.845333,
"29.00",2.417,4.878666,
"29.20",2.442,4.912,
"29.40",2.468,4.945333,
"29.60",2.495,4.978666,
"29.80",2.518,5.012,
"30.00",2.545,5.045333,
"30.20",2.572,5.078667,
"30.40",2.601,5.112,
"30.60",2.627,5.145333,
"30.80",2.653,5.178667,
"31.00",2.681,5.212,
"31.20",2.708,5.245333,
"31.40",2.735,5.278666,
"31.60",2.765,5.312,
"31.80",2.788,5.345333,
"32.00",2.819,5.378666,
"32.20",2.848,5.412,
"32.40",2.875,5.445666,
"32.60",2.903,5.478666,
"32.80",2.934,5.512,
"33.00",2.965,5.545666,
"33.20",2.993,5.579,
"33.40",3.023,5.612333,
"33.60",3.05,5.645667,
"33.80",3.075,5.679,
"34.00",3.104,5.712333,
"34.20",3.136,5.745333,
"34.40",3.166,5.778666,
"34.60",3.198,5.812,
"34.80",3.226,5.845333,
"35.00",3.255,5.878666,
"35.20",3.289,5.912,
"35.40",3.316,5.945333,
"35.60",3.348,5.978666,
"35.80",3.381,6.012,
"36.00",3.413,6.045333,
"36.20",3.443,6.078667,
"36.40",3.476,6.112,
"36.60",3.509,6.145333,
"36.80",3.537,6.178667,
"37.00",3.57,6.212,
"37.20",3.601,6.245333,
"37.40",3.635,6.278666,
"37.60",3.666,6.312,
"37.80",3.699,6.345333,
"38.00",3.729,6.378666,
"38.20",3.764,6.412,
"38.40",3.798,6.445333,
"38.60",3.829,6.478666,
"38.80",3.861,6.512,
"39.00",3.894,6.545333,
"39.20",3.926,6.578667,
"39.40",3.963,6.612,
"39.60",3.997,6.645667,
"39.80",4.029,6.678667,
"40.00",4.061,6.712,
"40.20",4.094,6.745333,
"40.40",4.13,6.778666,
"40.60",4.162,6.812,
"40.80",4.199,6.845333,
"41.00",4.235,6.878666,
"41.20",4.265,6.912,
"41.40",4.302,6.945333,
"41.60",4.337,6.978666,
"41.80",4.37,7.012,
"42.00",4.405,7.045333,
"42.20",4.438,7.078667,
"42.40",4.475,7.112,
"42.60",4.51,7.145333,
"42.80",4.542,7.178667,
"43.00",4.578,7.212,
"43.20",4.612,7.245333,
"43.40",4.651,7.278666,
"43.60",4.683,7.312,
"43.80",4.713,7.345333,
"44.00",4.751,7.378666,
"44.20",4.789,7.412,
"44.40",4.823,7.445333,
"44.60",4.859,7.478666,
"44.80",4.893,7.512,
"45.00",4.926,7.545333,
"45.20",4.961,7.578667,
"45.40",4.997,7.612,
"45.60",5.033,7.645333,
"45.80",5.067,7.678667,
"46.00",5.098,7.712333,
"46.20",5.135,7.745333,
"46.40",5.172,7.778666,
"46.60",5.204,7.812,
"46.80",5.238,7.845333,
"47.00",5.273,7.878666,
"47.20",5.306,7.912,
"47.40",5.342,7.945333,
"47.60",5.376,7.978666,
"47.80",5.409,8.012333,
"48.00",5.441,8.045667,
"48.20",5.476,8.078667,
"48.40",5.508,8.112,
"48.60",5.543,8.145333,
"48.80",5.57,8.178666,
"49.00",5.605,8.212,
"49.20",5.641,8.245333,
"49.40",5.674,8.278666,
"49.60",5.707,8.312333,
"49.80",5.739,8.345333,
"50.00",5.77,8.379,
"50.20",5.803,8.412,
"50.40",5.838,8.445333,
"50.60",5.868,8.478666,
"50.80",5.902,8.512,
"51.00",5.933,8.545333,
"51.20",5.968,8.578667,
"51.40",6.002,8.612,
"51.60",6.034,8.645333,
"51.80",6.064,8.678666,
"52.00",6.097,8.712,
"52.20",6.131,8.745333,
"52.40",6.163,8.778666,
"52.60",6.192,8.811999,
"52.80",6.226,8.845333,
"53.00",6.255,8.878667,
"53.20",6.287,8.912,
"53.40",6.318,8.945333,
"53.60",6.349,8.978666,
"53.80",6.377,9.012,
"54.00",6.409,9.045333,
"54.20",6.435,9.078667,
"54.40",6.468,9.112333,
"54.60",6.498,9.145333,
"54.80",6.527,9.179,
"55.00",6.558,9.212333,
"55.20",6.587,9.245667,
"55.40",6.615,9.278666,
"55.60",6.647,9.311999,
"55.80",6.674,9.345333,
"56.00",6.704,9.379,
"56.20",6.733,9.412333,
"56.40",6.76,9.445333,
"56.60",6.786,9.478666,
"56.80",6.816,9.512,
"57.00",6.841,9.545333,
"57.20",6.87,9.578667,
"57.40",6.898,9.612,
"57.60",6.925,9.645333,
"57.80",6.953,9.678666,
"58.00",6.978,9.712333,
"58.20",7.005,9.745667,
"58.40",7.029,9.778666,
"58.60",7.054,9.811999,
"58.80",7.077,9.845333,
"59.00",7.099,9.878667,
"59.20",7.124,9.912,
"59.40",7.153,9.945333,
"59.60",7.177,9.978666,
"59.80",7.202,10.012,
"60.00",7.226,10.04533,
"60.20",7.254,10.07867,
"60.40",7.284,10.112,
"60.60",7.31,10.14567,
"60.80",7.337,10.17867,
"61.00",7.362,10.212,
"61.20",7.391,10.24533,
"61.40",7.418,10.27867,
"61.60",7.444,10.312,
"61.80",7.469,10.34533,
"62.00",7.498,10.37867,
"62.20",7.524,10.412,
"62.40",7.553,10.44533,
"62.60",7.578,10.47867,
"62.80",7.604,10.512,
"63.00",7.629,10.54533,
"63.20",7.657,10.57867,
"63.40",7.681,10.612,
"63.60",7.708,10.64533,
"63.80",7.733,10.67867,
"64.00",7.757,10.712,
"64.20",7.783,10.74533,
"64.40",7.811,10.77867,
"64.60",7.836,10.812,
"64.80",7.862,10.84533,
"65.00",7.887,10.87867,
"65.20",7.911,10.912,
"65.40",7.937,10.94533,
"65.60",7.964,10.97867,
"65.80",7.985,11.012,
"66.00",8.009,11.04533,
"66.20",8.037,11.07867,
"66.40",8.063,11.112,
"66.60",8.088,11.14533,
"66.80",8.112,11.17867,
"67.00",8.14,11.212,
"67.20",8.165,11.24533,
"67.40",8.192,11.27867,
"67.60",8.214,11.312,
"67.80",8.243,11.34533,
"68.00",8.268,11.37867,
"68.20",8.294,11.412,
"68.40",8.322,11.44533,
"68.60",8.345,11.47867,
"68.80",8.365,11.512,
"69.00",8.392,11.54533,
"69.20",8.414,11.57867,
"69.40",8.439,11.612,
"69.60",8.466,11.64533,
"69.80",8.489,11.67867,
"70.00",8.511,11.712,
"70.20",8.534,11.74533,
"70.40",8.56,11.77867,
"70.60",8.582,11.812,
"70.80",8.603,11.84533,
"71.00",8.623,11.87867,
"71.20",8.648,11.912,
"71.40",8.67,11.94533,
"71.60",8.694,11.97867,
"71.80",8.712,12.012,
"72.00",8.733,12.04533,
"72.20",8.756,12.07867,
"72.40",8.777,12.112,
"72.60",8.797,12.14533,
"72.80",8.82,12.17867,
"73.00",8.837,12.212,
"73.20",8.86,12.24533,
"73.40",8.88,12.27867,
"73.60",8.897,12.31233,
"73.80",8.918,12.34567,
"74.00",8.938,12.379,
"74.20",8.96,12.41233,
"74.40",8.985,12.44533,
"74.60",9.005,12.47867,
"74.80",9.026,12.512,
"75.00",9.046,12.54533,
"75.20",9.071,12.57867,
"75.40",9.091,12.612,
"75.60",9.115,12.64533,
"75.80",9.135,12.67867,
"76.00",9.152,12.712,
"76.20",9.172,12.74533,
"76.40",9.192,12.77867,
"76.60",9.211,12.812,
"76.80",9.228,12.84533,
"77.00",9.243,12.87867,
"77.20",9.259,12.912,
"77.40",9.277,12.94533,
"77.60",9.293,12.97867,
"77.80",9.309,13.012,
"78.00",9.328,13.04567,
"78.20",9.35,13.07867,
"78.40",9.368,13.112,
"78.60",9.387,13.14533,
"78.80",9.401,13.17867,
"79.00",9.419,13.212,
"79.20",9.438,13.24533,
"79.40",9.459,13.27867,
"79.60",9.48,13.312,
"79.80",9.498,13.34533,
"80.00",9.515,13.37867,
"80.20",9.536,13.412,
"80.40",9.557,13.44533,
"80.60",9.576,13.47867,
"80.80",9.592,13.512,
"81.00",9.612,13.54533,
"81.20",9.632,13.57867,
"81.40",9.655,13.61167,
"81.60",9.675,13.64533,
"81.80",9.692,13.67867,
"82.00",9.716,13.712,
"82.20",9.738,13.74533,
"82.40",9.759,13.77867,
"82.60",9.782,13.812,
"82.80",9.798,13.84533,
"83.00",9.819,13.87867,
"83.20",9.841,13.912,
"83.40",9.863,13.94533,
"83.60",9.883,13.979,
"83.80",9.901,14.012,
"84.00",9.923,14.04533,
"84.20",9.948,14.07867,
"84.40",9.971,14.112,
"84.60",9.994,14.14533,
"84.80",10.014,14.179,
"85.00",10.032,14.212,
"85.20",10.052,14.24533,
"85.40",10.073,14.27867,
"85.60",10.095,14.31233,
"85.80",10.114,14.34533,
"86.00",10.136,14.379,
"86.20",10.158,14.412,
"86.40",10.181,14.44533,
"86.60",10.2,14.47867,
"86.80",10.22,14.512,
"87.00",10.239,14.54533,
"87.20",10.261,14.57867,
"87.40",10.281,14.612,
"87.60",10.299,14.64567,
"87.80",10.32,14.67867,
"88.00",10.337,14.712,
"88.20",10.357,14.74533,
"88.40",10.376,14.77867,
"88.60",10.394,14.812,
"88.80",10.412,14.84533,
"89.00",10.429,14.87867,
"89.20",10.447,14.912,
"89.40",10.467,14.94533,
"89.60",10.485,14.97867,
"89.80",10.5,15.012,
"90.00",10.518,15.04533,
"90.20",10.534,15.07867,
"90.40",10.552,15.112,
"90.60",10.574,15.14533,
"90.80",10.591,15.17867,
"91.00",10.609,15.212,
"91.20",10.628,15.24533,
"91.40",10.653,15.27867,
"91.60",10.669,15.312,
"91.80",10.687,15.34533,
"92.00",10.709,15.37867,
"92.20",10.732,15.412,
"92.40",10.753,15.44533,
"92.60",10.772,15.47867,
"92.80",10.791,15.512,
"93.00",10.807,15.54533,
"93.20",10.829,15.57867,
"93.40",10.85,15.612,
"93.60",10.869,15.64533,
"93.80",10.886,15.67867,
"94.00",10.906,15.712,
"94.20",10.926,15.74533,
"94.40",10.948,15.77867,
"94.60",10.967,15.812,
"94.80",10.983,15.84533,
"95.00",11.003,15.87867,
"95.20",11.023,15.912,
"95.40",11.042,15.94533,
"95.60",11.064,15.97867,
"95.80",11.08,16.012,
"96.00",11.101,16.045,
"96.20",11.118,16.07867,
"96.40",11.137,16.11167,
"96.60",11.151,16.145,
"96.80",11.172,16.17867,
"97.00",11.188,16.212,
"97.20",11.204,16.24533,
"97.40",11.225,16.27867,
"97.60",11.243,16.312,
"97.80",11.255,16.34534,
"98.00",11.272,16.37867,
"98.20",11.289,16.412,
"98.40",11.309,16.44533,
"98.60",11.322,16.47867,
"98.80",11.343,16.512,
"99.00",11.356,16.54533,
"99.20",11.37,16.57867,
"99.40",11.387,16.612,
"99.60",11.407,16.64533,
"99.80",11.419,16.67867,
"100.00",11.438,16.712,
"100.20",11.452,16.74533,
"100.40",11.474,16.77867,
"100.60",11.49,16.812,
"100.80",11.508,16.84534,
"101.00",11.52,16.87867,
"101.20",11.534,16.912,
"101.40",11.555,16.94533,
"101.60",11.571,16.97867,
"101.80",11.588,17.012,
"102.00",11.605,17.04533,
"102.20",11.622,17.07867,
"102.40",11.642,17.112,
"102.60",11.657,17.14533,
"102.80",11.676,17.17867,
"103.00",11.694,17.212,
"103.20",11.713,17.24533,
"103.40",11.733,17.27867,
"103.60",11.751,17.312,
"103.80",11.766,17.34534,
"104.00",11.783,17.37867,
"104.20",11.804,17.412,
"104.40",11.825,17.44533,
"104.60",11.843,17.47867,
"104.80",11.861,17.512,
"105.00",11.881,17.54533,
"105.20",11.899,17.57867,
"105.40",11.92,17.612,
"105.60",11.939,17.64533,
"105.80",11.953,17.67867,
"106.00",11.972,17.712,
"106.20",11.989,17.74533,
"106.40",12.008,17.77867,
"106.60",12.026,17.812,
"106.80",12.041,17.84534,
"107.00",12.056,17.87867,
"107.20",12.074,17.912,
"107.40",12.091,17.94533,
"107.60",12.105,17.97867,
"107.80",12.123,18.012,
"108.00",12.139,18.04533,
"108.20",12.15,18.07867,
"108.40",12.17,18.112,
"108.60",12.185,18.14533,
"108.80",12.198,18.17867,
"109.00",12.215,18.212,
"109.20",12.23,18.245,
"109.40",12.248,18.27867,
"109.60",12.263,18.312,
"109.80",12.28,18.34534,
"110.00",12.293,18.37867,
"110.20",12.313,18.412,
"110.40",12.33,18.445,
"110.60",12.347,18.47833,
"110.80",12.363,18.512,
"111.00",12.377,18.54533,
"111.20",12.391,18.57867,
"111.40",12.41,18.61167,
"111.60",12.424,18.64533,
"111.80",12.438,18.67867,
"112.00",12.453,18.712,
"112.20",12.47,18.74533,
"112.40",12.488,18.77833,
"112.60",12.502,18.81167,
"112.80",12.515,18.845,
"113.00",12.532,18.87867,
"113.20",12.547,18.91167,
"113.40",12.563,18.94533,
"113.60",12.577,18.97867,
"113.80",12.59,19.012,
"114.00",12.603,19.04533,
"114.20",12.619,19.07867,
"114.40",12.636,19.112,
"114.60",12.651,19.145,
"114.80",12.667,19.17867,
"115.00",12.682,19.212,
"115.20",12.697,19.24533,
"115.40",12.716,19.27867,
"115.60",12.735,19.312,
"115.80",12.75,19.34534,
"116.00",12.765,19.37867,
"116.20",12.786,19.412,
"116.40",12.802,19.44533,
"116.60",12.818,19.47833,
"116.80",12.838,19.51167,
"117.00",12.852,19.54533,
"117.20",12.871,19.57867,
"117.40",12.891,19.612,
"117.60",12.908,19.64533,
"117.80",12.923,19.67867,
"118.00",12.939,19.712,
"118.20",12.958,19.74533,
"118.40",12.977,19.77867,
"118.60",12.994,19.812,
"118.80",13.006,19.84534,
"119.00",13.023,19.87867,
"119.20",13.038,19.912,
"119.40",13.055,19.94533,
"119.60",13.073,19.97867,
"119.80",13.087,20.012,
"120.00",13.101,20.04567,
"120.20",13.117,20.079,
"120.40",13.133,20.112,
"120.60",13.149,20.14533,
"120.80",13.162,20.17867,
"121.00",13.175,20.212,
"121.20",13.192,20.24533,
"121.40",13.209,20.27867,
"121.60",13.221,20.312,
"121.80",13.232,20.34534,
"122.00",13.247,20.37867,
"122.20",13.261,20.412,
"122.40",13.275,20.44533,
"122.60",13.289,20.47867,
"122.80",13.301,20.51167,
"123.00",13.314,20.545,
"123.20",13.33,20.57833,
"123.40",13.345,20.61167,
"123.60",13.36,20.645,
"123.80",13.369,20.67833,
"124.00",13.385,20.71167,
"124.20",13.4,20.745,
"124.40",13.418,20.77833,
"124.60",13.43,20.81167,
"124.80",13.44,20.845,
"125.00",13.452,20.87833,
"125.20",13.468,20.91167,
"125.40",13.483,20.945,
"125.60",13.496,20.97833,
"125.80",13.508,21.01167,
"126.00",13.517,21.04533,
"126.20",13.527,21.07867,
"126.40",13.544,21.112,
"126.60",13.555,21.14533,
"126.80",13.567,21.17867,
"127.00",13.578,21.212,
"127.20",13.593,21.245,
"127.40",13.605,21.27833,
"127.60",13.619,21.31167,
"127.80",13.63,21.345,
"128.00",13.644,21.37867,
"128.20",13.661,21.41167,
"128.40",13.675,21.445,
"128.60",13.687,21.47867,
"128.80",13.699,21.512,
"129.00",13.711,21.54533,
"129.20",13.726,21.57867,
"129.40",13.738,21.612,
"129.60",13.749,21.64533,
"129.80",13.758,21.67867,
"130.00",13.769,21.712,
"130.20",13.78,21.745,
"130.40",13.792,21.77833,
"130.60",13.804,21.812,
"130.80",13.813,21.84534,
"131.00",13.823,21.87867,
"131.20",13.836,21.91167,
"131.40",13.847,21.945,
"131.60",13.857,21.97833,
"131.80",13.863,22.01167,
"132.00",13.868,22.04533,
"132.20",13.883,22.07833,
"132.40",13.89,22.112,
"132.60",13.9,22.145,
"132.80",13.907,22.17833,
"133.00",13.916,22.212,
"133.20",13.923,22.24533,
"133.40",13.93,22.27867,
"133.60",13.937,22.312,
"133.80",13.945,22.34534,
"134.00",13.955,22.37867,
"134.20",13.964,22.412,
"134.40",13.979,22.44533,
"134.60",13.992,22.47833,
"134.80",14.004,22.512,
"135.00",14.017,22.54533,
"135.20",14.034,22.57867,
"135.40",14.05,22.612,
"135.60",14.068,22.64533,
"135.80",14.083,22.67867,
"136.00",14.096,22.71167,
"136.20",14.114,22.74533,
"136.40",14.134,22.77833,
"136.60",14.147,22.81167,
"136.80",14.163,22.84534,
"137.00",14.176,22.87867,
"137.20",14.196,22.91167,
"137.40",14.214,22.945,
"137.60",14.228,22.97833,
"137.80",14.242,23.01167,
"138.00",14.255,23.045,
"138.20",14.271,23.07833,
"138.40",14.289,23.112,
"138.60",14.3,23.145,
"138.80",14.316,23.17833,
"139.00",14.328,23.212,
"139.20",14.341,23.24533,
"139.40",14.359,23.27867,
"139.60",14.372,23.312,
"139.80",14.387,23.34534,
"140.00",14.399,23.37867,
"140.20",14.415,23.412,
"140.40",14.431,23.44533,
"140.60",14.446,23.47867,
"140.80",14.458,23.512,
"141.00",14.47,23.54533,
"141.20",14.484,23.57867,
"141.40",14.5,23.61167,
"141.60",14.513,23.645,
"141.80",14.523,23.67833,
"142.00",14.535,23.71167,
"142.20",14.549,23.74533,
"142.40",14.564,23.77833,
"142.60",14.575,23.81167,
"142.80",14.583,23.845,
"143.00",14.593,23.87867,
"143.20",14.609,23.912,
"143.40",14.622,23.94533,
"143.60",14.632,23.97867,
"143.80",14.644,24.01167,
"144.00",14.656,24.04533,
"144.20",14.665,24.07833,
"144.40",14.678,24.11167,
"144.60",14.686,24.145,
"144.80",14.693,24.17833,
"145.00",14.699,24.212,
"145.20",14.709,24.24533,
"145.40",14.718,24.27867,
"145.60",14.723,24.312,
"145.80",14.727,24.34534,
"146.00",14.733,24.37867,
"146.20",14.738,24.412,
"146.40",14.742,24.44533,
"146.60",14.75,24.47867,
"146.80",14.758,24.512,
"147.00",14.769,24.54533,
"147.20",14.777,24.57833,
"147.40",14.788,24.612,
"147.60",14.796,24.64533,
"147.80",14.802,24.67867,
"148.00",14.807,24.712,
"148.20",14.815,24.74533,
"148.40",14.824,24.77867,
"148.60",14.832,24.812,
"148.80",14.84,24.84534,
"149.00",14.846,24.87867,
"149.20",14.852,24.912,
"149.40",14.863,24.94533,
"149.60",14.876,24.97867,
"149.80",14.883,25.012,
"150.00",14.891,25.04533,
"150.20",14.904,25.07867,
"150.40",14.916,25.11167,
"150.60",14.927,25.145,
"150.80",14.934,25.17867,
"151.00",14.941,25.212,
"151.20",14.952,25.24533,
"151.40",14.965,25.27833,
"151.60",14.973,25.31167,
"151.80",14.983,25.345,
"152.00",14.996,25.37833,
"152.20",15.007,25.412,
"152.40",15.02,25.445,
"152.60",15.033,25.47833,
"152.80",15.044,25.51167,
"153.00",15.056,25.54533,
"153.20",15.072,25.57867,
"153.40",15.088,25.612,
"153.60",15.099,25.64533,
"153.80",15.11,25.67867,
"154.00",15.121,25.712,
"154.20",15.137,25.745,
"154.40",15.15,25.77867,
"154.60",15.165,25.812,
"154.80",15.18,25.84534,
"155.00",15.191,25.87867,
"155.20",15.201,25.912,
"155.40",15.218,25.94533,
"155.60",15.232,25.97867,
"155.80",15.241,26.012,
"156.00",15.252,26.04533,
"156.20",15.262,26.07867,
"156.40",15.274,26.112,
"156.60",15.286,26.14533,
"156.80",15.297,26.17867,
"157.00",15.31,26.212,
"157.20",15.321,26.24533,
"157.40",15.336,26.27867,
"157.60",15.349,26.312,
"157.80",15.357,26.34534,
"158.00",15.37,26.37833,
"158.20",15.384,26.41167,
"158.40",15.399,26.44533,
"158.60",15.408,26.47833,
"158.80",15.42,26.512,
"159.00",15.428,26.54533,
"159.20",15.44,26.57867,
"159.40",15.454,26.612,
"159.60",15.463,26.64533,
"159.80",15.471,26.67867,
"160.00",15.479,26.712,
"160.20",15.488,26.74533,
"160.40",15.505,26.77867,
"160.60",15.518,26.812,
"160.80",15.531,26.84534,
"161.00",15.543,26.87867,
"161.20",15.557,26.912,
"161.40",15.572,26.94533,
"161.60",15.587,26.97867,
"161.80",15.6,27.012,
"162.00",15.615,27.04533,
"162.20",15.63,27.07833,
"162.40",15.645,27.11167,
"162.60",15.658,27.145,
"162.80",15.669,27.17867,
"163.00",15.684,27.212,
"163.20",15.698,27.24533,
"163.40",15.711,27.27867,
"163.60",15.721,27.312,
"163.80",15.73,27.34534,
"164.00",15.741,27.37867,
"164.20",15.753,27.412,
"164.40",15.769,27.44533,
"164.60",15.777,27.47867,
"164.80",15.788,27.512,
"165.00",15.796,27.54533,
"165.20",15.809,27.57867,
"165.40",15.823,27.612,
"165.60",15.829,27.645,
"165.80",15.84,27.67833,
"166.00",15.849,27.712,
"166.20",15.858,27.74533,
"166.40",15.868,27.77833,
"166.60",15.878,27.812,
"166.80",15.888,27.84534,
"167.00",15.897,27.87867,
"167.20",15.905,27.912,
"167.40",15.919,27.945,
"167.60",15.929,27.97833,
"167.80",15.936,28.012,
"168.00",15.944,28.04533,
"168.20",15.958,28.07867,
"168.40",15.971,28.112,
"168.60",15.979,28.14533,
"168.80",15.988,28.17867,
"169.00",15.993,28.212,
"169.20",16.002,28.245,
"169.40",16.017,28.27833,
"169.60",16.026,28.312,
"169.80",16.032,28.34534,
"170.00",16.038,28.37867,
"170.20",16.048,28.412,
"170.40",16.058,28.44533,
"170.60",16.066,28.47833,
"170.80",16.073,28.512,
"171.00",16.078,28.54533,
"171.20",16.09,28.57833,
"171.40",16.099,28.612,
"171.60",16.106,28.64533,
"171.80",16.114,28.67833,
"172.00",16.123,28.712,
"172.20",16.132,28.745,
"172.40",16.142,28.77833,
"172.60",16.15,28.812,
"172.80",16.159,28.84534,
"173.00",16.168,28.87867,
"173.20",16.177,28.912,
"173.40",16.19,28.94533,
"173.60",16.204,28.97867,
"173.80",16.21,29.012,
"174.00",16.221,29.04533,
"174.20",16.234,29.07833,
"174.40",16.243,29.11167,
"174.60",16.252,29.145,
"174.80",16.261,29.17833,
"175.00",16.271,29.212,
"175.20",16.284,29.245,
"175.40",16.294,29.27833,
"175.60",16.305,29.31167,
"175.80",16.314,29.34534,
"176.00",16.322,29.37867,
"176.20",16.334,29.412,
"176.40",16.347,29.44533,
"176.60",16.357,29.47833,
"176.80",16.367,29.512,
"177.00",16.378,29.54533,
"177.20",16.39,29.57867,
"177.40",16.404,29.61167,
"177.60",16.414,29.645,
"177.80",16.423,29.67867,
"178.00",16.434,29.712,
"178.20",16.443,29.74533,
"178.40",16.455,29.77867,
"178.60",16.464,29.812,
"178.80",16.469,29.845,
"179.00",16.477,29.87867,
"179.20",16.488,29.912,
"179.40",16.498,29.945,
"179.60",16.509,29.97833,
"179.80",16.515,30.012,
"180.00",16.523,30.04533,
"180.20",16.535,30.07867,
"180.40",16.547,30.112,
"180.60",16.557,30.14533,
"180.80",16.562,30.17833,
"181.00",16.57,30.21167,
"181.20",16.577,30.245,
"181.40",16.589,30.27833,
"181.60",16.6,30.31167,
"181.80",16.607,30.345,
"182.00",16.614,30.37867,
"182.20",16.628,30.41167,
"182.40",16.638,30.445,
"182.60",16.648,30.47833,
"182.80",16.655,30.51167,
"183.00",16.663,30.545,
"183.20",16.674,30.57833,
"183.40",16.686,30.612,
"183.60",16.695,30.64533,
"183.80",16.7,30.67867,
"184.00",16.707,30.712,
"184.20",16.721,30.745,
"184.40",16.733,30.77833,
"184.60",16.742,30.81167,
"184.80",16.748,30.845,
"185.00",16.755,30.87833,
"185.20",16.767,30.91167,
"185.40",16.778,30.945,
"185.60",16.79,30.97833,
"185.80",16.799,31.012,
"186.00",16.806,31.04533,
"186.20",16.817,31.07867,
"186.40",16.832,31.11167,
"186.60",16.841,31.145,
"186.80",16.85,31.17833,
"187.00",16.861,31.21167,
"187.20",16.871,31.24533,
"187.40",16.885,31.27833,
"187.60",16.892,31.31167,
"187.80",16.9,31.345,
"188.00",16.91,31.37867,
"188.20",16.923,31.412,
"188.40",16.932,31.44533,
"188.60",16.942,31.47867,
"188.80",16.95,31.51167,
"189.00",16.96,31.54533,
"189.20",16.969,31.57867,
"189.40",16.983,31.612,
"189.60",16.996,31.64533,
"189.80",17.001,31.67867,
"190.00",17.011,31.712,
"190.20",17.02,31.74533,
"190.40",17.034,31.77867,
"190.60",17.044,31.812,
"190.80",17.051,31.84534,
"191.00",17.057,31.87833,
"191.20",17.065,31.912,
"191.40",17.077,31.945,
"191.60",17.085,31.97833,
"191.80",17.094,32.01167,
"192.00",17.102,32.045,
"192.20",17.114,32.07867,
"192.40",17.121,32.11167,
"192.60",17.127,32.145,
"192.80",17.132,32.17833,
"193.00",17.14,32.212,
"193.20",17.148,32.245,
"193.40",17.155,32.27834,
"193.60",17.161,32.31167,
"193.80",17.168,32.345,
"194.00",17.175,32.37833,
"194.20",17.185,32.41167,
"194.40",17.195,32.445,
"194.60",17.204,32.47833,
"194.80",17.208,32.51167,
"195.00",17.212,32.545,
"195.20",17.217,32.57833,
"195.40",17.228,32.61167,
"195.60",17.236,32.645,
"195.80",17.241,32.67867,
"196.00",17.246,32.712,
"196.20",17.25,32.74533,
"196.40",17.259,32.77834,
"196.60",17.269,32.81167,
"196.80",17.274,32.845,
"197.00",17.28,32.87867,
"197.20",17.29,32.91167,
"197.40",17.298,32.945,
"197.60",17.306,32.97833,
"197.80",17.313,33.01167,
"198.00",17.319,33.045,
"198.20",17.333,33.07833,
"198.40",17.344,33.11167,
"198.60",17.35,33.145,
"198.80",17.355,33.17833,
"199.00",17.363,33.21167,
"199.20",17.371,33.245,
"199.40",17.381,33.27834,
"199.60",17.392,33.31167,
"199.80",17.396,33.345,
"200.00",17.402,33.37833,
"200.20",17.412,33.41167,
"200.40",17.424,33.445,
"200.60",17.435,33.47833,
"200.80",17.44,33.51167,
"201.00",17.449,33.545,
"201.20",17.456,33.57833,
"201.40",17.463,33.61134,
"201.60",17.472,33.64467,
"201.80",17.477,33.67833,
"202.00",17.483,33.71167,
"202.20",17.491,33.745,
"202.40",17.498,33.77834,
"202.60",17.505,33.81167,
"202.80",17.512,33.845,
"203.00",17.518,33.87833,
"203.20",17.525,33.91167,
"203.40",17.533,33.945,
"203.60",17.537,33.97833,
"203.80",17.542,34.012,
"204.00",17.548,34.04533,
"204.20",17.557,34.07867,
"204.40",17.57,34.11167,
"204.60",17.576,34.14533,
"204.80",17.58,34.17867,
"205.00",17.587,34.21167,
"205.20",17.593,34.245,
"205.40",17.605,34.27834,
"205.60",17.612,34.31167,
"205.80",17.619,34.345,
"206.00",17.625,34.37833,
"206.20",17.636,34.41167,
"206.40",17.643,34.445,
"206.60",17.649,34.47833,
"206.80",17.657,34.51167,
"207.00",17.664,34.545,
"207.20",17.673,34.57833,
"207.40",17.685,34.61167,
"207.60",17.694,34.645,
"207.80",17.699,34.67833,
"208.00",17.708,34.712,
"208.20",17.717,34.745,
"208.40",17.727,34.77834,
"208.60",17.733,34.81167,
"208.80",17.738,34.845,
"209.00",17.746,34.87833,
"209.20",17.755,34.912,
"209.40",17.765,34.945,
"209.60",17.768,34.97833,
"209.80",17.774,35.01167,
"210.00",17.781,35.045,
"210.20",17.789,35.07833,
"210.40",17.798,35.11167,
"210.60",17.808,35.145,
"210.80",17.812,35.17833,
"211.00",17.817,35.21167,
"211.20",17.825,35.245,
"211.40",17.835,35.27834,
"211.60",17.843,35.31167,
"211.80",17.848,35.345,
"212.00",17.858,35.37867,
"212.20",17.866,35.41167,
"212.40",17.873,35.445,
"212.60",17.883,35.47833,
"212.80",17.892,35.51167,
"213.00",17.899,35.54533,
"213.20",17.911,35.57867,
"213.40",17.921,35.612,
"213.60",17.926,35.64533,
"213.80",17.935,35.67867,
"214.00",17.944,35.712,
"214.20",17.955,35.74533,
"214.40",17.968,35.77867,
"214.60",17.976,35.81167,
"214.80",17.982,35.84533,
"215.00",17.992,35.87867,
"215.20",18.001,35.912,
"215.40",18.009,35.945,
"215.60",18.019,35.97833,
"215.80",18.023,36.01167,
"216.00",18.027,36.04533,
"216.20",18.035,36.07833,
"216.40",18.043,36.112,
"216.60",18.048,36.145,
"216.80",18.051,36.17833,
"217.00",18.054,36.21167,
"217.20",18.06,36.245,
"217.40",18.069,36.27834,
"217.60",18.073,36.31167,
"217.80",18.073,36.345,
"218.00",18.079,36.37833,
"218.20",18.088,36.41167,
"218.40",18.096,36.445,
"218.60",18.102,36.47833,
"218.80",18.11,36.51167,
"219.00",18.114,36.545,
"219.20",18.123,36.57833,
"219.40",18.132,36.61167,
"219.60",18.141,36.645,
"219.80",18.146,36.67833,
"220.00",18.148,36.71167,
"220.20",18.156,36.745,
"220.40",18.167,36.77834,
"220.60",18.173,36.81167,
"220.80",18.178,36.845,
"221.00",18.184,36.87833,
"221.20",18.19,36.91167,
"221.40",18.2,36.945,
"221.60",18.21,36.97833,
"221.80",18.214,37.01167,
"222.00",18.222,37.045,
"222.20",18.231,37.07833,
"222.40",18.24,37.11167,
"222.60",18.246,37.145,
"222.80",18.251,37.17833,
"223.00",18.257,37.212,
"223.20",18.264,37.245,
"223.40",18.273,37.27834,
"223.60",18.282,37.31167,
"223.80",18.283,37.345,
"224.00",18.285,37.378,
"224.20",18.293,37.41133,
"224.40",18.302,37.44467,
"224.60",18.31,37.478,
"224.80",18.313,37.51133,
"225.00",18.317,37.545,
"225.20",18.323,37.57833,
"225.40",18.334,37.61167,
"225.60",18.341,37.645,
"225.80",18.348,37.67833,
"226.00",18.353,37.71167,
"226.20",18.363,37.745,
"226.40",18.37,37.77834,
"226.60",18.378,37.81167,
"226.80",18.385,37.84533,
"227.00",18.392,37.87867,
"227.20",18.4,37.91167,
"227.40",18.409,37.945,
"227.60",18.416,37.97833,
"227.80",18.421,38.01167,
"228.00",18.424,38.045,
"228.20",18.436,38.07833,
"228.40",18.442,38.11167,
"228.60",18.447,38.145,
"228.80",18.452,38.17833,
"229.00",18.459,38.21167,
"229.20",18.465,38.245,
"229.40",18.473,38.27867,
"229.60",18.478,38.312,
"229.80",18.48,38.345,
"230.00",18.484,38.37867,
"230.20",18.494,38.41167,
"230.40",18.5,38.445,
"230.60",18.506,38.47833,
"230.80",18.512,38.51167,
"231.00",18.516,38.54533,
"231.20",18.521,38.57833,
"231.40",18.532,38.612,
"231.60",18.536,38.64533,
"231.80",18.539,38.67867,
"232.00",18.542,38.712,
"232.15",18.54,38.73667,