File: exposed_monofilament_10cm_10mmpm_24nm_250esh_11.csv
"Test Name","Test Mode","Test Type","Control","Test Speed 1","Test Speed 2","Test Speed 3","Change Point 1","Change Point 2","Disp. Origin","Break and Limit Action","Sensitivity:","Level:"
"","Single","Tensile","Stroke",10,1,1,"Off","Off","Start","Stop",0,1

"Title","Sub title","Comment"
"","",""

"Shape:","Batch Size:","SubBatch Size:"
"Plate",1,1
"Name:","Thickness","Width","Gauge Length",
"Size Unit:","mm","mm","mm",
" 1 - 1","1.0000","1.0000","100.0000",

"Name",
"Parameter",
"Units",
" 1 - 1",

" 1- 1"
"Time","Force","Stroke",
"sec","N","mm",
"0.00",.001,0,
"0.20",.005,3.733333E-02,
"0.40",.02,7.466666E-02,
"0.60",.033,.1116667,
"0.80",.045,.1486667,
"1.00",.061,.186,
"1.20",.072,.223,
"1.40",.087,.26,
"1.60",.101,.297,
"1.80",.116,.334,
"2.00",.127,.371,
"2.20",.138,.4066667,
"2.40",.153,.4423333,
"2.60",.167,.4773333,
"2.80",.177,.512,
"3.00",.192,.5466667,
"3.20",.205,.581,
"3.40",.215,.615,
"3.60",.229,.649,
"3.80",.242,.6826667,
"4.00",.254,.7166666,
"4.20",.264,.7503333,
"4.40",.28,.7836667,
"4.60",.292,.8173333,
"4.80",.305,.8506666,
"5.00",.317,.884,
"5.20",.33,.9176667,
"5.40",.344,.951,
"5.60",.355,.9846666,
"5.80",.369,1.018,
"6.00",.382,1.051333,
"6.20",.39,1.084667,
"6.40",.406,1.118,
"6.60",.42,1.151333,
"6.80",.433,1.184667,
"7.00",.444,1.218,
"7.20",.458,1.251333,
"7.40",.473,1.284667,
"7.60",.485,1.318,
"7.80",.498,1.351333,
"8.00",.511,1.384667,
"8.20",.524,1.418,
"8.40",.535,1.451333,
"8.60",.552,1.484667,
"8.80",.566,1.518,
"9.00",.579,1.551,
"9.20",.594,1.584333,
"9.40",.603,1.618,
"9.60",.619,1.651333,
"9.80",.631,1.684667,
"10.00",.648,1.718,
"10.20",.657,1.751333,
"10.40",.674,1.784667,
"10.60",.683,1.818,
"10.80",.7,1.851333,
"11.00",.713,1.884667,
"11.20",.726,1.918,
"11.40",.737,1.951333,
"11.60",.755,1.984667,
"11.80",.769,2.018,
"12.00",.784,2.051333,
"12.20",.797,2.084667,
"12.40",.812,2.118333,
"12.60",.826,2.151667,
"12.80",.842,2.185,
"13.00",.855,2.218,
"13.20",.869,2.251333,
"13.40",.883,2.284667,
"13.60",.898,2.318333,
"13.80",.914,2.351333,
"14.00",.931,2.385,
"14.20",.944,2.418,
"14.40",.957,2.451667,
"14.60",.974,2.485,
"14.80",.989,2.518,
"15.00",1.003,2.551333,
"15.20",1.018,2.584667,
"15.40",1.036,2.618,
"15.60",1.051,2.651667,
"15.80",1.067,2.684667,
"16.00",1.08,2.718,
"16.20",1.097,2.751333,
"16.40",1.112,2.785,
"16.60",1.128,2.818333,
"16.80",1.145,2.851667,
"17.00",1.161,2.885,
"17.20",1.174,2.918334,
"17.40",1.191,2.951667,
"17.60",1.21,2.985,
"17.80",1.225,3.018333,
"18.00",1.242,3.051667,
"18.20",1.26,3.085,
"18.40",1.276,3.118333,
"18.60",1.29,3.151667,
"18.80",1.307,3.184667,
"19.00",1.325,3.218,
"19.20",1.341,3.251333,
"19.40",1.358,3.284667,
"19.60",1.377,3.318,
"19.80",1.394,3.351333,
"20.00",1.414,3.384667,
"20.20",1.429,3.418,
"20.40",1.445,3.451334,
"20.60",1.463,3.484667,
"20.80",1.482,3.518,
"21.00",1.499,3.551333,
"21.20",1.517,3.584667,
"21.40",1.535,3.618333,
"21.60",1.554,3.651333,
"21.80",1.575,3.685,
"22.00",1.59,3.718333,
"22.20",1.611,3.751667,
"22.40",1.629,3.785,
"22.60",1.648,3.818333,
"22.80",1.667,3.851333,
"23.00",1.684,3.884667,
"23.20",1.705,3.918334,
"23.40",1.723,3.951334,
"23.60",1.743,3.984667,
"23.80",1.762,4.018333,
"24.00",1.783,4.051667,
"24.20",1.804,4.084667,
"24.40",1.821,4.118333,
"24.60",1.841,4.151333,
"24.80",1.862,4.184667,
"25.00",1.882,4.218,
"25.20",1.904,4.251333,
"25.40",1.923,4.284667,
"25.60",1.948,4.318,
"25.80",1.966,4.351333,
"26.00",1.99,4.385,
"26.20",2.008,4.418333,
"26.40",2.028,4.451666,
"26.60",2.053,4.485,
"26.80",2.075,4.518333,
"27.00",2.099,4.551333,
"27.20",2.115,4.584667,
"27.40",2.137,4.618,
"27.60",2.161,4.651333,
"27.80",2.186,4.684667,
"28.00",2.207,4.718333,
"28.20",2.232,4.751333,
"28.40",2.253,4.784667,
"28.60",2.274,4.818,
"28.80",2.299,4.851333,
"29.00",2.324,4.884666,
"29.20",2.348,4.918,
"29.40",2.37,4.951333,
"29.60",2.392,4.984666,
"29.80",2.42,5.018,
"30.00",2.441,5.051333,
"30.20",2.467,5.085,
"30.40",2.492,5.118,
"30.60",2.52,5.151333,
"30.80",2.54,5.184667,
"31.00",2.565,5.218,
"31.20",2.591,5.251333,
"31.40",2.617,5.284667,
"31.60",2.643,5.318,
"31.80",2.671,5.351333,
"32.00",2.696,5.384666,
"32.20",2.72,5.418,
"32.40",2.743,5.451333,
"32.60",2.774,5.484666,
"32.80",2.801,5.518,
"33.00",2.827,5.551333,
"33.20",2.855,5.584667,
"33.40",2.88,5.618,
"33.60",2.912,5.651333,
"33.80",2.939,5.684667,
"34.00",2.965,5.718,
"34.20",2.995,5.751667,
"34.40",3.019,5.784667,
"34.60",3.049,5.818,
"34.80",3.078,5.851333,
"35.00",3.105,5.884666,
"35.20",3.134,5.918,
"35.40",3.161,5.951333,
"35.60",3.189,5.984666,
"35.80",3.221,6.018,
"36.00",3.247,6.051333,
"36.20",3.274,6.085,
"36.40",3.305,6.118333,
"36.60",3.334,6.151667,
"36.80",3.366,6.184667,
"37.00",3.393,6.218,
"37.20",3.422,6.251667,
"37.40",3.45,6.284667,
"37.60",3.483,6.318333,
"37.80",3.507,6.351666,
"38.00",3.532,6.385,
"38.20",3.558,6.418333,
"38.40",3.583,6.451666,
"38.60",3.609,6.485,
"38.80",3.638,6.518333,
"39.00",3.664,6.551667,
"39.20",3.683,6.585,
"39.40",3.708,6.618333,
"39.60",3.741,6.651333,
"39.80",3.773,6.685,
"40.00",3.805,6.718333,
"40.20",3.835,6.751667,
"40.40",3.867,6.784667,
"40.60",3.899,6.818,
"40.80",3.931,6.851333,
"41.00",3.964,6.884666,
"41.20",3.996,6.918,
"41.40",4.028,6.951333,
"41.60",4.062,6.984666,
"41.80",4.095,7.018333,
"42.00",4.126,7.051667,
"42.20",4.153,7.084667,
"42.40",4.184,7.118,
"42.60",4.218,7.151333,
"42.80",4.251,7.184667,
"43.00",4.284,7.218,
"43.20",4.317,7.251333,
"43.40",4.348,7.284667,
"43.60",4.382,7.318,
"43.80",4.414,7.351333,
"44.00",4.449,7.384666,
"44.20",4.481,7.418,
"44.40",4.511,7.451333,
"44.60",4.546,7.484666,
"44.80",4.576,7.518,
"45.00",4.607,7.551333,
"45.20",4.642,7.584667,
"45.40",4.674,7.618,
"45.60",4.706,7.651333,
"45.80",4.739,7.685,
"46.00",4.771,7.718,
"46.20",4.802,7.751333,
"46.40",4.834,7.784667,
"46.60",4.868,7.818,
"46.80",4.901,7.851333,
"47.00",4.932,7.884666,
"47.20",4.964,7.918,
"47.40",4.997,7.951333,
"47.60",5.028,7.984666,
"47.80",5.062,8.018333,
"48.00",5.096,8.051667,
"48.20",5.126,8.084667,
"48.40",5.158,8.118,
"48.60",5.191,8.151334,
"48.80",5.224,8.184667,
"49.00",5.258,8.218,
"49.20",5.289,8.251333,
"49.40",5.322,8.284667,
"49.60",5.353,8.318001,
"49.80",5.387,8.351334,
"50.00",5.417,8.384667,
"50.20",5.448,8.418,
"50.40",5.481,8.451667,
"50.60",5.516,8.485001,
"50.80",5.547,8.518333,
"51.00",5.576,8.551667,
"51.20",5.609,8.585,
"51.40",5.641,8.618334,
"51.60",5.67,8.651667,
"51.80",5.702,8.684667,
"52.00",5.734,8.718333,
"52.20",5.763,8.751333,
"52.40",5.789,8.784667,
"52.60",5.825,8.818001,
"52.80",5.856,8.851334,
"53.00",5.885,8.884667,
"53.20",5.912,8.918,
"53.40",5.941,8.951667,
"53.60",5.976,8.985001,
"53.80",6.004,9.018001,
"54.00",6.032,9.051667,
"54.20",6.06,9.085,
"54.40",6.089,9.118334,
"54.60",6.119,9.151667,
"54.80",6.147,9.184667,
"55.00",6.176,9.218,
"55.20",6.206,9.251667,
"55.40",6.234,9.285001,
"55.60",6.266,9.318334,
"55.80",6.295,9.351667,
"56.00",6.324,9.385,
"56.20",6.354,9.418,
"56.40",6.381,9.451667,
"56.60",6.413,9.484667,
"56.80",6.441,9.518333,
"57.00",6.471,9.551667,
"57.20",6.497,9.584667,
"57.40",6.523,9.618,
"57.60",6.555,9.651334,
"57.80",6.584,9.684667,
"58.00",6.612,9.718,
"58.20",6.637,9.751667,
"58.40",6.668,9.785001,
"58.60",6.694,9.818334,
"58.80",6.723,9.851334,
"59.00",6.75,9.884667,
"59.20",6.776,9.918,
"59.40",6.803,9.951334,
"59.60",6.831,9.984667,
"59.80",6.86,10.01833,
"60.00",6.888,10.05133,
"60.20",6.914,10.085,
"60.40",6.939,10.11833,
"60.60",6.973,10.15167,
"60.80",6.998,10.185,
"61.00",7.025,10.218,
"61.20",7.056,10.25133,
"61.40",7.083,10.28467,
"61.60",7.114,10.318,
"61.80",7.141,10.35133,
"62.00",7.169,10.38467,
"62.20",7.195,10.418,
"62.40",7.224,10.45133,
"62.60",7.255,10.48467,
"62.80",7.282,10.518,
"63.00",7.307,10.55133,
"63.20",7.334,10.585,
"63.40",7.359,10.61833,
"63.60",7.384,10.65167,
"63.80",7.416,10.68467,
"64.00",7.44,10.718,
"64.20",7.464,10.75167,
"64.40",7.49,10.785,
"64.60",7.516,10.81833,
"64.80",7.54,10.85167,
"65.00",7.566,10.88467,
"65.20",7.59,10.91833,
"65.40",7.613,10.95133,
"65.60",7.64,10.98467,
"65.80",7.662,11.018,
"66.00",7.687,11.05133,
"66.20",7.71,11.08467,
"66.40",7.735,11.11833,
"66.60",7.762,11.15167,
"66.80",7.787,11.185,
"67.00",7.81,11.21833,
"67.20",7.832,11.25167,
"67.40",7.857,11.285,
"67.60",7.882,11.318,
"67.80",7.908,11.35133,
"68.00",7.935,11.38467,
"68.20",7.958,11.418,
"68.40",7.983,11.45133,
"68.60",8.002,11.48467,
"68.80",8.028,11.518,
"69.00",8.056,11.55133,
"69.20",8.08,11.58467,
"69.40",8.105,11.61833,
"69.60",8.131,11.65133,
"69.80",8.156,11.68467,
"70.00",8.184,11.71833,
"70.20",8.207,11.75167,
"70.40",8.231,11.785,
"70.60",8.255,11.81833,
"70.80",8.279,11.85167,
"71.00",8.301,11.88467,
"71.20",8.32,11.918,
"71.40",8.349,11.95133,
"71.60",8.373,11.985,
"71.80",8.397,12.01833,
"72.00",8.42,12.05133,
"72.20",8.441,12.08467,
"72.40",8.465,12.118,
"72.60",8.487,12.15133,
"72.80",8.513,12.18467,
"73.00",8.534,12.218,
"73.20",8.556,12.25133,
"73.40",8.578,12.28467,
"73.60",8.605,12.318,
"73.80",8.629,12.35133,
"74.00",8.653,12.38467,
"74.20",8.679,12.41833,
"74.40",8.697,12.45133,
"74.60",8.725,12.485,
"74.80",8.75,12.51833,
"75.00",8.775,12.55133,
"75.20",8.795,12.585,
"75.40",8.822,12.618,
"75.60",8.845,12.65133,
"75.80",8.871,12.68467,
"76.00",8.89,12.718,
"76.20",8.911,12.75167,
"76.40",8.935,12.785,
"76.60",8.96,12.818,
"76.80",8.98,12.85133,
"77.00",8.999,12.88467,
"77.20",9.019,12.918,
"77.40",9.039,12.95133,
"77.60",9.063,12.98467,
"77.80",9.086,13.01833,
"78.00",9.107,13.05167,
"78.20",9.124,13.08467,
"78.40",9.145,13.11833,
"78.60",9.167,13.15167,
"78.80",9.19,13.18467,
"79.00",9.209,13.21833,
"79.20",9.231,13.25167,
"79.40",9.249,13.285,
"79.60",9.272,13.31833,
"79.80",9.294,13.35133,
"80.00",9.313,13.385,
"80.20",9.333,13.41833,
"80.40",9.354,13.45167,
"80.60",9.376,13.48467,
"80.80",9.396,13.518,
"81.00",9.412,13.55133,
"81.20",9.43,13.58467,
"81.40",9.447,13.618,
"81.60",9.462,13.65133,
"81.80",9.474,13.68467,
"82.00",9.479,13.71833,
"82.20",9.477,13.75167,
"82.40",9.473,13.785,
"82.60",9.472,13.81833,
"82.80",9.476,13.85167,
"83.00",9.485,13.88467,
"83.20",9.494,13.91833,
"83.40",9.508,13.95133,
"83.60",9.514,13.98467,
"83.80",9.517,14.018,
"84.00",9.518,14.05167,
"84.20",9.522,14.08467,
"84.40",9.531,14.11833,
"84.60",9.549,14.15167,
"84.80",9.57,14.18467,
"85.00",9.592,14.218,
"85.20",9.618,14.25133,
"85.40",9.643,14.285,
"85.60",9.671,14.318,
"85.80",9.699,14.35133,
"86.00",9.723,14.385,
"86.20",9.748,14.418,
"86.40",9.774,14.45133,
"86.60",9.799,14.485,
"86.80",9.823,14.51833,
"87.00",9.845,14.55167,
"87.20",9.87,14.58467,
"87.40",9.892,14.618,
"87.60",9.915,14.65133,
"87.80",9.942,14.68467,
"88.00",9.966,14.718,
"88.20",9.99,14.75133,
"88.40",10.012,14.785,
"88.60",10.038,14.81833,
"88.80",10.065,14.85167,
"89.00",10.089,14.885,
"89.20",10.108,14.918,
"89.40",10.127,14.95133,
"89.60",10.153,14.98467,
"89.80",10.177,15.018,
"90.00",10.199,15.05167,
"90.20",10.218,15.085,
"90.40",10.241,15.118,
"90.60",10.264,15.15133,
"90.80",10.285,15.18467,
"91.00",10.303,15.218,
"91.20",10.318,15.25167,
"91.40",10.338,15.285,
"91.60",10.357,15.31833,
"91.80",10.378,15.35167,
"92.00",10.396,15.385,
"92.20",10.41,15.41833,
"92.40",10.429,15.45167,
"92.60",10.449,15.485,
"92.80",10.471,15.51833,
"93.00",10.49,15.55133,
"93.20",10.511,15.585,
"93.40",10.533,15.61833,
"93.60",10.555,15.65167,
"93.80",10.577,15.68467,
"94.00",10.596,15.718,
"94.20",10.618,15.75133,
"94.40",10.632,15.78467,
"94.60",10.656,15.818,
"94.80",10.673,15.85133,
"95.00",10.696,15.88467,
"95.20",10.716,15.918,
"95.40",10.734,15.95133,
"95.60",10.754,15.98467,
"95.80",10.775,16.018,
"96.00",10.797,16.05133,
"96.20",10.813,16.08467,
"96.40",10.836,16.11833,
"96.60",10.858,16.15167,
"96.80",10.878,16.185,
"97.00",10.896,16.218,
"97.20",10.914,16.25167,
"97.40",10.931,16.285,
"97.60",10.953,16.31833,
"97.80",10.973,16.35167,
"98.00",10.992,16.385,
"98.20",11.01,16.41833,
"98.40",11.026,16.45167,
"98.60",11.045,16.48467,
"98.80",11.064,16.518,
"99.00",11.085,16.55133,
"99.20",11.103,16.58467,
"99.40",11.122,16.618,
"99.60",11.14,16.65133,
"99.80",11.162,16.68467,
"100.00",11.179,16.718,
"100.20",11.2,16.75167,
"100.40",11.219,16.785,
"100.60",11.24,16.81833,
"100.80",11.26,16.85133,
"101.00",11.279,16.885,
"101.20",11.296,16.91833,
"101.40",11.315,16.95167,
"101.60",11.333,16.98467,
"101.80",11.354,17.018,
"102.00",11.37,17.05133,
"102.20",11.388,17.08467,
"102.40",11.407,17.11833,
"102.60",11.426,17.15167,
"102.80",11.449,17.185,
"103.00",11.467,17.218,
"103.20",11.485,17.25167,
"103.40",11.501,17.28467,
"103.60",11.522,17.318,
"103.80",11.542,17.35133,
"104.00",11.56,17.38467,
"104.20",11.579,17.418,
"104.40",11.593,17.45133,
"104.60",11.611,17.48467,
"104.80",11.628,17.518,
"105.00",11.643,17.55133,
"105.20",11.66,17.58467,
"105.40",11.68,17.61833,
"105.60",11.694,17.65167,
"105.80",11.714,17.685,
"106.00",11.731,17.718,
"106.20",11.744,17.75133,
"106.40",11.761,17.78467,
"106.60",11.778,17.818,
"106.80",11.799,17.85133,
"107.00",11.812,17.88467,
"107.20",11.828,17.918,
"107.40",11.844,17.95133,
"107.60",11.857,17.98467,
"107.80",11.879,18.018,
"108.00",11.889,18.05133,
"108.20",11.906,18.08467,
"108.40",11.921,18.118,
"108.60",11.937,18.15133,
"108.80",11.951,18.18467,
"109.00",11.969,18.218,
"109.20",11.982,18.25133,
"109.40",11.999,18.28467,
"109.60",12.013,18.31833,
"109.80",12.029,18.35133,
"110.00",12.047,18.385,
"110.20",12.064,18.41833,
"110.40",12.082,18.45167,
"110.60",12.098,18.48467,
"110.80",12.116,18.518,
"111.00",12.133,18.55133,
"111.20",12.148,18.58467,
"111.40",12.162,18.618,
"111.60",12.18,18.65133,
"111.80",12.196,18.68467,
"112.00",12.212,18.718,
"112.20",12.226,18.75133,
"112.40",12.243,18.78467,
"112.60",12.26,18.818,
"112.80",12.28,18.85133,
"113.00",12.297,18.88467,
"113.20",12.311,18.918,
"113.40",12.33,18.95133,
"113.60",12.347,18.98467,
"113.80",12.365,19.018,
"114.00",12.381,19.05133,
"114.20",12.397,19.08467,
"114.40",12.414,19.118,
"114.60",12.428,19.15133,
"114.80",12.449,19.18467,
"115.00",12.464,19.218,
"115.20",12.478,19.25133,
"115.40",12.495,19.28467,
"115.60",12.512,19.318,
"115.80",12.523,19.35133,
"116.00",12.537,19.38467,
"116.20",12.549,19.418,
"116.40",12.565,19.45133,
"116.60",12.581,19.48467,
"116.80",12.596,19.518,
"117.00",12.611,19.55133,
"117.20",12.626,19.58467,
"117.40",12.639,19.618,
"117.60",12.657,19.65167,
"117.80",12.678,19.68467,
"118.00",12.695,19.718,
"118.20",12.706,19.75133,
"118.40",12.722,19.785,
"118.60",12.742,19.81833,
"118.80",12.756,19.85133,
"119.00",12.773,19.88467,
"119.20",12.788,19.918,
"119.40",12.801,19.95133,
"119.60",12.817,19.98467,
"119.80",12.831,20.01833,
"120.00",12.849,20.05133,
"120.20",12.86,20.08467,
"120.40",12.875,20.11833,
"120.60",12.893,20.15167,
"120.80",12.908,20.185,
"121.00",12.922,20.218,
"121.20",12.934,20.25133,
"121.40",12.952,20.28467,
"121.60",12.973,20.318,
"121.80",12.988,20.35133,
"122.00",13.003,20.38467,
"122.20",13.014,20.418,
"122.40",13.029,20.45133,
"122.60",13.045,20.48467,
"122.80",13.064,20.518,
"123.00",13.079,20.55133,
"123.20",13.091,20.58467,
"123.40",13.103,20.618,
"123.60",13.117,20.65133,
"123.80",13.135,20.68467,
"124.00",13.147,20.718,
"124.20",13.161,20.75133,
"124.40",13.174,20.78467,
"124.60",13.188,20.818,
"124.80",13.202,20.85133,
"125.00",13.216,20.88467,
"125.20",13.227,20.918,
"125.40",13.24,20.95133,
"125.60",13.256,20.98467,
"125.80",13.267,21.018,
"126.00",13.278,21.05133,
"126.20",13.288,21.08467,
"126.40",13.3,21.118,
"126.60",13.313,21.15133,
"126.80",13.325,21.18467,
"127.00",13.335,21.218,
"127.20",13.348,21.251,
"127.40",13.356,21.28467,
"127.60",13.372,21.318,
"127.80",13.39,21.35133,
"128.00",13.4,21.38467,
"128.20",13.411,21.418,
"128.40",13.423,21.45133,
"128.60",13.436,21.48467,
"128.80",13.454,21.518,
"129.00",13.466,21.55133,
"129.20",13.475,21.58467,
"129.40",13.486,21.618,
"129.60",13.501,21.65133,
"129.80",13.516,21.68433,
"130.00",13.528,21.718,
"130.20",13.539,21.75133,
"130.40",13.556,21.78467,
"130.60",13.57,21.818,
"130.80",13.586,21.85133,
"131.00",13.602,21.88467,
"131.20",13.617,21.918,
"131.40",13.63,21.95133,
"131.60",13.647,21.98467,
"131.80",13.664,22.018,
"132.00",13.676,22.05133,
"132.20",13.687,22.08467,
"132.40",13.7,22.118,
"132.60",13.711,22.15133,
"132.80",13.727,22.18467,
"133.00",13.742,22.218,
"133.20",13.756,22.25133,
"133.40",13.772,22.28467,
"133.60",13.786,22.318,
"133.80",13.803,22.351,
"134.00",13.815,22.38467,
"134.20",13.832,22.418,
"134.40",13.847,22.45133,
"134.60",13.86,22.48467,
"134.80",13.88,22.518,
"135.00",13.893,22.55133,
"135.20",13.907,22.58467,
"135.40",13.924,22.618,
"135.60",13.939,22.65133,
"135.80",13.957,22.68467,
"136.00",13.969,22.718,
"136.20",13.981,22.75133,
"136.40",13.995,22.78467,
"136.60",14.014,22.818,
"136.80",14.027,22.85133,
"137.00",14.043,22.88467,
"137.20",14.056,22.918,
"137.40",14.068,22.95133,
"137.60",14.083,22.98467,
"137.80",14.099,23.018,
"138.00",14.113,23.05133,
"138.20",14.13,23.08467,
"138.40",14.142,23.118,
"138.60",14.157,23.15167,
"138.80",14.176,23.18467,
"139.00",14.192,23.218,
"139.20",14.208,23.25133,
"139.40",14.224,23.28467,
"139.60",14.235,23.318,
"139.80",14.25,23.35133,
"140.00",14.263,23.385,
"140.20",14.273,23.418,
"140.40",14.285,23.45133,
"140.60",14.297,23.48467,
"140.80",14.31,23.518,
"141.00",14.319,23.55133,
"141.20",14.325,23.58467,
"141.40",14.338,23.61833,
"141.60",14.348,23.65133,
"141.80",14.358,23.68467,
"142.00",14.372,23.718,
"142.20",14.38,23.75133,
"142.40",14.39,23.78467,
"142.60",14.408,23.818,
"142.80",14.421,23.85133,
"143.00",14.436,23.88467,
"143.20",14.45,23.918,
"143.40",14.459,23.95133,
"143.60",14.475,23.98467,
"143.80",14.495,24.018,
"144.00",14.509,24.05167,
"144.20",14.524,24.08467,
"144.40",14.542,24.11833,
"144.60",14.556,24.15133,
"144.80",14.574,24.18467,
"145.00",14.592,24.218,
"145.20",14.608,24.25133,
"145.40",14.624,24.28467,
"145.60",14.642,24.318,
"145.80",14.663,24.35133,
"146.00",14.679,24.38467,
"146.20",14.693,24.418,
"146.40",14.709,24.45133,
"146.60",14.725,24.48467,
"146.80",14.741,24.518,
"147.00",14.753,24.55133,
"147.20",14.765,24.58467,
"147.40",14.777,24.61833,
"147.60",14.789,24.65167,
"147.80",14.806,24.685,
"148.00",14.819,24.718,
"148.20",14.827,24.75133,
"148.40",14.835,24.78467,
"148.60",14.846,24.818,
"148.80",14.859,24.85133,
"149.00",14.872,24.88467,
"149.20",14.884,24.918,
"149.40",14.892,24.95133,
"149.60",14.906,24.98467,
"149.80",14.917,25.018,
"150.00",14.927,25.05133,
"150.20",14.938,25.085,
"150.40",14.949,25.11833,
"150.60",14.961,25.15167,
"150.80",14.977,25.185,
"151.00",14.985,25.218,
"151.20",14.994,25.25167,
"151.40",15.005,25.28467,
"151.60",15.019,25.318,
"151.80",15.034,25.35167,
"152.00",15.043,25.38467,
"152.20",15.053,25.418,
"152.40",15.062,25.45133,
"152.60",15.078,25.48467,
"152.80",15.091,25.518,
"153.00",15.105,25.55133,
"153.20",15.115,25.58467,
"153.40",15.125,25.618,
"153.60",15.137,25.65133,
"153.80",15.152,25.68467,
"154.00",15.167,25.718,
"154.20",15.177,25.75133,
"154.40",15.192,25.78467,
"154.60",15.205,25.81833,
"154.80",15.219,25.85167,
"155.00",15.235,25.88467,
"155.20",15.248,25.91833,
"155.40",15.266,25.95133,
"155.60",15.281,25.98467,
"155.80",15.294,26.018,
"156.00",15.309,26.05167,
"156.20",15.322,26.085,
"156.40",15.335,26.11833,
"156.60",15.352,26.15133,
"156.80",15.368,26.18467,
"157.00",15.379,26.218,
"157.20",15.392,26.25167,
"157.40",15.404,26.28467,
"157.60",15.42,26.318,
"157.80",15.434,26.35133,
"158.00",15.448,26.38467,
"158.20",15.455,26.41833,
"158.40",15.469,26.45167,
"158.60",15.481,26.485,
"158.80",15.491,26.518,
"159.00",15.503,26.55133,
"159.20",15.513,26.58467,
"159.40",15.519,26.618,
"159.60",15.531,26.65133,
"159.80",15.543,26.68467,
"160.00",15.559,26.718,
"160.20",15.571,26.75133,
"160.40",15.585,26.78467,
"160.60",15.599,26.818,
"160.80",15.616,26.85133,
"161.00",15.629,26.88467,
"161.20",15.642,26.918,
"161.40",15.657,26.95133,
"161.60",15.674,26.98467,
"161.80",15.69,27.018,
"162.00",15.701,27.05133,
"162.20",15.713,27.08467,
"162.40",15.723,27.118,
"162.60",15.74,27.15133,
"162.80",15.749,27.18467,
"163.00",15.762,27.218,
"163.20",15.768,27.25133,
"163.40",15.779,27.28467,
"163.60",15.791,27.318,
"163.80",15.805,27.35133,
"164.00",15.821,27.385,
"164.20",15.83,27.41833,
"164.40",15.838,27.45167,
"164.60",15.847,27.485,
"164.80",15.861,27.518,
"165.00",15.871,27.55133,
"165.20",15.88,27.585,
"165.40",15.89,27.61833,
"165.60",15.901,27.65167,
"165.80",15.912,27.685,
"166.00",15.92,27.718,
"166.20",15.927,27.75133,
"166.40",15.937,27.785,
"166.60",15.952,27.81833,
"166.80",15.962,27.85167,
"167.00",15.969,27.885,
"167.20",15.977,27.918,
"167.40",15.983,27.95133,
"167.60",15.993,27.98467,
"167.80",16.004,28.018,
"168.00",16.015,28.05167,
"168.20",16.021,28.08467,
"168.40",16.029,28.11833,
"168.60",16.041,28.15133,
"168.80",16.053,28.185,
"169.00",16.063,28.21833,
"169.20",16.065,28.25167,
"169.40",16.074,28.285,
"169.60",16.083,28.31833,
"169.80",16.091,28.35133,
"170.00",16.098,28.38467,
"170.20",16.106,28.418,
"170.40",16.119,28.45133,
"170.60",16.132,28.48467,
"170.80",16.146,28.51833,
"171.00",16.157,28.55167,
"171.20",16.167,28.58467,
"171.40",16.176,28.618,
"171.60",16.186,28.65133,
"171.80",16.199,28.68467,
"172.00",16.207,28.718,
"172.20",16.218,28.75133,
"172.40",16.229,28.78467,
"172.60",16.242,28.818,
"172.80",16.259,28.85133,
"173.00",16.269,28.88467,
"173.20",16.28,28.918,
"173.40",16.294,28.95133,
"173.60",16.308,28.98467,
"173.80",16.324,29.01833,
"174.00",16.337,29.05167,
"174.20",16.35,29.085,
"174.40",16.362,29.11833,
"174.60",16.375,29.15167,
"174.80",16.393,29.18467,
"175.00",16.404,29.218,
"175.20",16.416,29.25133,
"175.40",16.43,29.28467,
"175.60",16.445,29.318,
"175.80",16.457,29.35133,
"176.00",16.472,29.38467,
"176.20",16.48,29.418,
"176.40",16.493,29.45167,
"176.60",16.506,29.48467,
"176.80",16.52,29.51833,
"177.00",16.53,29.55167,
"177.20",16.54,29.585,
"177.40",16.55,29.61833,
"177.60",16.566,29.65133,
"177.80",16.578,29.685,
"178.00",16.589,29.718,
"178.20",16.6,29.75133,
"178.40",16.608,29.78467,
"178.60",16.622,29.818,
"178.80",16.634,29.85167,
"179.00",16.645,29.885,
"179.20",16.655,29.918,
"179.40",16.662,29.95167,
"179.60",16.675,29.98467,
"179.80",16.686,30.018,
"180.00",16.694,30.05133,
"180.20",16.703,30.08467,
"180.40",16.713,30.118,
"180.60",16.725,30.15133,
"180.80",16.738,30.18467,
"181.00",16.747,30.218,
"181.20",16.754,30.25133,
"181.40",16.767,30.28467,
"181.60",16.776,30.318,
"181.80",16.787,30.35133,
"182.00",16.794,30.38467,
"182.20",16.8,30.418,
"182.40",16.808,30.45133,
"182.60",16.819,30.48467,
"182.80",16.835,30.518,
"183.00",16.841,30.55133,
"183.20",16.848,30.58467,
"183.40",16.853,30.618,
"183.60",16.863,30.65133,
"183.80",16.875,30.68467,
"184.00",16.886,30.718,
"184.20",16.892,30.75133,
"184.40",16.895,30.78467,
"184.60",16.903,30.818,
"184.80",16.915,30.85133,
"185.00",16.917,30.88467,
"185.20",16.92,30.918,
"185.40",16.928,30.95133,
"185.60",16.932,30.98467,
"185.80",16.942,31.018,
"186.00",16.949,31.05133,
"186.20",16.954,31.08467,
"186.40",16.96,31.118,
"186.60",16.971,31.15133,
"186.80",16.985,31.18467,
"187.00",16.997,31.218,
"187.20",17.002,31.25133,
"187.40",17.018,31.28467,
"187.60",17.029,31.318,
"187.80",17.051,31.35167,
"188.00",17.066,31.385,
"188.20",17.079,31.418,
"188.40",17.092,31.45133,
"188.60",17.109,31.48467,
"188.80",17.129,31.51833,
"189.00",17.142,31.55133,
"189.20",17.156,31.585,
"189.40",17.169,31.61833,
"189.60",17.187,31.65167,
"189.80",17.2,31.68467,
"190.00",17.216,31.718,
"190.20",17.228,31.75133,
"190.40",17.245,31.785,
"190.60",17.256,31.81833,
"190.80",17.271,31.85167,
"191.00",17.28,31.88467,
"191.20",17.288,31.918,
"191.40",17.302,31.95133,
"191.60",17.315,31.98467,
"191.80",17.32,32.018,
"192.00",17.324,32.05133,
"192.20",17.33,32.08467,
"192.40",17.335,32.118,
"192.60",17.346,32.15167,
"192.80",17.356,32.18467,
"193.00",17.366,32.218,
"193.20",17.375,32.25134,
"193.40",17.382,32.28467,
"193.60",17.394,32.318,
"193.80",17.407,32.35133,
"194.00",17.419,32.38467,
"194.20",17.424,32.418,
"194.40",17.434,32.45133,
"194.60",17.443,32.48467,
"194.80",17.457,32.518,
"195.00",17.467,32.55133,
"195.20",17.475,32.58467,
"195.40",17.486,32.618,
"195.60",17.494,32.65133,
"195.80",17.508,32.68467,
"196.00",17.518,32.718,
"196.20",17.529,32.75167,
"196.40",17.545,32.78467,
"196.60",17.556,32.81833,
"196.80",17.571,32.85133,
"197.00",17.587,32.88467,
"197.20",17.6,32.91833,
"197.40",17.613,32.95167,
"197.60",17.628,32.985,
"197.80",17.648,33.01833,
"198.00",17.662,33.05167,
"198.20",17.67,33.085,
"198.40",17.683,33.11833,
"198.60",17.694,33.15167,
"198.80",17.708,33.18467,
"199.00",17.718,33.21833,
"199.20",17.725,33.25167,
"199.40",17.737,33.285,
"199.60",17.746,33.318,
"199.80",17.756,33.35133,
"200.00",17.766,33.38467,
"200.20",17.771,33.41833,
"200.40",17.781,33.45167,
"200.60",17.79,33.48467,
"200.80",17.8,33.518,
"201.00",17.805,33.55133,
"201.20",17.811,33.58467,
"201.40",17.82,33.61833,
"201.60",17.831,33.65167,
"201.80",17.836,33.68467,
"202.00",17.838,33.718,
"202.20",17.841,33.75134,
"202.40",17.849,33.78467,
"202.60",17.855,33.818,
"202.80",17.863,33.85133,
"203.00",17.869,33.88467,
"203.20",17.875,33.918,
"203.40",17.877,33.95133,
"203.60",17.888,33.98467,
"203.80",17.898,34.018,
"204.00",17.907,34.05133,
"204.20",17.91,34.08434,
"204.40",17.919,34.11767,
"204.60",17.927,34.151,
"204.80",17.939,34.18433,
"205.00",17.945,34.21767,
"205.20",17.952,34.25134,
"205.40",17.959,34.28467,
"205.60",17.97,34.318,
"205.80",17.979,34.35133,
"206.00",17.985,34.38467,
"206.20",17.991,34.418,
"206.40",17.995,34.45133,
"206.60",18.001,34.48467,
"206.80",18.011,34.518,
"207.00",18.011,34.55133,
"207.20",18.015,34.58467,
"207.40",18.02,34.618,
"207.60",18.025,34.65133,
"207.80",18.035,34.68467,
"208.00",18.039,34.718,
"208.20",18.043,34.75134,
"208.40",18.049,34.78467,
"208.60",18.055,34.818,
"208.80",18.064,34.85133,
"209.00",18.072,34.88467,
"209.20",18.076,34.918,
"209.40",18.079,34.95133,
"209.60",18.088,34.98467,
"209.80",18.102,35.018,
"210.00",18.109,35.05133,
"210.20",18.118,35.08467,
"210.40",18.132,35.118,
"210.60",18.147,35.15133,
"210.80",18.166,35.18433,
"211.00",18.176,35.218,
"211.20",18.191,35.25134,
"211.40",18.209,35.28467,
"211.60",18.223,35.318,
"211.80",18.24,35.35133,
"212.00",18.253,35.38467,
"212.20",18.264,35.418,
"212.40",18.273,35.451,
"212.60",18.289,35.48433,
"212.80",18.306,35.51767,
"213.00",18.316,35.551,
"213.20",18.326,35.58467,
"213.40",18.336,35.618,
"213.60",18.349,35.65133,
"213.80",18.359,35.68467,
"214.00",18.371,35.718,
"214.20",18.38,35.75134,
"214.40",18.386,35.78467,
"214.60",18.397,35.818,
"214.80",18.405,35.85133,
"215.00",18.416,35.88433,
"215.20",18.422,35.918,
"215.40",18.428,35.95133,
"215.60",18.435,35.98467,
"215.80",18.44,36.01767,
"216.00",18.446,36.051,
"216.20",18.449,36.08434,
"216.40",18.453,36.11767,
"216.60",18.461,36.15133,
"216.80",18.472,36.18433,
"217.00",18.478,36.21767,
"217.20",18.48,36.251,
"217.40",18.488,36.28433,
"217.60",18.497,36.31767,
"217.80",18.505,36.35133,
"218.00",18.515,36.38467,
"218.20",18.522,36.418,
"218.40",18.528,36.45133,
"218.60",18.537,36.48467,
"218.80",18.551,36.518,
"219.00",18.56,36.55133,
"219.20",18.566,36.58434,
"219.40",18.574,36.618,
"219.60",18.582,36.65133,
"219.80",18.595,36.68467,
"220.00",18.605,36.718,
"220.20",18.612,36.75134,
"220.40",18.622,36.78467,
"220.60",18.638,36.818,
"220.80",18.649,36.85133,
"221.00",18.657,36.88433,
"221.20",18.666,36.918,
"221.40",18.674,36.95133,
"221.60",18.683,36.98467,
"221.80",18.694,37.018,
"222.00",18.702,37.05133,
"222.20",18.708,37.08467,
"222.40",18.718,37.118,
"222.60",18.729,37.15133,
"222.80",18.738,37.18467,
"223.00",18.748,37.218,
"223.20",18.752,37.25134,
"223.40",18.756,37.28467,
"223.60",18.764,37.318,
"223.80",18.777,37.351,
"224.00",18.786,37.38433,
"224.20",18.793,37.418,
"224.40",18.797,37.45133,
"224.60",18.806,37.48467,
"224.80",18.82,37.518,
"225.00",18.826,37.55133,
"225.20",18.832,37.58467,
"225.40",18.839,37.618,
"225.60",18.849,37.65133,
"225.80",18.856,37.68467,
"226.00",18.867,37.718,
"226.20",18.874,37.75134,
"226.40",18.875,37.78467,
"226.60",18.888,37.818,
"226.80",18.897,37.85133,
"227.00",18.899,37.88467,
"227.20",18.907,37.918,
"227.40",18.914,37.95133,
"227.60",18.921,37.98467,
"227.80",18.934,38.018,
"228.00",18.941,38.05133,
"228.20",18.944,38.085,
"228.40",18.953,38.11833,
"228.60",18.961,38.15133,
"228.80",18.97,38.18467,
"229.00",18.982,38.218,
"229.20",18.989,38.25134,
"229.40",18.996,38.28467,
"229.60",19.007,38.318,
"229.80",19.019,38.35133,
"230.00",19.021,38.38467,
"230.20",19.029,38.418,
"230.40",19.036,38.45133,
"230.60",19.043,38.48467,
"230.80",19.051,38.518,
"231.00",19.056,38.55133,
"231.20",19.063,38.58467,
"231.40",19.067,38.618,
"231.60",19.074,38.65133,
"231.80",19.082,38.68467,
"232.00",19.086,38.718,
"232.20",19.088,38.75134,
"232.40",19.093,38.78467,
"232.60",19.097,38.818,
"232.80",19.107,38.85133,
"233.00",19.114,38.88467,
"233.20",19.124,38.918,
"233.40",19.131,38.95133,
"233.60",19.145,38.98467,
"233.80",19.158,39.018,
"234.00",19.172,39.05133,
"234.20",19.186,39.085,
"234.40",19.198,39.11833,
"234.60",19.21,39.15133,
"234.80",19.22,39.18467,
"235.00",19.231,39.218,
"235.20",19.237,39.25134,
"235.40",19.243,39.28467,
"235.60",19.254,39.318,
"235.80",19.265,39.35133,
"236.00",19.267,39.38467,
"236.20",19.268,39.418,
"236.40",19.277,39.45133,
"236.60",19.284,39.48467,
"236.80",19.292,39.518,
"237.00",19.295,39.55133,
"237.20",19.298,39.58467,
"237.40",19.302,39.618,
"237.60",19.306,39.65133,
"237.80",19.317,39.68467,
"238.00",19.32,39.718,
"238.20",19.325,39.75134,
"238.40",19.326,39.78467,
"238.60",19.333,39.818,
"238.80",19.344,39.85133,
"239.00",19.348,39.88467,
"239.20",19.351,39.918,
"239.40",19.355,39.95133,
"239.60",19.358,39.98433,
"239.80",19.364,40.01767,
"240.00",19.367,40.051,
"240.20",19.37,40.08467,
"240.40",19.371,40.118,
"240.60",19.378,40.15133,
"240.80",19.382,40.18467,
"241.00",19.385,40.218,
"241.20",19.387,40.251,
"241.40",19.394,40.28467,
"241.60",19.4,40.31767,
"241.80",19.408,40.35133,
"242.00",19.415,40.38467,
"242.20",19.419,40.418,
"242.40",19.425,40.45133,
"242.60",19.434,40.48467,
"242.80",19.445,40.518,
"243.00",19.451,40.55133,
"243.20",19.461,40.58467,
"243.40",19.468,40.618,
"243.60",19.476,40.65133,
"243.80",19.486,40.68467,
"244.00",19.497,40.718,
"244.20",19.503,40.75134,
"244.40",19.514,40.78467,
"244.60",19.524,40.818,
"244.80",19.54,40.85133,
"245.00",19.549,40.88433,
"245.20",19.559,40.918,
"245.40",19.572,40.95133,
"245.60",19.584,40.98467,
"245.80",19.596,41.018,
"246.00",19.608,41.05133,
"246.20",19.615,41.08434,
"246.40",19.623,41.11767,
"246.60",19.636,41.151,
"246.80",19.645,41.18433,
"247.00",19.652,41.218,
"247.20",19.658,41.25134,
"247.40",19.659,41.28467,
"247.60",19.673,41.318,
"247.80",19.684,41.35133,
"248.00",19.692,41.38467,
"248.20",19.693,41.418,
"248.40",19.701,41.45133,
"248.60",19.711,41.48467,
"248.80",19.718,41.518,
"249.00",19.726,41.55133,
"249.20",19.734,41.58467,
"249.40",19.736,41.618,
"249.60",19.743,41.65133,
"249.80",19.754,41.68467,
"250.00",19.762,41.718,
"250.20",19.766,41.75134,
"250.40",19.768,41.78467,
"250.60",19.775,41.818,
"250.80",19.785,41.85133,
"251.00",19.782,41.88467,
"251.20",19.784,41.918,
"251.40",19.782,41.95133,
"251.60",19.784,41.98467,
"251.80",19.789,42.018,
"252.00",19.79,42.05133,
"252.20",19.79,42.08467,
"252.40",19.788,42.118,
"252.60",19.794,42.15133,
"252.80",19.798,42.18467,
"253.00",19.805,42.21767,
"253.20",19.801,42.251,
"253.40",19.803,42.28467,
"253.60",19.809,42.318,
"253.80",19.811,42.35133,
"254.00",19.819,42.38467,
"254.20",19.822,42.418,
"254.40",19.824,42.45133,
"254.60",19.826,42.48467,
"254.80",19.835,42.518,
"255.00",19.841,42.55133,
"255.20",19.843,42.58467,
"255.40",19.847,42.618,
"255.60",19.853,42.65133,
"255.80",19.858,42.68433,
"256.00",19.861,42.71767,
"256.20",19.864,42.75134,
"256.40",19.869,42.78467,
"256.60",19.872,42.818,
"256.80",19.88,42.85133,
"257.00",19.887,42.88467,
"257.20",19.887,42.918,
"257.40",19.889,42.95133,
"257.60",19.9,42.98467,
"257.80",19.905,43.018,
"258.00",19.911,43.05133,
"258.20",19.919,43.08467,
"258.40",19.923,43.118,
"258.60",19.931,43.151,
"258.80",19.939,43.18433,
"259.00",19.947,43.218,
"259.20",19.953,43.25134,
"259.40",19.961,43.28467,
"259.60",19.966,43.318,
"259.80",19.978,43.35133,
"260.00",19.985,43.38467,
"260.20",19.993,43.418,
"260.40",20,43.45133,
"260.60",20.007,43.48467,
"260.80",20.019,43.518,
"261.00",20.028,43.55133,
"261.20",20.029,43.58467,
"261.40",20.035,43.618,
"261.60",20.044,43.65133,
"261.80",20.057,43.68467,
"262.00",20.067,43.718,
"262.20",20.072,43.75134,
"262.40",20.082,43.78467,
"262.60",20.09,43.818,
"262.80",20.104,43.85133,
"263.00",20.113,43.88467,
"263.20",20.119,43.918,
"263.40",20.12,43.95133,
"263.60",20.124,43.98467,
"263.80",20.133,44.018,
"264.00",20.141,44.05133,
"264.20",20.144,44.08467,
"264.40",20.15,44.118,
"264.60",20.154,44.15133,
"264.80",20.164,44.18467,
"265.00",20.167,44.218,
"265.20",20.061,44.25134,
"265.40",19.961,44.28433,
"265.60",19.973,44.31767,
"265.80",19.983,44.35133,
"266.00",19.992,44.38467,
"266.20",19.994,44.418,
"266.40",20.007,44.45133,
"266.60",20.02,44.48467,
"266.80",20.036,44.518,
"267.00",20.044,44.551,
"267.20",20.048,44.58434,
"267.40",20.055,44.61767,
"267.60",20.064,44.65133,
"267.80",20.077,44.68467,
"268.00",20.086,44.718,
"268.20",20.093,44.75134,
"268.40",20.103,44.78467,
"268.60",20.115,44.818,
"268.80",20.13,44.85133,
"269.00",20.133,44.88467,
"269.20",20.14,44.918,
"269.40",20.146,44.95133,
"269.60",20.154,44.98467,
"269.80",20.16,45.01767,
"270.00",20.165,45.051,
"270.20",20.168,45.08467,
"270.40",20.174,45.118,
"270.60",20.182,45.15133,
"270.80",20.192,45.18467,
"271.00",20.199,45.218,
"271.20",20.203,45.25134,
"271.40",20.21,45.28467,
"271.60",20.222,45.318,
"271.80",20.235,45.35133,
"272.00",20.236,45.38467,
"272.20",20.242,45.418,
"272.40",20.249,45.45133,
"272.60",20.256,45.48467,
"272.80",20.271,45.518,
"273.00",20.28,45.55133,
"273.20",20.288,45.58467,
"273.40",20.295,45.618,
"273.60",20.304,45.65133,
"273.80",20.31,45.68467,
"274.00",20.323,45.718,
"274.20",20.332,45.75134,
"274.40",20.34,45.78467,
"274.60",20.352,45.818,
"274.80",20.365,45.85133,
"275.00",20.374,45.88467,
"275.20",20.387,45.918,
"275.40",20.399,45.95133,
"275.60",20.417,45.98467,
"275.80",20.43,46.018,
"276.00",20.442,46.05133,
"276.20",20.452,46.08467,
"276.40",20.465,46.118,
"276.60",20.483,46.15133,
"276.80",20.495,46.18467,
"277.00",20.506,46.218,
"277.20",20.509,46.25134,
"277.40",20.517,46.28467,
"277.60",20.522,46.318,
"277.80",20.53,46.35133,
"278.00",20.534,46.38467,
"278.20",20.538,46.418,
"278.40",20.542,46.45133,
"278.60",20.55,46.48467,
"278.80",20.555,46.518,
"279.00",20.563,46.55133,
"279.20",20.566,46.58467,
"279.40",20.568,46.618,
"279.60",20.572,46.65133,
"279.80",20.577,46.68467,
"280.00",20.584,46.718,
"280.20",20.582,46.75134,
"280.40",20.588,46.78467,
"280.60",20.59,46.818,
"280.80",20.598,46.85133,
"281.00",20.599,46.88467,
"281.20",20.603,46.918,
"281.40",20.609,46.95133,
"281.60",20.617,46.98467,
"281.80",20.623,47.018,
"282.00",20.625,47.05133,
"282.20",20.623,47.08467,
"282.40",20.627,47.118,
"282.60",20.637,47.15133,
"282.80",20.644,47.18433,
"283.00",20.651,47.21767,
"283.20",20.651,47.251,
"283.40",20.657,47.28433,
"283.60",20.664,47.31767,
"283.80",20.679,47.351,
"284.00",20.688,47.38467,
"284.20",20.692,47.418,
"284.40",20.696,47.45133,
"284.60",20.709,47.48467,
"284.80",20.718,47.51767,
"285.00",20.724,47.551,
"285.20",20.734,47.58467,
"285.40",20.743,47.618,
"285.60",20.755,47.65133,
"285.80",20.768,47.68467,
"286.00",20.774,47.718,
"286.20",20.778,47.75134,
"286.40",20.788,47.78467,
"286.60",20.8,47.818,
"286.80",20.813,47.85133,
"287.00",20.816,47.88467,
"287.20",20.82,47.918,
"287.40",20.824,47.95133,
"287.60",20.831,47.98467,
"287.80",20.837,48.018,
"287.90",20.837,48.03467,