File: exposed_monofilament_10.3cm_10mmpm_24nm_560esh_2.csv
"Test Name","Test Mode","Test Type","Control","Test Speed 1","Test Speed 2","Test Speed 3","Change Point 1","Change Point 2","Disp. Origin","Break and Limit Action","Sensitivity:","Level:"
"","Single","Tensile","Stroke",10,1,1,"Off","Off","Start","Stop",0,1

"Title","Sub title","Comment"
"","",""

"Shape:","Batch Size:","SubBatch Size:"
"Plate",1,1
"Name:","Thickness","Width","Gauge Length",
"Size Unit:","mm","mm","mm",
" 1 - 1","1.0000","1.0000","100.0000",

"Name",
"Parameter",
"Units",
" 1 - 1",

" 1- 1"
"Time","Force","Stroke",
"sec","N","mm",
"0.00",.006,0,
"0.15",.003,2.733333E-02,
"0.30",.009,.055,
"0.45",.023,8.266667E-02,
"0.60",.034,.1103333,
"0.75",.046,.138,
"0.90",.056,.1656667,
"1.05",.07,.1933333,
"1.20",.081,.221,
"1.35",.093,.2483333,
"1.50",.104,.276,
"1.65",.117,.3036667,
"1.80",.125,.3313333,
"1.95",.137,.359,
"2.10",.149,.386,
"2.25",.161,.4126667,
"2.40",.171,.4393333,
"2.55",.182,.4656667,
"2.70",.192,.4916667,
"2.85",.202,.5176666,
"3.00",.21,.5433334,
"3.15",.221,.5693333,
"3.30",.229,.5946667,
"3.45",.242,.6203333,
"3.60",.251,.646,
"3.75",.261,.6713333,
"3.90",.27,.6966667,
"4.05",.284,.722,
"4.20",.292,.7473333,
"4.35",.3,.7723333,
"4.50",.309,.7976667,
"4.65",.321,.8226666,
"4.80",.332,.8476667,
"4.95",.339,.873,
"5.10",.35,.898,
"5.25",.36,.923,
"5.40",.371,.9483333,
"5.55",.378,.9733334,
"5.70",.388,.9983333,
"5.85",.398,1.023333,
"6.00",.408,1.048333,
"6.15",.417,1.073333,
"6.30",.426,1.098333,
"6.45",.439,1.123333,
"6.60",.446,1.148667,
"6.75",.454,1.173333,
"6.90",.465,1.198667,
"7.05",.476,1.223333,
"7.20",.484,1.248667,
"7.35",.492,1.273667,
"7.50",.504,1.298667,
"7.65",.516,1.323667,
"7.80",.526,1.348667,
"7.95",.534,1.373667,
"8.10",.543,1.398667,
"8.25",.553,1.423667,
"8.40",.562,1.448667,
"8.55",.571,1.473667,
"8.70",.58,1.498667,
"8.85",.589,1.523667,
"9.00",.599,1.548667,
"9.15",.608,1.573667,
"9.30",.618,1.598667,
"9.45",.629,1.623667,
"9.60",.639,1.648667,
"9.75",.646,1.673667,
"9.90",.656,1.698667,
"10.05",.668,1.723667,
"10.20",.675,1.748333,
"10.35",.681,1.773333,
"10.50",.693,1.798333,
"10.65",.704,1.823667,
"10.80",.714,1.848333,
"10.95",.722,1.873667,
"11.10",.73,1.898667,
"11.25",.743,1.923333,
"11.40",.751,1.948333,
"11.55",.758,1.973333,
"11.70",.767,1.998333,
"11.85",.78,2.023333,
"12.00",.79,2.048333,
"12.15",.798,2.073667,
"12.30",.807,2.098333,
"12.45",.822,2.123333,
"12.60",.829,2.148333,
"12.75",.837,2.173333,
"12.90",.845,2.198333,
"13.05",.857,2.223333,
"13.20",.867,2.248333,
"13.35",.877,2.273333,
"13.50",.886,2.298333,
"13.65",.896,2.323333,
"13.80",.907,2.348333,
"13.95",.913,2.373333,
"14.10",.923,2.398333,
"14.25",.937,2.423667,
"14.40",.948,2.448667,
"14.55",.956,2.473667,
"14.70",.965,2.498667,
"14.85",.975,2.523667,
"15.00",.986,2.548667,
"15.15",.995,2.573667,
"15.30",1.004,2.598667,
"15.45",1.016,2.623667,
"15.60",1.027,2.648667,
"15.75",1.035,2.673667,
"15.90",1.044,2.698667,
"16.05",1.054,2.723667,
"16.20",1.064,2.748667,
"16.35",1.077,2.773667,
"16.50",1.085,2.798667,
"16.65",1.096,2.823667,
"16.80",1.106,2.848667,
"16.95",1.118,2.873667,
"17.10",1.126,2.898667,
"17.25",1.137,2.923667,
"17.40",1.148,2.948667,
"17.55",1.159,2.973667,
"17.70",1.168,2.998667,
"17.85",1.182,3.023667,
"18.00",1.192,3.048667,
"18.15",1.202,3.073667,
"18.30",1.215,3.098667,
"18.45",1.227,3.123667,
"18.60",1.238,3.148667,
"18.75",1.247,3.173667,
"18.90",1.257,3.198667,
"19.05",1.271,3.223667,
"19.20",1.279,3.248667,
"19.35",1.286,3.273667,
"19.50",1.302,3.298667,
"19.65",1.317,3.323667,
"19.80",1.327,3.348667,
"19.95",1.337,3.373667,
"20.10",1.348,3.398667,
"20.25",1.36,3.423667,
"20.40",1.37,3.448667,
"20.55",1.383,3.473667,
"20.70",1.396,3.498667,
"20.85",1.408,3.523667,
"21.00",1.42,3.548333,
"21.15",1.43,3.573667,
"21.30",1.44,3.598333,
"21.45",1.453,3.623333,
"21.60",1.466,3.648333,
"21.75",1.48,3.673667,
"21.90",1.49,3.698667,
"22.05",1.503,3.723667,
"22.20",1.513,3.748667,
"22.35",1.525,3.773667,
"22.50",1.539,3.798667,
"22.65",1.552,3.823667,
"22.80",1.563,3.848333,
"22.95",1.575,3.873333,
"23.10",1.586,3.898333,
"23.25",1.597,3.923333,
"23.40",1.611,3.948333,
"23.55",1.625,3.973333,
"23.70",1.638,3.998333,
"23.85",1.652,4.023334,
"24.00",1.666,4.048333,
"24.15",1.677,4.073667,
"24.30",1.688,4.098333,
"24.45",1.705,4.123333,
"24.60",1.718,4.148334,
"24.75",1.731,4.173333,
"24.90",1.744,4.198333,
"25.05",1.757,4.223333,
"25.20",1.772,4.248333,
"25.35",1.784,4.273667,
"25.50",1.797,4.298333,
"25.65",1.814,4.323333,
"25.80",1.824,4.348333,
"25.95",1.839,4.373333,
"26.10",1.854,4.398667,
"26.25",1.868,4.423666,
"26.40",1.882,4.448333,
"26.55",1.896,4.473333,
"26.70",1.911,4.498667,
"26.85",1.927,4.523334,
"27.00",1.939,4.548333,
"27.15",1.955,4.573333,
"27.30",1.971,4.598333,
"27.45",1.985,4.623333,
"27.60",1.999,4.648334,
"27.75",2.015,4.673333,
"27.90",2.031,4.698667,
"28.05",2.044,4.723333,
"28.20",2.057,4.748333,
"28.35",2.074,4.773334,
"28.50",2.09,4.798333,
"28.65",2.106,4.823667,
"28.80",2.123,4.848333,
"28.95",2.139,4.873333,
"29.10",2.155,4.898667,
"29.25",2.17,4.923666,
"29.40",2.185,4.948667,
"29.55",2.202,4.973667,
"29.70",2.216,4.998667,
"29.85",2.233,5.023667,
"30.00",2.247,5.048666,
"30.15",2.264,5.073667,
"30.30",2.282,5.098667,
"30.45",2.299,5.123667,
"30.60",2.316,5.148667,
"30.75",2.333,5.173666,
"30.90",2.352,5.198667,
"31.05",2.366,5.223667,
"31.20",2.382,5.248667,
"31.35",2.4,5.273667,
"31.50",2.417,5.298666,
"31.65",2.435,5.323667,
"31.80",2.451,5.348667,
"31.95",2.47,5.373667,
"32.10",2.486,5.398667,
"32.25",2.503,5.423666,
"32.40",2.52,5.448667,
"32.55",2.539,5.473667,
"32.70",2.557,5.498667,
"32.85",2.574,5.523667,
"33.00",2.592,5.548333,
"33.15",2.611,5.573667,
"33.30",2.631,5.598667,
"33.45",2.648,5.623333,
"33.60",2.667,5.648667,
"33.75",2.687,5.673666,
"33.90",2.704,5.698667,
"34.05",2.722,5.723667,
"34.20",2.741,5.748667,
"34.35",2.761,5.773667,
"34.50",2.781,5.798666,
"34.65",2.8,5.823667,
"34.80",2.819,5.848333,
"34.95",2.839,5.873667,
"35.10",2.858,5.898667,
"35.25",2.879,5.923666,
"35.40",2.895,5.948667,
"35.55",2.915,5.973667,
"35.70",2.934,5.998667,
"35.85",2.952,6.023667,
"36.00",2.972,6.048666,
"36.15",2.991,6.074,
"36.30",3.012,6.098667,
"36.45",3.033,6.123667,
"36.60",3.055,6.148667,
"36.75",3.072,6.173666,
"36.90",3.093,6.198667,
"37.05",3.112,6.223667,
"37.20",3.135,6.248667,
"37.35",3.157,6.273667,
"37.50",3.179,6.298333,
"37.65",3.197,6.323667,
"37.80",3.219,6.348667,
"37.95",3.235,6.373667,
"38.10",3.257,6.398667,
"38.25",3.28,6.423666,
"38.40",3.302,6.448333,
"38.55",3.324,6.473667,
"38.70",3.344,6.498667,
"38.85",3.368,6.523334,
"39.00",3.384,6.548666,
"39.15",3.405,6.573667,
"39.30",3.428,6.598333,
"39.45",3.449,6.623333,
"39.60",3.473,6.648334,
"39.75",3.494,6.673666,
"39.90",3.517,6.698667,
"40.05",3.538,6.723667,
"40.20",3.56,6.748667,
"40.35",3.58,6.773667,
"40.50",3.605,6.798666,
"40.65",3.627,6.823667,
"40.80",3.651,6.848667,
"40.95",3.672,6.873333,
"41.10",3.694,6.898667,
"41.25",3.718,6.923666,
"41.40",3.742,6.948333,
"41.55",3.764,6.973667,
"41.70",3.788,6.998667,
"41.85",3.811,7.023334,
"42.00",3.832,7.048333,
"42.15",3.853,7.073667,
"42.30",3.88,7.098667,
"42.45",3.905,7.123333,
"42.60",3.927,7.148667,
"42.75",3.951,7.173333,
"42.90",3.974,7.198333,
"43.05",3.998,7.223667,
"43.20",4.021,7.248667,
"43.35",4.044,7.273334,
"43.50",4.069,7.298333,
"43.65",4.093,7.323667,
"43.80",4.116,7.348333,
"43.95",4.139,7.373333,
"44.10",4.162,7.398334,
"44.25",4.185,7.423666,
"44.40",4.211,7.448667,
"44.55",4.237,7.473667,
"44.70",4.261,7.498667,
"44.85",4.284,7.523667,
"45.00",4.309,7.548666,
"45.15",4.335,7.573667,
"45.30",4.36,7.598667,
"45.45",4.385,7.623333,
"45.60",4.411,7.648667,
"45.75",4.436,7.673666,
"45.90",4.461,7.698667,
"46.05",4.486,7.723667,
"46.20",4.51,7.748667,
"46.35",4.535,7.773667,
"46.50",4.561,7.798666,
"46.65",4.588,7.823667,
"46.80",4.614,7.848333,
"46.95",4.641,7.873333,
"47.10",4.664,7.898667,
"47.25",4.689,7.923666,
"47.40",4.714,7.948333,
"47.55",4.738,7.973333,
"47.70",4.766,7.998333,
"47.85",4.791,8.023334,
"48.00",4.817,8.048667,
"48.15",4.844,8.073667,
"48.30",4.868,8.098666,
"48.45",4.893,8.123333,
"48.60",4.919,8.148666,
"48.75",4.946,8.173667,
"48.90",4.97,8.198667,
"49.05",4.995,8.223333,
"49.20",5.022,8.248333,
"49.35",5.049,8.273666,
"49.50",5.075,8.298333,
"49.65",5.099,8.323667,
"49.80",5.127,8.348666,
"49.95",5.152,8.373667,
"50.10",5.177,8.398666,
"50.25",5.202,8.423667,
"50.40",5.226,8.448667,
"50.55",5.254,8.473333,
"50.70",5.279,8.498333,
"50.85",5.305,8.523334,
"51.00",5.328,8.548333,
"51.15",5.353,8.573667,
"51.30",5.377,8.598333,
"51.45",5.406,8.623333,
"51.60",5.43,8.648334,
"51.75",5.455,8.673333,
"51.90",5.48,8.698667,
"52.05",5.503,8.723666,
"52.20",5.528,8.748667,
"52.35",5.555,8.773666,
"52.50",5.58,8.798667,
"52.65",5.606,8.823667,
"52.80",5.627,8.848333,
"52.95",5.653,8.873667,
"53.10",5.676,8.898666,
"53.25",5.703,8.923667,
"53.40",5.726,8.948667,
"53.55",5.751,8.973666,
"53.70",5.776,8.998667,
"53.85",5.801,9.023666,
"54.00",5.822,9.048333,
"54.15",5.846,9.073667,
"54.30",5.871,9.098333,
"54.45",5.899,9.123333,
"54.60",5.923,9.148334,
"54.75",5.951,9.173333,
"54.90",5.973,9.198334,
"55.05",5.997,9.223333,
"55.20",6.02,9.248333,
"55.35",6.048,9.273334,
"55.50",6.07,9.298333,
"55.65",6.097,9.323667,
"55.80",6.122,9.348333,
"55.95",6.143,9.373667,
"56.10",6.17,9.398666,
"56.25",6.194,9.423667,
"56.40",6.22,9.448667,
"56.55",6.243,9.473666,
"56.70",6.269,9.498333,
"56.85",6.293,9.523666,
"57.00",6.317,9.548667,
"57.15",6.342,9.573667,
"57.30",6.367,9.598666,
"57.45",6.391,9.623667,
"57.60",6.419,9.648666,
"57.75",6.443,9.673667,
"57.90",6.465,9.698667,
"58.05",6.488,9.723666,
"58.20",6.514,9.748667,
"58.35",6.542,9.773666,
"58.50",6.565,9.798333,
"58.65",6.59,9.823334,
"58.80",6.614,9.848333,
"58.95",6.637,9.873333,
"59.10",6.661,9.898334,
"59.25",6.685,9.923333,
"59.40",6.707,9.948334,
"59.55",6.731,9.973333,
"59.70",6.756,9.998667,
"59.85",6.781,10.02367,
"60.00",6.803,10.04867,
"60.15",6.826,10.07367,
"60.30",6.849,10.09867,
"60.45",6.875,10.12333,
"60.60",6.897,10.14833,
"60.75",6.92,10.17333,
"60.90",6.945,10.19833,
"61.05",6.968,10.22333,
"61.20",6.989,10.24833,
"61.35",7.011,10.27333,
"61.50",7.032,10.29833,
"61.65",7.054,10.32367,
"61.80",7.077,10.34867,
"61.95",7.1,10.37367,
"62.10",7.124,10.39867,
"62.25",7.143,10.42367,
"62.40",7.166,10.44833,
"62.55",7.19,10.47333,
"62.70",7.212,10.49867,
"62.85",7.233,10.52333,
"63.00",7.256,10.54833,
"63.15",7.276,10.57367,
"63.30",7.298,10.59867,
"63.45",7.321,10.62333,
"63.60",7.344,10.64833,
"63.75",7.366,10.67333,
"63.90",7.386,10.69833,
"64.05",7.408,10.72333,
"64.20",7.427,10.74833,
"64.35",7.449,10.77367,
"64.50",7.473,10.79867,
"64.65",7.497,10.82367,
"64.80",7.518,10.84833,
"64.95",7.537,10.87333,
"65.10",7.557,10.89833,
"65.25",7.578,10.92367,
"65.40",7.599,10.94867,
"65.55",7.62,10.97367,
"65.70",7.641,10.99867,
"65.85",7.663,11.02367,
"66.00",7.68,11.04867,
"66.15",7.699,11.07367,
"66.30",7.721,11.09867,
"66.45",7.743,11.12367,
"66.60",7.763,11.14867,
"66.75",7.78,11.17367,
"66.90",7.799,11.19867,
"67.05",7.821,11.22367,
"67.20",7.84,11.24867,
"67.35",7.86,11.27367,
"67.50",7.879,11.29867,
"67.65",7.902,11.32367,
"67.80",7.92,11.34867,
"67.95",7.939,11.37367,
"68.10",7.961,11.39867,
"68.25",7.979,11.42367,
"68.40",8,11.44867,
"68.55",8.023,11.47367,
"68.70",8.043,11.49867,
"68.85",8.064,11.52333,
"69.00",8.08,11.54833,
"69.15",8.099,11.57333,
"69.30",8.12,11.59867,
"69.45",8.141,11.62333,
"69.60",8.163,11.64867,
"69.75",8.182,11.67367,
"69.90",8.2,11.69867,
"70.05",8.216,11.72367,
"70.20",8.233,11.74867,
"70.35",8.252,11.77367,
"70.50",8.269,11.79867,
"70.65",8.287,11.82367,
"70.80",8.3,11.84867,
"70.95",8.308,11.87367,
"71.10",8.31,11.89867,
"71.25",8.309,11.92367,
"71.40",8.31,11.94867,
"71.55",8.316,11.97367,
"71.70",8.276,11.99867,
"71.85",8.094,12.02367,
"72.00",8.078,12.04833,
"72.15",8.105,12.07367,
"72.30",8.138,12.09833,
"72.45",8.168,12.12333,
"72.60",8.196,12.14833,
"72.75",8.227,12.17333,
"72.90",8.257,12.19867,
"73.05",8.285,12.22367,
"73.20",8.315,12.24867,
"73.35",8.344,12.27367,
"73.50",8.372,12.29833,
"73.65",8.396,12.32367,
"73.80",8.426,12.34867,
"73.95",8.454,12.37333,
"74.10",8.476,12.39867,
"74.25",8.498,12.42367,
"74.40",8.524,12.44867,
"74.55",8.548,12.47367,
"74.70",8.571,12.49867,
"74.85",8.596,12.52367,
"75.00",8.617,12.54833,
"75.15",8.636,12.57367,
"75.30",8.66,12.59867,
"75.45",8.687,12.62333,
"75.60",8.705,12.64833,
"75.75",8.727,12.67333,
"75.90",8.749,12.69833,
"76.05",8.771,12.72333,
"76.20",8.795,12.74867,
"76.35",8.817,12.77367,
"76.50",8.838,12.79867,
"76.65",8.857,12.82367,
"76.80",8.877,12.84867,
"76.95",8.899,12.87367,
"77.10",8.915,12.89867,
"77.25",8.936,12.92367,
"77.40",8.954,12.94867,
"77.55",8.975,12.97333,
"77.70",8.991,12.99867,
"77.85",9.009,13.02367,
"78.00",9.023,13.04867,
"78.15",9.041,13.07367,
"78.30",9.058,13.09867,
"78.45",9.077,13.12333,
"78.60",9.092,13.14833,
"78.75",9.106,13.17333,
"78.90",9.122,13.19833,
"79.05",9.137,13.22333,
"79.20",9.154,13.24833,
"79.35",9.168,13.27333,
"79.50",9.186,13.29833,
"79.65",9.207,13.32367,
"79.80",9.227,13.34833,
"79.95",9.242,13.37333,
"80.10",9.258,13.39867,
"80.25",9.276,13.42367,
"80.40",9.295,13.44867,
"80.55",9.313,13.47367,
"80.70",9.332,13.49867,
"80.85",9.349,13.52367,
"81.00",9.366,13.54867,
"81.15",9.383,13.57367,
"81.30",9.398,13.59867,
"81.45",9.415,13.62367,
"81.60",9.432,13.64867,
"81.75",9.451,13.67367,
"81.90",9.469,13.69867,
"82.05",9.484,13.72367,
"82.20",9.504,13.74867,
"82.35",9.523,13.77367,
"82.50",9.541,13.79833,
"82.65",9.557,13.82367,
"82.80",9.572,13.84833,
"82.95",9.589,13.87333,
"83.10",9.605,13.89867,
"83.25",9.624,13.92367,
"83.40",9.643,13.94833,
"83.55",9.66,13.97333,
"83.70",9.673,13.99833,
"83.85",9.692,14.02333,
"84.00",9.71,14.04833,
"84.15",9.726,14.07367,
"84.30",9.743,14.09867,
"84.45",9.759,14.12367,
"84.60",9.778,14.14867,
"84.75",9.794,14.17367,
"84.90",9.811,14.19867,
"85.05",9.827,14.22333,
"85.20",9.841,14.24867,
"85.35",9.859,14.27367,
"85.50",9.877,14.29867,
"85.65",9.896,14.32367,
"85.80",9.915,14.34867,
"85.95",9.929,14.37367,
"86.10",9.946,14.39867,
"86.25",9.962,14.42367,
"86.40",9.978,14.44867,
"86.55",9.994,14.47333,
"86.70",10.011,14.49833,
"86.85",10.029,14.52333,
"87.00",10.043,14.54833,
"87.15",10.06,14.57367,
"87.30",10.08,14.59833,
"87.45",10.099,14.62333,
"87.60",10.117,14.64833,
"87.75",10.135,14.67333,
"87.90",10.15,14.69833,
"88.05",10.167,14.72333,
"88.20",10.185,14.74833,
"88.35",10.203,14.77333,
"88.50",10.222,14.79833,
"88.65",10.239,14.82367,
"88.80",10.255,14.84833,
"88.95",10.271,14.87333,
"89.10",10.289,14.89833,
"89.25",10.304,14.92333,
"89.40",10.323,14.94867,
"89.55",10.342,14.97333,
"89.70",10.361,14.99833,
"89.85",10.374,15.02333,
"90.00",10.389,15.04867,
"90.15",10.408,15.07367,
"90.30",10.426,15.09867,
"90.45",10.446,15.12333,
"90.60",10.461,15.14867,
"90.75",10.478,15.17367,
"90.90",10.493,15.19867,
"91.05",10.507,15.22333,
"91.20",10.523,15.24833,
"91.35",10.537,15.27333,
"91.50",10.553,15.29833,
"91.65",10.568,15.32367,
"91.80",10.585,15.34867,
"91.95",10.6,15.37367,
"92.10",10.617,15.39833,
"92.25",10.632,15.42367,
"92.40",10.647,15.44833,
"92.55",10.663,15.47333,
"92.70",10.676,15.49833,
"92.85",10.692,15.52333,
"93.00",10.707,15.54833,
"93.15",10.721,15.57333,
"93.30",10.736,15.59833,
"93.45",10.753,15.62333,
"93.60",10.767,15.64833,
"93.75",10.781,15.67333,
"93.90",10.796,15.69833,
"94.05",10.811,15.72333,
"94.20",10.828,15.74833,
"94.35",10.845,15.77367,
"94.50",10.861,15.79833,
"94.65",10.876,15.82333,
"94.80",10.892,15.84833,
"94.95",10.9,15.87333,
"95.10",10.916,15.89833,
"95.25",10.934,15.92333,
"95.40",10.949,15.94833,
"95.55",10.965,15.97333,
"95.70",10.978,15.99833,
"95.85",10.992,16.02367,
"96.00",11.005,16.04867,
"96.15",11.017,16.07367,
"96.30",11.031,16.09833,
"96.45",11.046,16.12333,
"96.60",11.06,16.14833,
"96.75",11.074,16.17333,
"96.90",11.089,16.19833,
"97.05",11.101,16.22333,
"97.20",11.117,16.24867,
"97.35",11.133,16.27333,
"97.50",11.148,16.29833,
"97.65",11.161,16.32333,
"97.80",11.177,16.34833,
"97.95",11.19,16.37333,
"98.10",11.204,16.39833,
"98.25",11.22,16.42367,
"98.40",11.234,16.44867,
"98.55",11.251,16.47333,
"98.70",11.263,16.49833,
"98.85",11.275,16.52333,
"99.00",11.29,16.54833,
"99.15",11.304,16.57367,
"99.30",11.32,16.59833,
"99.45",11.335,16.62333,
"99.60",11.351,16.64833,
"99.75",11.367,16.67333,
"99.90",11.381,16.69833,
"100.05",11.394,16.72333,
"100.20",11.409,16.74833,
"100.35",11.427,16.77367,
"100.50",11.444,16.79833,
"100.65",11.461,16.82367,
"100.80",11.474,16.84833,
"100.95",11.489,16.87333,
"101.10",11.501,16.89833,
"101.25",11.515,16.92333,
"101.40",11.53,16.94833,
"101.55",11.541,16.97333,
"101.70",11.556,16.99833,
"101.85",11.569,17.02333,
"102.00",11.582,17.04867,
"102.15",11.6,17.07367,
"102.30",11.613,17.09833,
"102.45",11.63,17.12333,
"102.60",11.644,17.14833,
"102.75",11.657,17.17333,
"102.90",11.672,17.19833,
"103.05",11.688,17.22333,
"103.20",11.699,17.24833,
"103.35",11.714,17.27333,
"103.50",11.729,17.29833,
"103.65",11.743,17.32367,
"103.80",11.754,17.34867,
"103.95",11.762,17.37367,
"104.10",11.773,17.39867,
"104.25",11.786,17.42367,
"104.40",11.8,17.44867,
"104.55",11.814,17.47333,
"104.70",11.824,17.49867,
"104.85",11.837,17.52367,
"105.00",11.845,17.54867,
"105.15",11.851,17.57367,
"105.30",11.858,17.59867,
"105.45",11.867,17.62367,
"105.60",11.871,17.64867,
"105.75",11.874,17.67367,
"105.90",11.876,17.69867,
"106.05",11.879,17.72333,
"106.20",11.883,17.74867,
"106.35",11.886,17.77333,
"106.50",11.893,17.79833,
"106.65",11.9,17.82367,
"106.80",11.907,17.84833,
"106.95",11.914,17.87367,
"107.10",11.926,17.89867,
"107.25",11.94,17.92367,
"107.40",11.951,17.94867,
"107.55",11.966,17.97367,
"107.70",11.98,17.99867,
"107.85",11.992,18.02333,
"108.00",12.002,18.04833,
"108.15",12.014,18.07367,
"108.30",12.032,18.09867,
"108.45",12.048,18.12333,
"108.60",12.064,18.14833,
"108.75",12.08,18.17333,
"108.90",12.095,18.19833,
"109.05",12.112,18.22333,
"109.20",12.128,18.24833,
"109.35",12.144,18.27333,
"109.50",12.161,18.29833,
"109.65",12.177,18.32333,
"109.80",12.193,18.34833,
"109.95",12.209,18.37333,
"110.10",12.223,18.39867,
"110.25",12.24,18.42333,
"110.40",12.256,18.44833,
"110.55",12.273,18.47333,
"110.70",12.289,18.49833,
"110.85",12.307,18.52333,
"111.00",12.32,18.54833,
"111.15",12.335,18.57333,
"111.30",12.351,18.59833,
"111.45",12.37,18.62333,
"111.60",12.383,18.64833,
"111.75",12.399,18.67367,
"111.90",12.413,18.69867,
"112.05",12.426,18.72367,
"112.20",12.439,18.74867,
"112.35",12.451,18.77367,
"112.50",12.469,18.79867,
"112.65",12.485,18.82367,
"112.80",12.495,18.84833,
"112.95",12.506,18.87333,
"113.10",12.52,18.89833,
"113.25",12.534,18.92367,
"113.40",12.549,18.94833,
"113.55",12.565,18.97333,
"113.70",12.577,18.99833,
"113.85",12.59,19.02333,
"114.00",12.599,19.04833,
"114.15",12.612,19.07367,
"114.30",12.626,19.09833,
"114.45",12.642,19.12333,
"114.60",12.657,19.14833,
"114.75",12.669,19.17333,
"114.90",12.682,19.19833,
"115.05",12.693,19.22333,
"115.20",12.705,19.24833,
"115.35",12.718,19.27367,
"115.50",12.731,19.29833,
"115.65",12.746,19.32333,
"115.80",12.759,19.34867,
"115.95",12.77,19.37367,
"116.10",12.782,19.39867,
"116.25",12.795,19.42367,
"116.40",12.807,19.44833,
"116.55",12.819,19.47333,
"116.70",12.832,19.49833,
"116.85",12.841,19.52333,
"117.00",12.85,19.54833,
"117.15",12.863,19.57367,
"117.30",12.877,19.59833,
"117.45",12.892,19.62333,
"117.60",12.905,19.64833,
"117.75",12.916,19.67333,
"117.90",12.925,19.69867,
"118.05",12.938,19.72333,
"118.20",12.952,19.74867,
"118.35",12.964,19.77367,
"118.50",12.977,19.79867,
"118.65",12.992,19.82367,
"118.80",13.002,19.84833,
"118.95",13.013,19.87333,
"119.10",13.024,19.89833,
"119.25",13.036,19.92333,
"119.40",13.051,19.94833,
"119.55",13.065,19.97333,
"119.70",13.074,19.99833,
"119.85",13.089,20.02333,
"120.00",13.1,20.04833,
"120.15",13.111,20.07333,
"120.30",13.122,20.09833,
"120.45",13.14,20.12333,
"120.60",13.153,20.14833,
"120.75",13.165,20.17333,
"120.90",13.176,20.19833,
"121.05",13.188,20.22333,
"121.20",13.2,20.24833,
"121.35",13.214,20.27333,
"121.50",13.229,20.29833,
"121.65",13.242,20.32367,
"121.80",13.257,20.34867,
"121.95",13.27,20.37367,
"122.10",13.282,20.39867,
"122.25",13.296,20.42367,
"122.40",13.31,20.44833,
"122.55",13.326,20.47333,
"122.70",13.341,20.49833,
"122.85",13.354,20.52333,
"123.00",13.367,20.54833,
"123.15",13.381,20.57367,
"123.30",13.396,20.59867,
"123.45",13.411,20.62333,
"123.60",13.422,20.64833,
"123.75",13.431,20.67333,
"123.90",13.44,20.69833,
"124.05",13.453,20.72333,
"124.20",13.462,20.74833,
"124.35",13.472,20.77333,
"124.50",13.488,20.79833,
"124.65",13.5,20.82333,
"124.80",13.509,20.84833,
"124.95",13.522,20.87333,
"125.10",13.532,20.89833,
"125.25",13.542,20.92333,
"125.40",13.554,20.94833,
"125.55",13.565,20.97333,
"125.70",13.577,20.99833,
"125.85",13.585,21.02333,
"126.00",13.593,21.04833,
"126.15",13.601,21.07367,
"126.30",13.612,21.09867,
"126.45",13.622,21.12333,
"126.60",13.631,21.14867,
"126.75",13.636,21.17367,
"126.90",13.644,21.19833,
"127.05",13.652,21.22333,
"127.20",13.659,21.24867,
"127.35",13.668,21.27367,
"127.50",13.68,21.29833,
"127.65",13.694,21.32333,
"127.80",13.703,21.34833,
"127.95",13.708,21.37333,
"128.10",13.72,21.39867,
"128.25",13.732,21.42367,
"128.40",13.744,21.44867,
"128.55",13.755,21.47333,
"128.70",13.768,21.49867,
"128.85",13.779,21.52333,
"129.00",13.787,21.54867,
"129.15",13.798,21.57367,
"129.30",13.807,21.59867,
"129.45",13.821,21.62367,
"129.60",13.835,21.64867,
"129.75",13.848,21.67367,
"129.90",13.859,21.69867,
"130.05",13.869,21.72367,
"130.20",13.877,21.74867,
"130.35",13.887,21.77367,
"130.50",13.898,21.79833,
"130.65",13.911,21.82333,
"130.80",13.919,21.84833,
"130.95",13.929,21.87333,
"131.10",13.938,21.89833,
"131.25",13.951,21.92367,
"131.40",13.96,21.94867,
"131.55",13.97,21.97333,
"131.70",13.98,21.99833,
"131.85",13.99,22.02333,
"132.00",14.001,22.04867,
"132.15",14.012,22.07333,
"132.30",14.021,22.09833,
"132.45",14.032,22.12333,
"132.60",14.041,22.14833,
"132.75",14.047,22.17333,
"132.90",14.052,22.19833,
"133.05",14.06,22.22333,
"133.20",14.068,22.24833,
"133.35",14.074,22.27333,
"133.50",14.078,22.29833,
"133.65",14.082,22.32333,
"133.80",14.08,22.34833,
"133.95",14.073,22.37333,
"134.10",14.067,22.39833,
"134.25",14.069,22.42333,
"134.40",14.07,22.44833,
"134.55",14.067,22.47333,
"134.70",14.065,22.49833,
"134.85",14.065,22.52333,
"135.00",14.065,22.54833,
"135.15",14.063,22.57333,
"135.30",14.066,22.59833,
"135.45",14.078,22.62333,
"135.60",14.089,22.64833,
"135.75",14.102,22.67333,
"135.90",14.11,22.69833,
"136.05",14.122,22.72333,
"136.20",14.135,22.74833,
"136.35",14.147,22.77367,
"136.50",14.163,22.79833,
"136.65",14.178,22.82333,
"136.80",14.195,22.84833,
"136.95",14.21,22.87333,
"137.10",14.225,22.89833,
"137.25",14.242,22.92333,
"137.40",14.258,22.94833,
"137.55",14.274,22.97333,
"137.70",14.289,22.99833,
"137.85",14.304,23.02333,
"138.00",14.318,23.04833,
"138.15",14.333,23.07367,
"138.30",14.351,23.09833,
"138.45",14.365,23.12333,
"138.60",14.38,23.14833,
"138.75",14.392,23.17333,
"138.90",14.408,23.19833,
"139.05",14.421,23.22333,
"139.20",14.434,23.24833,
"139.35",14.45,23.27333,
"139.50",14.465,23.29833,
"139.65",14.48,23.32333,
"139.80",14.489,23.34833,
"139.95",14.501,23.37333,
"140.10",14.511,23.39833,
"140.25",14.523,23.42367,
"140.40",14.536,23.44833,
"140.55",14.549,23.47333,
"140.70",14.563,23.49833,
"140.85",14.574,23.52333,
"141.00",14.58,23.54833,
"141.15",14.585,23.57333,
"141.30",14.593,23.59833,
"141.45",14.603,23.62333,
"141.60",14.611,23.64833,
"141.75",14.621,23.67333,
"141.90",14.631,23.69867,
"142.05",14.642,23.72333,
"142.20",14.648,23.74833,
"142.35",14.659,23.77333,
"142.50",14.671,23.79833,
"142.65",14.682,23.82333,
"142.80",14.692,23.84833,
"142.95",14.7,23.87333,
"143.10",14.708,23.89833,
"143.25",14.72,23.92333,
"143.40",14.728,23.94833,
"143.55",14.74,23.97333,
"143.70",14.743,23.99833,
"143.85",14.747,24.02333,
"144.00",14.749,24.04833,
"144.15",14.754,24.07333,
"144.30",14.764,24.09833,
"144.45",14.775,24.12333,
"144.60",14.786,24.14833,
"144.75",14.793,24.17333,
"144.90",14.804,24.19833,
"145.05",14.814,24.22333,
"145.20",14.822,24.24833,
"145.35",14.832,24.27333,
"145.50",14.844,24.29833,
"145.65",14.857,24.32333,
"145.80",14.867,24.34833,
"145.95",14.872,24.37333,
"146.10",14.883,24.39833,
"146.25",14.896,24.42333,
"146.40",14.905,24.44833,
"146.55",14.916,24.47333,
"146.70",14.926,24.49833,
"146.85",14.936,24.52333,
"147.00",14.944,24.548,
"147.15",14.953,24.57333,
"147.30",14.964,24.59833,
"147.45",14.975,24.62333,
"147.60",14.986,24.64833,
"147.75",14.995,24.67333,
"147.90",15.004,24.69833,
"148.05",15.016,24.723,
"148.20",15.027,24.74833,
"148.35",15.038,24.77333,
"148.50",15.046,24.79833,
"148.65",15.058,24.82333,
"148.80",15.066,24.848,
"148.95",15.076,24.873,
"149.10",15.084,24.89833,
"149.25",15.097,24.92333,
"149.40",15.108,24.948,
"149.55",15.118,24.973,
"149.70",15.128,24.99833,
"149.85",15.143,25.02333,
"150.00",15.15,25.04833,
"150.15",15.156,25.07333,
"150.30",15.165,25.09833,
"150.45",15.177,25.12333,
"150.60",15.186,25.14833,
"150.75",15.191,25.17333,
"150.90",15.195,25.19833,
"151.05",15.202,25.22333,
"151.20",15.205,25.24833,
"151.35",15.205,25.27333,
"151.50",15.211,25.29833,
"151.65",15.221,25.32333,
"151.80",15.225,25.34833,
"151.95",15.23,25.37333,
"152.10",15.238,25.39867,
"152.25",15.248,25.42367,
"152.40",15.26,25.44867,
"152.55",15.269,25.47367,
"152.70",15.278,25.49867,
"152.85",15.288,25.52333,
"153.00",15.298,25.54833,
"153.15",15.306,25.57367,
"153.30",15.317,25.59867,
"153.45",15.33,25.62333,
"153.60",15.341,25.64833,
"153.75",15.355,25.67333,
"153.90",15.36,25.69833,
"154.05",15.367,25.72333,
"154.20",15.375,25.74833,
"154.35",15.388,25.77333,
"154.50",15.4,25.79833,
"154.65",15.41,25.82333,
"154.80",15.42,25.84833,
"154.95",15.426,25.87333,
"155.10",15.436,25.89833,
"155.25",15.445,25.92333,
"155.40",15.452,25.94833,
"155.55",15.464,25.97333,
"155.70",15.474,25.99833,
"155.85",15.486,26.02333,
"156.00",15.494,26.04833,
"156.15",15.503,26.07333,
"156.30",15.514,26.09833,
"156.45",15.528,26.12333,
"156.60",15.538,26.14833,
"156.75",15.547,26.17333,
"156.90",15.557,26.19833,
"157.05",15.569,26.22333,
"157.20",15.579,26.24833,
"157.35",15.592,26.27333,
"157.50",15.605,26.29833,
"157.65",15.617,26.32333,
"157.80",15.624,26.34833,
"157.95",15.628,26.37333,
"158.10",15.64,26.39833,
"158.25",15.653,26.42367,
"158.40",15.664,26.44833,
"158.55",15.673,26.47333,
"158.70",15.683,26.49867,
"158.85",15.692,26.52367,
"159.00",15.699,26.54833,
"159.15",15.704,26.57367,
"159.30",15.713,26.59833,
"159.45",15.728,26.62333,
"159.60",15.739,26.64833,
"159.75",15.745,26.67333,
"159.90",15.758,26.69833,
"160.05",15.771,26.72333,
"160.20",15.778,26.74833,
"160.35",15.787,26.77367,
"160.50",15.799,26.79833,
"160.65",15.813,26.82333,
"160.80",15.82,26.84833,
"160.95",15.827,26.87333,
"161.10",15.836,26.89833,
"161.25",15.848,26.92333,
"161.40",15.858,26.94833,
"161.55",15.868,26.97333,
"161.70",15.877,26.99833,
"161.85",15.886,27.02333,
"162.00",15.892,27.04867,
"162.15",15.901,27.07367,
"162.30",15.911,27.09867,
"162.45",15.925,27.12333,
"162.60",15.934,27.14833,
"162.75",15.942,27.17333,
"162.90",15.951,27.19833,
"163.05",15.962,27.22333,
"163.20",15.971,27.24833,
"163.35",15.978,27.27333,
"163.50",15.987,27.29833,
"163.65",15.998,27.32333,
"163.80",16.004,27.34833,
"163.95",16.011,27.37333,
"164.10",16.02,27.39833,
"164.25",16.031,27.42333,
"164.40",16.039,27.44833,
"164.55",16.045,27.47333,
"164.70",16.055,27.49833,
"164.85",16.064,27.52333,
"165.00",16.073,27.54833,
"165.15",16.076,27.57333,
"165.30",16.088,27.59833,
"165.45",16.099,27.62333,
"165.60",16.107,27.64833,
"165.75",16.117,27.67333,
"165.90",16.124,27.69867,
"166.05",16.133,27.72333,
"166.20",16.14,27.74833,
"166.35",16.145,27.77333,
"166.50",16.152,27.79833,
"166.65",16.165,27.82333,
"166.80",16.172,27.84833,
"166.95",16.18,27.87333,
"167.10",16.185,27.89833,
"167.25",16.197,27.92333,
"167.40",16.205,27.94833,
"167.55",16.214,27.97333,
"167.70",16.218,27.99833,
"167.85",16.228,28.02333,
"168.00",16.232,28.04833,
"168.15",16.237,28.07333,
"168.30",16.245,28.09833,
"168.45",16.255,28.12333,
"168.60",16.266,28.14833,
"168.75",16.271,28.17333,
"168.90",16.278,28.19833,
"169.05",16.287,28.22333,
"169.20",16.293,28.24833,
"169.35",16.299,28.27333,
"169.50",16.311,28.29833,
"169.65",16.321,28.32333,
"169.80",16.33,28.34833,
"169.95",16.336,28.37367,
"170.10",16.342,28.39833,
"170.25",16.351,28.42333,
"170.40",16.357,28.44833,
"170.55",16.366,28.47333,
"170.70",16.376,28.49833,
"170.85",16.387,28.52333,
"171.00",16.395,28.54833,
"171.15",16.402,28.57367,
"171.30",16.41,28.59867,
"171.45",16.418,28.62333,
"171.60",16.425,28.64833,
"171.75",16.432,28.67333,
"171.90",16.443,28.69833,
"172.05",16.451,28.72333,
"172.20",16.46,28.74833,
"172.35",16.469,28.77367,
"172.50",16.48,28.79833,
"172.65",16.491,28.82333,
"172.80",16.498,28.84833,
"172.95",16.502,28.87333,
"173.10",16.51,28.89833,
"173.25",16.52,28.92333,
"173.40",16.531,28.94833,
"173.55",16.538,28.97333,
"173.70",16.545,28.99833,
"173.85",16.552,29.02333,
"174.00",16.557,29.04833,
"174.15",16.56,29.07333,
"174.30",16.57,29.09833,
"174.45",16.577,29.12333,
"174.60",16.587,29.14833,
"174.75",16.595,29.17333,
"174.90",16.601,29.19833,
"175.05",16.611,29.22333,
"175.20",16.618,29.24833,
"175.35",16.626,29.27333,
"175.50",16.638,29.29833,
"175.65",16.65,29.32333,
"175.80",16.657,29.34833,
"175.95",16.66,29.37333,
"176.10",16.668,29.39833,
"176.25",16.678,29.42333,
"176.40",16.687,29.44833,
"176.55",16.697,29.47333,
"176.70",16.707,29.49833,
"176.85",16.718,29.52333,
"177.00",16.728,29.54833,
"177.15",16.735,29.57333,
"177.30",16.743,29.59833,
"177.45",16.757,29.62333,
"177.60",16.769,29.64833,
"177.75",16.778,29.67333,
"177.90",16.788,29.69833,
"178.05",16.799,29.72333,
"178.20",16.809,29.74833,
"178.35",16.817,29.77333,
"178.50",16.824,29.79833,
"178.65",16.836,29.82333,
"178.80",16.844,29.84833,
"178.95",16.851,29.87333,
"179.10",16.858,29.89833,
"179.25",16.866,29.92333,
"179.40",16.873,29.94833,
"179.55",16.882,29.97333,
"179.70",16.887,29.99833,
"179.85",16.896,30.02333,
"180.00",16.9,30.04833,
"180.15",16.903,30.07333,
"180.30",16.909,30.09833,
"180.45",16.912,30.12333,
"180.60",16.918,30.14833,
"180.75",16.917,30.17333,
"180.80",16.916,30.18133,