File: exposed_flourocarbon_10cm_10mmpm_24nm_250esh_9.csv
"Test Name","Test Mode","Test Type","Control","Test Speed 1","Test Speed 2","Test Speed 3","Change Point 1","Change Point 2","Disp. Origin","Break and Limit Action","Sensitivity:","Level:"
"","Single","Tensile","Stroke",10,1,1,"Off","Off","Start","Stop",0,1

"Title","Sub title","Comment"
"","",""

"Shape:","Batch Size:","SubBatch Size:"
"Plate",1,1
"Name:","Thickness","Width","Gauge Length",
"Size Unit:","mm","mm","mm",
" 1 - 1","1.0000","1.0000","100.0000",

"Name",
"Parameter",
"Units",
" 1 - 1",

" 1- 1"
"Time","Force","Stroke",
"sec","N","mm",
"0.00",0,0,
"0.15",.004,.028,
"0.30",.021,.056,
"0.45",.042,8.366667E-02,
"0.60",.067,.1116667,
"0.75",.091,.1393333,
"0.90",.119,.167,
"1.05",.141,.195,
"1.20",.166,.2226667,
"1.35",.188,.2506666,
"1.50",.214,.2783333,
"1.65",.237,.306,
"1.80",.263,.334,
"1.95",.286,.3616666,
"2.10",.309,.389,
"2.25",.331,.416,
"2.40",.355,.4426666,
"2.55",.378,.469,
"2.70",.401,.4953333,
"2.85",.421,.5213333,
"3.00",.446,.5470001,
"3.15",.467,.573,
"3.30",.489,.5983334,
"3.45",.51,.624,
"3.60",.527,.6496667,
"3.75",.551,.675,
"3.90",.572,.7003334,
"4.05",.593,.7256667,
"4.20",.611,.751,
"4.35",.632,.776,
"4.50",.651,.8013334,
"4.65",.67,.8263333,
"4.80",.689,.8513334,
"4.95",.71,.8766667,
"5.10",.728,.9016667,
"5.25",.749,.927,
"5.40",.768,.952,
"5.55",.787,.977,
"5.70",.808,1.002,
"5.85",.827,1.027,
"6.00",.844,1.052333,
"6.15",.864,1.077333,
"6.30",.884,1.102,
"6.45",.9,1.127333,
"6.60",.919,1.152333,
"6.75",.937,1.177333,
"6.90",.956,1.202333,
"7.05",.974,1.227333,
"7.20",.992,1.252333,
"7.35",1.01,1.277333,
"7.50",1.029,1.302333,
"7.65",1.046,1.327333,
"7.80",1.063,1.352333,
"7.95",1.081,1.377333,
"8.10",1.099,1.402667,
"8.25",1.116,1.427333,
"8.40",1.13,1.452667,
"8.55",1.15,1.477667,
"8.70",1.165,1.502333,
"8.85",1.181,1.527333,
"9.00",1.198,1.552333,
"9.15",1.214,1.577333,
"9.30",1.23,1.602333,
"9.45",1.244,1.627333,
"9.60",1.261,1.652667,
"9.75",1.277,1.677333,
"9.90",1.291,1.702667,
"10.05",1.308,1.727667,
"10.20",1.323,1.752667,
"10.35",1.339,1.777667,
"10.50",1.355,1.802667,
"10.65",1.368,1.827333,
"10.80",1.386,1.852333,
"10.95",1.402,1.877333,
"11.10",1.414,1.902333,
"11.25",1.429,1.927333,
"11.40",1.443,1.952667,
"11.55",1.458,1.977333,
"11.70",1.47,2.002333,
"11.85",1.486,2.027333,
"12.00",1.501,2.052333,
"12.15",1.513,2.077333,
"12.30",1.525,2.102333,
"12.45",1.54,2.127333,
"12.60",1.555,2.152333,
"12.75",1.567,2.177333,
"12.90",1.581,2.202333,
"13.05",1.595,2.227333,
"13.20",1.608,2.252333,
"13.35",1.62,2.277333,
"13.50",1.632,2.302333,
"13.65",1.645,2.327333,
"13.80",1.658,2.352333,
"13.95",1.673,2.377333,
"14.10",1.685,2.402333,
"14.25",1.699,2.427333,
"14.40",1.712,2.452333,
"14.55",1.724,2.477333,
"14.70",1.735,2.502,
"14.85",1.749,2.527333,
"15.00",1.76,2.552333,
"15.15",1.773,2.577333,
"15.30",1.786,2.602333,
"15.45",1.798,2.627333,
"15.60",1.812,2.652333,
"15.75",1.824,2.677333,
"15.90",1.835,2.702333,
"16.05",1.848,2.727333,
"16.20",1.859,2.752333,
"16.35",1.872,2.777333,
"16.50",1.883,2.802333,
"16.65",1.896,2.827333,
"16.80",1.909,2.852333,
"16.95",1.919,2.877333,
"17.10",1.931,2.902333,
"17.25",1.944,2.927333,
"17.40",1.954,2.952333,
"17.55",1.969,2.977333,
"17.70",1.979,3.002333,
"17.85",1.991,3.027333,
"18.00",2.005,3.052333,
"18.15",2.018,3.077333,
"18.30",2.027,3.102333,
"18.45",2.039,3.127333,
"18.60",2.053,3.152333,
"18.75",2.067,3.177333,
"18.90",2.078,3.202333,
"19.05",2.088,3.227333,
"19.20",2.099,3.252333,
"19.35",2.114,3.277333,
"19.50",2.125,3.302333,
"19.65",2.138,3.327333,
"19.80",2.148,3.352,
"19.95",2.16,3.377333,
"20.10",2.171,3.402,
"20.25",2.184,3.427333,
"20.40",2.193,3.452,
"20.55",2.208,3.477333,
"20.70",2.22,3.502,
"20.85",2.232,3.527,
"21.00",2.244,3.552333,
"21.15",2.257,3.577333,
"21.30",2.268,3.602333,
"21.45",2.278,3.627333,
"21.60",2.289,3.652333,
"21.75",2.304,3.677,
"21.90",2.316,3.702,
"22.05",2.331,3.727,
"22.20",2.341,3.752333,
"22.35",2.352,3.777333,
"22.50",2.365,3.802333,
"22.65",2.377,3.827333,
"22.80",2.388,3.852333,
"22.95",2.401,3.877333,
"23.10",2.412,3.902333,
"23.25",2.423,3.927333,
"23.40",2.437,3.952333,
"23.55",2.449,3.977333,
"23.70",2.461,4.002333,
"23.85",2.472,4.027,
"24.00",2.483,4.052,
"24.15",2.495,4.077333,
"24.30",2.509,4.102334,
"24.45",2.521,4.127333,
"24.60",2.534,4.152,
"24.75",2.545,4.177,
"24.90",2.558,4.202,
"25.05",2.57,4.227,
"25.20",2.581,4.252,
"25.35",2.592,4.277333,
"25.50",2.605,4.302333,
"25.65",2.62,4.327333,
"25.80",2.631,4.352334,
"25.95",2.645,4.377333,
"26.10",2.656,4.402333,
"26.25",2.668,4.427333,
"26.40",2.681,4.452333,
"26.55",2.692,4.477334,
"26.70",2.704,4.502333,
"26.85",2.719,4.527333,
"27.00",2.73,4.552333,
"27.15",2.745,4.577333,
"27.30",2.754,4.602334,
"27.45",2.767,4.627333,
"27.60",2.78,4.652333,
"27.75",2.794,4.677333,
"27.90",2.806,4.702333,
"28.05",2.818,4.727334,
"28.20",2.832,4.752333,
"28.35",2.844,4.777333,
"28.50",2.856,4.802333,
"28.65",2.869,4.827333,
"28.80",2.881,4.852334,
"28.95",2.894,4.877333,
"29.10",2.908,4.902333,
"29.25",2.92,4.927333,
"29.40",2.932,4.952333,
"29.55",2.945,4.977334,
"29.70",2.958,5.002333,
"29.85",2.97,5.027333,
"30.00",2.984,5.052333,
"30.15",2.996,5.077333,
"30.30",3.011,5.102334,
"30.45",3.022,5.127333,
"30.60",3.037,5.152333,
"30.75",3.053,5.177,
"30.90",3.064,5.202333,
"31.05",3.074,5.227,
"31.20",3.089,5.252,
"31.35",3.104,5.277333,
"31.50",3.115,5.302333,
"31.65",3.126,5.327333,
"31.80",3.142,5.352334,
"31.95",3.157,5.377333,
"32.10",3.168,5.402333,
"32.25",3.179,5.427333,
"32.40",3.192,5.452333,
"32.55",3.206,5.477334,
"32.70",3.22,5.502333,
"32.85",3.235,5.527333,
"33.00",3.246,5.552333,
"33.15",3.26,5.577333,
"33.30",3.273,5.602,
"33.45",3.285,5.627,
"33.60",3.299,5.652,
"33.75",3.313,5.677,
"33.90",3.326,5.702,
"34.05",3.338,5.727,
"34.20",3.353,5.752,
"34.35",3.365,5.777,
"34.50",3.38,5.802333,
"34.65",3.391,5.827333,
"34.80",3.402,5.852334,
"34.95",3.418,5.877333,
"35.10",3.429,5.902333,
"35.25",3.443,5.927333,
"35.40",3.457,5.952333,
"35.55",3.471,5.977334,
"35.70",3.485,6.002333,
"35.85",3.498,6.027333,
"36.00",3.514,6.052333,
"36.15",3.524,6.077333,
"36.30",3.537,6.102334,
"36.45",3.55,6.127333,
"36.60",3.565,6.152333,
"36.75",3.58,6.177,
"36.90",3.593,6.202,
"37.05",3.608,6.227,
"37.20",3.623,6.252333,
"37.35",3.638,6.277333,
"37.50",3.655,6.302333,
"37.65",3.671,6.327333,
"37.80",3.684,6.352334,
"37.95",3.7,6.377333,
"38.10",3.713,6.402333,
"38.25",3.725,6.427333,
"38.40",3.74,6.452333,
"38.55",3.756,6.477334,
"38.70",3.771,6.502333,
"38.85",3.785,6.527333,
"39.00",3.799,6.552333,
"39.15",3.814,6.577,
"39.30",3.83,6.602334,
"39.45",3.845,6.627333,
"39.60",3.86,6.652667,
"39.75",3.874,6.677667,
"39.90",3.891,6.702667,
"40.05",3.905,6.727334,
"40.20",3.918,6.752333,
"40.35",3.934,6.777333,
"40.50",3.948,6.802333,
"40.65",3.964,6.827333,
"40.80",3.982,6.852334,
"40.95",3.995,6.877333,
"41.10",4.011,6.902333,
"41.25",4.026,6.927333,
"41.40",4.04,6.952333,
"41.55",4.056,6.977334,
"41.70",4.068,7.002333,
"41.85",4.083,7.027333,
"42.00",4.103,7.052333,
"42.15",4.119,7.077333,
"42.30",4.133,7.102334,
"42.45",4.145,7.127333,
"42.60",4.161,7.152333,
"42.75",4.176,7.177333,
"42.90",4.193,7.202333,
"43.05",4.209,7.227334,
"43.20",4.224,7.252333,
"43.35",4.238,7.277333,
"43.50",4.256,7.302333,
"43.65",4.271,7.327667,
"43.80",4.286,7.352334,
"43.95",4.302,7.377333,
"44.10",4.318,7.402333,
"44.25",4.333,7.427333,
"44.40",4.35,7.452333,
"44.55",4.366,7.477334,
"44.70",4.384,7.502333,
"44.85",4.399,7.527333,
"45.00",4.413,7.552333,
"45.15",4.428,7.577333,
"45.30",4.442,7.602334,
"45.45",4.459,7.627333,
"45.60",4.477,7.652667,
"45.75",4.491,7.677333,
"45.90",4.507,7.702333,
"46.05",4.522,7.727334,
"46.20",4.537,7.752333,
"46.35",4.555,7.777333,
"46.50",4.573,7.802333,
"46.65",4.591,7.827333,
"46.80",4.607,7.852334,
"46.95",4.623,7.877333,
"47.10",4.639,7.902333,
"47.25",4.654,7.927333,
"47.40",4.669,7.952333,
"47.55",4.686,7.977334,
"47.70",4.705,8.002333,
"47.85",4.723,8.027333,
"48.00",4.74,8.052333,
"48.15",4.755,8.077332,
"48.30",4.77,8.102333,
"48.45",4.788,8.127333,
"48.60",4.804,8.152333,
"48.75",4.82,8.177333,
"48.90",4.837,8.202332,
"49.05",4.855,8.227333,
"49.20",4.873,8.252333,
"49.35",4.892,8.277333,
"49.50",4.906,8.302333,
"49.65",4.924,8.327332,
"49.80",4.94,8.352333,
"49.95",4.959,8.377333,
"50.10",4.973,8.402333,
"50.25",4.99,8.427333,
"50.40",5.01,8.452332,
"50.55",5.027,8.477333,
"50.70",5.045,8.502333,
"50.85",5.06,8.527333,
"51.00",5.077,8.552333,
"51.15",5.095,8.577332,
"51.30",5.111,8.602333,
"51.45",5.127,8.627333,
"51.60",5.145,8.652333,
"51.75",5.165,8.677333,
"51.90",5.185,8.702332,
"52.05",5.202,8.727333,
"52.20",5.219,8.752333,
"52.35",5.233,8.777333,
"52.50",5.25,8.802333,
"52.65",5.268,8.827332,
"52.80",5.288,8.852333,
"52.95",5.307,8.877333,
"53.10",5.323,8.902333,
"53.25",5.341,8.927333,
"53.40",5.36,8.952666,
"53.55",5.379,8.977666,
"53.70",5.396,9.002333,
"53.85",5.414,9.027333,
"54.00",5.432,9.052333,
"54.15",5.451,9.077666,
"54.30",5.47,9.102333,
"54.45",5.489,9.127333,
"54.60",5.508,9.152333,
"54.75",5.524,9.177333,
"54.90",5.542,9.202332,
"55.05",5.561,9.227333,
"55.20",5.578,9.252333,
"55.35",5.597,9.277333,
"55.50",5.617,9.302333,
"55.65",5.637,9.327332,
"55.80",5.655,9.352333,
"55.95",5.675,9.377333,
"56.10",5.692,9.402333,
"56.25",5.709,9.427333,
"56.40",5.728,9.452332,
"56.55",5.75,9.477333,
"56.70",5.767,9.502333,
"56.85",5.788,9.527333,
"57.00",5.806,9.552333,
"57.15",5.824,9.577332,
"57.30",5.842,9.602333,
"57.45",5.86,9.627333,
"57.60",5.882,9.652333,
"57.75",5.9,9.677333,
"57.90",5.921,9.702332,
"58.05",5.94,9.726999,
"58.20",5.959,9.752333,
"58.35",5.978,9.777333,
"58.50",5.996,9.802333,
"58.65",6.016,9.827332,
"58.80",6.036,9.852333,
"58.95",6.055,9.877333,
"59.10",6.073,9.901999,
"59.25",6.091,9.926999,
"59.40",6.112,9.952,
"59.55",6.132,9.976999,
"59.70",6.153,10.002,
"59.85",6.174,10.027,
"60.00",6.192,10.052,
"60.15",6.212,10.077,
"60.30",6.231,10.102,
"60.45",6.25,10.127,
"60.60",6.27,10.15233,
"60.75",6.292,10.177,
"60.90",6.313,10.202,
"61.05",6.334,10.227,
"61.20",6.352,10.252,
"61.35",6.371,10.27733,
"61.50",6.39,10.302,
"61.65",6.412,10.327,
"61.80",6.432,10.352,
"61.95",6.453,10.377,
"62.10",6.473,10.40233,
"62.25",6.493,10.42733,
"62.40",6.515,10.45233,
"62.55",6.532,10.47733,
"62.70",6.553,10.50233,
"62.85",6.576,10.52733,
"63.00",6.596,10.55233,
"63.15",6.614,10.57733,
"63.30",6.633,10.60233,
"63.45",6.654,10.62733,
"63.60",6.675,10.65233,
"63.75",6.693,10.67733,
"63.90",6.714,10.70233,
"64.05",6.735,10.72733,
"64.20",6.753,10.75233,
"64.35",6.775,10.77733,
"64.50",6.795,10.80233,
"64.65",6.818,10.82733,
"64.80",6.839,10.85233,
"64.95",6.861,10.87733,
"65.10",6.881,10.90233,
"65.25",6.902,10.92733,
"65.40",6.921,10.95233,
"65.55",6.942,10.97733,
"65.70",6.965,11.00233,
"65.85",6.987,11.02733,
"66.00",7.008,11.05233,
"66.15",7.026,11.07733,
"66.30",7.046,11.10233,
"66.45",7.068,11.12733,
"66.60",7.091,11.15233,
"66.75",7.112,11.17733,
"66.90",7.133,11.20233,
"67.05",7.157,11.22733,
"67.20",7.176,11.25233,
"67.35",7.199,11.27733,
"67.50",7.221,11.30233,
"67.65",7.239,11.32733,
"67.80",7.263,11.35233,
"67.95",7.288,11.37733,
"68.10",7.309,11.40233,
"68.25",7.331,11.42733,
"68.40",7.353,11.45233,
"68.55",7.374,11.47733,
"68.70",7.396,11.50233,
"68.85",7.417,11.52767,
"69.00",7.441,11.55267,
"69.15",7.465,11.57733,
"69.30",7.485,11.60233,
"69.45",7.507,11.62733,
"69.60",7.529,11.65267,
"69.75",7.55,11.67733,
"69.90",7.574,11.70233,
"70.05",7.594,11.72733,
"70.20",7.616,11.75233,
"70.35",7.638,11.77733,
"70.50",7.662,11.80267,
"70.65",7.685,11.82767,
"70.80",7.706,11.85233,
"70.95",7.73,11.87733,
"71.10",7.749,11.90233,
"71.25",7.771,11.92733,
"71.40",7.794,11.95233,
"71.55",7.817,11.97733,
"71.70",7.842,12.00233,
"71.85",7.864,12.02733,
"72.00",7.889,12.05233,
"72.15",7.909,12.07733,
"72.30",7.932,12.10233,
"72.45",7.954,12.12733,
"72.60",7.976,12.15233,
"72.75",8,12.17733,
"72.90",8.024,12.20233,
"73.05",8.047,12.227,
"73.20",8.069,12.25233,
"73.35",8.091,12.27733,
"73.50",8.113,12.30233,
"73.65",8.136,12.32733,
"73.80",8.16,12.35233,
"73.95",8.185,12.37733,
"74.10",8.209,12.40233,
"74.25",8.231,12.42733,
"74.40",8.251,12.45233,
"74.55",8.276,12.47733,
"74.70",8.301,12.50233,
"74.85",8.326,12.52733,
"75.00",8.346,12.55233,
"75.15",8.368,12.57733,
"75.30",8.391,12.60233,
"75.45",8.413,12.62733,
"75.60",8.436,12.65233,
"75.75",8.461,12.67733,
"75.90",8.482,12.70233,
"76.05",8.504,12.72733,
"76.20",8.526,12.75233,
"76.35",8.547,12.77733,
"76.50",8.568,12.80233,
"76.65",8.593,12.82733,
"76.80",8.62,12.85233,
"76.95",8.642,12.87733,
"77.10",8.663,12.90233,
"77.25",8.684,12.92733,
"77.40",8.707,12.95233,
"77.55",8.732,12.97733,
"77.70",8.757,13.00233,
"77.85",8.781,13.02733,
"78.00",8.806,13.05233,
"78.15",8.83,13.07733,
"78.30",8.85,13.102,
"78.45",8.875,13.12733,
"78.60",8.899,13.15233,
"78.75",8.926,13.17733,
"78.90",8.95,13.20233,
"79.05",8.973,13.22733,
"79.20",8.996,13.25233,
"79.35",9.022,13.277,
"79.50",9.045,13.30233,
"79.65",9.069,13.32733,
"79.80",9.093,13.35233,
"79.95",9.121,13.37733,
"80.10",9.14,13.40233,
"80.25",9.166,13.42733,
"80.40",9.187,13.45233,
"80.55",9.213,13.47733,
"80.70",9.238,13.50233,
"80.85",9.26,13.52733,
"81.00",9.285,13.55233,
"81.15",9.307,13.57733,
"81.30",9.329,13.60233,
"81.45",9.354,13.62733,
"81.60",9.377,13.65233,
"81.75",9.403,13.67733,
"81.90",9.43,13.70233,
"82.05",9.456,13.72733,
"82.20",9.478,13.75233,
"82.35",9.5,13.77733,
"82.50",9.525,13.80233,
"82.65",9.551,13.82733,
"82.80",9.579,13.85233,
"82.95",9.606,13.87733,
"83.10",9.632,13.90233,
"83.25",9.658,13.92733,
"83.40",9.681,13.95233,
"83.55",9.708,13.97733,
"83.70",9.735,14.00233,
"83.85",9.762,14.02733,
"84.00",9.79,14.05233,
"84.15",9.815,14.07733,
"84.30",9.84,14.10233,
"84.45",9.867,14.12733,
"84.60",9.893,14.15233,
"84.75",9.92,14.17733,
"84.90",9.946,14.20233,
"85.05",9.972,14.22733,
"85.20",9.996,14.25233,
"85.35",10.023,14.27733,
"85.50",10.047,14.30233,
"85.65",10.076,14.32733,
"85.80",10.103,14.35233,
"85.95",10.13,14.37733,
"86.10",10.155,14.40233,
"86.25",10.181,14.42733,
"86.40",10.208,14.45267,
"86.55",10.234,14.47767,
"86.70",10.264,14.50233,
"86.85",10.293,14.52733,
"87.00",10.321,14.55233,
"87.15",10.349,14.57733,
"87.30",10.375,14.60233,
"87.45",10.402,14.62733,
"87.60",10.43,14.65267,
"87.75",10.459,14.67733,
"87.90",10.487,14.70233,
"88.05",10.515,14.72733,
"88.20",10.542,14.75233,
"88.35",10.568,14.77733,
"88.50",10.595,14.80233,
"88.65",10.626,14.82733,
"88.80",10.655,14.85233,
"88.95",10.682,14.87733,
"89.10",10.709,14.90233,
"89.25",10.74,14.92733,
"89.40",10.768,14.95233,
"89.55",10.797,14.97767,
"89.70",10.828,15.00233,
"89.85",10.856,15.02733,
"90.00",10.883,15.05233,
"90.15",10.908,15.07733,
"90.30",10.934,15.10233,
"90.45",10.964,15.12767,
"90.60",10.994,15.15233,
"90.75",11.021,15.17733,
"90.90",11.047,15.20233,
"91.05",11.076,15.22733,
"91.20",11.103,15.25233,
"91.35",11.13,15.27733,
"91.50",11.159,15.30233,
"91.65",11.19,15.32733,
"91.80",11.22,15.35233,
"91.95",11.25,15.37733,
"92.10",11.279,15.40233,
"92.25",11.305,15.42733,
"92.40",11.332,15.45233,
"92.55",11.357,15.47733,
"92.70",11.386,15.50233,
"92.85",11.416,15.52733,
"93.00",11.445,15.55233,
"93.15",11.473,15.57733,
"93.30",11.5,15.60233,
"93.45",11.526,15.62733,
"93.60",11.556,15.65233,
"93.75",11.585,15.67733,
"93.90",11.612,15.70233,
"94.05",11.638,15.72733,
"94.20",11.665,15.75233,
"94.35",11.691,15.77733,
"94.50",11.719,15.80233,
"94.65",11.75,15.82733,
"94.80",11.779,15.85233,
"94.95",11.807,15.87733,
"95.10",11.836,15.902,
"95.25",11.865,15.927,
"95.40",11.891,15.95233,
"95.55",11.919,15.97733,
"95.70",11.95,16.00233,
"95.85",11.978,16.02733,
"96.00",12.003,16.05233,
"96.15",12.03,16.07733,
"96.30",12.056,16.10233,
"96.45",12.082,16.12733,
"96.60",12.112,16.15233,
"96.75",12.142,16.17733,
"96.90",12.172,16.20233,
"97.05",12.204,16.22733,
"97.20",12.234,16.25233,
"97.35",12.26,16.27733,
"97.50",12.289,16.30233,
"97.65",12.322,16.327,
"97.80",12.352,16.352,
"97.95",12.384,16.37733,
"98.10",12.416,16.402,
"98.25",12.445,16.427,
"98.40",12.475,16.452,
"98.55",12.505,16.477,
"98.70",12.539,16.502,
"98.85",12.57,16.52733,
"99.00",12.603,16.55233,
"99.15",12.634,16.57733,
"99.30",12.666,16.60233,
"99.45",12.696,16.62733,
"99.60",12.73,16.65233,
"99.75",12.763,16.67733,
"99.90",12.796,16.70233,
"100.05",12.827,16.72733,
"100.20",12.856,16.75233,
"100.35",12.89,16.77733,
"100.50",12.919,16.80233,
"100.65",12.955,16.82733,
"100.80",12.992,16.85233,
"100.95",13.022,16.87767,
"101.10",13.054,16.90233,
"101.25",13.086,16.92733,
"101.40",13.12,16.95233,
"101.55",13.153,16.97733,
"101.70",13.189,17.00233,
"101.85",13.225,17.02733,
"102.00",13.257,17.05233,
"102.15",13.289,17.07733,
"102.30",13.318,17.10233,
"102.45",13.352,17.12733,
"102.60",13.387,17.15233,
"102.75",13.42,17.17733,
"102.90",13.45,17.20233,
"103.05",13.482,17.22733,
"103.20",13.514,17.25233,
"103.35",13.544,17.27733,
"103.50",13.576,17.30233,
"103.65",13.607,17.32733,
"103.80",13.638,17.35233,
"103.95",13.671,17.37733,
"104.10",13.702,17.40233,
"104.25",13.734,17.42733,
"104.40",13.762,17.45233,
"104.55",13.794,17.47733,
"104.70",13.824,17.502,
"104.85",13.852,17.52733,
"105.00",13.877,17.55233,
"105.15",13.902,17.57733,
"105.30",13.927,17.60233,
"105.45",13.952,17.62733,
"105.60",13.976,17.65233,
"105.75",14.006,17.67733,
"105.90",14.035,17.70233,
"106.05",14.062,17.72733,
"106.20",14.085,17.75233,
"106.35",14.111,17.77733,
"106.50",14.134,17.80233,
"106.65",14.161,17.82733,
"106.80",14.184,17.852,
"106.95",14.208,17.87733,
"107.10",14.228,17.902,
"107.25",14.248,17.92733,
"107.40",14.272,17.952,
"107.55",14.296,17.977,
"107.70",14.321,18.002,
"107.85",14.351,18.02733,
"108.00",14.383,18.05233,
"108.15",14.413,18.07733,
"108.30",14.441,18.10233,
"108.45",14.475,18.12733,
"108.60",14.507,18.15233,
"108.75",14.537,18.17733,
"108.90",14.571,18.20233,
"109.05",14.607,18.227,
"109.20",14.641,18.252,
"109.35",14.675,18.27733,
"109.50",14.709,18.30233,
"109.65",14.745,18.32733,
"109.80",14.783,18.35233,
"109.95",14.814,18.37733,
"110.10",14.848,18.40233,
"110.25",14.879,18.42733,
"110.40",14.91,18.45233,
"110.55",14.943,18.47733,
"110.70",14.979,18.502,
"110.85",15.011,18.527,
"111.00",15.042,18.55233,
"111.15",15.071,18.57733,
"111.30",15.102,18.602,
"111.45",15.129,18.62733,
"111.60",15.16,18.65233,
"111.75",15.192,18.677,
"111.90",15.226,18.702,
"112.05",15.254,18.727,
"112.20",15.286,18.75233,
"112.35",15.319,18.777,
"112.50",15.351,18.80233,
"112.65",15.384,18.82733,
"112.80",15.42,18.85233,
"112.95",15.454,18.87733,
"113.10",15.488,18.90233,
"113.25",15.519,18.927,
"113.40",15.554,18.95233,
"113.55",15.588,18.97733,
"113.70",15.621,19.002,
"113.85",15.656,19.027,
"114.00",15.689,19.052,
"114.15",15.726,19.077,
"114.30",15.758,19.102,
"114.45",15.793,19.127,
"114.60",15.829,19.152,
"114.75",15.861,19.177,
"114.90",15.9,19.202,
"115.05",15.932,19.227,
"115.20",15.966,19.252,
"115.35",15.998,19.277,
"115.50",16.034,19.302,
"115.65",16.069,19.327,
"115.80",16.108,19.35233,
"115.95",16.146,19.37733,
"116.10",16.178,19.40233,
"116.25",16.212,19.42733,
"116.40",16.247,19.45233,
"116.55",16.282,19.47733,
"116.70",16.32,19.50233,
"116.85",16.356,19.52733,
"117.00",16.393,19.55233,
"117.15",16.428,19.577,
"117.30",16.462,19.602,
"117.45",16.495,19.62733,
"117.60",16.531,19.65233,
"117.75",16.567,19.677,
"117.90",16.606,19.70233,
"118.05",16.643,19.72733,
"118.20",16.679,19.75233,
"118.35",16.712,19.777,
"118.50",16.748,19.80233,
"118.65",16.781,19.82733,
"118.80",16.82,19.85233,
"118.95",16.857,19.877,
"119.10",16.894,19.902,
"119.25",16.93,19.92733,
"119.40",16.962,19.95233,
"119.55",17.001,19.97733,
"119.70",17.032,20.00233,
"119.85",17.073,20.02733,
"120.00",17.106,20.052,
"120.15",17.14,20.07733,
"120.30",17.175,20.10233,
"120.45",17.212,20.12733,
"120.60",17.247,20.15233,
"120.75",17.283,20.17733,
"120.90",17.32,20.20233,
"121.05",17.353,20.22733,
"121.20",17.387,20.25233,
"121.35",17.421,20.27733,
"121.50",17.456,20.30233,
"121.65",17.495,20.32733,
"121.80",17.531,20.352,
"121.95",17.566,20.37733,
"122.10",17.602,20.40233,
"122.25",17.634,20.42733,
"122.40",17.666,20.45233,
"122.55",17.702,20.47733,
"122.70",17.737,20.50233,
"122.85",17.774,20.52733,
"123.00",17.81,20.55233,
"123.15",17.845,20.57733,
"123.30",17.877,20.602,
"123.45",17.911,20.627,
"123.60",17.947,20.65233,
"123.75",17.981,20.677,
"123.90",18.02,20.702,
"124.05",18.054,20.727,
"124.20",18.089,20.75233,
"124.35",18.126,20.77733,
"124.50",18.161,20.80233,
"124.65",18.196,20.82733,
"124.80",18.233,20.85233,
"124.95",18.265,20.87733,
"125.10",18.301,20.902,
"125.25",18.334,20.92733,
"125.40",18.368,20.95233,
"125.55",18.4,20.977,
"125.70",18.439,21.002,
"125.85",18.471,21.02733,
"126.00",18.507,21.05233,
"126.15",18.539,21.07733,
"126.30",18.569,21.102,
"126.45",18.604,21.127,
"126.60",18.638,21.15233,
"126.75",18.672,21.17733,
"126.90",18.706,21.20233,
"127.05",18.74,21.22733,
"127.20",18.773,21.25233,
"127.35",18.803,21.277,
"127.50",18.834,21.302,
"127.65",18.869,21.327,
"127.80",18.903,21.352,
"127.95",18.937,21.377,
"128.10",18.97,21.402,
"128.25",19.001,21.427,
"128.40",19.031,21.45233,
"128.55",19.064,21.47733,
"128.70",19.097,21.502,
"128.85",19.132,21.527,
"129.00",19.163,21.552,
"129.15",19.194,21.57733,
"129.30",19.223,21.602,
"129.45",19.253,21.627,
"129.60",19.286,21.652,
"129.75",19.32,21.677,
"129.90",19.353,21.702,
"130.05",19.381,21.727,
"130.20",19.412,21.752,
"130.35",19.441,21.777,
"130.50",19.473,21.802,
"130.65",19.505,21.827,
"130.80",19.537,21.852,
"130.95",19.568,21.877,
"131.10",19.595,21.902,
"131.25",19.62,21.927,
"131.40",19.65,21.95233,
"131.55",19.679,21.977,
"131.70",19.71,22.002,
"131.85",19.742,22.02733,
"132.00",19.769,22.05233,
"132.15",19.798,22.07733,
"132.30",19.822,22.102,
"132.45",19.849,22.12733,
"132.60",19.881,22.15233,
"132.75",19.913,22.177,
"132.90",19.943,22.20233,
"133.05",19.972,22.227,
"133.20",20.002,22.252,
"133.35",20.027,22.277,
"133.50",20.052,22.302,
"133.65",20.083,22.327,
"133.80",20.112,22.352,
"133.95",20.142,22.377,
"134.10",20.167,22.402,
"134.25",20.198,22.427,
"134.40",20.23,22.452,
"134.55",20.257,22.477,
"134.70",20.29,22.502,
"134.85",20.321,22.52733,
"135.00",20.35,22.55233,
"135.15",20.374,22.57733,
"135.30",20.402,22.60233,
"135.45",20.431,22.62733,
"135.60",20.462,22.652,
"135.75",20.491,22.677,
"135.90",20.524,22.702,
"136.05",20.55,22.727,
"136.20",20.574,22.752,
"136.35",20.601,22.777,
"136.50",20.63,22.802,
"136.65",20.66,22.82733,
"136.80",20.694,22.85233,
"136.95",20.72,22.87733,
"137.10",20.748,22.902,
"137.25",20.776,22.927,
"137.40",20.805,22.952,
"137.55",20.829,22.977,
"137.70",20.86,23.00233,
"137.85",20.89,23.02733,
"138.00",20.918,23.05233,
"138.15",20.943,23.07733,
"138.30",20.97,23.10233,
"138.45",20.993,23.12733,
"138.60",21.02,23.15233,
"138.75",21.047,23.17733,
"138.90",21.075,23.20233,
"139.05",21.099,23.227,
"139.20",21.123,23.252,
"139.35",21.152,23.27733,
"139.50",21.178,23.30233,
"139.65",21.204,23.32733,
"139.80",21.232,23.35233,
"139.95",21.26,23.37733,
"140.10",21.281,23.40233,
"140.25",21.303,23.42733,
"140.40",21.329,23.45233,
"140.55",21.354,23.47733,
"140.70",21.381,23.50233,
"140.85",21.406,23.52733,
"141.00",21.428,23.55233,
"141.15",21.449,23.577,
"141.30",21.47,23.602,
"141.45",21.495,23.62733,
"141.60",21.519,23.65233,
"141.75",21.546,23.677,
"141.90",21.574,23.70233,
"142.05",21.599,23.72733,
"142.20",21.62,23.75233,
"142.35",21.644,23.777,
"142.50",21.667,23.80233,
"142.65",21.692,23.82733,
"142.80",21.719,23.85233,
"142.95",21.743,23.87733,
"143.10",21.766,23.90233,
"143.25",21.791,23.92733,
"143.40",21.812,23.95233,
"143.55",21.832,23.97733,
"143.70",21.857,24.002,
"143.85",21.88,24.02733,
"144.00",21.903,24.052,
"144.15",21.926,24.077,
"144.30",21.948,24.102,
"144.45",21.969,24.12733,
"144.60",21.994,24.15233,
"144.75",22.019,24.17733,
"144.90",22.04,24.20233,
"145.05",22.061,24.227,
"145.20",22.081,24.252,
"145.35",22.103,24.27733,
"145.50",22.124,24.30233,
"145.65",22.147,24.32733,
"145.80",22.173,24.352,
"145.95",22.197,24.377,
"146.10",22.216,24.402,
"146.25",22.234,24.427,
"146.40",22.253,24.45233,
"146.55",22.273,24.47733,
"146.70",22.299,24.50233,
"146.85",22.327,24.52733,
"147.00",22.349,24.552,
"147.15",22.365,24.577,
"147.30",22.386,24.602,
"147.45",22.408,24.62733,
"147.60",22.43,24.65233,
"147.75",22.455,24.67733,
"147.90",22.475,24.70233,
"148.05",22.497,24.72733,
"148.20",22.518,24.75233,
"148.35",22.537,24.77733,
"148.50",22.558,24.80233,
"148.65",22.577,24.82733,
"148.80",22.599,24.852,
"148.95",22.622,24.877,
"149.10",22.644,24.902,
"149.25",22.664,24.92733,
"149.40",22.684,24.952,
"149.55",22.704,24.977,
"149.70",22.728,25.002,
"149.85",22.749,25.027,
"150.00",22.771,25.052,
"150.15",22.794,25.077,
"150.30",22.81,25.102,
"150.45",22.831,25.127,
"150.60",22.855,25.15233,
"150.75",22.877,25.177,
"150.90",22.898,25.20233,
"151.05",22.919,25.22733,
"151.20",22.94,25.252,
"151.35",22.956,25.27733,
"151.50",22.977,25.302,
"151.65",23,25.32733,
"151.80",23.024,25.35233,
"151.95",23.046,25.37733,
"152.10",23.068,25.40233,
"152.25",23.085,25.42733,
"152.40",23.104,25.45233,
"152.55",23.122,25.47733,
"152.70",23.145,25.50233,
"152.85",23.169,25.52733,
"153.00",23.19,25.55233,
"153.15",23.212,25.57733,
"153.30",23.232,25.602,
"153.45",23.25,25.627,
"153.60",23.27,25.65233,
"153.75",23.295,25.677,
"153.90",23.312,25.70233,
"154.05",23.336,25.72733,
"154.20",23.357,25.75233,
"154.35",23.381,25.77733,
"154.50",23.402,25.80233,
"154.65",23.424,25.82733,
"154.80",23.449,25.852,
"154.95",23.47,25.87733,
"155.10",23.493,25.902,
"155.25",23.513,25.927,
"155.40",23.534,25.952,
"155.55",23.561,25.977,
"155.70",23.586,26.002,
"155.85",23.608,26.02733,
"156.00",23.631,26.05233,
"156.15",23.65,26.07733,
"156.30",23.668,26.102,
"156.45",23.69,26.12733,
"156.60",23.716,26.15233,
"156.75",23.74,26.177,
"156.90",23.766,26.202,
"157.05",23.787,26.227,
"157.20",23.808,26.252,
"157.35",23.827,26.277,
"157.50",23.85,26.302,
"157.65",23.875,26.327,
"157.80",23.9,26.352,
"157.95",23.923,26.377,
"158.10",23.949,26.402,
"158.25",23.968,26.427,
"158.40",23.99,26.452,
"158.55",24.01,26.477,
"158.70",24.03,26.502,
"158.85",24.05,26.527,
"159.00",24.08,26.552,
"159.15",24.1,26.57733,
"159.30",24.12,26.602,
"159.45",24.15,26.627,
"159.60",24.17,26.652,
"159.75",24.2,26.677,
"159.90",24.22,26.70233,
"160.05",24.24,26.72733,
"160.20",24.27,26.75233,
"160.35",24.29,26.777,
"160.50",24.31,26.802,
"160.65",24.34,26.82733,
"160.80",24.36,26.852,
"160.95",24.38,26.87733,
"161.10",24.4,26.902,
"161.25",24.42,26.92733,
"161.40",24.44,26.952,
"161.55",24.47,26.977,
"161.70",24.49,27.002,
"161.85",24.52,27.027,
"162.00",24.54,27.05233,
"162.15",24.57,27.07733,
"162.30",24.59,27.102,
"162.45",24.61,27.127,
"162.60",24.63,27.15233,
"162.75",24.66,27.177,
"162.90",24.68,27.20233,
"163.05",24.71,27.227,
"163.20",24.72,27.252,
"163.35",24.75,27.27733,
"163.50",24.77,27.302,
"163.65",24.79,27.32733,
"163.80",24.81,27.352,
"163.95",24.84,27.377,
"164.10",24.86,27.402,
"164.25",24.88,27.427,
"164.40",24.9,27.452,
"164.55",24.92,27.477,
"164.70",24.95,27.502,
"164.85",24.97,27.527,
"165.00",24.99,27.552,
"165.15",25.02,27.577,
"165.30",25.04,27.602,
"165.45",25.06,27.627,
"165.60",25.08,27.652,
"165.75",25.11,27.677,
"165.90",25.13,27.702,
"166.05",25.15,27.727,
"166.20",25.17,27.752,
"166.35",25.2,27.777,
"166.50",25.22,27.80233,
"166.65",25.24,27.82733,
"166.80",25.26,27.852,
"166.95",25.29,27.87733,
"167.10",25.31,27.902,
"167.25",25.33,27.927,
"167.40",25.35,27.952,
"167.55",25.37,27.97733,
"167.70",25.39,28.00233,
"167.85",25.42,28.027,
"168.00",25.44,28.052,
"168.15",25.46,28.07733,
"168.30",25.47,28.102,
"168.45",25.49,28.127,
"168.60",25.51,28.152,
"168.75",25.53,28.177,
"168.90",25.55,28.202,
"169.05",25.57,28.227,
"169.20",25.58,28.252,
"169.35",25.6,28.277,
"169.50",25.62,28.302,
"169.65",25.64,28.327,
"169.80",25.65,28.352,
"169.95",25.65,28.37733,
"170.10",25.66,28.40233,
"170.25",25.66,28.42733,
"170.40",25.67,28.45233,
"170.55",25.67,28.47733,
"170.70",25.66,28.502,
"170.85",25.65,28.527,
"171.00",25.59,28.552,
"171.15",25.43,28.577,
"171.30",25.14,28.602,
"171.45",24.85,28.627,
"171.60",24.67,28.652,
"171.75",24.57,28.677,
"171.90",24.52,28.70233,
"172.05",24.49,28.72733,
"172.20",24.47,28.752,
"172.35",24.47,28.777,
"172.50",24.47,28.80233,
"172.65",24.49,28.827,
"172.80",24.51,28.852,
"172.95",24.53,28.87733,
"173.10",24.56,28.90233,
"173.25",24.58,28.927,
"173.40",24.61,28.952,
"173.55",24.64,28.977,
"173.70",24.68,29.002,
"173.85",24.72,29.027,
"174.00",24.75,29.052,
"174.15",24.78,29.077,
"174.30",24.82,29.102,
"174.45",24.86,29.127,
"174.60",24.9,29.152,
"174.75",24.95,29.177,
"174.90",24.99,29.202,
"175.05",25.03,29.227,
"175.20",25.07,29.252,
"175.35",25.11,29.277,
"175.50",25.14,29.30233,
"175.65",25.18,29.32733,
"175.80",25.22,29.352,
"175.95",25.26,29.377,
"176.10",25.3,29.402,
"176.25",25.33,29.427,
"176.40",25.36,29.45233,
"176.55",25.39,29.477,
"176.70",25.42,29.502,
"176.85",25.45,29.52733,
"177.00",25.48,29.55233,
"177.15",25.51,29.577,
"177.30",25.53,29.602,
"177.45",25.55,29.627,
"177.60",25.57,29.652,
"177.75",25.6,29.677,
"177.90",25.62,29.702,
"178.05",25.65,29.72733,
"178.20",25.68,29.752,
"178.35",25.7,29.777,
"178.50",25.72,29.802,
"178.65",25.75,29.827,
"178.80",25.77,29.852,
"178.95",25.8,29.877,
"179.10",25.83,29.902,
"179.25",25.85,29.927,
"179.40",25.87,29.952,
"179.55",25.89,29.977,
"179.70",25.92,30.002,
"179.85",25.94,30.027,
"180.00",25.97,30.052,
"180.15",25.99,30.077,
"180.30",26.01,30.102,
"180.45",26.03,30.127,
"180.60",26.06,30.152,
"180.75",26.09,30.177,
"180.90",26.11,30.202,
"181.05",26.14,30.227,
"181.20",26.16,30.252,
"181.35",26.18,30.277,
"181.50",26.21,30.302,
"181.65",26.23,30.327,
"181.80",26.26,30.352,
"181.95",26.29,30.377,
"182.10",26.31,30.402,
"182.25",26.33,30.427,
"182.40",26.36,30.452,
"182.55",26.38,30.477,
"182.70",26.4,30.502,
"182.85",26.43,30.527,
"183.00",26.45,30.552,
"183.15",26.48,30.577,
"183.30",26.5,30.60233,
"183.45",26.52,30.627,
"183.60",26.55,30.652,
"183.75",26.57,30.677,
"183.90",26.59,30.702,
"184.05",26.61,30.727,
"184.20",26.63,30.752,
"184.35",26.65,30.777,
"184.50",26.68,30.80233,
"184.65",26.71,30.82733,
"184.80",26.73,30.852,
"184.95",26.75,30.877,
"185.10",26.77,30.90233,
"185.25",26.79,30.92733,
"185.40",26.82,30.95233,
"185.55",26.84,30.977,
"185.70",26.87,31.002,
"185.85",26.89,31.027,
"186.00",26.92,31.052,
"186.15",26.94,31.077,
"186.30",26.95,31.102,
"186.45",26.98,31.127,
"186.60",27.01,31.152,
"186.75",27.03,31.177,
"186.90",27.06,31.20233,
"187.05",27.08,31.227,
"187.20",27.1,31.252,
"187.35",27.12,31.277,
"187.50",27.14,31.302,
"187.65",27.16,31.327,
"187.80",27.19,31.352,
"187.95",27.21,31.377,
"188.10",27.23,31.402,
"188.25",27.25,31.427,
"188.40",27.27,31.452,
"188.55",27.29,31.477,
"188.70",27.31,31.502,
"188.85",27.33,31.527,
"189.00",27.35,31.552,
"189.15",27.37,31.577,
"189.30",27.39,31.602,
"189.45",27.41,31.627,
"189.60",27.44,31.65233,
"189.75",27.46,31.677,
"189.90",27.48,31.702,
"190.05",27.49,31.727,
"190.20",27.51,31.752,
"190.35",27.53,31.777,
"190.50",27.55,31.80233,
"190.65",27.57,31.82733,
"190.80",27.59,31.85233,
"190.95",27.62,31.87733,
"191.10",27.63,31.902,
"191.25",27.65,31.92733,
"191.40",27.67,31.952,
"191.55",27.69,31.977,
"191.70",27.71,32.002,
"191.85",27.74,32.027,
"192.00",27.76,32.052,
"192.15",27.78,32.07734,
"192.30",27.79,32.10233,
"192.45",27.81,32.12733,
"192.60",27.84,32.15234,
"192.75",27.86,32.17733,
"192.90",27.88,32.20234,
"193.05",27.91,32.227,
"193.20",27.93,32.252,
"193.35",27.95,32.277,
"193.50",27.96,32.302,
"193.65",27.98,32.327,
"193.80",28.01,32.352,
"193.95",28.03,32.377,
"194.10",28.04,32.402,
"194.25",28.06,32.427,
"194.40",28.08,32.452,
"194.55",28.11,32.477,
"194.70",28.13,32.502,
"194.85",28.15,32.527,
"195.00",28.17,32.552,
"195.15",28.19,32.577,
"195.30",28.21,32.602,
"195.45",28.23,32.627,
"195.60",28.25,32.65234,
"195.75",28.28,32.67733,
"195.90",28.3,32.70234,
"196.05",28.31,32.72733,
"196.20",28.33,32.75233,
"196.35",28.35,32.77734,
"196.50",28.37,32.80233,
"196.65",28.39,32.827,
"196.80",28.42,32.852,
"196.95",28.44,32.877,
"197.10",28.46,32.902,
"197.25",28.47,32.927,
"197.40",28.49,32.952,
"197.55",28.51,32.977,
"197.70",28.53,33.002,
"197.85",28.55,33.027,
"198.00",28.57,33.052,
"198.15",28.59,33.07734,
"198.30",28.61,33.102,
"198.45",28.62,33.127,
"198.60",28.64,33.152,
"198.75",28.66,33.177,
"198.90",28.69,33.202,
"199.05",28.7,33.227,
"199.20",28.72,33.252,
"199.35",28.74,33.277,
"199.50",28.76,33.302,
"199.65",28.78,33.327,
"199.80",28.8,33.352,
"199.95",28.82,33.377,
"200.10",28.84,33.402,
"200.25",28.85,33.427,
"200.40",28.87,33.452,
"200.55",28.89,33.47733,
"200.70",28.91,33.502,
"200.85",28.93,33.52734,
"201.00",28.96,33.55233,
"201.15",28.97,33.57734,
"201.30",28.99,33.60233,
"201.45",29.01,33.62733,
"201.60",29.03,33.65234,
"201.75",29.05,33.677,
"201.90",29.07,33.702,
"202.05",29.09,33.727,
"202.20",29.11,33.752,
"202.35",29.12,33.777,
"202.50",29.14,33.80233,
"202.65",29.16,33.82734,
"202.80",29.18,33.85233,
"202.95",29.2,33.87733,
"203.10",29.22,33.902,
"203.25",29.24,33.927,
"203.40",29.26,33.952,
"203.55",29.28,33.97733,
"203.70",29.3,34.002,
"203.85",29.32,34.027,
"204.00",29.33,34.052,
"204.15",29.35,34.077,
"204.30",29.37,34.102,
"204.45",29.38,34.127,
"204.60",29.4,34.152,
"204.75",29.42,34.177,
"204.90",29.44,34.202,
"205.05",29.45,34.227,
"205.20",29.46,34.252,
"205.25",29.468,34.26033,