File: exposed_flourocarbon_10cm_10mmpm_24nm_250esh_8.csv
"Test Name","Test Mode","Test Type","Control","Test Speed 1","Test Speed 2","Test Speed 3","Change Point 1","Change Point 2","Disp. Origin","Break and Limit Action","Sensitivity:","Level:"
"","Single","Tensile","Stroke",10,1,1,"Off","Off","Start","Stop",0,1

"Title","Sub title","Comment"
"","",""

"Shape:","Batch Size:","SubBatch Size:"
"Plate",1,1
"Name:","Thickness","Width","Gauge Length",
"Size Unit:","mm","mm","mm",
" 1 - 1","1.0000","1.0000","100.0000",

"Name",
"Parameter",
"Units",
" 1 - 1",

" 1- 1"
"Time","Force","Stroke",
"sec","N","mm",
"0.00",.001,0,
"0.15",0,2.766667E-02,
"0.30",.011,5.533333E-02,
"0.45",.034,.083,
"0.60",.057,.111,
"0.75",.082,.1386667,
"0.90",.107,.1666667,
"1.05",.131,.1943333,
"1.20",.159,.2223333,
"1.35",.184,.25,
"1.50",.209,.278,
"1.65",.238,.3056667,
"1.80",.264,.3336667,
"1.95",.291,.3613333,
"2.10",.316,.3883334,
"2.25",.341,.4153333,
"2.40",.365,.442,
"2.55",.39,.4683333,
"2.70",.417,.4946667,
"2.85",.439,.5206667,
"3.00",.461,.5466667,
"3.15",.486,.5723333,
"3.30",.509,.598,
"3.45",.531,.6236666,
"3.60",.554,.649,
"3.75",.576,.6743333,
"3.90",.599,.7,
"4.05",.623,.725,
"4.20",.645,.7503333,
"4.35",.665,.7756667,
"4.50",.686,.801,
"4.65",.71,.826,
"4.80",.731,.8513333,
"4.95",.755,.876,
"5.10",.773,.9013333,
"5.25",.793,.9263333,
"5.40",.812,.9516667,
"5.55",.834,.9766667,
"5.70",.854,1.001667,
"5.85",.876,1.026667,
"6.00",.895,1.052,
"6.15",.912,1.076667,
"6.30",.933,1.101667,
"6.45",.952,1.126667,
"6.60",.974,1.151667,
"6.75",.992,1.176667,
"6.90",1.011,1.201667,
"7.05",1.031,1.227,
"7.20",1.047,1.252,
"7.35",1.067,1.277,
"7.50",1.084,1.302,
"7.65",1.105,1.327,
"7.80",1.122,1.352,
"7.95",1.139,1.377,
"8.10",1.156,1.402,
"8.25",1.172,1.427,
"8.40",1.19,1.452,
"8.55",1.205,1.477,
"8.70",1.226,1.502,
"8.85",1.244,1.527333,
"9.00",1.26,1.552333,
"9.15",1.277,1.577333,
"9.30",1.291,1.602333,
"9.45",1.31,1.627,
"9.60",1.324,1.652,
"9.75",1.341,1.677333,
"9.90",1.358,1.702,
"10.05",1.376,1.727,
"10.20",1.388,1.752,
"10.35",1.402,1.777,
"10.50",1.419,1.802,
"10.65",1.434,1.827,
"10.80",1.449,1.852,
"10.95",1.463,1.877,
"11.10",1.476,1.902,
"11.25",1.492,1.927,
"11.40",1.506,1.952,
"11.55",1.521,1.977333,
"11.70",1.534,2.002,
"11.85",1.551,2.027333,
"12.00",1.565,2.052333,
"12.15",1.578,2.077333,
"12.30",1.591,2.102333,
"12.45",1.605,2.127,
"12.60",1.618,2.152,
"12.75",1.632,2.177,
"12.90",1.646,2.202,
"13.05",1.659,2.227,
"13.20",1.671,2.252,
"13.35",1.684,2.277,
"13.50",1.695,2.302,
"13.65",1.709,2.327,
"13.80",1.723,2.352,
"13.95",1.738,2.377,
"14.10",1.751,2.402,
"14.25",1.762,2.427,
"14.40",1.776,2.452,
"14.55",1.789,2.477,
"14.70",1.803,2.502,
"14.85",1.815,2.527,
"15.00",1.827,2.552,
"15.15",1.84,2.577,
"15.30",1.852,2.602333,
"15.45",1.868,2.627333,
"15.60",1.879,2.652333,
"15.75",1.89,2.677333,
"15.90",1.904,2.702333,
"16.05",1.916,2.727333,
"16.20",1.928,2.752,
"16.35",1.939,2.777,
"16.50",1.951,2.802,
"16.65",1.965,2.827,
"16.80",1.976,2.852,
"16.95",1.99,2.877,
"17.10",2.001,2.902,
"17.25",2.012,2.927,
"17.40",2.024,2.952,
"17.55",2.035,2.977,
"17.70",2.05,3.002,
"17.85",2.063,3.027,
"18.00",2.077,3.052333,
"18.15",2.087,3.077,
"18.30",2.097,3.102,
"18.45",2.108,3.127,
"18.60",2.121,3.152,
"18.75",2.134,3.177333,
"18.90",2.145,3.202,
"19.05",2.16,3.227,
"19.20",2.17,3.252,
"19.35",2.179,3.277,
"19.50",2.193,3.302,
"19.65",2.207,3.327,
"19.80",2.218,3.352,
"19.95",2.23,3.377,
"20.10",2.242,3.402,
"20.25",2.256,3.427,
"20.40",2.27,3.452,
"20.55",2.28,3.477,
"20.70",2.292,3.502,
"20.85",2.305,3.527,
"21.00",2.316,3.552,
"21.15",2.329,3.576667,
"21.30",2.342,3.601667,
"21.45",2.352,3.627,
"21.60",2.364,3.652,
"21.75",2.38,3.677,
"21.90",2.392,3.702,
"22.05",2.399,3.727,
"22.20",2.413,3.751667,
"22.35",2.425,3.776667,
"22.50",2.438,3.801667,
"22.65",2.452,3.826667,
"22.80",2.465,3.852,
"22.95",2.477,3.876667,
"23.10",2.487,3.901667,
"23.25",2.498,3.927,
"23.40",2.511,3.951667,
"23.55",2.523,3.977,
"23.70",2.537,4.002,
"23.85",2.547,4.027,
"24.00",2.56,4.052,
"24.15",2.568,4.077,
"24.30",2.58,4.102,
"24.45",2.594,4.127,
"24.60",2.606,4.151667,
"24.75",2.618,4.177,
"24.90",2.63,4.202,
"25.05",2.643,4.227,
"25.20",2.655,4.252,
"25.35",2.669,4.277,
"25.50",2.681,4.302,
"25.65",2.692,4.327,
"25.80",2.707,4.352,
"25.95",2.718,4.377,
"26.10",2.729,4.402,
"26.25",2.743,4.427,
"26.40",2.756,4.452,
"26.55",2.769,4.477,
"26.70",2.783,4.502,
"26.85",2.798,4.527,
"27.00",2.809,4.552333,
"27.15",2.82,4.577333,
"27.30",2.834,4.602333,
"27.45",2.846,4.627333,
"27.60",2.86,4.652333,
"27.75",2.874,4.677,
"27.90",2.887,4.702,
"28.05",2.901,4.727333,
"28.20",2.911,4.752,
"28.35",2.926,4.777,
"28.50",2.937,4.802,
"28.65",2.954,4.827,
"28.80",2.968,4.852,
"28.95",2.98,4.877,
"29.10",2.99,4.902,
"29.25",3.005,4.927,
"29.40",3.019,4.952,
"29.55",3.03,4.977,
"29.70",3.045,5.002333,
"29.85",3.059,5.027333,
"30.00",3.071,5.052333,
"30.15",3.085,5.077333,
"30.30",3.095,5.102333,
"30.45",3.111,5.127333,
"30.60",3.125,5.152333,
"30.75",3.138,5.177333,
"30.90",3.15,5.202,
"31.05",3.164,5.227,
"31.20",3.175,5.252,
"31.35",3.187,5.277,
"31.50",3.202,5.302333,
"31.65",3.218,5.327,
"31.80",3.228,5.352,
"31.95",3.242,5.377,
"32.10",3.254,5.402,
"32.25",3.269,5.427,
"32.40",3.283,5.452,
"32.55",3.295,5.477,
"32.70",3.309,5.501667,
"32.85",3.324,5.526667,
"33.00",3.337,5.551666,
"33.15",3.351,5.576666,
"33.30",3.363,5.601666,
"33.45",3.379,5.627,
"33.60",3.393,5.652,
"33.75",3.406,5.677,
"33.90",3.418,5.702,
"34.05",3.431,5.727,
"34.20",3.447,5.751667,
"34.35",3.457,5.777,
"34.50",3.473,5.802,
"34.65",3.488,5.827,
"34.80",3.501,5.852,
"34.95",3.514,5.877,
"35.10",3.527,5.902,
"35.25",3.543,5.926666,
"35.40",3.557,5.952,
"35.55",3.571,5.976666,
"35.70",3.585,6.002,
"35.85",3.599,6.027,
"36.00",3.611,6.052,
"36.15",3.625,6.077,
"36.30",3.639,6.102,
"36.45",3.654,6.126667,
"36.60",3.668,6.151667,
"36.75",3.681,6.176666,
"36.90",3.695,6.201666,
"37.05",3.708,6.226666,
"37.20",3.723,6.251667,
"37.35",3.739,6.276667,
"37.50",3.751,6.301666,
"37.65",3.767,6.327,
"37.80",3.781,6.352,
"37.95",3.796,6.377,
"38.10",3.811,6.401667,
"38.25",3.825,6.427,
"38.40",3.837,6.452,
"38.55",3.851,6.477,
"38.70",3.865,6.502,
"38.85",3.88,6.527,
"39.00",3.893,6.552,
"39.15",3.91,6.577,
"39.30",3.925,6.602,
"39.45",3.938,6.627,
"39.60",3.953,6.651667,
"39.75",3.966,6.676666,
"39.90",3.981,6.702,
"40.05",3.997,6.727,
"40.20",4.008,6.752,
"40.35",4.025,6.777,
"40.50",4.039,6.802,
"40.65",4.055,6.827,
"40.80",4.071,6.852333,
"40.95",4.085,6.877333,
"41.10",4.097,6.902333,
"41.25",4.115,6.927333,
"41.40",4.129,6.952333,
"41.55",4.145,6.977333,
"41.70",4.163,7.002,
"41.85",4.176,7.027,
"42.00",4.191,7.052,
"42.15",4.207,7.077,
"42.30",4.222,7.102,
"42.45",4.238,7.127,
"42.60",4.254,7.151667,
"42.75",4.271,7.177,
"42.90",4.285,7.201666,
"43.05",4.301,7.226666,
"43.20",4.315,7.251667,
"43.35",4.333,7.276667,
"43.50",4.35,7.302,
"43.65",4.367,7.327,
"43.80",4.381,7.352,
"43.95",4.399,7.377,
"44.10",4.415,7.402,
"44.25",4.43,7.427,
"44.40",4.447,7.452,
"44.55",4.463,7.477,
"44.70",4.48,7.502,
"44.85",4.494,7.527,
"45.00",4.508,7.552,
"45.15",4.525,7.577,
"45.30",4.542,7.602,
"45.45",4.558,7.627,
"45.60",4.576,7.652,
"45.75",4.594,7.677,
"45.90",4.61,7.702,
"46.05",4.624,7.727,
"46.20",4.639,7.752,
"46.35",4.657,7.777,
"46.50",4.674,7.802,
"46.65",4.691,7.827,
"46.80",4.708,7.852,
"46.95",4.727,7.877,
"47.10",4.742,7.902,
"47.25",4.759,7.927,
"47.40",4.773,7.952,
"47.55",4.792,7.977,
"47.70",4.807,8.002,
"47.85",4.825,8.027,
"48.00",4.843,8.052,
"48.15",4.86,8.077001,
"48.30",4.874,8.102,
"48.45",4.891,8.127,
"48.60",4.909,8.152,
"48.75",4.929,8.177,
"48.90",4.946,8.202001,
"49.05",4.962,8.227,
"49.20",4.979,8.252,
"49.35",4.997,8.277,
"49.50",5.013,8.302,
"49.65",5.031,8.327001,
"49.80",5.047,8.352,
"49.95",5.066,8.377,
"50.10",5.082,8.402,
"50.25",5.099,8.427,
"50.40",5.115,8.452001,
"50.55",5.133,8.477,
"50.70",5.152,8.502,
"50.85",5.169,8.527,
"51.00",5.185,8.552,
"51.15",5.197,8.577001,
"51.30",5.215,8.602,
"51.45",5.233,8.627,
"51.60",5.252,8.652,
"51.75",5.272,8.677,
"51.90",5.286,8.702001,
"52.05",5.307,8.727,
"52.20",5.324,8.752,
"52.35",5.341,8.777,
"52.50",5.359,8.802,
"52.65",5.376,8.827001,
"52.80",5.393,8.852,
"52.95",5.409,8.877,
"53.10",5.428,8.902,
"53.25",5.447,8.927,
"53.40",5.467,8.952001,
"53.55",5.486,8.977,
"53.70",5.505,9.002,
"53.85",5.524,9.027,
"54.00",5.54,9.052,
"54.15",5.556,9.077001,
"54.30",5.574,9.102,
"54.45",5.595,9.127,
"54.60",5.615,9.152,
"54.75",5.635,9.177,
"54.90",5.653,9.202001,
"55.05",5.67,9.226666,
"55.20",5.687,9.251667,
"55.35",5.706,9.277,
"55.50",5.725,9.302,
"55.65",5.745,9.327001,
"55.80",5.763,9.352,
"55.95",5.784,9.377,
"56.10",5.803,9.402,
"56.25",5.822,9.427,
"56.40",5.838,9.452001,
"56.55",5.858,9.477,
"56.70",5.881,9.502,
"56.85",5.903,9.527,
"57.00",5.918,9.552,
"57.15",5.935,9.577001,
"57.30",5.957,9.602,
"57.45",5.977,9.627,
"57.60",5.995,9.652,
"57.75",6.012,9.677,
"57.90",6.035,9.702001,
"58.05",6.052,9.727,
"58.20",6.071,9.752,
"58.35",6.093,9.777,
"58.50",6.11,9.801667,
"58.65",6.13,9.826667,
"58.80",6.149,9.851666,
"58.95",6.165,9.876667,
"59.10",6.187,9.901667,
"59.25",6.208,9.927,
"59.40",6.23,9.952001,
"59.55",6.251,9.977,
"59.70",6.27,10.002,
"59.85",6.29,10.027,
"60.00",6.309,10.052,
"60.15",6.329,10.077,
"60.30",6.348,10.102,
"60.45",6.369,10.12733,
"60.60",6.39,10.152,
"60.75",6.411,10.177,
"60.90",6.43,10.20233,
"61.05",6.451,10.22733,
"61.20",6.469,10.25233,
"61.35",6.49,10.27733,
"61.50",6.511,10.302,
"61.65",6.531,10.327,
"61.80",6.554,10.352,
"61.95",6.574,10.37733,
"62.10",6.595,10.40233,
"62.25",6.614,10.427,
"62.40",6.633,10.452,
"62.55",6.656,10.477,
"62.70",6.677,10.502,
"62.85",6.701,10.527,
"63.00",6.722,10.552,
"63.15",6.742,10.577,
"63.30",6.76,10.602,
"63.45",6.782,10.627,
"63.60",6.803,10.652,
"63.75",6.826,10.677,
"63.90",6.848,10.702,
"64.05",6.868,10.727,
"64.20",6.889,10.752,
"64.35",6.912,10.777,
"64.50",6.934,10.802,
"64.65",6.956,10.827,
"64.80",6.975,10.852,
"64.95",6.998,10.877,
"65.10",7.017,10.902,
"65.25",7.037,10.927,
"65.40",7.062,10.952,
"65.55",7.081,10.977,
"65.70",7.103,11.00233,
"65.85",7.126,11.02733,
"66.00",7.147,11.05233,
"66.15",7.166,11.077,
"66.30",7.187,11.102,
"66.45",7.211,11.12733,
"66.60",7.234,11.152,
"66.75",7.257,11.17733,
"66.90",7.279,11.202,
"67.05",7.3,11.227,
"67.20",7.319,11.252,
"67.35",7.338,11.277,
"67.50",7.361,11.302,
"67.65",7.386,11.327,
"67.80",7.409,11.352,
"67.95",7.43,11.377,
"68.10",7.454,11.402,
"68.25",7.474,11.427,
"68.40",7.495,11.452,
"68.55",7.517,11.47667,
"68.70",7.54,11.502,
"68.85",7.561,11.52667,
"69.00",7.584,11.552,
"69.15",7.605,11.577,
"69.30",7.629,11.602,
"69.45",7.653,11.62667,
"69.60",7.676,11.65167,
"69.75",7.699,11.67667,
"69.90",7.72,11.702,
"70.05",7.741,11.727,
"70.20",7.762,11.752,
"70.35",7.788,11.777,
"70.50",7.812,11.802,
"70.65",7.835,11.827,
"70.80",7.857,11.852,
"70.95",7.881,11.87667,
"71.10",7.904,11.90167,
"71.25",7.925,11.92667,
"71.40",7.946,11.95167,
"71.55",7.973,11.977,
"71.70",7.997,12.002,
"71.85",8.019,12.027,
"72.00",8.042,12.052,
"72.15",8.064,12.07667,
"72.30",8.086,12.102,
"72.45",8.109,12.12667,
"72.60",8.133,12.15167,
"72.75",8.159,12.17667,
"72.90",8.183,12.20167,
"73.05",8.206,12.227,
"73.20",8.231,12.25167,
"73.35",8.253,12.27667,
"73.50",8.274,12.30167,
"73.65",8.301,12.32667,
"73.80",8.324,12.352,
"73.95",8.345,12.377,
"74.10",8.369,12.402,
"74.25",8.395,12.427,
"74.40",8.419,12.452,
"74.55",8.442,12.477,
"74.70",8.467,12.502,
"74.85",8.491,12.52667,
"75.00",8.511,12.55167,
"75.15",8.536,12.57667,
"75.30",8.559,12.602,
"75.45",8.584,12.627,
"75.60",8.61,12.652,
"75.75",8.633,12.677,
"75.90",8.659,12.702,
"76.05",8.682,12.727,
"76.20",8.702,12.75167,
"76.35",8.724,12.777,
"76.50",8.752,12.802,
"76.65",8.78,12.827,
"76.80",8.807,12.852,
"76.95",8.83,12.877,
"77.10",8.853,12.902,
"77.25",8.878,12.927,
"77.40",8.901,12.952,
"77.55",8.927,12.977,
"77.70",8.953,13.002,
"77.85",8.981,13.027,
"78.00",9.006,13.052,
"78.15",9.033,13.077,
"78.30",9.053,13.102,
"78.45",9.077,13.127,
"78.60",9.103,13.152,
"78.75",9.129,13.177,
"78.90",9.154,13.202,
"79.05",9.181,13.227,
"79.20",9.206,13.25233,
"79.35",9.233,13.27733,
"79.50",9.26,13.30233,
"79.65",9.289,13.32733,
"79.80",9.316,13.35233,
"79.95",9.339,13.377,
"80.10",9.363,13.40233,
"80.25",9.391,13.42733,
"80.40",9.418,13.452,
"80.55",9.446,13.477,
"80.70",9.475,13.502,
"80.85",9.5,13.527,
"81.00",9.525,13.552,
"81.15",9.551,13.577,
"81.30",9.577,13.602,
"81.45",9.603,13.62733,
"81.60",9.632,13.652,
"81.75",9.66,13.67733,
"81.90",9.688,13.70233,
"82.05",9.717,13.727,
"82.20",9.741,13.752,
"82.35",9.77,13.777,
"82.50",9.797,13.802,
"82.65",9.826,13.82667,
"82.80",9.853,13.852,
"82.95",9.882,13.877,
"83.10",9.91,13.902,
"83.25",9.936,13.92667,
"83.40",9.964,13.952,
"83.55",9.993,13.977,
"83.70",10.022,14.002,
"83.85",10.05,14.02667,
"84.00",10.078,14.052,
"84.15",10.104,14.077,
"84.30",10.135,14.102,
"84.45",10.164,14.12733,
"84.60",10.195,14.15233,
"84.75",10.223,14.17733,
"84.90",10.251,14.202,
"85.05",10.277,14.227,
"85.20",10.305,14.25233,
"85.35",10.338,14.277,
"85.50",10.368,14.302,
"85.65",10.398,14.327,
"85.80",10.426,14.352,
"85.95",10.453,14.377,
"86.10",10.481,14.402,
"86.25",10.509,14.427,
"86.40",10.538,14.452,
"86.55",10.569,14.477,
"86.70",10.6,14.502,
"86.85",10.629,14.527,
"87.00",10.66,14.55233,
"87.15",10.688,14.57733,
"87.30",10.718,14.60233,
"87.45",10.748,14.62733,
"87.60",10.78,14.65233,
"87.75",10.811,14.67733,
"87.90",10.844,14.70233,
"88.05",10.874,14.72733,
"88.20",10.902,14.75233,
"88.35",10.931,14.77733,
"88.50",10.962,14.802,
"88.65",10.994,14.827,
"88.80",11.024,14.852,
"88.95",11.053,14.877,
"89.10",11.083,14.902,
"89.25",11.115,14.927,
"89.40",11.142,14.952,
"89.55",11.174,14.977,
"89.70",11.209,15.002,
"89.85",11.242,15.027,
"90.00",11.272,15.052,
"90.15",11.299,15.077,
"90.30",11.331,15.102,
"90.45",11.363,15.127,
"90.60",11.396,15.152,
"90.75",11.43,15.177,
"90.90",11.46,15.202,
"91.05",11.49,15.227,
"91.20",11.519,15.252,
"91.35",11.55,15.277,
"91.50",11.585,15.302,
"91.65",11.621,15.327,
"91.80",11.652,15.35233,
"91.95",11.685,15.377,
"92.10",11.713,15.402,
"92.25",11.744,15.427,
"92.40",11.778,15.452,
"92.55",11.812,15.477,
"92.70",11.846,15.502,
"92.85",11.88,15.527,
"93.00",11.911,15.552,
"93.15",11.94,15.577,
"93.30",11.973,15.602,
"93.45",12.007,15.627,
"93.60",12.039,15.652,
"93.75",12.073,15.677,
"93.90",12.105,15.702,
"94.05",12.137,15.727,
"94.20",12.173,15.75233,
"94.35",12.205,15.777,
"94.50",12.242,15.80233,
"94.65",12.273,15.827,
"94.80",12.308,15.85233,
"94.95",12.34,15.877,
"95.10",12.375,15.902,
"95.25",12.408,15.927,
"95.40",12.443,15.952,
"95.55",12.476,15.977,
"95.70",12.509,16.002,
"95.85",12.545,16.027,
"96.00",12.577,16.052,
"96.15",12.61,16.077,
"96.30",12.643,16.102,
"96.45",12.675,16.127,
"96.60",12.713,16.152,
"96.75",12.75,16.177,
"96.90",12.782,16.202,
"97.05",12.816,16.227,
"97.20",12.848,16.252,
"97.35",12.878,16.277,
"97.50",12.918,16.302,
"97.65",12.955,16.327,
"97.80",12.992,16.352,
"97.95",13.028,16.377,
"98.10",13.063,16.402,
"98.25",13.099,16.427,
"98.40",13.133,16.452,
"98.55",13.168,16.477,
"98.70",13.204,16.502,
"98.85",13.241,16.527,
"99.00",13.275,16.552,
"99.15",13.312,16.577,
"99.30",13.346,16.602,
"99.45",13.382,16.627,
"99.60",13.422,16.652,
"99.75",13.456,16.677,
"99.90",13.494,16.702,
"100.05",13.528,16.727,
"100.20",13.563,16.752,
"100.35",13.598,16.777,
"100.50",13.636,16.802,
"100.65",13.676,16.827,
"100.80",13.711,16.852,
"100.95",13.747,16.877,
"101.10",13.783,16.902,
"101.25",13.818,16.927,
"101.40",13.856,16.952,
"101.55",13.892,16.977,
"101.70",13.931,17.002,
"101.85",13.968,17.027,
"102.00",14.004,17.052,
"102.15",14.04,17.077,
"102.30",14.074,17.102,
"102.45",14.11,17.127,
"102.60",14.152,17.152,
"102.75",14.191,17.177,
"102.90",14.228,17.202,
"103.05",14.266,17.227,
"103.20",14.302,17.252,
"103.35",14.335,17.277,
"103.50",14.373,17.302,
"103.65",14.414,17.327,
"103.80",14.45,17.352,
"103.95",14.488,17.377,
"104.10",14.525,17.402,
"104.25",14.562,17.427,
"104.40",14.599,17.452,
"104.55",14.641,17.477,
"104.70",14.678,17.502,
"104.85",14.715,17.527,
"105.00",14.752,17.552,
"105.15",14.787,17.577,
"105.30",14.828,17.60233,
"105.45",14.865,17.62733,
"105.60",14.906,17.652,
"105.75",14.945,17.677,
"105.90",14.982,17.70233,
"106.05",15.017,17.727,
"106.20",15.054,17.75233,
"106.35",15.094,17.77733,
"106.50",15.133,17.80233,
"106.65",15.172,17.82733,
"106.80",15.21,17.85233,
"106.95",15.248,17.87733,
"107.10",15.284,17.90233,
"107.25",15.319,17.92733,
"107.40",15.356,17.952,
"107.55",15.396,17.97733,
"107.70",15.434,18.002,
"107.85",15.475,18.027,
"108.00",15.511,18.052,
"108.15",15.546,18.077,
"108.30",15.582,18.10233,
"108.45",15.622,18.127,
"108.60",15.661,18.152,
"108.75",15.699,18.177,
"108.90",15.737,18.202,
"109.05",15.774,18.227,
"109.20",15.81,18.25233,
"109.35",15.847,18.27733,
"109.50",15.887,18.30233,
"109.65",15.929,18.327,
"109.80",15.968,18.35233,
"109.95",16.002,18.377,
"110.10",16.038,18.402,
"110.25",16.076,18.42733,
"110.40",16.117,18.45233,
"110.55",16.157,18.477,
"110.70",16.194,18.502,
"110.85",16.231,18.527,
"111.00",16.268,18.552,
"111.15",16.306,18.577,
"111.30",16.343,18.60233,
"111.45",16.381,18.62733,
"111.60",16.418,18.65233,
"111.75",16.46,18.67733,
"111.90",16.498,18.70233,
"112.05",16.53,18.72733,
"112.20",16.566,18.75233,
"112.35",16.603,18.77733,
"112.50",16.639,18.80233,
"112.65",16.68,18.827,
"112.80",16.716,18.852,
"112.95",16.755,18.877,
"113.10",16.793,18.902,
"113.25",16.828,18.927,
"113.40",16.865,18.952,
"113.55",16.904,18.977,
"113.70",16.942,19.002,
"113.85",16.978,19.02733,
"114.00",17.017,19.05233,
"114.15",17.048,19.077,
"114.30",17.085,19.10233,
"114.45",17.122,19.127,
"114.60",17.16,19.152,
"114.75",17.2,19.177,
"114.90",17.236,19.202,
"115.05",17.269,19.227,
"115.20",17.307,19.252,
"115.35",17.344,19.277,
"115.50",17.381,19.302,
"115.65",17.416,19.327,
"115.80",17.452,19.352,
"115.95",17.488,19.377,
"116.10",17.523,19.402,
"116.25",17.557,19.42733,
"116.40",17.593,19.452,
"116.55",17.629,19.477,
"116.70",17.668,19.502,
"116.85",17.705,19.527,
"117.00",17.74,19.552,
"117.15",17.774,19.577,
"117.30",17.809,19.602,
"117.45",17.842,19.627,
"117.60",17.879,19.652,
"117.75",17.916,19.67733,
"117.90",17.953,19.70233,
"118.05",17.985,19.72733,
"118.20",18.02,19.752,
"118.35",18.056,19.777,
"118.50",18.09,19.802,
"118.65",18.127,19.827,
"118.80",18.164,19.85233,
"118.95",18.2,19.877,
"119.10",18.232,19.902,
"119.25",18.268,19.927,
"119.40",18.302,19.952,
"119.55",18.341,19.977,
"119.70",18.378,20.002,
"119.85",18.41,20.02733,
"120.00",18.445,20.05233,
"120.15",18.475,20.077,
"120.30",18.508,20.10233,
"120.45",18.543,20.12733,
"120.60",18.58,20.152,
"120.75",18.616,20.177,
"120.90",18.643,20.202,
"121.05",18.673,20.227,
"121.20",18.708,20.252,
"121.35",18.741,20.277,
"121.50",18.773,20.302,
"121.65",18.809,20.327,
"121.80",18.842,20.35233,
"121.95",18.872,20.37733,
"122.10",18.9,20.40233,
"122.25",18.93,20.427,
"122.40",18.959,20.452,
"122.55",18.995,20.477,
"122.70",19.027,20.502,
"122.85",19.058,20.527,
"123.00",19.091,20.55233,
"123.15",19.119,20.577,
"123.30",19.148,20.60233,
"123.45",19.18,20.62733,
"123.60",19.214,20.65233,
"123.75",19.248,20.677,
"123.90",19.277,20.702,
"124.05",19.308,20.727,
"124.20",19.34,20.752,
"124.35",19.374,20.777,
"124.50",19.407,20.80233,
"124.65",19.438,20.827,
"124.80",19.469,20.852,
"124.95",19.497,20.87733,
"125.10",19.528,20.902,
"125.25",19.56,20.92733,
"125.40",19.591,20.952,
"125.55",19.623,20.977,
"125.70",19.652,21.002,
"125.85",19.68,21.027,
"126.00",19.709,21.052,
"126.15",19.735,21.077,
"126.30",19.763,21.102,
"126.45",19.794,21.127,
"126.60",19.827,21.152,
"126.75",19.858,21.177,
"126.90",19.883,21.202,
"127.05",19.91,21.227,
"127.20",19.938,21.252,
"127.35",19.963,21.277,
"127.50",19.993,21.302,
"127.65",20.026,21.327,
"127.80",20.054,21.352,
"127.95",20.079,21.377,
"128.10",20.106,21.402,
"128.25",20.128,21.427,
"128.40",20.156,21.452,
"128.55",20.182,21.477,
"128.70",20.21,21.502,
"128.85",20.238,21.527,
"129.00",20.264,21.552,
"129.15",20.285,21.577,
"129.30",20.309,21.602,
"129.45",20.334,21.627,
"129.60",20.359,21.652,
"129.75",20.384,21.677,
"129.90",20.405,21.702,
"130.05",20.427,21.727,
"130.20",20.446,21.752,
"130.35",20.471,21.777,
"130.50",20.492,21.802,
"130.65",20.512,21.827,
"130.80",20.53,21.852,
"130.95",20.548,21.877,
"131.10",20.566,21.902,
"131.25",20.583,21.927,
"131.40",20.601,21.952,
"131.55",20.621,21.977,
"131.70",20.642,22.002,
"131.85",20.664,22.027,
"132.00",20.683,22.052,
"132.15",20.701,22.077,
"132.30",20.718,22.102,
"132.45",20.74,22.127,
"132.60",20.762,22.152,
"132.75",20.781,22.177,
"132.90",20.797,22.202,
"133.05",20.814,22.227,
"133.20",20.83,22.252,
"133.35",20.843,22.277,
"133.50",20.862,22.302,
"133.65",20.882,22.327,
"133.80",20.901,22.35233,
"133.95",20.923,22.37733,
"134.10",20.943,22.40233,
"134.25",20.962,22.427,
"134.40",20.988,22.452,
"134.55",21.008,22.477,
"134.70",21.031,22.502,
"134.85",21.055,22.527,
"135.00",21.073,22.55167,
"135.15",21.099,22.577,
"135.30",21.121,22.602,
"135.45",21.149,22.62667,
"135.60",21.173,22.65167,
"135.75",21.2,22.67667,
"135.90",21.223,22.70167,
"136.05",21.246,22.727,
"136.20",21.267,22.752,
"136.35",21.292,22.777,
"136.50",21.318,22.802,
"136.65",21.345,22.82667,
"136.80",21.369,22.85167,
"136.95",21.391,22.87667,
"137.10",21.409,22.902,
"137.25",21.431,22.927,
"137.40",21.454,22.952,
"137.55",21.479,22.977,
"137.70",21.504,23.002,
"137.85",21.53,23.027,
"138.00",21.554,23.052,
"138.15",21.58,23.077,
"138.30",21.602,23.102,
"138.45",21.626,23.127,
"138.60",21.651,23.152,
"138.75",21.677,23.177,
"138.90",21.701,23.202,
"139.05",21.722,23.22667,
"139.20",21.744,23.25167,
"139.35",21.767,23.277,
"139.50",21.794,23.302,
"139.65",21.817,23.327,
"139.80",21.84,23.352,
"139.95",21.86,23.377,
"140.10",21.88,23.402,
"140.25",21.902,23.427,
"140.40",21.926,23.452,
"140.55",21.95,23.477,
"140.70",21.976,23.502,
"140.85",21.999,23.527,
"141.00",22.016,23.552,
"141.15",22.038,23.577,
"141.30",22.06,23.602,
"141.45",22.084,23.627,
"141.60",22.107,23.652,
"141.75",22.134,23.67733,
"141.90",22.155,23.70233,
"142.05",22.181,23.72733,
"142.20",22.201,23.752,
"142.35",22.222,23.77733,
"142.50",22.246,23.802,
"142.65",22.269,23.827,
"142.80",22.293,23.852,
"142.95",22.315,23.877,
"143.10",22.337,23.902,
"143.25",22.358,23.927,
"143.40",22.379,23.952,
"143.55",22.403,23.977,
"143.70",22.425,24.002,
"143.85",22.445,24.027,
"144.00",22.467,24.052,
"144.15",22.489,24.07733,
"144.30",22.511,24.10233,
"144.45",22.536,24.12733,
"144.60",22.561,24.152,
"144.75",22.581,24.177,
"144.90",22.601,24.202,
"145.05",22.623,24.227,
"145.20",22.647,24.252,
"145.35",22.669,24.277,
"145.50",22.693,24.302,
"145.65",22.718,24.327,
"145.80",22.741,24.352,
"145.95",22.758,24.377,
"146.10",22.779,24.402,
"146.25",22.803,24.427,
"146.40",22.828,24.452,
"146.55",22.853,24.477,
"146.70",22.879,24.502,
"146.85",22.902,24.527,
"147.00",22.925,24.552,
"147.15",22.944,24.577,
"147.30",22.969,24.602,
"147.45",22.993,24.62733,
"147.60",23.018,24.652,
"147.75",23.045,24.67733,
"147.90",23.071,24.70233,
"148.05",23.091,24.72733,
"148.20",23.114,24.752,
"148.35",23.136,24.777,
"148.50",23.16,24.802,
"148.65",23.184,24.827,
"148.80",23.211,24.852,
"148.95",23.231,24.877,
"149.10",23.257,24.902,
"149.25",23.281,24.927,
"149.40",23.304,24.952,
"149.55",23.327,24.977,
"149.70",23.354,25.002,
"149.85",23.377,25.027,
"150.00",23.398,25.05233,
"150.15",23.42,25.07733,
"150.30",23.444,25.10233,
"150.45",23.471,25.12733,
"150.60",23.496,25.152,
"150.75",23.52,25.177,
"150.90",23.544,25.202,
"151.05",23.563,25.227,
"151.20",23.583,25.252,
"151.35",23.606,25.277,
"151.50",23.63,25.302,
"151.65",23.656,25.327,
"151.80",23.681,25.352,
"151.95",23.706,25.377,
"152.10",23.724,25.402,
"152.25",23.751,25.427,
"152.40",23.771,25.452,
"152.55",23.798,25.477,
"152.70",23.827,25.502,
"152.85",23.85,25.527,
"153.00",23.871,25.552,
"153.15",23.893,25.577,
"153.30",23.916,25.602,
"153.45",23.942,25.627,
"153.60",23.967,25.652,
"153.75",23.99,25.677,
"153.90",24.01,25.702,
"154.05",24.04,25.727,
"154.20",24.06,25.752,
"154.35",24.09,25.777,
"154.50",24.11,25.802,
"154.65",24.14,25.827,
"154.80",24.16,25.852,
"154.95",24.19,25.877,
"155.10",24.21,25.902,
"155.25",24.23,25.927,
"155.40",24.26,25.952,
"155.55",24.29,25.977,
"155.70",24.31,26.002,
"155.85",24.34,26.027,
"156.00",24.36,26.052,
"156.15",24.38,26.077,
"156.30",24.41,26.102,
"156.45",24.43,26.127,
"156.60",24.46,26.152,
"156.75",24.49,26.177,
"156.90",24.51,26.202,
"157.05",24.54,26.22733,
"157.20",24.56,26.252,
"157.35",24.58,26.27733,
"157.50",24.61,26.30233,
"157.65",24.64,26.327,
"157.80",24.67,26.35233,
"157.95",24.69,26.37733,
"158.10",24.72,26.40233,
"158.25",24.74,26.427,
"158.40",24.76,26.452,
"158.55",24.78,26.477,
"158.70",24.81,26.502,
"158.85",24.83,26.527,
"159.00",24.86,26.552,
"159.15",24.88,26.577,
"159.30",24.91,26.602,
"159.45",24.93,26.627,
"159.60",24.96,26.652,
"159.75",24.98,26.677,
"159.90",25.01,26.702,
"160.05",25.03,26.727,
"160.20",25.05,26.752,
"160.35",25.08,26.777,
"160.50",25.1,26.802,
"160.65",25.13,26.827,
"160.80",25.15,26.852,
"160.95",25.17,26.877,
"161.10",25.2,26.902,
"161.25",25.22,26.927,
"161.40",25.24,26.952,
"161.55",25.27,26.977,
"161.70",25.3,27.002,
"161.85",25.32,27.027,
"162.00",25.34,27.052,
"162.15",25.36,27.077,
"162.30",25.39,27.102,
"162.45",25.41,27.12733,
"162.60",25.44,27.152,
"162.75",25.46,27.177,
"162.90",25.49,27.202,
"163.05",25.51,27.227,
"163.20",25.53,27.252,
"163.35",25.56,27.277,
"163.50",25.58,27.302,
"163.65",25.61,27.327,
"163.80",25.64,27.352,
"163.95",25.66,27.377,
"164.10",25.68,27.402,
"164.25",25.71,27.427,
"164.40",25.73,27.452,
"164.55",25.76,27.477,
"164.70",25.78,27.502,
"164.85",25.81,27.527,
"165.00",25.83,27.55233,
"165.15",25.86,27.577,
"165.30",25.88,27.60233,
"165.45",25.9,27.62733,
"165.60",25.93,27.652,
"165.75",25.96,27.677,
"165.90",25.98,27.702,
"166.05",26,27.727,
"166.20",26.02,27.752,
"166.35",26.05,27.777,
"166.50",26.07,27.802,
"166.65",26.1,27.827,
"166.80",26.13,27.852,
"166.95",26.15,27.877,
"167.10",26.17,27.902,
"167.25",26.2,27.927,
"167.40",26.22,27.952,
"167.55",26.24,27.977,
"167.70",26.27,28.002,
"167.85",26.3,28.027,
"168.00",26.32,28.052,
"168.15",26.34,28.077,
"168.30",26.36,28.102,
"168.45",26.39,28.127,
"168.60",26.41,28.152,
"168.75",26.44,28.177,
"168.90",26.46,28.202,
"169.05",26.48,28.227,
"169.20",26.5,28.252,
"169.35",26.53,28.277,
"169.50",26.55,28.302,
"169.65",26.58,28.327,
"169.80",26.6,28.352,
"169.95",26.62,28.377,
"170.10",26.64,28.402,
"170.25",26.67,28.427,
"170.40",26.69,28.452,
"170.55",26.72,28.477,
"170.70",26.75,28.502,
"170.85",26.77,28.527,
"171.00",26.79,28.552,
"171.15",26.81,28.577,
"171.30",26.84,28.602,
"171.45",26.86,28.627,
"171.60",26.89,28.652,
"171.75",26.92,28.677,
"171.90",26.94,28.702,
"172.05",26.96,28.727,
"172.20",26.99,28.752,
"172.35",27.01,28.777,
"172.50",27.03,28.802,
"172.65",27.06,28.827,
"172.80",27.09,28.852,
"172.95",27.11,28.877,
"173.10",27.13,28.902,
"173.25",27.16,28.927,
"173.40",27.18,28.952,
"173.55",27.2,28.977,
"173.70",27.23,29.002,
"173.85",27.25,29.027,
"174.00",27.27,29.052,
"174.15",27.3,29.077,
"174.30",27.32,29.10233,
"174.45",27.34,29.12733,
"174.60",27.37,29.152,
"174.75",27.4,29.17733,
"174.90",27.42,29.202,
"175.05",27.44,29.227,
"175.20",27.46,29.252,
"175.35",27.49,29.27733,
"175.50",27.51,29.30233,
"175.65",27.54,29.32733,
"175.80",27.56,29.35233,
"175.95",27.58,29.37733,
"176.10",27.6,29.40233,
"176.25",27.63,29.427,
"176.40",27.65,29.452,
"176.55",27.68,29.477,
"176.70",27.7,29.502,
"176.85",27.72,29.527,
"177.00",27.74,29.552,
"177.15",27.77,29.577,
"177.30",27.79,29.602,
"177.45",27.81,29.627,
"177.60",27.84,29.652,
"177.75",27.86,29.677,
"177.90",27.89,29.702,
"178.05",27.91,29.727,
"178.20",27.92,29.752,
"178.35",27.95,29.777,
"178.50",27.97,29.802,
"178.65",28,29.827,
"178.80",28.02,29.852,
"178.95",28.04,29.877,
"179.10",28.06,29.902,
"179.25",28.09,29.927,
"179.40",28.11,29.952,
"179.55",28.14,29.977,
"179.70",28.16,30.002,
"179.85",28.18,30.027,
"180.00",28.2,30.052,
"180.15",28.22,30.077,
"180.30",28.24,30.102,
"180.45",28.27,30.127,
"180.60",28.29,30.152,
"180.75",28.31,30.177,
"180.90",28.33,30.202,
"181.05",28.35,30.227,
"181.20",28.37,30.25233,
"181.35",28.39,30.27733,
"181.50",28.42,30.30233,
"181.65",28.44,30.32733,
"181.80",28.46,30.35233,
"181.95",28.48,30.377,
"182.10",28.5,30.402,
"182.25",28.52,30.427,
"182.40",28.54,30.452,
"182.55",28.56,30.47733,
"182.70",28.59,30.50233,
"182.85",28.61,30.52733,
"183.00",28.63,30.55233,
"183.15",28.65,30.57733,
"183.30",28.67,30.60233,
"183.45",28.68,30.62733,
"183.60",28.7,30.652,
"183.75",28.72,30.677,
"183.90",28.74,30.702,
"184.05",28.76,30.727,
"184.20",28.78,30.752,
"184.35",28.8,30.777,
"184.50",28.82,30.802,
"184.65",28.84,30.827,
"184.80",28.86,30.85233,
"184.95",28.87,30.87733,
"185.10",28.89,30.90233,
"185.25",28.91,30.927,
"185.40",28.92,30.95233,
"185.55",28.94,30.97733,
"185.70",28.956,31.00233,