File: exposed_flourocarbon_10cm_10mmpm_24nm_560esh_2.csv
"Test Name","Test Mode","Test Type","Control","Test Speed 1","Test Speed 2","Test Speed 3","Change Point 1","Change Point 2","Disp. Origin","Break and Limit Action","Sensitivity:","Level:"
"","Single","Tensile","Stroke",10,1,1,"Off","Off","Start","Stop",0,1

"Title","Sub title","Comment"
"","",""

"Shape:","Batch Size:","SubBatch Size:"
"Plate",1,1
"Name:","Thickness","Width","Gauge Length",
"Size Unit:","mm","mm","mm",
" 1 - 1","1.0000","1.0000","100.0000",

"Name",
"Parameter",
"Units",
" 1 - 1",

" 1- 1"
"Time","Force","Stroke",
"sec","N","mm",
"0.00",.003,0,
"0.15",0,2.766667E-02,
"0.30",-.002,5.533333E-02,
"0.45",.001,.083,
"0.60",.002,.1103333,
"0.75",-.001,.138,
"0.90",.001,.1656667,
"1.05",.009,.1933333,
"1.20",.024,.221,
"1.35",.049,.2483333,
"1.50",.074,.276,
"1.65",.101,.3036667,
"1.80",.126,.3313333,
"1.95",.154,.3586667,
"2.10",.178,.3856667,
"2.25",.21,.4123333,
"2.40",.234,.439,
"2.55",.259,.4653333,
"2.70",.287,.4913333,
"2.85",.311,.5176666,
"3.00",.337,.543,
"3.15",.361,.569,
"3.30",.386,.5946667,
"3.45",.41,.62,
"3.60",.434,.6456667,
"3.75",.458,.671,
"3.90",.481,.6963333,
"4.05",.506,.7213333,
"4.20",.533,.7466667,
"4.35",.554,.772,
"4.50",.578,.797,
"4.65",.602,.822,
"4.80",.627,.8473333,
"4.95",.65,.8723333,
"5.10",.673,.8973333,
"5.25",.695,.9226667,
"5.40",.72,.9476666,
"5.55",.742,.9726666,
"5.70",.762,.998,
"5.85",.786,1.023,
"6.00",.806,1.048,
"6.15",.83,1.073,
"6.30",.85,1.098,
"6.45",.873,1.123,
"6.60",.892,1.148,
"6.75",.912,1.173,
"6.90",.938,1.198,
"7.05",.958,1.223,
"7.20",.979,1.248,
"7.35",.999,1.273,
"7.50",1.02,1.298,
"7.65",1.04,1.323,
"7.80",1.062,1.348,
"7.95",1.079,1.373,
"8.10",1.101,1.398333,
"8.25",1.123,1.423,
"8.40",1.142,1.448333,
"8.55",1.161,1.473,
"8.70",1.178,1.498,
"8.85",1.199,1.523,
"9.00",1.22,1.548,
"9.15",1.238,1.573,
"9.30",1.257,1.598,
"9.45",1.276,1.623,
"9.60",1.294,1.648,
"9.75",1.311,1.673,
"9.90",1.33,1.698,
"10.05",1.348,1.723,
"10.20",1.365,1.748,
"10.35",1.382,1.773,
"10.50",1.4,1.798,
"10.65",1.417,1.823333,
"10.80",1.435,1.848333,
"10.95",1.452,1.873,
"11.10",1.469,1.898,
"11.25",1.486,1.923,
"11.40",1.502,1.948,
"11.55",1.515,1.973333,
"11.70",1.532,1.998333,
"11.85",1.55,2.023333,
"12.00",1.565,2.048,
"12.15",1.581,2.073,
"12.30",1.598,2.098,
"12.45",1.613,2.123,
"12.60",1.627,2.148333,
"12.75",1.645,2.173333,
"12.90",1.657,2.198333,
"13.05",1.673,2.223333,
"13.20",1.687,2.248333,
"13.35",1.7,2.273333,
"13.50",1.714,2.298333,
"13.65",1.731,2.323333,
"13.80",1.744,2.348,
"13.95",1.759,2.373,
"14.10",1.773,2.398333,
"14.25",1.787,2.423,
"14.40",1.799,2.448333,
"14.55",1.813,2.473333,
"14.70",1.828,2.498333,
"14.85",1.841,2.523,
"15.00",1.853,2.548,
"15.15",1.867,2.573333,
"15.30",1.883,2.598333,
"15.45",1.897,2.623333,
"15.60",1.908,2.648,
"15.75",1.921,2.673333,
"15.90",1.933,2.698,
"16.05",1.948,2.723,
"16.20",1.962,2.748333,
"16.35",1.975,2.773,
"16.50",1.987,2.798333,
"16.65",2,2.823333,
"16.80",2.01,2.848333,
"16.95",2.023,2.873333,
"17.10",2.039,2.898333,
"17.25",2.053,2.923333,
"17.40",2.063,2.948,
"17.55",2.079,2.973,
"17.70",2.09,2.998333,
"17.85",2.105,3.023333,
"18.00",2.117,3.048,
"18.15",2.128,3.073,
"18.30",2.14,3.098,
"18.45",2.154,3.123,
"18.60",2.164,3.148,
"18.75",2.178,3.173,
"18.90",2.192,3.198333,
"19.05",2.207,3.223333,
"19.20",2.218,3.248333,
"19.35",2.227,3.273333,
"19.50",2.238,3.298,
"19.65",2.252,3.323333,
"19.80",2.264,3.348333,
"19.95",2.278,3.373333,
"20.10",2.291,3.398333,
"20.25",2.303,3.423333,
"20.40",2.313,3.448333,
"20.55",2.325,3.473333,
"20.70",2.34,3.498333,
"20.85",2.355,3.523333,
"21.00",2.367,3.548333,
"21.15",2.378,3.573333,
"21.30",2.389,3.598333,
"21.45",2.401,3.623333,
"21.60",2.413,3.648333,
"21.75",2.424,3.673333,
"21.90",2.438,3.698,
"22.05",2.452,3.723333,
"22.20",2.463,3.748,
"22.35",2.477,3.773333,
"22.50",2.491,3.798333,
"22.65",2.506,3.823333,
"22.80",2.517,3.848333,
"22.95",2.53,3.873333,
"23.10",2.544,3.898333,
"23.25",2.558,3.923333,
"23.40",2.569,3.948333,
"23.55",2.58,3.973333,
"23.70",2.596,3.998333,
"23.85",2.611,4.023334,
"24.00",2.622,4.048,
"24.15",2.634,4.073334,
"24.30",2.649,4.098333,
"24.45",2.661,4.123333,
"24.60",2.672,4.148334,
"24.75",2.684,4.173334,
"24.90",2.699,4.198334,
"25.05",2.711,4.223333,
"25.20",2.724,4.248333,
"25.35",2.735,4.273334,
"25.50",2.749,4.298,
"25.65",2.765,4.323334,
"25.80",2.777,4.348333,
"25.95",2.788,4.373333,
"26.10",2.801,4.398334,
"26.25",2.816,4.423,
"26.40",2.829,4.448,
"26.55",2.841,4.473,
"26.70",2.857,4.498,
"26.85",2.872,4.523,
"27.00",2.884,4.548,
"27.15",2.897,4.573334,
"27.30",2.912,4.598,
"27.45",2.926,4.623,
"27.60",2.939,4.648,
"27.75",2.951,4.673334,
"27.90",2.965,4.698334,
"28.05",2.981,4.723,
"28.20",2.995,4.748333,
"28.35",3.008,4.773334,
"28.50",3.02,4.798,
"28.65",3.034,4.823,
"28.80",3.048,4.848,
"28.95",3.065,4.873,
"29.10",3.078,4.898334,
"29.25",3.091,4.923334,
"29.40",3.104,4.948334,
"29.55",3.118,4.973333,
"29.70",3.13,4.998333,
"29.85",3.146,5.023334,
"30.00",3.159,5.048,
"30.15",3.175,5.073,
"30.30",3.186,5.098,
"30.45",3.202,5.123333,
"30.60",3.215,5.148,
"30.75",3.228,5.173,
"30.90",3.243,5.198,
"31.05",3.258,5.223333,
"31.20",3.272,5.248333,
"31.35",3.289,5.273,
"31.50",3.302,5.298,
"31.65",3.317,5.323,
"31.80",3.329,5.348,
"31.95",3.345,5.373,
"32.10",3.36,5.398,
"32.25",3.375,5.423,
"32.40",3.389,5.448,
"32.55",3.404,5.473,
"32.70",3.418,5.498,
"32.85",3.432,5.523,
"33.00",3.448,5.548,
"33.15",3.464,5.573334,
"33.30",3.48,5.598,
"33.45",3.494,5.623,
"33.60",3.505,5.648,
"33.75",3.519,5.673,
"33.90",3.529,5.698,
"34.05",3.475,5.723333,
"34.20",3.452,5.748333,
"34.35",3.467,5.773334,
"34.50",3.486,5.798,
"34.65",3.503,5.823,
"34.80",3.522,5.848333,
"34.95",3.539,5.873333,
"35.10",3.556,5.898334,
"35.25",3.576,5.923334,
"35.40",3.594,5.948334,
"35.55",3.609,5.973333,
"35.70",3.624,5.998333,
"35.85",3.641,6.023334,
"36.00",3.657,6.048334,
"36.15",3.674,6.073334,
"36.30",3.691,6.098333,
"36.45",3.705,6.123333,
"36.60",3.719,6.148334,
"36.75",3.737,6.173334,
"36.90",3.753,6.198334,
"37.05",3.769,6.223333,
"37.20",3.785,6.248333,
"37.35",3.802,6.273334,
"37.50",3.817,6.298334,
"37.65",3.834,6.323334,
"37.80",3.849,6.348333,
"37.95",3.865,6.373333,
"38.10",3.885,6.398334,
"38.25",3.901,6.423334,
"38.40",3.916,6.448334,
"38.55",3.934,6.473333,
"38.70",3.949,6.498333,
"38.85",3.966,6.523334,
"39.00",3.983,6.548334,
"39.15",3.998,6.573334,
"39.30",4.016,6.598333,
"39.45",4.031,6.623333,
"39.60",4.047,6.648334,
"39.75",4.062,6.673334,
"39.90",4.079,6.698,
"40.05",4.098,6.723333,
"40.20",4.113,6.748333,
"40.35",4.131,6.773334,
"40.50",4.149,6.798334,
"40.65",4.165,6.823334,
"40.80",4.177,6.848333,
"40.95",4.194,6.873333,
"41.10",4.211,6.898334,
"41.25",4.228,6.923334,
"41.40",4.244,6.948334,
"41.55",4.262,6.973333,
"41.70",4.278,6.998333,
"41.85",4.296,7.023334,
"42.00",4.312,7.048,
"42.15",4.329,7.073334,
"42.30",4.344,7.098333,
"42.45",4.36,7.123333,
"42.60",4.377,7.148334,
"42.75",4.396,7.173334,
"42.90",4.412,7.198,
"43.05",4.43,7.223,
"43.20",4.444,7.248,
"43.35",4.459,7.273,
"43.50",4.476,7.298,
"43.65",4.493,7.323,
"43.80",4.511,7.348333,
"43.95",4.531,7.373,
"44.10",4.546,7.398334,
"44.25",4.564,7.423334,
"44.40",4.579,7.448334,
"44.55",4.594,7.473,
"44.70",4.611,7.498,
"44.85",4.63,7.523,
"45.00",4.648,7.548,
"45.15",4.667,7.573,
"45.30",4.684,7.598,
"45.45",4.702,7.623,
"45.60",4.72,7.648,
"45.75",4.736,7.673,
"45.90",4.756,7.698,
"46.05",4.772,7.723333,
"46.20",4.79,7.748333,
"46.35",4.807,7.773,
"46.50",4.823,7.798334,
"46.65",4.842,7.823334,
"46.80",4.859,7.848333,
"46.95",4.879,7.873333,
"47.10",4.897,7.898334,
"47.25",4.838,7.923334,
"47.40",4.662,7.948334,
"47.55",4.675,7.973333,
"47.70",4.705,7.998333,
"47.85",4.73,8.023,
"48.00",4.757,8.047999,
"48.15",4.782,8.073,
"48.30",4.806,8.098,
"48.45",4.831,8.123,
"48.60",4.853,8.148,
"48.75",4.88,8.172999,
"48.90",4.905,8.198,
"49.05",4.93,8.223,
"49.20",4.954,8.248,
"49.35",4.976,8.273,
"49.50",4.996,8.297999,
"49.65",5.018,8.323,
"49.80",5.038,8.348,
"49.95",5.059,8.373,
"50.10",5.083,8.398,
"50.25",5.102,8.422999,
"50.40",5.124,8.448,
"50.55",5.143,8.473,
"50.70",5.163,8.498,
"50.85",5.184,8.523,
"51.00",5.205,8.547999,
"51.15",5.227,8.573,
"51.30",5.242,8.598,
"51.45",5.26,8.623,
"51.60",5.281,8.648,
"51.75",5.299,8.672999,
"51.90",5.319,8.698,
"52.05",5.339,8.723,
"52.20",5.361,8.748,
"52.35",5.377,8.773,
"52.50",5.395,8.797999,
"52.65",5.415,8.823333,
"52.80",5.432,8.848333,
"52.95",5.453,8.873333,
"53.10",5.472,8.898334,
"53.25",5.489,8.923333,
"53.40",5.505,8.948,
"53.55",5.52,8.973,
"53.70",5.538,8.998,
"53.85",5.559,9.023334,
"54.00",5.579,9.048333,
"54.15",5.595,9.073333,
"54.30",5.613,9.098333,
"54.45",5.631,9.123333,
"54.60",5.647,9.148,
"54.75",5.666,9.172999,
"54.90",5.685,9.198,
"55.05",5.705,9.223,
"55.20",5.722,9.248,
"55.35",5.739,9.273334,
"55.50",5.762,9.298333,
"55.65",5.783,9.323333,
"55.80",5.801,9.348333,
"55.95",5.82,9.373333,
"56.10",5.84,9.398334,
"56.25",5.859,9.423333,
"56.40",5.878,9.448333,
"56.55",5.896,9.473333,
"56.70",5.916,9.498,
"56.85",5.94,9.523,
"57.00",5.96,9.547999,
"57.15",5.981,9.573333,
"57.30",5.998,9.598,
"57.45",6.015,9.623,
"57.60",6.037,9.648,
"57.75",6.056,9.672999,
"57.90",6.075,9.698,
"58.05",6.1,9.723,
"58.20",6.118,9.748,
"58.35",6.138,9.773,
"58.50",6.159,9.797999,
"58.65",6.178,9.823,
"58.80",6.197,9.848333,
"58.95",6.219,9.873,
"59.10",6.24,9.898,
"59.25",6.263,9.923333,
"59.40",6.281,9.948333,
"59.55",6.299,9.973,
"59.70",6.321,9.998,
"59.85",6.341,10.023,
"60.00",6.361,10.048,
"60.15",6.383,10.073,
"60.30",6.405,10.098,
"60.45",6.426,10.123,
"60.60",6.445,10.148,
"60.75",6.464,10.173,
"60.90",6.485,10.198,
"61.05",6.507,10.22333,
"61.20",6.527,10.24833,
"61.35",6.547,10.27333,
"61.50",6.566,10.29833,
"61.65",6.59,10.32333,
"61.80",6.612,10.34833,
"61.95",6.631,10.373,
"62.10",6.654,10.39833,
"62.25",6.674,10.423,
"62.40",6.694,10.44833,
"62.55",6.715,10.47333,
"62.70",6.74,10.49833,
"62.85",6.762,10.523,
"63.00",6.784,10.548,
"63.15",6.802,10.57333,
"63.30",6.825,10.598,
"63.45",6.846,10.623,
"63.60",6.868,10.648,
"63.75",6.89,10.673,
"63.90",6.913,10.698,
"64.05",6.937,10.72333,
"64.20",6.958,10.748,
"64.35",6.978,10.773,
"64.50",7.001,10.798,
"64.65",7.018,10.82333,
"64.80",7.04,10.84833,
"64.95",7.067,10.87333,
"65.10",7.091,10.89833,
"65.25",7.113,10.92333,
"65.40",7.133,10.94833,
"65.55",7.153,10.97333,
"65.70",7.174,10.99833,
"65.85",7.199,11.02333,
"66.00",7.221,11.048,
"66.15",7.242,11.07333,
"66.30",7.268,11.09833,
"66.45",7.29,11.123,
"66.60",7.311,11.14833,
"66.75",7.331,11.17333,
"66.90",7.353,11.198,
"67.05",7.376,11.223,
"67.20",7.398,11.248,
"67.35",7.419,11.273,
"67.50",7.438,11.298,
"67.65",7.46,11.323,
"67.80",7.481,11.348,
"67.95",7.504,11.373,
"68.10",7.523,11.398,
"68.25",7.543,11.423,
"68.40",7.565,11.448,
"68.55",7.583,11.473,
"68.70",7.606,11.498,
"68.85",7.626,11.523,
"69.00",7.649,11.548,
"69.15",7.664,11.573,
"69.30",7.673,11.598,
"69.45",7.684,11.623,
"69.60",7.688,11.648,
"69.75",7.693,11.673,
"69.90",7.707,11.698,
"70.05",7.723,11.723,
"70.20",7.738,11.748,
"70.35",7.754,11.773,
"70.50",7.773,11.798,
"70.65",7.794,11.82333,
"70.80",7.815,11.84833,
"70.95",7.837,11.873,
"71.10",7.86,11.89833,
"71.25",7.884,11.923,
"71.40",7.904,11.948,
"71.55",7.93,11.973,
"71.70",7.953,11.998,
"71.85",7.978,12.02333,
"72.00",8.003,12.04833,
"72.15",8.03,12.07333,
"72.30",8.053,12.098,
"72.45",8.077,12.12333,
"72.60",8.099,12.14833,
"72.75",8.124,12.17333,
"72.90",8.15,12.19833,
"73.05",8.174,12.223,
"73.20",8.196,12.24833,
"73.35",8.218,12.27333,
"73.50",8.237,12.298,
"73.65",8.26,12.32333,
"73.80",8.282,12.34833,
"73.95",8.307,12.37333,
"74.10",8.325,12.39833,
"74.25",8.347,12.42333,
"74.40",8.368,12.44833,
"74.55",8.39,12.473,
"74.70",8.41,12.498,
"74.85",8.432,12.523,
"75.00",8.458,12.548,
"75.15",8.484,12.573,
"75.30",8.506,12.598,
"75.45",8.531,12.62333,
"75.60",8.554,12.64833,
"75.75",8.578,12.673,
"75.90",8.605,12.698,
"76.05",8.629,12.723,
"76.20",8.657,12.748,
"76.35",8.681,12.773,
"76.50",8.705,12.79833,
"76.65",8.73,12.82333,
"76.80",8.756,12.84833,
"76.95",8.782,12.87333,
"77.10",8.806,12.89833,
"77.25",8.831,12.92333,
"77.40",8.852,12.94833,
"77.55",8.877,12.97333,
"77.70",8.899,12.99833,
"77.85",8.923,13.023,
"78.00",8.948,13.048,
"78.15",8.968,13.073,
"78.30",8.991,13.098,
"78.45",9.015,13.12333,
"78.60",9.037,13.14833,
"78.75",9.061,13.17333,
"78.90",9.089,13.198,
"79.05",9.119,13.223,
"79.20",9.142,13.248,
"79.35",9.169,13.27333,
"79.50",9.194,13.298,
"79.65",9.219,13.32333,
"79.80",9.245,13.34833,
"79.95",9.27,13.373,
"80.10",9.301,13.39833,
"80.25",9.327,13.42333,
"80.40",9.355,13.44833,
"80.55",9.379,13.47333,
"80.70",9.404,13.49833,
"80.85",9.429,13.523,
"81.00",9.455,13.548,
"81.15",9.48,13.573,
"81.30",9.508,13.598,
"81.45",9.536,13.62333,
"81.60",9.56,13.648,
"81.75",9.588,13.673,
"81.90",9.619,13.698,
"82.05",9.647,13.723,
"82.20",9.675,13.748,
"82.35",9.7,13.77333,
"82.50",9.725,13.79833,
"82.65",9.753,13.82333,
"82.80",9.78,13.84833,
"82.95",9.808,13.873,
"83.10",9.832,13.898,
"83.25",9.86,13.923,
"83.40",9.884,13.948,
"83.55",9.904,13.973,
"83.70",9.933,13.998,
"83.85",9.96,14.023,
"84.00",9.986,14.048,
"84.15",10.014,14.073,
"84.30",10.041,14.098,
"84.45",10.068,14.123,
"84.60",10.093,14.148,
"84.75",10.116,14.173,
"84.90",10.145,14.198,
"85.05",10.173,14.223,
"85.20",10.201,14.248,
"85.35",10.226,14.273,
"85.50",10.251,14.298,
"85.65",10.279,14.323,
"85.80",10.309,14.348,
"85.95",10.337,14.373,
"86.10",10.363,14.398,
"86.25",10.394,14.423,
"86.40",10.423,14.448,
"86.55",10.45,14.473,
"86.70",10.479,14.49833,
"86.85",10.511,14.523,
"87.00",10.542,14.548,
"87.15",10.57,14.573,
"87.30",10.598,14.598,
"87.45",10.628,14.623,
"87.60",10.659,14.64833,
"87.75",10.69,14.67333,
"87.90",10.722,14.69833,
"88.05",10.755,14.72333,
"88.20",10.783,14.748,
"88.35",10.814,14.773,
"88.50",10.84,14.798,
"88.65",10.867,14.82333,
"88.80",10.9,14.84833,
"88.95",10.932,14.873,
"89.10",10.965,14.898,
"89.25",10.994,14.92333,
"89.40",11.022,14.94833,
"89.55",11.05,14.97333,
"89.70",11.082,14.99833,
"89.85",11.111,15.023,
"90.00",11.138,15.048,
"90.15",11.169,15.073,
"90.30",11.199,15.098,
"90.45",11.229,15.123,
"90.60",11.257,15.148,
"90.75",11.286,15.173,
"90.90",11.317,15.198,
"91.05",11.347,15.223,
"91.20",11.378,15.24833,
"91.35",11.406,15.273,
"91.50",11.436,15.298,
"91.65",11.467,15.323,
"91.80",11.498,15.348,
"91.95",11.53,15.373,
"92.10",11.561,15.398,
"92.25",11.592,15.423,
"92.40",11.621,15.448,
"92.55",11.651,15.473,
"92.70",11.682,15.49833,
"92.85",11.715,15.52333,
"93.00",11.747,15.548,
"93.15",11.777,15.57333,
"93.30",11.806,15.598,
"93.45",11.835,15.623,
"93.60",11.864,15.648,
"93.75",11.895,15.673,
"93.90",11.928,15.698,
"94.05",11.961,15.723,
"94.20",11.995,15.748,
"94.35",12.025,15.773,
"94.50",12.059,15.798,
"94.65",12.089,15.82333,
"94.80",12.121,15.84833,
"94.95",12.158,15.873,
"95.10",12.192,15.898,
"95.25",12.226,15.923,
"95.40",12.258,15.94833,
"95.55",12.292,15.973,
"95.70",12.324,15.99833,
"95.85",12.358,16.023,
"96.00",12.39,16.048,
"96.15",12.421,16.07333,
"96.30",12.456,16.098,
"96.45",12.489,16.12333,
"96.60",12.522,16.14833,
"96.75",12.555,16.17333,
"96.90",12.591,16.198,
"97.05",12.623,16.223,
"97.20",12.655,16.248,
"97.35",12.687,16.273,
"97.50",12.719,16.298,
"97.65",12.752,16.323,
"97.80",12.788,16.348,
"97.95",12.82,16.373,
"98.10",12.857,16.398,
"98.25",12.889,16.423,
"98.40",12.92,16.448,
"98.55",12.952,16.473,
"98.70",12.985,16.498,
"98.85",13.021,16.523,
"99.00",13.054,16.548,
"99.15",13.089,16.573,
"99.30",13.121,16.598,
"99.45",13.153,16.623,
"99.60",13.185,16.648,
"99.75",13.219,16.673,
"99.90",13.252,16.698,
"100.05",13.287,16.723,
"100.20",13.324,16.748,
"100.35",13.359,16.773,
"100.50",13.388,16.79833,
"100.65",13.423,16.82333,
"100.80",13.456,16.84833,
"100.95",13.488,16.873,
"101.10",13.522,16.898,
"101.25",13.557,16.923,
"101.40",13.589,16.948,
"101.55",13.619,16.973,
"101.70",13.649,16.998,
"101.85",13.684,17.023,
"102.00",13.714,17.048,
"102.15",13.738,17.073,
"102.30",13.76,17.098,
"102.45",13.778,17.123,
"102.60",13.8,17.148,
"102.75",13.823,17.173,
"102.90",13.842,17.198,
"103.05",13.857,17.223,
"103.20",13.853,17.248,
"103.35",13.841,17.273,
"103.50",13.833,17.298,
"103.65",13.835,17.323,
"103.80",13.832,17.348,
"103.95",13.822,17.373,
"104.10",13.822,17.398,
"104.25",13.833,17.423,
"104.40",13.847,17.448,
"104.55",13.869,17.473,
"104.70",13.896,17.49833,
"104.85",13.928,17.523,
"105.00",13.965,17.548,
"105.15",14.001,17.57333,
"105.30",14.04,17.598,
"105.45",14.078,17.623,
"105.60",14.113,17.648,
"105.75",14.151,17.673,
"105.90",14.189,17.698,
"106.05",14.229,17.723,
"106.20",14.269,17.748,
"106.35",14.308,17.773,
"106.50",14.345,17.798,
"106.65",14.382,17.823,
"106.80",14.421,17.848,
"106.95",14.463,17.873,
"107.10",14.504,17.898,
"107.25",14.541,17.923,
"107.40",14.576,17.948,
"107.55",14.614,17.973,
"107.70",14.655,17.998,
"107.85",14.695,18.023,
"108.00",14.734,18.048,
"108.15",14.773,18.073,
"108.30",14.808,18.098,
"108.45",14.841,18.123,
"108.60",14.876,18.148,
"108.75",14.911,18.17333,
"108.90",14.952,18.198,
"109.05",14.99,18.223,
"109.20",15.022,18.248,
"109.35",15.056,18.273,
"109.50",15.091,18.298,
"109.65",15.128,18.323,
"109.80",15.163,18.348,
"109.95",15.199,18.373,
"110.10",15.238,18.398,
"110.25",15.275,18.423,
"110.40",15.31,18.448,
"110.55",15.344,18.473,
"110.70",15.381,18.498,
"110.85",15.421,18.523,
"111.00",15.459,18.548,
"111.15",15.496,18.573,
"111.30",15.534,18.598,
"111.45",15.57,18.62333,
"111.60",15.606,18.64833,
"111.75",15.646,18.673,
"111.90",15.684,18.698,
"112.05",15.722,18.723,
"112.20",15.758,18.748,
"112.35",15.792,18.77333,
"112.50",15.831,18.798,
"112.65",15.868,18.823,
"112.80",15.907,18.848,
"112.95",15.948,18.873,
"113.10",15.987,18.898,
"113.25",16.023,18.923,
"113.40",16.056,18.948,
"113.55",16.092,18.973,
"113.70",16.131,18.998,
"113.85",16.17,19.023,
"114.00",16.21,19.048,
"114.15",16.248,19.073,
"114.30",16.284,19.098,
"114.45",16.321,19.123,
"114.60",16.356,19.148,
"114.75",16.391,19.173,
"114.90",16.428,19.198,
"115.05",16.469,19.223,
"115.20",16.507,19.248,
"115.35",16.54,19.273,
"115.50",16.577,19.298,
"115.65",16.615,19.32333,
"115.80",16.651,19.34833,
"115.95",16.688,19.373,
"116.10",16.726,19.39833,
"116.25",16.763,19.423,
"116.40",16.798,19.44833,
"116.55",16.835,19.473,
"116.70",16.873,19.498,
"116.85",16.91,19.523,
"117.00",16.949,19.548,
"117.15",16.981,19.573,
"117.30",17.017,19.598,
"117.45",17.051,19.62333,
"117.60",17.089,19.64833,
"117.75",17.126,19.673,
"117.90",17.164,19.69833,
"118.05",17.201,19.723,
"118.20",17.235,19.748,
"118.35",17.27,19.773,
"118.50",17.301,19.798,
"118.65",17.333,19.823,
"118.80",17.371,19.848,
"118.95",17.409,19.873,
"119.10",17.444,19.898,
"119.25",17.479,19.923,
"119.40",17.51,19.948,
"119.55",17.539,19.973,
"119.70",17.57,19.998,
"119.85",17.604,20.023,
"120.00",17.638,20.048,
"120.15",17.673,20.073,
"120.30",17.705,20.098,
"120.45",17.733,20.123,
"120.60",17.762,20.148,
"120.75",17.795,20.173,
"120.90",17.83,20.198,
"121.05",17.862,20.223,
"121.20",17.895,20.248,
"121.35",17.925,20.273,
"121.50",17.955,20.298,
"121.65",17.988,20.323,
"121.80",18.024,20.348,
"121.95",18.06,20.373,
"122.10",18.096,20.398,
"122.25",18.128,20.423,
"122.40",18.16,20.448,
"122.55",18.193,20.473,
"122.70",18.229,20.498,
"122.85",18.266,20.523,
"123.00",18.306,20.548,
"123.15",18.34,20.57333,
"123.30",18.374,20.59833,
"123.45",18.41,20.62333,
"123.60",18.439,20.64833,
"123.75",18.478,20.673,
"123.90",18.513,20.698,
"124.05",18.549,20.723,
"124.20",18.583,20.748,
"124.35",18.617,20.773,
"124.50",18.653,20.798,
"124.65",18.687,20.823,
"124.80",18.724,20.84833,
"124.95",18.761,20.873,
"125.10",18.798,20.898,
"125.25",18.833,20.92333,
"125.40",18.87,20.94833,
"125.55",18.902,20.973,
"125.70",18.937,20.99833,
"125.85",18.971,21.023,
"126.00",19.006,21.048,
"126.15",19.041,21.073,
"126.30",19.075,21.098,
"126.45",19.108,21.123,
"126.60",19.143,21.148,
"126.75",19.174,21.173,
"126.90",19.21,21.198,
"127.05",19.245,21.223,
"127.20",19.276,21.248,
"127.35",19.308,21.273,
"127.50",19.343,21.298,
"127.65",19.375,21.32333,
"127.80",19.408,21.348,
"127.95",19.441,21.373,
"128.10",19.478,21.398,
"128.25",19.511,21.423,
"128.40",19.543,21.44833,
"128.55",19.573,21.473,
"128.70",19.605,21.498,
"128.85",19.639,21.523,
"129.00",19.675,21.548,
"129.15",19.708,21.573,
"129.30",19.742,21.598,
"129.45",19.77,21.623,
"129.60",19.802,21.648,
"129.75",19.833,21.673,
"129.90",19.867,21.698,
"130.05",19.901,21.723,
"130.20",19.932,21.748,
"130.35",19.96,21.773,
"130.50",19.992,21.798,
"130.65",20.023,21.823,
"130.80",20.051,21.848,
"130.95",20.08,21.873,
"131.10",20.112,21.898,
"131.25",20.142,21.923,
"131.40",20.171,21.948,
"131.55",20.2,21.973,
"131.70",20.228,21.998,
"131.85",20.261,22.023,
"132.00",20.293,22.048,
"132.15",20.323,22.073,
"132.30",20.351,22.098,
"132.45",20.38,22.123,
"132.60",20.409,22.148,
"132.75",20.441,22.173,
"132.90",20.472,22.198,
"133.05",20.501,22.22333,
"133.20",20.531,22.24833,
"133.35",20.556,22.27333,
"133.50",20.583,22.29833,
"133.65",20.611,22.32333,
"133.80",20.643,22.34833,
"133.95",20.678,22.373,
"134.10",20.705,22.39833,
"134.25",20.73,22.423,
"134.40",20.755,22.44833,
"134.55",20.783,22.47333,
"134.70",20.811,22.498,
"134.85",20.836,22.523,
"135.00",20.867,22.548,
"135.15",20.898,22.57333,
"135.30",20.928,22.598,
"135.45",20.953,22.623,
"135.60",20.979,22.648,
"135.75",21.007,22.673,
"135.90",21.038,22.698,
"136.05",21.068,22.723,
"136.20",21.096,22.748,
"136.35",21.122,22.773,
"136.50",21.15,22.798,
"136.65",21.18,22.82333,
"136.80",21.21,22.84833,
"136.95",21.242,22.873,
"137.10",21.27,22.898,
"137.25",21.297,22.923,
"137.40",21.323,22.948,
"137.55",21.351,22.973,
"137.70",21.381,22.998,
"137.85",21.41,23.023,
"138.00",21.439,23.048,
"138.15",21.471,23.073,
"138.30",21.5,23.098,
"138.45",21.526,23.123,
"138.60",21.551,23.148,
"138.75",21.579,23.173,
"138.90",21.609,23.198,
"139.05",21.638,23.223,
"139.20",21.666,23.248,
"139.35",21.69,23.273,
"139.50",21.712,23.298,
"139.65",21.738,23.323,
"139.80",21.766,23.348,
"139.95",21.793,23.373,
"140.10",21.82,23.398,
"140.25",21.851,23.423,
"140.40",21.874,23.448,
"140.55",21.899,23.473,
"140.70",21.926,23.498,
"140.85",21.952,23.523,
"141.00",21.981,23.548,
"141.15",22.007,23.573,
"141.30",22.03,23.598,
"141.45",22.051,23.623,
"141.60",22.073,23.648,
"141.75",22.099,23.673,
"141.90",22.123,23.698,
"142.05",22.148,23.723,
"142.20",22.172,23.748,
"142.35",22.195,23.773,
"142.50",22.214,23.798,
"142.65",22.235,23.82333,
"142.80",22.259,23.848,
"142.95",22.283,23.873,
"143.10",22.307,23.898,
"143.25",22.329,23.923,
"143.40",22.35,23.94833,
"143.55",22.371,23.973,
"143.70",22.393,23.99833,
"143.85",22.417,24.02333,
"144.00",22.442,24.04833,
"144.15",22.464,24.073,
"144.30",22.489,24.098,
"144.45",22.507,24.123,
"144.60",22.526,24.148,
"144.75",22.549,24.17333,
"144.90",22.573,24.198,
"145.05",22.596,24.223,
"145.20",22.618,24.248,
"145.35",22.64,24.273,
"145.50",22.658,24.298,
"145.65",22.679,24.323,
"145.80",22.699,24.348,
"145.95",22.724,24.373,
"146.10",22.745,24.39833,
"146.25",22.765,24.423,
"146.40",22.786,24.448,
"146.55",22.807,24.473,
"146.70",22.831,24.498,
"146.85",22.853,24.523,
"147.00",22.876,24.548,
"147.15",22.899,24.57333,
"147.30",22.921,24.59833,
"147.45",22.939,24.62333,
"147.60",22.958,24.64833,
"147.75",22.981,24.67333,
"147.90",23.005,24.698,
"148.05",23.029,24.723,
"148.20",23.047,24.748,
"148.35",23.066,24.773,
"148.50",23.084,24.798,
"148.65",23.104,24.82333,
"148.80",23.127,24.848,
"148.95",23.149,24.873,
"149.10",23.173,24.898,
"149.25",23.196,24.923,
"149.40",23.215,24.948,
"149.55",23.234,24.973,
"149.70",23.256,24.998,
"149.85",23.278,25.023,
"150.00",23.302,25.048,
"150.15",23.325,25.073,
"150.30",23.347,25.098,
"150.45",23.366,25.12333,
"150.60",23.387,25.148,
"150.75",23.406,25.173,
"150.90",23.427,25.198,
"151.05",23.45,25.223,
"151.20",23.475,25.248,
"151.35",23.496,25.273,
"151.50",23.513,25.298,
"151.65",23.536,25.323,
"151.80",23.558,25.348,
"151.95",23.583,25.373,
"152.10",23.603,25.398,
"152.25",23.626,25.423,
"152.40",23.644,25.44833,
"152.55",23.662,25.473,
"152.70",23.683,25.498,
"152.85",23.708,25.523,
"153.00",23.729,25.548,
"153.15",23.75,25.573,
"153.30",23.771,25.59833,
"153.45",23.79,25.62333,
"153.60",23.81,25.64833,
"153.75",23.832,25.673,
"153.90",23.857,25.698,
"154.05",23.882,25.723,
"154.20",23.905,25.748,
"154.35",23.926,25.773,
"154.50",23.947,25.798,
"154.65",23.968,25.823,
"154.80",23.98,25.848,
"154.95",24.01,25.873,
"155.10",24.03,25.898,
"155.25",24.06,25.923,
"155.40",24.08,25.948,
"155.55",24.1,25.973,
"155.70",24.12,25.998,
"155.85",24.15,26.023,
"156.00",24.17,26.048,
"156.15",24.19,26.073,
"156.30",24.22,26.098,
"156.45",24.24,26.123,
"156.60",24.26,26.148,
"156.75",24.29,26.173,
"156.90",24.31,26.198,
"157.05",24.34,26.223,
"157.20",24.36,26.248,
"157.35",24.38,26.27333,
"157.50",24.4,26.29833,
"157.65",24.42,26.32333,
"157.80",24.45,26.348,
"157.95",24.48,26.373,
"158.10",24.5,26.39833,
"158.25",24.52,26.423,
"158.40",24.54,26.448,
"158.55",24.56,26.47333,
"158.70",24.59,26.49833,
"158.85",24.61,26.52333,
"159.00",24.64,26.548,
"159.15",24.66,26.573,
"159.30",24.69,26.598,
"159.45",24.71,26.623,
"159.60",24.73,26.648,
"159.75",24.75,26.673,
"159.90",24.78,26.698,
"160.05",24.81,26.723,
"160.20",24.83,26.748,
"160.35",24.85,26.77333,
"160.50",24.87,26.798,
"160.65",24.89,26.823,
"160.80",24.91,26.848,
"160.95",24.94,26.873,
"161.10",24.96,26.898,
"161.25",24.98,26.923,
"161.40",25,26.948,
"161.55",25.03,26.973,
"161.70",25.05,26.998,
"161.85",25.07,27.023,
"162.00",25.1,27.048,
"162.15",25.12,27.073,
"162.30",25.14,27.098,
"162.45",25.16,27.12333,
"162.60",25.18,27.148,
"162.75",25.2,27.173,
"162.90",25.23,27.198,
"163.05",25.25,27.223,
"163.20",25.27,27.248,
"163.35",25.29,27.273,
"163.50",25.31,27.298,
"163.65",25.33,27.323,
"163.80",25.35,27.348,
"163.95",25.38,27.373,
"164.10",25.41,27.398,
"164.25",25.43,27.423,
"164.40",25.45,27.448,
"164.55",25.47,27.473,
"164.70",25.49,27.498,
"164.85",25.52,27.523,
"165.00",25.54,27.548,
"165.15",25.56,27.57333,
"165.30",25.59,27.598,
"165.45",25.61,27.623,
"165.60",25.63,27.648,
"165.75",25.65,27.673,
"165.90",25.67,27.698,
"166.05",25.7,27.723,
"166.20",25.72,27.748,
"166.35",25.74,27.773,
"166.50",25.77,27.798,
"166.65",25.79,27.823,
"166.80",25.82,27.848,
"166.95",25.84,27.873,
"167.10",25.86,27.898,
"167.25",25.88,27.923,
"167.40",25.91,27.948,
"167.55",25.93,27.973,
"167.70",25.95,27.998,
"167.85",25.98,28.023,
"168.00",26.01,28.048,
"168.15",26.03,28.073,
"168.30",26.05,28.098,
"168.45",26.07,28.123,
"168.60",26.09,28.148,
"168.75",26.12,28.173,
"168.90",26.14,28.198,
"169.05",26.17,28.223,
"169.20",26.19,28.248,
"169.35",26.21,28.273,
"169.50",26.23,28.298,
"169.65",26.25,28.323,
"169.80",26.27,28.348,
"169.95",26.3,28.373,
"170.10",26.32,28.398,
"170.25",26.35,28.423,
"170.40",26.36,28.448,
"170.55",26.38,28.473,
"170.70",26.4,28.498,
"170.85",26.42,28.523,
"171.00",26.44,28.548,
"171.15",26.46,28.573,
"171.30",26.472,28.598,