File: exposed_flourocarbon_10cm_10mmpm_12nm_250esh_4.csv
"Test Name","Test Mode","Test Type","Control","Test Speed 1","Test Speed 2","Test Speed 3","Change Point 1","Change Point 2","Disp. Origin","Break and Limit Action","Sensitivity:","Level:"
"","Single","Tensile","Stroke",10,1,1,"Off","Off","Start","Stop",0,1

"Title","Sub title","Comment"
"","",""

"Shape:","Batch Size:","SubBatch Size:"
"Plate",1,1
"Name:","Thickness","Width","Gauge Length",
"Size Unit:","mm","mm","mm",
" 1 - 1","1.0000","1.0000","100.0000",

"Name",
"Parameter",
"Units",
" 1 - 1",

" 1- 1"
"Time","Force","Stroke",
"sec","N","mm",
"0.00",.001,0,
"0.15",.001,.027,
"0.30",.012,.055,
"0.45",.037,.083,
"0.60",.062,.111,
"0.75",.086,.1386667,
"0.90",.116,.1666667,
"1.05",.141,.1946667,
"1.20",.165,.2226667,
"1.35",.19,.2503333,
"1.50",.217,.2783333,
"1.65",.24,.3063333,
"1.80",.267,.3343333,
"1.95",.291,.362,
"2.10",.317,.389,
"2.25",.341,.416,
"2.40",.364,.4426667,
"2.55",.388,.469,
"2.70",.413,.4953333,
"2.85",.437,.521,
"3.00",.46,.547,
"3.15",.481,.5726666,
"3.30",.502,.5983334,
"3.45",.523,.6236666,
"3.60",.547,.6493334,
"3.75",.57,.6746666,
"3.90",.589,.7,
"4.05",.612,.7253333,
"4.20",.633,.7506667,
"4.35",.654,.776,
"4.50",.674,.801,
"4.65",.695,.826,
"4.80",.714,.8513333,
"4.95",.733,.8763334,
"5.10",.756,.9016666,
"5.25",.776,.9266667,
"5.40",.793,.9516667,
"5.55",.813,.9766667,
"5.70",.834,1.001667,
"5.85",.853,1.027,
"6.00",.872,1.052,
"6.15",.892,1.077,
"6.30",.911,1.102,
"6.45",.929,1.127,
"6.60",.949,1.152,
"6.75",.968,1.177,
"6.90",.986,1.202,
"7.05",1.002,1.227,
"7.20",1.02,1.252,
"7.35",1.037,1.277,
"7.50",1.053,1.302333,
"7.65",1.072,1.327,
"7.80",1.091,1.352,
"7.95",1.109,1.377333,
"8.10",1.127,1.402333,
"8.25",1.141,1.427333,
"8.40",1.157,1.452333,
"8.55",1.173,1.477333,
"8.70",1.193,1.502333,
"8.85",1.207,1.527333,
"9.00",1.222,1.552,
"9.15",1.239,1.577,
"9.30",1.253,1.602,
"9.45",1.27,1.627333,
"9.60",1.286,1.652333,
"9.75",1.301,1.677333,
"9.90",1.318,1.702,
"10.05",1.331,1.727,
"10.20",1.345,1.752,
"10.35",1.362,1.777,
"10.50",1.376,1.802,
"10.65",1.391,1.827,
"10.80",1.403,1.852,
"10.95",1.418,1.877,
"11.10",1.432,1.902,
"11.25",1.445,1.927,
"11.40",1.461,1.952333,
"11.55",1.478,1.977333,
"11.70",1.491,2.002,
"11.85",1.504,2.027333,
"12.00",1.52,2.052,
"12.15",1.533,2.077333,
"12.30",1.547,2.102,
"12.45",1.561,2.127,
"12.60",1.574,2.152,
"12.75",1.59,2.177333,
"12.90",1.603,2.202333,
"13.05",1.616,2.227333,
"13.20",1.63,2.252333,
"13.35",1.643,2.277333,
"13.50",1.658,2.302333,
"13.65",1.67,2.327,
"13.80",1.684,2.352,
"13.95",1.697,2.377,
"14.10",1.712,2.402,
"14.25",1.726,2.427,
"14.40",1.737,2.452333,
"14.55",1.75,2.477,
"14.70",1.765,2.502,
"14.85",1.777,2.527,
"15.00",1.792,2.552,
"15.15",1.805,2.577,
"15.30",1.818,2.602,
"15.45",1.828,2.627,
"15.60",1.843,2.652,
"15.75",1.857,2.677,
"15.90",1.87,2.702,
"16.05",1.883,2.727333,
"16.20",1.897,2.752,
"16.35",1.909,2.777333,
"16.50",1.923,2.802333,
"16.65",1.938,2.827333,
"16.80",1.952,2.852333,
"16.95",1.963,2.877,
"17.10",1.975,2.902,
"17.25",1.988,2.927,
"17.40",1.999,2.952,
"17.55",2.012,2.977,
"17.70",2.027,3.002,
"17.85",2.039,3.027,
"18.00",2.055,3.052,
"18.15",2.068,3.077333,
"18.30",2.081,3.102333,
"18.45",2.095,3.127,
"18.60",2.109,3.152,
"18.75",2.121,3.177,
"18.90",2.132,3.202,
"19.05",2.146,3.227,
"19.20",2.162,3.252333,
"19.35",2.175,3.277333,
"19.50",2.188,3.302333,
"19.65",2.201,3.327333,
"19.80",2.214,3.352333,
"19.95",2.228,3.377333,
"20.10",2.242,3.402333,
"20.25",2.252,3.427333,
"20.40",2.268,3.452333,
"20.55",2.279,3.477333,
"20.70",2.292,3.502333,
"20.85",2.308,3.527333,
"21.00",2.318,3.552,
"21.15",2.332,3.577333,
"21.30",2.348,3.602333,
"21.45",2.36,3.627333,
"21.60",2.372,3.652333,
"21.75",2.386,3.677333,
"21.90",2.401,3.702333,
"22.05",2.414,3.727333,
"22.20",2.425,3.752333,
"22.35",2.44,3.777333,
"22.50",2.453,3.802333,
"22.65",2.465,3.827333,
"22.80",2.48,3.852333,
"22.95",2.495,3.877333,
"23.10",2.506,3.902,
"23.25",2.521,3.927,
"23.40",2.534,3.952333,
"23.55",2.547,3.977333,
"23.70",2.562,4.002333,
"23.85",2.575,4.027333,
"24.00",2.591,4.052333,
"24.15",2.602,4.077333,
"24.30",2.616,4.102334,
"24.45",2.629,4.127333,
"24.60",2.644,4.152333,
"24.75",2.657,4.177333,
"24.90",2.672,4.202,
"25.05",2.684,4.227,
"25.20",2.696,4.252,
"25.35",2.712,4.277333,
"25.50",2.728,4.302333,
"25.65",2.74,4.327333,
"25.80",2.752,4.352334,
"25.95",2.767,4.377333,
"26.10",2.782,4.402333,
"26.25",2.793,4.427333,
"26.40",2.807,4.452333,
"26.55",2.82,4.477334,
"26.70",2.833,4.502333,
"26.85",2.848,4.527,
"27.00",2.862,4.552,
"27.15",2.875,4.577,
"27.30",2.89,4.602,
"27.45",2.903,4.627,
"27.60",2.917,4.652,
"27.75",2.932,4.677,
"27.90",2.945,4.702,
"28.05",2.959,4.727,
"28.20",2.972,4.752333,
"28.35",2.984,4.777333,
"28.50",3.002,4.802333,
"28.65",3.017,4.827,
"28.80",3.028,4.852,
"28.95",3.041,4.877,
"29.10",3.056,4.902,
"29.25",3.072,4.927,
"29.40",3.085,4.952333,
"29.55",3.099,4.977334,
"29.70",3.115,5.002333,
"29.85",3.132,5.027,
"30.00",3.145,5.052333,
"30.15",3.155,5.077333,
"30.30",3.171,5.102334,
"30.45",3.187,5.127,
"30.60",3.2,5.152,
"30.75",3.215,5.177,
"30.90",3.229,5.202,
"31.05",3.244,5.227,
"31.20",3.258,5.252,
"31.35",3.272,5.277333,
"31.50",3.288,5.302,
"31.65",3.302,5.327,
"31.80",3.318,5.352334,
"31.95",3.332,5.377333,
"32.10",3.348,5.402333,
"32.25",3.361,5.427333,
"32.40",3.376,5.452333,
"32.55",3.389,5.477334,
"32.70",3.404,5.502,
"32.85",3.421,5.527,
"33.00",3.436,5.552,
"33.15",3.451,5.577333,
"33.30",3.466,5.602334,
"33.45",3.48,5.627,
"33.60",3.496,5.652,
"33.75",3.512,5.677,
"33.90",3.526,5.702,
"34.05",3.543,5.727334,
"34.20",3.556,5.752333,
"34.35",3.572,5.777333,
"34.50",3.588,5.802333,
"34.65",3.603,5.827333,
"34.80",3.618,5.852334,
"34.95",3.635,5.877,
"35.10",3.65,5.902,
"35.25",3.664,5.927333,
"35.40",3.679,5.952333,
"35.55",3.694,5.977334,
"35.70",3.709,6.002333,
"35.85",3.726,6.027333,
"36.00",3.74,6.052333,
"36.15",3.756,6.077333,
"36.30",3.771,6.102334,
"36.45",3.785,6.127333,
"36.60",3.802,6.152333,
"36.75",3.819,6.177333,
"36.90",3.835,6.202333,
"37.05",3.85,6.227334,
"37.20",3.866,6.252333,
"37.35",3.883,6.277333,
"37.50",3.9,6.302333,
"37.65",3.916,6.327333,
"37.80",3.932,6.352,
"37.95",3.947,6.377333,
"38.10",3.966,6.402,
"38.25",3.978,6.427333,
"38.40",3.993,6.452333,
"38.55",4.009,6.477,
"38.70",4.027,6.502,
"38.85",4.043,6.527,
"39.00",4.059,6.552,
"39.15",4.073,6.577333,
"39.30",4.091,6.602,
"39.45",4.106,6.627333,
"39.60",4.124,6.652333,
"39.75",4.14,6.677333,
"39.90",4.158,6.702333,
"40.05",4.174,6.727334,
"40.20",4.189,6.752333,
"40.35",4.205,6.777333,
"40.50",4.222,6.802333,
"40.65",4.239,6.827,
"40.80",4.255,6.852,
"40.95",4.271,6.877,
"41.10",4.286,6.902,
"41.25",4.303,6.927,
"41.40",4.316,6.952,
"41.55",4.336,6.977,
"41.70",4.352,7.002,
"41.85",4.37,7.027333,
"42.00",4.385,7.052333,
"42.15",4.402,7.077333,
"42.30",4.418,7.102,
"42.45",4.432,7.127,
"42.60",4.449,7.152,
"42.75",4.467,7.177,
"42.90",4.486,7.202,
"43.05",4.502,7.227,
"43.20",4.516,7.252333,
"43.35",4.534,7.277333,
"43.50",4.549,7.302333,
"43.65",4.566,7.327,
"43.80",4.583,7.352334,
"43.95",4.601,7.377333,
"44.10",4.616,7.402333,
"44.25",4.634,7.427333,
"44.40",4.649,7.452333,
"44.55",4.665,7.477334,
"44.70",4.682,7.502333,
"44.85",4.702,7.527333,
"45.00",4.718,7.552,
"45.15",4.735,7.577,
"45.30",4.752,7.602,
"45.45",4.769,7.627,
"45.60",4.788,7.652,
"45.75",4.803,7.677,
"45.90",4.82,7.702333,
"46.05",4.838,7.727,
"46.20",4.854,7.752,
"46.35",4.869,7.777,
"46.50",4.887,7.802,
"46.65",4.904,7.827,
"46.80",4.924,7.852,
"46.95",4.941,7.877,
"47.10",4.956,7.902,
"47.25",4.972,7.927,
"47.40",4.99,7.952,
"47.55",5.008,7.977,
"47.70",5.029,8.002,
"47.85",5.046,8.027,
"48.00",5.064,8.052,
"48.15",5.082,8.077,
"48.30",5.097,8.102333,
"48.45",5.115,8.127334,
"48.60",5.135,8.152,
"48.75",5.152,8.177,
"48.90",5.171,8.202,
"49.05",5.19,8.227,
"49.20",5.208,8.252,
"49.35",5.226,8.277,
"49.50",5.244,8.302,
"49.65",5.262,8.327,
"49.80",5.282,8.352,
"49.95",5.303,8.377,
"50.10",5.322,8.402,
"50.25",5.341,8.427333,
"50.40",5.36,8.452333,
"50.55",5.377,8.477,
"50.70",5.401,8.502,
"50.85",5.417,8.527333,
"51.00",5.436,8.552,
"51.15",5.456,8.577,
"51.30",5.473,8.602333,
"51.45",5.492,8.627,
"51.60",5.513,8.652,
"51.75",5.532,8.677,
"51.90",5.551,8.702,
"52.05",5.568,8.727,
"52.20",5.586,8.752,
"52.35",5.605,8.777,
"52.50",5.628,8.802,
"52.65",5.648,8.827,
"52.80",5.671,8.852,
"52.95",5.688,8.877,
"53.10",5.707,8.902,
"53.25",5.726,8.927,
"53.40",5.747,8.952333,
"53.55",5.769,8.977333,
"53.70",5.712,9.002,
"53.85",5.625,9.027,
"54.00",5.636,9.052,
"54.15",5.658,9.077,
"54.30",5.681,9.102,
"54.45",5.705,9.127,
"54.60",5.73,9.152,
"54.75",5.757,9.177,
"54.90",5.78,9.202,
"55.05",5.804,9.227,
"55.20",5.828,9.252,
"55.35",5.854,9.277333,
"55.50",5.876,9.302333,
"55.65",5.902,9.327,
"55.80",5.925,9.352333,
"55.95",5.947,9.377,
"56.10",5.97,9.402,
"56.25",5.99,9.427,
"56.40",6.012,9.452,
"56.55",6.036,9.477,
"56.70",6.058,9.502,
"56.85",6.081,9.527,
"57.00",6.1,9.552,
"57.15",6.12,9.577,
"57.30",6.141,9.602333,
"57.45",6.164,9.627334,
"57.60",6.183,9.652,
"57.75",6.203,9.677,
"57.90",6.225,9.702,
"58.05",6.246,9.727333,
"58.20",6.266,9.752,
"58.35",6.285,9.777,
"58.50",6.305,9.802,
"58.65",6.326,9.827,
"58.80",6.347,9.852,
"58.95",6.367,9.877,
"59.10",6.39,9.902,
"59.25",6.409,9.927,
"59.40",6.428,9.952,
"59.55",6.448,9.977,
"59.70",6.469,10.002,
"59.85",6.491,10.027,
"60.00",6.512,10.052,
"60.15",6.534,10.077,
"60.30",6.557,10.102,
"60.45",6.577,10.127,
"60.60",6.597,10.152,
"60.75",6.62,10.177,
"60.90",6.643,10.202,
"61.05",6.663,10.227,
"61.20",6.683,10.25167,
"61.35",6.703,10.277,
"61.50",6.724,10.302,
"61.65",6.746,10.327,
"61.80",6.767,10.352,
"61.95",6.788,10.377,
"62.10",6.809,10.402,
"62.25",6.828,10.427,
"62.40",6.85,10.452,
"62.55",6.875,10.477,
"62.70",6.897,10.502,
"62.85",6.919,10.527,
"63.00",6.939,10.552,
"63.15",6.961,10.577,
"63.30",6.979,10.602,
"63.45",7.001,10.627,
"63.60",7.026,10.652,
"63.75",7.048,10.677,
"63.90",7.07,10.702,
"64.05",7.09,10.72733,
"64.20",7.112,10.752,
"64.35",7.134,10.77733,
"64.50",7.156,10.80233,
"64.65",7.18,10.82733,
"64.80",7.203,10.85233,
"64.95",7.224,10.877,
"65.10",7.245,10.902,
"65.25",7.269,10.927,
"65.40",7.29,10.952,
"65.55",7.314,10.97733,
"65.70",7.337,11.00233,
"65.85",7.361,11.02733,
"66.00",7.382,11.05233,
"66.15",7.404,11.07733,
"66.30",7.426,11.10233,
"66.45",7.45,11.12733,
"66.60",7.473,11.152,
"66.75",7.497,11.177,
"66.90",7.519,11.202,
"67.05",7.543,11.22733,
"67.20",7.564,11.252,
"67.35",7.587,11.27733,
"67.50",7.607,11.30233,
"67.65",7.634,11.327,
"67.80",7.657,11.352,
"67.95",7.682,11.377,
"68.10",7.703,11.40233,
"68.25",7.725,11.42733,
"68.40",7.747,11.45233,
"68.55",7.771,11.47733,
"68.70",7.797,11.502,
"68.85",7.823,11.52733,
"69.00",7.843,11.552,
"69.15",7.866,11.577,
"69.30",7.889,11.60233,
"69.45",7.911,11.62733,
"69.60",7.937,11.65233,
"69.75",7.961,11.67733,
"69.90",7.984,11.70233,
"70.05",8.009,11.72733,
"70.20",8.03,11.75233,
"70.35",8.053,11.77733,
"70.50",8.079,11.80233,
"70.65",8.105,11.827,
"70.80",8.129,11.85233,
"70.95",8.154,11.87733,
"71.10",8.178,11.90233,
"71.25",8.2,11.92733,
"71.40",8.228,11.95233,
"71.55",8.256,11.977,
"71.70",8.282,12.002,
"71.85",8.306,12.027,
"72.00",8.331,12.052,
"72.15",8.354,12.077,
"72.30",8.379,12.102,
"72.45",8.404,12.127,
"72.60",8.432,12.152,
"72.75",8.46,12.177,
"72.90",8.486,12.202,
"73.05",8.513,12.227,
"73.20",8.539,12.252,
"73.35",8.564,12.277,
"73.50",8.59,12.302,
"73.65",8.619,12.327,
"73.80",8.643,12.352,
"73.95",8.669,12.377,
"74.10",8.696,12.402,
"74.25",8.724,12.427,
"74.40",8.747,12.45233,
"74.55",8.776,12.477,
"74.70",8.804,12.502,
"74.85",8.83,12.527,
"75.00",8.856,12.552,
"75.15",8.881,12.57733,
"75.30",8.911,12.60233,
"75.45",8.935,12.62733,
"75.60",8.963,12.65233,
"75.75",8.991,12.677,
"75.90",9.017,12.702,
"76.05",9.042,12.727,
"76.20",9.067,12.75233,
"76.35",9.096,12.77733,
"76.50",9.122,12.80233,
"76.65",9.152,12.827,
"76.80",9.177,12.85233,
"76.95",9.2,12.877,
"77.10",9.227,12.902,
"77.25",9.252,12.92733,
"77.40",9.278,12.95233,
"77.55",9.306,12.977,
"77.70",9.332,13.002,
"77.85",9.359,13.027,
"78.00",9.385,13.052,
"78.15",9.41,13.07733,
"78.30",9.437,13.10233,
"78.45",9.462,13.12733,
"78.60",9.491,13.152,
"78.75",9.518,13.177,
"78.90",9.544,13.202,
"79.05",9.57,13.227,
"79.20",9.599,13.252,
"79.35",9.624,13.277,
"79.50",9.65,13.302,
"79.65",9.68,13.327,
"79.80",9.707,13.352,
"79.95",9.736,13.377,
"80.10",9.762,13.40233,
"80.25",9.785,13.427,
"80.40",9.812,13.452,
"80.55",9.84,13.47733,
"80.70",9.867,13.502,
"80.85",9.895,13.52733,
"81.00",9.922,13.552,
"81.15",9.949,13.57733,
"81.30",9.975,13.602,
"81.45",10.004,13.627,
"81.60",10.033,13.652,
"81.75",10.062,13.677,
"81.90",10.09,13.702,
"82.05",10.118,13.727,
"82.20",10.143,13.752,
"82.35",10.172,13.777,
"82.50",10.199,13.802,
"82.65",10.229,13.827,
"82.80",10.26,13.852,
"82.95",10.287,13.877,
"83.10",10.312,13.90233,
"83.25",10.341,13.927,
"83.40",10.368,13.952,
"83.55",10.396,13.977,
"83.70",10.423,14.002,
"83.85",10.453,14.027,
"84.00",10.483,14.052,
"84.15",10.509,14.077,
"84.30",10.536,14.102,
"84.45",10.563,14.127,
"84.60",10.594,14.152,
"84.75",10.623,14.177,
"84.90",10.65,14.202,
"85.05",10.679,14.227,
"85.20",10.707,14.252,
"85.35",10.733,14.27733,
"85.50",10.761,14.30233,
"85.65",10.792,14.327,
"85.80",10.819,14.352,
"85.95",10.845,14.377,
"86.10",10.873,14.402,
"86.25",10.901,14.427,
"86.40",10.929,14.45233,
"86.55",10.959,14.47733,
"86.70",10.989,14.502,
"86.85",11.017,14.52733,
"87.00",11.047,14.55233,
"87.15",11.073,14.57733,
"87.30",11.1,14.602,
"87.45",11.127,14.62733,
"87.60",11.155,14.652,
"87.75",11.187,14.67733,
"87.90",11.215,14.702,
"88.05",11.239,14.727,
"88.20",11.265,14.752,
"88.35",11.28,14.777,
"88.50",11.295,14.802,
"88.65",11.31,14.827,
"88.80",11.33,14.852,
"88.95",11.356,14.877,
"89.10",11.381,14.902,
"89.25",11.405,14.927,
"89.40",11.431,14.952,
"89.55",11.46,14.977,
"89.70",11.487,15.002,
"89.85",11.519,15.02733,
"90.00",11.545,15.052,
"90.15",11.571,15.077,
"90.30",11.596,15.102,
"90.45",11.628,15.127,
"90.60",11.657,15.152,
"90.75",11.689,15.177,
"90.90",11.719,15.202,
"91.05",11.751,15.227,
"91.20",11.782,15.252,
"91.35",11.815,15.277,
"91.50",11.845,15.302,
"91.65",11.877,15.327,
"91.80",11.911,15.352,
"91.95",11.938,15.377,
"92.10",11.969,15.402,
"92.25",11.998,15.427,
"92.40",12.03,15.452,
"92.55",12.062,15.477,
"92.70",12.097,15.502,
"92.85",12.125,15.527,
"93.00",12.155,15.55167,
"93.15",12.182,15.577,
"93.30",12.213,15.602,
"93.45",12.243,15.627,
"93.60",12.277,15.652,
"93.75",12.309,15.677,
"93.90",12.341,15.702,
"94.05",12.371,15.727,
"94.20",12.399,15.752,
"94.35",12.434,15.777,
"94.50",12.466,15.802,
"94.65",12.498,15.827,
"94.80",12.53,15.852,
"94.95",12.559,15.877,
"95.10",12.591,15.902,
"95.25",12.623,15.927,
"95.40",12.655,15.952,
"95.55",12.689,15.977,
"95.70",12.723,16.002,
"95.85",12.755,16.027,
"96.00",12.789,16.052,
"96.15",12.82,16.077,
"96.30",12.855,16.102,
"96.45",12.889,16.127,
"96.60",12.925,16.152,
"96.75",12.959,16.17733,
"96.90",12.991,16.20233,
"97.05",13.023,16.227,
"97.20",13.056,16.252,
"97.35",13.089,16.277,
"97.50",13.122,16.302,
"97.65",13.158,16.327,
"97.80",13.191,16.352,
"97.95",13.221,16.377,
"98.10",13.242,16.402,
"98.25",13.271,16.427,
"98.40",13.307,16.452,
"98.55",13.342,16.477,
"98.70",13.38,16.502,
"98.85",13.415,16.527,
"99.00",13.45,16.552,
"99.15",13.484,16.577,
"99.30",13.515,16.602,
"99.45",13.547,16.62733,
"99.60",13.584,16.652,
"99.75",13.618,16.677,
"99.90",13.653,16.702,
"100.05",13.687,16.72733,
"100.20",13.72,16.752,
"100.35",13.756,16.77733,
"100.50",13.792,16.802,
"100.65",13.827,16.827,
"100.80",13.862,16.852,
"100.95",13.897,16.877,
"101.10",13.931,16.902,
"101.25",13.964,16.927,
"101.40",13.998,16.95233,
"101.55",14.037,16.97733,
"101.70",14.072,17.002,
"101.85",14.104,17.02733,
"102.00",14.136,17.052,
"102.15",14.166,17.077,
"102.30",14.198,17.102,
"102.45",14.23,17.127,
"102.60",14.265,17.152,
"102.75",14.298,17.177,
"102.90",14.332,17.202,
"103.05",14.366,17.227,
"103.20",14.398,17.252,
"103.35",14.43,17.277,
"103.50",14.462,17.302,
"103.65",14.497,17.327,
"103.80",14.532,17.352,
"103.95",14.566,17.377,
"104.10",14.599,17.402,
"104.25",14.633,17.427,
"104.40",14.667,17.452,
"104.55",14.702,17.477,
"104.70",14.737,17.502,
"104.85",14.768,17.527,
"105.00",14.797,17.552,
"105.15",14.825,17.577,
"105.30",14.859,17.60167,
"105.45",14.892,17.627,
"105.60",14.926,17.652,
"105.75",14.959,17.677,
"105.90",14.994,17.702,
"106.05",15.022,17.727,
"106.20",15.046,17.752,
"106.35",15.078,17.777,
"106.50",15.109,17.802,
"106.65",15.142,17.827,
"106.80",15.176,17.85167,
"106.95",15.206,17.87667,
"107.10",15.24,17.90133,
"107.25",15.27,17.92633,
"107.40",15.304,17.95167,
"107.55",15.336,17.977,
"107.70",15.375,18.002,
"107.85",15.408,18.027,
"108.00",15.437,18.05167,
"108.15",15.464,18.077,
"108.30",15.491,18.102,
"108.45",15.523,18.127,
"108.60",15.557,18.152,
"108.75",15.589,18.177,
"108.90",15.623,18.202,
"109.05",15.659,18.227,
"109.20",15.691,18.25233,
"109.35",15.726,18.27733,
"109.50",15.761,18.30233,
"109.65",15.794,18.32733,
"109.80",15.83,18.35267,
"109.95",15.868,18.37767,
"110.10",15.901,18.40267,
"110.25",15.933,18.42733,
"110.40",15.967,18.45233,
"110.55",16.001,18.47733,
"110.70",16.035,18.50233,
"110.85",16.066,18.527,
"111.00",16.099,18.552,
"111.15",16.13,18.57667,
"111.30",16.163,18.60167,
"111.45",16.197,18.62667,
"111.60",16.233,18.652,
"111.75",16.272,18.677,
"111.90",16.308,18.702,
"112.05",16.341,18.727,
"112.20",16.374,18.75167,
"112.35",16.411,18.77667,
"112.50",16.446,18.80167,
"112.65",16.48,18.82667,
"112.80",16.516,18.852,
"112.95",16.551,18.877,
"113.10",16.585,18.90233,
"113.25",16.617,18.927,
"113.40",16.649,18.952,
"113.55",16.684,18.977,
"113.70",16.725,19.002,
"113.85",16.758,19.027,
"114.00",16.79,19.052,
"114.15",16.822,19.07733,
"114.30",16.854,19.102,
"114.45",16.887,19.12733,
"114.60",16.92,19.15233,
"114.75",16.956,19.17733,
"114.90",16.99,19.20233,
"115.05",17.022,19.22733,
"115.20",17.056,19.25233,
"115.35",17.09,19.27733,
"115.50",17.123,19.30233,
"115.65",17.157,19.32733,
"115.80",17.193,19.35233,
"115.95",17.224,19.37733,
"116.10",17.255,19.40233,
"116.25",17.291,19.42733,
"116.40",17.326,19.452,
"116.55",17.359,19.477,
"116.70",17.395,19.502,
"116.85",17.429,19.527,
"117.00",17.461,19.552,
"117.15",17.495,19.577,
"117.30",17.527,19.602,
"117.45",17.562,19.627,
"117.60",17.597,19.652,
"117.75",17.635,19.677,
"117.90",17.671,19.702,
"118.05",17.704,19.727,
"118.20",17.735,19.752,
"118.35",17.768,19.777,
"118.50",17.803,19.80233,
"118.65",17.838,19.827,
"118.80",17.873,19.85233,
"118.95",17.908,19.87733,
"119.10",17.939,19.902,
"119.25",17.972,19.927,
"119.40",18.001,19.952,
"119.55",18.031,19.977,
"119.70",18.063,20.002,
"119.85",18.096,20.02733,
"120.00",18.124,20.052,
"120.15",18.156,20.077,
"120.30",18.187,20.102,
"120.45",18.217,20.12733,
"120.60",18.252,20.15233,
"120.75",18.285,20.17733,
"120.90",18.315,20.20233,
"121.05",18.347,20.22733,
"121.20",18.378,20.25233,
"121.35",18.409,20.27733,
"121.50",18.442,20.30233,
"121.65",18.476,20.327,
"121.80",18.508,20.352,
"121.95",18.538,20.377,
"122.10",18.569,20.402,
"122.25",18.597,20.427,
"122.40",18.63,20.452,
"122.55",18.664,20.477,
"122.70",18.701,20.502,
"122.85",18.731,20.527,
"123.00",18.764,20.552,
"123.15",18.795,20.577,
"123.30",18.824,20.602,
"123.45",18.855,20.627,
"123.60",18.889,20.652,
"123.75",18.919,20.677,
"123.90",18.953,20.702,
"124.05",18.983,20.727,
"124.20",19.015,20.752,
"124.35",19.044,20.777,
"124.50",19.076,20.802,
"124.65",19.111,20.827,
"124.80",19.141,20.852,
"124.95",19.174,20.877,
"125.10",19.205,20.90233,
"125.25",19.234,20.927,
"125.40",19.259,20.952,
"125.55",19.291,20.97733,
"125.70",19.321,21.002,
"125.85",19.35,21.02733,
"126.00",19.379,21.052,
"126.15",19.404,21.077,
"126.30",19.432,21.102,
"126.45",19.461,21.127,
"126.60",19.497,21.152,
"126.75",19.526,21.177,
"126.90",19.555,21.202,
"127.05",19.582,21.227,
"127.20",19.609,21.252,
"127.35",19.636,21.277,
"127.50",19.666,21.30233,
"127.65",19.697,21.327,
"127.80",19.728,21.352,
"127.95",19.754,21.377,
"128.10",19.78,21.402,
"128.25",19.81,21.427,
"128.40",19.837,21.452,
"128.55",19.867,21.477,
"128.70",19.896,21.502,
"128.85",19.924,21.527,
"129.00",19.953,21.552,
"129.15",19.981,21.577,
"129.30",20.008,21.602,
"129.45",20.035,21.627,
"129.60",20.062,21.652,
"129.75",20.093,21.677,
"129.90",20.12,21.702,
"130.05",20.148,21.72733,
"130.20",20.175,21.752,
"130.35",20.203,21.777,
"130.50",20.229,21.802,
"130.65",20.261,21.827,
"130.80",20.289,21.852,
"130.95",20.314,21.877,
"131.10",20.342,21.902,
"131.25",20.368,21.927,
"131.40",20.395,21.952,
"131.55",20.42,21.977,
"131.70",20.452,22.002,
"131.85",20.477,22.027,
"132.00",20.504,22.052,
"132.15",20.529,22.077,
"132.30",20.554,22.102,
"132.45",20.582,22.127,
"132.60",20.611,22.152,
"132.75",20.636,22.177,
"132.90",20.66,22.202,
"133.05",20.685,22.227,
"133.20",20.707,22.252,
"133.35",20.731,22.277,
"133.50",20.755,22.30233,
"133.65",20.781,22.327,
"133.80",20.806,22.352,
"133.95",20.829,22.377,
"134.10",20.85,22.402,
"134.25",20.874,22.427,
"134.40",20.898,22.452,
"134.55",20.923,22.477,
"134.70",20.949,22.502,
"134.85",20.973,22.527,
"135.00",20.999,22.552,
"135.15",21.02,22.577,
"135.30",21.048,22.60233,
"135.45",21.072,22.627,
"135.60",21.095,22.652,
"135.75",21.118,22.677,
"135.90",21.139,22.702,
"136.05",21.162,22.727,
"136.20",21.181,22.752,
"136.35",21.205,22.777,
"136.50",21.23,22.802,
"136.65",21.252,22.82733,
"136.80",21.277,22.852,
"136.95",21.299,22.87733,
"137.10",21.318,22.902,
"137.25",21.337,22.927,
"137.40",21.358,22.952,
"137.55",21.381,22.977,
"137.70",21.406,23.002,
"137.85",21.426,23.027,
"138.00",21.449,23.052,
"138.15",21.469,23.077,
"138.30",21.49,23.102,
"138.45",21.508,23.127,
"138.60",21.531,23.152,
"138.75",21.554,23.177,
"138.90",21.575,23.202,
"139.05",21.598,23.227,
"139.20",21.614,23.252,
"139.35",21.632,23.277,
"139.50",21.654,23.302,
"139.65",21.675,23.327,
"139.80",21.698,23.352,
"139.95",21.717,23.377,
"140.10",21.736,23.402,
"140.25",21.755,23.427,
"140.40",21.775,23.452,
"140.55",21.795,23.477,
"140.70",21.818,23.502,
"140.85",21.836,23.527,
"141.00",21.855,23.552,
"141.15",21.876,23.577,
"141.30",21.897,23.602,
"141.45",21.918,23.62733,
"141.60",21.94,23.652,
"141.75",21.961,23.677,
"141.90",21.98,23.702,
"142.05",21.999,23.727,
"142.20",22.016,23.752,
"142.35",22.038,23.77733,
"142.50",22.059,23.802,
"142.65",22.08,23.827,
"142.80",22.101,23.852,
"142.95",22.124,23.877,
"143.10",22.14,23.902,
"143.25",22.16,23.927,
"143.40",22.181,23.952,
"143.55",22.2,23.977,
"143.70",22.223,24.002,
"143.85",22.244,24.027,
"144.00",22.262,24.052,
"144.15",22.282,24.077,
"144.30",22.3,24.10233,
"144.45",22.319,24.127,
"144.60",22.341,24.152,
"144.75",22.361,24.177,
"144.90",22.379,24.202,
"145.05",22.397,24.227,
"145.20",22.416,24.252,
"145.35",22.43,24.277,
"145.50",22.445,24.302,
"145.65",22.461,24.327,
"145.80",22.476,24.352,
"145.95",22.488,24.377,
"146.10",22.498,24.402,
"146.25",22.51,24.427,
"146.40",22.523,24.452,
"146.55",22.542,24.477,
"146.70",22.562,24.502,
"146.85",22.577,24.527,
"147.00",22.595,24.552,
"147.15",22.608,24.577,
"147.30",22.623,24.602,
"147.45",22.637,24.627,
"147.60",22.657,24.65233,
"147.75",22.681,24.677,
"147.90",22.7,24.702,
"148.05",22.717,24.727,
"148.20",22.735,24.75233,
"148.35",22.753,24.777,
"148.50",22.773,24.802,
"148.65",22.791,24.827,
"148.80",22.813,24.852,
"148.95",22.833,24.877,
"149.10",22.851,24.902,
"149.25",22.872,24.927,
"149.40",22.893,24.952,
"149.55",22.915,24.977,
"149.70",22.939,25.002,
"149.85",22.962,25.027,
"150.00",22.981,25.052,
"150.15",23.002,25.077,
"150.30",23.023,25.102,
"150.45",23.047,25.127,
"150.60",23.073,25.152,
"150.75",23.098,25.177,
"150.90",23.118,25.202,
"151.05",23.139,25.22733,
"151.20",23.159,25.252,
"151.35",23.179,25.277,
"151.50",23.204,25.302,
"151.65",23.224,25.327,
"151.80",23.247,25.352,
"151.95",23.266,25.377,
"152.10",23.283,25.402,
"152.25",23.303,25.427,
"152.40",23.324,25.452,
"152.55",23.346,25.477,
"152.70",23.37,25.502,
"152.85",23.395,25.527,
"153.00",23.417,25.552,
"153.15",23.435,25.577,
"153.30",23.453,25.602,
"153.45",23.472,25.627,
"153.60",23.493,25.652,
"153.75",23.514,25.677,
"153.90",23.539,25.702,
"154.05",23.558,25.727,
"154.20",23.576,25.752,
"154.35",23.595,25.777,
"154.50",23.617,25.802,
"154.65",23.638,25.827,
"154.80",23.659,25.852,
"154.95",23.68,25.877,
"155.10",23.701,25.902,
"155.25",23.721,25.927,
"155.40",23.741,25.952,
"155.55",23.765,25.977,
"155.70",23.788,26.002,
"155.85",23.811,26.027,
"156.00",23.828,26.052,
"156.15",23.846,26.077,
"156.30",23.869,26.102,
"156.45",23.89,26.127,
"156.60",23.912,26.152,
"156.75",23.934,26.177,
"156.90",23.954,26.20233,
"157.05",23.969,26.227,
"157.20",23.98,26.252,
"157.35",24,26.277,
"157.50",24.02,26.302,
"157.65",24.04,26.327,
"157.80",24.06,26.352,
"157.95",24.08,26.377,
"158.10",24.1,26.40233,
"158.25",24.12,26.427,
"158.40",24.14,26.45233,
"158.55",24.16,26.47733,
"158.70",24.18,26.502,
"158.85",24.2,26.52733,
"159.00",24.22,26.55233,
"159.15",24.24,26.57733,
"159.30",24.26,26.60233,
"159.45",24.28,26.62733,
"159.60",24.31,26.65233,
"159.75",24.33,26.67733,
"159.90",24.35,26.702,
"160.05",24.37,26.72733,
"160.20",24.39,26.752,
"160.35",24.41,26.77733,
"160.50",24.43,26.802,
"160.65",24.45,26.827,
"160.80",24.47,26.852,
"160.95",24.49,26.877,
"161.10",24.51,26.902,
"161.25",24.53,26.927,
"161.40",24.55,26.952,
"161.55",24.57,26.977,
"161.70",24.59,27.002,
"161.85",24.61,27.027,
"162.00",24.63,27.052,
"162.15",24.64,27.077,
"162.30",24.66,27.102,
"162.45",24.68,27.127,
"162.60",24.7,27.152,
"162.75",24.73,27.177,
"162.90",24.75,27.202,
"163.05",24.77,27.227,
"163.20",24.79,27.252,
"163.35",24.81,27.277,
"163.50",24.83,27.302,
"163.65",24.85,27.327,
"163.80",24.87,27.352,
"163.95",24.89,27.377,
"164.10",24.91,27.402,
"164.25",24.93,27.427,
"164.40",24.95,27.452,
"164.55",24.97,27.477,
"164.70",25,27.502,
"164.85",25.01,27.527,
"165.00",25.04,27.552,
"165.15",25.06,27.577,
"165.30",25.07,27.602,
"165.45",25.09,27.627,
"165.60",25.12,27.652,
"165.75",25.14,27.677,
"165.90",25.16,27.702,
"166.05",25.17,27.727,
"166.20",25.19,27.752,
"166.35",25.21,27.77733,
"166.50",25.23,27.802,
"166.65",25.25,27.827,
"166.80",25.28,27.852,
"166.95",25.29,27.877,
"167.10",25.31,27.902,
"167.25",25.33,27.927,
"167.40",25.34,27.95233,
"167.55",25.36,27.97733,
"167.70",25.38,28.002,
"167.85",25.41,28.02733,
"168.00",25.42,28.052,
"168.15",25.44,28.077,
"168.30",25.45,28.10233,
"168.45",25.47,28.127,
"168.60",25.49,28.152,
"168.75",25.51,28.177,
"168.90",25.53,28.202,
"169.05",25.55,28.227,
"169.20",25.57,28.252,
"169.35",25.59,28.27733,
"169.50",25.61,28.30233,
"169.65",25.63,28.327,
"169.80",25.65,28.352,
"169.95",25.67,28.37733,
"170.10",25.69,28.40233,
"170.25",25.71,28.42733,
"170.40",25.73,28.45233,
"170.55",25.75,28.47733,
"170.70",25.77,28.502,
"170.85",25.79,28.52733,
"171.00",25.81,28.55233,
"171.15",25.82,28.57733,
"171.30",25.84,28.60233,
"171.45",25.87,28.62733,
"171.60",25.89,28.65233,
"171.75",25.91,28.677,
"171.90",25.93,28.702,
"172.05",25.95,28.727,
"172.20",25.96,28.752,
"172.35",25.98,28.77733,
"172.50",26,28.80233,
"172.65",26.03,28.827,
"172.80",26.05,28.852,
"172.95",26.07,28.877,
"173.10",26.08,28.902,
"173.25",26.1,28.927,
"173.40",26.12,28.952,
"173.55",26.14,28.977,
"173.70",26.17,29.002,
"173.85",26.19,29.027,
"174.00",26.21,29.052,
"174.15",26.23,29.077,
"174.30",26.24,29.10233,
"174.45",26.27,29.127,
"174.60",26.29,29.152,
"174.75",26.31,29.177,
"174.90",26.33,29.202,
"175.05",26.35,29.227,
"175.20",26.37,29.252,
"175.35",26.39,29.277,
"175.50",26.41,29.302,
"175.65",26.43,29.327,
"175.80",26.45,29.352,
"175.95",26.47,29.377,
"176.10",26.49,29.402,
"176.25",26.51,29.427,
"176.40",26.53,29.452,
"176.55",26.55,29.477,
"176.70",26.58,29.502,
"176.85",26.6,29.527,
"177.00",26.61,29.552,
"177.15",26.63,29.577,
"177.30",26.65,29.602,
"177.45",26.67,29.627,
"177.60",26.7,29.652,
"177.75",26.72,29.67733,
"177.90",26.74,29.70233,
"178.05",26.75,29.72733,
"178.20",26.77,29.752,
"178.35",26.79,29.777,
"178.50",26.81,29.80233,
"178.65",26.84,29.827,
"178.80",26.86,29.852,
"178.95",26.88,29.877,
"179.10",26.9,29.902,
"179.25",26.92,29.927,
"179.40",26.94,29.952,
"179.55",26.96,29.977,
"179.70",26.98,30.002,
"179.85",27,30.027,
"180.00",27.02,30.052,
"180.15",27.04,30.077,
"180.30",27.06,30.102,
"180.45",27.08,30.127,
"180.60",27.1,30.152,
"180.75",27.13,30.177,
"180.90",27.15,30.202,
"181.05",27.16,30.227,
"181.20",27.18,30.252,
"181.35",27.2,30.277,
"181.50",27.22,30.302,
"181.65",27.24,30.327,
"181.80",27.26,30.352,
"181.95",27.28,30.377,
"182.10",27.3,30.402,
"182.25",27.32,30.427,
"182.40",27.34,30.452,
"182.55",27.36,30.477,
"182.70",27.38,30.502,
"182.85",27.4,30.527,
"183.00",27.42,30.552,
"183.15",27.44,30.577,
"183.30",27.46,30.602,
"183.45",27.48,30.62733,
"183.60",27.5,30.652,
"183.75",27.52,30.677,
"183.90",27.54,30.702,
"184.05",27.56,30.727,
"184.20",27.58,30.752,
"184.35",27.6,30.777,
"184.50",27.61,30.802,
"184.65",27.64,30.827,
"184.80",27.66,30.852,
"184.95",27.68,30.877,
"185.10",27.69,30.902,
"185.25",27.71,30.92667,
"185.40",27.73,30.95167,
"185.55",27.75,30.97667,
"185.70",27.77,31.00167,
"185.85",27.79,31.027,
"186.00",27.81,31.052,
"186.15",27.83,31.077,
"186.30",27.85,31.102,
"186.45",27.87,31.127,
"186.60",27.89,31.15167,
"186.75",27.91,31.17667,
"186.90",27.93,31.20167,
"187.05",27.94,31.22667,
"187.20",27.96,31.25167,
"187.35",27.98,31.27667,
"187.50",28,31.302,
"187.65",28.03,31.32667,
"187.80",28.05,31.352,
"187.95",28.07,31.377,
"188.10",28.09,31.402,
"188.25",28.11,31.427,
"188.40",28.13,31.452,
"188.55",28.15,31.477,
"188.70",28.17,31.502,
"188.85",28.19,31.527,
"189.00",28.21,31.55167,
"189.15",28.23,31.577,
"189.30",28.24,31.602,
"189.45",28.26,31.627,
"189.60",28.28,31.652,
"189.75",28.3,31.677,
"189.90",28.32,31.702,
"190.05",28.33,31.727,
"190.20",28.35,31.752,
"190.35",28.36,31.777,
"190.50",28.37,31.802,
"190.55",28.37,31.81033,