File: exposed_flourocarbon_10cm_10mmpm_24nm_560esh_1.csv
"Test Name","Test Mode","Test Type","Control","Test Speed 1","Test Speed 2","Test Speed 3","Change Point 1","Change Point 2","Disp. Origin","Break and Limit Action","Sensitivity:","Level:"
"","Single","Tensile","Stroke",10,1,1,"Off","Off","Start","Stop",0,1

"Title","Sub title","Comment"
"","",""

"Shape:","Batch Size:","SubBatch Size:"
"Plate",1,1
"Name:","Thickness","Width","Gauge Length",
"Size Unit:","mm","mm","mm",
" 1 - 1","1.0000","1.0000","100.0000",

"Name",
"Parameter",
"Units",
" 1 - 1",

" 1- 1"
"Time","Force","Stroke",
"sec","N","mm",
"0.00",.002,0,
"0.15",.004,2.766667E-02,
"0.30",.018,.055,
"0.45",.044,8.266667E-02,
"0.60",.069,.1103333,
"0.75",.096,.138,
"0.90",.123,.1653333,
"1.05",.149,.193,
"1.20",.176,.2206667,
"1.35",.199,.248,
"1.50",.223,.2756667,
"1.65",.249,.3033333,
"1.80",.275,.331,
"1.95",.3,.3583333,
"2.10",.324,.385,
"2.25",.348,.4116667,
"2.40",.373,.4383333,
"2.55",.395,.4643333,
"2.70",.419,.4906667,
"2.85",.444,.5163333,
"3.00",.465,.542,
"3.15",.485,.568,
"3.30",.509,.5933333,
"3.45",.53,.619,
"3.60",.555,.6443334,
"3.75",.574,.6696666,
"3.90",.595,.695,
"4.05",.617,.7203333,
"4.20",.637,.7456667,
"4.35",.659,.771,
"4.50",.678,.796,
"4.65",.696,.821,
"4.80",.718,.846,
"4.95",.738,.8713334,
"5.10",.759,.8963333,
"5.25",.778,.9213333,
"5.40",.795,.9466667,
"5.55",.816,.9716667,
"5.70",.837,.9966667,
"5.85",.855,1.021667,
"6.00",.874,1.046667,
"6.15",.893,1.071667,
"6.30",.909,1.096667,
"6.45",.926,1.122,
"6.60",.946,1.146667,
"6.75",.964,1.171667,
"6.90",.982,1.196667,
"7.05",.999,1.222,
"7.20",1.017,1.246667,
"7.35",1.033,1.272,
"7.50",1.052,1.297,
"7.65",1.068,1.321667,
"7.80",1.084,1.346667,
"7.95",1.101,1.371667,
"8.10",1.116,1.396667,
"8.25",1.132,1.421667,
"8.40",1.151,1.446667,
"8.55",1.166,1.471667,
"8.70",1.182,1.496667,
"8.85",1.197,1.521667,
"9.00",1.212,1.546667,
"9.15",1.228,1.571667,
"9.30",1.244,1.596667,
"9.45",1.258,1.621667,
"9.60",1.274,1.646667,
"9.75",1.288,1.671667,
"9.90",1.302,1.696667,
"10.05",1.318,1.721667,
"10.20",1.333,1.746667,
"10.35",1.346,1.771667,
"10.50",1.36,1.796667,
"10.65",1.377,1.821667,
"10.80",1.393,1.847,
"10.95",1.406,1.871667,
"11.10",1.421,1.896667,
"11.25",1.434,1.921667,
"11.40",1.449,1.947,
"11.55",1.461,1.971667,
"11.70",1.474,1.996667,
"11.85",1.487,2.021667,
"12.00",1.505,2.046667,
"12.15",1.516,2.071667,
"12.30",1.529,2.096667,
"12.45",1.541,2.122,
"12.60",1.555,2.147,
"12.75",1.57,2.172,
"12.90",1.585,2.197,
"13.05",1.597,2.221667,
"13.20",1.61,2.246667,
"13.35",1.621,2.272,
"13.50",1.637,2.297,
"13.65",1.65,2.321667,
"13.80",1.663,2.347,
"13.95",1.676,2.372,
"14.10",1.688,2.397,
"14.25",1.701,2.422,
"14.40",1.714,2.447,
"14.55",1.726,2.472,
"14.70",1.74,2.497,
"14.85",1.753,2.522,
"15.00",1.767,2.547,
"15.15",1.781,2.571667,
"15.30",1.788,2.597,
"15.45",1.8,2.621667,
"15.60",1.814,2.646667,
"15.75",1.827,2.671667,
"15.90",1.838,2.696667,
"16.05",1.853,2.721667,
"16.20",1.864,2.747,
"16.35",1.875,2.772,
"16.50",1.888,2.797,
"16.65",1.899,2.821667,
"16.80",1.914,2.846667,
"16.95",1.925,2.872,
"17.10",1.938,2.897,
"17.25",1.95,2.921667,
"17.40",1.962,2.946667,
"17.55",1.974,2.971667,
"17.70",1.986,2.996667,
"17.85",1.996,3.021667,
"18.00",2.009,3.046667,
"18.15",2.022,3.071667,
"18.30",2.031,3.096667,
"18.45",2.044,3.121667,
"18.60",2.057,3.147,
"18.75",2.071,3.172,
"18.90",2.083,3.197,
"19.05",2.093,3.221667,
"19.20",2.107,3.247,
"19.35",2.118,3.272,
"19.50",2.131,3.297,
"19.65",2.145,3.321667,
"19.80",2.159,3.346667,
"19.95",2.171,3.371667,
"20.10",2.186,3.396667,
"20.25",2.196,3.421667,
"20.40",2.209,3.447,
"20.55",2.22,3.472,
"20.70",2.229,3.496667,
"20.85",2.244,3.521667,
"21.00",2.259,3.546667,
"21.15",2.271,3.571667,
"21.30",2.283,3.597,
"21.45",2.295,3.622,
"21.60",2.31,3.647,
"21.75",2.323,3.671667,
"21.90",2.338,3.696667,
"22.05",2.348,3.721667,
"22.20",2.362,3.746667,
"22.35",2.374,3.772,
"22.50",2.387,3.797,
"22.65",2.401,3.821667,
"22.80",2.415,3.846667,
"22.95",2.427,3.871667,
"23.10",2.44,3.896667,
"23.25",2.454,3.921667,
"23.40",2.466,3.946667,
"23.55",2.48,3.971667,
"23.70",2.494,3.996667,
"23.85",2.507,4.021667,
"24.00",2.521,4.046667,
"24.15",2.533,4.071667,
"24.30",2.547,4.096667,
"24.45",2.562,4.121666,
"24.60",2.576,4.146667,
"24.75",2.587,4.171667,
"24.90",2.602,4.196667,
"25.05",2.615,4.221667,
"25.20",2.628,4.246666,
"25.35",2.638,4.271667,
"25.50",2.656,4.296667,
"25.65",2.669,4.321667,
"25.80",2.682,4.346667,
"25.95",2.696,4.371666,
"26.10",2.709,4.397,
"26.25",2.724,4.421667,
"26.40",2.738,4.447,
"26.55",2.751,4.472,
"26.70",2.766,4.497,
"26.85",2.779,4.522,
"27.00",2.797,4.547,
"27.15",2.811,4.572,
"27.30",2.823,4.596667,
"27.45",2.837,4.621666,
"27.60",2.848,4.646667,
"27.75",2.862,4.671667,
"27.90",2.878,4.697,
"28.05",2.892,4.722,
"28.20",2.905,4.747,
"28.35",2.919,4.772,
"28.50",2.935,4.796667,
"28.65",2.949,4.821667,
"28.80",2.965,4.846667,
"28.95",2.981,4.871666,
"29.10",2.994,4.896667,
"29.25",3.009,4.921667,
"29.40",3.024,4.946667,
"29.55",3.038,4.971667,
"29.70",3.054,4.996666,
"29.85",3.071,5.022,
"30.00",3.085,5.047,
"30.15",3.096,5.071667,
"30.30",3.112,5.096667,
"30.45",3.126,5.122,
"30.60",3.141,5.147,
"30.75",3.158,5.172,
"30.90",3.173,5.197,
"31.05",3.188,5.221667,
"31.20",3.203,5.246666,
"31.35",3.217,5.272,
"31.50",3.231,5.296667,
"31.65",3.247,5.321667,
"31.80",3.264,5.346667,
"31.95",3.278,5.372,
"32.10",3.293,5.397,
"32.25",3.307,5.422,
"32.40",3.322,5.447,
"32.55",3.336,5.472,
"32.70",3.355,5.497,
"32.85",3.369,5.522,
"33.00",3.386,5.547,
"33.15",3.4,5.572,
"33.30",3.414,5.597,
"33.45",3.43,5.621666,
"33.60",3.447,5.647,
"33.75",3.462,5.672,
"33.90",3.476,5.697,
"34.05",3.491,5.722,
"34.20",3.506,5.746666,
"34.35",3.523,5.772,
"34.50",3.535,5.796667,
"34.65",3.553,5.821667,
"34.80",3.571,5.846667,
"34.95",3.584,5.871666,
"35.10",3.599,5.896667,
"35.25",3.614,5.921667,
"35.40",3.63,5.946667,
"35.55",3.644,5.971667,
"35.70",3.664,5.996666,
"35.85",3.679,6.022,
"36.00",3.697,6.047,
"36.15",3.713,6.072,
"36.30",3.729,6.097,
"36.45",3.747,6.122,
"36.60",3.76,6.146667,
"36.75",3.772,6.171667,
"36.90",3.79,6.196667,
"37.05",3.807,6.221667,
"37.20",3.822,6.246666,
"37.35",3.84,6.272,
"37.50",3.854,6.296667,
"37.65",3.872,6.321667,
"37.80",3.889,6.346667,
"37.95",3.904,6.371666,
"38.10",3.918,6.397,
"38.25",3.934,6.421667,
"38.40",3.953,6.446667,
"38.55",3.97,6.472,
"38.70",3.987,6.496666,
"38.85",4.004,6.522,
"39.00",4.022,6.546667,
"39.15",4.034,6.571667,
"39.30",4.052,6.596667,
"39.45",4.07,6.621666,
"39.60",4.086,6.646667,
"39.75",4.103,6.671667,
"39.90",4.121,6.696667,
"40.05",4.136,6.721667,
"40.20",4.152,6.746666,
"40.35",4.167,6.771667,
"40.50",4.183,6.796667,
"40.65",4.201,6.821667,
"40.80",4.218,6.846667,
"40.95",4.235,6.871666,
"41.10",4.252,6.896667,
"41.25",4.269,6.921667,
"41.40",4.284,6.946667,
"41.55",4.3,6.971667,
"41.70",4.314,6.996666,
"41.85",4.272,7.021667,
"42.00",4.238,7.046667,
"42.15",4.258,7.071667,
"42.30",4.275,7.096667,
"42.45",4.298,7.121666,
"42.60",4.318,7.146667,
"42.75",4.338,7.171667,
"42.90",4.358,7.196667,
"43.05",4.376,7.221667,
"43.20",4.398,7.246666,
"43.35",4.418,7.271667,
"43.50",4.439,7.296667,
"43.65",4.458,7.321667,
"43.80",4.478,7.346667,
"43.95",4.497,7.372,
"44.10",4.517,7.396667,
"44.25",4.535,7.421667,
"44.40",4.555,7.446667,
"44.55",4.575,7.471667,
"44.70",4.594,7.496666,
"44.85",4.612,7.521667,
"45.00",4.63,7.546667,
"45.15",4.648,7.571667,
"45.30",4.666,7.596667,
"45.45",4.684,7.621666,
"45.60",4.704,7.646667,
"45.75",4.722,7.671667,
"45.90",4.74,7.696667,
"46.05",4.76,7.722,
"46.20",4.78,7.746666,
"46.35",4.798,7.772,
"46.50",4.816,7.796667,
"46.65",4.835,7.821667,
"46.80",4.854,7.846667,
"46.95",4.874,7.871666,
"47.10",4.891,7.896667,
"47.25",4.907,7.921667,
"47.40",4.927,7.946667,
"47.55",4.946,7.971667,
"47.70",4.965,7.996666,
"47.85",4.985,8.021667,
"48.00",5.003,8.046667,
"48.15",5.022,8.071667,
"48.30",5.039,8.096666,
"48.45",5.058,8.121667,
"48.60",5.081,8.147,
"48.75",5.099,8.172,
"48.90",5.117,8.196667,
"49.05",5.137,8.221666,
"49.20",5.154,8.246667,
"49.35",5.172,8.271667,
"49.50",5.192,8.296667,
"49.65",5.209,8.321667,
"49.80",5.228,8.346666,
"49.95",5.248,8.371667,
"50.10",5.267,8.396667,
"50.25",5.285,8.421667,
"50.40",5.304,8.446667,
"50.55",5.321,8.472,
"50.70",5.343,8.496667,
"50.85",5.361,8.521667,
"51.00",5.379,8.546667,
"51.15",5.396,8.571667,
"51.30",5.411,8.597,
"51.45",5.229,8.622,
"51.60",4.94,8.647,
"51.75",4.962,8.671667,
"51.90",4.994,8.696667,
"52.05",5.026,8.721666,
"52.20",5.058,8.746667,
"52.35",5.09,8.772,
"52.50",5.126,8.796667,
"52.65",5.159,8.821667,
"52.80",5.192,8.846666,
"52.95",5.225,8.872,
"53.10",5.254,8.897,
"53.25",5.286,8.922,
"53.40",5.319,8.947,
"53.55",5.348,8.972,
"53.70",5.378,8.996667,
"53.85",5.402,9.022,
"54.00",5.431,9.047,
"54.15",5.459,9.071667,
"54.30",5.484,9.096666,
"54.45",5.509,9.121667,
"54.60",5.535,9.146667,
"54.75",5.558,9.171667,
"54.90",5.583,9.196667,
"55.05",5.607,9.221666,
"55.20",5.628,9.246667,
"55.35",5.651,9.272,
"55.50",5.672,9.297,
"55.65",5.696,9.321667,
"55.80",5.717,9.346666,
"55.95",5.738,9.371667,
"56.10",5.757,9.397,
"56.25",5.776,9.422,
"56.40",5.798,9.447,
"56.55",5.816,9.472,
"56.70",5.839,9.496667,
"56.85",5.857,9.522,
"57.00",5.874,9.546667,
"57.15",5.891,9.571667,
"57.30",5.91,9.596666,
"57.45",5.934,9.622,
"57.60",5.953,9.646667,
"57.75",5.971,9.671667,
"57.90",5.992,9.696667,
"58.05",6.008,9.722,
"58.20",6.029,9.747,
"58.35",6.048,9.772,
"58.50",6.065,9.797,
"58.65",6.09,9.821667,
"58.80",6.109,9.846666,
"58.95",6.128,9.871667,
"59.10",6.145,9.897,
"59.25",6.165,9.922,
"59.40",6.183,9.947,
"59.55",6.201,9.971666,
"59.70",6.22,9.996667,
"59.85",6.242,10.02167,
"60.00",6.259,10.04667,
"60.15",6.278,10.07167,
"60.30",6.296,10.097,
"60.45",6.314,10.122,
"60.60",6.333,10.14667,
"60.75",6.348,10.17167,
"60.90",6.368,10.19667,
"61.05",6.385,10.22167,
"61.20",6.404,10.24667,
"61.35",6.422,10.27167,
"61.50",6.436,10.297,
"61.65",6.455,10.32167,
"61.80",6.477,10.34667,
"61.95",6.493,10.37167,
"62.10",6.51,10.39667,
"62.25",6.526,10.42167,
"62.40",6.545,10.447,
"62.55",6.559,10.47167,
"62.70",6.575,10.497,
"62.85",6.59,10.52167,
"63.00",6.609,10.54667,
"63.15",6.628,10.57167,
"63.30",6.647,10.597,
"63.45",6.665,10.622,
"63.60",6.689,10.647,
"63.75",6.71,10.67167,
"63.90",6.731,10.69667,
"64.05",6.75,10.722,
"64.20",6.771,10.747,
"64.35",6.789,10.772,
"64.50",6.813,10.797,
"64.65",6.836,10.82167,
"64.80",6.856,10.84667,
"64.95",6.875,10.87167,
"65.10",6.893,10.897,
"65.25",6.914,10.92167,
"65.40",6.935,10.94667,
"65.55",6.958,10.97167,
"65.70",6.98,10.99667,
"65.85",6.999,11.02167,
"66.00",7.023,11.04667,
"66.15",7.043,11.07167,
"66.30",7.064,11.09667,
"66.45",7.084,11.12167,
"66.60",7.108,11.14667,
"66.75",7.131,11.17167,
"66.90",7.153,11.19667,
"67.05",7.175,11.22167,
"67.20",7.198,11.24667,
"67.35",7.216,11.27167,
"67.50",7.237,11.29667,
"67.65",7.26,11.32167,
"67.80",7.283,11.347,
"67.95",7.309,11.37167,
"68.10",7.329,11.397,
"68.25",7.352,11.42167,
"68.40",7.374,11.447,
"68.55",7.397,11.472,
"68.70",7.418,11.49667,
"68.85",7.441,11.52167,
"69.00",7.464,11.54667,
"69.15",7.485,11.57167,
"69.30",7.508,11.59667,
"69.45",7.533,11.62167,
"69.60",7.556,11.64667,
"69.75",7.58,11.67167,
"69.90",7.598,11.69667,
"70.05",7.619,11.72167,
"70.20",7.639,11.74667,
"70.35",7.659,11.77167,
"70.50",7.684,11.79667,
"70.65",7.709,11.82167,
"70.80",7.733,11.84667,
"70.95",7.755,11.87133,
"71.10",7.777,11.89633,
"71.25",7.799,11.92167,
"71.40",7.823,11.94667,
"71.55",7.848,11.97167,
"71.70",7.868,11.99667,
"71.85",7.89,12.02167,
"72.00",7.915,12.04667,
"72.15",7.936,12.07167,
"72.30",7.958,12.09667,
"72.45",7.982,12.12167,
"72.60",8.004,12.14667,
"72.75",8.027,12.17167,
"72.90",8.048,12.19667,
"73.05",8.068,12.22167,
"73.20",8.089,12.24667,
"73.35",8.111,12.27167,
"73.50",8.131,12.29667,
"73.65",8.155,12.32167,
"73.80",8.178,12.34667,
"73.95",8.198,12.37167,
"74.10",8.216,12.39667,
"74.25",8.236,12.42167,
"74.40",8.257,12.44667,
"74.55",8.278,12.47167,
"74.70",8.299,12.49633,
"74.85",8.321,12.52167,
"75.00",8.342,12.54667,
"75.15",8.365,12.57167,
"75.30",8.385,12.59667,
"75.45",8.408,12.622,
"75.60",8.43,12.64667,
"75.75",8.451,12.67167,
"75.90",8.474,12.69667,
"76.05",8.497,12.72167,
"76.20",8.517,12.74667,
"76.35",8.539,12.77167,
"76.50",8.565,12.79667,
"76.65",8.591,12.82167,
"76.80",8.615,12.84667,
"76.95",8.638,12.87167,
"77.10",8.66,12.89667,
"77.25",8.683,12.92167,
"77.40",8.705,12.94667,
"77.55",8.726,12.97167,
"77.70",8.749,12.99667,
"77.85",8.772,13.02167,
"78.00",8.792,13.04667,
"78.15",8.813,13.07167,
"78.30",8.836,13.097,
"78.45",8.862,13.12167,
"78.60",8.888,13.14667,
"78.75",8.911,13.17167,
"78.90",8.933,13.19667,
"79.05",8.955,13.222,
"79.20",8.98,13.24667,
"79.35",9.001,13.272,
"79.50",9.026,13.297,
"79.65",9.049,13.32167,
"79.80",9.077,13.34667,
"79.95",9.102,13.37167,
"80.10",9.122,13.397,
"80.25",9.146,13.42167,
"80.40",9.169,13.44667,
"80.55",9.195,13.47167,
"80.70",9.222,13.497,
"80.85",9.248,13.52167,
"81.00",9.271,13.54667,
"81.15",9.296,13.57167,
"81.30",9.318,13.59667,
"81.45",9.342,13.62167,
"81.60",9.367,13.64667,
"81.75",9.394,13.67167,
"81.90",9.421,13.69667,
"82.05",9.447,13.72167,
"82.20",9.472,13.74667,
"82.35",9.498,13.77167,
"82.50",9.521,13.79667,
"82.65",9.547,13.82167,
"82.80",9.575,13.84667,
"82.95",9.601,13.87167,
"83.10",9.627,13.89667,
"83.25",9.652,13.92167,
"83.40",9.679,13.947,
"83.55",9.704,13.972,
"83.70",9.731,13.997,
"83.85",9.757,14.022,
"84.00",9.784,14.047,
"84.15",9.808,14.072,
"84.30",9.833,14.097,
"84.45",9.862,14.122,
"84.60",9.884,14.147,
"84.75",9.91,14.172,
"84.90",9.934,14.197,
"85.05",9.957,14.222,
"85.20",9.979,14.247,
"85.35",10.001,14.272,
"85.50",10.027,14.297,
"85.65",10.054,14.322,
"85.80",10.081,14.347,
"85.95",10.106,14.372,
"86.10",10.129,14.397,
"86.25",10.153,14.42167,
"86.40",10.176,14.44667,
"86.55",10.199,14.472,
"86.70",10.223,14.497,
"86.85",10.245,14.522,
"87.00",10.266,14.54667,
"87.15",10.288,14.57167,
"87.30",10.307,14.59667,
"87.45",10.333,14.62167,
"87.60",10.359,14.647,
"87.75",10.389,14.67167,
"87.90",10.416,14.697,
"88.05",10.444,14.722,
"88.20",10.473,14.747,
"88.35",10.502,14.772,
"88.50",10.532,14.79667,
"88.65",10.562,14.82167,
"88.80",10.588,14.847,
"88.95",10.62,14.87167,
"89.10",10.649,14.89667,
"89.25",10.678,14.92167,
"89.40",10.707,14.947,
"89.55",10.737,14.972,
"89.70",10.766,14.99667,
"89.85",10.8,15.022,
"90.00",10.828,15.047,
"90.15",10.856,15.07167,
"90.30",10.886,15.09667,
"90.45",10.913,15.12167,
"90.60",10.943,15.14667,
"90.75",10.974,15.17167,
"90.90",11.002,15.197,
"91.05",11.028,15.22167,
"91.20",11.059,15.24667,
"91.35",11.087,15.272,
"91.50",11.116,15.297,
"91.65",11.146,15.322,
"91.80",11.177,15.347,
"91.95",11.205,15.372,
"92.10",11.234,15.397,
"92.25",11.26,15.42167,
"92.40",11.29,15.44667,
"92.55",11.322,15.472,
"92.70",11.351,15.49667,
"92.85",11.379,15.522,
"93.00",11.404,15.54667,
"93.15",11.434,15.572,
"93.30",11.463,15.597,
"93.45",11.493,15.622,
"93.60",11.523,15.647,
"93.75",11.553,15.67167,
"93.90",11.582,15.69667,
"94.05",11.61,15.72167,
"94.20",11.634,15.74667,
"94.35",11.664,15.772,
"94.50",11.691,15.797,
"94.65",11.721,15.822,
"94.80",11.749,15.847,
"94.95",11.779,15.872,
"95.10",11.801,15.897,
"95.25",11.823,15.922,
"95.40",11.846,15.947,
"95.55",11.87,15.972,
"95.70",11.887,15.99667,
"95.85",11.875,16.02167,
"96.00",11.275,16.04667,
"96.15",11.016,16.07167,
"96.30",11.015,16.097,
"96.45",11.04,16.122,
"96.60",11.078,16.14667,
"96.75",11.12,16.17167,
"96.90",11.161,16.19667,
"97.05",11.202,16.22167,
"97.20",11.25,16.24667,
"97.35",11.293,16.272,
"97.50",11.342,16.297,
"97.65",11.388,16.32167,
"97.80",11.435,16.347,
"97.95",11.481,16.37167,
"98.10",11.527,16.39667,
"98.25",11.57,16.42167,
"98.40",11.614,16.447,
"98.55",11.66,16.472,
"98.70",11.705,16.49667,
"98.85",11.747,16.52167,
"99.00",11.784,16.54667,
"99.15",11.823,16.57167,
"99.30",11.862,16.59667,
"99.45",11.902,16.62167,
"99.60",11.942,16.647,
"99.75",11.983,16.67167,
"99.90",12.022,16.69667,
"100.05",12.058,16.72167,
"100.20",12.09,16.74667,
"100.35",12.124,16.772,
"100.50",12.162,16.797,
"100.65",12.197,16.82167,
"100.80",12.234,16.84667,
"100.95",12.265,16.872,
"101.10",12.297,16.897,
"101.25",12.33,16.922,
"101.40",12.362,16.947,
"101.55",12.393,16.97167,
"101.70",12.426,16.99667,
"101.85",12.459,17.02167,
"102.00",12.489,17.047,
"102.15",12.521,17.072,
"102.30",12.549,17.097,
"102.45",12.577,17.122,
"102.60",12.61,17.147,
"102.75",12.636,17.172,
"102.90",12.668,17.197,
"103.05",12.698,17.222,
"103.20",12.723,17.247,
"103.35",12.754,17.272,
"103.50",12.782,17.297,
"103.65",12.813,17.32167,
"103.80",12.843,17.347,
"103.95",12.87,17.37167,
"104.10",12.896,17.397,
"104.25",12.925,17.42167,
"104.40",12.954,17.447,
"104.55",12.985,17.472,
"104.70",13.016,17.49667,
"104.85",13.045,17.522,
"105.00",13.072,17.547,
"105.15",13.096,17.572,
"105.30",13.128,17.59667,
"105.45",13.155,17.62167,
"105.60",13.186,17.64667,
"105.75",13.218,17.67167,
"105.90",13.251,17.69667,
"106.05",13.279,17.72167,
"106.20",13.31,17.74667,
"106.35",13.34,17.77167,
"106.50",13.373,17.79667,
"106.65",13.404,17.82167,
"106.80",13.437,17.84667,
"106.95",13.469,17.87167,
"107.10",13.5,17.89667,
"107.25",13.527,17.92167,
"107.40",13.559,17.94667,
"107.55",13.591,17.97167,
"107.70",13.623,17.99667,
"107.85",13.654,18.02167,
"108.00",13.683,18.04667,
"108.15",13.711,18.07167,
"108.30",13.741,18.097,
"108.45",13.774,18.122,
"108.60",13.805,18.147,
"108.75",13.839,18.17167,
"108.90",13.87,18.197,
"109.05",13.898,18.22167,
"109.20",13.925,18.24667,
"109.35",13.957,18.272,
"109.50",13.988,18.297,
"109.65",14.019,18.32167,
"109.80",14.053,18.34667,
"109.95",14.084,18.37167,
"110.10",14.112,18.39667,
"110.25",14.138,18.42167,
"110.40",14.169,18.447,
"110.55",14.203,18.47167,
"110.70",14.235,18.49667,
"110.85",14.267,18.52167,
"111.00",14.297,18.54667,
"111.15",14.325,18.57167,
"111.30",14.354,18.59667,
"111.45",14.385,18.62167,
"111.60",14.416,18.647,
"111.75",14.448,18.67167,
"111.90",14.477,18.69667,
"112.05",14.506,18.72167,
"112.20",14.534,18.747,
"112.35",14.561,18.772,
"112.50",14.593,18.797,
"112.65",14.624,18.82167,
"112.80",14.654,18.847,
"112.95",14.687,18.87167,
"113.10",14.716,18.897,
"113.25",14.746,18.922,
"113.40",14.778,18.947,
"113.55",14.81,18.972,
"113.70",14.844,18.99667,
"113.85",14.871,19.022,
"114.00",14.902,19.04667,
"114.15",14.932,19.072,
"114.30",14.966,19.09667,
"114.45",14.997,19.12167,
"114.60",15.032,19.14667,
"114.75",15.064,19.17167,
"114.90",15.096,19.197,
"115.05",15.127,19.222,
"115.20",15.157,19.247,
"115.35",15.192,19.272,
"115.50",15.225,19.29667,
"115.65",15.259,19.32167,
"115.80",15.295,19.34667,
"115.95",15.327,19.37167,
"116.10",15.358,19.397,
"116.25",15.386,19.42167,
"116.40",15.419,19.44667,
"116.55",15.455,19.47167,
"116.70",15.486,19.49667,
"116.85",15.52,19.522,
"117.00",15.554,19.54667,
"117.15",15.588,19.572,
"117.30",15.62,19.597,
"117.45",15.65,19.62167,
"117.60",15.681,19.64667,
"117.75",15.714,19.67167,
"117.90",15.746,19.69667,
"118.05",15.777,19.722,
"118.20",15.807,19.747,
"118.35",15.837,19.772,
"118.50",15.868,19.797,
"118.65",15.899,19.822,
"118.80",15.931,19.847,
"118.95",15.962,19.872,
"119.10",15.99,19.897,
"119.25",16.021,19.922,
"119.40",16.051,19.947,
"119.55",16.085,19.972,
"119.70",16.117,19.99667,
"119.85",16.146,20.022,
"120.00",16.177,20.04667,
"120.15",16.204,20.07167,
"120.30",16.235,20.09667,
"120.45",16.268,20.12167,
"120.60",16.303,20.14667,
"120.75",16.335,20.17167,
"120.90",16.37,20.19667,
"121.05",16.398,20.22167,
"121.20",16.429,20.24667,
"121.35",16.457,20.27167,
"121.50",16.491,20.29667,
"121.65",16.526,20.32167,
"121.80",16.558,20.347,
"121.95",16.59,20.372,
"122.10",16.622,20.397,
"122.25",16.65,20.42167,
"122.40",16.684,20.44667,
"122.55",16.715,20.472,
"122.70",16.746,20.497,
"122.85",16.779,20.522,
"123.00",16.812,20.54667,
"123.15",16.842,20.57167,
"123.30",16.87,20.59667,
"123.45",16.902,20.62167,
"123.60",16.937,20.647,
"123.75",16.973,20.672,
"123.90",17.004,20.69667,
"124.05",17.034,20.722,
"124.20",17.065,20.74667,
"124.35",17.096,20.772,
"124.50",17.13,20.79667,
"124.65",17.164,20.82167,
"124.80",17.194,20.847,
"124.95",17.228,20.872,
"125.10",17.259,20.897,
"125.25",17.29,20.92167,
"125.40",17.319,20.94667,
"125.55",17.352,20.97167,
"125.70",17.389,20.99667,
"125.85",17.422,21.02167,
"126.00",17.454,21.04667,
"126.15",17.483,21.07167,
"126.30",17.516,21.09667,
"126.45",17.551,21.12167,
"126.60",17.581,21.14667,
"126.75",17.617,21.17167,
"126.90",17.651,21.19667,
"127.05",17.681,21.222,
"127.20",17.712,21.24667,
"127.35",17.741,21.272,
"127.50",17.774,21.297,
"127.65",17.809,21.32167,
"127.80",17.844,21.347,
"127.95",17.874,21.372,
"128.10",17.903,21.397,
"128.25",17.93,21.42167,
"128.40",17.963,21.44667,
"128.55",17.994,21.47167,
"128.70",18.031,21.49667,
"128.85",18.063,21.52167,
"129.00",18.089,21.54667,
"129.15",18.12,21.57167,
"129.30",18.152,21.59667,
"129.45",18.182,21.62167,
"129.60",18.215,21.64667,
"129.75",18.248,21.67167,
"129.90",18.281,21.69667,
"130.05",18.308,21.72167,
"130.20",18.338,21.74667,
"130.35",18.367,21.77167,
"130.50",18.401,21.79667,
"130.65",18.435,21.82167,
"130.80",18.469,21.84667,
"130.95",18.5,21.87167,
"131.10",18.532,21.89667,
"131.25",18.563,21.92167,
"131.40",18.592,21.94667,
"131.55",18.619,21.97167,
"131.70",18.651,21.99667,
"131.85",18.686,22.02167,
"132.00",18.716,22.04667,
"132.15",18.743,22.072,
"132.30",18.775,22.097,
"132.45",18.805,22.122,
"132.60",18.836,22.14667,
"132.75",18.868,22.17167,
"132.90",18.896,22.19667,
"133.05",18.925,22.22167,
"133.20",18.956,22.24667,
"133.35",18.985,22.27167,
"133.50",19.015,22.29667,
"133.65",19.047,22.32167,
"133.80",19.08,22.34667,
"133.95",19.114,22.37167,
"134.10",19.141,22.39667,
"134.25",19.17,22.42167,
"134.40",19.196,22.44667,
"134.55",19.228,22.47167,
"134.70",19.26,22.49667,
"134.85",19.291,22.52167,
"135.00",19.319,22.54667,
"135.15",19.349,22.57167,
"135.30",19.377,22.59667,
"135.45",19.406,22.62167,
"135.60",19.436,22.64667,
"135.75",19.472,22.67167,
"135.90",19.504,22.69667,
"136.05",19.533,22.72167,
"136.20",19.561,22.74667,
"136.35",19.589,22.77167,
"136.50",19.621,22.79667,
"136.65",19.651,22.82167,
"136.80",19.686,22.84667,
"136.95",19.716,22.87167,
"137.10",19.748,22.89667,
"137.25",19.773,22.92167,
"137.40",19.802,22.94667,
"137.55",19.834,22.97167,
"137.70",19.857,22.99667,
"137.85",19.888,23.02167,
"138.00",19.92,23.04667,
"138.15",19.95,23.07167,
"138.30",19.977,23.09667,
"138.45",20.009,23.12167,
"138.60",20.039,23.14667,
"138.75",20.07,23.17167,
"138.90",20.101,23.19667,
"139.05",20.128,23.22167,
"139.20",20.157,23.24667,
"139.35",20.183,23.27167,
"139.50",20.215,23.29667,
"139.65",20.243,23.32167,
"139.80",20.274,23.34667,
"139.95",20.303,23.37167,
"140.10",20.331,23.39667,
"140.25",20.356,23.42167,
"140.40",20.385,23.447,
"140.55",20.415,23.472,
"140.70",20.446,23.49667,
"140.85",20.474,23.522,
"141.00",20.503,23.547,
"141.15",20.527,23.572,
"141.30",20.554,23.59667,
"141.45",20.582,23.622,
"141.60",20.61,23.64667,
"141.75",20.639,23.67167,
"141.90",20.668,23.69667,
"142.05",20.692,23.72167,
"142.20",20.718,23.74667,
"142.35",20.746,23.772,
"142.50",20.77,23.79667,
"142.65",20.799,23.82167,
"142.80",20.829,23.84667,
"142.95",20.859,23.87167,
"143.10",20.882,23.89667,
"143.25",20.909,23.92167,
"143.40",20.934,23.947,
"143.55",20.961,23.972,
"143.70",20.993,23.997,
"143.85",21.019,24.022,
"144.00",21.044,24.04667,
"144.15",21.068,24.07167,
"144.30",21.093,24.097,
"144.45",21.119,24.122,
"144.60",21.144,24.14667,
"144.75",21.172,24.17167,
"144.90",21.202,24.197,
"145.05",21.226,24.222,
"145.20",21.25,24.247,
"145.35",21.272,24.272,
"145.50",21.298,24.29667,
"145.65",21.324,24.32167,
"145.80",21.352,24.34667,
"145.95",21.378,24.37167,
"146.10",21.403,24.39667,
"146.25",21.425,24.42167,
"146.40",21.45,24.447,
"146.55",21.477,24.47167,
"146.70",21.501,24.49667,
"146.85",21.526,24.52167,
"147.00",21.549,24.54667,
"147.15",21.571,24.57167,
"147.30",21.594,24.59667,
"147.45",21.618,24.62167,
"147.60",21.643,24.64667,
"147.75",21.669,24.67167,
"147.90",21.693,24.69667,
"148.05",21.716,24.722,
"148.20",21.738,24.747,
"148.35",21.764,24.772,
"148.50",21.785,24.797,
"148.65",21.81,24.82167,
"148.80",21.837,24.847,
"148.95",21.859,24.872,
"149.10",21.879,24.897,
"149.25",21.9,24.922,
"149.40",21.925,24.947,
"149.55",21.944,24.972,
"149.70",21.971,24.99667,
"149.85",21.993,25.022,
"150.00",22.016,25.04667,
"150.15",22.035,25.07167,
"150.30",22.053,25.09667,
"150.45",22.077,25.12167,
"150.60",22.101,25.14667,
"150.75",22.128,25.17167,
"150.90",22.149,25.19667,
"151.05",22.17,25.22167,
"151.20",22.19,25.24667,
"151.35",22.211,25.27167,
"151.50",22.231,25.29667,
"151.65",22.257,25.32167,
"151.80",22.286,25.34667,
"151.95",22.306,25.37167,
"152.10",22.326,25.39667,
"152.25",22.347,25.42167,
"152.40",22.369,25.44667,
"152.55",22.391,25.47167,
"152.70",22.413,25.49667,
"152.85",22.437,25.52167,
"153.00",22.459,25.54667,
"153.15",22.48,25.57167,
"153.30",22.501,25.59667,
"153.45",22.523,25.62167,
"153.60",22.544,25.64667,
"153.75",22.568,25.67167,
"153.90",22.588,25.697,
"154.05",22.609,25.72167,
"154.20",22.629,25.74667,
"154.35",22.651,25.77167,
"154.50",22.67,25.79667,
"154.65",22.693,25.82167,
"154.80",22.716,25.84667,
"154.95",22.734,25.87167,
"155.10",22.751,25.89667,
"155.25",22.771,25.92167,
"155.40",22.79,25.94667,
"155.55",22.815,25.972,
"155.70",22.838,25.997,
"155.85",22.857,26.022,
"156.00",22.875,26.047,
"156.15",22.895,26.072,
"156.30",22.915,26.097,
"156.45",22.933,26.122,
"156.60",22.955,26.147,
"156.75",22.975,26.17167,
"156.90",22.999,26.197,
"157.05",23.02,26.22167,
"157.20",23.039,26.24667,
"157.35",23.056,26.272,
"157.50",23.075,26.29667,
"157.65",23.097,26.32167,
"157.80",23.118,26.34667,
"157.95",23.134,26.37167,
"158.10",23.156,26.397,
"158.25",23.175,26.42167,
"158.40",23.196,26.44667,
"158.55",23.216,26.47167,
"158.70",23.239,26.49667,
"158.85",23.258,26.52167,
"159.00",23.274,26.54667,
"159.15",23.295,26.57167,
"159.30",23.311,26.59667,
"159.45",23.334,26.622,
"159.60",23.356,26.64667,
"159.75",23.376,26.67167,
"159.90",23.394,26.697,
"160.05",23.413,26.722,
"160.20",23.429,26.74667,
"160.35",23.443,26.77167,
"160.50",23.464,26.79667,
"160.65",23.486,26.82167,
"160.80",23.506,26.847,
"160.95",23.524,26.87167,
"161.10",23.538,26.897,
"161.25",23.551,26.92167,
"161.35",23.556,26.93833,