File: exposed_monofilament_10cm_10mmpm_24nm_250esh_12.csv
"Test Name","Test Mode","Test Type","Control","Test Speed 1","Test Speed 2","Test Speed 3","Change Point 1","Change Point 2","Disp. Origin","Break and Limit Action","Sensitivity:","Level:"
"","Single","Tensile","Stroke",10,1,1,"Off","Off","Start","Stop",0,1

"Title","Sub title","Comment"
"","",""

"Shape:","Batch Size:","SubBatch Size:"
"Plate",1,1
"Name:","Thickness","Width","Gauge Length",
"Size Unit:","mm","mm","mm",
" 1 - 1","1.0000","1.0000","100.0000",

"Name",
"Parameter",
"Units",
" 1 - 1",

" 1- 1"
"Time","Force","Stroke",
"sec","N","mm",
"0.00",.002,0,
"0.20",.003,.037,
"0.40",.012,.074,
"0.60",.026,.111,
"0.80",.04,.1483333,
"1.00",.056,.1853333,
"1.20",.07,.2223333,
"1.40",.084,.2593333,
"1.60",.098,.2966667,
"1.80",.113,.3336667,
"2.00",.127,.3703333,
"2.20",.14,.406,
"2.40",.157,.4416667,
"2.60",.169,.4763333,
"2.80",.181,.5113333,
"3.00",.195,.5456666,
"3.20",.209,.58,
"3.40",.221,.614,
"3.60",.234,.648,
"3.80",.245,.682,
"4.00",.258,.7156667,
"4.20",.274,.7493333,
"4.40",.288,.783,
"4.60",.298,.8163333,
"4.80",.313,.85,
"5.00",.327,.8833333,
"5.20",.339,.917,
"5.40",.351,.9503333,
"5.60",.361,.9836667,
"5.80",.377,1.017,
"6.00",.391,1.050667,
"6.20",.408,1.083667,
"6.40",.42,1.117,
"6.60",.431,1.150667,
"6.80",.447,1.184,
"7.00",.458,1.217333,
"7.20",.472,1.250667,
"7.40",.486,1.284,
"7.60",.499,1.317333,
"7.80",.512,1.350667,
"8.00",.528,1.384,
"8.20",.543,1.417333,
"8.40",.554,1.450667,
"8.60",.568,1.484,
"8.80",.582,1.517333,
"9.00",.597,1.550667,
"9.20",.611,1.584,
"9.40",.626,1.617333,
"9.60",.638,1.650667,
"9.80",.653,1.684,
"10.00",.671,1.717333,
"10.20",.684,1.750667,
"10.40",.696,1.783667,
"10.60",.708,1.817333,
"10.80",.724,1.850667,
"11.00",.739,1.884,
"11.20",.754,1.917333,
"11.40",.769,1.950667,
"11.60",.782,1.984,
"11.80",.797,2.017667,
"12.00",.813,2.050667,
"12.20",.828,2.084,
"12.40",.844,2.117333,
"12.60",.859,2.150667,
"12.80",.872,2.184,
"13.00",.887,2.217333,
"13.20",.901,2.250667,
"13.40",.919,2.284,
"13.60",.935,2.317667,
"13.80",.951,2.350667,
"14.00",.967,2.384,
"14.20",.984,2.417333,
"14.40",.998,2.450667,
"14.60",1.014,2.484,
"14.80",1.027,2.517333,
"15.00",1.043,2.550667,
"15.20",1.061,2.584,
"15.40",1.074,2.617333,
"15.60",1.092,2.650667,
"15.80",1.109,2.684,
"16.00",1.125,2.717667,
"16.20",1.142,2.751,
"16.40",1.161,2.784333,
"16.60",1.177,2.817667,
"16.80",1.192,2.851,
"17.00",1.21,2.884,
"17.20",1.226,2.917667,
"17.40",1.244,2.950667,
"17.60",1.262,2.984,
"17.80",1.279,3.017667,
"18.00",1.295,3.051,
"18.20",1.313,3.084,
"18.40",1.333,3.117333,
"18.60",1.349,3.151,
"18.80",1.368,3.184333,
"19.00",1.388,3.217333,
"19.20",1.406,3.250667,
"19.40",1.423,3.284333,
"19.60",1.441,3.317667,
"19.80",1.46,3.351,
"20.00",1.478,3.384,
"20.20",1.497,3.417333,
"20.40",1.516,3.450667,
"20.60",1.535,3.484,
"20.80",1.554,3.517333,
"21.00",1.575,3.550667,
"21.20",1.592,3.584333,
"21.40",1.612,3.617666,
"21.60",1.634,3.651,
"21.80",1.65,3.684,
"22.00",1.671,3.717333,
"22.20",1.693,3.751,
"22.40",1.712,3.784,
"22.60",1.732,3.817333,
"22.80",1.752,3.850667,
"23.00",1.773,3.884,
"23.20",1.791,3.917333,
"23.40",1.814,3.950667,
"23.60",1.836,3.984,
"23.80",1.857,4.017667,
"24.00",1.879,4.050667,
"24.20",1.9,4.084,
"24.40",1.919,4.117333,
"24.60",1.945,4.150667,
"24.80",1.967,4.184,
"25.00",1.988,4.217667,
"25.20",2.012,4.250667,
"25.40",2.033,4.284,
"25.60",2.055,4.317334,
"25.80",2.077,4.350667,
"26.00",2.103,4.384,
"26.20",2.125,4.417334,
"26.40",2.149,4.451,
"26.60",2.174,4.484334,
"26.80",2.195,4.517667,
"27.00",2.221,4.550667,
"27.20",2.249,4.584,
"27.40",2.273,4.617333,
"27.60",2.294,4.650667,
"27.80",2.319,4.684,
"28.00",2.346,4.717333,
"28.20",2.37,4.750667,
"28.40",2.395,4.784,
"28.60",2.42,4.817334,
"28.80",2.446,4.850667,
"29.00",2.47,4.884,
"29.20",2.495,4.917667,
"29.40",2.521,4.951,
"29.60",2.549,4.984,
"29.80",2.574,5.017334,
"30.00",2.6,5.050667,
"30.20",2.627,5.084,
"30.40",2.652,5.117333,
"30.60",2.679,5.150667,
"30.80",2.705,5.184,
"31.00",2.735,5.217333,
"31.20",2.759,5.250667,
"31.40",2.79,5.284334,
"31.60",2.817,5.317667,
"31.80",2.846,5.351,
"32.00",2.872,5.384334,
"32.20",2.903,5.417334,
"32.40",2.931,5.450667,
"32.60",2.958,5.484334,
"32.80",2.985,5.517334,
"33.00",3.018,5.550667,
"33.20",3.043,5.584,
"33.40",3.073,5.617333,
"33.60",3.102,5.650667,
"33.80",3.133,5.684,
"34.00",3.163,5.717333,
"34.20",3.194,5.750667,
"34.40",3.218,5.784,
"34.60",3.246,5.817334,
"34.80",3.268,5.850667,
"35.00",3.295,5.884,
"35.20",3.327,5.917334,
"35.40",3.351,5.950667,
"35.60",3.357,5.984,
"35.80",3.355,6.017334,
"36.00",3.386,6.050667,
"36.20",3.42,6.084,
"36.40",3.455,6.117333,
"36.60",3.489,6.150667,
"36.80",3.521,6.184,
"37.00",3.551,6.217333,
"37.20",3.579,6.250667,
"37.40",3.613,6.284,
"37.60",3.642,6.317334,
"37.80",3.676,6.350667,
"38.00",3.708,6.384,
"38.20",3.737,6.417667,
"38.40",3.764,6.451,
"38.60",3.796,6.484,
"38.80",3.83,6.517667,
"39.00",3.865,6.550667,
"39.20",3.896,6.584,
"39.40",3.93,6.617667,
"39.60",3.964,6.651,
"39.80",3.997,6.684333,
"40.00",4.033,6.717333,
"40.20",4.067,6.750667,
"40.40",4.099,6.784,
"40.60",4.133,6.817334,
"40.80",4.166,6.850667,
"41.00",4.199,6.884,
"41.20",4.235,6.917667,
"41.40",4.268,6.950667,
"41.60",4.302,6.984,
"41.80",4.34,7.017334,
"42.00",4.372,7.050667,
"42.20",4.41,7.084,
"42.40",4.444,7.117333,
"42.60",4.474,7.150667,
"42.80",4.51,7.184,
"43.00",4.545,7.217333,
"43.20",4.577,7.250667,
"43.40",4.61,7.284,
"43.60",4.644,7.317334,
"43.80",4.674,7.350667,
"44.00",4.709,7.384334,
"44.20",4.74,7.417334,
"44.40",4.773,7.450667,
"44.60",4.807,7.484,
"44.80",4.839,7.517334,
"45.00",4.871,7.550667,
"45.20",4.906,7.584,
"45.40",4.939,7.617333,
"45.60",4.972,7.650667,
"45.80",5.004,7.684,
"46.00",5.037,7.717333,
"46.20",5.072,7.751,
"46.40",5.104,7.784,
"46.60",5.137,7.817334,
"46.80",5.17,7.850667,
"47.00",5.201,7.884,
"47.20",5.239,7.917334,
"47.40",5.269,7.950667,
"47.60",5.302,7.984,
"47.80",5.336,8.017333,
"48.00",5.368,8.050667,
"48.20",5.4,8.084,
"48.40",5.434,8.117333,
"48.60",5.466,8.150666,
"48.80",5.498,8.184,
"49.00",5.533,8.217333,
"49.20",5.567,8.250667,
"49.40",5.597,8.283999,
"49.60",5.627,8.317333,
"49.80",5.662,8.350666,
"50.00",5.694,8.384,
"50.20",5.726,8.417333,
"50.40",5.758,8.450666,
"50.60",5.79,8.483999,
"50.80",5.821,8.517333,
"51.00",5.853,8.550667,
"51.20",5.884,8.584,
"51.40",5.917,8.617333,
"51.60",5.947,8.650666,
"51.80",5.979,8.684,
"52.00",6.009,8.717333,
"52.20",6.043,8.750667,
"52.40",6.072,8.783999,
"52.60",6.103,8.817333,
"52.80",6.134,8.850666,
"53.00",6.165,8.884,
"53.20",6.198,8.917333,
"53.40",6.229,8.950666,
"53.60",6.26,8.983999,
"53.80",6.291,9.017333,
"54.00",6.324,9.050667,
"54.20",6.352,9.084,
"54.40",6.38,9.117333,
"54.60",6.411,9.150666,
"54.80",6.443,9.184,
"55.00",6.475,9.217333,
"55.20",6.504,9.250667,
"55.40",6.534,9.283999,
"55.60",6.562,9.317333,
"55.80",6.59,9.350666,
"56.00",6.623,9.384,
"56.20",6.654,9.417333,
"56.40",6.683,9.450666,
"56.60",6.709,9.483999,
"56.80",6.74,9.517333,
"57.00",6.769,9.550667,
"57.20",6.802,9.584,
"57.40",6.827,9.617333,
"57.60",6.853,9.650666,
"57.80",6.882,9.684,
"58.00",6.911,9.717333,
"58.20",6.941,9.750667,
"58.40",6.968,9.783999,
"58.60",6.996,9.817333,
"58.80",7.023,9.850666,
"59.00",7.048,9.883666,
"59.20",7.076,9.917333,
"59.40",7.104,9.950666,
"59.60",7.128,9.983999,
"59.80",7.156,10.01733,
"60.00",7.184,10.05067,
"60.20",7.205,10.084,
"60.40",7.226,10.11733,
"60.60",7.245,10.15067,
"60.80",7.265,10.184,
"61.00",7.287,10.21733,
"61.20",7.308,10.25067,
"61.40",7.328,10.284,
"61.60",7.348,10.31733,
"61.80",7.373,10.35067,
"62.00",7.4,10.384,
"62.20",7.424,10.41733,
"62.40",7.448,10.45067,
"62.60",7.474,10.48367,
"62.80",7.502,10.517,
"63.00",7.529,10.55033,
"63.20",7.556,10.58367,
"63.40",7.586,10.617,
"63.60",7.612,10.65067,
"63.80",7.643,10.684,
"64.00",7.668,10.717,
"64.20",7.699,10.75067,
"64.40",7.727,10.784,
"64.60",7.752,10.81733,
"64.80",7.779,10.85067,
"65.00",7.808,10.884,
"65.20",7.837,10.91733,
"65.40",7.863,10.95067,
"65.60",7.89,10.984,
"65.80",7.917,11.01733,
"66.00",7.945,11.05067,
"66.20",7.974,11.084,
"66.40",8.003,11.11733,
"66.60",8.028,11.15067,
"66.80",8.052,11.184,
"67.00",8.079,11.21733,
"67.20",8.104,11.25067,
"67.40",8.129,11.284,
"67.60",8.154,11.31733,
"67.80",8.18,11.35067,
"68.00",8.204,11.384,
"68.20",8.233,11.41733,
"68.40",8.255,11.45067,
"68.60",8.28,11.48433,
"68.80",8.306,11.51767,
"69.00",8.331,11.55067,
"69.20",8.354,11.584,
"69.40",8.376,11.61767,
"69.60",8.402,11.651,
"69.80",8.426,11.68433,
"70.00",8.449,11.71733,
"70.20",8.474,11.75067,
"70.40",8.494,11.784,
"70.60",8.517,11.81733,
"70.80",8.54,11.85067,
"71.00",8.565,11.884,
"71.20",8.588,11.91733,
"71.40",8.609,11.95067,
"71.60",8.629,11.984,
"71.80",8.65,12.01733,
"72.00",8.672,12.05067,
"72.20",8.695,12.084,
"72.40",8.715,12.11733,
"72.60",8.733,12.15067,
"72.80",8.752,12.184,
"73.00",8.775,12.21733,
"73.20",8.8,12.25067,
"73.40",8.819,12.284,
"73.60",8.843,12.31733,
"73.80",8.866,12.35067,
"74.00",8.887,12.384,
"74.20",8.912,12.41733,
"74.40",8.935,12.45067,
"74.60",8.958,12.484,
"74.80",8.98,12.51733,
"75.00",9.006,12.55067,
"75.20",9.029,12.584,
"75.40",9.05,12.61733,
"75.60",9.07,12.65067,
"75.80",9.091,12.684,
"76.00",9.116,12.71733,
"76.20",9.142,12.75067,
"76.40",9.164,12.784,
"76.60",9.187,12.81733,
"76.80",9.209,12.85067,
"77.00",9.237,12.884,
"77.20",9.261,12.91733,
"77.40",9.285,12.95067,
"77.60",9.305,12.984,
"77.80",9.326,13.01733,
"78.00",9.349,13.05067,
"78.20",9.373,13.084,
"78.40",9.397,13.11733,
"78.60",9.421,13.15067,
"78.80",9.442,13.184,
"79.00",9.464,13.21733,
"79.20",9.487,13.25067,
"79.40",9.508,13.284,
"79.60",9.532,13.31733,
"79.80",9.557,13.35067,
"80.00",9.584,13.384,
"80.20",9.603,13.41733,
"80.40",9.625,13.45067,
"80.60",9.645,13.484,
"80.80",9.667,13.51733,
"81.00",9.69,13.55067,
"81.20",9.714,13.584,
"81.40",9.734,13.61733,
"81.60",9.754,13.65067,
"81.80",9.776,13.684,
"82.00",9.8,13.71733,
"82.20",9.824,13.75067,
"82.40",9.845,13.784,
"82.60",9.867,13.81733,
"82.80",9.886,13.85067,
"83.00",9.911,13.884,
"83.20",9.935,13.91733,
"83.40",9.956,13.95067,
"83.60",9.979,13.984,
"83.80",10.001,14.01733,
"84.00",10.021,14.05067,
"84.20",10.045,14.084,
"84.40",10.064,14.11733,
"84.60",10.083,14.15067,
"84.80",10.105,14.184,
"85.00",10.128,14.217,
"85.20",10.151,14.25067,
"85.40",10.168,14.284,
"85.60",10.186,14.317,
"85.80",10.209,14.35067,
"86.00",10.23,14.384,
"86.20",10.255,14.41733,
"86.40",10.275,14.45067,
"86.60",10.292,14.484,
"86.80",10.309,14.51733,
"87.00",10.329,14.55033,
"87.20",10.35,14.584,
"87.40",10.37,14.61733,
"87.60",10.387,14.65067,
"87.80",10.408,14.684,
"88.00",10.429,14.71733,
"88.20",10.446,14.75067,
"88.40",10.468,14.784,
"88.60",10.484,14.81733,
"88.80",10.501,14.85067,
"89.00",10.521,14.884,
"89.20",10.54,14.91733,
"89.40",10.56,14.95067,
"89.60",10.576,14.984,
"89.80",10.598,15.01733,
"90.00",10.622,15.05067,
"90.20",10.642,15.084,
"90.40",10.661,15.11733,
"90.60",10.679,15.15033,
"90.80",10.699,15.184,
"91.00",10.723,15.217,
"91.20",10.743,15.25067,
"91.40",10.764,15.284,
"91.60",10.784,15.31733,
"91.80",10.803,15.35067,
"92.00",10.823,15.38367,
"92.20",10.844,15.417,
"92.40",10.861,15.45033,
"92.60",10.878,15.48367,
"92.80",10.892,15.51733,
"93.00",10.907,15.55033,
"93.20",10.922,15.58367,
"93.40",10.932,15.61733,
"93.60",10.94,15.65033,
"93.80",10.948,15.684,
"94.00",10.954,15.717,
"94.20",10.948,15.75067,
"94.40",10.925,15.78367,
"94.60",10.861,15.817,
"94.80",10.768,15.85033,
"95.00",10.744,15.88367,
"95.20",10.747,15.91733,
"95.40",10.764,15.95067,
"95.60",10.782,15.984,
"95.80",10.805,16.01733,
"96.00",10.828,16.05067,
"96.20",10.849,16.084,
"96.40",10.864,16.11733,
"96.60",10.878,16.15067,
"96.80",10.895,16.184,
"97.00",10.914,16.217,
"97.20",10.931,16.25067,
"97.40",10.952,16.284,
"97.60",10.975,16.317,
"97.80",11.002,16.35067,
"98.00",11.03,16.384,
"98.20",11.064,16.417,
"98.40",11.092,16.45067,
"98.60",11.119,16.484,
"98.80",11.148,16.51733,
"99.00",11.18,16.55067,
"99.20",11.206,16.584,
"99.40",11.234,16.617,
"99.60",11.259,16.65067,
"99.80",11.286,16.684,
"100.00",11.317,16.71733,
"100.20",11.342,16.75067,
"100.40",11.364,16.784,
"100.60",11.385,16.81733,
"100.80",11.407,16.85033,
"101.00",11.43,16.884,
"101.20",11.449,16.91733,
"101.40",11.468,16.95033,
"101.60",11.481,16.984,
"101.80",11.499,17.01733,
"102.00",11.516,17.05067,
"102.20",11.529,17.08367,
"102.40",11.545,17.117,
"102.60",11.561,17.15067,
"102.80",11.574,17.184,
"103.00",11.59,17.217,
"103.20",11.603,17.25067,
"103.40",11.616,17.284,
"103.60",11.63,17.31733,
"103.80",11.648,17.35067,
"104.00",11.664,17.384,
"104.20",11.681,17.41733,
"104.40",11.695,17.45033,
"104.60",11.709,17.48367,
"104.80",11.728,17.51733,
"105.00",11.748,17.55033,
"105.20",11.761,17.584,
"105.40",11.777,17.61733,
"105.60",11.791,17.65067,
"105.80",11.809,17.684,
"106.00",11.827,17.71733,
"106.20",11.845,17.75033,
"106.40",11.862,17.78367,
"106.60",11.878,17.81733,
"106.80",11.894,17.85033,
"107.00",11.912,17.88367,
"107.20",11.93,17.917,
"107.40",11.948,17.95067,
"107.60",11.962,17.984,
"107.80",11.979,18.01733,
"108.00",11.997,18.05033,
"108.20",12.012,18.084,
"108.40",12.028,18.11733,
"108.60",12.044,18.15067,
"108.80",12.06,18.184,
"109.00",12.076,18.21733,
"109.20",12.093,18.25067,
"109.40",12.107,18.284,
"109.60",12.119,18.31733,
"109.80",12.136,18.35067,
"110.00",12.151,18.384,
"110.20",12.167,18.41733,
"110.40",12.179,18.45067,
"110.60",12.191,18.484,
"110.80",12.205,18.51733,
"111.00",12.224,18.55067,
"111.20",12.242,18.584,
"111.40",12.258,18.61733,
"111.60",12.273,18.65067,
"111.80",12.289,18.684,
"112.00",12.305,18.71733,
"112.20",12.323,18.75067,
"112.40",12.339,18.784,
"112.60",12.354,18.81733,
"112.80",12.371,18.85067,
"113.00",12.387,18.884,
"113.20",12.404,18.91733,
"113.40",12.42,18.95067,
"113.60",12.435,18.984,
"113.80",12.45,19.01733,
"114.00",12.469,19.05067,
"114.20",12.485,19.084,
"114.40",12.5,19.11733,
"114.60",12.516,19.15067,
"114.80",12.529,19.184,
"115.00",12.549,19.21733,
"115.20",12.564,19.25067,
"115.40",12.578,19.284,
"115.60",12.59,19.31767,
"115.80",12.605,19.351,
"116.00",12.623,19.384,
"116.20",12.637,19.41733,
"116.40",12.651,19.45067,
"116.60",12.664,19.48433,
"116.80",12.679,19.51733,
"117.00",12.694,19.55067,
"117.20",12.71,19.584,
"117.40",12.721,19.61733,
"117.60",12.734,19.65067,
"117.80",12.751,19.684,
"118.00",12.766,19.71733,
"118.20",12.78,19.75067,
"118.40",12.792,19.784,
"118.60",12.805,19.81733,
"118.80",12.818,19.85067,
"119.00",12.832,19.884,
"119.20",12.844,19.91733,
"119.40",12.853,19.95067,
"119.60",12.863,19.984,
"119.80",12.874,20.01733,
"120.00",12.889,20.05033,
"120.20",12.9,20.084,
"120.40",12.91,20.11733,
"120.60",12.922,20.15067,
"120.80",12.932,20.184,
"121.00",12.947,20.21733,
"121.20",12.963,20.25067,
"121.40",12.975,20.284,
"121.60",12.984,20.31733,
"121.80",12.998,20.351,
"122.00",13.014,20.384,
"122.20",13.028,20.41733,
"122.40",13.042,20.45067,
"122.60",13.053,20.48433,
"122.80",13.067,20.51733,
"123.00",13.084,20.55067,
"123.20",13.099,20.584,
"123.40",13.115,20.61733,
"123.60",13.127,20.65067,
"123.80",13.143,20.684,
"124.00",13.16,20.71733,
"124.20",13.176,20.75067,
"124.40",13.19,20.784,
"124.60",13.206,20.81733,
"124.80",13.22,20.85067,
"125.00",13.236,20.884,
"125.20",13.252,20.91733,
"125.40",13.269,20.95067,
"125.60",13.282,20.984,
"125.80",13.299,21.01733,
"126.00",13.319,21.05033,
"126.20",13.338,21.084,
"126.40",13.357,21.11733,
"126.60",13.372,21.15067,
"126.80",13.389,21.184,
"127.00",13.407,21.21733,
"127.20",13.425,21.25067,
"127.40",13.442,21.284,
"127.60",13.454,21.31733,
"127.80",13.469,21.35067,
"128.00",13.484,21.384,
"128.20",13.5,21.41733,
"128.40",13.513,21.45067,
"128.60",13.524,21.484,
"128.80",13.536,21.51733,
"129.00",13.552,21.55067,
"129.20",13.563,21.584,
"129.40",13.576,21.61733,
"129.60",13.592,21.65033,
"129.80",13.606,21.68367,
"130.00",13.626,21.717,
"130.20",13.644,21.75033,
"130.40",13.66,21.78367,
"130.60",13.673,21.81733,
"130.80",13.691,21.85067,
"131.00",13.708,21.88367,
"131.20",13.726,21.917,
"131.40",13.739,21.95067,
"131.60",13.75,21.984,
"131.80",13.765,22.01733,
"132.00",13.782,22.05033,
"132.20",13.793,22.08367,
"132.40",13.808,22.11733,
"132.60",13.82,22.15033,
"132.80",13.834,22.184,
"133.00",13.849,22.217,
"133.20",13.861,22.25033,
"133.40",13.876,22.28367,
"133.60",13.889,22.317,
"133.80",13.903,22.35033,
"134.00",13.921,22.38367,
"134.20",13.934,22.417,
"134.40",13.946,22.45033,
"134.60",13.958,22.48367,
"134.80",13.971,22.517,
"135.00",13.987,22.55033,
"135.20",13.999,22.584,
"135.40",14.012,22.617,
"135.60",14.022,22.65033,
"135.80",14.035,22.68367,
"136.00",14.049,22.71733,
"136.20",14.062,22.75067,
"136.40",14.074,22.784,
"136.60",14.084,22.81733,
"136.80",14.093,22.85067,
"137.00",14.106,22.884,
"137.20",14.123,22.91733,
"137.40",14.136,22.95067,
"137.60",14.147,22.984,
"137.80",14.154,23.01733,
"138.00",14.169,23.05033,
"138.20",14.183,23.084,
"138.40",14.194,23.11733,
"138.60",14.206,23.15067,
"138.80",14.217,23.184,
"139.00",14.234,23.21733,
"139.20",14.25,23.25067,
"139.40",14.261,23.284,
"139.60",14.272,23.31733,
"139.80",14.285,23.35067,
"140.00",14.303,23.384,
"140.20",14.319,23.41733,
"140.40",14.331,23.45067,
"140.60",14.344,23.484,
"140.80",14.356,23.51733,
"141.00",14.374,23.55067,
"141.20",14.391,23.584,
"141.40",14.405,23.61733,
"141.60",14.419,23.65067,
"141.80",14.432,23.68367,
"142.00",14.448,23.717,
"142.20",14.467,23.75067,
"142.40",14.481,23.784,
"142.60",14.495,23.81733,
"142.80",14.51,23.85067,
"143.00",14.528,23.884,
"143.20",14.545,23.91733,
"143.40",14.559,23.95067,
"143.60",14.573,23.984,
"143.80",14.587,24.01767,
"144.00",14.602,24.05067,
"144.20",14.617,24.084,
"144.40",14.625,24.11733,
"144.60",14.638,24.15067,
"144.80",14.653,24.184,
"145.00",14.667,24.21733,
"145.20",14.681,24.25067,
"145.40",14.694,24.284,
"145.60",14.707,24.31733,
"145.80",14.721,24.35067,
"146.00",14.739,24.384,
"146.20",14.754,24.41733,
"146.40",14.767,24.45067,
"146.60",14.778,24.484,
"146.80",14.787,24.51733,
"147.00",14.8,24.55033,
"147.20",14.817,24.584,
"147.40",14.831,24.61733,
"147.60",14.841,24.65067,
"147.80",14.854,24.684,
"148.00",14.867,24.71733,
"148.20",14.881,24.75067,
"148.40",14.895,24.784,
"148.60",14.909,24.81733,
"148.80",14.926,24.85067,
"149.00",14.941,24.884,
"149.20",14.956,24.91733,
"149.40",14.968,24.95067,
"149.60",14.979,24.984,
"149.80",14.993,25.01733,
"150.00",15.01,25.05067,
"150.20",15.023,25.084,
"150.40",15.033,25.11733,
"150.60",15.042,25.15067,
"150.80",15.053,25.184,
"151.00",15.067,25.21733,
"151.20",15.079,25.251,
"151.40",15.089,25.284,
"151.60",15.099,25.31733,
"151.80",15.11,25.35067,
"152.00",15.123,25.384,
"152.20",15.138,25.41733,
"152.40",15.15,25.45067,
"152.60",15.162,25.484,
"152.80",15.173,25.51733,
"153.00",15.186,25.55067,
"153.20",15.199,25.584,
"153.40",15.213,25.61733,
"153.60",15.227,25.65067,
"153.80",15.24,25.684,
"154.00",15.256,25.71733,
"154.20",15.269,25.75067,
"154.40",15.279,25.784,
"154.60",15.293,25.81733,
"154.80",15.303,25.85067,
"155.00",15.312,25.884,
"155.20",15.325,25.91733,
"155.40",15.336,25.95067,
"155.60",15.347,25.984,
"155.80",15.356,26.01733,
"156.00",15.369,26.05067,
"156.20",15.384,26.084,
"156.40",15.395,26.11733,
"156.60",15.401,26.15067,
"156.80",15.412,26.184,
"157.00",15.426,26.217,
"157.20",15.436,26.25067,
"157.40",15.448,26.284,
"157.60",15.458,26.31733,
"157.80",15.467,26.35067,
"158.00",15.474,26.38367,
"158.20",15.484,26.417,
"158.40",15.493,26.45067,
"158.60",15.505,26.484,
"158.80",15.515,26.51733,
"159.00",15.527,26.55033,
"159.20",15.536,26.584,
"159.40",15.545,26.61733,
"159.60",15.556,26.65067,
"159.80",15.571,26.684,
"160.00",15.586,26.71733,
"160.20",15.599,26.75067,
"160.40",15.609,26.784,
"160.60",15.62,26.81733,
"160.80",15.629,26.85067,
"161.00",15.644,26.884,
"161.20",15.654,26.91733,
"161.40",15.667,26.95067,
"161.60",15.673,26.984,
"161.80",15.684,27.01767,
"162.00",15.698,27.05067,
"162.20",15.714,27.084,
"162.40",15.725,27.11733,
"162.60",15.734,27.15067,
"162.80",15.742,27.184,
"163.00",15.756,27.21767,
"163.20",15.77,27.251,
"163.40",15.78,27.284,
"163.60",15.789,27.31733,
"163.80",15.799,27.35067,
"164.00",15.809,27.38367,
"164.20",15.821,27.41733,
"164.40",15.83,27.45067,
"164.60",15.837,27.484,
"164.80",15.844,27.51733,
"165.00",15.852,27.55033,
"165.20",15.859,27.584,
"165.40",15.866,27.61733,
"165.60",15.87,27.65067,
"165.80",15.879,27.684,
"166.00",15.89,27.717,
"166.20",15.906,27.75067,
"166.40",15.916,27.78367,
"166.60",15.925,27.817,
"166.80",15.935,27.85033,
"167.00",15.947,27.88367,
"167.20",15.96,27.91733,
"167.40",15.971,27.95067,
"167.60",15.982,27.984,
"167.80",15.99,28.01733,
"168.00",16.003,28.05067,
"168.20",16.014,28.084,
"168.40",16.025,28.11733,
"168.60",16.034,28.15067,
"168.80",16.042,28.184,
"169.00",16.057,28.21733,
"169.20",16.068,28.25067,
"169.40",16.079,28.284,
"169.60",16.09,28.31733,
"169.80",16.104,28.35067,
"170.00",16.12,28.384,
"170.20",16.128,28.41733,
"170.40",16.139,28.45067,
"170.60",16.144,28.484,
"170.80",16.156,28.51733,
"171.00",16.171,28.55067,
"171.20",16.182,28.58433,
"171.40",16.192,28.61767,
"171.60",16.199,28.651,
"171.80",16.209,28.68433,
"172.00",16.222,28.71767,
"172.20",16.232,28.75067,
"172.40",16.244,28.784,
"172.60",16.255,28.81733,
"172.80",16.268,28.85067,
"173.00",16.276,28.884,
"173.20",16.287,28.91733,
"173.40",16.299,28.951,
"173.60",16.31,28.984,
"173.80",16.32,29.01733,
"174.00",16.331,29.05067,
"174.20",16.338,29.084,
"174.40",16.348,29.11733,
"174.60",16.357,29.15067,
"174.80",16.37,29.184,
"175.00",16.383,29.21733,
"175.20",16.395,29.25067,
"175.40",16.407,29.284,
"175.60",16.418,29.31733,
"175.80",16.432,29.35067,
"176.00",16.447,29.384,
"176.20",16.463,29.41733,
"176.40",16.474,29.45067,
"176.60",16.481,29.484,
"176.80",16.492,29.51733,
"177.00",16.507,29.55067,
"177.20",16.52,29.584,
"177.40",16.532,29.61733,
"177.60",16.545,29.65067,
"177.80",16.554,29.684,
"178.00",16.566,29.71733,
"178.20",16.581,29.75067,
"178.40",16.587,29.784,
"178.60",16.596,29.81733,
"178.80",16.611,29.85067,
"179.00",16.617,29.884,
"179.20",16.627,29.91767,
"179.40",16.636,29.951,
"179.60",16.642,29.984,
"179.80",16.649,30.01733,
"180.00",16.658,30.05067,
"180.20",16.666,30.084,
"180.40",16.669,30.11733,
"180.60",16.672,30.15067,
"180.80",16.677,30.184,
"181.00",16.686,30.21733,
"181.20",16.698,30.25067,
"181.40",16.705,30.284,
"181.60",16.712,30.31733,
"181.80",16.719,30.351,
"182.00",16.729,30.38433,
"182.20",16.744,30.41767,
"182.40",16.751,30.45067,
"182.60",16.759,30.484,
"182.80",16.769,30.51733,
"183.00",16.778,30.55067,
"183.20",16.787,30.584,
"183.40",16.798,30.61733,
"183.60",16.806,30.65067,
"183.80",16.817,30.684,
"184.00",16.828,30.71733,
"184.20",16.837,30.75067,
"184.40",16.845,30.784,
"184.60",16.854,30.81733,
"184.80",16.864,30.85067,
"185.00",16.874,30.884,
"185.20",16.884,30.91733,
"185.40",16.895,30.95067,
"185.60",16.904,30.984,
"185.80",16.916,31.01733,
"186.00",16.93,31.05033,
"186.20",16.941,31.08367,
"186.40",16.949,31.117,
"186.60",16.958,31.15033,
"186.80",16.969,31.18367,
"187.00",16.984,31.217,
"187.20",16.995,31.25033,
"187.40",17,31.284,
"187.60",17.006,31.317,
"187.80",17.014,31.35033,
"188.00",17.024,31.384,
"188.20",17.034,31.41733,
"188.40",17.039,31.45067,
"188.60",17.043,31.484,
"188.80",17.051,31.51733,
"189.00",17.059,31.55067,
"189.20",17.067,31.584,
"189.40",17.07,31.61733,
"189.60",17.074,31.65067,
"189.80",17.081,31.684,
"190.00",17.088,31.71733,
"190.20",17.094,31.75067,
"190.40",17.101,31.784,
"190.60",17.104,31.81733,
"190.80",17.112,31.85067,
"191.00",17.119,31.884,
"191.20",17.129,31.91733,
"191.40",17.138,31.95067,
"191.60",17.144,31.984,
"191.80",17.152,32.01733,
"192.00",17.163,32.05067,
"192.20",17.171,32.084,
"192.40",17.181,32.11733,
"192.60",17.187,32.15067,
"192.80",17.193,32.184,
"193.00",17.201,32.21733,
"193.20",17.211,32.25066,
"193.40",17.216,32.284,
"193.60",17.221,32.31733,
"193.80",17.229,32.35067,
"194.00",17.237,32.384,
"194.20",17.245,32.41733,
"194.40",17.252,32.45066,
"194.60",17.259,32.484,
"194.80",17.265,32.51733,
"195.00",17.275,32.55067,
"195.20",17.283,32.584,
"195.40",17.292,32.61733,
"195.60",17.298,32.65067,
"195.80",17.307,32.684,
"196.00",17.316,32.71733,
"196.20",17.326,32.75066,
"196.40",17.333,32.784,
"196.60",17.34,32.81733,
"196.80",17.344,32.85067,
"197.00",17.357,32.884,
"197.20",17.371,32.91733,
"197.40",17.381,32.951,
"197.60",17.392,32.98433,
"197.80",17.405,33.01733,
"198.00",17.419,33.05067,
"198.20",17.43,33.084,
"198.40",17.44,33.11733,
"198.60",17.452,33.15067,
"198.80",17.462,33.184,
"199.00",17.473,33.21733,
"199.20",17.486,33.251,
"199.40",17.496,33.284,
"199.60",17.506,33.31733,
"199.80",17.518,33.351,
"200.00",17.533,33.38433,
"200.20",17.543,33.41766,
"200.40",17.551,33.451,
"200.60",17.56,33.48433,
"200.80",17.572,33.51733,
"201.00",17.586,33.55067,
"201.20",17.597,33.584,
"201.40",17.608,33.61766,
"201.60",17.616,33.651,
"201.80",17.627,33.68433,
"202.00",17.639,33.71733,
"202.20",17.65,33.75066,
"202.40",17.663,33.784,
"202.60",17.671,33.81733,
"202.80",17.679,33.85067,
"203.00",17.69,33.884,
"203.20",17.699,33.91766,
"203.40",17.709,33.951,
"203.60",17.717,33.984,
"203.80",17.721,34.01733,
"204.00",17.733,34.05067,
"204.20",17.739,34.084,
"204.40",17.744,34.11733,
"204.60",17.75,34.15067,
"204.80",17.757,34.184,
"205.00",17.768,34.21733,
"205.20",17.778,34.25066,
"205.40",17.784,34.284,
"205.60",17.791,34.31733,
"205.80",17.8,34.35067,
"206.00",17.813,34.384,
"206.20",17.823,34.41733,
"206.40",17.832,34.45066,
"206.60",17.839,34.484,
"206.80",17.847,34.51733,
"207.00",17.86,34.55067,
"207.20",17.87,34.584,
"207.40",17.873,34.61733,
"207.60",17.877,34.65067,
"207.80",17.882,34.684,
"208.00",17.889,34.71733,
"208.20",17.896,34.75066,
"208.40",17.902,34.784,
"208.60",17.905,34.81733,
"208.80",17.913,34.85067,
"209.00",17.921,34.884,
"209.20",17.93,34.91733,
"209.40",17.933,34.95066,
"209.60",17.938,34.984,
"209.80",17.945,35.01733,
"210.00",17.957,35.05067,
"210.20",17.961,35.084,
"210.40",17.966,35.11733,
"210.60",17.97,35.15067,
"210.80",17.972,35.184,
"211.00",17.979,35.21733,
"211.20",17.982,35.25066,
"211.40",17.981,35.284,
"211.60",17.986,35.31733,
"211.80",17.988,35.35067,
"212.00",17.992,35.384,
"212.20",17.995,35.41733,
"212.40",17.999,35.45066,
"212.60",18,35.484,
"212.80",18.003,35.51733,
"213.00",18.005,35.55067,
"213.20",18.011,35.584,
"213.40",18.015,35.61733,
"213.60",18.02,35.65067,
"213.80",18.025,35.684,
"214.00",18.033,35.71733,
"214.20",18.039,35.75066,
"214.40",18.043,35.784,
"214.60",18.05,35.81733,
"214.80",18.056,35.85067,
"215.00",18.066,35.884,
"215.20",18.072,35.91733,
"215.40",18.074,35.95066,
"215.60",18.076,35.984,
"215.80",18.081,36.01733,
"216.00",18.089,36.05067,
"216.20",18.093,36.084,
"216.40",18.096,36.11733,
"216.60",18.096,36.15067,
"216.80",18.098,36.184,
"217.00",18.106,36.21733,
"217.20",18.114,36.25066,
"217.40",18.116,36.284,
"217.60",18.123,36.31733,
"217.80",18.129,36.35067,
"218.00",18.139,36.384,
"218.20",18.152,36.41733,
"218.40",18.159,36.45066,
"218.60",18.167,36.484,
"218.80",18.177,36.51733,
"219.00",18.189,36.55067,
"219.20",18.195,36.584,
"219.40",18.201,36.61733,
"219.60",18.206,36.65067,
"219.80",18.213,36.684,
"220.00",18.22,36.71733,
"220.20",18.226,36.75066,
"220.40",18.231,36.784,
"220.60",18.24,36.81767,
"220.80",18.252,36.851,
"221.00",18.263,36.88433,
"221.20",18.274,36.91766,
"221.40",18.288,36.951,
"221.60",18.3,36.98433,
"221.80",18.314,37.01733,
"222.00",18.331,37.05067,
"222.20",18.344,37.084,
"222.40",18.364,37.11733,
"222.60",18.38,37.15067,
"222.80",18.394,37.184,
"223.00",18.411,37.21733,
"223.20",18.424,37.25066,
"223.40",18.438,37.284,
"223.60",18.451,37.31733,
"223.80",18.46,37.35067,
"224.00",18.472,37.384,
"224.20",18.485,37.41733,
"224.40",18.492,37.45066,
"224.60",18.5,37.484,
"224.80",18.511,37.51733,
"225.00",18.519,37.55067,
"225.20",18.525,37.584,
"225.40",18.525,37.61733,
"225.60",18.526,37.65067,
"225.80",18.528,37.68433,
"226.00",18.535,37.71733,
"226.20",18.539,37.75066,
"226.40",18.543,37.784,
"226.60",18.544,37.81733,
"226.80",18.547,37.85067,
"227.00",18.55,37.884,
"227.20",18.553,37.91733,
"227.40",18.555,37.951,
"227.60",18.554,37.984,
"227.80",18.553,38.01733,
"228.00",18.555,38.05067,
"228.20",18.557,38.084,
"228.40",18.554,38.11733,
"228.60",18.551,38.15067,
"228.80",18.551,38.184,
"229.00",18.557,38.21733,
"229.20",18.559,38.25066,
"229.40",18.563,38.284,
"229.60",18.565,38.31733,
"229.80",18.573,38.35067,
"230.00",18.575,38.384,
"230.20",18.582,38.41733,
"230.40",18.588,38.45066,
"230.60",18.595,38.484,
"230.80",18.603,38.51733,
"231.00",18.613,38.55067,
"231.20",18.625,38.584,
"231.40",18.632,38.61733,
"231.60",18.634,38.65067,
"231.80",18.641,38.684,
"232.00",18.652,38.717,
"232.20",18.659,38.75033,
"232.40",18.664,38.78366,
"232.60",18.66,38.81733,