File: exposed_monofilament_10cm_10mmpm_24nm_250esh_9.csv
"Test Name","Test Mode","Test Type","Control","Test Speed 1","Test Speed 2","Test Speed 3","Change Point 1","Change Point 2","Disp. Origin","Break and Limit Action","Sensitivity:","Level:"
"","Single","Tensile","Stroke",10,1,1,"Off","Off","Start","Stop",0,1

"Title","Sub title","Comment"
"","",""

"Shape:","Batch Size:","SubBatch Size:"
"Plate",1,1
"Name:","Thickness","Width","Gauge Length",
"Size Unit:","mm","mm","mm",
" 1 - 1","1.0000","1.0000","100.0000",

"Name",
"Parameter",
"Units",
" 1 - 1",

" 1- 1"
"Time","Force","Stroke",
"sec","N","mm",
"0.00",.001,0,
"0.20",.002,3.733334E-02,
"0.40",.015,7.433333E-02,
"0.60",.031,.1116667,
"0.80",.044,.1486667,
"1.00",.058,.1856667,
"1.20",.073,.223,
"1.40",.082,.26,
"1.60",.094,.297,
"1.80",.109,.334,
"2.00",.123,.3706667,
"2.20",.138,.4066667,
"2.40",.15,.4423333,
"2.60",.166,.4773333,
"2.80",.177,.512,
"3.00",.19,.5466667,
"3.20",.201,.581,
"3.40",.216,.615,
"3.60",.228,.649,
"3.80",.238,.683,
"4.00",.252,.7166667,
"4.20",.264,.7503334,
"4.40",.278,.784,
"4.60",.289,.8173333,
"4.80",.301,.851,
"5.00",.314,.8846667,
"5.20",.325,.918,
"5.40",.339,.9513333,
"5.60",.351,.9846667,
"5.80",.364,1.018333,
"6.00",.377,1.051667,
"6.20",.388,1.085,
"6.40",.402,1.118333,
"6.60",.415,1.151667,
"6.80",.426,1.185,
"7.00",.437,1.218333,
"7.20",.452,1.251667,
"7.40",.465,1.285,
"7.60",.474,1.318333,
"7.80",.49,1.351667,
"8.00",.501,1.385,
"8.20",.515,1.418333,
"8.40",.53,1.451667,
"8.60",.539,1.485,
"8.80",.552,1.518333,
"9.00",.568,1.551667,
"9.20",.578,1.585,
"9.40",.591,1.618333,
"9.60",.603,1.651667,
"9.80",.615,1.685,
"10.00",.629,1.718333,
"10.20",.641,1.751667,
"10.40",.656,1.785,
"10.60",.669,1.818333,
"10.80",.681,1.851667,
"11.00",.694,1.885,
"11.20",.707,1.918333,
"11.40",.721,1.951667,
"11.60",.735,1.985,
"11.80",.747,2.018333,
"12.00",.76,2.051667,
"12.20",.774,2.085,
"12.40",.788,2.118333,
"12.60",.8,2.151667,
"12.80",.814,2.185,
"13.00",.825,2.218333,
"13.20",.838,2.251667,
"13.40",.853,2.285,
"13.60",.867,2.318333,
"13.80",.88,2.351667,
"14.00",.892,2.385,
"14.20",.909,2.418333,
"14.40",.92,2.451667,
"14.60",.937,2.485,
"14.80",.948,2.518333,
"15.00",.962,2.551667,
"15.20",.978,2.585,
"15.40",.992,2.618333,
"15.60",1.006,2.651667,
"15.80",1.019,2.685,
"16.00",1.034,2.718667,
"16.20",1.049,2.751667,
"16.40",1.065,2.785333,
"16.60",1.078,2.818333,
"16.80",1.093,2.851667,
"17.00",1.107,2.885,
"17.20",1.122,2.918333,
"17.40",1.135,2.951667,
"17.60",1.149,2.985,
"17.80",1.165,3.018333,
"18.00",1.178,3.051667,
"18.20",1.195,3.085,
"18.40",1.212,3.118333,
"18.60",1.228,3.151667,
"18.80",1.242,3.185,
"19.00",1.256,3.218333,
"19.20",1.272,3.251667,
"19.40",1.289,3.285,
"19.60",1.301,3.318333,
"19.80",1.319,3.351667,
"20.00",1.334,3.385,
"20.20",1.351,3.418333,
"20.40",1.366,3.451667,
"20.60",1.384,3.485,
"20.80",1.399,3.518333,
"21.00",1.414,3.551667,
"21.20",1.431,3.585,
"21.40",1.451,3.618333,
"21.60",1.465,3.651667,
"21.80",1.483,3.685,
"22.00",1.5,3.718333,
"22.20",1.515,3.751667,
"22.40",1.534,3.785,
"22.60",1.553,3.818333,
"22.80",1.567,3.851667,
"23.00",1.586,3.885,
"23.20",1.603,3.918333,
"23.40",1.624,3.951667,
"23.60",1.638,3.984667,
"23.80",1.656,4.018333,
"24.00",1.673,4.051667,
"24.20",1.694,4.085,
"24.40",1.712,4.118333,
"24.60",1.729,4.151333,
"24.80",1.75,4.185,
"25.00",1.766,4.218333,
"25.20",1.787,4.251667,
"25.40",1.803,4.285,
"25.60",1.824,4.318333,
"25.80",1.843,4.351667,
"26.00",1.86,4.385,
"26.20",1.884,4.418334,
"26.40",1.901,4.451667,
"26.60",1.92,4.485,
"26.80",1.939,4.518333,
"27.00",1.96,4.551667,
"27.20",1.983,4.585,
"27.40",2.003,4.618333,
"27.60",2.021,4.651667,
"27.80",2.042,4.685,
"28.00",2.06,4.718333,
"28.20",2.082,4.751333,
"28.40",2.099,4.785,
"28.60",2.124,4.818,
"28.80",2.144,4.851667,
"29.00",2.167,4.885,
"29.20",2.188,4.918334,
"29.40",2.209,4.951667,
"29.60",2.228,4.985,
"29.80",2.251,5.018333,
"30.00",2.272,5.051667,
"30.20",2.295,5.085,
"30.40",2.315,5.118333,
"30.60",2.341,5.151667,
"30.80",2.362,5.185,
"31.00",2.384,5.218333,
"31.20",2.407,5.251333,
"31.40",2.428,5.285,
"31.60",2.452,5.318333,
"31.80",2.477,5.351667,
"32.00",2.5,5.385,
"32.20",2.525,5.418334,
"32.40",2.547,5.451667,
"32.60",2.569,5.485,
"32.80",2.593,5.518333,
"33.00",2.618,5.551667,
"33.20",2.644,5.585,
"33.40",2.668,5.618333,
"33.60",2.688,5.651667,
"33.80",2.712,5.685,
"34.00",2.738,5.718333,
"34.20",2.763,5.751667,
"34.40",2.787,5.785,
"34.60",2.812,5.818333,
"34.80",2.838,5.851667,
"35.00",2.861,5.885,
"35.20",2.886,5.918334,
"35.40",2.914,5.951667,
"35.60",2.941,5.985,
"35.80",2.963,6.018333,
"36.00",2.99,6.051667,
"36.20",3.017,6.085,
"36.40",3.043,6.118333,
"36.60",3.071,6.151667,
"36.80",3.095,6.185,
"37.00",3.123,6.218333,
"37.20",3.151,6.251667,
"37.40",3.175,6.285,
"37.60",3.203,6.318333,
"37.80",3.23,6.352,
"38.00",3.258,6.385,
"38.20",3.288,6.418667,
"38.40",3.313,6.451667,
"38.60",3.338,6.485,
"38.80",3.371,6.518333,
"39.00",3.394,6.551667,
"39.20",3.423,6.585,
"39.40",3.451,6.618333,
"39.60",3.478,6.651667,
"39.80",3.505,6.685,
"40.00",3.533,6.718333,
"40.20",3.562,6.751667,
"40.40",3.591,6.785,
"40.60",3.618,6.818333,
"40.80",3.644,6.851667,
"41.00",3.672,6.885,
"41.20",3.702,6.918334,
"41.40",3.729,6.951667,
"41.60",3.757,6.985,
"41.80",3.788,7.018333,
"42.00",3.819,7.052,
"42.20",3.847,7.085,
"42.40",3.876,7.118333,
"42.60",3.903,7.151667,
"42.80",3.933,7.185,
"43.00",3.96,7.218333,
"43.20",3.992,7.251667,
"43.40",4.017,7.285,
"43.60",4.047,7.318333,
"43.80",4.074,7.351667,
"44.00",4.105,7.385,
"44.20",4.135,7.418334,
"44.40",4.167,7.451667,
"44.60",4.192,7.485,
"44.80",4.226,7.518667,
"45.00",4.256,7.552,
"45.20",4.285,7.585333,
"45.40",4.318,7.618667,
"45.60",4.346,7.652,
"45.80",4.379,7.685,
"46.00",4.405,7.718333,
"46.20",4.437,7.751667,
"46.40",4.468,7.785,
"46.60",4.497,7.818333,
"46.80",4.528,7.851667,
"47.00",4.559,7.885,
"47.20",4.591,7.918334,
"47.40",4.62,7.951667,
"47.60",4.65,7.985,
"47.80",4.679,8.018332,
"48.00",4.708,8.051666,
"48.20",4.743,8.084999,
"48.40",4.77,8.118333,
"48.60",4.8,8.151667,
"48.80",4.831,8.184999,
"49.00",4.861,8.218333,
"49.20",4.892,8.251666,
"49.40",4.922,8.285,
"49.60",4.954,8.318333,
"49.80",4.983,8.351666,
"50.00",5.012,8.384999,
"50.20",5.044,8.418333,
"50.40",5.074,8.451666,
"50.60",5.103,8.485,
"50.80",5.133,8.518332,
"51.00",5.162,8.551666,
"51.20",5.195,8.584999,
"51.40",5.223,8.618333,
"51.60",5.254,8.651667,
"51.80",5.28,8.684999,
"52.00",5.313,8.718333,
"52.20",5.341,8.751666,
"52.40",5.372,8.785,
"52.60",5.4,8.818333,
"52.80",5.427,8.851666,
"53.00",5.459,8.884999,
"53.20",5.491,8.918333,
"53.40",5.519,8.951666,
"53.60",5.546,8.985,
"53.80",5.574,9.018666,
"54.00",5.604,9.051999,
"54.20",5.634,9.084999,
"54.40",5.663,9.118333,
"54.60",5.692,9.151667,
"54.80",5.718,9.184999,
"55.00",5.747,9.218333,
"55.20",5.775,9.251666,
"55.40",5.806,9.285,
"55.60",5.829,9.318333,
"55.80",5.86,9.351666,
"56.00",5.888,9.385333,
"56.20",5.915,9.418333,
"56.40",5.942,9.451666,
"56.60",5.972,9.485,
"56.80",5.998,9.518332,
"57.00",6.028,9.551999,
"57.20",6.056,9.584999,
"57.40",6.084,9.618667,
"57.60",6.108,9.651999,
"57.80",6.134,9.685333,
"58.00",6.163,9.718333,
"58.20",6.189,9.751666,
"58.40",6.217,9.785,
"58.60",6.244,9.818333,
"58.80",6.271,9.851666,
"59.00",6.298,9.885333,
"59.20",6.326,9.918333,
"59.40",6.352,9.952,
"59.60",6.379,9.985,
"59.80",6.406,10.01867,
"60.00",6.434,10.052,
"60.20",6.462,10.085,
"60.40",6.488,10.11833,
"60.60",6.511,10.15167,
"60.80",6.539,10.185,
"61.00",6.566,10.21833,
"61.20",6.592,10.25167,
"61.40",6.616,10.285,
"61.60",6.643,10.31833,
"61.80",6.669,10.35167,
"62.00",6.696,10.38533,
"62.20",6.722,10.41833,
"62.40",6.745,10.45167,
"62.60",6.772,10.485,
"62.80",6.799,10.51833,
"63.00",6.822,10.55167,
"63.20",6.852,10.585,
"63.40",6.878,10.61833,
"63.60",6.902,10.65167,
"63.80",6.928,10.68533,
"64.00",6.953,10.71833,
"64.20",6.979,10.75167,
"64.40",7.004,10.785,
"64.60",7.03,10.81833,
"64.80",7.052,10.85167,
"65.00",7.079,10.885,
"65.20",7.105,10.918,
"65.40",7.129,10.95167,
"65.60",7.153,10.985,
"65.80",7.179,11.01833,
"66.00",7.201,11.05167,
"66.20",7.227,11.085,
"66.40",7.249,11.118,
"66.60",7.275,11.15167,
"66.80",7.3,11.185,
"67.00",7.324,11.21833,
"67.20",7.348,11.25167,
"67.40",7.372,11.285,
"67.60",7.394,11.31833,
"67.80",7.419,11.35167,
"68.00",7.444,11.385,
"68.20",7.471,11.41833,
"68.40",7.49,11.45167,
"68.60",7.514,11.485,
"68.80",7.541,11.51833,
"69.00",7.562,11.55167,
"69.20",7.585,11.585,
"69.40",7.61,11.61833,
"69.60",7.632,11.652,
"69.80",7.654,11.68533,
"70.00",7.679,11.71833,
"70.20",7.702,11.75167,
"70.40",7.725,11.785,
"70.60",7.749,11.81833,
"70.80",7.771,11.85167,
"71.00",7.796,11.88533,
"71.20",7.819,11.91833,
"71.40",7.844,11.952,
"71.60",7.864,11.985,
"71.80",7.889,12.01867,
"72.00",7.913,12.05167,
"72.20",7.934,12.085,
"72.40",7.956,12.11833,
"72.60",7.98,12.15167,
"72.80",8.002,12.185,
"73.00",8.026,12.21833,
"73.20",8.049,12.25167,
"73.40",8.071,12.285,
"73.60",8.094,12.31833,
"73.80",8.111,12.35167,
"74.00",8.135,12.38533,
"74.20",8.159,12.41833,
"74.40",8.179,12.45167,
"74.60",8.203,12.485,
"74.80",8.226,12.51867,
"75.00",8.25,12.55167,
"75.20",8.272,12.585,
"75.40",8.297,12.61833,
"75.60",8.316,12.65167,
"75.80",8.334,12.685,
"76.00",8.355,12.71833,
"76.20",8.383,12.75167,
"76.40",8.405,12.785,
"76.60",8.423,12.81833,
"76.80",8.446,12.85167,
"77.00",8.468,12.885,
"77.20",8.489,12.91833,
"77.40",8.51,12.95167,
"77.60",8.529,12.985,
"77.80",8.554,13.01867,
"78.00",8.578,13.052,
"78.20",8.601,13.085,
"78.40",8.624,13.11833,
"78.60",8.643,13.15167,
"78.80",8.664,13.18533,
"79.00",8.686,13.21867,
"79.20",8.709,13.252,
"79.40",8.73,13.28533,
"79.60",8.751,13.31867,
"79.80",8.77,13.352,
"80.00",8.793,13.385,
"80.20",8.814,13.41833,
"80.40",8.836,13.45167,
"80.60",8.851,13.485,
"80.80",8.873,13.51833,
"81.00",8.893,13.55167,
"81.20",8.917,13.585,
"81.40",8.939,13.61833,
"81.60",8.956,13.65167,
"81.80",8.98,13.685,
"82.00",9,13.71833,
"82.20",9.021,13.75167,
"82.40",9.04,13.785,
"82.60",9.063,13.81833,
"82.80",9.081,13.85167,
"83.00",9.104,13.88533,
"83.20",9.127,13.91833,
"83.40",9.146,13.95167,
"83.60",9.166,13.985,
"83.80",9.185,14.01833,
"84.00",9.206,14.05167,
"84.20",9.228,14.085,
"84.40",9.253,14.11867,
"84.60",9.271,14.15167,
"84.80",9.29,14.185,
"85.00",9.313,14.21867,
"85.20",9.332,14.25167,
"85.40",9.354,14.285,
"85.60",9.373,14.31833,
"85.80",9.393,14.352,
"86.00",9.415,14.38533,
"86.20",9.434,14.41833,
"86.40",9.456,14.45167,
"86.60",9.476,14.485,
"86.80",9.494,14.51833,
"87.00",9.511,14.552,
"87.20",9.536,14.585,
"87.40",9.552,14.61867,
"87.60",9.572,14.652,
"87.80",9.591,14.68533,
"88.00",9.612,14.71867,
"88.20",9.634,14.752,
"88.40",9.653,14.78533,
"88.60",9.669,14.81867,
"88.80",9.691,14.852,
"89.00",9.709,14.88533,
"89.20",9.731,14.91867,
"89.40",9.751,14.952,
"89.60",9.77,14.98533,
"89.80",9.784,15.01833,
"90.00",9.806,15.05167,
"90.20",9.826,15.085,
"90.40",9.845,15.11833,
"90.60",9.862,15.15167,
"90.80",9.879,15.185,
"91.00",9.904,15.21833,
"91.20",9.922,15.25167,
"91.40",9.942,15.28533,
"91.60",9.959,15.31833,
"91.80",9.977,15.352,
"92.00",10.001,15.38533,
"92.20",10.022,15.41867,
"92.40",10.037,15.45167,
"92.60",10.056,15.485,
"92.80",10.072,15.51833,
"93.00",10.093,15.55167,
"93.20",10.114,15.585,
"93.40",10.134,15.61867,
"93.60",10.151,15.652,
"93.80",10.17,15.685,
"94.00",10.186,15.71833,
"94.20",10.204,15.75167,
"94.40",10.225,15.785,
"94.60",10.243,15.81833,
"94.80",10.26,15.852,
"95.00",10.282,15.88533,
"95.20",10.302,15.91867,
"95.40",10.321,15.952,
"95.60",10.34,15.985,
"95.80",10.356,16.01867,
"96.00",10.376,16.05167,
"96.20",10.394,16.085,
"96.40",10.414,16.11833,
"96.60",10.428,16.15167,
"96.80",10.448,16.185,
"97.00",10.467,16.21833,
"97.20",10.486,16.25167,
"97.40",10.502,16.285,
"97.60",10.519,16.31833,
"97.80",10.539,16.35167,
"98.00",10.556,16.385,
"98.20",10.576,16.41833,
"98.40",10.592,16.45167,
"98.60",10.61,16.485,
"98.80",10.627,16.51833,
"99.00",10.648,16.55167,
"99.20",10.668,16.585,
"99.40",10.686,16.61867,
"99.60",10.703,16.65167,
"99.80",10.718,16.685,
"100.00",10.733,16.71833,
"100.20",10.754,16.75167,
"100.40",10.775,16.78533,
"100.60",10.79,16.81833,
"100.80",10.806,16.85167,
"101.00",10.824,16.885,
"101.20",10.841,16.91833,
"101.40",10.86,16.95167,
"101.60",10.874,16.985,
"101.80",10.896,17.01833,
"102.00",10.911,17.05167,
"102.20",10.93,17.085,
"102.40",10.949,17.11833,
"102.60",10.965,17.15167,
"102.80",10.983,17.185,
"103.00",11.003,17.21833,
"103.20",11.022,17.25167,
"103.40",11.037,17.285,
"103.60",11.054,17.31833,
"103.80",11.069,17.352,
"104.00",11.089,17.385,
"104.20",11.106,17.41833,
"104.40",11.126,17.45167,
"104.60",11.139,17.485,
"104.80",11.154,17.51833,
"105.00",11.173,17.55167,
"105.20",11.193,17.585,
"105.40",11.209,17.61833,
"105.60",11.226,17.65167,
"105.80",11.243,17.685,
"106.00",11.261,17.71833,
"106.20",11.277,17.75167,
"106.40",11.295,17.785,
"106.60",11.316,17.81833,
"106.80",11.325,17.85167,
"107.00",11.347,17.885,
"107.20",11.363,17.91833,
"107.40",11.382,17.95167,
"107.60",11.396,17.985,
"107.80",11.413,18.01867,
"108.00",11.435,18.052,
"108.20",11.453,18.085,
"108.40",11.47,18.11833,
"108.60",11.481,18.15167,
"108.80",11.5,18.185,
"109.00",11.515,18.21833,
"109.20",11.533,18.25167,
"109.40",11.555,18.28533,
"109.60",11.572,18.31833,
"109.80",11.586,18.35167,
"110.00",11.604,18.385,
"110.20",11.621,18.41833,
"110.40",11.639,18.45167,
"110.60",11.657,18.485,
"110.80",11.671,18.51833,
"111.00",11.686,18.55167,
"111.20",11.707,18.585,
"111.40",11.722,18.61833,
"111.60",11.739,18.65167,
"111.80",11.753,18.685,
"112.00",11.772,18.71833,
"112.20",11.787,18.75167,
"112.40",11.806,18.785,
"112.60",11.82,18.81833,
"112.80",11.837,18.85167,
"113.00",11.854,18.885,
"113.20",11.873,18.91833,
"113.40",11.889,18.95167,
"113.60",11.905,18.985,
"113.80",11.92,19.01833,
"114.00",11.937,19.05167,
"114.20",11.953,19.085,
"114.40",11.97,19.11833,
"114.60",11.985,19.15167,
"114.80",12.003,19.185,
"115.00",12.021,19.21833,
"115.20",12.038,19.25167,
"115.40",12.058,19.285,
"115.60",12.07,19.31833,
"115.80",12.083,19.352,
"116.00",12.101,19.385,
"116.20",12.116,19.41833,
"116.40",12.134,19.45167,
"116.60",12.149,19.485,
"116.80",12.166,19.51867,
"117.00",12.181,19.552,
"117.20",12.197,19.585,
"117.40",12.214,19.61867,
"117.60",12.229,19.65167,
"117.80",12.242,19.68533,
"118.00",12.258,19.71833,
"118.20",12.276,19.75167,
"118.40",12.291,19.785,
"118.60",12.304,19.81833,
"118.80",12.319,19.85167,
"119.00",12.337,19.885,
"119.20",12.354,19.91833,
"119.40",12.368,19.95167,
"119.60",12.381,19.98533,
"119.80",12.396,20.01867,
"120.00",12.412,20.05167,
"120.20",12.429,20.085,
"120.40",12.445,20.11833,
"120.60",12.458,20.15167,
"120.80",12.471,20.185,
"121.00",12.486,20.21833,
"121.20",12.503,20.25167,
"121.40",12.515,20.285,
"121.60",12.531,20.31833,
"121.80",12.546,20.35167,
"122.00",12.561,20.385,
"122.20",12.576,20.41833,
"122.40",12.592,20.45167,
"122.60",12.607,20.485,
"122.80",12.619,20.51833,
"123.00",12.639,20.55167,
"123.20",12.653,20.585,
"123.40",12.669,20.61833,
"123.60",12.68,20.65167,
"123.80",12.697,20.685,
"124.00",12.713,20.71833,
"124.20",12.727,20.75167,
"124.40",12.747,20.785,
"124.60",12.757,20.81833,
"124.80",12.77,20.85167,
"125.00",12.783,20.885,
"125.20",12.801,20.91833,
"125.40",12.818,20.95167,
"125.60",12.828,20.985,
"125.80",12.842,21.01833,
"126.00",12.858,21.05167,
"126.20",12.872,21.085,
"126.40",12.888,21.11833,
"126.60",12.898,21.15167,
"126.80",12.911,21.185,
"127.00",12.926,21.21833,
"127.20",12.944,21.25167,
"127.40",12.96,21.285,
"127.60",12.972,21.31833,
"127.80",12.986,21.35167,
"128.00",13.003,21.385,
"128.20",13.021,21.41833,
"128.40",13.035,21.45167,
"128.60",13.049,21.485,
"128.80",13.062,21.51833,
"129.00",13.079,21.55167,
"129.20",13.094,21.585,
"129.40",13.109,21.61833,
"129.60",13.121,21.65167,
"129.80",13.133,21.68533,
"130.00",13.149,21.71867,
"130.20",13.167,21.75167,
"130.40",13.18,21.785,
"130.60",13.193,21.81833,
"130.80",13.207,21.85167,
"131.00",13.222,21.885,
"131.20",13.237,21.91833,
"131.40",13.254,21.95167,
"131.60",13.269,21.985,
"131.80",13.278,22.01867,
"132.00",13.296,22.05167,
"132.20",13.316,22.085,
"132.40",13.331,22.11833,
"132.60",13.342,22.15167,
"132.80",13.355,22.185,
"133.00",13.373,22.21833,
"133.20",13.387,22.25167,
"133.40",13.402,22.285,
"133.60",13.413,22.31833,
"133.80",13.428,22.35167,
"134.00",13.44,22.385,
"134.20",13.46,22.41833,
"134.40",13.473,22.45167,
"134.60",13.484,22.485,
"134.80",13.497,22.51833,
"135.00",13.511,22.55167,
"135.20",13.524,22.585,
"135.40",13.539,22.61833,
"135.60",13.551,22.65167,
"135.80",13.564,22.68533,
"136.00",13.577,22.71833,
"136.20",13.591,22.75167,
"136.40",13.603,22.785,
"136.60",13.619,22.81833,
"136.80",13.631,22.85167,
"137.00",13.646,22.885,
"137.20",13.659,22.91833,
"137.40",13.673,22.95167,
"137.60",13.686,22.985,
"137.80",13.699,23.01833,
"138.00",13.713,23.05167,
"138.20",13.728,23.085,
"138.40",13.743,23.11833,
"138.60",13.754,23.15167,
"138.80",13.768,23.185,
"139.00",13.782,23.21833,
"139.20",13.797,23.25167,
"139.40",13.812,23.285,
"139.60",13.826,23.31833,
"139.80",13.838,23.35167,
"140.00",13.848,23.385,
"140.20",13.867,23.41833,
"140.40",13.884,23.45167,
"140.60",13.896,23.485,
"140.80",13.912,23.51867,
"141.00",13.923,23.552,
"141.20",13.939,23.585,
"141.40",13.949,23.61867,
"141.60",13.963,23.652,
"141.80",13.976,23.68533,
"142.00",13.992,23.71833,
"142.20",14.003,23.75167,
"142.40",14.017,23.785,
"142.60",14.028,23.81833,
"142.80",14.043,23.85167,
"143.00",14.056,23.885,
"143.20",14.071,23.91833,
"143.40",14.085,23.95167,
"143.60",14.094,23.985,
"143.80",14.108,24.01833,
"144.00",14.117,24.05167,
"144.20",14.137,24.085,
"144.40",14.151,24.11833,
"144.60",14.162,24.15167,
"144.80",14.173,24.18533,
"145.00",14.191,24.21867,
"145.20",14.201,24.252,
"145.40",14.217,24.28533,
"145.60",14.225,24.31833,
"145.80",14.236,24.35167,
"146.00",14.25,24.385,
"146.20",14.264,24.41833,
"146.40",14.278,24.45167,
"146.60",14.29,24.485,
"146.80",14.301,24.51833,
"147.00",14.319,24.55167,
"147.20",14.331,24.585,
"147.40",14.343,24.61867,
"147.60",14.354,24.652,
"147.80",14.367,24.68533,
"148.00",14.381,24.71867,
"148.20",14.395,24.75167,
"148.40",14.408,24.785,
"148.60",14.418,24.81833,
"148.80",14.429,24.85167,
"149.00",14.443,24.885,
"149.20",14.458,24.91867,
"149.40",14.475,24.952,
"149.60",14.486,24.98533,
"149.80",14.497,25.01867,
"150.00",14.507,25.052,
"150.20",14.52,25.085,
"150.40",14.532,25.11833,
"150.60",14.546,25.15167,
"150.80",14.557,25.18533,
"151.00",14.571,25.21867,
"151.20",14.582,25.252,
"151.40",14.592,25.28533,
"151.60",14.603,25.31867,
"151.80",14.616,25.352,
"152.00",14.628,25.38533,
"152.20",14.642,25.41833,
"152.40",14.656,25.45167,
"152.60",14.664,25.48533,
"152.80",14.676,25.51867,
"153.00",14.689,25.552,
"153.20",14.702,25.58533,
"153.40",14.712,25.61867,
"153.60",14.724,25.652,
"153.80",14.734,25.685,
"154.00",14.743,25.71833,
"154.20",14.76,25.75167,
"154.40",14.774,25.785,
"154.60",14.786,25.81833,
"154.80",14.795,25.852,
"155.00",14.809,25.88533,
"155.20",14.824,25.91833,
"155.40",14.835,25.952,
"155.60",14.848,25.98533,
"155.80",14.857,26.01867,
"156.00",14.87,26.05167,
"156.20",14.883,26.085,
"156.40",14.897,26.11833,
"156.60",14.905,26.15167,
"156.80",14.914,26.185,
"157.00",14.93,26.21833,
"157.20",14.946,26.25167,
"157.40",14.953,26.285,
"157.60",14.962,26.31867,
"157.80",14.975,26.35167,
"158.00",14.988,26.38533,
"158.20",15.004,26.41833,
"158.40",15.01,26.45167,
"158.60",15.022,26.485,
"158.80",15.031,26.51833,
"159.00",15.045,26.55167,
"159.20",15.059,26.585,
"159.40",15.069,26.61833,
"159.60",15.081,26.65167,
"159.80",15.094,26.685,
"160.00",15.104,26.71833,
"160.20",15.116,26.75167,
"160.40",15.131,26.785,
"160.60",15.139,26.81833,
"160.80",15.152,26.85167,
"161.00",15.166,26.885,
"161.20",15.177,26.91833,
"161.40",15.192,26.95167,
"161.60",15.206,26.98533,
"161.80",15.215,27.01867,
"162.00",15.228,27.05167,
"162.20",15.245,27.085,
"162.40",15.258,27.11833,
"162.60",15.27,27.15167,
"162.80",15.281,27.18533,
"163.00",15.297,27.21867,
"163.20",15.308,27.25167,
"163.40",15.32,27.28533,
"163.60",15.33,27.31867,
"163.80",15.343,27.352,
"164.00",15.352,27.38533,
"164.20",15.368,27.41833,
"164.40",15.384,27.45167,
"164.60",15.392,27.485,
"164.80",15.403,27.51833,
"165.00",15.415,27.55167,
"165.20",15.431,27.585,
"165.40",15.443,27.61833,
"165.60",15.451,27.65167,
"165.80",15.462,27.685,
"166.00",15.473,27.71833,
"166.20",15.487,27.75167,
"166.40",15.497,27.785,
"166.60",15.506,27.81833,
"166.80",15.518,27.85167,
"167.00",15.528,27.885,
"167.20",15.541,27.91833,
"167.40",15.554,27.952,
"167.60",15.561,27.98533,
"167.80",15.573,28.01867,
"168.00",15.59,28.052,
"168.20",15.601,28.085,
"168.40",15.612,28.11833,
"168.60",15.618,28.15167,
"168.80",15.628,28.185,
"169.00",15.64,28.21867,
"169.20",15.652,28.25167,
"169.40",15.666,28.28533,
"169.60",15.67,28.31833,
"169.80",15.68,28.352,
"170.00",15.691,28.385,
"170.20",15.703,28.41833,
"170.40",15.714,28.45167,
"170.60",15.724,28.485,
"170.80",15.735,28.51833,
"171.00",15.745,28.55167,
"171.20",15.76,28.585,
"171.40",15.767,28.61833,
"171.60",15.782,28.65167,
"171.80",15.791,28.68533,
"172.00",15.804,28.71867,
"172.20",15.818,28.752,
"172.40",15.828,28.78533,
"172.60",15.835,28.81833,
"172.80",15.843,28.85167,
"173.00",15.855,28.885,
"173.20",15.87,28.91833,
"173.40",15.88,28.95167,
"173.60",15.889,28.985,
"173.80",15.898,29.01833,
"174.00",15.909,29.05167,
"174.20",15.918,29.085,
"174.40",15.934,29.11833,
"174.60",15.942,29.15167,
"174.80",15.95,29.185,
"175.00",15.96,29.21833,
"175.20",15.974,29.25167,
"175.40",15.987,29.285,
"175.60",15.993,29.31833,
"175.80",16.007,29.35167,
"176.00",16.014,29.385,
"176.20",16.027,29.41833,
"176.40",16.034,29.45133,
"176.60",16.047,29.48467,
"176.80",16.056,29.51833,
"177.00",16.067,29.55167,
"177.20",16.081,29.585,
"177.40",16.093,29.61833,
"177.60",16.098,29.65167,
"177.80",16.105,29.685,
"178.00",16.12,29.71833,
"178.20",16.131,29.75167,
"178.40",16.139,29.785,
"178.60",16.147,29.81833,
"178.80",16.155,29.85167,
"179.00",16.166,29.88467,
"179.20",16.174,29.918,
"179.40",16.19,29.95167,
"179.60",16.196,29.985,
"179.80",16.204,30.01833,
"180.00",16.217,30.05167,
"180.20",16.229,30.085,
"180.40",16.237,30.11833,
"180.60",16.246,30.15167,
"180.80",16.256,30.185,
"181.00",16.267,30.21833,
"181.20",16.279,30.25167,
"181.40",16.289,30.285,
"181.60",16.298,30.31833,
"181.80",16.31,30.352,
"182.00",16.325,30.38533,
"182.20",16.337,30.41867,
"182.40",16.343,30.452,
"182.60",16.354,30.485,
"182.80",16.36,30.51833,
"183.00",16.369,30.55167,
"183.20",16.386,30.585,
"183.40",16.396,30.61833,
"183.60",16.401,30.652,
"183.80",16.411,30.68533,
"184.00",16.419,30.71867,
"184.20",16.435,30.75167,
"184.40",16.444,30.78533,
"184.60",16.455,30.81833,
"184.80",16.46,30.85167,
"185.00",16.471,30.885,
"185.20",16.482,30.91833,
"185.40",16.495,30.95167,
"185.60",16.498,30.985,
"185.80",16.508,31.01833,
"186.00",16.519,31.05167,
"186.20",16.53,31.085,
"186.40",16.54,31.11833,
"186.60",16.548,31.15167,
"186.80",16.558,31.185,
"187.00",16.567,31.21833,
"187.20",16.581,31.25167,
"187.40",16.587,31.285,
"187.60",16.596,31.31833,
"187.80",16.603,31.35167,
"188.00",16.615,31.38533,
"188.20",16.631,31.41867,
"188.40",16.638,31.45167,
"188.60",16.642,31.485,
"188.80",16.652,31.51833,
"189.00",16.662,31.55167,
"189.20",16.679,31.58533,
"189.40",16.686,31.61867,
"189.60",16.697,31.652,
"189.80",16.705,31.68533,
"190.00",16.714,31.71867,
"190.20",16.727,31.75167,
"190.40",16.735,31.785,
"190.60",16.749,31.81833,
"190.80",16.754,31.852,
"191.00",16.764,31.885,
"191.20",16.772,31.91833,
"191.40",16.786,31.95167,
"191.60",16.793,31.985,
"191.80",16.803,32.01833,
"192.00",16.81,32.05167,
"192.20",16.824,32.085,
"192.40",16.832,32.11834,
"192.60",16.839,32.15167,
"192.80",16.852,32.18533,
"193.00",16.864,32.21867,
"193.20",16.873,32.252,
"193.40",16.883,32.28534,
"193.60",16.888,32.31834,
"193.80",16.893,32.352,
"194.00",16.902,32.38533,
"194.20",16.916,32.41833,
"194.40",16.926,32.45167,
"194.60",16.933,32.485,
"194.80",16.94,32.51867,
"195.00",16.952,32.552,
"195.20",16.96,32.58533,
"195.40",16.969,32.61867,
"195.60",16.979,32.652,
"195.80",16.983,32.68533,
"196.00",16.997,32.71867,
"196.20",17.004,32.752,
"196.40",17.015,32.785,
"196.60",17.021,32.81867,
"196.80",17.033,32.852,
"197.00",17.04,32.88533,
"197.20",17.05,32.91867,
"197.40",17.06,32.952,
"197.60",17.067,32.98534,
"197.80",17.075,33.01867,
"198.00",17.084,33.052,
"198.20",17.094,33.085,
"198.40",17.1,33.11867,
"198.60",17.107,33.152,
"198.80",17.114,33.18533,
"199.00",17.122,33.21867,
"199.20",17.137,33.252,
"199.40",17.144,33.28534,
"199.60",17.15,33.31834,
"199.80",17.157,33.352,
"200.00",17.169,33.385,
"200.20",17.182,33.41833,
"200.40",17.191,33.45167,
"200.60",17.198,33.485,
"200.80",17.206,33.51833,
"201.00",17.212,33.55167,
"201.20",17.227,33.585,
"201.40",17.233,33.61834,
"201.60",17.24,33.65167,
"201.80",17.249,33.68533,
"202.00",17.263,33.71867,
"202.20",17.272,33.75167,
"202.40",17.28,33.785,
"202.60",17.289,33.81867,
"202.80",17.298,33.852,
"203.00",17.308,33.88533,
"203.20",17.318,33.91833,
"203.40",17.326,33.952,
"203.60",17.33,33.985,
"203.80",17.338,34.01867,
"204.00",17.349,34.052,
"204.20",17.359,34.085,
"204.40",17.367,34.11834,
"204.60",17.374,34.15167,
"204.80",17.377,34.185,
"205.00",17.388,34.21867,
"205.20",17.402,34.25167,
"205.40",17.411,34.28534,
"205.60",17.417,34.31834,
"205.80",17.422,34.35167,
"206.00",17.43,34.385,
"206.20",17.439,34.41833,
"206.40",17.449,34.45167,
"206.60",17.454,34.485,
"206.80",17.467,34.51833,
"207.00",17.477,34.552,
"207.20",17.488,34.58533,
"207.40",17.494,34.61867,
"207.60",17.504,34.652,
"207.80",17.509,34.68533,
"208.00",17.522,34.71867,
"208.20",17.531,34.75167,
"208.40",17.538,34.78534,
"208.60",17.544,34.81834,
"208.80",17.552,34.85167,
"209.00",17.56,34.885,
"209.20",17.573,34.91833,
"209.40",17.583,34.952,
"209.60",17.59,34.985,
"209.80",17.596,35.01833,
"210.00",17.604,35.05167,
"210.20",17.617,35.085,
"210.40",17.627,35.11834,
"210.60",17.637,35.15167,
"210.80",17.641,35.185,
"211.00",17.649,35.21833,
"211.20",17.66,35.25167,
"211.40",17.668,35.285,
"211.60",17.677,35.31834,
"211.80",17.682,35.35167,
"212.00",17.693,35.385,
"212.20",17.704,35.41833,
"212.40",17.715,35.45167,
"212.60",17.72,35.485,
"212.80",17.725,35.51833,
"213.00",17.735,35.55167,
"213.20",17.748,35.585,
"213.40",17.756,35.61834,
"213.60",17.762,35.65167,
"213.80",17.768,35.68533,
"214.00",17.778,35.71833,
"214.20",17.788,35.75167,
"214.40",17.797,35.785,
"214.60",17.802,35.81834,
"214.80",17.806,35.85167,
"215.00",17.818,35.885,
"215.20",17.829,35.91833,
"215.40",17.84,35.95167,
"215.60",17.846,35.985,
"215.80",17.852,36.01833,
"216.00",17.861,36.05167,
"216.20",17.867,36.085,
"216.40",17.879,36.11834,
"216.60",17.887,36.15167,
"216.80",17.894,36.185,
"217.00",17.902,36.21833,
"217.20",17.911,36.25167,
"217.40",17.918,36.28534,
"217.60",17.925,36.31834,
"217.80",17.929,36.352,
"218.00",17.942,36.385,
"218.20",17.953,36.41833,
"218.40",17.962,36.45167,
"218.60",17.966,36.485,
"218.80",17.972,36.51833,
"219.00",17.982,36.55167,
"219.20",17.995,36.585,
"219.40",18.003,36.61834,
"219.60",18.011,36.652,
"219.80",18.016,36.68533,
"220.00",18.024,36.71867,
"220.20",18.031,36.75167,
"220.40",18.043,36.785,
"220.60",18.045,36.81834,
"220.80",18.055,36.852,
"221.00",18.063,36.88533,
"221.20",18.069,36.91867,
"221.40",18.079,36.952,
"221.60",18.087,36.98534,
"221.80",18.094,37.01867,
"222.00",18.102,37.052,
"222.20",18.108,37.085,
"222.40",18.115,37.11834,
"222.60",18.121,37.15167,
"222.80",18.126,37.185,
"223.00",18.135,37.21867,
"223.20",18.146,37.25167,
"223.40",18.149,37.285,
"223.60",18.156,37.31834,
"223.80",18.161,37.35167,
"224.00",18.165,37.385,
"224.20",18.18,37.41833,
"224.40",18.188,37.45167,
"224.60",18.194,37.485,
"224.80",18.2,37.51833,
"225.00",18.207,37.552,
"225.20",18.213,37.58533,
"225.40",18.222,37.61867,
"225.60",18.227,37.652,
"225.80",18.232,37.68533,
"226.00",18.237,37.71833,
"226.20",18.239,37.75167,