File: exposed_monofilament_10cm_10mmpm_24nm_250esh_13.csv
"Test Name","Test Mode","Test Type","Control","Test Speed 1","Test Speed 2","Test Speed 3","Change Point 1","Change Point 2","Disp. Origin","Break and Limit Action","Sensitivity:","Level:"
"","Single","Tensile","Stroke",10,1,1,"Off","Off","Start","Stop",0,1

"Title","Sub title","Comment"
"","",""

"Shape:","Batch Size:","SubBatch Size:"
"Plate",1,1
"Name:","Thickness","Width","Gauge Length",
"Size Unit:","mm","mm","mm",
" 1 - 1","1.0000","1.0000","100.0000",

"Name",
"Parameter",
"Units",
" 1 - 1",

" 1- 1"
"Time","Force","Stroke",
"sec","N","mm",
"0.00",.001,0,
"0.15",.001,.028,
"0.30",.005,5.566667E-02,
"0.45",.015,8.366667E-02,
"0.60",.024,.1113333,
"0.75",.035,.139,
"0.90",.045,.167,
"1.05",.054,.1946667,
"1.20",.068,.2223333,
"1.35",.078,.2503333,
"1.50",.087,.278,
"1.65",.096,.3056667,
"1.80",.108,.3336667,
"1.95",.117,.3613333,
"2.10",.127,.388,
"2.25",.136,.415,
"2.40",.149,.4416667,
"2.55",.159,.468,
"2.70",.166,.4943334,
"2.85",.177,.52,
"3.00",.187,.546,
"3.15",.196,.5716667,
"3.30",.204,.5973334,
"3.45",.214,.6226667,
"3.60",.223,.6483334,
"3.75",.231,.6736667,
"3.90",.241,.699,
"4.05",.25,.724,
"4.20",.258,.7493333,
"4.35",.266,.7746667,
"4.50",.275,.7996667,
"4.65",.284,.8246667,
"4.80",.296,.85,
"4.95",.306,.875,
"5.10",.313,.9,
"5.25",.323,.9253333,
"5.40",.334,.9503334,
"5.55",.342,.9753333,
"5.70",.35,1.000333,
"5.85",.36,1.025667,
"6.00",.373,1.050667,
"6.15",.379,1.075667,
"6.30",.387,1.100667,
"6.45",.398,1.125667,
"6.60",.406,1.150667,
"6.75",.415,1.175667,
"6.90",.425,1.200667,
"7.05",.433,1.225667,
"7.20",.444,1.250667,
"7.35",.454,1.275667,
"7.50",.463,1.300667,
"7.65",.473,1.325667,
"7.80",.483,1.350667,
"7.95",.492,1.375667,
"8.10",.5,1.400667,
"8.25",.51,1.425667,
"8.40",.522,1.450667,
"8.55",.53,1.475667,
"8.70",.541,1.500333,
"8.85",.551,1.525667,
"9.00",.56,1.550667,
"9.15",.569,1.575667,
"9.30",.579,1.600667,
"9.45",.588,1.625667,
"9.60",.601,1.650667,
"9.75",.608,1.675667,
"9.90",.617,1.700667,
"10.05",.631,1.725667,
"10.20",.64,1.750667,
"10.35",.649,1.775667,
"10.50",.659,1.800667,
"10.65",.67,1.825667,
"10.80",.68,1.850667,
"10.95",.688,1.875667,
"11.10",.699,1.900667,
"11.25",.709,1.925667,
"11.40",.718,1.950667,
"11.55",.73,1.975667,
"11.70",.74,2.000667,
"11.85",.751,2.025667,
"12.00",.761,2.050667,
"12.15",.772,2.075667,
"12.30",.782,2.100667,
"12.45",.79,2.125667,
"12.60",.8,2.150667,
"12.75",.811,2.175667,
"12.90",.823,2.200667,
"13.05",.832,2.225667,
"13.20",.846,2.250667,
"13.35",.854,2.275667,
"13.50",.865,2.300667,
"13.65",.877,2.325667,
"13.80",.888,2.350667,
"13.95",.898,2.375667,
"14.10",.909,2.400667,
"14.25",.922,2.425667,
"14.40",.933,2.450667,
"14.55",.941,2.475667,
"14.70",.953,2.500667,
"14.85",.962,2.525667,
"15.00",.973,2.550667,
"15.15",.985,2.575667,
"15.30",.996,2.600667,
"15.45",1.006,2.625667,
"15.60",1.018,2.650667,
"15.75",1.029,2.675667,
"15.90",1.041,2.700667,
"16.05",1.051,2.725667,
"16.20",1.062,2.750667,
"16.35",1.073,2.775667,
"16.50",1.084,2.800667,
"16.65",1.098,2.825667,
"16.80",1.109,2.850667,
"16.95",1.122,2.875667,
"17.10",1.132,2.900667,
"17.25",1.146,2.925667,
"17.40",1.156,2.950667,
"17.55",1.168,2.975667,
"17.70",1.182,3.000667,
"17.85",1.191,3.025667,
"18.00",1.206,3.050667,
"18.15",1.217,3.075667,
"18.30",1.229,3.100667,
"18.45",1.238,3.125667,
"18.60",1.252,3.150667,
"18.75",1.267,3.175333,
"18.90",1.278,3.200667,
"19.05",1.289,3.225667,
"19.20",1.302,3.250333,
"19.35",1.314,3.275667,
"19.50",1.327,3.300667,
"19.65",1.339,3.325333,
"19.80",1.351,3.350333,
"19.95",1.365,3.375667,
"20.10",1.375,3.400333,
"20.25",1.387,3.425333,
"20.40",1.4,3.450667,
"20.55",1.414,3.475667,
"20.70",1.427,3.500667,
"20.85",1.44,3.525667,
"21.00",1.454,3.550667,
"21.15",1.467,3.575667,
"21.30",1.478,3.600667,
"21.45",1.492,3.625667,
"21.60",1.505,3.650667,
"21.75",1.519,3.675333,
"21.90",1.533,3.700333,
"22.05",1.548,3.725333,
"22.20",1.558,3.750667,
"22.35",1.574,3.775667,
"22.50",1.588,3.800667,
"22.65",1.602,3.825667,
"22.80",1.616,3.850667,
"22.95",1.628,3.875667,
"23.10",1.642,3.901,
"23.25",1.658,3.925667,
"23.40",1.67,3.951,
"23.55",1.687,3.975667,
"23.70",1.701,4.000667,
"23.85",1.715,4.026,
"24.00",1.731,4.050667,
"24.15",1.746,4.075667,
"24.30",1.759,4.100667,
"24.45",1.771,4.125667,
"24.60",1.788,4.150667,
"24.75",1.807,4.175667,
"24.90",1.818,4.200667,
"25.05",1.831,4.225667,
"25.20",1.848,4.250667,
"25.35",1.862,4.275667,
"25.50",1.878,4.300667,
"25.65",1.895,4.325667,
"25.80",1.913,4.350667,
"25.95",1.927,4.375667,
"26.10",1.942,4.400667,
"26.25",1.957,4.425667,
"26.40",1.971,4.450667,
"26.55",1.988,4.475667,
"26.70",2.007,4.500667,
"26.85",2.021,4.526,
"27.00",2.037,4.550667,
"27.15",2.052,4.576,
"27.30",2.068,4.600667,
"27.45",2.083,4.625667,
"27.60",2.103,4.650667,
"27.75",2.119,4.675667,
"27.90",2.137,4.700667,
"28.05",2.152,4.725667,
"28.20",2.168,4.751,
"28.35",2.186,4.775667,
"28.50",2.203,4.800667,
"28.65",2.221,4.825667,
"28.80",2.236,4.851,
"28.95",2.253,4.876,
"29.10",2.272,4.901,
"29.25",2.291,4.926,
"29.40",2.306,4.951,
"29.55",2.322,4.976,
"29.70",2.341,5.000667,
"29.85",2.362,5.026,
"30.00",2.377,5.050667,
"30.15",2.394,5.075667,
"30.30",2.41,5.100667,
"30.45",2.424,5.125667,
"30.60",2.445,5.150667,
"30.75",2.465,5.175667,
"30.90",2.482,5.200667,
"31.05",2.499,5.225667,
"31.20",2.518,5.250667,
"31.35",2.535,5.275667,
"31.50",2.555,5.300667,
"31.65",2.576,5.325667,
"31.80",2.593,5.350667,
"31.95",2.61,5.375667,
"32.10",2.632,5.400667,
"32.25",2.648,5.425667,
"32.40",2.667,5.451,
"32.55",2.689,5.476,
"32.70",2.708,5.500667,
"32.85",2.726,5.525667,
"33.00",2.748,5.551,
"33.15",2.767,5.576,
"33.30",2.787,5.600667,
"33.45",2.804,5.625667,
"33.60",2.823,5.650667,
"33.75",2.844,5.675667,
"33.90",2.866,5.700667,
"34.05",2.886,5.725667,
"34.20",2.909,5.750667,
"34.35",2.927,5.775667,
"34.50",2.948,5.800667,
"34.65",2.967,5.826,
"34.80",2.989,5.850667,
"34.95",3.01,5.876,
"35.10",3.029,5.901,
"35.25",3.051,5.926,
"35.40",3.073,5.951,
"35.55",3.092,5.975667,
"35.70",3.111,6.000667,
"35.85",3.131,6.025667,
"36.00",3.154,6.050667,
"36.15",3.174,6.075667,
"36.30",3.196,6.100667,
"36.45",3.217,6.126,
"36.60",3.235,6.150667,
"36.75",3.259,6.175667,
"36.90",3.278,6.201,
"37.05",3.297,6.226,
"37.20",3.316,6.250667,
"37.35",3.337,6.276,
"37.50",3.355,6.301,
"37.65",3.37,6.325667,
"37.80",3.383,6.350667,
"37.95",3.401,6.375667,
"38.10",3.418,6.400667,
"38.25",3.432,6.426,
"38.40",3.447,6.451,
"38.55",3.46,6.475667,
"38.70",3.48,6.500667,
"38.85",3.501,6.526,
"39.00",3.519,6.551,
"39.15",3.529,6.576,
"39.30",3.541,6.601,
"39.45",3.56,6.626,
"39.60",3.581,6.651,
"39.75",3.606,6.675667,
"39.90",3.628,6.700667,
"40.05",3.649,6.725667,
"40.20",3.672,6.750667,
"40.35",3.694,6.775667,
"40.50",3.718,6.800667,
"40.65",3.742,6.826,
"40.80",3.765,6.851,
"40.95",3.787,6.875667,
"41.10",3.805,6.900667,
"41.25",3.828,6.925667,
"41.40",3.848,6.950667,
"41.55",3.87,6.975667,
"41.70",3.894,7.000667,
"41.85",3.921,7.026,
"42.00",3.943,7.050667,
"42.15",3.963,7.075667,
"42.30",3.986,7.100667,
"42.45",4.01,7.125667,
"42.60",4.034,7.150667,
"42.75",4.059,7.175667,
"42.90",4.081,7.200667,
"43.05",4.103,7.226,
"43.20",4.128,7.251,
"43.35",4.149,7.276,
"43.50",4.171,7.301,
"43.65",4.197,7.326,
"43.80",4.223,7.351,
"43.95",4.247,7.375667,
"44.10",4.266,7.400667,
"44.25",4.291,7.425667,
"44.40",4.312,7.450667,
"44.55",4.336,7.475667,
"44.70",4.36,7.500667,
"44.85",4.385,7.525667,
"45.00",4.41,7.550667,
"45.15",4.435,7.576,
"45.30",4.456,7.600667,
"45.45",4.48,7.625667,
"45.60",4.503,7.650667,
"45.75",4.529,7.675667,
"45.90",4.552,7.700667,
"46.05",4.573,7.725667,
"46.20",4.597,7.750667,
"46.35",4.622,7.775667,
"46.50",4.647,7.800667,
"46.65",4.67,7.825667,
"46.80",4.695,7.850667,
"46.95",4.715,7.875667,
"47.10",4.739,7.900667,
"47.25",4.763,7.925667,
"47.40",4.786,7.950667,
"47.55",4.81,7.975333,
"47.70",4.835,8.000667,
"47.85",4.858,8.025666,
"48.00",4.88,8.050666,
"48.15",4.905,8.075666,
"48.30",4.926,8.100666,
"48.45",4.947,8.125667,
"48.60",4.969,8.150666,
"48.75",4.993,8.175666,
"48.90",5.019,8.200666,
"49.05",5.041,8.225666,
"49.20",5.065,8.250667,
"49.35",5.087,8.276,
"49.50",5.11,8.301,
"49.65",5.133,8.325999,
"49.80",5.158,8.350666,
"49.95",5.183,8.375667,
"50.10",5.204,8.400666,
"50.25",5.228,8.425666,
"50.40",5.251,8.450999,
"50.55",5.275,8.476,
"50.70",5.298,8.500999,
"50.85",5.322,8.526,
"51.00",5.346,8.551,
"51.15",5.368,8.575999,
"51.30",5.392,8.600666,
"51.45",5.416,8.625999,
"51.60",5.44,8.650666,
"51.75",5.463,8.675666,
"51.90",5.485,8.700666,
"52.05",5.508,8.725666,
"52.20",5.531,8.750667,
"52.35",5.554,8.775666,
"52.50",5.578,8.800666,
"52.65",5.604,8.825666,
"52.80",5.625,8.850666,
"52.95",5.647,8.875667,
"53.10",5.671,8.900666,
"53.25",5.692,8.925666,
"53.40",5.714,8.950999,
"53.55",5.739,8.976,
"53.70",5.761,9.000667,
"53.85",5.783,9.026,
"54.00",5.805,9.050666,
"54.15",5.826,9.075666,
"54.30",5.846,9.100666,
"54.45",5.866,9.125667,
"54.60",5.889,9.150666,
"54.75",5.91,9.175666,
"54.90",5.934,9.200666,
"55.05",5.955,9.225666,
"55.20",5.975,9.250667,
"55.35",5.994,9.275666,
"55.50",6.016,9.300666,
"55.65",6.038,9.325666,
"55.80",6.06,9.350666,
"55.95",6.082,9.375667,
"56.10",6.1,9.400666,
"56.25",6.122,9.425666,
"56.40",6.142,9.450666,
"56.55",6.164,9.475666,
"56.70",6.186,9.500667,
"56.85",6.205,9.525666,
"57.00",6.226,9.550666,
"57.15",6.247,9.575666,
"57.30",6.266,9.600666,
"57.45",6.289,9.625667,
"57.60",6.31,9.650666,
"57.75",6.332,9.675666,
"57.90",6.351,9.700666,
"58.05",6.372,9.725666,
"58.20",6.39,9.750667,
"58.35",6.409,9.775666,
"58.50",6.426,9.800666,
"58.65",6.449,9.825666,
"58.80",6.468,9.850666,
"58.95",6.492,9.875667,
"59.10",6.513,9.900666,
"59.25",6.53,9.925666,
"59.40",6.547,9.950666,
"59.55",6.566,9.975666,
"59.70",6.587,10.00067,
"59.85",6.612,10.02567,
"60.00",6.63,10.05067,
"60.15",6.648,10.07567,
"60.30",6.668,10.10067,
"60.45",6.691,10.12567,
"60.60",6.713,10.15067,
"60.75",6.734,10.17567,
"60.90",6.756,10.201,
"61.05",6.774,10.226,
"61.20",6.798,10.251,
"61.35",6.818,10.276,
"61.50",6.837,10.301,
"61.65",6.857,10.32567,
"61.80",6.877,10.35067,
"61.95",6.898,10.37567,
"62.10",6.915,10.40067,
"62.25",6.936,10.42567,
"62.40",6.955,10.45067,
"62.55",6.974,10.47567,
"62.70",6.995,10.50067,
"62.85",7.015,10.526,
"63.00",7.034,10.551,
"63.15",7.052,10.576,
"63.30",7.071,10.601,
"63.45",7.09,10.626,
"63.60",7.108,10.651,
"63.75",7.126,10.676,
"63.90",7.147,10.701,
"64.05",7.166,10.72567,
"64.20",7.183,10.751,
"64.35",7.201,10.776,
"64.50",7.217,10.801,
"64.65",7.236,10.826,
"64.80",7.255,10.851,
"64.95",7.276,10.876,
"65.10",7.294,10.90067,
"65.25",7.312,10.92567,
"65.40",7.332,10.951,
"65.55",7.349,10.976,
"65.70",7.367,11.001,
"65.85",7.387,11.026,
"66.00",7.405,11.05067,
"66.15",7.423,11.076,
"66.30",7.441,11.10067,
"66.45",7.462,11.12567,
"66.60",7.482,11.151,
"66.75",7.501,11.17567,
"66.90",7.519,11.201,
"67.05",7.538,11.226,
"67.20",7.554,11.251,
"67.35",7.574,11.276,
"67.50",7.591,11.301,
"67.65",7.609,11.326,
"67.80",7.629,11.351,
"67.95",7.645,11.376,
"68.10",7.659,11.401,
"68.25",7.677,11.426,
"68.40",7.695,11.451,
"68.55",7.714,11.476,
"68.70",7.731,11.50067,
"68.85",7.749,11.526,
"69.00",7.768,11.551,
"69.15",7.783,11.576,
"69.30",7.799,11.601,
"69.45",7.816,11.626,
"69.60",7.831,11.651,
"69.75",7.849,11.676,
"69.90",7.867,11.701,
"70.05",7.881,11.72567,
"70.20",7.895,11.75067,
"70.35",7.912,11.77567,
"70.50",7.928,11.80067,
"70.65",7.944,11.82567,
"70.80",7.962,11.85067,
"70.95",7.977,11.87567,
"71.10",7.991,11.90067,
"71.25",8.009,11.92567,
"71.40",8.024,11.951,
"71.55",8.044,11.976,
"71.70",8.061,12.00067,
"71.85",8.078,12.02567,
"72.00",8.095,12.05067,
"72.15",8.113,12.07567,
"72.30",8.127,12.10067,
"72.45",8.143,12.126,
"72.60",8.161,12.151,
"72.75",8.181,12.176,
"72.90",8.198,12.201,
"73.05",8.216,12.226,
"73.20",8.229,12.25067,
"73.35",8.247,12.27567,
"73.50",8.262,12.30067,
"73.65",8.284,12.32567,
"73.80",8.302,12.35067,
"73.95",8.32,12.37567,
"74.10",8.335,12.40067,
"74.25",8.352,12.426,
"74.40",8.368,12.451,
"74.55",8.384,12.47567,
"74.70",8.403,12.50067,
"74.85",8.422,12.52567,
"75.00",8.437,12.55067,
"75.15",8.452,12.57567,
"75.30",8.468,12.60067,
"75.45",8.488,12.62567,
"75.60",8.502,12.65067,
"75.75",8.52,12.67567,
"75.90",8.535,12.70067,
"76.05",8.552,12.72567,
"76.20",8.569,12.75067,
"76.35",8.584,12.77567,
"76.50",8.601,12.80067,
"76.65",8.618,12.82567,
"76.80",8.633,12.85067,
"76.95",8.65,12.87567,
"77.10",8.664,12.90067,
"77.25",8.681,12.926,
"77.40",8.697,12.951,
"77.55",8.713,12.976,
"77.70",8.733,13.00067,
"77.85",8.749,13.02567,
"78.00",8.765,13.05067,
"78.15",8.78,13.07567,
"78.30",8.796,13.10067,
"78.45",8.811,13.12567,
"78.60",8.828,13.151,
"78.75",8.849,13.17567,
"78.90",8.864,13.201,
"79.05",8.877,13.226,
"79.20",8.893,13.25067,
"79.35",8.907,13.27567,
"79.50",8.921,13.301,
"79.65",8.94,13.326,
"79.80",8.955,13.35067,
"79.95",8.973,13.37567,
"80.10",8.988,13.40067,
"80.25",9.004,13.42567,
"80.40",9.02,13.45067,
"80.55",9.033,13.47567,
"80.70",9.05,13.50067,
"80.85",9.067,13.52567,
"81.00",9.084,13.55067,
"81.15",9.095,13.57567,
"81.30",9.113,13.60067,
"81.45",9.128,13.626,
"81.60",9.147,13.651,
"81.75",9.163,13.67567,
"81.90",9.178,13.70067,
"82.05",9.196,13.72567,
"82.20",9.211,13.75067,
"82.35",9.224,13.77567,
"82.50",9.241,13.80067,
"82.65",9.258,13.826,
"82.80",9.277,13.851,
"82.95",9.29,13.87567,
"83.10",9.305,13.90067,
"83.25",9.322,13.92567,
"83.40",9.338,13.95067,
"83.55",9.355,13.97567,
"83.70",9.371,14.00067,
"83.85",9.389,14.02567,
"84.00",9.406,14.05067,
"84.15",9.422,14.07567,
"84.30",9.436,14.10067,
"84.45",9.451,14.12567,
"84.60",9.467,14.15067,
"84.75",9.485,14.17567,
"84.90",9.502,14.20067,
"85.05",9.518,14.22567,
"85.20",9.533,14.25067,
"85.35",9.549,14.27567,
"85.50",9.564,14.30067,
"85.65",9.581,14.326,
"85.80",9.597,14.351,
"85.95",9.612,14.376,
"86.10",9.628,14.40067,
"86.25",9.642,14.42567,
"86.40",9.657,14.45067,
"86.55",9.674,14.47567,
"86.70",9.69,14.50067,
"86.85",9.706,14.52567,
"87.00",9.719,14.551,
"87.15",9.734,14.576,
"87.30",9.752,14.601,
"87.45",9.763,14.626,
"87.60",9.778,14.651,
"87.75",9.792,14.676,
"87.90",9.811,14.701,
"88.05",9.821,14.726,
"88.20",9.832,14.75067,
"88.35",9.845,14.77567,
"88.50",9.858,14.80067,
"88.65",9.874,14.826,
"88.80",9.889,14.85067,
"88.95",9.903,14.87567,
"89.10",9.916,14.90067,
"89.25",9.931,14.92567,
"89.40",9.946,14.951,
"89.55",9.957,14.976,
"89.70",9.971,15.001,
"89.85",9.986,15.02567,
"90.00",10.003,15.05067,
"90.15",10.015,15.07567,
"90.30",10.027,15.10067,
"90.45",10.042,15.12567,
"90.60",10.055,15.15067,
"90.75",10.069,15.17567,
"90.90",10.086,15.20067,
"91.05",10.1,15.22567,
"91.20",10.114,15.25067,
"91.35",10.127,15.27567,
"91.50",10.142,15.30067,
"91.65",10.159,15.326,
"91.80",10.176,15.351,
"91.95",10.193,15.376,
"92.10",10.205,15.401,
"92.25",10.218,15.426,
"92.40",10.234,15.451,
"92.55",10.248,15.47567,
"92.70",10.263,15.50067,
"92.85",10.279,15.52567,
"93.00",10.295,15.55067,
"93.15",10.305,15.576,
"93.30",10.32,15.601,
"93.45",10.334,15.626,
"93.60",10.348,15.651,
"93.75",10.365,15.67567,
"93.90",10.379,15.70067,
"94.05",10.394,15.72567,
"94.20",10.408,15.75067,
"94.35",10.423,15.77567,
"94.50",10.433,15.80067,
"94.65",10.447,15.82567,
"94.80",10.465,15.85067,
"94.95",10.48,15.87567,
"95.10",10.495,15.90067,
"95.25",10.506,15.926,
"95.40",10.521,15.951,
"95.55",10.537,15.976,
"95.70",10.551,16.001,
"95.85",10.564,16.026,
"96.00",10.579,16.051,
"96.15",10.594,16.07567,
"96.30",10.605,16.10067,
"96.45",10.617,16.126,
"96.60",10.63,16.151,
"96.75",10.645,16.176,
"96.90",10.656,16.201,
"97.05",10.668,16.226,
"97.20",10.68,16.251,
"97.35",10.693,16.276,
"97.50",10.709,16.301,
"97.65",10.723,16.32567,
"97.80",10.74,16.35067,
"97.95",10.749,16.37567,
"98.10",10.763,16.40067,
"98.25",10.78,16.42567,
"98.40",10.793,16.45067,
"98.55",10.805,16.47567,
"98.70",10.821,16.50067,
"98.85",10.837,16.52567,
"99.00",10.852,16.551,
"99.15",10.869,16.576,
"99.30",10.88,16.60067,
"99.45",10.894,16.626,
"99.60",10.91,16.651,
"99.75",10.921,16.67567,
"99.90",10.935,16.70067,
"100.05",10.952,16.72567,
"100.20",10.963,16.75067,
"100.35",10.975,16.77567,
"100.50",10.989,16.80067,
"100.65",11.003,16.82567,
"100.80",11.017,16.85067,
"100.95",11.027,16.87567,
"101.10",11.043,16.90067,
"101.25",11.057,16.92567,
"101.40",11.07,16.951,
"101.55",11.086,16.976,
"101.70",11.102,17.00067,
"101.85",11.113,17.02567,
"102.00",11.125,17.05067,
"102.15",11.137,17.07567,
"102.30",11.151,17.10067,
"102.45",11.164,17.12567,
"102.60",11.175,17.15067,
"102.75",11.189,17.17567,
"102.90",11.201,17.20067,
"103.05",11.213,17.22567,
"103.20",11.223,17.25067,
"103.35",11.235,17.27567,
"103.50",11.249,17.30067,
"103.65",11.26,17.32567,
"103.80",11.278,17.35067,
"103.95",11.294,17.37567,
"104.10",11.304,17.40067,
"104.25",11.317,17.42567,
"104.40",11.329,17.45067,
"104.55",11.34,17.47567,
"104.70",11.354,17.50067,
"104.85",11.369,17.52567,
"105.00",11.381,17.55067,
"105.15",11.394,17.57567,
"105.30",11.404,17.60067,
"105.45",11.417,17.626,
"105.60",11.429,17.651,
"105.75",11.44,17.67567,
"105.90",11.454,17.701,
"106.05",11.465,17.72567,
"106.20",11.477,17.75067,
"106.35",11.487,17.77567,
"106.50",11.501,17.80067,
"106.65",11.515,17.82567,
"106.80",11.525,17.85067,
"106.95",11.535,17.87567,
"107.10",11.547,17.90067,
"107.25",11.558,17.92567,
"107.40",11.572,17.95067,
"107.55",11.585,17.976,
"107.70",11.601,18.00067,
"107.85",11.615,18.02567,
"108.00",11.627,18.05067,
"108.15",11.638,18.07567,
"108.30",11.65,18.10067,
"108.45",11.663,18.126,
"108.60",11.68,18.151,
"108.75",11.693,18.176,
"108.90",11.706,18.201,
"109.05",11.717,18.226,
"109.20",11.731,18.251,
"109.35",11.742,18.276,
"109.50",11.752,18.301,
"109.65",11.768,18.326,
"109.80",11.782,18.35067,
"109.95",11.795,18.37567,
"110.10",11.806,18.40067,
"110.25",11.817,18.42567,
"110.40",11.83,18.45067,
"110.55",11.841,18.47567,
"110.70",11.854,18.50067,
"110.85",11.865,18.526,
"111.00",11.88,18.551,
"111.15",11.89,18.576,
"111.30",11.901,18.60067,
"111.45",11.916,18.626,
"111.60",11.931,18.651,
"111.75",11.944,18.67567,
"111.90",11.954,18.70067,
"112.05",11.962,18.72567,
"112.20",11.975,18.75067,
"112.35",11.987,18.77567,
"112.50",11.999,18.80067,
"112.65",12.013,18.82567,
"112.80",12.026,18.85067,
"112.95",12.037,18.87567,
"113.10",12.048,18.90067,
"113.25",12.057,18.92567,
"113.40",12.069,18.95067,
"113.55",12.08,18.97567,
"113.70",12.091,19.00067,
"113.85",12.106,19.026,
"114.00",12.12,19.051,
"114.15",12.129,19.07567,
"114.30",12.138,19.101,
"114.45",12.149,19.12567,
"114.60",12.163,19.151,
"114.75",12.172,19.17567,
"114.90",12.184,19.20067,
"115.05",12.198,19.226,
"115.20",12.212,19.251,
"115.35",12.223,19.276,
"115.50",12.234,19.301,
"115.65",12.246,19.326,
"115.80",12.259,19.351,
"115.95",12.274,19.37567,
"116.10",12.284,19.40067,
"116.25",12.292,19.42567,
"116.40",12.307,19.45067,
"116.55",12.319,19.476,
"116.70",12.335,19.50067,
"116.85",12.347,19.526,
"117.00",12.36,19.551,
"117.15",12.368,19.576,
"117.30",12.38,19.601,
"117.45",12.393,19.626,
"117.60",12.411,19.651,
"117.75",12.423,19.676,
"117.90",12.435,19.701,
"118.05",12.449,19.726,
"118.20",12.458,19.751,
"118.35",12.468,19.776,
"118.50",12.481,19.801,
"118.65",12.493,19.82567,
"118.80",12.507,19.851,
"118.95",12.519,19.876,
"119.10",12.53,19.901,
"119.25",12.539,19.926,
"119.40",12.55,19.951,
"119.55",12.563,19.976,
"119.70",12.575,20.00067,
"119.85",12.586,20.02567,
"120.00",12.601,20.05067,
"120.15",12.612,20.07567,
"120.30",12.624,20.101,
"120.45",12.635,20.126,
"120.60",12.645,20.15067,
"120.75",12.66,20.17567,
"120.90",12.674,20.20067,
"121.05",12.685,20.22567,
"121.20",12.696,20.251,
"121.35",12.71,20.276,
"121.50",12.724,20.301,
"121.65",12.738,20.326,
"121.80",12.753,20.351,
"121.95",12.764,20.376,
"122.10",12.778,20.401,
"122.25",12.791,20.426,
"122.40",12.803,20.451,
"122.55",12.815,20.476,
"122.70",12.829,20.501,
"122.85",12.845,20.526,
"123.00",12.856,20.551,
"123.15",12.863,20.576,
"123.30",12.873,20.601,
"123.45",12.884,20.626,
"123.60",12.896,20.651,
"123.75",12.911,20.676,
"123.90",12.922,20.701,
"124.05",12.93,20.726,
"124.20",12.944,20.751,
"124.35",12.951,20.77567,
"124.50",12.96,20.80067,
"124.65",12.971,20.82567,
"124.80",12.981,20.85067,
"124.95",12.99,20.87567,
"125.10",13.004,20.901,
"125.25",13.013,20.92567,
"125.40",13.022,20.951,
"125.55",13.035,20.976,
"125.70",13.045,21.00067,
"125.85",13.053,21.02567,
"126.00",13.068,21.05067,
"126.15",13.078,21.07567,
"126.30",13.087,21.10067,
"126.45",13.098,21.12567,
"126.60",13.107,21.151,
"126.75",13.121,21.176,
"126.90",13.13,21.201,
"127.05",13.136,21.226,
"127.20",13.144,21.251,
"127.35",13.151,21.276,
"127.50",13.159,21.301,
"127.65",13.17,21.32567,
"127.80",13.181,21.35067,
"127.95",13.189,21.37567,
"128.10",13.197,21.40067,
"128.25",13.205,21.42567,
"128.40",13.216,21.451,
"128.55",13.225,21.476,
"128.70",13.237,21.501,
"128.85",13.246,21.526,
"129.00",13.257,21.551,
"129.15",13.263,21.576,
"129.30",13.269,21.60067,
"129.45",13.278,21.626,
"129.60",13.287,21.65067,
"129.75",13.297,21.67567,
"129.90",13.306,21.70067,
"130.05",13.313,21.72567,
"130.20",13.322,21.75067,
"130.35",13.331,21.77567,
"130.50",13.339,21.80067,
"130.65",13.349,21.82567,
"130.80",13.362,21.85067,
"130.95",13.372,21.87567,
"131.10",13.379,21.90067,
"131.25",13.391,21.92567,
"131.40",13.403,21.95067,
"131.55",13.412,21.97567,
"131.70",13.421,22.00067,
"131.85",13.432,22.02567,
"132.00",13.444,22.05067,
"132.15",13.453,22.07567,
"132.30",13.465,22.10067,
"132.45",13.474,22.12567,
"132.60",13.485,22.15067,
"132.75",13.497,22.17567,
"132.90",13.509,22.20067,
"133.05",13.519,22.22567,
"133.20",13.529,22.25067,
"133.35",13.536,22.276,
"133.50",13.547,22.301,
"133.65",13.56,22.32567,
"133.80",13.573,22.35067,
"133.95",13.582,22.37567,
"134.10",13.592,22.40067,
"134.25",13.599,22.42567,
"134.40",13.61,22.45067,
"134.55",13.617,22.47567,
"134.70",13.626,22.50067,
"134.85",13.637,22.52567,
"135.00",13.648,22.55067,
"135.15",13.655,22.57567,
"135.30",13.664,22.60067,
"135.45",13.672,22.62567,
"135.60",13.683,22.651,
"135.75",13.69,22.67567,
"135.90",13.701,22.70067,
"136.05",13.707,22.72567,
"136.20",13.716,22.75067,
"136.35",13.724,22.77567,
"136.50",13.734,22.80067,
"136.65",13.745,22.82567,
"136.80",13.756,22.85067,
"136.95",13.766,22.876,
"137.10",13.774,22.90067,
"137.25",13.784,22.92567,
"137.40",13.792,22.951,
"137.55",13.802,22.97567,
"137.70",13.813,23.00067,
"137.85",13.824,23.02567,
"138.00",13.833,23.05067,
"138.15",13.842,23.07567,
"138.30",13.848,23.10067,
"138.45",13.859,23.12567,
"138.60",13.87,23.15067,
"138.75",13.881,23.17567,
"138.90",13.89,23.20067,
"139.05",13.899,23.22567,
"139.20",13.912,23.25067,
"139.35",13.917,23.27567,
"139.50",13.924,23.30067,
"139.65",13.935,23.32567,
"139.80",13.947,23.35067,
"139.95",13.957,23.37567,
"140.10",13.962,23.40067,
"140.25",13.971,23.42567,
"140.40",13.981,23.45067,
"140.55",13.989,23.47567,
"140.70",13.999,23.50067,
"140.85",14.008,23.52567,
"141.00",14.022,23.551,
"141.15",14.03,23.576,
"141.30",14.038,23.60067,
"141.45",14.048,23.626,
"141.60",14.063,23.651,
"141.75",14.072,23.67567,
"141.90",14.08,23.701,
"142.05",14.092,23.72567,
"142.20",14.102,23.75067,
"142.35",14.111,23.77567,
"142.50",14.118,23.80067,
"142.65",14.13,23.82567,
"142.80",14.143,23.85067,
"142.95",14.153,23.87567,
"143.10",14.163,23.90067,
"143.25",14.171,23.92567,
"143.40",14.184,23.95067,
"143.55",14.192,23.97567,
"143.70",14.205,24.00033,
"143.85",14.216,24.02567,
"144.00",14.23,24.05067,
"144.15",14.239,24.07567,
"144.30",14.247,24.10033,
"144.45",14.256,24.12567,
"144.60",14.267,24.15067,
"144.75",14.279,24.17567,
"144.90",14.292,24.20067,
"145.05",14.303,24.22567,
"145.20",14.312,24.25067,
"145.35",14.324,24.27567,
"145.50",14.335,24.30067,
"145.65",14.346,24.32567,
"145.80",14.36,24.35067,
"145.95",14.372,24.37567,
"146.10",14.381,24.40067,
"146.25",14.395,24.42567,
"146.40",14.407,24.45067,
"146.55",14.416,24.47567,
"146.70",14.428,24.50067,
"146.85",14.438,24.52567,
"147.00",14.449,24.55067,
"147.15",14.457,24.57567,
"147.30",14.464,24.60067,
"147.45",14.475,24.626,
"147.60",14.488,24.651,
"147.75",14.495,24.676,
"147.90",14.506,24.701,
"148.05",14.513,24.72567,
"148.20",14.522,24.75067,
"148.35",14.527,24.77567,
"148.50",14.535,24.80067,
"148.65",14.545,24.82567,
"148.80",14.558,24.85067,
"148.95",14.566,24.87567,
"149.10",14.576,24.90067,
"149.25",14.583,24.92567,
"149.40",14.59,24.951,
"149.55",14.6,24.97567,
"149.70",14.608,25.00067,
"149.85",14.616,25.02567,
"150.00",14.627,25.05067,
"150.15",14.636,25.07567,
"150.30",14.643,25.10067,
"150.45",14.649,25.12567,
"150.60",14.659,25.15067,
"150.75",14.665,25.17567,
"150.90",14.673,25.20067,
"151.05",14.68,25.22567,
"151.20",14.689,25.25067,
"151.35",14.697,25.27567,
"151.50",14.707,25.30067,
"151.65",14.716,25.32567,
"151.80",14.728,25.35067,
"151.95",14.736,25.37567,
"152.10",14.745,25.40067,
"152.25",14.753,25.42567,
"152.40",14.764,25.45067,
"152.55",14.773,25.47567,
"152.70",14.783,25.50067,
"152.85",14.792,25.526,
"153.00",14.8,25.551,
"153.15",14.807,25.576,
"153.30",14.814,25.60067,
"153.45",14.824,25.62567,
"153.60",14.835,25.65067,
"153.75",14.845,25.67567,
"153.90",14.855,25.70067,
"154.05",14.862,25.72567,
"154.20",14.871,25.75067,
"154.35",14.88,25.77567,
"154.50",14.886,25.80067,
"154.65",14.892,25.826,
"154.80",14.907,25.851,
"154.95",14.916,25.876,
"155.10",14.921,25.901,
"155.25",14.931,25.926,
"155.40",14.94,25.951,
"155.55",14.946,25.976,
"155.70",14.953,26.00067,
"155.85",14.96,26.02567,
"156.00",14.97,26.05067,
"156.15",14.976,26.076,
"156.30",14.984,26.101,
"156.45",14.993,26.126,
"156.60",15.003,26.151,
"156.75",15.012,26.17567,
"156.90",15.022,26.201,
"157.05",15.026,26.226,
"157.20",15.037,26.251,
"157.35",15.042,26.276,
"157.50",15.049,26.30067,
"157.65",15.058,26.32567,
"157.80",15.069,26.351,
"157.95",15.077,26.376,
"158.10",15.083,26.401,
"158.25",15.089,26.426,
"158.40",15.095,26.451,
"158.55",15.098,26.47567,
"158.70",15.105,26.50067,
"158.85",15.118,26.52567,
"159.00",15.126,26.55067,
"159.15",15.133,26.57567,
"159.30",15.134,26.60067,
"159.45",15.142,26.62567,
"159.60",15.152,26.65067,
"159.75",15.162,26.67567,
"159.90",15.171,26.70067,
"160.05",15.176,26.72567,
"160.20",15.186,26.75067,
"160.35",15.192,26.77567,
"160.50",15.201,26.80067,
"160.65",15.212,26.82567,
"160.80",15.22,26.85067,
"160.95",15.228,26.87567,
"161.10",15.235,26.90067,
"161.25",15.241,26.92567,
"161.40",15.252,26.95067,
"161.55",15.262,26.97567,
"161.70",15.27,27.00067,
"161.85",15.282,27.02567,
"162.00",15.29,27.05067,
"162.15",15.298,27.07567,
"162.30",15.306,27.10067,
"162.45",15.312,27.126,
"162.60",15.323,27.151,
"162.75",15.333,27.176,
"162.90",15.34,27.201,
"163.05",15.345,27.226,
"163.20",15.352,27.25067,
"163.35",15.356,27.27567,
"163.50",15.363,27.30067,
"163.65",15.37,27.32567,
"163.80",15.383,27.35067,
"163.95",15.394,27.376,
"164.10",15.399,27.40067,
"164.25",15.405,27.42567,
"164.40",15.414,27.45067,
"164.55",15.419,27.47567,
"164.70",15.427,27.50067,
"164.85",15.438,27.526,
"165.00",15.447,27.551,
"165.15",15.456,27.576,
"165.30",15.459,27.601,
"165.45",15.464,27.62567,
"165.60",15.475,27.65067,
"165.75",15.481,27.676,
"165.90",15.489,27.701,
"166.05",15.498,27.72567,
"166.20",15.507,27.75067,
"166.35",15.515,27.77567,
"166.50",15.524,27.80067,
"166.65",15.534,27.82567,
"166.80",15.543,27.85067,
"166.95",15.551,27.87567,
"167.10",15.557,27.90067,
"167.25",15.566,27.92567,
"167.40",15.577,27.95067,
"167.55",15.585,27.976,
"167.70",15.597,28.00067,
"167.85",15.607,28.026,
"168.00",15.617,28.05067,
"168.15",15.627,28.076,
"168.30",15.633,28.10067,
"168.45",15.639,28.126,
"168.60",15.654,28.151,
"168.75",15.664,28.176,
"168.90",15.675,28.201,
"169.05",15.685,28.226,
"169.20",15.695,28.25067,
"169.35",15.702,28.27567,
"169.50",15.707,28.30067,
"169.65",15.717,28.32567,
"169.80",15.728,28.35067,
"169.95",15.74,28.37567,
"170.10",15.743,28.40067,
"170.25",15.745,28.42567,
"170.40",15.753,28.45067,
"170.55",15.76,28.47567,
"170.70",15.765,28.50067,
"170.85",15.77,28.52567,
"171.00",15.771,28.551,
"171.15",15.76,28.576,