File: exposed_monofilament_10cm_10mmpm_12nm_250esh_7.csv
"Test Name","Test Mode","Test Type","Control","Test Speed 1","Test Speed 2","Test Speed 3","Change Point 1","Change Point 2","Disp. Origin","Break and Limit Action","Sensitivity:","Level:"
"","Single","Tensile","Stroke",10,1,1,"Off","Off","Start","Stop",0,1

"Title","Sub title","Comment"
"","",""

"Shape:","Batch Size:","SubBatch Size:"
"Plate",1,1
"Name:","Thickness","Width","Gauge Length",
"Size Unit:","mm","mm","mm",
" 1 - 1","1.0000","1.0000","100.0000",

"Name",
"Parameter",
"Units",
" 1 - 1",

" 1- 1"
"Time","Force","Stroke",
"sec","N","mm",
"0.00",.001,0,
"0.20",.002,3.733333E-02,
"0.40",.014,7.433333E-02,
"0.60",.026,.1116667,
"0.80",.041,.1486667,
"1.00",.055,.1856667,
"1.20",.069,.2226667,
"1.40",.083,.2596667,
"1.60",.095,.2966667,
"1.80",.107,.3326667,
"2.00",.122,.3683333,
"2.20",.136,.4033333,
"2.40",.147,.4383333,
"2.60",.158,.4726667,
"2.80",.172,.507,
"3.00",.186,.541,
"3.20",.198,.575,
"3.40",.212,.609,
"3.60",.223,.6426666,
"3.80",.236,.6763333,
"4.00",.249,.71,
"4.20",.261,.7436666,
"4.40",.274,.777,
"4.60",.288,.8106667,
"4.80",.3,.844,
"5.00",.31,.8773333,
"5.20",.323,.9106666,
"5.40",.337,.9443333,
"5.60",.35,.9776667,
"5.80",.363,1.011,
"6.00",.373,1.044333,
"6.20",.387,1.077667,
"6.40",.401,1.111,
"6.60",.415,1.144333,
"6.80",.426,1.177667,
"7.00",.438,1.211,
"7.20",.451,1.244333,
"7.40",.463,1.277667,
"7.60",.477,1.311,
"7.80",.492,1.344333,
"8.00",.503,1.377667,
"8.20",.514,1.411,
"8.40",.529,1.444667,
"8.60",.543,1.477667,
"8.80",.558,1.511333,
"9.00",.568,1.544667,
"9.20",.583,1.577667,
"9.40",.593,1.611,
"9.60",.608,1.644333,
"9.80",.621,1.678,
"10.00",.634,1.711333,
"10.20",.647,1.744333,
"10.40",.663,1.778,
"10.60",.675,1.811,
"10.80",.689,1.844333,
"11.00",.7,1.877667,
"11.20",.716,1.911,
"11.40",.729,1.944333,
"11.60",.741,1.978,
"11.80",.757,2.011333,
"12.00",.774,2.044667,
"12.20",.784,2.078,
"12.40",.8,2.111333,
"12.60",.813,2.144667,
"12.80",.828,2.178,
"13.00",.841,2.211333,
"13.20",.858,2.244667,
"13.40",.872,2.278,
"13.60",.886,2.311333,
"13.80",.9,2.344667,
"14.00",.913,2.378,
"14.20",.93,2.411,
"14.40",.942,2.444333,
"14.60",.956,2.477667,
"14.80",.972,2.511,
"15.00",.99,2.544333,
"15.20",1.004,2.577667,
"15.40",1.019,2.611333,
"15.60",1.038,2.644333,
"15.80",1.052,2.678,
"16.00",1.066,2.711,
"16.20",1.083,2.744333,
"16.40",1.096,2.778,
"16.60",1.112,2.811333,
"16.80",1.131,2.844667,
"17.00",1.144,2.878,
"17.20",1.163,2.911,
"17.40",1.177,2.944667,
"17.60",1.191,2.977667,
"17.80",1.21,3.011,
"18.00",1.224,3.044667,
"18.20",1.242,3.078,
"18.40",1.259,3.111333,
"18.60",1.275,3.144667,
"18.80",1.29,3.178,
"19.00",1.308,3.211,
"19.20",1.323,3.244333,
"19.40",1.343,3.277667,
"19.60",1.358,3.311,
"19.80",1.377,3.344667,
"20.00",1.394,3.378,
"20.20",1.409,3.411333,
"20.40",1.428,3.444667,
"20.60",1.447,3.477667,
"20.80",1.465,3.511333,
"21.00",1.482,3.544667,
"21.20",1.501,3.578,
"21.40",1.518,3.611333,
"21.60",1.537,3.644667,
"21.80",1.556,3.678,
"22.00",1.574,3.711333,
"22.20",1.593,3.744667,
"22.40",1.611,3.778,
"22.60",1.63,3.811,
"22.80",1.649,3.844333,
"23.00",1.668,3.877667,
"23.20",1.686,3.911,
"23.40",1.707,3.944333,
"23.60",1.727,3.977667,
"23.80",1.747,4.011,
"24.00",1.766,4.044666,
"24.20",1.785,4.078,
"24.40",1.804,4.111333,
"24.60",1.825,4.144667,
"24.80",1.846,4.178,
"25.00",1.866,4.211,
"25.20",1.887,4.244667,
"25.40",1.908,4.278,
"25.60",1.929,4.311333,
"25.80",1.95,4.344666,
"26.00",1.974,4.378,
"26.20",1.992,4.411333,
"26.40",2.013,4.444666,
"26.60",2.039,4.478,
"26.80",2.059,4.511333,
"27.00",2.083,4.544333,
"27.20",2.105,4.577666,
"27.40",2.128,4.611333,
"27.60",2.149,4.644667,
"27.80",2.169,4.678,
"28.00",2.199,4.711,
"28.20",2.216,4.744333,
"28.40",2.24,4.778,
"28.60",2.265,4.811333,
"28.80",2.291,4.844666,
"29.00",2.313,4.877666,
"29.20",2.336,4.911,
"29.40",2.36,4.944333,
"29.60",2.383,4.978,
"29.80",2.409,5.011,
"30.00",2.431,5.044666,
"30.20",2.457,5.077666,
"30.40",2.483,5.111,
"30.60",2.507,5.144333,
"30.80",2.536,5.177667,
"31.00",2.559,5.211,
"31.20",2.584,5.244333,
"31.40",2.607,5.278,
"31.60",2.636,5.311333,
"31.80",2.664,5.344666,
"32.00",2.686,5.378,
"32.20",2.714,5.411333,
"32.40",2.739,5.444666,
"32.60",2.767,5.478,
"32.80",2.794,5.511,
"33.00",2.821,5.544666,
"33.20",2.846,5.577666,
"33.40",2.877,5.611333,
"33.60",2.904,5.644667,
"33.80",2.932,5.678,
"34.00",2.962,5.711,
"34.20",2.988,5.744333,
"34.40",3.014,5.777667,
"34.60",3.042,5.811,
"34.80",3.072,5.844333,
"35.00",3.099,5.877666,
"35.20",3.129,5.911,
"35.40",3.159,5.944333,
"35.60",3.187,5.977666,
"35.80",3.219,6.011,
"36.00",3.249,6.044333,
"36.20",3.276,6.077666,
"36.40",3.306,6.111,
"36.60",3.337,6.144333,
"36.80",3.365,6.177667,
"37.00",3.399,6.211,
"37.20",3.426,6.244333,
"37.40",3.455,6.277667,
"37.60",3.485,6.311333,
"37.80",3.516,6.344666,
"38.00",3.55,6.377666,
"38.20",3.579,6.411,
"38.40",3.61,6.444666,
"38.60",3.642,6.477666,
"38.80",3.668,6.511,
"39.00",3.686,6.544333,
"39.20",3.701,6.577666,
"39.40",3.718,6.611,
"39.60",3.744,6.644333,
"39.80",3.778,6.677667,
"40.00",3.808,6.711,
"40.20",3.841,6.744333,
"40.40",3.872,6.777667,
"40.60",3.909,6.811,
"40.80",3.945,6.844666,
"41.00",3.975,6.878,
"41.20",4.006,6.911333,
"41.40",4.038,6.944333,
"41.60",4.074,6.977666,
"41.80",4.104,7.011,
"42.00",4.135,7.044333,
"42.20",4.17,7.077666,
"42.40",4.202,7.111,
"42.60",4.237,7.144333,
"42.80",4.271,7.178,
"43.00",4.302,7.211,
"43.20",4.334,7.244333,
"43.40",4.369,7.278,
"43.60",4.399,7.311333,
"43.80",4.434,7.344666,
"44.00",4.466,7.377666,
"44.20",4.504,7.411,
"44.40",4.534,7.444333,
"44.60",4.567,7.478,
"44.80",4.603,7.511,
"45.00",4.632,7.544666,
"45.20",4.665,7.578,
"45.40",4.697,7.611333,
"45.60",4.726,7.644333,
"45.80",4.757,7.677667,
"46.00",4.792,7.711333,
"46.20",4.821,7.744333,
"46.40",4.853,7.777667,
"46.60",4.885,7.811,
"46.80",4.92,7.844333,
"47.00",4.95,7.877666,
"47.20",4.979,7.911,
"47.40",5.012,7.944666,
"47.60",5.044,7.978,
"47.80",5.078,8.011001,
"48.00",5.11,8.044333,
"48.20",5.14,8.077667,
"48.40",5.172,8.111,
"48.60",5.202,8.144334,
"48.80",5.231,8.177667,
"49.00",5.263,8.211,
"49.20",5.293,8.244333,
"49.40",5.323,8.277667,
"49.60",5.358,8.311,
"49.80",5.39,8.344334,
"50.00",5.419,8.377667,
"50.20",5.451,8.411,
"50.40",5.482,8.444334,
"50.60",5.512,8.477667,
"50.80",5.545,8.511333,
"51.00",5.575,8.544667,
"51.20",5.604,8.577667,
"51.40",5.633,8.611334,
"51.60",5.666,8.644667,
"51.80",5.699,8.678,
"52.00",5.727,8.711333,
"52.20",5.757,8.744333,
"52.40",5.786,8.778,
"52.60",5.819,8.811,
"52.80",5.847,8.844666,
"53.00",5.877,8.878,
"53.20",5.908,8.911334,
"53.40",5.937,8.944667,
"53.60",5.967,8.978001,
"53.80",5.997,9.011333,
"54.00",6.026,9.044667,
"54.20",6.052,9.078,
"54.40",6.085,9.111334,
"54.60",6.114,9.144667,
"54.80",6.145,9.178,
"55.00",6.173,9.211,
"55.20",6.199,9.244333,
"55.40",6.23,9.277667,
"55.60",6.264,9.311334,
"55.80",6.293,9.344334,
"56.00",6.32,9.378,
"56.20",6.347,9.411,
"56.40",6.377,9.444334,
"56.60",6.404,9.477667,
"56.80",6.434,9.511001,
"57.00",6.461,9.544333,
"57.20",6.492,9.577667,
"57.40",6.52,9.611,
"57.60",6.548,9.644667,
"57.80",6.576,9.677667,
"58.00",6.601,9.711,
"58.20",6.631,9.744667,
"58.40",6.659,9.778,
"58.60",6.687,9.811,
"58.80",6.714,9.844334,
"59.00",6.743,9.877667,
"59.20",6.767,9.911,
"59.40",6.797,9.944334,
"59.60",6.823,9.977667,
"59.80",6.85,10.01133,
"60.00",6.88,10.04433,
"60.20",6.907,10.07767,
"60.40",6.933,10.111,
"60.60",6.961,10.14433,
"60.80",6.985,10.17767,
"61.00",7.012,10.211,
"61.20",7.036,10.24433,
"61.40",7.063,10.27767,
"61.60",7.09,10.31133,
"61.80",7.118,10.34433,
"62.00",7.143,10.37767,
"62.20",7.168,10.411,
"62.40",7.194,10.44433,
"62.60",7.222,10.47767,
"62.80",7.248,10.511,
"63.00",7.274,10.54433,
"63.20",7.298,10.57767,
"63.40",7.323,10.611,
"63.60",7.35,10.64433,
"63.80",7.374,10.67767,
"64.00",7.398,10.711,
"64.20",7.424,10.74467,
"64.40",7.448,10.778,
"64.60",7.472,10.811,
"64.80",7.496,10.84433,
"65.00",7.521,10.87767,
"65.20",7.543,10.911,
"65.40",7.568,10.94433,
"65.60",7.591,10.97767,
"65.80",7.62,11.011,
"66.00",7.64,11.04467,
"66.20",7.66,11.07767,
"66.40",7.685,11.111,
"66.60",7.71,11.14433,
"66.80",7.733,11.178,
"67.00",7.757,11.21133,
"67.20",7.781,11.24467,
"67.40",7.799,11.278,
"67.60",7.823,11.311,
"67.80",7.847,11.34467,
"68.00",7.869,11.37767,
"68.20",7.889,11.411,
"68.40",7.913,11.44467,
"68.60",7.934,11.47767,
"68.80",7.96,11.51133,
"69.00",7.982,11.54433,
"69.20",8.002,11.57767,
"69.40",8.022,11.611,
"69.60",8.047,11.64433,
"69.80",8.069,11.678,
"70.00",8.091,11.71133,
"70.20",8.113,11.74433,
"70.40",8.134,11.778,
"70.60",8.159,11.81133,
"70.80",8.179,11.84467,
"71.00",8.2,11.87767,
"71.20",8.218,11.911,
"71.40",8.238,11.94433,
"71.60",8.263,11.97767,
"71.80",8.284,12.011,
"72.00",8.305,12.04467,
"72.20",8.322,12.078,
"72.40",8.334,12.11133,
"72.60",8.343,12.14467,
"72.80",8.355,12.178,
"73.00",8.363,12.211,
"73.20",8.373,12.24433,
"73.40",8.383,12.278,
"73.60",8.395,12.31133,
"73.80",8.416,12.34467,
"74.00",8.432,12.378,
"74.20",8.453,12.411,
"74.40",8.473,12.44433,
"74.60",8.495,12.47767,
"74.80",8.52,12.511,
"75.00",8.544,12.54433,
"75.20",8.569,12.57767,
"75.40",8.591,12.611,
"75.60",8.618,12.64433,
"75.80",8.643,12.67767,
"76.00",8.667,12.71133,
"76.20",8.69,12.74433,
"76.40",8.711,12.77767,
"76.60",8.741,12.811,
"76.80",8.767,12.84433,
"77.00",8.787,12.87767,
"77.20",8.81,12.91133,
"77.40",8.835,12.94467,
"77.60",8.855,12.97767,
"77.80",8.879,13.011,
"78.00",8.901,13.04433,
"78.20",8.922,13.07767,
"78.40",8.945,13.111,
"78.60",8.968,13.14433,
"78.80",8.989,13.17767,
"79.00",9.015,13.211,
"79.20",9.034,13.24433,
"79.40",9.053,13.278,
"79.60",9.075,13.311,
"79.80",9.096,13.34433,
"80.00",9.117,13.37767,
"80.20",9.134,13.41133,
"80.40",9.158,13.44467,
"80.60",9.179,13.47767,
"80.80",9.199,13.51133,
"81.00",9.218,13.54467,
"81.20",9.239,13.578,
"81.40",9.256,13.61133,
"81.60",9.282,13.64467,
"81.80",9.303,13.678,
"82.00",9.322,13.71133,
"82.20",9.341,13.74467,
"82.40",9.363,13.778,
"82.60",9.385,13.811,
"82.80",9.405,13.84433,
"83.00",9.429,13.87767,
"83.20",9.447,13.911,
"83.40",9.464,13.94433,
"83.60",9.484,13.97767,
"83.80",9.51,14.011,
"84.00",9.529,14.04433,
"84.20",9.546,14.07767,
"84.40",9.571,14.111,
"84.60",9.59,14.14433,
"84.80",9.611,14.178,
"85.00",9.631,14.21133,
"85.20",9.651,14.24467,
"85.40",9.671,14.278,
"85.60",9.69,14.311,
"85.80",9.711,14.34467,
"86.00",9.73,14.378,
"86.20",9.751,14.41133,
"86.40",9.772,14.44467,
"86.60",9.791,14.478,
"86.80",9.814,14.51133,
"87.00",9.832,14.54467,
"87.20",9.851,14.57767,
"87.40",9.871,14.611,
"87.60",9.887,14.64433,
"87.80",9.907,14.67767,
"88.00",9.929,14.71133,
"88.20",9.95,14.74433,
"88.40",9.971,14.778,
"88.60",9.989,14.811,
"88.80",10.007,14.84433,
"89.00",10.029,14.87767,
"89.20",10.045,14.911,
"89.40",10.066,14.94433,
"89.60",10.087,14.978,
"89.80",10.107,15.011,
"90.00",10.126,15.04433,
"90.20",10.145,15.07767,
"90.40",10.166,15.111,
"90.60",10.186,15.14433,
"90.80",10.208,15.17767,
"91.00",10.227,15.211,
"91.20",10.244,15.24433,
"91.40",10.262,15.27767,
"91.60",10.283,15.311,
"91.80",10.306,15.34433,
"92.00",10.326,15.37767,
"92.20",10.344,15.41133,
"92.40",10.362,15.44433,
"92.60",10.382,15.47767,
"92.80",10.401,15.511,
"93.00",10.421,15.54433,
"93.20",10.438,15.57767,
"93.40",10.459,15.61133,
"93.60",10.476,15.64467,
"93.80",10.495,15.678,
"94.00",10.51,15.711,
"94.20",10.529,15.74433,
"94.40",10.549,15.77767,
"94.60",10.567,15.811,
"94.80",10.587,15.84433,
"95.00",10.605,15.87767,
"95.20",10.618,15.911,
"95.40",10.637,15.94433,
"95.60",10.656,15.978,
"95.80",10.677,16.01133,
"96.00",10.691,16.04467,
"96.20",10.706,16.078,
"96.40",10.726,16.11133,
"96.60",10.747,16.14467,
"96.80",10.763,16.178,
"97.00",10.781,16.211,
"97.20",10.795,16.24433,
"97.40",10.813,16.27767,
"97.60",10.835,16.311,
"97.80",10.852,16.34433,
"98.00",10.87,16.37767,
"98.20",10.886,16.41133,
"98.40",10.907,16.44467,
"98.60",10.924,16.47767,
"98.80",10.941,16.51133,
"99.00",10.961,16.54433,
"99.20",10.976,16.57767,
"99.40",10.996,16.611,
"99.60",11.012,16.64433,
"99.80",11.032,16.67767,
"100.00",11.047,16.711,
"100.20",11.065,16.74433,
"100.40",11.083,16.77767,
"100.60",11.101,16.811,
"100.80",11.122,16.84467,
"101.00",11.139,16.87767,
"101.20",11.155,16.911,
"101.40",11.175,16.94433,
"101.60",11.193,16.97767,
"101.80",11.216,17.011,
"102.00",11.233,17.04433,
"102.20",11.248,17.07767,
"102.40",11.265,17.111,
"102.60",11.283,17.14433,
"102.80",11.301,17.17767,
"103.00",11.319,17.211,
"103.20",11.336,17.24433,
"103.40",11.351,17.27767,
"103.60",11.37,17.31133,
"103.80",11.389,17.34433,
"104.00",11.407,17.37767,
"104.20",11.421,17.411,
"104.40",11.44,17.44433,
"104.60",11.458,17.47767,
"104.80",11.474,17.511,
"105.00",11.493,17.54433,
"105.20",11.509,17.57767,
"105.40",11.527,17.61133,
"105.60",11.543,17.64433,
"105.80",11.562,17.678,
"106.00",11.578,17.71133,
"106.20",11.592,17.74467,
"106.40",11.607,17.778,
"106.60",11.628,17.811,
"106.80",11.645,17.84433,
"107.00",11.662,17.87767,
"107.20",11.68,17.911,
"107.40",11.697,17.94467,
"107.60",11.713,17.978,
"107.80",11.732,18.01133,
"108.00",11.752,18.04467,
"108.20",11.767,18.07767,
"108.40",11.781,18.111,
"108.60",11.799,18.14433,
"108.80",11.819,18.17767,
"109.00",11.834,18.211,
"109.20",11.849,18.24467,
"109.40",11.864,18.278,
"109.60",11.883,18.311,
"109.80",11.899,18.34467,
"110.00",11.916,18.37767,
"110.20",11.932,18.411,
"110.40",11.948,18.44467,
"110.60",11.968,18.47767,
"110.80",11.983,18.511,
"111.00",11.998,18.54433,
"111.20",12.014,18.57767,
"111.40",12.029,18.61133,
"111.60",12.046,18.64467,
"111.80",12.066,18.678,
"112.00",12.082,18.71133,
"112.20",12.097,18.74433,
"112.40",12.113,18.77767,
"112.60",12.129,18.811,
"112.80",12.148,18.84467,
"113.00",12.162,18.87767,
"113.20",12.18,18.911,
"113.40",12.196,18.94433,
"113.60",12.214,18.97767,
"113.80",12.23,19.01133,
"114.00",12.245,19.04467,
"114.20",12.263,19.078,
"114.40",12.279,19.11133,
"114.60",12.296,19.14467,
"114.80",12.313,19.178,
"115.00",12.328,19.21133,
"115.20",12.344,19.24467,
"115.40",12.359,19.278,
"115.60",12.376,19.31133,
"115.80",12.397,19.34467,
"116.00",12.408,19.378,
"116.20",12.423,19.41133,
"116.40",12.437,19.44467,
"116.60",12.453,19.478,
"116.80",12.471,19.51133,
"117.00",12.487,19.54467,
"117.20",12.5,19.578,
"117.40",12.516,19.61133,
"117.60",12.534,19.64467,
"117.80",12.551,19.678,
"118.00",12.566,19.71133,
"118.20",12.577,19.74467,
"118.40",12.589,19.778,
"118.60",12.607,19.81133,
"118.80",12.624,19.84467,
"119.00",12.636,19.87767,
"119.20",12.651,19.911,
"119.40",12.665,19.94433,
"119.60",12.681,19.97767,
"119.80",12.699,20.01133,
"120.00",12.712,20.04467,
"120.20",12.726,20.078,
"120.40",12.742,20.11133,
"120.60",12.761,20.14433,
"120.80",12.776,20.178,
"121.00",12.787,20.211,
"121.20",12.802,20.24467,
"121.40",12.819,20.27767,
"121.60",12.835,20.311,
"121.80",12.854,20.34433,
"122.00",12.87,20.378,
"122.20",12.883,20.41133,
"122.40",12.897,20.44467,
"122.60",12.914,20.478,
"122.80",12.928,20.51133,
"123.00",12.946,20.54433,
"123.20",12.958,20.57767,
"123.40",12.97,20.611,
"123.60",12.984,20.64467,
"123.80",13.002,20.67767,
"124.00",13.016,20.71133,
"124.20",13.03,20.74467,
"124.40",13.043,20.778,
"124.60",13.061,20.811,
"124.80",13.075,20.84433,
"125.00",13.09,20.87767,
"125.20",13.102,20.911,
"125.40",13.118,20.94433,
"125.60",13.134,20.978,
"125.80",13.149,21.011,
"126.00",13.164,21.04433,
"126.20",13.176,21.078,
"126.40",13.19,21.11133,
"126.60",13.206,21.14433,
"126.80",13.221,21.17767,
"127.00",13.235,21.211,
"127.20",13.247,21.24467,
"127.40",13.262,21.27767,
"127.60",13.274,21.31133,
"127.80",13.291,21.34433,
"128.00",13.306,21.37767,
"128.20",13.321,21.411,
"128.40",13.334,21.44467,
"128.60",13.347,21.478,
"128.80",13.364,21.51133,
"129.00",13.377,21.54433,
"129.20",13.39,21.57767,
"129.40",13.405,21.611,
"129.60",13.418,21.64433,
"129.80",13.434,21.67767,
"130.00",13.448,21.71133,
"130.20",13.461,21.74467,
"130.40",13.476,21.778,
"130.60",13.492,21.811,
"130.80",13.506,21.84467,
"131.00",13.522,21.87767,
"131.20",13.532,21.911,
"131.40",13.545,21.94433,
"131.60",13.558,21.97767,
"131.80",13.571,22.011,
"132.00",13.587,22.04467,
"132.20",13.598,22.07767,
"132.40",13.614,22.111,
"132.60",13.629,22.14433,
"132.80",13.642,22.17767,
"133.00",13.66,22.211,
"133.20",13.673,22.24433,
"133.40",13.683,22.27767,
"133.60",13.699,22.311,
"133.80",13.715,22.34433,
"134.00",13.727,22.37767,
"134.20",13.74,22.411,
"134.40",13.756,22.44467,
"134.60",13.772,22.47767,
"134.80",13.786,22.511,
"135.00",13.8,22.54433,
"135.20",13.81,22.57767,
"135.40",13.828,22.611,
"135.60",13.843,22.64433,
"135.80",13.856,22.67767,
"136.00",13.868,22.711,
"136.20",13.882,22.74433,
"136.40",13.894,22.77767,
"136.60",13.912,22.811,
"136.80",13.925,22.84433,
"137.00",13.94,22.87767,
"137.20",13.951,22.911,
"137.40",13.963,22.94433,
"137.60",13.979,22.97767,
"137.80",13.992,23.011,
"138.00",14.007,23.04467,
"138.20",14.019,23.078,
"138.40",14.034,23.11133,
"138.60",14.047,23.14433,
"138.80",14.06,23.178,
"139.00",14.074,23.21133,
"139.20",14.088,23.24467,
"139.40",14.1,23.278,
"139.60",14.116,23.31133,
"139.80",14.129,23.34467,
"140.00",14.139,23.37767,
"140.20",14.154,23.411,
"140.40",14.167,23.44433,
"140.60",14.182,23.47767,
"140.80",14.196,23.511,
"141.00",14.208,23.54433,
"141.20",14.223,23.57767,
"141.40",14.235,23.611,
"141.60",14.248,23.64433,
"141.80",14.264,23.678,
"142.00",14.277,23.71133,
"142.20",14.288,23.74467,
"142.40",14.299,23.778,
"142.60",14.313,23.811,
"142.80",14.327,23.84433,
"143.00",14.342,23.87767,
"143.20",14.354,23.911,
"143.40",14.363,23.94467,
"143.60",14.378,23.97767,
"143.80",14.394,24.011,
"144.00",14.407,24.04467,
"144.20",14.419,24.07767,
"144.40",14.433,24.111,
"144.60",14.446,24.14467,
"144.80",14.461,24.178,
"145.00",14.471,24.211,
"145.20",14.483,24.24433,
"145.40",14.496,24.278,
"145.60",14.51,24.31133,
"145.80",14.525,24.34467,
"146.00",14.537,24.378,
"146.20",14.55,24.41133,
"146.40",14.563,24.44433,
"146.60",14.575,24.47767,
"146.80",14.589,24.511,
"147.00",14.605,24.54433,
"147.20",14.617,24.57767,
"147.40",14.627,24.611,
"147.60",14.64,24.64433,
"147.80",14.654,24.67767,
"148.00",14.666,24.711,
"148.20",14.676,24.74433,
"148.40",14.688,24.77767,
"148.60",14.703,24.811,
"148.80",14.716,24.84433,
"149.00",14.724,24.87767,
"149.20",14.737,24.911,
"149.40",14.744,24.94433,
"149.60",14.76,24.97767,
"149.80",14.774,25.011,
"150.00",14.782,25.04433,
"150.20",14.793,25.07767,
"150.40",14.807,25.11133,
"150.60",14.823,25.14467,
"150.80",14.836,25.178,
"151.00",14.848,25.21133,
"151.20",14.859,25.24433,
"151.40",14.869,25.27767,
"151.60",14.883,25.31133,
"151.80",14.898,25.34467,
"152.00",14.91,25.378,
"152.20",14.921,25.41133,
"152.40",14.933,25.44467,
"152.60",14.944,25.478,
"152.80",14.959,25.51133,
"153.00",14.974,25.54467,
"153.20",14.983,25.57767,
"153.40",14.995,25.611,
"153.60",15.006,25.64433,
"153.80",15.019,25.678,
"154.00",15.03,25.71133,
"154.20",15.041,25.74433,
"154.40",15.053,25.77767,
"154.60",15.067,25.811,
"154.80",15.077,25.84433,
"155.00",15.087,25.87767,
"155.20",15.097,25.911,
"155.40",15.111,25.94433,
"155.60",15.125,25.97767,
"155.80",15.135,26.011,
"156.00",15.146,26.04467,
"156.20",15.156,26.078,
"156.40",15.169,26.11133,
"156.60",15.182,26.14433,
"156.80",15.194,26.178,
"157.00",15.207,26.211,
"157.20",15.215,26.24433,
"157.40",15.228,26.27767,
"157.60",15.24,26.311,
"157.80",15.253,26.34433,
"158.00",15.266,26.37767,
"158.20",15.277,26.411,
"158.40",15.287,26.44467,
"158.60",15.298,26.47767,
"158.80",15.31,26.511,
"159.00",15.32,26.54433,
"159.20",15.334,26.57767,
"159.40",15.345,26.611,
"159.60",15.356,26.64433,
"159.80",15.369,26.67767,
"160.00",15.378,26.711,
"160.20",15.387,26.74433,
"160.40",15.399,26.77767,
"160.60",15.414,26.811,
"160.80",15.426,26.84433,
"161.00",15.437,26.87767,
"161.20",15.446,26.911,
"161.40",15.456,26.94433,
"161.60",15.469,26.97767,
"161.80",15.482,27.011,
"162.00",15.492,27.04433,
"162.20",15.502,27.07767,
"162.40",15.512,27.11133,
"162.60",15.528,27.14433,
"162.80",15.536,27.17767,
"163.00",15.551,27.211,
"163.20",15.559,27.24433,
"163.40",15.568,27.27767,
"163.60",15.58,27.311,
"163.80",15.593,27.34433,
"164.00",15.602,27.37767,
"164.20",15.616,27.411,
"164.40",15.627,27.44433,
"164.60",15.639,27.47767,
"164.80",15.65,27.511,
"165.00",15.663,27.54433,
"165.20",15.67,27.57767,
"165.40",15.682,27.61133,
"165.60",15.697,27.64467,
"165.80",15.711,27.678,
"166.00",15.72,27.71133,
"166.20",15.726,27.74433,
"166.40",15.736,27.778,
"166.60",15.749,27.811,
"166.80",15.763,27.84467,
"167.00",15.773,27.878,
"167.20",15.78,27.911,
"167.40",15.788,27.94433,
"167.60",15.8,27.978,
"167.80",15.812,28.011,
"168.00",15.822,28.04467,
"168.20",15.83,28.07767,
"168.40",15.841,28.11133,
"168.60",15.851,28.14467,
"168.80",15.862,28.178,
"169.00",15.874,28.21133,
"169.20",15.885,28.24467,
"169.40",15.895,28.278,
"169.60",15.907,28.31133,
"169.80",15.919,28.34467,
"170.00",15.928,28.378,
"170.20",15.937,28.41133,
"170.40",15.947,28.44467,
"170.60",15.959,28.478,
"170.80",15.969,28.51133,
"171.00",15.976,28.54433,
"171.20",15.988,28.57767,
"171.40",15.998,28.611,
"171.60",16.008,28.64433,
"171.80",16.023,28.67767,
"172.00",16.037,28.711,
"172.20",16.044,28.74467,
"172.40",16.054,28.778,
"172.60",16.066,28.81133,
"172.80",16.077,28.84467,
"173.00",16.089,28.878,
"173.20",16.098,28.911,
"173.40",16.108,28.94433,
"173.60",16.12,28.97767,
"173.80",16.129,29.011,
"174.00",16.137,29.04433,
"174.20",16.13,29.07767,
"174.40",16.124,29.111,
"174.60",16.125,29.14433,
"174.80",16.127,29.17767,
"175.00",16.128,29.211,
"175.20",16.132,29.24433,
"175.40",16.135,29.27767,
"175.60",16.145,29.31133,
"175.80",16.155,29.34433,
"176.00",16.163,29.37767,
"176.20",16.168,29.41133,
"176.40",16.178,29.44467,
"176.60",16.189,29.47767,
"176.80",16.204,29.51133,
"177.00",16.215,29.54433,
"177.20",16.224,29.57767,
"177.40",16.233,29.611,
"177.60",16.245,29.64433,
"177.80",16.258,29.67767,
"178.00",16.269,29.711,
"178.20",16.277,29.74467,
"178.40",16.289,29.778,
"178.60",16.3,29.811,
"178.80",16.313,29.84433,
"179.00",16.322,29.87767,
"179.20",16.33,29.911,
"179.40",16.344,29.94467,
"179.60",16.358,29.978,
"179.80",16.371,30.01133,
"180.00",16.382,30.04467,
"180.20",16.393,30.078,
"180.40",16.406,30.11133,
"180.60",16.417,30.14467,
"180.80",16.43,30.178,
"181.00",16.44,30.21133,
"181.20",16.45,30.24433,
"181.40",16.46,30.278,
"181.60",16.47,30.31133,
"181.80",16.485,30.34467,
"182.00",16.498,30.378,
"182.20",16.509,30.41133,
"182.40",16.515,30.44467,
"182.60",16.525,30.478,
"182.80",16.541,30.51133,
"183.00",16.55,30.54433,
"183.20",16.558,30.57767,
"183.40",16.569,30.611,
"183.60",16.579,30.64433,
"183.80",16.593,30.67767,
"184.00",16.602,30.71133,
"184.20",16.609,30.74467,
"184.40",16.619,30.778,
"184.60",16.63,30.81133,
"184.80",16.639,30.84467,
"185.00",16.651,30.87767,
"185.20",16.659,30.91133,
"185.40",16.669,30.94467,
"185.60",16.679,30.978,
"185.80",16.69,31.01133,
"186.00",16.698,31.04467,
"186.20",16.708,31.078,
"186.40",16.715,31.11133,
"186.60",16.724,31.14467,
"186.80",16.737,31.178,
"187.00",16.748,31.211,
"187.20",16.755,31.24433,
"187.40",16.763,31.27767,
"187.60",16.773,31.311,
"187.80",16.786,31.34467,
"188.00",16.799,31.378,
"188.20",16.808,31.411,
"188.40",16.813,31.44433,
"188.60",16.822,31.478,
"188.80",16.834,31.51133,
"189.00",16.842,31.54467,
"189.20",16.85,31.578,
"189.40",16.862,31.61133,
"189.60",16.871,31.64433,
"189.80",16.88,31.678,
"190.00",16.886,31.711,
"190.20",16.894,31.74433,
"190.40",16.906,31.778,
"190.60",16.916,31.81133,
"190.80",16.925,31.84467,
"191.00",16.932,31.878,
"191.20",16.938,31.911,
"191.40",16.945,31.94467,
"191.60",16.956,31.97767,
"191.80",16.967,32.01133,
"192.00",16.976,32.04467,
"192.20",16.984,32.078,
"192.40",16.989,32.11133,
"192.60",16.999,32.14466,
"192.80",17.008,32.178,
"193.00",17.018,32.211,
"193.20",17.024,32.24433,
"193.40",17.03,32.27766,
"193.60",17.039,32.31133,
"193.80",17.05,32.34467,
"194.00",17.059,32.37767,
"194.20",17.064,32.41133,
"194.40",17.071,32.44466,
"194.60",17.086,32.47766,
"194.80",17.094,32.51133,
"195.00",17.103,32.54467,
"195.20",17.112,32.578,
"195.40",17.118,32.61133,
"195.60",17.131,32.64466,
"195.80",17.14,32.678,
"196.00",17.145,32.71133,
"196.20",17.152,32.74466,
"196.40",17.164,32.778,
"196.60",17.172,32.811,
"196.80",17.183,32.84467,
"197.00",17.192,32.878,
"197.20",17.204,32.91133,
"197.40",17.212,32.94466,
"197.60",17.223,32.978,
"197.80",17.234,33.01133,
"198.00",17.243,33.04467,
"198.20",17.249,33.078,
"198.40",17.26,33.11133,
"198.60",17.268,33.14466,
"198.80",17.28,33.178,
"199.00",17.287,33.21133,
"199.20",17.295,33.24466,
"199.40",17.304,33.278,
"199.60",17.313,33.31133,
"199.80",17.321,33.34467,
"200.00",17.327,33.378,
"200.20",17.324,33.41133,
"200.40",17.325,33.44466,
"200.60",17.332,33.478,
"200.80",17.338,33.511,
"201.00",17.339,33.54433,
"201.20",17.345,33.578,
"201.40",17.352,33.61133,
"201.60",17.364,33.64466,
"201.80",17.376,33.67767,
"202.00",17.383,33.71133,
"202.20",17.389,33.74466,
"202.40",17.393,33.778,
"202.60",17.404,33.81133,
"202.80",17.417,33.84467,
"203.00",17.424,33.87767,
"203.20",17.433,33.911,
"203.40",17.441,33.94466,
"203.60",17.448,33.978,
"203.80",17.462,34.01133,
"204.00",17.47,34.04467,
"204.20",17.477,34.078,
"204.40",17.49,34.11133,
"204.60",17.5,34.14466,
"204.80",17.51,34.178,
"205.00",17.519,34.21133,
"205.20",17.529,34.24466,
"205.40",17.538,34.278,
"205.60",17.546,34.31133,
"205.80",17.556,34.34467,
"206.00",17.564,34.37767,
"206.20",17.57,34.411,
"206.40",17.576,34.44433,
"206.60",17.587,34.47766,
"206.80",17.597,34.511,
"207.00",17.606,34.54433,
"207.20",17.612,34.578,
"207.40",17.621,34.611,
"207.60",17.629,34.64433,
"207.80",17.641,34.67767,
"208.00",17.65,34.71133,
"208.20",17.656,34.74433,
"208.40",17.664,34.77766,
"208.60",17.672,34.811,
"208.80",17.681,34.84433,
"209.00",17.693,34.87767,
"209.20",17.698,34.911,
"209.40",17.706,34.94433,
"209.60",17.718,34.97766,
"209.80",17.726,35.011,
"210.00",17.736,35.04433,
"210.20",17.742,35.07766,
"210.40",17.753,35.111,
"210.60",17.763,35.14433,
"210.80",17.775,35.17767,
"211.00",17.78,35.211,
"211.20",17.789,35.24433,
"211.40",17.799,35.27766,
"211.60",17.81,35.311,
"211.80",17.821,35.34433,
"212.00",17.831,35.37767,
"212.20",17.835,35.411,
"212.40",17.842,35.44433,
"212.60",17.852,35.47766,
"212.80",17.863,35.511,
"213.00",17.87,35.54433,
"213.20",17.877,35.57766,
"213.40",17.885,35.611,
"213.60",17.892,35.64433,
"213.80",17.901,35.67767,
"214.00",17.907,35.711,
"214.20",17.912,35.74433,
"214.40",17.922,35.77766,
"214.60",17.931,35.811,
"214.80",17.94,35.84433,
"215.00",17.949,35.87767,
"215.20",17.957,35.911,
"215.40",17.962,35.94433,
"215.60",17.977,35.97766,
"215.80",17.985,36.01133,
"216.00",17.99,36.04467,
"216.20",17.996,36.07766,
"216.40",18.004,36.111,
"216.60",18.012,36.14433,
"216.80",18.021,36.17767,
"217.00",18.029,36.211,
"217.20",18.035,36.24433,
"217.40",18.041,36.27766,
"217.60",18.049,36.311,
"217.80",18.06,36.34433,
"218.00",18.07,36.37767,
"218.20",18.072,36.411,
"218.40",18.08,36.44433,
"218.60",18.086,36.47766,
"218.80",18.097,36.511,
"219.00",18.105,36.54433,
"219.20",18.11,36.57766,
"219.40",18.118,36.611,
"219.60",18.127,36.64433,
"219.80",18.135,36.67767,
"220.00",18.143,36.711,
"220.20",18.151,36.74433,
"220.40",18.156,36.77766,
"220.60",18.168,36.811,
"220.80",18.178,36.84433,
"221.00",18.184,36.87767,
"221.20",18.189,36.911,
"221.40",18.2,36.94433,
"221.60",18.213,36.978,
"221.80",18.222,37.011,
"222.00",18.232,37.04433,
"222.20",18.236,37.078,
"222.40",18.244,37.11133,
"222.60",18.252,37.14433,
"222.80",18.262,37.178,
"223.00",18.268,37.211,
"223.20",18.276,37.24433,
"223.40",18.283,37.278,
"223.60",18.29,37.311,
"223.80",18.3,37.34433,
"224.00",18.308,37.37767,
"224.20",18.313,37.411,
"224.40",18.321,37.44466,
"224.60",18.329,37.47766,
"224.80",18.339,37.511,
"225.00",18.342,37.54433,
"225.20",18.349,37.57766,
"225.40",18.354,37.611,
"225.60",18.364,37.64466,
"225.80",18.375,37.678,
"226.00",18.381,37.71133,
"226.20",18.386,37.74466,
"226.40",18.392,37.778,
"226.60",18.401,37.811,
"226.80",18.407,37.84467,
"227.00",18.412,37.87767,
"227.20",18.418,37.911,
"227.40",18.423,37.94433,
"227.60",18.43,37.97766,
"227.80",18.437,38.011,
"228.00",18.443,38.04467,
"228.20",18.45,38.07766,
"228.40",18.457,38.11133,
"228.60",18.46,38.14433,
"228.80",18.465,38.17767,
"229.00",18.475,38.211,
"229.20",18.482,38.24433,
"229.40",18.49,38.278,
"229.60",18.496,38.31133,
"229.80",18.501,38.34433,
"230.00",18.508,38.378,
"230.20",18.512,38.41133,
"230.40",18.517,38.44466,
"230.60",18.529,38.478,
"230.80",18.538,38.511,
"231.00",18.539,38.54433,
"231.20",18.545,38.57766,
"231.40",18.551,38.611,
"231.60",18.563,38.64433,
"231.80",18.572,38.67767,
"232.00",18.579,38.71133,
"232.20",18.587,38.74433,
"232.40",18.592,38.778,
"232.60",18.603,38.81133,
"232.80",18.613,38.84467,
"233.00",18.622,38.878,
"233.20",18.626,38.91133,
"233.40",18.631,38.94466,
"233.60",18.638,38.97766,
"233.80",18.646,39.01133,
"234.00",18.654,39.04467,
"234.20",18.661,39.078,
"234.40",18.668,39.11133,
"234.60",18.679,39.14433,
"234.80",18.687,39.178,
"235.00",18.692,39.21133,
"235.20",18.698,39.24466,
"235.40",18.704,39.278,
"235.60",18.713,39.31133,
"235.80",18.724,39.34467,
"236.00",18.728,39.378,
"236.20",18.73,39.41133,
"236.40",18.736,39.44433,
"236.60",18.746,39.47766,
"236.80",18.756,39.511,
"237.00",18.761,39.54433,
"237.20",18.766,39.578,
"237.40",18.772,39.61133,
"237.60",18.778,39.64466,
"237.80",18.789,39.678,
"238.00",18.795,39.71133,
"238.20",18.8,39.74466,
"238.40",18.807,39.778,
"238.60",18.812,39.811,
"238.80",18.816,39.84467,
"239.00",18.824,39.87767,
"239.20",18.829,39.911,
"239.40",18.837,39.94433,
"239.60",18.842,39.978,
"239.80",18.851,40.01133,
"240.00",18.855,40.04433,
"240.20",18.855,40.078,
"240.40",18.861,40.11133,
"240.60",18.871,40.14466,
"240.80",18.878,40.178,
"241.00",18.881,40.21133,
"241.20",18.88,40.24433,
"241.40",18.883,40.278,
"241.60",18.888,40.311,
"241.80",18.897,40.34467,
"242.00",18.903,40.378,
"242.20",18.907,40.41133,
"242.40",18.907,40.44466,
"242.60",18.911,40.478,
"242.80",18.917,40.511,
"243.00",18.92,40.54433,
"243.20",18.921,40.57766,
"243.40",18.906,40.611,
"243.60",18.82,40.64433,
"243.80",18.781,40.67767,
"244.00",18.752,40.71133,
"244.20",18.729,40.74466,
"244.40",18.715,40.77766,
"244.60",18.703,40.811,
"244.80",18.698,40.84467,
"245.00",18.692,40.878,
"245.20",18.689,40.91133,
"245.40",18.691,40.94466,
"245.60",18.697,40.978,
"245.80",18.708,41.01133,
"246.00",18.709,41.04467,
"246.20",18.713,41.07766,
"246.40",18.722,41.11133,
"246.60",18.736,41.14433,
"246.80",18.754,41.17767,
"247.00",18.769,41.211,
"247.20",18.786,41.24433,
"247.40",18.801,41.27766,
"247.60",18.817,41.311,
"247.80",18.837,41.34433,
"248.00",18.851,41.37767,
"248.20",18.863,41.411,
"248.40",18.879,41.44433,
"248.60",18.89,41.47766,
"248.80",18.899,41.51133,
"249.00",18.896,41.54467,
"249.20",18.909,41.578,
"249.40",18.92,41.61133,
"249.60",18.933,41.64466,
"249.80",18.951,41.678,
"250.00",18.967,41.71133,
"250.20",18.978,41.74466,
"250.40",18.994,41.778,
"250.60",19.012,41.811,
"250.80",19.026,41.84433,
"251.00",19.039,41.87767,
"251.20",19.051,41.911,
"251.40",19.063,41.94433,
"251.60",19.078,41.97766,
"251.80",19.091,42.011,
"252.00",19.103,42.04467,
"252.20",19.111,42.078,
"252.40",19.119,42.11133,
"252.60",19.131,42.14466,
"252.80",19.14,42.17767,
"253.00",19.15,42.211,
"253.20",19.159,42.24433,
"253.40",19.164,42.27766,
"253.60",19.176,42.311,
"253.80",19.183,42.34433,
"254.00",19.19,42.37767,
"254.20",19.198,42.41133,
"254.40",19.206,42.44466,
"254.60",19.214,42.47766,
"254.80",19.223,42.51133,
"255.00",19.23,42.54433,
"255.20",19.231,42.57766,
"255.40",19.234,42.61133,
"255.60",19.243,42.64433,
"255.80",19.251,42.678,
"256.00",19.254,42.71133,
"256.20",19.258,42.74433,
"256.40",19.263,42.77766,
"256.60",19.271,42.811,
"256.80",19.28,42.84433,
"257.00",19.284,42.87767,
"257.20",19.287,42.911,
"257.40",19.293,42.94433,
"257.60",19.301,42.97766,
"257.80",19.308,43.011,
"258.00",19.316,43.04467,
"258.20",19.322,43.078,
"258.40",19.325,43.11133,
"258.60",19.33,43.14433,
"258.80",19.34,43.178,
"259.00",19.347,43.211,
"259.20",19.354,43.24433,
"259.40",19.359,43.27766,
"259.60",19.367,43.311,
"259.80",19.375,43.34433,
"260.00",19.383,43.37767,
"260.20",19.389,43.411,
"260.40",19.397,43.44433,
"260.60",19.407,43.47766,
"260.80",19.412,43.511,
"261.00",19.418,43.54433,
"261.20",19.424,43.57766,
"261.40",19.428,43.611,
"261.60",19.435,43.64433,
"261.80",19.444,43.678,
"262.00",19.45,43.71133,
"262.20",19.453,43.74433,
"262.40",19.457,43.77766,
"262.60",19.465,43.811,
"262.80",19.472,43.84433,
"263.00",19.478,43.87767,
"263.20",19.484,43.911,
"263.40",19.489,43.94433,
"263.60",19.497,43.97766,
"263.80",19.504,44.011,
"264.00",19.51,44.04433,
"264.20",19.512,44.07766,
"264.40",19.514,44.111,
"264.60",19.521,44.14433,
"264.80",19.528,44.17767,
"265.00",19.534,44.211,
"265.20",19.539,44.24433,
"265.40",19.544,44.27766,
"265.60",19.555,44.311,
"265.80",19.565,44.34433,
"266.00",19.569,44.37767,
"266.20",19.575,44.411,
"266.40",19.582,44.44433,
"266.60",19.59,44.47766,
"266.80",19.603,44.511,
"267.00",19.609,44.54433,
"267.20",19.615,44.57766,
"267.40",19.621,44.611,
"267.60",19.627,44.64433,
"267.80",19.636,44.678,
"268.00",19.643,44.71133,
"268.20",19.65,44.74466,
"268.40",19.655,44.778,
"268.60",19.661,44.811,
"268.80",19.673,44.84433,
"269.00",19.676,44.87767,
"269.20",19.685,44.911,
"269.40",19.691,44.94433,
"269.60",19.7,44.97766,
"269.80",19.707,45.01133,
"270.00",19.712,45.04467,
"270.20",19.716,45.07766,
"270.40",19.723,45.111,
"270.60",19.732,45.14433,
"270.80",19.74,45.178,
"271.00",19.748,45.21133,
"271.20",19.748,45.24433,
"271.40",19.755,45.27766,
"271.60",19.762,45.311,
"271.80",19.772,45.34433,
"272.00",19.778,45.37767,
"272.20",19.781,45.411,
"272.40",19.786,45.44433,
"272.60",19.791,45.47766,
"272.80",19.798,45.51133,
"273.00",19.803,45.54433,
"273.20",19.81,45.57766,
"273.40",19.814,45.61133,
"273.60",19.819,45.64433,
"273.80",19.824,45.678,
"274.00",19.83,45.711,
"274.20",19.835,45.74433,
"274.40",19.841,45.77766,
"274.60",19.849,45.811,
"274.80",19.853,45.84433,
"275.00",19.857,45.87767,
"275.20",19.862,45.911,
"275.40",19.868,45.94433,
"275.60",19.879,45.97766,
"275.80",19.886,46.011,
"276.00",19.89,46.04433,
"276.20",19.893,46.07766,
"276.40",19.901,46.111,
"276.60",19.908,46.14433,
"276.80",19.914,46.178,
"277.00",19.922,46.211,
"277.20",19.927,46.24466,
"277.40",19.928,46.27766,
"277.60",19.941,46.311,
"277.80",19.945,46.34433,
"278.00",19.951,46.378,
"278.20",19.954,46.41133,
"278.40",19.955,46.44466,
"278.60",19.961,46.478,
"278.80",19.968,46.51133,
"278.95",19.963,46.536,