File: exposed_monofilament_10cm_10mmpm_12nm_250esh_8.csv
"Test Name","Test Mode","Test Type","Control","Test Speed 1","Test Speed 2","Test Speed 3","Change Point 1","Change Point 2","Disp. Origin","Break and Limit Action","Sensitivity:","Level:"
"","Single","Tensile","Stroke",10,1,1,"Off","Off","Start","Stop",0,1

"Title","Sub title","Comment"
"","",""

"Shape:","Batch Size:","SubBatch Size:"
"Plate",1,1
"Name:","Thickness","Width","Gauge Length",
"Size Unit:","mm","mm","mm",
" 1 - 1","1.0000","1.0000","100.0000",

"Name",
"Parameter",
"Units",
" 1 - 1",

" 1- 1"
"Time","Force","Stroke",
"sec","N","mm",
"0.00",0,0,
"0.15",.002,.028,
"0.30",.011,5.566667E-02,
"0.45",.019,8.333334E-02,
"0.60",.031,.1113333,
"0.75",.045,.139,
"0.90",.055,.1666667,
"1.05",.067,.1946667,
"1.20",.078,.2223333,
"1.35",.091,.2503333,
"1.50",.1,.278,
"1.65",.11,.3056667,
"1.80",.121,.3336667,
"1.95",.133,.3613333,
"2.10",.144,.3883333,
"2.25",.154,.4153333,
"2.40",.168,.442,
"2.55",.176,.4683333,
"2.70",.186,.4946667,
"2.85",.196,.5206667,
"3.00",.207,.5463334,
"3.15",.215,.5723333,
"3.30",.224,.5976667,
"3.45",.234,.6233333,
"3.60",.244,.649,
"3.75",.256,.6743333,
"3.90",.267,.6996667,
"4.05",.276,.725,
"4.20",.287,.7503334,
"4.35",.297,.7756667,
"4.50",.308,.8006667,
"4.65",.318,.826,
"4.80",.325,.851,
"4.95",.336,.876,
"5.10",.349,.9013333,
"5.25",.36,.9263334,
"5.40",.369,.9513333,
"5.55",.378,.9763334,
"5.70",.387,1.001333,
"5.85",.397,1.026667,
"6.00",.407,1.051667,
"6.15",.418,1.076667,
"6.30",.429,1.101667,
"6.45",.437,1.126667,
"6.60",.447,1.151667,
"6.75",.459,1.176667,
"6.90",.469,1.201667,
"7.05",.48,1.227,
"7.20",.489,1.251667,
"7.35",.5,1.276667,
"7.50",.509,1.301667,
"7.65",.52,1.326667,
"7.80",.53,1.352,
"7.95",.542,1.376667,
"8.10",.553,1.402,
"8.25",.562,1.427,
"8.40",.571,1.452,
"8.55",.58,1.477,
"8.70",.592,1.502,
"8.85",.604,1.527,
"9.00",.612,1.552,
"9.15",.623,1.577,
"9.30",.636,1.602,
"9.45",.645,1.627,
"9.60",.656,1.652,
"9.75",.667,1.677,
"9.90",.678,1.702,
"10.05",.688,1.726667,
"10.20",.698,1.752,
"10.35",.71,1.776667,
"10.50",.721,1.801667,
"10.65",.731,1.827,
"10.80",.743,1.851667,
"10.95",.754,1.876667,
"11.10",.763,1.901667,
"11.25",.775,1.926667,
"11.40",.785,1.951667,
"11.55",.796,1.976667,
"11.70",.808,2.001667,
"11.85",.819,2.026667,
"12.00",.832,2.051667,
"12.15",.843,2.076667,
"12.30",.853,2.101667,
"12.45",.864,2.126667,
"12.60",.874,2.151667,
"12.75",.888,2.177,
"12.90",.902,2.202,
"13.05",.914,2.226667,
"13.20",.924,2.251667,
"13.35",.934,2.276667,
"13.50",.948,2.302,
"13.65",.957,2.327,
"13.80",.968,2.352,
"13.95",.981,2.377,
"14.10",.993,2.402,
"14.25",1.005,2.427,
"14.40",1.018,2.452,
"14.55",1.03,2.477,
"14.70",1.042,2.502,
"14.85",1.055,2.527,
"15.00",1.068,2.551667,
"15.15",1.079,2.576667,
"15.30",1.092,2.601667,
"15.45",1.101,2.626667,
"15.60",1.115,2.651667,
"15.75",1.127,2.676667,
"15.90",1.14,2.701667,
"16.05",1.153,2.726667,
"16.20",1.165,2.751667,
"16.35",1.178,2.776667,
"16.50",1.19,2.801667,
"16.65",1.202,2.827,
"16.80",1.219,2.852,
"16.95",1.229,2.876667,
"17.10",1.242,2.901667,
"17.25",1.257,2.926667,
"17.40",1.269,2.951667,
"17.55",1.284,2.976667,
"17.70",1.297,3.001667,
"17.85",1.31,3.026667,
"18.00",1.322,3.051667,
"18.15",1.336,3.077,
"18.30",1.349,3.102,
"18.45",1.363,3.126667,
"18.60",1.378,3.152,
"18.75",1.391,3.176667,
"18.90",1.406,3.201667,
"19.05",1.422,3.226667,
"19.20",1.433,3.251667,
"19.35",1.447,3.276667,
"19.50",1.461,3.301667,
"19.65",1.478,3.327,
"19.80",1.489,3.352,
"19.95",1.503,3.377,
"20.10",1.518,3.402,
"20.25",1.533,3.427,
"20.40",1.545,3.452,
"20.55",1.56,3.477,
"20.70",1.576,3.502,
"20.85",1.592,3.527,
"21.00",1.605,3.552,
"21.15",1.622,3.577,
"21.30",1.637,3.602,
"21.45",1.652,3.627,
"21.60",1.666,3.652,
"21.75",1.681,3.677,
"21.90",1.696,3.702,
"22.05",1.713,3.727,
"22.20",1.73,3.752,
"22.35",1.746,3.777,
"22.50",1.761,3.802,
"22.65",1.778,3.827,
"22.80",1.793,3.852,
"22.95",1.808,3.876667,
"23.10",1.825,3.901667,
"23.25",1.843,3.926667,
"23.40",1.856,3.951667,
"23.55",1.871,3.976667,
"23.70",1.885,4.001667,
"23.85",1.905,4.026667,
"24.00",1.92,4.051667,
"24.15",1.938,4.076667,
"24.30",1.954,4.101667,
"24.45",1.971,4.126667,
"24.60",1.985,4.151667,
"24.75",2.005,4.176667,
"24.90",2.021,4.201667,
"25.05",2.039,4.226667,
"25.20",2.056,4.251667,
"25.35",2.073,4.276667,
"25.50",2.091,4.301667,
"25.65",2.111,4.326667,
"25.80",2.128,4.351667,
"25.95",2.145,4.376667,
"26.10",2.165,4.401667,
"26.25",2.183,4.426667,
"26.40",2.2,4.451667,
"26.55",2.216,4.476667,
"26.70",2.235,4.501667,
"26.85",2.255,4.526667,
"27.00",2.274,4.551667,
"27.15",2.294,4.576667,
"27.30",2.311,4.601667,
"27.45",2.329,4.626667,
"27.60",2.347,4.651667,
"27.75",2.367,4.676667,
"27.90",2.386,4.702,
"28.05",2.407,4.726667,
"28.20",2.426,4.752,
"28.35",2.445,4.777,
"28.50",2.464,4.802,
"28.65",2.484,4.827,
"28.80",2.505,4.851667,
"28.95",2.523,4.876667,
"29.10",2.541,4.901667,
"29.25",2.565,4.926667,
"29.40",2.583,4.951667,
"29.55",2.604,4.976667,
"29.70",2.623,5.002,
"29.85",2.644,5.027,
"30.00",2.663,5.052,
"30.15",2.685,5.077,
"30.30",2.704,5.102,
"30.45",2.724,5.126667,
"30.60",2.744,5.152,
"30.75",2.765,5.177,
"30.90",2.788,5.201667,
"31.05",2.807,5.227,
"31.20",2.828,5.251667,
"31.35",2.848,5.277,
"31.50",2.868,5.302,
"31.65",2.892,5.327,
"31.80",2.915,5.352,
"31.95",2.936,5.376667,
"32.10",2.956,5.402,
"32.25",2.98,5.427,
"32.40",2.983,5.452,
"32.55",2.963,5.477,
"32.70",2.974,5.502,
"32.85",2.996,5.527,
"33.00",3.018,5.551667,
"33.15",3.04,5.577,
"33.30",3.062,5.601667,
"33.45",3.084,5.626667,
"33.60",3.108,5.651667,
"33.75",3.13,5.676667,
"33.90",3.151,5.701667,
"34.05",3.176,5.726667,
"34.20",3.198,5.752,
"34.35",3.22,5.777,
"34.50",3.24,5.802,
"34.65",3.26,5.827,
"34.80",3.285,5.851667,
"34.95",3.307,5.876667,
"35.10",3.332,5.901667,
"35.25",3.355,5.926667,
"35.40",3.376,5.952,
"35.55",3.395,5.977,
"35.70",3.408,6.002,
"35.85",3.416,6.027,
"36.00",3.432,6.051667,
"36.15",3.444,6.077,
"36.30",3.465,6.102,
"36.45",3.486,6.127,
"36.60",3.501,6.152,
"36.75",3.514,6.176667,
"36.90",3.528,6.201667,
"37.05",3.534,6.227,
"37.20",3.54,6.252,
"37.35",3.555,6.277,
"37.50",3.577,6.302,
"37.65",3.599,6.327,
"37.80",3.622,6.352,
"37.95",3.648,6.377,
"38.10",3.676,6.402,
"38.25",3.702,6.427,
"38.40",3.724,6.452,
"38.55",3.75,6.476667,
"38.70",3.775,6.501667,
"38.85",3.801,6.526667,
"39.00",3.828,6.551667,
"39.15",3.853,6.576667,
"39.30",3.879,6.601667,
"39.45",3.906,6.627,
"39.60",3.931,6.652,
"39.75",3.956,6.677,
"39.90",3.981,6.701667,
"40.05",4.007,6.726667,
"40.20",4.031,6.751667,
"40.35",4.058,6.776667,
"40.50",4.082,6.801667,
"40.65",4.106,6.827,
"40.80",4.132,6.851667,
"40.95",4.159,6.876667,
"41.10",4.184,6.901667,
"41.25",4.209,6.926667,
"41.40",4.235,6.951667,
"41.55",4.261,6.976667,
"41.70",4.284,7.001667,
"41.85",4.311,7.026667,
"42.00",4.338,7.051667,
"42.15",4.361,7.076667,
"42.30",4.387,7.101667,
"42.45",4.412,7.126667,
"42.60",4.437,7.151667,
"42.75",4.463,7.176667,
"42.90",4.49,7.201667,
"43.05",4.516,7.226667,
"43.20",4.54,7.251667,
"43.35",4.564,7.276667,
"43.50",4.513,7.301667,
"43.65",4.457,7.326667,
"43.80",4.482,7.351667,
"43.95",4.512,7.376667,
"44.10",4.538,7.401667,
"44.25",4.568,7.426667,
"44.40",4.594,7.451667,
"44.55",4.621,7.477,
"44.70",4.646,7.502,
"44.85",4.674,7.527,
"45.00",4.703,7.552,
"45.15",4.728,7.577,
"45.30",4.755,7.601667,
"45.45",4.781,7.626667,
"45.60",4.807,7.651667,
"45.75",4.832,7.676667,
"45.90",4.857,7.701667,
"46.05",4.884,7.726667,
"46.20",4.91,7.751667,
"46.35",4.934,7.776667,
"46.50",4.96,7.801667,
"46.65",4.988,7.826667,
"46.80",5.013,7.851667,
"46.95",5.038,7.876667,
"47.10",5.064,7.901667,
"47.25",5.088,7.926667,
"47.40",5.112,7.951667,
"47.55",5.135,7.976667,
"47.70",5.161,8.001666,
"47.85",5.186,8.026667,
"48.00",5.213,8.051666,
"48.15",5.237,8.077,
"48.30",5.263,8.101999,
"48.45",5.283,8.127,
"48.60",5.193,8.151999,
"48.75",5.071,8.176999,
"48.90",5.09,8.202,
"49.05",5.119,8.226999,
"49.20",5.15,8.252,
"49.35",5.177,8.276667,
"49.50",5.204,8.301666,
"49.65",5.234,8.326666,
"49.80",5.262,8.351666,
"49.95",5.29,8.376666,
"50.10",5.32,8.401667,
"50.25",5.345,8.426666,
"50.40",5.373,8.451666,
"50.55",5.4,8.476666,
"50.70",5.424,8.501666,
"50.85",5.452,8.526999,
"51.00",5.478,8.551666,
"51.15",5.507,8.577,
"51.30",5.531,8.601666,
"51.45",5.555,8.626666,
"51.60",5.579,8.651667,
"51.75",5.604,8.676666,
"51.90",5.629,8.701666,
"52.05",5.655,8.726666,
"52.20",5.677,8.751666,
"52.35",5.701,8.776667,
"52.50",5.724,8.801666,
"52.65",5.749,8.826666,
"52.80",5.772,8.851666,
"52.95",5.798,8.876666,
"53.10",5.823,8.901999,
"53.25",5.844,8.926666,
"53.40",5.864,8.951666,
"53.55",5.888,8.976666,
"53.70",5.913,9.001666,
"53.85",5.936,9.026999,
"54.00",5.959,9.051666,
"54.15",5.981,9.076666,
"54.30",6.005,9.101666,
"54.45",6.023,9.126666,
"54.60",6.046,9.151667,
"54.75",6.069,9.176666,
"54.90",6.09,9.201666,
"55.05",6.114,9.226666,
"55.20",6.135,9.251666,
"55.35",6.158,9.276667,
"55.50",6.18,9.301666,
"55.65",6.2,9.326666,
"55.80",6.222,9.351666,
"55.95",6.247,9.376666,
"56.10",6.269,9.401667,
"56.25",6.287,9.426666,
"56.40",6.307,9.451666,
"56.55",6.33,9.476666,
"56.70",6.352,9.501666,
"56.85",6.373,9.526667,
"57.00",6.395,9.551666,
"57.15",6.416,9.576666,
"57.30",6.436,9.601666,
"57.45",6.457,9.626666,
"57.60",6.476,9.651667,
"57.75",6.499,9.676666,
"57.90",6.521,9.701666,
"58.05",6.544,9.726666,
"58.20",6.563,9.751666,
"58.35",6.582,9.776999,
"58.50",6.603,9.801666,
"58.65",6.624,9.826666,
"58.80",6.643,9.851666,
"58.95",6.667,9.876666,
"59.10",6.688,9.901667,
"59.25",6.708,9.926666,
"59.40",6.727,9.951666,
"59.55",6.748,9.976666,
"59.70",6.767,10.00167,
"59.85",6.79,10.02667,
"60.00",6.809,10.05167,
"60.15",6.829,10.07667,
"60.30",6.848,10.10167,
"60.45",6.869,10.12667,
"60.60",6.889,10.15167,
"60.75",6.908,10.177,
"60.90",6.926,10.20167,
"61.05",6.95,10.22667,
"61.20",6.97,10.25167,
"61.35",6.988,10.27667,
"61.50",7.006,10.30167,
"61.65",7.025,10.32667,
"61.80",7.044,10.35167,
"61.95",7.065,10.37667,
"62.10",7.086,10.40167,
"62.25",7.106,10.42667,
"62.40",7.125,10.452,
"62.55",7.139,10.47667,
"62.70",7.161,10.50167,
"62.85",7.18,10.52667,
"63.00",7.2,10.55167,
"63.15",7.223,10.57667,
"63.30",7.243,10.60167,
"63.45",7.261,10.62667,
"63.60",7.279,10.65167,
"63.75",7.297,10.67667,
"63.90",7.317,10.70167,
"64.05",7.336,10.72667,
"64.20",7.356,10.75167,
"64.35",7.376,10.777,
"64.50",7.393,10.80167,
"64.65",7.412,10.827,
"64.80",7.431,10.85167,
"64.95",7.45,10.87667,
"65.10",7.47,10.90167,
"65.25",7.485,10.92667,
"65.40",7.508,10.95167,
"65.55",7.527,10.97667,
"65.70",7.545,11.00167,
"65.85",7.565,11.02667,
"66.00",7.586,11.05167,
"66.15",7.606,11.07667,
"66.30",7.622,11.10167,
"66.45",7.641,11.12667,
"66.60",7.658,11.15167,
"66.75",7.679,11.17667,
"66.90",7.699,11.20167,
"67.05",7.716,11.22667,
"67.20",7.733,11.25167,
"67.35",7.753,11.27667,
"67.50",7.769,11.30167,
"67.65",7.787,11.327,
"67.80",7.808,11.352,
"67.95",7.831,11.377,
"68.10",7.847,11.402,
"68.25",7.863,11.427,
"68.40",7.883,11.452,
"68.55",7.899,11.477,
"68.70",7.919,11.502,
"68.85",7.937,11.527,
"69.00",7.954,11.55167,
"69.15",7.972,11.577,
"69.30",7.993,11.60167,
"69.45",8.007,11.62667,
"69.60",8.023,11.65167,
"69.75",8.042,11.67667,
"69.90",8.061,11.70167,
"70.05",8.076,11.72667,
"70.20",8.096,11.75167,
"70.35",8.112,11.77667,
"70.50",8.129,11.80167,
"70.65",8.149,11.827,
"70.80",8.153,11.85167,
"70.95",8.149,11.87667,
"71.10",8.16,11.90167,
"71.25",8.177,11.92667,
"71.40",8.193,11.95167,
"71.55",8.213,11.97667,
"71.70",8.229,12.00167,
"71.85",8.242,12.02667,
"72.00",8.26,12.05167,
"72.15",8.279,12.07667,
"72.30",8.297,12.10167,
"72.45",8.31,12.12667,
"72.60",8.331,12.15167,
"72.75",8.351,12.17667,
"72.90",8.372,12.20167,
"73.05",8.388,12.22667,
"73.20",8.406,12.25167,
"73.35",8.426,12.27667,
"73.50",8.444,12.30167,
"73.65",8.463,12.32667,
"73.80",8.479,12.35167,
"73.95",8.496,12.377,
"74.10",8.513,12.40167,
"74.25",8.533,12.42667,
"74.40",8.551,12.45167,
"74.55",8.566,12.47667,
"74.70",8.578,12.50167,
"74.85",8.598,12.52667,
"75.00",8.618,12.55167,
"75.15",8.636,12.57667,
"75.30",8.654,12.60167,
"75.45",8.666,12.62667,
"75.60",8.679,12.65167,
"75.75",8.697,12.67667,
"75.90",8.717,12.70167,
"76.05",8.735,12.72667,
"76.20",8.754,12.75167,
"76.35",8.759,12.77667,
"76.50",8.765,12.80167,
"76.65",8.786,12.82667,
"76.80",8.804,12.85167,
"76.95",8.816,12.87667,
"77.10",8.828,12.90167,
"77.25",8.844,12.92667,
"77.40",8.863,12.95167,
"77.55",8.881,12.97667,
"77.70",8.901,13.00167,
"77.85",8.912,13.02667,
"78.00",8.926,13.05167,
"78.15",8.947,13.07667,
"78.30",8.964,13.10167,
"78.45",8.982,13.12667,
"78.60",8.997,13.152,
"78.75",9.01,13.177,
"78.90",9.024,13.202,
"79.05",9.042,13.22667,
"79.20",9.064,13.25167,
"79.35",9.082,13.277,
"79.50",9.096,13.30167,
"79.65",9.114,13.327,
"79.80",9.124,13.352,
"79.95",9.139,13.37667,
"80.10",9.156,13.40167,
"80.25",9.176,13.427,
"80.40",9.193,13.452,
"80.55",9.208,13.47667,
"80.70",9.225,13.50167,
"80.85",9.239,13.52667,
"81.00",9.252,13.55167,
"81.15",9.269,13.57667,
"81.30",9.289,13.60167,
"81.45",9.308,13.62667,
"81.60",9.324,13.65167,
"81.75",9.337,13.67667,
"81.90",9.351,13.70167,
"82.05",9.37,13.727,
"82.20",9.388,13.752,
"82.35",9.402,13.777,
"82.50",9.419,13.802,
"82.65",9.436,13.827,
"82.80",9.447,13.85167,
"82.95",9.46,13.87667,
"83.10",9.479,13.90167,
"83.25",9.495,13.92667,
"83.40",9.511,13.95167,
"83.55",9.529,13.97667,
"83.70",9.542,14.00167,
"83.85",9.551,14.02667,
"84.00",9.568,14.05167,
"84.15",9.588,14.077,
"84.30",9.606,14.102,
"84.45",9.62,14.12667,
"84.60",9.637,14.152,
"84.75",9.645,14.177,
"84.90",9.658,14.20167,
"85.05",9.673,14.22667,
"85.20",9.69,14.25167,
"85.35",9.707,14.27667,
"85.50",9.721,14.30167,
"85.65",9.731,14.32667,
"85.80",9.747,14.35167,
"85.95",9.765,14.37667,
"86.10",9.783,14.40167,
"86.25",9.798,14.42667,
"86.40",9.811,14.45167,
"86.55",9.823,14.47667,
"86.70",9.837,14.50167,
"86.85",9.855,14.527,
"87.00",9.873,14.55167,
"87.15",9.89,14.57667,
"87.30",9.901,14.60167,
"87.45",9.909,14.62667,
"87.60",9.927,14.65167,
"87.75",9.944,14.67667,
"87.90",9.962,14.70167,
"88.05",9.979,14.72667,
"88.20",9.99,14.75167,
"88.35",10.004,14.77667,
"88.50",10.02,14.80167,
"88.65",10.035,14.82667,
"88.80",10.051,14.85167,
"88.95",10.069,14.87667,
"89.10",10.081,14.90167,
"89.25",10.095,14.92667,
"89.40",10.112,14.95167,
"89.55",10.125,14.97667,
"89.70",10.141,15.00167,
"89.85",10.158,15.02667,
"90.00",10.166,15.05167,
"90.15",10.18,15.07667,
"90.30",10.198,15.10167,
"90.45",10.212,15.12667,
"90.60",10.226,15.15167,
"90.75",10.242,15.177,
"90.90",10.253,15.20167,
"91.05",10.269,15.22667,
"91.20",10.286,15.25167,
"91.35",10.3,15.27667,
"91.50",10.314,15.30167,
"91.65",10.327,15.327,
"91.80",10.341,15.35167,
"91.95",10.357,15.37667,
"92.10",10.372,15.40167,
"92.25",10.387,15.42667,
"92.40",10.398,15.452,
"92.55",10.401,15.47667,
"92.70",10.369,15.50167,
"92.85",10.351,15.527,
"93.00",10.342,15.55167,
"93.15",10.345,15.577,
"93.30",10.352,15.60167,
"93.45",10.363,15.62667,
"93.60",10.376,15.65167,
"93.75",10.393,15.67667,
"93.90",10.406,15.70167,
"94.05",10.413,15.72667,
"94.20",10.428,15.75167,
"94.35",10.44,15.77667,
"94.50",10.449,15.80167,
"94.65",10.462,15.827,
"94.80",10.476,15.85167,
"94.95",10.489,15.87667,
"95.10",10.502,15.90167,
"95.25",10.516,15.92667,
"95.40",10.533,15.95167,
"95.55",10.549,15.97667,
"95.70",10.564,16.00167,
"95.85",10.58,16.027,
"96.00",10.592,16.05167,
"96.15",10.606,16.077,
"96.30",10.621,16.102,
"96.45",10.637,16.127,
"96.60",10.654,16.152,
"96.75",10.669,16.177,
"96.90",10.683,16.20167,
"97.05",10.7,16.227,
"97.20",10.722,16.252,
"97.35",10.737,16.27667,
"97.50",10.753,16.30167,
"97.65",10.761,16.327,
"97.80",10.776,16.352,
"97.95",10.799,16.37667,
"98.10",10.815,16.402,
"98.25",10.838,16.427,
"98.40",10.847,16.452,
"98.55",10.859,16.47667,
"98.70",10.878,16.502,
"98.85",10.893,16.527,
"99.00",10.911,16.552,
"99.15",10.922,16.57667,
"99.30",10.933,16.60167,
"99.45",10.951,16.62667,
"99.60",10.965,16.65167,
"99.75",10.977,16.67667,
"99.90",10.986,16.70167,
"100.05",11.001,16.72667,
"100.20",11.015,16.75167,
"100.35",11.03,16.77667,
"100.50",11.047,16.80167,
"100.65",11.056,16.827,
"100.80",11.07,16.852,
"100.95",11.089,16.87667,
"101.10",11.102,16.90167,
"101.25",11.111,16.92667,
"101.40",11.119,16.95167,
"101.55",11.138,16.97667,
"101.70",11.153,17.00167,
"101.85",11.167,17.02667,
"102.00",11.178,17.05167,
"102.15",11.191,17.07667,
"102.30",11.202,17.10167,
"102.45",11.213,17.12667,
"102.60",11.212,17.15167,
"102.75",11.22,17.17667,
"102.90",11.234,17.20167,
"103.05",11.247,17.227,
"103.20",11.257,17.252,
"103.35",11.27,17.27667,
"103.50",11.287,17.30167,
"103.65",11.294,17.327,
"103.80",11.302,17.35167,
"103.95",11.322,17.37667,
"104.10",11.335,17.40167,
"104.25",11.345,17.427,
"104.40",11.358,17.452,
"104.55",11.375,17.477,
"104.70",11.389,17.502,
"104.85",11.394,17.52667,
"105.00",11.408,17.55167,
"105.15",11.428,17.57667,
"105.30",11.439,17.60167,
"105.45",11.448,17.62667,
"105.60",11.462,17.65167,
"105.75",11.479,17.67667,
"105.90",11.494,17.70167,
"106.05",11.506,17.72667,
"106.20",11.52,17.75167,
"106.35",11.538,17.77667,
"106.50",11.548,17.80167,
"106.65",11.56,17.827,
"106.80",11.576,17.852,
"106.95",11.591,17.87667,
"107.10",11.607,17.90167,
"107.25",11.612,17.92667,
"107.40",11.619,17.95167,
"107.55",11.633,17.97667,
"107.70",11.645,18.00167,
"107.85",11.656,18.02667,
"108.00",11.672,18.05167,
"108.15",11.689,18.07667,
"108.30",11.703,18.10167,
"108.45",11.709,18.12667,
"108.60",11.724,18.15167,
"108.75",11.742,18.17667,
"108.90",11.758,18.20167,
"109.05",11.767,18.22667,
"109.20",11.784,18.25167,
"109.35",11.799,18.27667,
"109.50",11.809,18.30167,
"109.65",11.82,18.32667,
"109.80",11.836,18.35167,
"109.95",11.85,18.37667,
"110.10",11.864,18.40167,
"110.25",11.876,18.42667,
"110.40",11.89,18.452,
"110.55",11.903,18.47667,
"110.70",11.913,18.502,
"110.85",11.926,18.527,
"111.00",11.944,18.55167,
"111.15",11.955,18.57667,
"111.30",11.963,18.60167,
"111.45",11.98,18.62667,
"111.60",11.99,18.65167,
"111.75",12.002,18.67667,
"111.90",12.017,18.70167,
"112.05",12.031,18.72667,
"112.20",12.041,18.75167,
"112.35",12.051,18.77667,
"112.50",12.061,18.80167,
"112.65",12.076,18.82667,
"112.80",12.089,18.85167,
"112.95",12.096,18.87667,
"113.10",12.111,18.90167,
"113.25",12.122,18.92667,
"113.40",12.128,18.95167,
"113.55",12.143,18.97667,
"113.70",12.156,19.00167,
"113.85",12.161,19.02667,
"114.00",12.178,19.05167,
"114.15",12.19,19.07667,
"114.30",12.199,19.10167,
"114.45",12.211,19.12667,
"114.60",12.221,19.15167,
"114.75",12.23,19.17667,
"114.90",12.244,19.20167,
"115.05",12.254,19.22667,
"115.20",12.262,19.25167,
"115.35",12.273,19.27667,
"115.50",12.283,19.30167,
"115.65",12.29,19.32667,
"115.80",12.298,19.35167,
"115.95",12.314,19.37667,
"116.10",12.325,19.40167,
"116.25",12.335,19.427,
"116.40",12.346,19.452,
"116.55",12.356,19.47667,
"116.70",12.367,19.50167,
"116.85",12.379,19.52667,
"117.00",12.394,19.55167,
"117.15",12.403,19.57667,
"117.30",12.414,19.602,
"117.45",12.427,19.627,
"117.60",12.438,19.652,
"117.75",12.447,19.67667,
"117.90",12.463,19.70167,
"118.05",12.478,19.72667,
"118.20",12.485,19.75167,
"118.35",12.499,19.77667,
"118.50",12.511,19.80167,
"118.65",12.516,19.82667,
"118.80",12.528,19.85167,
"118.95",12.543,19.87667,
"119.10",12.557,19.90167,
"119.25",12.564,19.92667,
"119.40",12.578,19.95167,
"119.55",12.591,19.97667,
"119.70",12.599,20.00167,
"119.85",12.609,20.02633,
"120.00",12.625,20.05133,
"120.15",12.635,20.07633,
"120.30",12.648,20.10167,
"120.45",12.661,20.12667,
"120.60",12.673,20.15167,
"120.75",12.684,20.17667,
"120.90",12.698,20.20167,
"121.05",12.713,20.22667,
"121.20",12.723,20.25167,
"121.35",12.732,20.27667,
"121.50",12.748,20.30167,
"121.65",12.757,20.32667,
"121.80",12.766,20.35167,
"121.95",12.78,20.37667,
"122.10",12.795,20.40167,
"122.25",12.805,20.42667,
"122.40",12.814,20.45167,
"122.55",12.824,20.47667,
"122.70",12.832,20.50167,
"122.85",12.843,20.52667,
"123.00",12.862,20.55167,
"123.15",12.872,20.57667,
"123.30",12.883,20.60167,
"123.45",12.896,20.62667,
"123.60",12.903,20.65167,
"123.75",12.913,20.67667,
"123.90",12.927,20.70167,
"124.05",12.94,20.72667,
"124.20",12.948,20.75167,
"124.35",12.961,20.77667,
"124.50",12.972,20.80167,
"124.65",12.979,20.827,
"124.80",12.994,20.85167,
"124.95",13.007,20.87667,
"125.10",13.014,20.902,
"125.25",13.028,20.92667,
"125.40",13.037,20.95167,
"125.55",13.045,20.97667,
"125.70",13.056,21.00167,
"125.85",13.073,21.02667,
"126.00",13.08,21.05167,
"126.15",13.094,21.077,
"126.30",13.108,21.102,
"126.45",13.113,21.12667,
"126.60",13.126,21.152,
"126.75",13.139,21.17667,
"126.90",13.148,21.20167,
"127.05",13.162,21.22667,
"127.20",13.176,21.25167,
"127.35",13.184,21.27667,
"127.50",13.193,21.30167,
"127.65",13.204,21.32667,
"127.80",13.215,21.352,
"127.95",13.226,21.37667,
"128.10",13.24,21.40167,
"128.25",13.252,21.42667,
"128.40",13.257,21.452,
"128.55",13.271,21.47667,
"128.70",13.28,21.50167,
"128.85",13.289,21.52667,
"129.00",13.304,21.55167,
"129.15",13.316,21.57667,
"129.30",13.324,21.60167,
"129.45",13.34,21.62667,
"129.60",13.349,21.65167,
"129.75",13.359,21.67667,
"129.90",13.374,21.70167,
"130.05",13.385,21.72667,
"130.20",13.393,21.75167,
"130.35",13.405,21.77667,
"130.50",13.417,21.80167,
"130.65",13.423,21.82667,
"130.80",13.436,21.85167,
"130.95",13.448,21.87667,
"131.10",13.459,21.90167,
"131.25",13.471,21.92667,
"131.40",13.477,21.95167,
"131.55",13.486,21.97667,
"131.70",13.5,22.00167,
"131.85",13.509,22.02667,
"132.00",13.518,22.05167,
"132.15",13.532,22.07667,
"132.30",13.539,22.10167,
"132.45",13.545,22.12667,
"132.60",13.556,22.15167,
"132.75",13.564,22.17667,
"132.90",13.577,22.20167,
"133.05",13.59,22.22667,
"133.20",13.598,22.25167,
"133.35",13.609,22.27667,
"133.50",13.62,22.30167,
"133.65",13.627,22.32667,
"133.80",13.636,22.35167,
"133.95",13.647,22.37633,
"134.10",13.657,22.40167,
"134.25",13.671,22.42667,
"134.40",13.683,22.45167,
"134.55",13.689,22.47667,
"134.70",13.702,22.50167,
"134.85",13.712,22.52667,
"135.00",13.718,22.55167,
"135.15",13.731,22.57667,
"135.30",13.743,22.60167,
"135.45",13.748,22.62667,
"135.60",13.759,22.65167,
"135.75",13.77,22.67667,
"135.90",13.777,22.70167,
"136.05",13.79,22.72667,
"136.20",13.798,22.75167,
"136.35",13.802,22.77667,
"136.50",13.804,22.80167,
"136.65",13.808,22.82667,
"136.80",13.813,22.85167,
"136.95",13.826,22.87633,
"137.10",13.836,22.90133,
"137.25",13.842,22.92667,
"137.40",13.85,22.95133,
"137.55",13.861,22.97633,
"137.70",13.867,23.00133,
"137.85",13.875,23.02667,
"138.00",13.89,23.05167,
"138.15",13.9,23.07667,
"138.30",13.907,23.10167,
"138.45",13.921,23.12667,
"138.60",13.93,23.15167,
"138.75",13.938,23.17667,
"138.90",13.947,23.20167,
"139.05",13.953,23.22667,
"139.20",13.958,23.25167,
"139.35",13.962,23.27667,
"139.50",13.966,23.30167,
"139.65",13.976,23.32667,
"139.80",13.987,23.35167,
"139.95",13.997,23.37667,
"140.10",14.003,23.40167,
"140.25",14,23.42667,
"140.40",13.999,23.452,
"140.55",14.01,23.477,
"140.70",14.021,23.502,
"140.85",14.03,23.527,
"141.00",14.039,23.55167,
"141.15",14.051,23.57667,
"141.30",14.06,23.60167,
"141.45",14.074,23.62667,
"141.60",14.084,23.65167,
"141.75",14.098,23.67667,
"141.90",14.11,23.70167,
"142.05",14.122,23.72667,
"142.20",14.137,23.75167,
"142.35",14.147,23.77667,
"142.50",14.16,23.80167,
"142.65",14.17,23.827,
"142.80",14.181,23.85167,
"142.95",14.196,23.87667,
"143.10",14.207,23.902,
"143.25",14.215,23.92667,
"143.40",14.224,23.95167,
"143.55",14.234,23.97667,
"143.70",14.245,24.00167,
"143.85",14.256,24.02667,
"144.00",14.267,24.05167,
"144.15",14.278,24.07667,
"144.30",14.293,24.10167,
"144.45",14.303,24.12667,
"144.60",14.311,24.15167,
"144.75",14.319,24.17667,
"144.90",14.333,24.20167,
"145.05",14.344,24.22667,
"145.20",14.35,24.25167,
"145.35",14.361,24.27667,
"145.50",14.37,24.30167,
"145.65",14.378,24.32667,
"145.80",14.392,24.35167,
"145.95",14.403,24.37667,
"146.10",14.416,24.40167,
"146.25",14.422,24.42667,
"146.40",14.429,24.45167,
"146.55",14.441,24.47667,
"146.70",14.451,24.50167,
"146.85",14.46,24.52667,
"147.00",14.473,24.55167,
"147.15",14.483,24.57667,
"147.30",14.491,24.60167,
"147.45",14.496,24.627,
"147.60",14.502,24.65167,
"147.75",14.51,24.677,
"147.90",14.526,24.702,
"148.05",14.533,24.727,
"148.20",14.547,24.752,
"148.35",14.551,24.777,
"148.50",14.558,24.802,
"148.65",14.57,24.827,
"148.80",14.576,24.85167,
"148.95",14.588,24.87667,
"149.10",14.597,24.90167,
"149.25",14.605,24.92667,
"149.40",14.613,24.95167,
"149.55",14.622,24.97667,
"149.70",14.63,25.00167,
"149.85",14.642,25.02667,
"150.00",14.645,25.05167,
"150.15",14.655,25.07667,
"150.30",14.67,25.10167,
"150.45",14.674,25.12667,
"150.60",14.685,25.15167,
"150.75",14.691,25.17667,
"150.90",14.702,25.20167,
"151.05",14.713,25.22667,
"151.20",14.719,25.25167,
"151.35",14.724,25.27667,
"151.50",14.734,25.30167,
"151.65",14.744,25.32667,
"151.80",14.75,25.35167,
"151.95",14.764,25.37667,
"152.10",14.77,25.40167,
"152.25",14.781,25.42667,
"152.40",14.785,25.45167,
"152.55",14.792,25.47667,
"152.70",14.801,25.50167,
"152.85",14.806,25.52667,
"153.00",14.816,25.55167,
"153.15",14.825,25.57667,
"153.30",14.834,25.60167,
"153.45",14.845,25.62667,
"153.60",14.85,25.65167,
"153.75",14.859,25.67667,
"153.90",14.872,25.702,
"154.05",14.879,25.727,
"154.20",14.893,25.752,
"154.35",14.901,25.777,
"154.50",14.91,25.802,
"154.65",14.921,25.827,
"154.80",14.928,25.852,
"154.95",14.936,25.87667,
"155.10",14.944,25.902,
"155.25",14.953,25.92667,
"155.40",14.96,25.952,
"155.55",14.967,25.97667,
"155.70",14.976,26.002,
"155.85",14.984,26.027,
"156.00",14.995,26.052,
"156.15",15.003,26.077,
"156.30",15.012,26.102,
"156.45",15.019,26.127,
"156.60",15.027,26.152,
"156.75",15.04,26.177,
"156.90",15.048,26.202,
"157.05",15.056,26.22667,
"157.20",15.066,26.252,
"157.35",15.073,26.27667,
"157.50",15.083,26.30167,
"157.65",15.091,26.327,
"157.80",15.093,26.35167,
"157.95",15.11,26.37667,
"158.10",15.12,26.40167,
"158.25",15.13,26.427,
"158.40",15.137,26.452,
"158.55",15.143,26.477,
"158.70",15.153,26.502,
"158.85",15.162,26.527,
"159.00",15.168,26.55167,
"159.15",15.179,26.57667,
"159.30",15.186,26.60167,
"159.45",15.189,26.62667,
"159.60",15.197,26.65167,
"159.75",15.202,26.67667,
"159.90",15.212,26.70167,
"160.05",15.221,26.72667,
"160.20",15.231,26.75167,
"160.35",15.237,26.77667,
"160.50",15.247,26.802,
"160.65",15.255,26.827,
"160.80",15.26,26.85167,
"160.95",15.272,26.87667,
"161.10",15.28,26.90167,
"161.25",15.287,26.92667,
"161.40",15.293,26.95167,
"161.55",15.299,26.97667,
"161.70",15.309,27.00167,
"161.85",15.314,27.02667,
"162.00",15.327,27.05167,
"162.15",15.336,27.07667,
"162.30",15.342,27.10167,
"162.45",15.346,27.12667,
"162.60",15.353,27.15167,
"162.75",15.362,27.17667,
"162.90",15.372,27.20167,
"163.05",15.38,27.22667,
"163.20",15.391,27.25167,
"163.35",15.404,27.27667,
"163.50",15.411,27.30167,
"163.65",15.415,27.32667,
"163.80",15.424,27.35167,
"163.95",15.435,27.37667,
"164.10",15.446,27.40167,
"164.25",15.457,27.42667,
"164.40",15.464,27.452,
"164.55",15.472,27.47667,
"164.70",15.481,27.50167,
"164.85",15.483,27.52667,
"165.00",15.499,27.55167,
"165.15",15.503,27.57667,
"165.30",15.5,27.60167,
"165.45",15.503,27.62667,
"165.60",15.507,27.65167,
"165.75",15.517,27.67667,
"165.90",15.529,27.70167,
"166.05",15.532,27.72667,
"166.20",15.544,27.75167,
"166.35",15.552,27.77667,
"166.50",15.556,27.80167,
"166.65",15.568,27.82667,
"166.80",15.576,27.85167,
"166.95",15.587,27.87667,
"167.10",15.599,27.90167,
"167.25",15.603,27.92667,
"167.40",15.608,27.95167,
"167.55",15.617,27.97667,
"167.70",15.627,28.00167,
"167.85",15.635,28.02667,
"168.00",15.649,28.05167,
"168.15",15.656,28.07667,
"168.30",15.668,28.10167,
"168.45",15.673,28.12667,
"168.60",15.68,28.15167,
"168.75",15.689,28.17667,
"168.90",15.701,28.20167,
"169.05",15.707,28.22667,
"169.20",15.724,28.25167,
"169.35",15.731,28.27667,
"169.50",15.739,28.30167,
"169.65",15.746,28.32667,
"169.80",15.755,28.35167,
"169.95",15.764,28.37667,
"170.10",15.776,28.40167,
"170.25",15.779,28.427,
"170.40",15.785,28.452,
"170.55",15.794,28.47667,
"170.70",15.803,28.50167,
"170.85",15.812,28.527,
"171.00",15.823,28.55167,
"171.15",15.832,28.577,
"171.30",15.84,28.60167,
"171.45",15.843,28.62667,
"171.60",15.853,28.65167,
"171.75",15.863,28.67667,
"171.90",15.869,28.70167,
"172.05",15.879,28.72667,
"172.20",15.889,28.75167,
"172.35",15.893,28.77667,
"172.50",15.897,28.80167,
"172.65",15.907,28.82667,
"172.80",15.913,28.85167,
"172.95",15.927,28.87667,
"173.10",15.937,28.90167,
"173.25",15.941,28.92667,
"173.40",15.952,28.95167,
"173.55",15.957,28.97667,
"173.70",15.962,29.00167,
"173.85",15.972,29.027,
"174.00",15.98,29.052,
"174.15",15.989,29.077,
"174.30",16.002,29.102,
"174.45",16.004,29.12667,
"174.60",16.008,29.15167,
"174.75",16.019,29.177,
"174.90",16.027,29.20167,
"175.05",16.033,29.22667,
"175.20",16.045,29.25167,
"175.35",16.05,29.27667,
"175.50",16.06,29.30167,
"175.65",16.067,29.327,
"175.80",16.077,29.352,
"175.95",16.086,29.377,
"176.10",16.097,29.402,
"176.25",16.105,29.427,
"176.40",16.109,29.452,
"176.55",16.116,29.47667,
"176.70",16.126,29.50167,
"176.85",16.135,29.52667,
"177.00",16.142,29.55167,
"177.15",16.15,29.57667,
"177.30",16.157,29.60167,
"177.45",16.165,29.62667,
"177.60",16.171,29.65167,
"177.75",16.179,29.67667,
"177.90",16.188,29.70167,
"178.05",16.197,29.72667,
"178.20",16.207,29.75167,
"178.35",16.212,29.77667,
"178.50",16.221,29.80167,
"178.65",16.227,29.82667,
"178.80",16.231,29.85167,
"178.95",16.242,29.87667,
"179.10",16.249,29.90167,
"179.25",16.258,29.92667,
"179.40",16.262,29.95167,
"179.55",16.269,29.97667,
"179.70",16.275,30.00167,
"179.85",16.277,30.02667,
"180.00",16.287,30.05167,
"180.15",16.293,30.07667,
"180.30",16.3,30.10167,
"180.45",16.307,30.12667,
"180.60",16.315,30.15167,
"180.75",16.322,30.177,
"180.90",16.331,30.20167,
"181.05",16.341,30.22667,
"181.20",16.343,30.25167,
"181.35",16.351,30.27667,
"181.50",16.355,30.30167,
"181.65",16.358,30.32667,
"181.80",16.363,30.35167,
"181.95",16.374,30.37667,
"182.10",16.383,30.402,
"182.25",16.388,30.427,
"182.40",16.393,30.452,
"182.55",16.403,30.477,
"182.70",16.411,30.502,
"182.85",16.414,30.527,
"183.00",16.416,30.55167,
"183.15",16.425,30.577,
"183.30",16.432,30.60167,
"183.45",16.438,30.62667,
"183.60",16.443,30.65167,
"183.75",16.453,30.67667,
"183.90",16.464,30.702,
"184.05",16.474,30.727,
"184.20",16.482,30.752,
"184.35",16.49,30.777,
"184.50",16.502,30.80167,
"184.65",16.506,30.827,
"184.80",16.514,30.85167,
"184.95",16.524,30.87667,
"185.10",16.534,30.90167,
"185.25",16.539,30.92667,
"185.40",16.545,30.952,
"185.55",16.552,30.97667,
"185.70",16.563,31.002,
"185.85",16.573,31.027,
"186.00",16.58,31.052,
"186.15",16.588,31.077,
"186.30",16.593,31.102,
"186.45",16.599,31.12667,
"186.60",16.603,31.15167,
"186.75",16.614,31.17667,
"186.90",16.625,31.20167,
"187.05",16.63,31.22667,
"187.20",16.637,31.25167,
"187.35",16.645,31.277,
"187.50",16.651,31.30167,
"187.65",16.655,31.327,
"187.80",16.659,31.352,
"187.95",16.67,31.37667,
"188.10",16.677,31.402,
"188.25",16.686,31.427,
"188.40",16.691,31.452,
"188.55",16.695,31.477,
"188.70",16.701,31.502,
"188.85",16.711,31.527,
"189.00",16.716,31.55167,
"189.15",16.722,31.57667,
"189.30",16.729,31.60167,
"189.45",16.734,31.62667,
"189.60",16.738,31.65167,
"189.75",16.742,31.67667,
"189.90",16.753,31.702,
"190.05",16.757,31.727,
"190.20",16.763,31.752,
"190.35",16.769,31.77667,
"190.50",16.773,31.80167,
"190.65",16.777,31.827,
"190.80",16.783,31.85167,
"190.95",16.79,31.87667,
"191.10",16.802,31.90167,
"191.25",16.804,31.92667,
"191.40",16.808,31.952,
"191.55",16.816,31.97667,
"191.70",16.821,32.00167,
"191.85",16.823,32.02667,
"192.00",16.829,32.05167,
"192.15",16.836,32.077,
"192.30",16.84,32.102,
"192.45",16.841,32.127,
"192.60",16.844,32.15167,
"192.75",16.85,32.17667,
"192.90",16.857,32.20167,
"193.05",16.861,32.22667,
"193.20",16.864,32.25167,
"193.35",16.872,32.27667,
"193.50",16.875,32.30167,
"193.65",16.878,32.32667,
"193.80",16.887,32.35167,
"193.95",16.895,32.37667,
"194.10",16.906,32.40167,
"194.25",16.91,32.42667,
"194.40",16.916,32.452,
"194.55",16.926,32.47667,
"194.70",16.932,32.50167,
"194.85",16.936,32.52667,
"195.00",16.945,32.55167,
"195.15",16.953,32.57667,
"195.30",16.964,32.60167,
"195.45",16.97,32.62667,
"195.60",16.974,32.65167,
"195.75",16.984,32.67667,
"195.90",16.995,32.70167,
"196.05",17.004,32.72667,
"196.20",17.008,32.75167,
"196.35",17.013,32.77667,
"196.50",17.022,32.80167,
"196.65",17.032,32.82667,
"196.80",17.038,32.85167,
"196.95",17.053,32.87667,
"197.10",17.06,32.90167,
"197.25",17.06,32.92667,
"197.40",17.065,32.95167,
"197.55",17.07,32.97667,
"197.70",17.077,33.00167,
"197.85",17.087,33.02667,
"198.00",17.094,33.05167,
"198.15",17.106,33.07667,
"198.30",17.112,33.10167,
"198.45",17.113,33.12667,
"198.60",17.119,33.15167,
"198.75",17.124,33.17633,
"198.90",17.13,33.20167,
"199.05",17.14,33.22667,
"199.20",17.146,33.25167,
"199.35",17.151,33.27634,
"199.50",17.159,33.30133,
"199.65",17.163,33.32634,
"199.80",17.166,33.35133,
"199.95",17.176,33.37634,
"200.10",17.179,33.40134,
"200.25",17.181,33.42667,
"200.40",17.192,33.45167,
"200.55",17.196,33.47633,
"200.70",17.202,33.50167,
"200.85",17.212,33.52667,
"201.00",17.214,33.55133,
"201.15",17.218,33.57634,
"201.30",17.227,33.60133,
"201.45",17.227,33.62667,
"201.60",17.225,33.65167,