File: exposed_flourocarbon_10cm_10mmpm_24nm_560esh_3.csv
"Test Name","Test Mode","Test Type","Control","Test Speed 1","Test Speed 2","Test Speed 3","Change Point 1","Change Point 2","Disp. Origin","Break and Limit Action","Sensitivity:","Level:"
"","Single","Tensile","Stroke",10,1,1,"Off","Off","Start","Stop",0,1

"Title","Sub title","Comment"
"","",""

"Shape:","Batch Size:","SubBatch Size:"
"Plate",1,1
"Name:","Thickness","Width","Gauge Length",
"Size Unit:","mm","mm","mm",
" 1 - 1","1.0000","1.0000","100.0000",

"Name",
"Parameter",
"Units",
" 1 - 1",

" 1- 1"
"Time","Force","Stroke",
"sec","N","mm",
"0.00",0,0,
"0.10",-.001,1.833333E-02,
"0.20",0,.037,
"0.30",-.001,5.533333E-02,
"0.40",0,7.366666E-02,
"0.50",0,.092,
"0.60",.002,.1103333,
"0.70",.006,.1286667,
"0.80",.012,.1473333,
"0.90",.019,.1656667,
"1.00",.033,.184,
"1.10",.049,.2023333,
"1.20",.065,.2206667,
"1.30",.082,.239,
"1.40",.098,.2573333,
"1.50",.116,.276,
"1.60",.132,.2943333,
"1.70",.15,.3126667,
"1.80",.168,.331,
"1.90",.185,.3493333,
"2.00",.203,.3676667,
"2.10",.22,.3853333,
"2.20",.237,.4033333,
"2.30",.253,.421,
"2.40",.27,.4386667,
"2.50",.288,.4563333,
"2.60",.303,.4736667,
"2.70",.319,.491,
"2.80",.336,.5083333,
"2.90",.353,.5256667,
"3.00",.369,.5426667,
"3.10",.386,.56,
"3.20",.402,.577,
"3.30",.416,.5943334,
"3.40",.431,.611,
"3.50",.448,.6283333,
"3.60",.464,.645,
"3.70",.48,.662,
"3.80",.495,.679,
"3.90",.51,.6956667,
"4.00",.526,.7126666,
"4.10",.542,.7293333,
"4.20",.557,.7463333,
"4.30",.573,.763,
"4.40",.588,.78,
"4.50",.602,.7966667,
"4.60",.616,.8133333,
"4.70",.631,.8303334,
"4.80",.647,.847,
"4.90",.662,.8636667,
"5.00",.674,.8806667,
"5.10",.691,.8973333,
"5.20",.707,.914,
"5.30",.719,.9306667,
"5.40",.732,.9473333,
"5.50",.747,.964,
"5.60",.762,.9806666,
"5.70",.778,.9973333,
"5.80",.793,1.014,
"5.90",.804,1.031,
"6.00",.817,1.047667,
"6.10",.833,1.064333,
"6.20",.847,1.081,
"6.30",.86,1.097667,
"6.40",.874,1.114333,
"6.50",.888,1.131,
"6.60",.901,1.147667,
"6.70",.912,1.164333,
"6.80",.926,1.181,
"6.90",.942,1.197333,
"7.00",.955,1.214333,
"7.10",.969,1.231,
"7.20",.982,1.247667,
"7.30",.995,1.264333,
"7.40",1.007,1.281,
"7.50",1.019,1.297667,
"7.60",1.032,1.314333,
"7.70",1.045,1.331,
"7.80",1.057,1.347667,
"7.90",1.07,1.364333,
"8.00",1.085,1.381,
"8.10",1.096,1.397667,
"8.20",1.107,1.414333,
"8.30",1.117,1.431,
"8.40",1.129,1.447667,
"8.50",1.143,1.464333,
"8.60",1.154,1.481,
"8.70",1.164,1.497667,
"8.80",1.177,1.514333,
"8.90",1.19,1.531,
"9.00",1.202,1.547667,
"9.10",1.213,1.564333,
"9.20",1.224,1.581,
"9.30",1.236,1.597667,
"9.40",1.247,1.614333,
"9.50",1.258,1.631,
"9.60",1.27,1.647667,
"9.70",1.281,1.664667,
"9.80",1.291,1.681,
"9.90",1.302,1.697667,
"10.00",1.313,1.714333,
"10.10",1.323,1.731,
"10.20",1.334,1.747667,
"10.30",1.345,1.764333,
"10.40",1.355,1.781,
"10.50",1.365,1.797667,
"10.60",1.375,1.814667,
"10.70",1.387,1.831,
"10.80",1.397,1.847667,
"10.90",1.404,1.864333,
"11.00",1.414,1.881,
"11.10",1.424,1.897667,
"11.20",1.434,1.914333,
"11.30",1.443,1.931,
"11.40",1.452,1.947667,
"11.50",1.462,1.964333,
"11.60",1.473,1.981,
"11.70",1.484,1.997667,
"11.80",1.493,2.014333,
"11.90",1.504,2.031,
"12.00",1.513,2.047667,
"12.10",1.521,2.064333,
"12.20",1.53,2.081,
"12.30",1.536,2.097667,
"12.40",1.545,2.114333,
"12.50",1.557,2.131333,
"12.60",1.567,2.148,
"12.70",1.576,2.164667,
"12.80",1.586,2.181,
"12.90",1.595,2.197667,
"13.00",1.602,2.214333,
"13.10",1.61,2.231,
"13.20",1.621,2.247667,
"13.30",1.63,2.264333,
"13.40",1.638,2.281,
"13.50",1.646,2.297667,
"13.60",1.655,2.314333,
"13.70",1.663,2.331,
"13.80",1.673,2.347667,
"13.90",1.683,2.364333,
"14.00",1.69,2.381,
"14.10",1.7,2.397667,
"14.20",1.71,2.414333,
"14.30",1.717,2.431,
"14.40",1.725,2.447667,
"14.50",1.731,2.464333,
"14.60",1.739,2.481,
"14.70",1.747,2.497667,
"14.80",1.758,2.514333,
"14.90",1.766,2.531,
"15.00",1.776,2.547667,
"15.10",1.784,2.564333,
"15.20",1.793,2.581,
"15.30",1.801,2.597667,
"15.40",1.806,2.614333,
"15.50",1.811,2.631,
"15.60",1.821,2.647667,
"15.70",1.83,2.664333,
"15.80",1.839,2.681,
"15.90",1.849,2.697667,
"16.00",1.857,2.714333,
"16.10",1.865,2.731,
"16.20",1.874,2.747667,
"16.30",1.881,2.764333,
"16.40",1.889,2.781,
"16.50",1.895,2.797667,
"16.60",1.905,2.814333,
"16.70",1.913,2.831,
"16.80",1.922,2.847667,
"16.90",1.931,2.864333,
"17.00",1.94,2.881,
"17.10",1.947,2.897667,
"17.20",1.952,2.914333,
"17.30",1.959,2.931,
"17.40",1.97,2.947667,
"17.50",1.978,2.964333,
"17.60",1.985,2.981,
"17.70",1.993,2.997667,
"17.80",2.002,3.014333,
"17.90",2.01,3.031,
"18.00",2.019,3.047667,
"18.10",2.026,3.064333,
"18.20",2.034,3.081,
"18.30",2.041,3.097667,
"18.40",2.047,3.114333,
"18.50",2.056,3.131,
"18.60",2.067,3.147667,
"18.70",2.076,3.164667,
"18.80",2.082,3.181333,
"18.90",2.088,3.198,
"19.00",2.097,3.214667,
"19.10",2.107,3.231,
"19.20",2.114,3.248,
"19.30",2.121,3.264667,
"19.40",2.13,3.281,
"19.50",2.138,3.298,
"19.60",2.145,3.314667,
"19.70",2.154,3.331,
"19.80",2.163,3.347667,
"19.90",2.169,3.364333,
"20.00",2.177,3.381333,
"20.10",2.186,3.397667,
"20.20",2.196,3.414667,
"20.30",2.204,3.431333,
"20.40",2.211,3.447667,
"20.50",2.218,3.464333,
"20.60",2.225,3.481,
"20.70",2.232,3.497667,
"20.80",2.241,3.514333,
"20.90",2.249,3.531,
"21.00",2.257,3.547667,
"21.10",2.264,3.564333,
"21.20",2.273,3.581,
"21.30",2.282,3.597667,
"21.40",2.289,3.614333,
"21.50",2.296,3.631,
"21.60",2.304,3.648,
"21.70",2.313,3.664667,
"21.80",2.322,3.681,
"21.90",2.331,3.697667,
"22.00",2.34,3.714667,
"22.10",2.349,3.731,
"22.20",2.356,3.747667,
"22.30",2.361,3.764333,
"22.40",2.371,3.781,
"22.50",2.378,3.797667,
"22.60",2.387,3.814667,
"22.70",2.397,3.831333,
"22.80",2.404,3.848,
"22.90",2.411,3.864333,
"23.00",2.42,3.881,
"23.10",2.427,3.897667,
"23.20",2.436,3.914333,
"23.30",2.444,3.931,
"23.40",2.452,3.947667,
"23.50",2.459,3.964333,
"23.60",2.469,3.981,
"23.70",2.478,3.997667,
"23.80",2.486,4.014334,
"23.90",2.493,4.031,
"24.00",2.503,4.047667,
"24.10",2.511,4.064333,
"24.20",2.521,4.081,
"24.30",2.527,4.097667,
"24.40",2.535,4.114334,
"24.50",2.544,4.131,
"24.60",2.553,4.147667,
"24.70",2.561,4.164333,
"24.80",2.57,4.181,
"24.90",2.578,4.197667,
"25.00",2.588,4.214334,
"25.10",2.597,4.231,
"25.20",2.605,4.247667,
"25.30",2.613,4.264334,
"25.40",2.621,4.281,
"25.50",2.629,4.297667,
"25.60",2.638,4.314333,
"25.70",2.645,4.331,
"25.80",2.653,4.347667,
"25.90",2.661,4.364334,
"26.00",2.67,4.381,
"26.10",2.678,4.397667,
"26.20",2.687,4.414333,
"26.30",2.696,4.431,
"26.40",2.703,4.447667,
"26.50",2.711,4.464334,
"26.60",2.723,4.481,
"26.70",2.731,4.497667,
"26.80",2.738,4.514334,
"26.90",2.747,4.531,
"27.00",2.756,4.547667,
"27.10",2.765,4.564333,
"27.20",2.774,4.581,
"27.30",2.78,4.597667,
"27.40",2.789,4.614334,
"27.50",2.8,4.631,
"27.60",2.809,4.647667,
"27.70",2.818,4.664333,
"27.80",2.828,4.681,
"27.90",2.835,4.697667,
"28.00",2.844,4.714334,
"28.10",2.852,4.731,
"28.20",2.863,4.747667,
"28.30",2.869,4.764334,
"28.40",2.878,4.781,
"28.50",2.885,4.797667,
"28.60",2.894,4.814333,
"28.70",2.903,4.831,
"28.80",2.913,4.847667,
"28.90",2.923,4.864334,
"29.00",2.932,4.881333,
"29.10",2.941,4.897667,
"29.20",2.948,4.914667,
"29.30",2.956,4.931334,
"29.40",2.965,4.948,
"29.50",2.974,4.964667,
"29.60",2.983,4.981334,
"29.70",2.993,4.998,
"29.80",3.002,5.014667,
"29.90",3.011,5.031,
"30.00",3.02,5.048,
"30.10",3.03,5.064333,
"30.20",3.04,5.081,
"30.30",3.049,5.097667,
"30.40",3.057,5.114334,
"30.50",3.065,5.131,
"30.60",3.073,5.147667,
"30.70",3.081,5.164333,
"30.80",3.091,5.181,
"30.90",3.1,5.197667,
"31.00",3.11,5.214334,
"31.10",3.121,5.231,
"31.20",3.131,5.247667,
"31.30",3.138,5.264667,
"31.40",3.147,5.281,
"31.50",3.156,5.297667,
"31.60",3.166,5.314333,
"31.70",3.175,5.331,
"31.80",3.184,5.347667,
"31.90",3.193,5.364334,
"32.00",3.203,5.381,
"32.10",3.212,5.397667,
"32.20",3.222,5.414333,
"32.30",3.231,5.431,
"32.40",3.24,5.447667,
"32.50",3.249,5.464334,
"32.60",3.258,5.481,
"32.70",3.267,5.497667,
"32.80",3.277,5.514334,
"32.90",3.287,5.531,
"33.00",3.295,5.547667,
"33.10",3.303,5.564333,
"33.20",3.314,5.581,
"33.30",3.323,5.597667,
"33.40",3.331,5.614334,
"33.50",3.339,5.631,
"33.60",3.349,5.647667,
"33.70",3.361,5.664333,
"33.80",3.371,5.681,
"33.90",3.379,5.697667,
"34.00",3.389,5.714334,
"34.10",3.399,5.731,
"34.20",3.409,5.747667,
"34.30",3.42,5.764334,
"34.40",3.429,5.781,
"34.50",3.437,5.797667,
"34.60",3.445,5.814333,
"34.70",3.456,5.831,
"34.80",3.466,5.847667,
"34.90",3.475,5.864334,
"35.00",3.487,5.881,
"35.10",3.499,5.897667,
"35.20",3.508,5.914333,
"35.30",3.516,5.931,
"35.40",3.526,5.947667,
"35.50",3.535,5.964334,
"35.60",3.545,5.981,
"35.70",3.556,5.997667,
"35.80",3.565,6.014334,
"35.90",3.574,6.030667,
"36.00",3.584,6.047667,
"36.10",3.595,6.064,
"36.20",3.605,6.081,
"36.30",3.615,6.097667,
"36.40",3.625,6.114334,
"36.50",3.635,6.131,
"36.60",3.646,6.147667,
"36.70",3.655,6.164333,
"36.80",3.667,6.180667,
"36.90",3.679,6.197333,
"37.00",3.688,6.214334,
"37.10",3.697,6.231,
"37.20",3.707,6.247334,
"37.30",3.717,6.264334,
"37.40",3.726,6.280667,
"37.50",3.735,6.297667,
"37.60",3.746,6.314333,
"37.70",3.755,6.331,
"37.80",3.766,6.347333,
"37.90",3.774,6.364334,
"38.00",3.787,6.381,
"38.10",3.797,6.397667,
"38.20",3.805,6.414333,
"38.30",3.815,6.431,
"38.40",3.826,6.447333,
"38.50",3.835,6.464,
"38.60",3.845,6.481,
"38.70",3.856,6.497667,
"38.80",3.866,6.514,
"38.90",3.876,6.530667,
"39.00",3.885,6.547667,
"39.10",3.894,6.564333,
"39.20",3.904,6.581,
"39.30",3.914,6.597667,
"39.40",3.926,6.614334,
"39.50",3.936,6.631,
"39.60",3.944,6.647667,
"39.70",3.954,6.664333,
"39.80",3.965,6.681,
"39.90",3.975,6.697667,
"40.00",3.986,6.714334,
"40.10",3.996,6.731,
"40.20",4.006,6.747667,
"40.30",4.016,6.764334,
"40.40",4.024,6.781,
"40.50",4.034,6.797667,
"40.60",4.047,6.814333,
"40.70",4.057,6.831,
"40.80",4.069,6.847667,
"40.90",4.08,6.864334,
"41.00",4.089,6.881,
"41.10",4.099,6.897667,
"41.20",4.109,6.914333,
"41.30",4.122,6.931,
"41.40",4.133,6.947667,
"41.50",4.143,6.964334,
"41.60",4.153,6.981,
"41.70",4.164,6.997667,
"41.80",4.176,7.014334,
"41.90",4.188,7.031,
"42.00",4.198,7.047667,
"42.10",4.209,7.064333,
"42.20",4.22,7.080667,
"42.30",4.229,7.097667,
"42.40",4.24,7.114,
"42.50",4.25,7.131,
"42.60",4.262,7.147667,
"42.70",4.274,7.164333,
"42.80",4.285,7.181,
"42.90",4.295,7.197333,
"43.00",4.306,7.214,
"43.10",4.317,7.230667,
"43.20",4.328,7.247334,
"43.30",4.339,7.264334,
"43.40",4.349,7.280667,
"43.50",4.359,7.297334,
"43.60",4.37,7.314333,
"43.70",4.384,7.330667,
"43.80",4.397,7.347333,
"43.90",4.408,7.364,
"44.00",4.417,7.380667,
"44.10",4.427,7.397334,
"44.20",4.44,7.414,
"44.30",4.452,7.430667,
"44.40",4.462,7.447333,
"44.50",4.474,7.464,
"44.60",4.484,7.480667,
"44.70",4.495,7.497667,
"44.80",4.506,7.514334,
"44.90",4.518,7.530667,
"45.00",4.53,7.547334,
"45.10",4.538,7.564,
"45.20",4.551,7.580667,
"45.30",4.564,7.597667,
"45.40",4.574,7.614,
"45.50",4.585,7.630667,
"45.60",4.595,7.647334,
"45.70",4.607,7.664333,
"45.80",4.62,7.680667,
"45.90",4.633,7.697333,
"46.00",4.644,7.714,
"46.10",4.655,7.730667,
"46.20",4.667,7.747334,
"46.30",4.678,7.764,
"46.40",4.691,7.780667,
"46.50",4.703,7.797667,
"46.60",4.714,7.814333,
"46.70",4.725,7.831,
"46.80",4.736,7.847667,
"46.90",4.751,7.864,
"47.00",4.764,7.881,
"47.10",4.774,7.897334,
"47.20",4.785,7.914333,
"47.30",4.796,7.930667,
"47.40",4.805,7.947333,
"47.50",4.815,7.964334,
"47.60",4.827,7.981,
"47.70",4.84,7.997667,
"47.80",4.851,8.014333,
"47.90",4.866,8.031,
"48.00",4.881,8.047667,
"48.10",4.891,8.064333,
"48.20",4.901,8.080999,
"48.30",4.911,8.097667,
"48.40",4.922,8.113999,
"48.50",4.934,8.131,
"48.60",4.947,8.147666,
"48.70",4.958,8.164333,
"48.80",4.97,8.181,
"48.90",4.986,8.197666,
"49.00",5,8.214333,
"49.10",5.01,8.231,
"49.20",5.02,8.247666,
"49.30",5.033,8.264333,
"49.40",5.045,8.281,
"49.50",5.056,8.297667,
"49.60",5.069,8.314333,
"49.70",5.081,8.330999,
"49.80",5.093,8.347667,
"49.90",5.107,8.364333,
"50.00",5.12,8.381,
"50.10",5.131,8.397666,
"50.20",5.142,8.414333,
"50.30",5.153,8.431,
"50.40",5.165,8.447666,
"50.50",5.177,8.464333,
"50.60",5.189,8.481,
"50.70",5.204,8.497666,
"50.80",5.217,8.514333,
"50.90",5.228,8.531,
"51.00",5.241,8.547667,
"51.10",5.252,8.564333,
"51.20",5.263,8.580999,
"51.30",5.277,8.597667,
"51.40",5.289,8.614333,
"51.50",5.301,8.631,
"51.60",5.315,8.647666,
"51.70",5.329,8.664333,
"51.80",5.34,8.681,
"51.90",5.352,8.697666,
"52.00",5.364,8.714333,
"52.10",5.378,8.731,
"52.20",5.39,8.747666,
"52.30",5.402,8.764333,
"52.40",5.416,8.781,
"52.50",5.428,8.797667,
"52.60",5.44,8.814333,
"52.70",5.454,8.830999,
"52.80",5.468,8.847667,
"52.90",5.481,8.864333,
"53.00",5.493,8.881,
"53.10",5.507,8.897666,
"53.20",5.52,8.914333,
"53.30",5.532,8.931333,
"53.40",5.545,8.947666,
"53.50",5.557,8.964333,
"53.60",5.571,8.981333,
"53.70",5.585,8.997666,
"53.80",5.599,9.014333,
"53.90",5.612,9.031,
"54.00",5.624,9.047667,
"54.10",5.637,9.064333,
"54.20",5.65,9.080999,
"54.30",5.661,9.097667,
"54.40",5.673,9.114333,
"54.50",5.687,9.131,
"54.60",5.7,9.147666,
"54.70",5.713,9.164333,
"54.80",5.727,9.181,
"54.90",5.74,9.197666,
"55.00",5.756,9.214333,
"55.10",5.771,9.231,
"55.20",5.782,9.247666,
"55.30",5.793,9.264333,
"55.40",5.806,9.281,
"55.50",5.819,9.297667,
"55.60",5.832,9.314333,
"55.70",5.845,9.330999,
"55.80",5.86,9.347667,
"55.90",5.875,9.364333,
"56.00",5.887,9.381,
"56.10",5.901,9.397666,
"56.20",5.913,9.414333,
"56.30",5.926,9.431,
"56.40",5.94,9.447666,
"56.50",5.954,9.464333,
"56.60",5.968,9.481,
"56.70",5.981,9.497666,
"56.80",5.994,9.514333,
"56.90",6.009,9.531,
"57.00",6.023,9.547667,
"57.10",6.037,9.564333,
"57.20",6.05,9.580999,
"57.30",6.061,9.598,
"57.40",6.075,9.614333,
"57.50",6.089,9.631,
"57.60",6.102,9.647666,
"57.70",6.114,9.664333,
"57.80",6.129,9.681,
"57.90",6.145,9.697666,
"58.00",6.156,9.714333,
"58.10",6.17,9.731,
"58.20",6.185,9.747666,
"58.30",6.199,9.764333,
"58.40",6.211,9.781,
"58.50",6.224,9.797667,
"58.60",6.239,9.814333,
"58.70",6.253,9.830999,
"58.80",6.269,9.847667,
"58.90",6.282,9.864333,
"59.00",6.295,9.881,
"59.10",6.311,9.897666,
"59.20",6.324,9.914333,
"59.30",6.338,9.931,
"59.40",6.349,9.947666,
"59.50",6.362,9.964333,
"59.60",6.377,9.981,
"59.70",6.393,9.997666,
"59.80",6.407,10.01433,
"59.90",6.421,10.031,
"60.00",6.438,10.04767,
"60.10",6.452,10.06433,
"60.20",6.465,10.081,
"60.30",6.479,10.09767,
"60.40",6.493,10.11433,
"60.50",6.509,10.131,
"60.60",6.524,10.14767,
"60.70",6.537,10.16433,
"60.80",6.553,10.181,
"60.90",6.566,10.19767,
"61.00",6.579,10.21433,
"61.10",6.592,10.231,
"61.20",6.606,10.24767,
"61.30",6.621,10.26433,
"61.40",6.635,10.281,
"61.50",6.651,10.29767,
"61.60",6.667,10.31433,
"61.70",6.679,10.331,
"61.80",6.692,10.34767,
"61.90",6.707,10.36433,
"62.00",6.725,10.381,
"62.10",6.741,10.39767,
"62.20",6.755,10.41433,
"62.30",6.768,10.431,
"62.40",6.782,10.44767,
"62.50",6.796,10.46433,
"62.60",6.811,10.481,
"62.70",6.826,10.49767,
"62.80",6.84,10.51433,
"62.90",6.856,10.531,
"63.00",6.872,10.54767,
"63.10",6.888,10.56433,
"63.20",6.902,10.581,
"63.30",6.912,10.59767,
"63.40",6.927,10.61433,
"63.50",6.943,10.631,
"63.60",6.957,10.64767,
"63.70",6.972,10.66433,
"63.80",6.988,10.681,
"63.90",7.004,10.69767,
"64.00",7.02,10.71433,
"64.10",7.035,10.731,
"64.20",7.049,10.74767,
"64.30",7.063,10.76433,
"64.40",7.079,10.781,
"64.50",7.095,10.79767,
"64.60",7.109,10.81433,
"64.70",7.123,10.831,
"64.80",7.14,10.84733,
"64.90",7.156,10.864,
"65.00",7.172,10.881,
"65.10",7.187,10.89767,
"65.20",7.201,10.91433,
"65.30",7.216,10.931,
"65.40",7.234,10.94767,
"65.50",7.249,10.96433,
"65.60",7.264,10.981,
"65.70",7.277,10.99767,
"65.80",7.292,11.01433,
"65.90",7.309,11.031,
"66.00",7.325,11.04767,
"66.10",7.341,11.06433,
"66.20",7.357,11.081,
"66.30",7.372,11.09767,
"66.40",7.385,11.11433,
"66.50",7.401,11.131,
"66.60",7.416,11.14767,
"66.70",7.433,11.16433,
"66.80",7.449,11.181,
"66.90",7.464,11.19767,
"67.00",7.48,11.21433,
"67.10",7.495,11.231,
"67.20",7.511,11.24767,
"67.30",7.527,11.26433,
"67.40",7.542,11.281,
"67.50",7.557,11.29767,
"67.60",7.574,11.31433,
"67.70",7.591,11.331,
"67.80",7.608,11.34767,
"67.90",7.625,11.36433,
"68.00",7.639,11.381,
"68.10",7.657,11.39767,
"68.20",7.673,11.41433,
"68.30",7.687,11.431,
"68.40",7.701,11.44767,
"68.50",7.718,11.46433,
"68.60",7.732,11.481,
"68.70",7.747,11.49767,
"68.80",7.767,11.51433,
"68.90",7.786,11.531,
"69.00",7.802,11.54767,
"69.10",7.817,11.56433,
"69.20",7.835,11.581,
"69.30",7.85,11.59767,
"69.40",7.864,11.61433,
"69.50",7.879,11.631,
"69.60",7.894,11.64767,
"69.70",7.91,11.66433,
"69.80",7.928,11.681,
"69.90",7.946,11.69767,
"70.00",7.963,11.71433,
"70.10",7.979,11.731,
"70.20",7.996,11.74767,
"70.30",8.013,11.76433,
"70.40",8.027,11.781,
"70.50",8.042,11.79767,
"70.60",8.06,11.81433,
"70.70",8.076,11.831,
"70.80",8.09,11.84767,
"70.90",8.106,11.86433,
"71.00",8.125,11.881,
"71.10",8.14,11.89767,
"71.20",8.156,11.91433,
"71.30",8.172,11.931,
"71.40",8.188,11.94767,
"71.50",8.206,11.96433,
"71.60",8.223,11.981,
"71.70",8.238,11.99767,
"71.80",8.256,12.01433,
"71.90",8.274,12.031,
"72.00",8.29,12.04767,
"72.10",8.308,12.064,
"72.20",8.324,12.081,
"72.30",8.339,12.09767,
"72.40",8.354,12.114,
"72.50",8.371,12.13067,
"72.60",8.389,12.14733,
"72.70",8.405,12.164,
"72.80",8.423,12.18067,
"72.90",8.442,12.19733,
"73.00",8.459,12.21433,
"73.10",8.474,12.231,
"73.20",8.491,12.24767,
"73.30",8.506,12.26433,
"73.40",8.52,12.28067,
"73.50",8.536,12.29733,
"73.60",8.554,12.31433,
"73.70",8.572,12.331,
"73.80",8.589,12.34733,
"73.90",8.603,12.364,
"74.00",8.619,12.381,
"74.10",8.637,12.39733,
"74.20",8.653,12.414,
"74.30",8.668,12.431,
"74.40",8.684,12.44733,
"74.50",8.7,12.46433,
"74.60",8.715,12.481,
"74.70",8.735,12.49767,
"74.80",8.753,12.51433,
"74.90",8.769,12.531,
"75.00",8.787,12.54767,
"75.10",8.804,12.56433,
"75.20",8.822,12.581,
"75.30",8.841,12.59767,
"75.40",8.856,12.61433,
"75.50",8.872,12.631,
"75.60",8.887,12.64767,
"75.70",8.903,12.66433,
"75.80",8.922,12.681,
"75.90",8.942,12.69767,
"76.00",8.961,12.71433,
"76.10",8.977,12.731,
"76.20",8.993,12.74767,
"76.30",9.013,12.76433,
"76.40",9.03,12.781,
"76.50",9.047,12.79767,
"76.60",9.065,12.81433,
"76.70",9.081,12.831,
"76.80",9.101,12.84767,
"76.90",9.118,12.86433,
"77.00",9.134,12.881,
"77.10",9.151,12.89767,
"77.20",9.167,12.91433,
"77.30",9.183,12.931,
"77.40",9.199,12.94767,
"77.50",9.219,12.96433,
"77.60",9.239,12.981,
"77.70",9.255,12.99767,
"77.80",9.272,13.01433,
"77.90",9.292,13.031,
"78.00",9.31,13.04767,
"78.10",9.325,13.06433,
"78.20",9.343,13.081,
"78.30",9.361,13.09767,
"78.40",9.378,13.11433,
"78.50",9.397,13.131,
"78.60",9.415,13.14767,
"78.70",9.434,13.16433,
"78.80",9.452,13.181,
"78.90",9.471,13.19767,
"79.00",9.492,13.21433,
"79.10",9.51,13.231,
"79.20",9.527,13.24767,
"79.30",9.545,13.26433,
"79.40",9.562,13.281,
"79.50",9.58,13.29767,
"79.60",9.601,13.31433,
"79.70",9.62,13.331,
"79.80",9.64,13.34767,
"79.90",9.661,13.36433,
"80.00",9.68,13.381,
"80.10",9.694,13.39767,
"80.20",9.71,13.41433,
"80.30",9.73,13.431,
"80.40",9.75,13.44733,
"80.50",9.768,13.464,
"80.60",9.787,13.48067,
"80.70",9.806,13.49733,
"80.80",9.826,13.514,
"80.90",9.847,13.53067,
"81.00",9.866,13.54733,
"81.10",9.886,13.56433,
"81.20",9.905,13.581,
"81.30",9.922,13.59767,
"81.40",9.941,13.61433,
"81.50",9.959,13.63067,
"81.60",9.979,13.64767,
"81.70",9.999,13.66433,
"81.80",10.019,13.681,
"81.90",10.039,13.69767,
"82.00",10.056,13.71433,
"82.10",10.074,13.731,
"82.20",10.094,13.74767,
"82.30",10.113,13.76433,
"82.40",10.131,13.781,
"82.50",10.149,13.79767,
"82.60",10.17,13.81433,
"82.70",10.19,13.831,
"82.80",10.209,13.84767,
"82.90",10.228,13.864,
"83.00",10.247,13.88067,
"83.10",10.266,13.89767,
"83.20",10.285,13.91433,
"83.30",10.303,13.931,
"83.40",10.322,13.94767,
"83.50",10.341,13.96433,
"83.60",10.359,13.981,
"83.70",10.376,13.99767,
"83.80",10.395,14.01433,
"83.90",10.415,14.031,
"84.00",10.436,14.04767,
"84.10",10.455,14.06433,
"84.20",10.472,14.081,
"84.30",10.491,14.09767,
"84.40",10.51,14.11433,
"84.50",10.524,14.131,
"84.60",10.538,14.14767,
"84.70",10.549,14.16433,
"84.80",10.561,14.181,
"84.90",10.576,14.19767,
"85.00",10.589,14.21433,
"85.10",10.604,14.231,
"85.20",10.618,14.24767,
"85.30",10.632,14.26467,
"85.40",10.651,14.281,
"85.50",10.667,14.298,
"85.60",10.682,14.31467,
"85.70",10.698,14.331,
"85.80",10.715,14.34767,
"85.90",10.731,14.36433,
"86.00",10.748,14.381,
"86.10",10.765,14.39767,
"86.20",10.783,14.41433,
"86.30",10.8,14.431,
"86.40",10.818,14.44767,
"86.50",10.836,14.46433,
"86.60",10.856,14.481,
"86.70",10.876,14.498,
"86.80",10.896,14.51467,
"86.90",10.914,14.53133,
"87.00",10.929,14.54767,
"87.10",10.943,14.56433,
"87.20",10.959,14.581,
"87.30",10.971,14.598,
"87.40",10.986,14.61433,
"87.50",10.997,14.631,
"87.60",10.994,14.64767,
"87.70",10.94,14.66467,
"87.80",10.842,14.681,
"87.90",10.757,14.69767,
"88.00",10.7,14.71433,
"88.10",10.652,14.73133,
"88.20",10.595,14.74767,
"88.30",10.493,14.76467,
"88.40",10.36,14.781,
"88.50",10.284,14.79767,
"88.60",10.276,14.81433,
"88.70",10.281,14.831,
"88.80",10.3,14.84767,
"88.90",10.323,14.86433,
"89.00",10.351,14.881,
"89.10",10.38,14.89767,
"89.20",10.408,14.91433,
"89.30",10.434,14.931,
"89.40",10.462,14.94767,
"89.50",10.495,14.96467,
"89.60",10.525,14.98133,
"89.70",10.556,14.998,
"89.80",10.587,15.01467,
"89.90",10.618,15.031,
"90.00",10.649,15.048,
"90.10",10.679,15.06467,
"90.20",10.708,15.081,
"90.30",10.736,15.09767,
"90.40",10.765,15.11433,
"90.50",10.794,15.131,
"90.60",10.821,15.14767,
"90.70",10.849,15.16467,
"90.80",10.875,15.18133,
"90.90",10.9,15.198,
"91.00",10.928,15.21467,
"91.10",10.958,15.23133,
"91.20",10.983,15.248,
"91.30",11.009,15.26467,
"91.40",11.039,15.28133,
"91.50",11.066,15.298,
"91.60",11.092,15.31467,
"91.70",11.12,15.33133,
"91.80",11.145,15.348,
"91.90",11.172,15.36433,
"92.00",11.198,15.381,
"92.10",11.222,15.39767,
"92.20",11.246,15.41433,
"92.30",11.27,15.431,
"92.40",11.295,15.44767,
"92.50",11.319,15.46433,
"92.60",11.345,15.481,
"92.70",11.37,15.498,
"92.80",11.394,15.51467,
"92.90",11.419,15.531,
"93.00",11.443,15.548,
"93.10",11.465,15.56433,
"93.20",11.488,15.581,
"93.30",11.511,15.59767,
"93.40",11.532,15.61433,
"93.50",11.554,15.631,
"93.60",11.577,15.648,
"93.70",11.603,15.66433,
"93.80",11.627,15.68133,
"93.90",11.649,15.698,
"94.00",11.673,15.71467,
"94.10",11.695,15.73133,
"94.20",11.717,15.74767,
"94.30",11.74,15.76433,
"94.40",11.763,15.781,
"94.50",11.784,15.798,
"94.60",11.804,15.81467,
"94.70",11.825,15.83133,
"94.80",11.849,15.848,
"94.90",11.871,15.86433,
"95.00",11.895,15.881,
"95.10",11.918,15.89767,
"95.20",11.94,15.91433,
"95.30",11.959,15.93133,
"95.40",11.979,15.948,
"95.50",12,15.96433,
"95.60",12.021,15.98133,
"95.70",12.046,15.998,
"95.80",12.07,16.01433,
"95.90",12.092,16.031,
"96.00",12.113,16.04767,
"96.10",12.133,16.06433,
"96.20",12.155,16.081,
"96.30",12.175,16.09767,
"96.40",12.198,16.11433,
"96.50",12.22,16.131,
"96.60",12.242,16.14767,
"96.70",12.266,16.16467,
"96.80",12.288,16.181,
"96.90",12.311,16.19767,
"97.00",12.333,16.21467,
"97.10",12.353,16.231,
"97.20",12.377,16.24767,
"97.30",12.397,16.26467,
"97.40",12.418,16.281,
"97.50",12.44,16.298,
"97.60",12.462,16.31467,
"97.70",12.486,16.331,
"97.80",12.509,16.34767,
"97.90",12.532,16.36433,
"98.00",12.555,16.381,
"98.10",12.575,16.39767,
"98.20",12.596,16.41433,
"98.30",12.618,16.431,
"98.40",12.639,16.44767,
"98.50",12.66,16.46433,
"98.60",12.683,16.481,
"98.70",12.705,16.49767,
"98.80",12.728,16.51433,
"98.90",12.752,16.531,
"99.00",12.775,16.54767,
"99.10",12.799,16.56467,
"99.20",12.822,16.581,
"99.30",12.844,16.598,
"99.40",12.864,16.61433,
"99.50",12.886,16.631,
"99.60",12.908,16.648,
"99.70",12.93,16.66467,
"99.80",12.953,16.681,
"99.90",12.977,16.69767,
"100.00",12.998,16.71433,
"100.10",13.021,16.731,
"100.20",13.046,16.74767,
"100.30",13.067,16.76433,
"100.40",13.089,16.781,
"100.50",13.112,16.79767,
"100.60",13.134,16.81433,
"100.70",13.157,16.831,
"100.80",13.179,16.84767,
"100.90",13.202,16.86433,
"101.00",13.227,16.881,
"101.10",13.249,16.89767,
"101.20",13.272,16.91433,
"101.30",13.295,16.93133,
"101.40",13.319,16.948,
"101.50",13.342,16.96467,
"101.60",13.364,16.98133,
"101.70",13.389,16.998,
"101.80",13.413,17.01433,
"101.90",13.439,17.031,
"102.00",13.462,17.04767,
"102.10",13.481,17.06433,
"102.20",13.502,17.081,
"102.30",13.526,17.09767,
"102.40",13.55,17.11433,
"102.50",13.573,17.131,
"102.60",13.596,17.148,
"102.70",13.618,17.16467,
"102.80",13.642,17.181,
"102.90",13.667,17.19767,
"103.00",13.691,17.21433,
"103.10",13.715,17.231,
"103.20",13.738,17.24767,
"103.30",13.758,17.26433,
"103.40",13.78,17.281,
"103.50",13.802,17.29767,
"103.60",13.824,17.31433,
"103.70",13.848,17.331,
"103.80",13.873,17.34767,
"103.90",13.9,17.36433,
"104.00",13.924,17.381,
"104.10",13.949,17.39767,
"104.20",13.972,17.41433,
"104.30",13.995,17.431,
"104.40",14.019,17.44767,
"104.50",14.042,17.46433,
"104.60",14.065,17.481,
"104.70",14.088,17.49767,
"104.80",14.111,17.51433,
"104.90",14.137,17.53067,
"105.00",14.162,17.54733,
"105.10",14.187,17.564,
"105.20",14.21,17.58067,
"105.30",14.233,17.59767,
"105.40",14.257,17.61433,
"105.50",14.283,17.631,
"105.60",14.306,17.64767,
"105.70",14.328,17.66433,
"105.80",14.353,17.681,
"105.90",14.378,17.69767,
"106.00",14.401,17.71433,
"106.10",14.424,17.731,
"106.20",14.448,17.74767,
"106.30",14.471,17.76433,
"106.40",14.495,17.78067,
"106.50",14.519,17.79767,
"106.60",14.543,17.81433,
"106.70",14.568,17.831,
"106.80",14.593,17.84767,
"106.90",14.617,17.86433,
"107.00",14.642,17.881,
"107.10",14.666,17.89767,
"107.20",14.69,17.91433,
"107.30",14.713,17.931,
"107.40",14.736,17.94767,
"107.50",14.761,17.96433,
"107.60",14.785,17.981,
"107.70",14.812,17.99767,
"107.80",14.836,18.01433,
"107.90",14.861,18.031,
"108.00",14.885,18.04767,
"108.10",14.908,18.06433,
"108.20",14.932,18.081,
"108.30",14.954,18.09767,
"108.40",14.976,18.11433,
"108.50",14.999,18.131,
"108.60",15.024,18.14767,
"108.70",15.049,18.16433,
"108.80",15.074,18.181,
"108.90",15.101,18.19767,
"109.00",15.127,18.21433,
"109.10",15.15,18.231,
"109.20",15.172,18.24767,
"109.30",15.196,18.26433,
"109.40",15.219,18.281,
"109.50",15.241,18.29767,
"109.60",15.266,18.31433,
"109.70",15.292,18.331,
"109.80",15.318,18.34767,
"109.90",15.343,18.36433,
"110.00",15.367,18.381,
"110.10",15.392,18.39733,
"110.20",15.413,18.414,
"110.30",15.435,18.431,
"110.40",15.461,18.44733,
"110.50",15.483,18.46433,
"110.60",15.508,18.481,
"110.70",15.534,18.49767,
"110.80",15.557,18.51433,
"110.90",15.583,18.531,
"111.00",15.611,18.54767,
"111.10",15.637,18.56433,
"111.20",15.658,18.58067,
"111.30",15.68,18.59767,
"111.40",15.707,18.61433,
"111.50",15.73,18.631,
"111.60",15.755,18.64767,
"111.70",15.78,18.66433,
"111.80",15.805,18.681,
"111.90",15.832,18.69767,
"112.00",15.858,18.71433,
"112.10",15.882,18.73067,
"112.20",15.906,18.74767,
"112.30",15.93,18.76433,
"112.40",15.954,18.78067,
"112.50",15.98,18.79733,
"112.60",16.003,18.81433,
"112.70",16.027,18.831,
"112.80",16.054,18.84733,
"112.90",16.079,18.864,
"113.00",16.102,18.881,
"113.10",16.125,18.89767,
"113.20",16.149,18.914,
"113.30",16.173,18.931,
"113.40",16.195,18.94733,
"113.50",16.219,18.96433,
"113.60",16.242,18.98067,
"113.70",16.267,18.99767,
"113.80",16.295,19.014,
"113.90",16.321,19.031,
"114.00",16.347,19.04767,
"114.10",16.372,19.06433,
"114.20",16.395,19.081,
"114.30",16.418,19.09767,
"114.40",16.444,19.11433,
"114.50",16.47,19.131,
"114.60",16.494,19.14767,
"114.70",16.519,19.16433,
"114.80",16.545,19.181,
"114.90",16.57,19.19767,
"115.00",16.597,19.21433,
"115.10",16.623,19.231,
"115.20",16.646,19.24767,
"115.30",16.669,19.26433,
"115.40",16.695,19.281,
"115.50",16.72,19.29767,
"115.60",16.743,19.31433,
"115.70",16.767,19.331,
"115.80",16.793,19.34767,
"115.90",16.82,19.36433,
"116.00",16.845,19.381,
"116.10",16.87,19.39767,
"116.20",16.895,19.41433,
"116.30",16.92,19.431,
"116.40",16.946,19.44767,
"116.50",16.971,19.46433,
"116.60",16.997,19.481,
"116.70",17.023,19.49767,
"116.80",17.048,19.51433,
"116.90",17.074,19.531,
"117.00",17.098,19.54767,
"117.10",17.125,19.56433,
"117.20",17.151,19.581,
"117.30",17.174,19.59767,
"117.40",17.198,19.61433,
"117.50",17.223,19.631,
"117.60",17.248,19.64767,
"117.70",17.276,19.66433,
"117.80",17.302,19.681,
"117.90",17.328,19.69767,
"118.00",17.353,19.71433,
"118.10",17.378,19.731,
"118.20",17.4,19.74767,
"118.30",17.422,19.76433,
"118.40",17.447,19.781,
"118.50",17.471,19.79767,
"118.60",17.495,19.81433,
"118.70",17.52,19.831,
"118.80",17.545,19.84767,
"118.90",17.571,19.86433,
"119.00",17.598,19.881,
"119.10",17.622,19.89767,
"119.20",17.645,19.91433,
"119.30",17.669,19.931,
"119.40",17.691,19.94767,
"119.50",17.712,19.96433,
"119.60",17.734,19.981,
"119.70",17.759,19.99767,
"119.80",17.786,20.01433,
"119.90",17.811,20.031,
"120.00",17.834,20.04767,
"120.10",17.858,20.06433,
"120.20",17.883,20.081,
"120.30",17.905,20.09767,
"120.40",17.926,20.11433,
"120.50",17.949,20.131,
"120.60",17.972,20.14767,
"120.70",17.996,20.16433,
"120.80",18.021,20.181,
"120.90",18.045,20.19767,
"121.00",18.069,20.21433,
"121.10",18.092,20.231,
"121.20",18.116,20.24767,
"121.30",18.14,20.26467,
"121.40",18.164,20.281,
"121.50",18.186,20.29767,
"121.60",18.208,20.31433,
"121.70",18.232,20.331,
"121.80",18.259,20.34767,
"121.90",18.285,20.36433,
"122.00",18.306,20.38133,
"122.10",18.33,20.398,
"122.20",18.351,20.41433,
"122.30",18.374,20.431,
"122.40",18.398,20.44767,
"122.50",18.42,20.46433,
"122.60",18.444,20.481,
"122.70",18.468,20.49767,
"122.80",18.494,20.51433,
"122.90",18.519,20.531,
"123.00",18.543,20.54767,
"123.10",18.566,20.56433,
"123.20",18.587,20.581,
"123.30",18.606,20.59767,
"123.40",18.628,20.61433,
"123.50",18.653,20.631,
"123.60",18.676,20.648,
"123.70",18.7,20.66433,
"123.80",18.726,20.681,
"123.90",18.75,20.69767,
"124.00",18.773,20.71433,
"124.10",18.796,20.731,
"124.20",18.818,20.74767,
"124.30",18.84,20.76433,
"124.40",18.862,20.781,
"124.50",18.885,20.79767,
"124.60",18.908,20.81433,
"124.70",18.93,20.831,
"124.80",18.954,20.84767,
"124.90",18.981,20.86433,
"125.00",19.005,20.881,
"125.10",19.027,20.89767,
"125.20",19.047,20.91433,
"125.30",19.069,20.931,
"125.40",19.093,20.94767,
"125.50",19.117,20.96433,
"125.60",19.141,20.981,
"125.70",19.163,20.99767,
"125.80",19.186,21.01433,
"125.90",19.21,21.031,
"126.00",19.235,21.04767,
"126.10",19.259,21.06433,
"126.20",19.281,21.081,
"126.30",19.303,21.09767,
"126.40",19.328,21.114,
"126.50",19.352,21.131,
"126.60",19.375,21.14767,
"126.70",19.399,21.16433,
"126.80",19.424,21.181,
"126.90",19.45,21.19733,
"127.00",19.473,21.21433,
"127.10",19.494,21.231,
"127.20",19.516,21.24767,
"127.30",19.536,21.26433,
"127.40",19.558,21.281,
"127.50",19.581,21.29767,
"127.60",19.605,21.31433,
"127.70",19.629,21.331,
"127.80",19.653,21.34733,
"127.90",19.676,21.364,
"128.00",19.697,21.38067,
"128.10",19.717,21.39733,
"128.20",19.738,21.414,
"128.30",19.759,21.43067,
"128.40",19.78,21.44733,
"128.50",19.801,21.46433,
"128.60",19.824,21.481,
"128.70",19.846,21.49767,
"128.80",19.869,21.51433,
"128.90",19.895,21.531,
"129.00",19.918,21.54767,
"129.10",19.94,21.56433,
"129.20",19.961,21.581,
"129.30",19.982,21.59767,
"129.40",20,21.61433,
"129.50",20.019,21.631,
"129.60",20.041,21.64767,
"129.70",20.064,21.66433,
"129.80",20.086,21.681,
"129.90",20.111,21.69767,
"130.00",20.132,21.71433,
"130.10",20.152,21.731,
"130.20",20.174,21.74767,
"130.30",20.194,21.76433,
"130.40",20.213,21.781,
"130.50",20.233,21.79733,
"130.60",20.254,21.814,
"130.70",20.274,21.83067,
"130.80",20.297,21.84733,
"130.90",20.319,21.864,
"131.00",20.337,21.88067,
"131.10",20.356,21.89733,
"131.20",20.378,21.91433,
"131.30",20.397,21.931,
"131.40",20.417,21.94767,
"131.50",20.438,21.96433,
"131.60",20.459,21.981,
"131.70",20.479,21.99767,
"131.80",20.5,22.01433,
"131.90",20.521,22.031,
"132.00",20.543,22.04767,
"132.10",20.564,22.06433,
"132.20",20.581,22.081,
"132.30",20.597,22.09767,
"132.40",20.617,22.11433,
"132.50",20.636,22.131,
"132.60",20.656,22.14767,
"132.70",20.678,22.16433,
"132.80",20.699,22.181,
"132.90",20.718,22.19767,
"133.00",20.737,22.21433,
"133.10",20.753,22.231,
"133.20",20.77,22.24767,
"133.30",20.788,22.26433,
"133.40",20.808,22.281,
"133.50",20.825,22.29767,
"133.60",20.845,22.31433,
"133.70",20.864,22.331,
"133.80",20.886,22.34767,
"133.90",20.91,22.36433,
"134.00",20.93,22.381,
"134.10",20.95,22.39767,
"134.20",20.971,22.41433,
"134.30",20.989,22.431,
"134.40",21.007,22.44767,
"134.50",21.026,22.46433,
"134.60",21.045,22.481,
"134.70",21.065,22.49767,
"134.80",21.086,22.51433,
"134.90",21.107,22.531,
"135.00",21.127,22.54767,
"135.10",21.148,22.56433,
"135.20",21.17,22.581,
"135.30",21.188,22.59767,
"135.40",21.204,22.61467,
"135.50",21.224,22.631,
"135.60",21.244,22.64767,
"135.70",21.263,22.66433,
"135.80",21.281,22.681,
"135.90",21.302,22.69767,
"136.00",21.322,22.71433,
"136.10",21.34,22.731,
"136.20",21.356,22.74767,
"136.30",21.376,22.76433,
"136.40",21.396,22.781,
"136.50",21.416,22.79767,
"136.60",21.436,22.81433,
"136.70",21.455,22.831,
"136.80",21.477,22.84767,
"136.90",21.496,22.86433,
"137.00",21.515,22.881,
"137.10",21.535,22.89767,
"137.20",21.554,22.914,
"137.30",21.57,22.931,
"137.40",21.586,22.94733,
"137.50",21.605,22.964,
"137.60",21.624,22.98067,
"137.70",21.643,22.99733,
"137.80",21.664,23.014,
"137.90",21.686,23.03067,
"138.00",21.706,23.04733,
"138.10",21.725,23.064,
"138.20",21.745,23.08067,
"138.30",21.76,23.09733,
"138.40",21.777,23.114,
"138.50",21.798,23.13067,
"138.60",21.815,23.14733,
"138.70",21.833,23.164,
"138.80",21.854,23.18067,
"138.90",21.877,23.19733,
"139.00",21.898,23.21433,
"139.10",21.915,23.231,
"139.20",21.931,23.24767,
"139.30",21.949,23.26433,
"139.40",21.965,23.28067,
"139.50",21.984,23.29767,
"139.60",22.002,23.31433,
"139.70",22.019,23.331,
"139.80",22.039,23.34733,
"139.90",22.057,23.364,
"140.00",22.076,23.38067,
"140.10",22.094,23.39733,
"140.20",22.109,23.414,
"140.30",22.125,23.43067,
"140.40",22.14,23.44767,
"140.50",22.159,23.46433,
"140.60",22.179,23.481,
"140.70",22.196,23.49767,
"140.80",22.213,23.514,
"140.90",22.23,23.53067,
"141.00",22.249,23.54767,
"141.10",22.265,23.564,
"141.20",22.281,23.58067,
"141.30",22.295,23.59767,
"141.40",22.311,23.61433,
"141.50",22.33,23.631,
"141.60",22.346,23.64767,
"141.70",22.362,23.66433,
"141.80",22.379,23.681,
"141.90",22.397,23.69767,
"142.00",22.414,23.71433,
"142.10",22.429,23.731,
"142.20",22.443,23.74767,
"142.30",22.456,23.76433,
"142.40",22.469,23.78067,
"142.50",22.483,23.79767,
"142.60",22.496,23.81433,
"142.70",22.509,23.831,
"142.80",22.526,23.84767,
"142.90",22.543,23.86433,
"143.00",22.557,23.881,
"143.10",22.569,23.89767,
"143.20",22.578,23.91433,
"143.30",22.587,23.931,
"143.40",22.595,23.94767,
"143.50",22.603,23.96433,
"143.60",22.609,23.981,
"143.70",22.613,23.99767,
"143.80",22.615,24.01433,