File: pristine_flourocarbon_10cm_10mmpm_3.csv
"Test Name","Test Mode","Test Type","Control","Test Speed 1","Test Speed 2","Test Speed 3","Change Point 1","Change Point 2","Disp. Origin","Break and Limit Action","Sensitivity:","Level:"
"","Single","Tensile","Stroke",10,1,1,"Off","Off","Start","Stop",0,1

"Title","Sub title","Comment"
"","",""

"Shape:","Batch Size:","SubBatch Size:"
"Plate",1,1
"Name:","Thickness","Width","Gauge Length",
"Size Unit:","mm","mm","mm",
" 1 - 1","1.0000","1.0000","100.0000",

"Name",
"Parameter",
"Units",
" 1 - 1",

" 1- 1"
"Time","Force","Stroke",
"sec","N","mm",
"0.00",0,0,
"0.10",-.001,1.866667E-02,
"0.20",.004,3.733334E-02,
"0.30",.014,5.566667E-02,
"0.40",.029,7.433333E-02,
"0.50",.042,.093,
"0.60",.058,.1116667,
"0.70",.077,.13,
"0.80",.092,.1486667,
"0.90",.109,.1673333,
"1.00",.126,.186,
"1.10",.144,.2046667,
"1.20",.162,.223,
"1.30",.178,.2416667,
"1.40",.194,.2603333,
"1.50",.21,.2786667,
"1.60",.226,.2973333,
"1.70",.244,.316,
"1.80",.261,.3346667,
"1.90",.277,.353,
"2.00",.294,.3716667,
"2.10",.311,.3896667,
"2.20",.328,.4076667,
"2.30",.346,.4253333,
"2.40",.361,.4433333,
"2.50",.378,.461,
"2.60",.395,.4783333,
"2.70",.409,.496,
"2.80",.425,.5133333,
"2.90",.442,.5306666,
"3.00",.457,.548,
"3.10",.473,.5653333,
"3.20",.487,.5823333,
"3.30",.501,.5993333,
"3.40",.517,.6163333,
"3.50",.534,.6336667,
"3.60",.548,.6503333,
"3.70",.562,.6673334,
"3.80",.578,.6843333,
"3.90",.593,.7013333,
"4.00",.607,.718,
"4.10",.621,.735,
"4.20",.635,.7516667,
"4.30",.652,.7686667,
"4.40",.668,.7853333,
"4.50",.682,.8023334,
"4.60",.695,.819,
"4.70",.708,.8356667,
"4.80",.721,.8526667,
"4.90",.735,.8693333,
"5.00",.752,.886,
"5.10",.766,.9026667,
"5.20",.78,.9193333,
"5.30",.794,.936,
"5.40",.808,.9526666,
"5.50",.821,.9696667,
"5.60",.835,.9863333,
"5.70",.85,1.003,
"5.80",.865,1.019667,
"5.90",.878,1.036333,
"6.00",.891,1.053,
"6.10",.905,1.069667,
"6.20",.918,1.086667,
"6.30",.933,1.103,
"6.40",.946,1.119667,
"6.50",.959,1.136667,
"6.60",.971,1.153333,
"6.70",.986,1.169667,
"6.80",1,1.186333,
"6.90",1.011,1.203333,
"7.00",1.025,1.22,
"7.10",1.04,1.236667,
"7.20",1.052,1.253,
"7.30",1.063,1.27,
"7.40",1.077,1.286667,
"7.50",1.09,1.303333,
"7.60",1.104,1.319667,
"7.70",1.116,1.336333,
"7.80",1.126,1.353,
"7.90",1.139,1.369667,
"8.00",1.151,1.386333,
"8.10",1.163,1.403,
"8.20",1.176,1.419667,
"8.30",1.188,1.436333,
"8.40",1.2,1.453333,
"8.50",1.213,1.47,
"8.60",1.227,1.486667,
"8.70",1.238,1.503333,
"8.80",1.247,1.52,
"8.90",1.258,1.536667,
"9.00",1.27,1.553333,
"9.10",1.283,1.57,
"9.20",1.297,1.586667,
"9.30",1.307,1.603333,
"9.40",1.32,1.619667,
"9.50",1.332,1.636333,
"9.60",1.341,1.653,
"9.70",1.351,1.669667,
"9.80",1.362,1.686333,
"9.90",1.374,1.703,
"10.00",1.384,1.719667,
"10.10",1.394,1.736333,
"10.20",1.406,1.753333,
"10.30",1.418,1.769667,
"10.40",1.429,1.786667,
"10.50",1.438,1.803333,
"10.60",1.449,1.82,
"10.70",1.461,1.836667,
"10.80",1.47,1.853333,
"10.90",1.48,1.87,
"11.00",1.492,1.886667,
"11.10",1.503,1.903333,
"11.20",1.511,1.92,
"11.30",1.521,1.936667,
"11.40",1.534,1.953333,
"11.50",1.545,1.97,
"11.60",1.553,1.986333,
"11.70",1.562,2.003333,
"11.80",1.572,2.019666,
"11.90",1.582,2.036667,
"12.00",1.592,2.053333,
"12.10",1.602,2.07,
"12.20",1.611,2.086667,
"12.30",1.621,2.103,
"12.40",1.63,2.119667,
"12.50",1.641,2.136333,
"12.60",1.65,2.153333,
"12.70",1.658,2.17,
"12.80",1.666,2.186666,
"12.90",1.676,2.203333,
"13.00",1.687,2.22,
"13.10",1.696,2.236666,
"13.20",1.705,2.253333,
"13.30",1.713,2.27,
"13.40",1.722,2.286333,
"13.50",1.732,2.303,
"13.60",1.741,2.319667,
"13.70",1.749,2.336667,
"13.80",1.756,2.353,
"13.90",1.765,2.369667,
"14.00",1.774,2.386333,
"14.10",1.784,2.403333,
"14.20",1.793,2.42,
"14.30",1.801,2.436333,
"14.40",1.809,2.453333,
"14.50",1.819,2.47,
"14.60",1.827,2.486666,
"14.70",1.836,2.503333,
"14.80",1.846,2.52,
"14.90",1.854,2.536667,
"15.00",1.86,2.553333,
"15.10",1.867,2.57,
"15.20",1.876,2.586667,
"15.30",1.884,2.603333,
"15.40",1.892,2.62,
"15.50",1.902,2.637,
"15.60",1.908,2.653333,
"15.70",1.916,2.67,
"15.80",1.923,2.686666,
"15.90",1.934,2.703666,
"16.00",1.942,2.720333,
"16.10",1.949,2.736666,
"16.20",1.956,2.753333,
"16.30",1.966,2.77,
"16.40",1.975,2.786667,
"16.50",1.981,2.803333,
"16.60",1.986,2.820333,
"16.70",1.997,2.836667,
"16.80",2.006,2.853333,
"16.90",2.012,2.87,
"17.00",2.021,2.887,
"17.10",2.03,2.903666,
"17.20",2.039,2.92,
"17.30",2.046,2.936666,
"17.40",2.052,2.953333,
"17.50",2.061,2.97,
"17.60",2.069,2.986666,
"17.70",2.075,3.003333,
"17.80",2.082,3.02,
"17.90",2.09,3.036667,
"18.00",2.099,3.053333,
"18.10",2.108,3.07,
"18.20",2.114,3.086667,
"18.30",2.122,3.103333,
"18.40",2.13,3.12,
"18.50",2.135,3.136667,
"18.60",2.144,3.153333,
"18.70",2.154,3.17,
"18.80",2.16,3.186666,
"18.90",2.166,3.203333,
"19.00",2.175,3.22,
"19.10",2.183,3.236666,
"19.20",2.189,3.253333,
"19.30",2.196,3.27,
"19.40",2.203,3.286667,
"19.50",2.212,3.303333,
"19.60",2.22,3.32,
"19.70",2.227,3.336667,
"19.80",2.235,3.353333,
"19.90",2.243,3.37,
"20.00",2.249,3.386667,
"20.10",2.258,3.403333,
"20.20",2.265,3.42,
"20.30",2.273,3.436666,
"20.40",2.282,3.453333,
"20.50",2.289,3.47,
"20.60",2.295,3.486666,
"20.70",2.302,3.503333,
"20.80",2.31,3.52,
"20.90",2.318,3.536667,
"21.00",2.327,3.553333,
"21.10",2.335,3.57,
"21.20",2.342,3.586667,
"21.30",2.35,3.603333,
"21.40",2.358,3.62,
"21.50",2.366,3.636667,
"21.60",2.373,3.653333,
"21.70",2.378,3.67,
"21.80",2.387,3.686666,
"21.90",2.396,3.703333,
"22.00",2.401,3.72,
"22.10",2.41,3.737,
"22.20",2.42,3.753333,
"22.30",2.428,3.770333,
"22.40",2.432,3.787,
"22.50",2.44,3.803667,
"22.60",2.45,3.820333,
"22.70",2.456,3.837,
"22.80",2.463,3.853667,
"22.90",2.471,3.870333,
"23.00",2.481,3.887,
"23.10",2.49,3.903666,
"23.20",2.497,3.920333,
"23.30",2.506,3.937,
"23.40",2.515,3.953666,
"23.50",2.524,3.970333,
"23.60",2.53,3.987,
"23.70",2.535,4.003667,
"23.80",2.542,4.02,
"23.90",2.552,4.036667,
"24.00",2.559,4.053333,
"24.10",2.568,4.070333,
"24.20",2.577,4.087,
"24.30",2.582,4.103667,
"24.40",2.589,4.12,
"24.50",2.598,4.137,
"24.60",2.606,4.153667,
"24.70",2.612,4.17,
"24.80",2.62,4.187,
"24.90",2.629,4.203667,
"25.00",2.636,4.220334,
"25.10",2.645,4.237,
"25.20",2.654,4.253667,
"25.30",2.661,4.270333,
"25.40",2.67,4.287,
"25.50",2.679,4.303667,
"25.60",2.685,4.320333,
"25.70",2.693,4.336667,
"25.80",2.701,4.353333,
"25.90",2.707,4.37,
"26.00",2.716,4.387,
"26.10",2.725,4.403334,
"26.20",2.733,4.42,
"26.30",2.743,4.436667,
"26.40",2.749,4.453333,
"26.50",2.758,4.47,
"26.60",2.767,4.486667,
"26.70",2.773,4.503334,
"26.80",2.782,4.52,
"26.90",2.79,4.536667,
"27.00",2.796,4.553333,
"27.10",2.805,4.57,
"27.20",2.816,4.586667,
"27.30",2.825,4.603333,
"27.40",2.831,4.62,
"27.50",2.84,4.636667,
"27.60",2.849,4.653334,
"27.70",2.856,4.67,
"27.80",2.862,4.686667,
"27.90",2.871,4.703333,
"28.00",2.878,4.72,
"28.10",2.887,4.736667,
"28.20",2.897,4.753334,
"28.30",2.904,4.77,
"28.40",2.912,4.786667,
"28.50",2.923,4.803333,
"28.60",2.931,4.820333,
"28.70",2.939,4.837,
"28.80",2.946,4.853667,
"28.90",2.954,4.870334,
"29.00",2.961,4.887,
"29.10",2.97,4.903667,
"29.20",2.978,4.920333,
"29.30",2.985,4.937,
"29.40",2.997,4.953333,
"29.50",3.007,4.97,
"29.60",3.014,4.986667,
"29.70",3.021,5.003334,
"29.80",3.03,5.02,
"29.90",3.039,5.036667,
"30.00",3.048,5.053333,
"30.10",3.058,5.07,
"30.20",3.068,5.086667,
"30.30",3.076,5.103333,
"30.40",3.082,5.12,
"30.50",3.091,5.136667,
"30.60",3.099,5.153334,
"30.70",3.107,5.17,
"30.80",3.116,5.186667,
"30.90",3.125,5.203333,
"31.00",3.136,5.22,
"31.10",3.145,5.236667,
"31.20",3.153,5.253334,
"31.30",3.162,5.27,
"31.40",3.17,5.286667,
"31.50",3.178,5.303333,
"31.60",3.186,5.32,
"31.70",3.196,5.336667,
"31.80",3.205,5.353333,
"31.90",3.214,5.37,
"32.00",3.223,5.387,
"32.10",3.232,5.403667,
"32.20",3.241,5.42,
"32.30",3.25,5.436667,
"32.40",3.261,5.453333,
"32.50",3.27,5.47,
"32.60",3.279,5.486667,
"32.70",3.289,5.503667,
"32.80",3.297,5.52,
"32.90",3.305,5.536667,
"33.00",3.316,5.553667,
"33.10",3.327,5.57,
"33.20",3.335,5.586667,
"33.30",3.344,5.603333,
"33.40",3.352,5.62,
"33.50",3.361,5.636667,
"33.60",3.372,5.653334,
"33.70",3.383,5.67,
"33.80",3.392,5.686667,
"33.90",3.401,5.703333,
"34.00",3.41,5.72,
"34.10",3.418,5.736667,
"34.20",3.426,5.753334,
"34.30",3.438,5.77,
"34.40",3.449,5.786667,
"34.50",3.458,5.803333,
"34.60",3.466,5.82,
"34.70",3.476,5.837,
"34.80",3.485,5.853667,
"34.90",3.492,5.87,
"35.00",3.501,5.887,
"35.10",3.512,5.903667,
"35.20",3.521,5.92,
"35.30",3.529,5.936667,
"35.40",3.539,5.953333,
"35.50",3.548,5.97,
"35.60",3.557,5.986667,
"35.70",3.568,6.003334,
"35.80",3.577,6.02,
"35.90",3.585,6.036667,
"36.00",3.594,6.053333,
"36.10",3.605,6.07,
"36.20",3.616,6.086667,
"36.30",3.629,6.103333,
"36.40",3.638,6.12,
"36.50",3.647,6.136667,
"36.60",3.658,6.153334,
"36.70",3.667,6.17,
"36.80",3.678,6.186667,
"36.90",3.686,6.203333,
"37.00",3.696,6.22,
"37.10",3.707,6.237,
"37.20",3.716,6.253667,
"37.30",3.725,6.27,
"37.40",3.737,6.286667,
"37.50",3.747,6.303333,
"37.60",3.755,6.32,
"37.70",3.765,6.336667,
"37.80",3.773,6.353333,
"37.90",3.783,6.37,
"38.00",3.792,6.386667,
"38.10",3.801,6.403334,
"38.20",3.813,6.42,
"38.30",3.823,6.436667,
"38.40",3.834,6.453333,
"38.50",3.846,6.470334,
"38.60",3.857,6.487,
"38.70",3.867,6.503667,
"38.80",3.875,6.520333,
"38.90",3.885,6.537,
"39.00",3.896,6.553667,
"39.10",3.907,6.57,
"39.20",3.918,6.587,
"39.30",3.928,6.603333,
"39.40",3.936,6.620334,
"39.50",3.945,6.636667,
"39.60",3.957,6.653667,
"39.70",3.969,6.67,
"39.80",3.98,6.686667,
"39.90",3.99,6.703333,
"40.00",3.999,6.72,
"40.10",4.009,6.736667,
"40.20",4.019,6.753334,
"40.30",4.029,6.77,
"40.40",4.04,6.786667,
"40.50",4.051,6.803333,
"40.60",4.061,6.82,
"40.70",4.07,6.836667,
"40.80",4.08,6.853333,
"40.90",4.09,6.87,
"41.00",4.099,6.886667,
"41.10",4.111,6.903667,
"41.20",4.123,6.92,
"41.30",4.134,6.936667,
"41.40",4.147,6.953667,
"41.50",4.158,6.970334,
"41.60",4.166,6.987,
"41.70",4.177,7.003667,
"41.80",4.189,7.020333,
"41.90",4.199,7.036667,
"42.00",4.21,7.053333,
"42.10",4.22,7.07,
"42.20",4.23,7.086667,
"42.30",4.241,7.103333,
"42.40",4.25,7.12,
"42.50",4.26,7.136667,
"42.60",4.272,7.153334,
"42.70",4.282,7.17,
"42.80",4.292,7.186667,
"42.90",4.304,7.203333,
"43.00",4.314,7.220334,
"43.10",4.324,7.236667,
"43.20",4.334,7.253334,
"43.30",4.347,7.27,
"43.40",4.359,7.286667,
"43.50",4.37,7.303333,
"43.60",4.38,7.32,
"43.70",4.392,7.336667,
"43.80",4.403,7.353333,
"43.90",4.413,7.37,
"44.00",4.423,7.386667,
"44.10",4.434,7.403334,
"44.20",4.448,7.42,
"44.30",4.46,7.436667,
"44.40",4.472,7.453333,
"44.50",4.483,7.47,
"44.60",4.493,7.486667,
"44.70",4.504,7.503334,
"44.80",4.515,7.520333,
"44.90",4.526,7.536667,
"45.00",4.535,7.553333,
"45.10",4.546,7.57,
"45.20",4.559,7.586667,
"45.30",4.573,7.603333,
"45.40",4.585,7.62,
"45.50",4.595,7.636667,
"45.60",4.607,7.653334,
"45.70",4.62,7.67,
"45.80",4.63,7.686667,
"45.90",4.64,7.703333,
"46.00",4.653,7.72,
"46.10",4.665,7.736667,
"46.20",4.678,7.753334,
"46.30",4.69,7.770333,
"46.40",4.7,7.786667,
"46.50",4.71,7.803333,
"46.60",4.722,7.820333,
"46.70",4.732,7.836667,
"46.80",4.743,7.853333,
"46.90",4.755,7.87,
"47.00",4.767,7.886667,
"47.10",4.781,7.903667,
"47.20",4.795,7.920333,
"47.30",4.808,7.936667,
"47.40",4.819,7.953667,
"47.50",4.828,7.97,
"47.60",4.837,7.986667,
"47.70",4.848,8.003333,
"47.80",4.862,8.02,
"47.90",4.874,8.036666,
"48.00",4.885,8.053333,
"48.10",4.899,8.07,
"48.20",4.913,8.086666,
"48.30",4.926,8.103333,
"48.40",4.937,8.120333,
"48.50",4.948,8.137,
"48.60",4.959,8.153666,
"48.70",4.972,8.170333,
"48.80",4.985,8.186999,
"48.90",4.994,8.203667,
"49.00",5.004,8.220333,
"49.10",5.017,8.237,
"49.20",5.03,8.253666,
"49.30",5.043,8.270333,
"49.40",5.056,8.286666,
"49.50",5.068,8.303666,
"49.60",5.082,8.32,
"49.70",5.095,8.336666,
"49.80",5.104,8.353333,
"49.90",5.115,8.37,
"50.00",5.128,8.387,
"50.10",5.14,8.403666,
"50.20",5.153,8.420333,
"50.30",5.165,8.436666,
"50.40",5.178,8.453333,
"50.50",5.191,8.469999,
"50.60",5.202,8.487,
"50.70",5.214,8.503333,
"50.80",5.225,8.52,
"50.90",5.237,8.537,
"51.00",5.251,8.553666,
"51.10",5.264,8.570333,
"51.20",5.276,8.586666,
"51.30",5.289,8.603333,
"51.40",5.301,8.62,
"51.50",5.311,8.636666,
"51.60",5.324,8.653333,
"51.70",5.337,8.67,
"51.80",5.348,8.686666,
"51.90",5.361,8.703333,
"52.00",5.375,8.719999,
"52.10",5.387,8.736667,
"52.20",5.4,8.753333,
"52.30",5.413,8.77,
"52.40",5.425,8.786666,
"52.50",5.438,8.803333,
"52.60",5.451,8.82,
"52.70",5.463,8.837,
"52.80",5.477,8.853666,
"52.90",5.491,8.870333,
"53.00",5.502,8.887,
"53.10",5.513,8.903666,
"53.20",5.528,8.920333,
"53.30",5.545,8.936999,
"53.40",5.557,8.953667,
"53.50",5.569,8.970333,
"53.60",5.581,8.986667,
"53.70",5.591,9.003333,
"53.80",5.603,9.02,
"53.90",5.618,9.037,
"54.00",5.632,9.053333,
"54.10",5.645,9.07,
"54.20",5.658,9.087,
"54.30",5.671,9.103333,
"54.40",5.685,9.12,
"54.50",5.699,9.137,
"54.60",5.712,9.153666,
"54.70",5.725,9.170333,
"54.80",5.739,9.186999,
"54.90",5.752,9.203667,
"55.00",5.762,9.220333,
"55.10",5.775,9.237,
"55.20",5.791,9.253666,
"55.30",5.804,9.270333,
"55.40",5.818,9.287,
"55.50",5.83,9.303666,
"55.60",5.843,9.320333,
"55.70",5.857,9.336666,
"55.80",5.868,9.353333,
"55.90",5.881,9.370333,
"56.00",5.896,9.386666,
"56.10",5.91,9.403666,
"56.20",5.925,9.420333,
"56.30",5.94,9.436666,
"56.40",5.953,9.453333,
"56.50",5.966,9.470333,
"56.60",5.979,9.487,
"56.70",5.992,9.503666,
"56.80",6.006,9.520333,
"56.90",6.019,9.537,
"57.00",6.031,9.553666,
"57.10",6.045,9.570333,
"57.20",6.06,9.587,
"57.30",6.073,9.603666,
"57.40",6.086,9.62,
"57.50",6.101,9.636666,
"57.60",6.112,9.653333,
"57.70",6.125,9.67,
"57.80",6.137,9.686666,
"57.90",6.15,9.703333,
"58.00",6.165,9.719999,
"58.10",6.179,9.736667,
"58.20",6.191,9.753333,
"58.30",6.208,9.77,
"58.40",6.223,9.786666,
"58.50",6.236,9.803666,
"58.60",6.251,9.820333,
"58.70",6.264,9.837,
"58.80",6.276,9.853666,
"58.90",6.29,9.870333,
"59.00",6.305,9.887,
"59.10",6.319,9.903666,
"59.20",6.334,9.92,
"59.30",6.347,9.936666,
"59.40",6.361,9.953333,
"59.50",6.377,9.969999,
"59.60",6.39,9.986667,
"59.70",6.404,10.00333,
"59.80",6.417,10.02,
"59.90",6.433,10.03667,
"60.00",6.447,10.05333,
"60.10",6.458,10.07,
"60.20",6.473,10.08667,
"60.30",6.489,10.103,
"60.40",6.503,10.12,
"60.50",6.517,10.13667,
"60.60",6.532,10.15333,
"60.70",6.546,10.17,
"60.80",6.56,10.18667,
"60.90",6.575,10.20333,
"61.00",6.59,10.22,
"61.10",6.605,10.23667,
"61.20",6.619,10.25333,
"61.30",6.635,10.27,
"61.40",6.651,10.28667,
"61.50",6.665,10.30333,
"61.60",6.68,10.32,
"61.70",6.693,10.33667,
"61.80",6.704,10.35333,
"61.90",6.72,10.37,
"62.00",6.737,10.38667,
"62.10",6.751,10.40333,
"62.20",6.765,10.42,
"62.30",6.782,10.43667,
"62.40",6.796,10.45333,
"62.50",6.81,10.47,
"62.60",6.824,10.48667,
"62.70",6.839,10.50333,
"62.80",6.854,10.52,
"62.90",6.869,10.53667,
"63.00",6.885,10.55333,
"63.10",6.9,10.57,
"63.20",6.915,10.58667,
"63.30",6.928,10.60333,
"63.40",6.946,10.62,
"63.50",6.963,10.63667,
"63.60",6.976,10.65333,
"63.70",6.99,10.67,
"63.80",7.004,10.68667,
"63.90",7.018,10.70333,
"64.00",7.035,10.72,
"64.10",7.05,10.73667,
"64.20",7.064,10.75333,
"64.30",7.081,10.77,
"64.40",7.098,10.78667,
"64.50",7.112,10.80333,
"64.60",7.128,10.82,
"64.70",7.144,10.83667,
"64.80",7.158,10.85333,
"64.90",7.174,10.87,
"65.00",7.19,10.88667,
"65.10",7.204,10.90333,
"65.20",7.218,10.92,
"65.30",7.235,10.93667,
"65.40",7.251,10.95333,
"65.50",7.268,10.97,
"65.60",7.283,10.98667,
"65.70",7.296,11.00333,
"65.80",7.312,11.02,
"65.90",7.327,11.03667,
"66.00",7.343,11.05367,
"66.10",7.359,11.07033,
"66.20",7.376,11.08667,
"66.30",7.395,11.10333,
"66.40",7.41,11.12033,
"66.50",7.425,11.137,
"66.60",7.441,11.15367,
"66.70",7.456,11.17033,
"66.80",7.47,11.187,
"66.90",7.486,11.20367,
"67.00",7.503,11.22033,
"67.10",7.52,11.237,
"67.20",7.536,11.25367,
"67.30",7.551,11.27,
"67.40",7.567,11.287,
"67.50",7.584,11.30333,
"67.60",7.601,11.32,
"67.70",7.614,11.33667,
"67.80",7.628,11.35333,
"67.90",7.642,11.37,
"68.00",7.658,11.38667,
"68.10",7.674,11.40333,
"68.20",7.691,11.42,
"68.30",7.708,11.43667,
"68.40",7.724,11.45333,
"68.50",7.742,11.47,
"68.60",7.76,11.487,
"68.70",7.777,11.50333,
"68.80",7.792,11.52,
"68.90",7.808,11.53667,
"69.00",7.825,11.55367,
"69.10",7.841,11.57033,
"69.20",7.858,11.587,
"69.30",7.876,11.60367,
"69.40",7.894,11.62,
"69.50",7.91,11.63667,
"69.60",7.925,11.65333,
"69.70",7.943,11.67,
"69.80",7.957,11.68667,
"69.90",7.974,11.70333,
"70.00",7.993,11.72,
"70.10",8.008,11.73667,
"70.20",8.025,11.75333,
"70.30",8.042,11.77,
"70.40",8.059,11.78667,
"70.50",8.076,11.80333,
"70.60",8.093,11.82,
"70.70",8.11,11.83667,
"70.80",8.127,11.85367,
"70.90",8.145,11.87,
"71.00",8.161,11.887,
"71.10",8.178,11.90367,
"71.20",8.198,11.92033,
"71.30",8.216,11.937,
"71.40",8.232,11.95333,
"71.50",8.246,11.97,
"71.60",8.265,11.98667,
"71.70",8.284,12.00333,
"71.80",8.299,12.02,
"71.90",8.316,12.03667,
"72.00",8.333,12.05333,
"72.10",8.35,12.07,
"72.20",8.37,12.08667,
"72.30",8.388,12.10333,
"72.40",8.406,12.12,
"72.50",8.424,12.13667,
"72.60",8.441,12.15333,
"72.70",8.458,12.17,
"72.80",8.474,12.18667,
"72.90",8.49,12.20333,
"73.00",8.509,12.22,
"73.10",8.528,12.23667,
"73.20",8.547,12.25333,
"73.30",8.563,12.27,
"73.40",8.583,12.28667,
"73.50",8.603,12.30333,
"73.60",8.621,12.32,
"73.70",8.639,12.33667,
"73.80",8.655,12.35333,
"73.90",8.673,12.37,
"74.00",8.692,12.38667,
"74.10",8.709,12.40333,
"74.20",8.728,12.42,
"74.30",8.748,12.43667,
"74.40",8.768,12.45333,
"74.50",8.786,12.47,
"74.60",8.804,12.48667,
"74.70",8.822,12.50333,
"74.80",8.838,12.52,
"74.90",8.856,12.53667,
"75.00",8.875,12.55333,
"75.10",8.891,12.57,
"75.20",8.91,12.58667,
"75.30",8.931,12.60333,
"75.40",8.95,12.62,
"75.50",8.969,12.63667,
"75.60",8.989,12.65333,
"75.70",9.008,12.67,
"75.80",9.026,12.68667,
"75.90",9.043,12.70333,
"76.00",9.063,12.72,
"76.10",9.085,12.73667,
"76.20",9.103,12.75333,
"76.30",9.121,12.77,
"76.40",9.141,12.78667,
"76.50",9.16,12.80333,
"76.60",9.177,12.82,
"76.70",9.195,12.83667,
"76.80",9.215,12.85333,
"76.90",9.234,12.87,
"77.00",9.253,12.887,
"77.10",9.273,12.90367,
"77.20",9.291,12.92,
"77.30",9.31,12.93667,
"77.40",9.329,12.95333,
"77.50",9.349,12.97,
"77.60",9.369,12.98667,
"77.70",9.388,13.00333,
"77.80",9.405,13.02,
"77.90",9.423,13.03667,
"78.00",9.444,13.05333,
"78.10",9.465,13.07,
"78.20",9.488,13.08667,
"78.30",9.51,13.10333,
"78.40",9.531,13.12,
"78.50",9.549,13.13667,
"78.60",9.567,13.15333,
"78.70",9.585,13.17,
"78.80",9.603,13.18667,
"78.90",9.621,13.20333,
"79.00",9.641,13.22,
"79.10",9.662,13.23667,
"79.20",9.681,13.25333,
"79.30",9.702,13.27,
"79.40",9.724,13.28667,
"79.50",9.745,13.30333,
"79.60",9.766,13.32,
"79.70",9.784,13.33667,
"79.80",9.803,13.35333,
"79.90",9.824,13.37,
"80.00",9.844,13.387,
"80.10",9.865,13.40333,
"80.20",9.884,13.42033,
"80.30",9.903,13.43667,
"80.40",9.925,13.45333,
"80.50",9.947,13.47,
"80.60",9.967,13.48667,
"80.70",9.987,13.50333,
"80.80",10.007,13.52,
"80.90",10.028,13.53667,
"81.00",10.049,13.55333,
"81.10",10.07,13.57,
"81.20",10.091,13.58667,
"81.30",10.111,13.60333,
"81.40",10.134,13.62,
"81.50",10.155,13.63667,
"81.60",10.175,13.65333,
"81.70",10.195,13.67,
"81.80",10.214,13.68667,
"81.90",10.233,13.70333,
"82.00",10.255,13.72,
"82.10",10.279,13.73667,
"82.20",10.301,13.75333,
"82.30",10.322,13.77,
"82.40",10.344,13.78667,
"82.50",10.367,13.80333,
"82.60",10.384,13.82,
"82.70",10.403,13.83667,
"82.80",10.425,13.85333,
"82.90",10.446,13.87,
"83.00",10.467,13.88667,
"83.10",10.49,13.90333,
"83.20",10.512,13.92033,
"83.30",10.533,13.93667,
"83.40",10.556,13.95333,
"83.50",10.579,13.97,
"83.60",10.598,13.98667,
"83.70",10.62,14.00367,
"83.80",10.641,14.02033,
"83.90",10.659,14.037,
"84.00",10.681,14.05367,
"84.10",10.704,14.07,
"84.20",10.726,14.087,
"84.30",10.749,14.10333,
"84.40",10.772,14.12,
"84.50",10.796,14.137,
"84.60",10.819,14.15333,
"84.70",10.84,14.17,
"84.80",10.859,14.187,
"84.90",10.88,14.20367,
"85.00",10.901,14.22033,
"85.10",10.924,14.237,
"85.20",10.946,14.25367,
"85.30",10.966,14.27,
"85.40",10.99,14.28667,
"85.50",11.014,14.30333,
"85.60",11.037,14.32,
"85.70",11.057,14.33667,
"85.80",11.076,14.35333,
"85.90",11.101,14.37,
"86.00",11.123,14.38667,
"86.10",11.144,14.40333,
"86.20",11.168,14.42033,
"86.30",11.192,14.43667,
"86.40",11.215,14.45367,
"86.50",11.236,14.47,
"86.60",11.26,14.48667,
"86.70",11.284,14.50333,
"86.80",11.304,14.52,
"86.90",11.327,14.53667,
"87.00",11.353,14.55367,
"87.10",11.374,14.57,
"87.20",11.398,14.58667,
"87.30",11.422,14.60333,
"87.40",11.445,14.62,
"87.50",11.468,14.637,
"87.60",11.487,14.65333,
"87.70",11.508,14.67,
"87.80",11.531,14.68667,
"87.90",11.556,14.70333,
"88.00",11.581,14.72,
"88.10",11.604,14.73667,
"88.20",11.627,14.75333,
"88.30",11.651,14.77,
"88.40",11.676,14.787,
"88.50",11.699,14.80367,
"88.60",11.722,14.82033,
"88.70",11.745,14.837,
"88.80",11.767,14.85367,
"88.90",11.79,14.87033,
"89.00",11.815,14.887,
"89.10",11.838,14.90367,
"89.20",11.86,14.92033,
"89.30",11.884,14.93667,
"89.40",11.91,14.95333,
"89.50",11.934,14.97,
"89.60",11.958,14.98667,
"89.70",11.98,15.00333,
"89.80",12.002,15.02,
"89.90",12.026,15.03667,
"90.00",12.049,15.05333,
"90.10",12.072,15.07,
"90.20",12.097,15.08667,
"90.30",12.123,15.10333,
"90.40",12.148,15.12,
"90.50",12.173,15.13667,
"90.60",12.198,15.15333,
"90.70",12.222,15.17,
"90.80",12.245,15.18667,
"90.90",12.268,15.20333,
"91.00",12.292,15.22033,
"91.10",12.316,15.23667,
"91.20",12.343,15.25333,
"91.30",12.369,15.27,
"91.40",12.392,15.28667,
"91.50",12.415,15.30333,
"91.60",12.441,15.32,
"91.70",12.465,15.33667,
"91.80",12.486,15.35333,
"91.90",12.51,15.37,
"92.00",12.535,15.38667,
"92.10",12.562,15.40333,
"92.20",12.588,15.42033,
"92.30",12.612,15.43667,
"92.40",12.638,15.45367,
"92.50",12.665,15.47033,
"92.60",12.688,15.487,
"92.70",12.71,15.50367,
"92.80",12.733,15.52,
"92.90",12.757,15.53667,
"93.00",12.781,15.55333,
"93.10",12.805,15.57,
"93.20",12.832,15.58667,
"93.30",12.859,15.60333,
"93.40",12.884,15.62,
"93.50",12.909,15.63667,
"93.60",12.934,15.65333,
"93.70",12.957,15.67,
"93.80",12.982,15.687,
"93.90",13.008,15.70367,
"94.00",13.03,15.72033,
"94.10",13.054,15.737,
"94.20",13.081,15.75333,
"94.30",13.108,15.77,
"94.40",13.135,15.78667,
"94.50",13.159,15.80333,
"94.60",13.182,15.82,
"94.70",13.206,15.83667,
"94.80",13.229,15.85333,
"94.90",13.256,15.87,
"95.00",13.281,15.88667,
"95.10",13.309,15.90367,
"95.20",13.337,15.92,
"95.30",13.363,15.93667,
"95.40",13.39,15.95333,
"95.50",13.414,15.97,
"95.60",13.44,15.98667,
"95.70",13.465,16.00333,
"95.80",13.49,16.02,
"95.90",13.514,16.03667,
"96.00",13.539,16.05333,
"96.10",13.568,16.07,
"96.20",13.595,16.08667,
"96.30",13.622,16.10333,
"96.40",13.647,16.12,
"96.50",13.672,16.13667,
"96.60",13.695,16.15333,
"96.70",13.719,16.17,
"96.80",13.745,16.18667,
"96.90",13.773,16.20333,
"97.00",13.798,16.22,
"97.10",13.822,16.23667,
"97.20",13.851,16.25333,
"97.30",13.879,16.27,
"97.40",13.905,16.28667,
"97.50",13.93,16.30333,
"97.60",13.954,16.32,
"97.70",13.98,16.33667,
"97.80",14.007,16.35333,
"97.90",14.035,16.37,
"98.00",14.058,16.38667,
"98.10",14.08,16.40333,
"98.20",14.109,16.42,
"98.30",14.14,16.43667,
"98.40",14.167,16.45333,
"98.50",14.19,16.47,
"98.60",14.217,16.48667,
"98.70",14.244,16.50333,
"98.80",14.269,16.52,
"98.90",14.294,16.53667,
"99.00",14.32,16.55333,
"99.10",14.347,16.57,
"99.20",14.373,16.58667,
"99.30",14.399,16.603,
"99.40",14.428,16.62,
"99.50",14.456,16.63667,
"99.60",14.484,16.653,
"99.70",14.508,16.66967,
"99.80",14.532,16.68633,
"99.90",14.558,16.703,
"100.00",14.584,16.71967,
"100.10",14.612,16.73633,
"100.20",14.638,16.753,
"100.30",14.663,16.76967,
"100.40",14.69,16.78633,
"100.50",14.716,16.80333,
"100.60",14.745,16.82,
"100.70",14.773,16.83667,
"100.80",14.797,16.85333,
"100.90",14.822,16.87,
"101.00",14.851,16.88667,
"101.10",14.881,16.90333,
"101.20",14.909,16.92,
"101.30",14.938,16.93667,
"101.40",14.965,16.95333,
"101.50",14.99,16.97,
"101.60",15.016,16.98667,
"101.70",15.043,17.00333,
"101.80",15.071,17.02,
"101.90",15.097,17.03667,
"102.00",15.122,17.05333,
"102.10",15.148,17.07,
"102.20",15.176,17.08667,
"102.30",15.202,17.10333,
"102.40",15.229,17.12,
"102.50",15.256,17.13667,
"102.60",15.281,17.15333,
"102.70",15.306,17.17,
"102.80",15.331,17.18667,
"102.90",15.357,17.20333,
"103.00",15.384,17.22,
"103.10",15.41,17.23667,
"103.20",15.438,17.25333,
"103.30",15.465,17.27,
"103.40",15.491,17.28667,
"103.50",15.519,17.30333,
"103.60",15.547,17.32,
"103.70",15.574,17.33667,
"103.80",15.598,17.35333,
"103.90",15.623,17.37,
"104.00",15.649,17.38667,
"104.10",15.673,17.40333,
"104.20",15.7,17.42,
"104.30",15.729,17.43667,
"104.40",15.757,17.45333,
"104.50",15.783,17.47,
"104.60",15.808,17.48667,
"104.70",15.836,17.50333,
"104.80",15.859,17.52,
"104.90",15.882,17.53667,
"105.00",15.91,17.55333,
"105.10",15.936,17.57,
"105.20",15.961,17.58667,
"105.30",15.989,17.60333,
"105.40",16.015,17.62,
"105.50",16.041,17.63667,
"105.60",16.07,17.65333,
"105.70",16.096,17.67,
"105.80",16.12,17.68667,
"105.90",16.144,17.70333,
"106.00",16.169,17.72,
"106.10",16.197,17.73667,
"106.20",16.225,17.75333,
"106.30",16.252,17.77,
"106.40",16.279,17.78667,
"106.50",16.301,17.80367,
"106.60",16.327,17.82033,
"106.70",16.353,17.837,
"106.80",16.377,17.85367,
"106.90",16.403,17.87,
"107.00",16.428,17.88667,
"107.10",16.456,17.90333,
"107.20",16.482,17.92,
"107.30",16.506,17.93667,
"107.40",16.532,17.95333,
"107.50",16.559,17.97,
"107.60",16.584,17.98667,
"107.70",16.606,18.00333,
"107.80",16.63,18.02,
"107.90",16.658,18.03667,
"108.00",16.682,18.05333,
"108.10",16.705,18.07,
"108.20",16.729,18.08667,
"108.30",16.755,18.10333,
"108.40",16.784,18.12,
"108.50",16.812,18.13667,
"108.60",16.836,18.15333,
"108.70",16.859,18.17,
"108.80",16.883,18.18667,
"108.90",16.905,18.20333,
"109.00",16.929,18.22,
"109.10",16.951,18.23667,
"109.20",16.976,18.25333,
"109.30",17.002,18.27,
"109.40",17.029,18.28667,
"109.50",17.054,18.30333,
"109.60",17.08,18.32,
"109.70",17.102,18.33667,
"109.80",17.123,18.35333,
"109.90",17.148,18.37,
"110.00",17.171,18.38667,
"110.10",17.194,18.40333,
"110.20",17.22,18.41967,
"110.30",17.246,18.43633,
"110.40",17.27,18.453,
"110.50",17.295,18.46967,
"110.60",17.317,18.48667,
"110.70",17.338,18.50333,
"110.80",17.362,18.52,
"110.90",17.387,18.53667,
"111.00",17.41,18.55333,
"111.10",17.432,18.57,
"111.20",17.456,18.58667,
"111.30",17.483,18.60333,
"111.40",17.506,18.62,
"111.50",17.527,18.63667,
"111.60",17.55,18.65333,
"111.70",17.571,18.66967,
"111.80",17.591,18.68667,
"111.90",17.611,18.70333,
"112.00",17.634,18.72,
"112.10",17.66,18.73667,
"112.20",17.684,18.75333,
"112.30",17.707,18.77,
"112.40",17.729,18.78667,
"112.50",17.75,18.80333,
"112.60",17.771,18.82,
"112.70",17.794,18.83667,
"112.80",17.813,18.85333,
"112.90",17.832,18.87,
"113.00",17.855,18.88667,
"113.10",17.877,18.90333,
"113.20",17.9,18.92,
"113.30",17.923,18.93667,
"113.40",17.948,18.95333,
"113.50",17.973,18.97,
"113.60",17.992,18.98667,
"113.70",18.01,19.00333,
"113.80",18.032,19.02,
"113.90",18.051,19.03667,
"114.00",18.074,19.05333,
"114.10",18.097,19.07,
"114.20",18.117,19.08667,
"114.30",18.141,19.10333,
"114.40",18.169,19.12,
"114.50",18.191,19.13667,
"114.60",18.212,19.15333,
"114.70",18.234,19.17,
"114.80",18.253,19.18667,
"114.90",18.272,19.20333,
"115.00",18.292,19.22,
"115.10",18.315,19.23667,
"115.20",18.338,19.25333,
"115.30",18.359,19.27,
"115.40",18.379,19.28667,
"115.50",18.4,19.30333,
"115.60",18.419,19.32,
"115.70",18.437,19.33667,
"115.80",18.459,19.35333,
"115.90",18.482,19.37,
"116.00",18.501,19.38667,
"116.10",18.518,19.40333,
"116.20",18.538,19.42,
"116.30",18.557,19.43667,
"116.40",18.579,19.45333,
"116.50",18.602,19.47,
"116.60",18.62,19.48667,
"116.70",18.639,19.50333,
"116.80",18.657,19.52,
"116.90",18.678,19.53667,
"117.00",18.699,19.55333,
"117.10",18.717,19.57,
"117.20",18.741,19.58667,
"117.30",18.76,19.60333,
"117.40",18.776,19.62,
"117.50",18.794,19.63667,
"117.60",18.809,19.65333,
"117.70",18.823,19.67,
"117.80",18.838,19.68667,
"117.90",18.853,19.70333,
"118.00",18.869,19.72,
"118.10",18.887,19.73667,
"118.20",18.905,19.75333,
"118.30",18.926,19.77,
"118.40",18.945,19.78667,
"118.50",18.961,19.80333,
"118.60",18.98,19.82,
"118.70",18.999,19.83667,
"118.80",19.012,19.85333,
"118.90",19.026,19.87,
"119.00",19.044,19.88667,
"119.10",19.06,19.90333,
"119.20",19.083,19.92,
"119.30",19.104,19.93667,
"119.40",19.122,19.95333,
"119.50",19.141,19.97,
"119.60",19.16,19.98667,
"119.70",19.177,20.00333,
"119.80",19.194,20.02,
"119.90",19.212,20.03667,
"120.00",19.229,20.05333,
"120.10",19.245,20.07,
"120.20",19.263,20.08667,
"120.30",19.281,20.103,
"120.40",19.299,20.11967,
"120.50",19.317,20.13633,
"120.60",19.338,20.15333,
"120.70",19.359,20.16967,
"120.80",19.376,20.18633,
"120.90",19.394,20.203,
"121.00",19.412,20.21967,
"121.10",19.43,20.23633,
"121.20",19.448,20.253,
"121.30",19.469,20.26967,
"121.40",19.489,20.28633,
"121.50",19.508,20.303,
"121.60",19.529,20.31967,
"121.70",19.548,20.33633,
"121.80",19.564,20.353,
"121.90",19.583,20.36967,
"122.00",19.601,20.38633,
"122.10",19.619,20.403,
"122.20",19.639,20.41967,
"122.30",19.661,20.43633,
"122.40",19.68,20.45333,
"122.50",19.699,20.47,
"122.60",19.714,20.48667,
"122.70",19.728,20.50333,
"122.80",19.745,20.52,
"122.90",19.76,20.53633,
"123.00",19.776,20.553,
"123.10",19.794,20.56967,
"123.20",19.813,20.58633,
"123.30",19.832,20.603,
"123.40",19.852,20.62,
"123.50",19.872,20.63667,
"123.60",19.889,20.653,
"123.70",19.904,20.67,
"123.80",19.922,20.68633,
"123.90",19.943,20.703,
"124.00",19.96,20.71967,
"124.10",19.98,20.73633,
"124.20",20.001,20.75333,
"124.30",20.019,20.76967,
"124.40",20.038,20.78667,
"124.50",20.055,20.80333,
"124.60",20.073,20.81967,
"124.70",20.091,20.83667,
"124.80",20.109,20.85333,
"124.90",20.128,20.87,
"125.00",20.145,20.88667,
"125.10",20.161,20.90333,
"125.20",20.182,20.92,
"125.30",20.201,20.93667,
"125.40",20.217,20.95333,
"125.50",20.234,20.97,
"125.60",20.25,20.98633,
"125.70",20.269,21.00333,
"125.80",20.288,21.01967,
"125.90",20.307,21.03633,
"126.00",20.327,21.05333,
"126.10",20.345,21.06967,
"126.20",20.366,21.08667,
"126.30",20.383,21.103,
"126.40",20.4,21.11967,
"126.50",20.418,21.13667,
"126.60",20.436,21.15333,
"126.70",20.454,21.17,
"126.80",20.47,21.18667,
"126.90",20.488,21.20333,
"127.00",20.508,21.22,
"127.10",20.528,21.23667,
"127.20",20.548,21.25333,
"127.30",20.568,21.27,
"127.40",20.588,21.28633,
"127.50",20.605,21.30333,
"127.60",20.621,21.31967,
"127.70",20.635,21.33633,
"127.80",20.651,21.353,
"127.90",20.671,21.36967,
"128.00",20.687,21.38633,
"128.10",20.702,21.403,
"128.20",20.722,21.42,
"128.30",20.743,21.43633,
"128.40",20.762,21.45333,
"128.50",20.781,21.47,
"128.60",20.797,21.48667,
"128.70",20.813,21.50333,
"128.80",20.831,21.52,
"128.90",20.846,21.53667,
"129.00",20.862,21.55333,
"129.10",20.88,21.57,
"129.20",20.897,21.58667,
"129.30",20.914,21.60333,
"129.40",20.933,21.62,
"129.50",20.953,21.63667,
"129.60",20.972,21.65333,
"129.70",20.986,21.67,
"129.80",20.999,21.68667,
"129.90",21.016,21.70333,
"130.00",21.032,21.72,
"130.10",21.047,21.73667,
"130.20",21.062,21.75333,
"130.30",21.079,21.77,
"130.40",21.095,21.78667,
"130.50",21.109,21.80333,
"130.60",21.122,21.82,
"130.70",21.135,21.83667,
"130.80",21.153,21.85333,
"130.90",21.168,21.87,
"131.00",21.183,21.88667,
"131.10",21.2,21.90333,
"131.20",21.216,21.92,
"131.30",21.233,21.93633,
"131.40",21.245,21.95333,
"131.50",21.255,21.97,
"131.60",21.273,21.98633,
"131.70",21.289,22.00333,
"131.80",21.298,22.02,
"131.90",21.31,22.03667,
"132.00",21.325,22.05333,
"132.10",21.339,22.07,
"132.20",21.353,22.08667,
"132.30",21.371,22.10333,
"132.40",21.386,22.12,
"132.50",21.395,22.13667,
"132.60",21.405,22.15333,
"132.70",21.415,22.17,
"132.80",21.424,22.18667,
"132.90",21.436,22.20333,
"133.00",21.446,22.22,
"133.10",21.454,22.23667,
"133.20",21.462,22.25333,
"133.30",21.468,22.27,
"133.35",21.468,22.27833,