File: pristine_monofilament_10cm_10mmpm_3.csv
"Test Name","Test Mode","Test Type","Control","Test Speed 1","Test Speed 2","Test Speed 3","Change Point 1","Change Point 2","Disp. Origin","Break and Limit Action","Sensitivity:","Level:"
"","Single","Tensile","Stroke",10,1,1,"Off","Off","Start","Stop",0,1

"Title","Sub title","Comment"
"","",""

"Shape:","Batch Size:","SubBatch Size:"
"Plate",1,1
"Name:","Thickness","Width","Gauge Length",
"Size Unit:","mm","mm","mm",
" 1 - 1","1.0000","1.0000","100.0000",

"Name",
"Parameter",
"Units",
" 1 - 1",

" 1- 1"
"Time","Force","Stroke",
"sec","N","mm",
"0.00",-.002,0,
"0.20",0,3.733333E-02,
"0.40",.012,7.433333E-02,
"0.60",.023,.1113333,
"0.80",.037,.1483333,
"1.00",.048,.1856667,
"1.20",.06,.2226667,
"1.40",.07,.2596667,
"1.60",.085,.2966667,
"1.80",.095,.334,
"2.00",.108,.371,
"2.20",.12,.4066667,
"2.40",.131,.4423333,
"2.60",.141,.4773333,
"2.80",.153,.5123333,
"3.00",.165,.5466666,
"3.20",.176,.581,
"3.40",.188,.6153333,
"3.60",.201,.6493333,
"3.80",.211,.6833333,
"4.00",.221,.7169999,
"4.20",.231,.7506666,
"4.40",.245,.7843333,
"4.60",.254,.818,
"4.80",.267,.8513333,
"5.00",.28,.8846666,
"5.20",.291,.9183333,
"5.40",.301,.9516667,
"5.60",.311,.985,
"5.80",.326,1.018667,
"6.00",.337,1.052,
"6.20",.349,1.085333,
"6.40",.36,1.118667,
"6.60",.371,1.152,
"6.80",.382,1.185333,
"7.00",.397,1.218667,
"7.20",.408,1.252,
"7.40",.419,1.285333,
"7.60",.429,1.318667,
"7.80",.44,1.352,
"8.00",.456,1.385333,
"8.20",.468,1.419,
"8.40",.478,1.452,
"8.60",.491,1.485667,
"8.80",.502,1.518667,
"9.00",.517,1.552333,
"9.20",.527,1.585333,
"9.40",.54,1.619,
"9.60",.552,1.652333,
"9.80",.562,1.685667,
"10.00",.578,1.719,
"10.20",.589,1.752333,
"10.40",.601,1.785667,
"10.60",.614,1.819,
"10.80",.626,1.852333,
"11.00",.638,1.885667,
"11.20",.652,1.919,
"11.40",.664,1.952333,
"11.60",.679,1.985667,
"11.80",.69,2.019,
"12.00",.702,2.052333,
"12.20",.715,2.085667,
"12.40",.726,2.119,
"12.60",.741,2.152333,
"12.80",.754,2.185667,
"13.00",.765,2.219,
"13.20",.779,2.252333,
"13.40",.794,2.285667,
"13.60",.805,2.319,
"13.80",.82,2.352334,
"14.00",.832,2.385667,
"14.20",.846,2.419,
"14.40",.862,2.452333,
"14.60",.875,2.485667,
"14.80",.889,2.518667,
"15.00",.902,2.552333,
"15.20",.919,2.585667,
"15.40",.934,2.619,
"15.60",.945,2.652333,
"15.80",.959,2.685667,
"16.00",.974,2.719,
"16.20",.988,2.752333,
"16.40",1.005,2.785667,
"16.60",1.02,2.819,
"16.80",1.036,2.852334,
"17.00",1.048,2.885667,
"17.20",1.064,2.919,
"17.40",1.078,2.952333,
"17.60",1.093,2.985667,
"17.80",1.11,3.019,
"18.00",1.126,3.052333,
"18.20",1.139,3.085667,
"18.40",1.157,3.119,
"18.60",1.171,3.152333,
"18.80",1.186,3.185667,
"19.00",1.202,3.219,
"19.20",1.22,3.252333,
"19.40",1.236,3.285667,
"19.60",1.251,3.319,
"19.80",1.267,3.352334,
"20.00",1.282,3.385667,
"20.20",1.299,3.419,
"20.40",1.316,3.452333,
"20.60",1.335,3.485667,
"20.80",1.349,3.519,
"21.00",1.369,3.552333,
"21.20",1.386,3.585667,
"21.40",1.405,3.619,
"21.60",1.421,3.652333,
"21.80",1.438,3.685667,
"22.00",1.457,3.719,
"22.20",1.476,3.752333,
"22.40",1.492,3.785667,
"22.60",1.509,3.819,
"22.80",1.527,3.852,
"23.00",1.548,3.885667,
"23.20",1.567,3.918667,
"23.40",1.586,3.952333,
"23.60",1.604,3.985667,
"23.80",1.625,4.019,
"24.00",1.64,4.052333,
"24.20",1.66,4.085667,
"24.40",1.68,4.119,
"24.60",1.7,4.152333,
"24.80",1.721,4.185667,
"25.00",1.74,4.219334,
"25.20",1.761,4.252334,
"25.40",1.78,4.285667,
"25.60",1.8,4.319334,
"25.80",1.82,4.352334,
"26.00",1.839,4.385667,
"26.20",1.863,4.419,
"26.40",1.882,4.452333,
"26.60",1.904,4.485667,
"26.80",1.926,4.519,
"27.00",1.948,4.552333,
"27.20",1.968,4.585667,
"27.40",1.992,4.619333,
"27.60",2.012,4.652667,
"27.80",2.034,4.686,
"28.00",2.057,4.719,
"28.20",2.077,4.752334,
"28.40",2.103,4.785667,
"28.60",2.123,4.819,
"28.80",2.146,4.852334,
"29.00",2.169,4.885667,
"29.20",2.193,4.919,
"29.40",2.216,4.952333,
"29.60",2.237,4.985667,
"29.80",2.26,5.019,
"30.00",2.284,5.052333,
"30.20",2.311,5.085667,
"30.40",2.333,5.119,
"30.60",2.353,5.152333,
"30.80",2.38,5.185667,
"31.00",2.404,5.219,
"31.20",2.427,5.252334,
"31.40",2.453,5.285667,
"31.60",2.477,5.319,
"31.80",2.502,5.352334,
"32.00",2.527,5.385334,
"32.20",2.553,5.419,
"32.40",2.578,5.452333,
"32.60",2.602,5.485333,
"32.80",2.628,5.519,
"33.00",2.654,5.552333,
"33.20",2.683,5.585667,
"33.40",2.709,5.619,
"33.60",2.732,5.652333,
"33.80",2.756,5.685667,
"34.00",2.788,5.719,
"34.20",2.812,5.752334,
"34.40",2.841,5.785667,
"34.60",2.867,5.819,
"34.80",2.893,5.852334,
"35.00",2.92,5.886,
"35.20",2.95,5.919,
"35.40",2.981,5.952333,
"35.60",3.009,5.986,
"35.80",3.038,6.019333,
"36.00",3.067,6.052333,
"36.20",3.094,6.085667,
"36.40",3.125,6.119,
"36.60",3.154,6.152333,
"36.80",3.185,6.185667,
"37.00",3.213,6.219,
"37.20",3.245,6.252334,
"37.40",3.275,6.285667,
"37.60",3.306,6.319,
"37.80",3.333,6.352334,
"38.00",3.362,6.385667,
"38.20",3.397,6.419,
"38.40",3.428,6.452333,
"38.60",3.457,6.485667,
"38.80",3.489,6.519333,
"39.00",3.521,6.552667,
"39.20",3.552,6.586,
"39.40",3.581,6.619333,
"39.60",3.614,6.652667,
"39.80",3.643,6.686,
"40.00",3.673,6.719334,
"40.20",3.707,6.752334,
"40.40",3.737,6.785667,
"40.60",3.77,6.819,
"40.80",3.802,6.852334,
"41.00",3.835,6.886,
"41.20",3.865,6.919,
"41.40",3.898,6.952667,
"41.60",3.93,6.986,
"41.80",3.96,7.019333,
"42.00",3.993,7.052667,
"42.20",4.024,7.085667,
"42.40",4.057,7.119,
"42.60",4.087,7.152333,
"42.80",4.119,7.185667,
"43.00",4.152,7.219,
"43.20",4.185,7.252334,
"43.40",4.217,7.286,
"43.60",4.247,7.319334,
"43.80",4.28,7.352667,
"44.00",4.315,7.385667,
"44.20",4.347,7.419,
"44.40",4.38,7.452333,
"44.60",4.411,7.485667,
"44.80",4.443,7.519,
"45.00",4.477,7.552667,
"45.20",4.511,7.585667,
"45.40",4.545,7.619333,
"45.60",4.574,7.652667,
"45.80",4.608,7.686,
"46.00",4.639,7.719,
"46.20",4.673,7.752334,
"46.40",4.708,7.785667,
"46.60",4.743,7.819334,
"46.80",4.772,7.852334,
"47.00",4.806,7.885667,
"47.20",4.838,7.919,
"47.40",4.872,7.952667,
"47.60",4.902,7.986,
"47.80",4.936,8.019334,
"48.00",4.968,8.052667,
"48.20",5,8.086,
"48.40",5.034,8.119333,
"48.60",5.065,8.152333,
"48.80",5.098,8.185667,
"49.00",5.131,8.219,
"49.20",5.165,8.252334,
"49.40",5.196,8.285666,
"49.60",5.226,8.319333,
"49.80",5.259,8.352333,
"50.00",5.289,8.385667,
"50.20",5.324,8.419,
"50.40",5.356,8.452333,
"50.60",5.385,8.485667,
"50.80",5.412,8.519,
"51.00",5.445,8.552334,
"51.20",5.475,8.585667,
"51.40",5.508,8.619,
"51.60",5.539,8.652333,
"51.80",5.568,8.685667,
"52.00",5.598,8.719,
"52.20",5.628,8.752334,
"52.40",5.658,8.785666,
"52.60",5.688,8.819,
"52.80",5.717,8.852,
"53.00",5.748,8.885667,
"53.20",5.78,8.919,
"53.40",5.811,8.952333,
"53.60",5.841,8.985667,
"53.80",5.871,9.019,
"54.00",5.901,9.052334,
"54.20",5.932,9.085667,
"54.40",5.963,9.119,
"54.60",5.991,9.152333,
"54.80",6.019,9.185333,
"55.00",6.047,9.219,
"55.20",6.079,9.252334,
"55.40",6.108,9.285666,
"55.60",6.137,9.319,
"55.80",6.163,9.352333,
"56.00",6.19,9.385667,
"56.20",6.222,9.419,
"56.40",6.25,9.452333,
"56.60",6.279,9.485667,
"56.80",6.308,9.518667,
"57.00",6.338,9.552334,
"57.20",6.367,9.585334,
"57.40",6.397,9.619,
"57.60",6.428,9.652333,
"57.80",6.456,9.685667,
"58.00",6.485,9.719,
"58.20",6.514,9.752334,
"58.40",6.543,9.785666,
"58.60",6.57,9.819,
"58.80",6.597,9.852333,
"59.00",6.623,9.885667,
"59.20",6.652,9.919,
"59.40",6.68,9.952333,
"59.60",6.706,9.985667,
"59.80",6.73,10.019,
"60.00",6.76,10.05233,
"60.20",6.787,10.08567,
"60.40",6.818,10.119,
"60.60",6.844,10.15233,
"60.80",6.873,10.18533,
"61.00",6.902,10.219,
"61.20",6.932,10.25233,
"61.40",6.961,10.28567,
"61.60",6.989,10.319,
"61.80",7.013,10.35233,
"62.00",7.043,10.38567,
"62.20",7.07,10.419,
"62.40",7.095,10.45233,
"62.60",7.121,10.48567,
"62.80",7.145,10.519,
"63.00",7.172,10.55233,
"63.20",7.198,10.58533,
"63.40",7.22,10.619,
"63.60",7.241,10.65233,
"63.80",7.267,10.68567,
"64.00",7.29,10.719,
"64.20",7.317,10.75233,
"64.40",7.342,10.78567,
"64.60",7.365,10.819,
"64.80",7.391,10.852,
"65.00",7.414,10.88567,
"65.20",7.441,10.919,
"65.40",7.464,10.95233,
"65.60",7.486,10.98567,
"65.80",7.507,11.019,
"66.00",7.534,11.05233,
"66.20",7.555,11.08533,
"66.40",7.577,11.119,
"66.60",7.6,11.15233,
"66.80",7.622,11.18567,
"67.00",7.648,11.219,
"67.20",7.668,11.252,
"67.40",7.695,11.28567,
"67.60",7.714,11.319,
"67.80",7.741,11.35233,
"68.00",7.761,11.38567,
"68.20",7.785,11.419,
"68.40",7.808,11.452,
"68.60",7.827,11.48567,
"68.80",7.85,11.519,
"69.00",7.877,11.55233,
"69.20",7.903,11.58533,
"69.40",7.925,11.619,
"69.60",7.947,11.65233,
"69.80",7.969,11.68567,
"70.00",7.994,11.719,
"70.20",8.021,11.75233,
"70.40",8.044,11.78533,
"70.60",8.065,11.81867,
"70.80",8.091,11.85233,
"71.00",8.111,11.88567,
"71.20",8.136,11.919,
"71.40",8.156,11.95233,
"71.60",8.175,11.98567,
"71.80",8.192,12.019,
"72.00",8.217,12.05233,
"72.20",8.24,12.08567,
"72.40",8.262,12.119,
"72.60",8.286,12.15233,
"72.80",8.308,12.18567,
"73.00",8.329,12.219,
"73.20",8.353,12.25233,
"73.40",8.377,12.28567,
"73.60",8.397,12.319,
"73.80",8.421,12.35233,
"74.00",8.444,12.38567,
"74.20",8.468,12.419,
"74.40",8.493,12.45233,
"74.60",8.515,12.48567,
"74.80",8.536,12.519,
"75.00",8.556,12.55233,
"75.20",8.584,12.58533,
"75.40",8.605,12.61867,
"75.60",8.629,12.652,
"75.80",8.646,12.68533,
"76.00",8.668,12.71867,
"76.20",8.69,12.75233,
"76.40",8.713,12.78567,
"76.60",8.734,12.819,
"76.80",8.753,12.85233,
"77.00",8.773,12.88567,
"77.20",8.794,12.919,
"77.40",8.814,12.95233,
"77.60",8.835,12.98567,
"77.80",8.854,13.019,
"78.00",8.875,13.05233,
"78.20",8.899,13.08567,
"78.40",8.924,13.119,
"78.60",8.944,13.15233,
"78.80",8.966,13.18567,
"79.00",8.994,13.219,
"79.20",9.019,13.25233,
"79.40",9.039,13.28567,
"79.60",9.059,13.319,
"79.80",9.083,13.35233,
"80.00",9.104,13.38567,
"80.20",9.124,13.419,
"80.40",9.147,13.45233,
"80.60",9.17,13.48567,
"80.80",9.189,13.519,
"81.00",9.214,13.55233,
"81.20",9.237,13.58567,
"81.40",9.266,13.619,
"81.60",9.289,13.65233,
"81.80",9.316,13.68567,
"82.00",9.346,13.719,
"82.20",9.373,13.75233,
"82.40",9.398,13.78567,
"82.60",9.419,13.819,
"82.80",9.442,13.852,
"83.00",9.465,13.88567,
"83.20",9.486,13.919,
"83.40",9.507,13.95233,
"83.60",9.53,13.98567,
"83.80",9.548,14.019,
"84.00",9.571,14.05233,
"84.20",9.59,14.08567,
"84.40",9.611,14.119,
"84.60",9.63,14.15233,
"84.80",9.649,14.18567,
"85.00",9.67,14.219,
"85.20",9.693,14.25233,
"85.40",9.714,14.28567,
"85.60",9.738,14.319,
"85.80",9.754,14.35233,
"86.00",9.776,14.38567,
"86.20",9.797,14.419,
"86.40",9.818,14.452,
"86.60",9.835,14.48533,
"86.80",9.853,14.519,
"87.00",9.869,14.552,
"87.20",9.889,14.58533,
"87.40",9.909,14.619,
"87.60",9.929,14.65233,
"87.80",9.95,14.68567,
"88.00",9.972,14.719,
"88.20",9.995,14.75233,
"88.40",10.015,14.78567,
"88.60",10.035,14.819,
"88.80",10.053,14.85233,
"89.00",10.072,14.88567,
"89.20",10.095,14.91867,
"89.40",10.116,14.95233,
"89.60",10.136,14.98567,
"89.80",10.156,15.01867,
"90.00",10.176,15.05233,
"90.20",10.198,15.08567,
"90.40",10.218,15.119,
"90.60",10.234,15.15233,
"90.80",10.253,15.18567,
"91.00",10.273,15.219,
"91.20",10.298,15.252,
"91.40",10.319,15.28533,
"91.60",10.335,15.319,
"91.80",10.355,15.35233,
"92.00",10.374,15.38567,
"92.20",10.393,15.41867,
"92.40",10.415,15.45233,
"92.60",10.433,15.48533,
"92.80",10.449,15.51867,
"93.00",10.468,15.55233,
"93.20",10.492,15.58533,
"93.40",10.508,15.619,
"93.60",10.529,15.65233,
"93.80",10.545,15.68567,
"94.00",10.569,15.719,
"94.20",10.589,15.75233,
"94.40",10.609,15.78567,
"94.60",10.626,15.819,
"94.80",10.647,15.85233,
"95.00",10.667,15.88567,
"95.20",10.691,15.919,
"95.40",10.71,15.95233,
"95.60",10.737,15.98567,
"95.80",10.752,16.019,
"96.00",10.776,16.05233,
"96.20",10.797,16.08567,
"96.40",10.819,16.119,
"96.60",10.841,16.15233,
"96.80",10.857,16.18567,
"97.00",10.876,16.219,
"97.20",10.895,16.25233,
"97.40",10.911,16.28567,
"97.60",10.929,16.319,
"97.80",10.944,16.35233,
"98.00",10.962,16.38567,
"98.20",10.98,16.419,
"98.40",10.995,16.45233,
"98.60",11.009,16.48567,
"98.80",11.02,16.519,
"99.00",11.041,16.55233,
"99.20",11.058,16.58567,
"99.40",11.074,16.619,
"99.60",11.09,16.65233,
"99.80",11.111,16.68567,
"100.00",11.131,16.71867,
"100.20",11.154,16.752,
"100.40",11.177,16.78567,
"100.60",11.194,16.81867,
"100.80",11.211,16.852,
"101.00",11.234,16.88533,
"101.20",11.26,16.919,
"101.40",11.278,16.95233,
"101.60",11.296,16.98567,
"101.80",11.314,17.019,
"102.00",11.329,17.052,
"102.20",11.349,17.08533,
"102.40",11.365,17.119,
"102.60",11.383,17.152,
"102.80",11.398,17.18567,
"103.00",11.415,17.219,
"103.20",11.434,17.25233,
"103.40",11.449,17.28567,
"103.60",11.467,17.319,
"103.80",11.484,17.35233,
"104.00",11.503,17.38567,
"104.20",11.521,17.41867,
"104.40",11.544,17.45233,
"104.60",11.563,17.48533,
"104.80",11.582,17.51867,
"105.00",11.604,17.55233,
"105.20",11.628,17.58567,
"105.40",11.651,17.619,
"105.60",11.666,17.65233,
"105.80",11.686,17.68567,
"106.00",11.704,17.719,
"106.20",11.722,17.75233,
"106.40",11.74,17.78567,
"106.60",11.758,17.819,
"106.80",11.77,17.85233,
"107.00",11.783,17.88567,
"107.20",11.799,17.919,
"107.40",11.816,17.95233,
"107.60",11.83,17.98567,
"107.80",11.847,18.019,
"108.00",11.86,18.05233,
"108.20",11.877,18.08567,
"108.40",11.895,18.119,
"108.60",11.911,18.152,
"108.80",11.925,18.18533,
"109.00",11.939,18.21867,
"109.20",11.959,18.252,
"109.40",11.972,18.28567,
"109.60",11.983,18.319,
"109.80",11.996,18.35233,
"110.00",12.012,18.38567,
"110.20",12.033,18.419,
"110.40",12.047,18.45233,
"110.60",12.061,18.48533,
"110.80",12.078,18.519,
"111.00",12.095,18.55233,
"111.20",12.117,18.58533,
"111.40",12.135,18.619,
"111.60",12.151,18.65233,
"111.80",12.165,18.68567,
"112.00",12.182,18.719,
"112.20",12.196,18.75233,
"112.40",12.209,18.78567,
"112.60",12.22,18.81867,
"112.80",12.231,18.852,
"113.00",12.245,18.88567,
"113.20",12.26,18.919,
"113.40",12.271,18.95233,
"113.60",12.286,18.98567,
"113.80",12.3,19.019,
"114.00",12.317,19.05233,
"114.20",12.337,19.08567,
"114.40",12.35,19.119,
"114.60",12.369,19.15233,
"114.80",12.382,19.18567,
"115.00",12.4,19.21867,
"115.20",12.414,19.252,
"115.40",12.431,19.28567,
"115.60",12.445,19.319,
"115.80",12.457,19.35233,
"116.00",12.471,19.38567,
"116.20",12.489,19.419,
"116.40",12.501,19.45233,
"116.60",12.517,19.48567,
"116.80",12.53,19.519,
"117.00",12.545,19.55233,
"117.20",12.563,19.58567,
"117.40",12.581,19.619,
"117.60",12.594,19.65233,
"117.80",12.615,19.68567,
"118.00",12.633,19.719,
"118.20",12.652,19.75233,
"118.40",12.667,19.78567,
"118.60",12.683,19.819,
"118.80",12.697,19.85233,
"119.00",12.713,19.88567,
"119.20",12.731,19.919,
"119.40",12.746,19.95233,
"119.60",12.753,19.98567,
"119.80",12.765,20.019,
"120.00",12.782,20.05233,
"120.20",12.801,20.08567,
"120.40",12.822,20.119,
"120.60",12.84,20.15233,
"120.80",12.858,20.18567,
"121.00",12.875,20.219,
"121.20",12.896,20.25233,
"121.40",12.912,20.28567,
"121.60",12.928,20.319,
"121.80",12.947,20.35233,
"122.00",12.962,20.38567,
"122.20",12.979,20.419,
"122.40",12.993,20.45233,
"122.60",13.01,20.48567,
"122.80",13.025,20.519,
"123.00",13.042,20.55233,
"123.20",13.056,20.58567,
"123.40",13.068,20.619,
"123.60",13.083,20.65233,
"123.80",13.097,20.68567,
"124.00",13.112,20.719,
"124.20",13.129,20.75233,
"124.40",13.144,20.78567,
"124.60",13.158,20.819,
"124.80",13.169,20.85233,
"125.00",13.183,20.88567,
"125.20",13.202,20.919,
"125.40",13.215,20.95233,
"125.60",13.228,20.98567,
"125.80",13.24,21.019,
"126.00",13.254,21.052,
"126.20",13.273,21.08533,
"126.40",13.295,21.119,
"126.60",13.308,21.15233,
"126.80",13.324,21.18567,
"127.00",13.339,21.21867,
"127.20",13.357,21.252,
"127.40",13.371,21.28533,
"127.60",13.39,21.319,
"127.80",13.405,21.35233,
"128.00",13.422,21.38567,
"128.20",13.439,21.41867,
"128.40",13.454,21.452,
"128.60",13.469,21.48533,
"128.80",13.485,21.51867,
"129.00",13.501,21.55233,
"129.20",13.52,21.58567,
"129.40",13.534,21.619,
"129.60",13.544,21.65233,
"129.80",13.555,21.68567,
"130.00",13.57,21.719,
"130.20",13.589,21.75233,
"130.40",13.603,21.78567,
"130.60",13.617,21.819,
"130.80",13.633,21.85233,
"131.00",13.648,21.88567,
"131.20",13.664,21.91867,
"131.40",13.682,21.95233,
"131.60",13.696,21.98567,
"131.80",13.707,22.019,
"132.00",13.723,22.05233,
"132.20",13.737,22.08567,
"132.40",13.754,22.119,
"132.60",13.768,22.15233,
"132.80",13.782,22.18567,
"133.00",13.799,22.219,
"133.20",13.817,22.252,
"133.40",13.83,22.28567,
"133.60",13.844,22.319,
"133.80",13.86,22.35233,
"134.00",13.874,22.38533,
"134.20",13.885,22.41867,
"134.40",13.897,22.452,
"134.60",13.906,22.48567,
"134.80",13.92,22.519,
"135.00",13.934,22.55233,
"135.20",13.952,22.58567,
"135.40",13.967,22.619,
"135.60",13.983,22.65233,
"135.80",13.996,22.68567,
"136.00",14.015,22.719,
"136.20",14.031,22.75233,
"136.40",14.051,22.78567,
"136.60",14.064,22.819,
"136.80",14.081,22.85233,
"137.00",14.098,22.88567,
"137.20",14.117,22.91867,
"137.40",14.131,22.95233,
"137.60",14.147,22.98567,
"137.80",14.162,23.019,
"138.00",14.176,23.05233,
"138.20",14.192,23.08567,
"138.40",14.203,23.119,
"138.60",14.213,23.15233,
"138.80",14.224,23.18533,
"139.00",14.237,23.219,
"139.20",14.254,23.25233,
"139.40",14.267,23.28567,
"139.60",14.276,23.319,
"139.80",14.287,23.35233,
"140.00",14.306,23.38567,
"140.20",14.321,23.41867,
"140.40",14.338,23.452,
"140.60",14.351,23.48567,
"140.80",14.364,23.519,
"141.00",14.375,23.55233,
"141.20",14.39,23.58533,
"141.40",14.407,23.619,
"141.60",14.42,23.65233,
"141.80",14.436,23.68567,
"142.00",14.452,23.719,
"142.20",14.47,23.75233,
"142.40",14.485,23.78567,
"142.60",14.499,23.819,
"142.80",14.51,23.852,
"143.00",14.525,23.88567,
"143.20",14.541,23.919,
"143.40",14.553,23.95233,
"143.60",14.562,23.98567,
"143.80",14.575,24.019,
"144.00",14.594,24.05233,
"144.20",14.61,24.08567,
"144.40",14.625,24.119,
"144.60",14.639,24.15233,
"144.80",14.642,24.18567,
"145.00",14.655,24.219,
"145.20",14.667,24.25233,
"145.40",14.68,24.28567,
"145.60",14.685,24.319,
"145.80",14.697,24.352,
"146.00",14.709,24.38567,
"146.20",14.719,24.419,
"146.40",14.734,24.45233,
"146.60",14.745,24.48533,
"146.80",14.755,24.51867,
"147.00",14.767,24.55233,
"147.20",14.782,24.58567,
"147.40",14.794,24.619,
"147.60",14.806,24.65233,
"147.80",14.819,24.68567,
"148.00",14.828,24.719,
"148.20",14.843,24.75233,
"148.40",14.852,24.78533,
"148.60",14.865,24.81867,
"148.80",14.877,24.85233,
"149.00",14.892,24.88567,
"149.20",14.909,24.919,
"149.40",14.921,24.95233,
"149.60",14.931,24.98567,
"149.80",14.941,25.019,
"150.00",14.953,25.05233,
"150.20",14.966,25.08567,
"150.40",14.977,25.119,
"150.60",14.985,25.15233,
"150.80",14.996,25.18533,
"151.00",15.009,25.219,
"151.20",15.021,25.25233,
"151.40",15.034,25.28567,
"151.60",15.046,25.319,
"151.80",15.059,25.352,
"152.00",15.072,25.38533,
"152.20",15.081,25.41867,
"152.40",15.097,25.452,
"152.60",15.105,25.48533,
"152.80",15.12,25.519,
"153.00",15.13,25.55233,
"153.20",15.142,25.58533,
"153.40",15.153,25.619,
"153.60",15.16,25.65233,
"153.80",15.171,25.68567,
"154.00",15.185,25.719,
"154.20",15.201,25.75233,
"154.40",15.213,25.78567,
"154.60",15.227,25.819,
"154.80",15.242,25.85233,
"155.00",15.263,25.88567,
"155.20",15.283,25.919,
"155.40",15.308,25.95233,
"155.60",15.33,25.98567,
"155.80",15.352,26.019,
"156.00",15.372,26.05233,
"156.20",15.396,26.08567,
"156.40",15.42,26.119,
"156.60",15.438,26.15233,
"156.80",15.456,26.18567,
"157.00",15.476,26.219,
"157.20",15.491,26.25233,
"157.40",15.504,26.28567,
"157.60",15.513,26.319,
"157.80",15.524,26.35233,
"158.00",15.534,26.38567,
"158.20",15.546,26.419,
"158.40",15.554,26.45233,
"158.60",15.562,26.48567,
"158.80",15.572,26.519,
"159.00",15.581,26.55233,
"159.20",15.593,26.58567,
"159.40",15.604,26.619,
"159.60",15.608,26.65233,
"159.80",15.618,26.68567,
"160.00",15.626,26.719,
"160.20",15.636,26.75233,
"160.40",15.641,26.78567,
"160.60",15.642,26.819,
"160.80",15.649,26.85233,
"161.00",15.652,26.88567,
"161.20",15.661,26.919,
"161.40",15.672,26.95233,
"161.60",15.682,26.986,
"161.80",15.692,27.019,
"162.00",15.701,27.05233,
"162.20",15.708,27.08567,
"162.40",15.718,27.119,
"162.60",15.727,27.15233,
"162.80",15.737,27.18567,
"163.00",15.744,27.219,
"163.20",15.758,27.25233,
"163.40",15.764,27.28567,
"163.60",15.776,27.319,
"163.80",15.791,27.35233,
"164.00",15.802,27.38567,
"164.20",15.817,27.419,
"164.40",15.835,27.45233,
"164.60",15.846,27.48567,
"164.80",15.857,27.519,
"165.00",15.871,27.55233,
"165.20",15.886,27.58567,
"165.40",15.902,27.619,
"165.60",15.912,27.65233,
"165.80",15.922,27.68567,
"166.00",15.935,27.719,
"166.20",15.95,27.75233,
"166.40",15.961,27.78533,
"166.60",15.971,27.81867,
"166.80",15.979,27.852,
"167.00",15.992,27.88533,
"167.20",16.003,27.919,
"167.40",16.018,27.952,
"167.60",16.036,27.98567,
"167.80",16.056,28.019,
"168.00",16.068,28.05233,
"168.20",16.083,28.08567,
"168.40",16.098,28.119,
"168.60",16.109,28.15233,
"168.80",16.122,28.18567,
"169.00",16.14,28.219,
"169.20",16.157,28.25233,
"169.40",16.169,28.28567,
"169.60",16.179,28.319,
"169.80",16.188,28.35233,
"170.00",16.205,28.38567,
"170.20",16.22,28.419,
"170.40",16.235,28.45233,
"170.60",16.248,28.48567,
"170.80",16.262,28.519,
"171.00",16.279,28.55233,
"171.20",16.294,28.58533,
"171.40",16.311,28.619,
"171.60",16.324,28.65233,
"171.80",16.333,28.68567,
"172.00",16.343,28.719,
"172.20",16.349,28.752,
"172.40",16.363,28.78533,
"172.60",16.368,28.81867,
"172.80",16.375,28.852,
"173.00",16.385,28.88533,
"173.20",16.393,28.91867,
"173.40",16.407,28.952,
"173.60",16.414,28.98567,
"173.80",16.421,29.019,
"174.00",16.432,29.05233,
"174.20",16.44,29.08533,
"174.40",16.446,29.11867,
"174.60",16.453,29.152,
"174.80",16.46,29.18533,
"175.00",16.472,29.219,
"175.20",16.486,29.25233,
"175.40",16.5,29.28567,
"175.60",16.512,29.319,
"175.80",16.525,29.35233,
"176.00",16.537,29.38567,
"176.20",16.553,29.419,
"176.40",16.569,29.45233,
"176.60",16.581,29.48567,
"176.80",16.594,29.519,
"177.00",16.605,29.55233,
"177.20",16.622,29.58567,
"177.40",16.634,29.619,
"177.60",16.645,29.65233,
"177.80",16.658,29.68567,
"178.00",16.669,29.719,
"178.20",16.68,29.75233,
"178.40",16.692,29.78567,
"178.60",16.699,29.819,
"178.80",16.714,29.85233,
"179.00",16.726,29.88567,
"179.20",16.736,29.919,
"179.40",16.746,29.952,
"179.60",16.751,29.98533,
"179.80",16.758,30.019,
"180.00",16.766,30.05233,
"180.20",16.782,30.08567,
"180.40",16.792,30.119,
"180.60",16.801,30.15233,
"180.80",16.807,30.18567,
"181.00",16.819,30.219,
"181.20",16.827,30.25233,
"181.40",16.841,30.28567,
"181.60",16.846,30.319,
"181.80",16.856,30.35233,
"182.00",16.865,30.38567,
"182.20",16.879,30.419,
"182.40",16.891,30.452,
"182.60",16.902,30.48567,
"182.80",16.919,30.51867,
"183.00",16.936,30.55233,
"183.20",16.954,30.58567,
"183.40",16.969,30.619,
"183.60",16.981,30.65233,
"183.80",16.995,30.68533,
"184.00",17.013,30.71867,
"184.20",17.029,30.752,
"184.40",17.041,30.78533,
"184.60",17.05,30.81867,
"184.80",17.059,30.85233,
"185.00",17.072,30.88567,
"185.20",17.089,30.91867,
"185.40",17.101,30.95233,
"185.60",17.112,30.98567,
"185.80",17.121,31.019,
"186.00",17.132,31.052,
"186.20",17.148,31.08533,
"186.40",17.16,31.11867,
"186.60",17.172,31.152,
"186.80",17.184,31.18533,
"187.00",17.197,31.219,
"187.20",17.207,31.252,
"187.40",17.218,31.28567,
"187.60",17.225,31.319,
"187.80",17.234,31.35233,
"188.00",17.245,31.38533,
"188.20",17.261,31.41867,
"188.40",17.27,31.452,
"188.60",17.281,31.48533,
"188.80",17.292,31.51867,
"189.00",17.303,31.552,
"189.20",17.314,31.58533,
"189.40",17.325,31.61867,
"189.60",17.332,31.652,
"189.80",17.338,31.68533,
"190.00",17.351,31.71867,
"190.20",17.363,31.752,
"190.40",17.376,31.78533,
"190.60",17.385,31.819,
"190.80",17.398,31.85233,
"191.00",17.405,31.88567,
"191.20",17.415,31.91867,
"191.40",17.425,31.952,
"191.60",17.43,31.98567,
"191.80",17.441,32.019,
"192.00",17.448,32.05233,
"192.20",17.455,32.08533,
"192.40",17.464,32.11866,
"192.60",17.47,32.152,
"192.80",17.476,32.18533,
"193.00",17.487,32.219,
"193.20",17.497,32.252,
"193.40",17.505,32.28566,
"193.60",17.51,32.319,
"193.80",17.52,32.35233,
"194.00",17.525,32.38567,
"194.20",17.535,32.419,
"194.40",17.542,32.45233,
"194.60",17.547,32.48566,
"194.80",17.548,32.519,
"195.00",17.555,32.552,
"195.20",17.563,32.58533,
"195.40",17.567,32.61866,
"195.60",17.569,32.65233,
"195.80",17.57,32.68533,
"196.00",17.575,32.71867,
"196.20",17.581,32.752,
"196.40",17.591,32.78566,
"196.60",17.596,32.819,
"196.80",17.604,32.85233,
"197.00",17.612,32.88567,
"197.20",17.622,32.91866,
"197.40",17.633,32.952,
"197.60",17.643,32.98533,
"197.80",17.654,33.01867,
"198.00",17.667,33.052,
"198.20",17.676,33.08533,
"198.40",17.687,33.11866,
"198.60",17.695,33.152,
"198.80",17.706,33.18533,
"199.00",17.718,33.21867,
"199.20",17.729,33.252,
"199.40",17.737,33.28533,
"199.60",17.745,33.319,
"199.80",17.756,33.35233,
"200.00",17.769,33.38533,
"200.20",17.783,33.41866,
"200.40",17.793,33.452,
"200.60",17.802,33.48533,
"200.80",17.808,33.51867,
"201.00",17.811,33.552,
"201.20",17.822,33.58533,
"201.40",17.829,33.61866,
"201.60",17.832,33.652,
"201.80",17.838,33.68567,
"202.00",17.845,33.719,
"202.20",17.851,33.752,
"202.40",17.862,33.78533,
"202.60",17.867,33.81866,
"202.80",17.879,33.852,
"203.00",17.89,33.88567,
"203.20",17.9,33.91866,
"203.40",17.908,33.952,
"203.60",17.912,33.98566,
"203.80",17.924,34.01867,
"204.00",17.934,34.052,
"204.20",17.949,34.08533,
"204.40",17.966,34.11866,
"204.60",17.978,34.15233,
"204.80",17.989,34.18567,
"205.00",18.006,34.219,
"205.20",18.023,34.252,
"205.40",18.041,34.28566,
"205.60",18.053,34.319,
"205.80",18.062,34.35233,
"206.00",18.076,34.38567,
"206.20",18.09,34.419,
"206.40",18.103,34.45233,
"206.60",18.109,34.48566,
"206.80",18.117,34.519,
"207.00",18.122,34.55233,
"207.20",18.135,34.58533,
"207.40",18.142,34.619,
"207.60",18.145,34.65233,
"207.80",18.151,34.68567,
"208.00",18.162,34.719,
"208.20",18.176,34.75233,
"208.40",18.187,34.78566,
"208.60",18.199,34.819,
"208.80",18.213,34.85233,
"209.00",18.226,34.88567,
"209.20",18.239,34.91866,
"209.40",18.251,34.952,
"209.60",18.254,34.98566,
"209.80",18.262,35.019,
"210.00",18.271,35.05233,
"210.20",18.283,35.08567,
"210.40",18.292,35.11866,
"210.60",18.298,35.15233,
"210.80",18.303,35.18533,
"211.00",18.31,35.21867,
"211.20",18.322,35.252,
"211.40",18.335,35.28533,
"211.60",18.341,35.319,
"211.80",18.351,35.35233,
"212.00",18.361,35.38533,
"212.20",18.371,35.41866,
"212.40",18.384,35.452,
"212.60",18.395,35.48533,
"212.80",18.404,35.51867,
"213.00",18.419,35.552,
"213.20",18.432,35.58533,
"213.40",18.447,35.61866,
"213.60",18.454,35.652,
"213.80",18.468,35.68533,
"214.00",18.489,35.71867,
"214.20",18.505,35.752,
"214.40",18.518,35.78533,
"214.60",18.532,35.819,
"214.80",18.543,35.85233,
"215.00",18.555,35.88567,
"215.20",18.572,35.91866,
"215.40",18.584,35.952,
"215.60",18.594,35.98566,
"215.80",18.6,36.01867,
"216.00",18.603,36.05233,
"216.20",18.606,36.08533,
"216.40",18.612,36.11866,
"216.60",18.612,36.152,
"216.80",18.609,36.18533,
"217.00",18.604,36.21867,
"217.20",18.606,36.252,
"217.40",18.606,36.28533,
"217.60",18.611,36.319,
"217.80",18.615,36.35233,
"218.00",18.621,36.38567,
"218.20",18.632,36.419,
"218.40",18.642,36.452,
"218.60",18.656,36.48533,
"218.80",18.667,36.51867,
"219.00",18.686,36.552,
"219.20",18.706,36.58533,
"219.40",18.723,36.61866,
"219.60",18.735,36.652,
"219.80",18.744,36.68533,
"220.00",18.755,36.719,
"220.20",18.771,36.75233,
"220.40",18.782,36.78566,
"220.60",18.791,36.819,
"220.80",18.797,36.85233,
"221.00",18.807,36.88567,
"221.20",18.82,36.91866,
"221.40",18.828,36.95233,
"221.60",18.834,36.98566,
"221.80",18.841,37.019,
"222.00",18.848,37.05233,
"222.20",18.858,37.08533,
"222.40",18.867,37.11866,
"222.60",18.876,37.152,
"222.80",18.884,37.18533,
"223.00",18.899,37.219,
"223.20",18.911,37.25233,
"223.40",18.92,37.28566,
"223.60",18.928,37.319,
"223.80",18.939,37.35233,
"224.00",18.951,37.38567,
"224.20",18.964,37.41866,
"224.40",18.974,37.452,
"224.60",18.982,37.48533,
"224.80",18.99,37.51867,
"225.00",18.994,37.552,
"225.20",18.998,37.58533,
"225.40",19.001,37.61866,
"225.60",19.006,37.652,
"225.80",19.011,37.68533,
"226.00",19.02,37.71867,
"226.20",19.029,37.752,
"226.40",19.041,37.78533,
"226.60",19.047,37.81866,
"226.80",19.052,37.852,
"227.00",19.065,37.88533,
"227.20",19.075,37.91866,
"227.40",19.086,37.952,
"227.60",19.095,37.98566,
"227.80",19.104,38.01867,
"228.00",19.112,38.052,
"228.20",19.122,38.08533,
"228.40",19.131,38.119,
"228.60",19.141,38.152,
"228.80",19.15,38.18533,
"229.00",19.158,38.21867,
"229.20",19.169,38.252,
"229.40",19.18,38.28566,
"229.60",19.187,38.319,
"229.80",19.189,38.35233,
"230.00",19.197,38.38567,
"230.20",19.207,38.419,
"230.40",19.214,38.452,
"230.60",19.219,38.48533,
"230.80",19.223,38.51867,
"231.00",19.229,38.552,
"231.20",19.237,38.58533,
"231.40",19.238,38.61866,
"231.60",19.238,38.65233,
"231.80",19.239,38.68567,
"232.00",19.24,38.719,
"232.20",19.244,38.75233,
"232.40",19.246,38.78566,
"232.60",19.251,38.81866,
"232.80",19.256,38.852,
"233.00",19.261,38.88567,
"233.20",19.266,38.919,
"233.40",19.269,38.95233,
"233.60",19.273,38.98566,
"233.80",19.278,39.019,
"234.00",19.285,39.05233,
"234.20",19.293,39.08567,
"234.40",19.3,39.119,
"234.60",19.306,39.152,
"234.80",19.312,39.18567,
"235.00",19.329,39.21867,
"235.20",19.345,39.252,
"235.40",19.362,39.28533,
"235.60",19.373,39.319,
"235.80",19.378,39.352,
"236.00",19.391,39.38533,
"236.20",19.406,39.41866,
"236.40",19.42,39.452,
"236.60",19.427,39.48533,
"236.80",19.432,39.51867,
"237.00",19.44,39.552,
"237.20",19.45,39.58533,
"237.40",19.458,39.61866,
"237.60",19.469,39.652,
"237.80",19.477,39.68533,
"238.00",19.488,39.71867,
"238.20",19.503,39.752,
"238.40",19.511,39.78533,
"238.60",19.52,39.81866,
"238.80",19.527,39.852,
"239.00",19.539,39.88567,
"239.20",19.551,39.91866,
"239.40",19.558,39.95233,
"239.60",19.565,39.98566,
"239.80",19.568,40.01867,
"240.00",19.574,40.052,
"240.20",19.583,40.08533,
"240.40",19.587,40.11866,
"240.60",19.595,40.152,
"240.80",19.598,40.18533,
"241.00",19.599,40.21867,
"241.20",19.604,40.252,
"241.40",19.606,40.28533,
"241.60",19.606,40.31866,
"241.80",19.608,40.352,
"242.00",19.609,40.38533,
"242.20",19.615,40.41866,
"242.40",19.622,40.452,
"242.60",19.628,40.48533,
"242.80",19.629,40.51867,
"242.85",19.627,40.527,