File: pristine_flourocarbon_10cm_10mmpm_2.csv
"Test Name","Test Mode","Test Type","Control","Test Speed 1","Test Speed 2","Test Speed 3","Change Point 1","Change Point 2","Disp. Origin","Break and Limit Action","Sensitivity:","Level:"
"","Single","Tensile","Stroke",10,1,1,"Off","Off","Start","Stop",0,1

"Title","Sub title","Comment"
"","",""

"Shape:","Batch Size:","SubBatch Size:"
"Plate",1,1
"Name:","Thickness","Width","Gauge Length",
"Size Unit:","mm","mm","mm",
" 1 - 1","1.0000","1.0000","100.0000",

"Name",
"Parameter",
"Units",
" 1 - 1",

" 1- 1"
"Time","Force","Stroke",
"sec","N","mm",
"0.00",-.002,0,
"0.15",-.001,2.766667E-02,
"0.30",.011,5.566667E-02,
"0.45",.038,8.333334E-02,
"0.60",.061,.111,
"0.75",.081,.139,
"0.90",.107,.167,
"1.05",.134,.1946667,
"1.20",.158,.2226667,
"1.35",.183,.2503333,
"1.50",.208,.278,
"1.65",.232,.306,
"1.80",.255,.334,
"1.95",.281,.3616667,
"2.10",.306,.3886667,
"2.25",.33,.4153333,
"2.40",.354,.442,
"2.55",.375,.4683333,
"2.70",.399,.4943333,
"2.85",.42,.5203333,
"3.00",.442,.5463333,
"3.15",.465,.572,
"3.30",.487,.5976667,
"3.45",.51,.6233333,
"3.60",.531,.6486667,
"3.75",.553,.674,
"3.90",.573,.6993333,
"4.05",.595,.7246667,
"4.20",.618,.75,
"4.35",.64,.775,
"4.50",.658,.8003333,
"4.65",.68,.8256667,
"4.80",.701,.8506666,
"4.95",.718,.8756667,
"5.10",.739,.9006667,
"5.25",.758,.926,
"5.40",.78,.951,
"5.55",.8,.976,
"5.70",.819,1.001,
"5.85",.838,1.026,
"6.00",.855,1.051,
"6.15",.874,1.076,
"6.30",.896,1.101333,
"6.45",.915,1.126333,
"6.60",.933,1.151333,
"6.75",.95,1.176333,
"6.90",.971,1.201333,
"7.05",.989,1.226333,
"7.20",1.007,1.251333,
"7.35",1.023,1.276333,
"7.50",1.038,1.301333,
"7.65",1.056,1.326333,
"7.80",1.075,1.351333,
"7.95",1.093,1.376333,
"8.10",1.108,1.401333,
"8.25",1.125,1.426333,
"8.40",1.144,1.451333,
"8.55",1.162,1.476333,
"8.70",1.178,1.501333,
"8.85",1.194,1.526333,
"9.00",1.212,1.551333,
"9.15",1.225,1.576333,
"9.30",1.241,1.601333,
"9.45",1.256,1.626333,
"9.60",1.268,1.651333,
"9.75",1.287,1.676333,
"9.90",1.303,1.701333,
"10.05",1.313,1.726333,
"10.20",1.329,1.751333,
"10.35",1.345,1.776333,
"10.50",1.36,1.801333,
"10.65",1.372,1.826333,
"10.80",1.386,1.851333,
"10.95",1.399,1.876333,
"11.10",1.415,1.901333,
"11.25",1.429,1.926333,
"11.40",1.439,1.951333,
"11.55",1.455,1.976333,
"11.70",1.469,2.001333,
"11.85",1.48,2.026333,
"12.00",1.494,2.051333,
"12.15",1.506,2.076333,
"12.30",1.518,2.101333,
"12.45",1.528,2.126333,
"12.60",1.543,2.151333,
"12.75",1.556,2.176333,
"12.90",1.571,2.201,
"13.05",1.583,2.226333,
"13.20",1.592,2.251333,
"13.35",1.605,2.276333,
"13.50",1.618,2.301333,
"13.65",1.629,2.326333,
"13.80",1.641,2.351333,
"13.95",1.656,2.376333,
"14.10",1.668,2.401333,
"14.25",1.677,2.426333,
"14.40",1.689,2.451333,
"14.55",1.7,2.476333,
"14.70",1.71,2.501333,
"14.85",1.72,2.526,
"15.00",1.732,2.551,
"15.15",1.743,2.576,
"15.30",1.757,2.601333,
"15.45",1.765,2.626333,
"15.60",1.774,2.651333,
"15.75",1.786,2.676333,
"15.90",1.799,2.701333,
"16.05",1.808,2.726333,
"16.20",1.82,2.751333,
"16.35",1.832,2.776333,
"16.50",1.844,2.801333,
"16.65",1.854,2.826333,
"16.80",1.864,2.851333,
"16.95",1.878,2.876333,
"17.10",1.887,2.901333,
"17.25",1.898,2.926333,
"17.40",1.907,2.951333,
"17.55",1.917,2.976333,
"17.70",1.929,3.001,
"17.85",1.941,3.026,
"18.00",1.951,3.051333,
"18.15",1.961,3.076333,
"18.30",1.973,3.101333,
"18.45",1.982,3.126333,
"18.60",1.993,3.151333,
"18.75",2.004,3.176333,
"18.90",2.016,3.201,
"19.05",2.026,3.226333,
"19.20",2.037,3.251333,
"19.35",2.047,3.276333,
"19.50",2.058,3.301333,
"19.65",2.07,3.326333,
"19.80",2.081,3.351333,
"19.95",2.092,3.376333,
"20.10",2.102,3.401333,
"20.25",2.11,3.426333,
"20.40",2.122,3.451333,
"20.55",2.134,3.476333,
"20.70",2.146,3.501333,
"20.85",2.156,3.526333,
"21.00",2.167,3.551333,
"21.15",2.176,3.576333,
"21.30",2.188,3.601333,
"21.45",2.199,3.626333,
"21.60",2.21,3.651333,
"21.75",2.22,3.676333,
"21.90",2.232,3.701333,
"22.05",2.242,3.726333,
"22.20",2.252,3.751333,
"22.35",2.264,3.776333,
"22.50",2.274,3.801333,
"22.65",2.283,3.826333,
"22.80",2.293,3.851333,
"22.95",2.306,3.876333,
"23.10",2.317,3.901333,
"23.25",2.325,3.926667,
"23.40",2.336,3.951667,
"23.55",2.35,3.976667,
"23.70",2.358,4.001667,
"23.85",2.37,4.026333,
"24.00",2.38,4.051333,
"24.15",2.391,4.076667,
"24.30",2.403,4.101666,
"24.45",2.415,4.126667,
"24.60",2.426,4.151667,
"24.75",2.434,4.176667,
"24.90",2.447,4.201334,
"25.05",2.459,4.226333,
"25.20",2.467,4.251333,
"25.35",2.478,4.276333,
"25.50",2.488,4.301333,
"25.65",2.5,4.326334,
"25.80",2.514,4.351333,
"25.95",2.525,4.376333,
"26.10",2.537,4.401667,
"26.25",2.548,4.426667,
"26.40",2.556,4.451334,
"26.55",2.568,4.476333,
"26.70",2.579,4.501333,
"26.85",2.591,4.526333,
"27.00",2.603,4.551667,
"27.15",2.614,4.576667,
"27.30",2.63,4.601666,
"27.45",2.641,4.626667,
"27.60",2.65,4.651667,
"27.75",2.666,4.676667,
"27.90",2.676,4.701667,
"28.05",2.689,4.726666,
"28.20",2.702,4.751333,
"28.35",2.712,4.776333,
"28.50",2.726,4.801333,
"28.65",2.734,4.826667,
"28.80",2.747,4.851666,
"28.95",2.761,4.876333,
"29.10",2.774,4.901333,
"29.25",2.786,4.926333,
"29.40",2.796,4.951667,
"29.55",2.81,4.976333,
"29.70",2.824,5.001667,
"29.85",2.836,5.026667,
"30.00",2.848,5.051667,
"30.15",2.862,5.076667,
"30.30",2.875,5.101666,
"30.45",2.886,5.126667,
"30.60",2.898,5.151667,
"30.75",2.911,5.176667,
"30.90",2.926,5.201334,
"31.05",2.936,5.226666,
"31.20",2.948,5.251667,
"31.35",2.961,5.276667,
"31.50",2.976,5.301667,
"31.65",2.989,5.326667,
"31.80",3.002,5.351666,
"31.95",3.016,5.376333,
"32.10",3.027,5.401667,
"32.25",3.038,5.426333,
"32.40",3.053,5.451334,
"32.55",3.064,5.476666,
"32.70",3.079,5.501667,
"32.85",3.092,5.526667,
"33.00",3.102,5.551667,
"33.15",3.115,5.576667,
"33.30",3.131,5.601666,
"33.45",3.144,5.626333,
"33.60",3.154,5.651667,
"33.75",3.167,5.676333,
"33.90",3.18,5.701334,
"34.05",3.195,5.726333,
"34.20",3.207,5.751333,
"34.35",3.218,5.776333,
"34.50",3.233,5.801333,
"34.65",3.246,5.826334,
"34.80",3.257,5.851333,
"34.95",3.271,5.876333,
"35.10",3.286,5.901333,
"35.25",3.303,5.926333,
"35.40",3.313,5.951334,
"35.55",3.327,5.976333,
"35.70",3.339,6.001333,
"35.85",3.353,6.026333,
"36.00",3.37,6.051333,
"36.15",3.382,6.076334,
"36.30",3.397,6.101333,
"36.45",3.408,6.126333,
"36.60",3.419,6.151333,
"36.75",3.433,6.176333,
"36.90",3.449,6.201334,
"37.05",3.461,6.226333,
"37.20",3.475,6.251667,
"37.35",3.492,6.276333,
"37.50",3.505,6.301333,
"37.65",3.518,6.326334,
"37.80",3.532,6.351333,
"37.95",3.547,6.376333,
"38.10",3.561,6.401333,
"38.25",3.575,6.426333,
"38.40",3.587,6.451334,
"38.55",3.601,6.476333,
"38.70",3.618,6.501667,
"38.85",3.633,6.526333,
"39.00",3.645,6.551333,
"39.15",3.657,6.576334,
"39.30",3.673,6.601333,
"39.45",3.687,6.626333,
"39.60",3.7,6.651333,
"39.75",3.714,6.676333,
"39.90",3.731,6.701334,
"40.05",3.744,6.726333,
"40.20",3.758,6.751333,
"40.35",3.771,6.776333,
"40.50",3.786,6.801333,
"40.65",3.802,6.826667,
"40.80",3.818,6.851333,
"40.95",3.831,6.876333,
"41.10",3.846,6.901333,
"41.25",3.863,6.926333,
"41.40",3.877,6.951334,
"41.55",3.893,6.976666,
"41.70",3.909,7.001333,
"41.85",3.924,7.026333,
"42.00",3.936,7.051333,
"42.15",3.955,7.076334,
"42.30",3.97,7.101333,
"42.45",3.982,7.126333,
"42.60",3.996,7.151333,
"42.75",4.013,7.176333,
"42.90",4.028,7.201334,
"43.05",4.044,7.226333,
"43.20",4.061,7.251333,
"43.35",4.076,7.276333,
"43.50",4.09,7.301333,
"43.65",4.105,7.326334,
"43.80",4.12,7.351333,
"43.95",4.138,7.376333,
"44.10",4.153,7.401333,
"44.25",4.167,7.426333,
"44.40",4.183,7.451334,
"44.55",4.199,7.476333,
"44.70",4.214,7.501333,
"44.85",4.232,7.526333,
"45.00",4.245,7.551333,
"45.15",4.26,7.576334,
"45.30",4.278,7.601333,
"45.45",4.294,7.626333,
"45.60",4.308,7.651667,
"45.75",4.326,7.676333,
"45.90",4.34,7.701334,
"46.05",4.358,7.726333,
"46.20",4.372,7.751333,
"46.35",4.388,7.776333,
"46.50",4.407,7.801333,
"46.65",4.423,7.826334,
"46.80",4.439,7.851333,
"46.95",4.453,7.876333,
"47.10",4.47,7.901333,
"47.25",4.486,7.926333,
"47.40",4.502,7.951334,
"47.55",4.516,7.976333,
"47.70",4.532,8.001333,
"47.85",4.551,8.026334,
"48.00",4.564,8.051333,
"48.15",4.581,8.076333,
"48.30",4.597,8.101334,
"48.45",4.613,8.126667,
"48.60",4.632,8.151667,
"48.75",4.647,8.176666,
"48.90",4.664,8.201333,
"49.05",4.684,8.226666,
"49.20",4.699,8.251333,
"49.35",4.715,8.276334,
"49.50",4.73,8.301666,
"49.65",4.747,8.326333,
"49.80",4.765,8.351334,
"49.95",4.78,8.376333,
"50.10",4.798,8.401334,
"50.25",4.814,8.426333,
"50.40",4.83,8.451333,
"50.55",4.849,8.476334,
"50.70",4.866,8.501333,
"50.85",4.883,8.526334,
"51.00",4.902,8.551333,
"51.15",4.921,8.576333,
"51.30",4.937,8.601334,
"51.45",4.952,8.626333,
"51.60",4.972,8.651334,
"51.75",4.989,8.676333,
"51.90",5.01,8.701333,
"52.05",5.025,8.726334,
"52.20",5.041,8.751333,
"52.35",5.06,8.776334,
"52.50",5.08,8.801333,
"52.65",5.094,8.826333,
"52.80",5.112,8.851334,
"52.95",5.134,8.876333,
"53.10",5.154,8.901334,
"53.25",5.17,8.926333,
"53.40",5.186,8.951333,
"53.55",5.204,8.976334,
"53.70",5.225,9.001333,
"53.85",5.245,9.026334,
"54.00",5.263,9.051333,
"54.15",5.283,9.076333,
"54.30",5.302,9.101334,
"54.45",5.32,9.126333,
"54.60",5.34,9.151334,
"54.75",5.358,9.176333,
"54.90",5.378,9.201333,
"55.05",5.399,9.226334,
"55.20",5.417,9.251333,
"55.35",5.437,9.276334,
"55.50",5.453,9.301333,
"55.65",5.474,9.326333,
"55.80",5.495,9.351334,
"55.95",5.515,9.376333,
"56.10",5.534,9.401334,
"56.25",5.552,9.426333,
"56.40",5.575,9.451333,
"56.55",5.591,9.476334,
"56.70",5.609,9.501333,
"56.85",5.63,9.526334,
"57.00",5.65,9.551333,
"57.15",5.669,9.576333,
"57.30",5.687,9.601334,
"57.45",5.706,9.626333,
"57.60",5.727,9.651334,
"57.75",5.748,9.676333,
"57.90",5.765,9.701333,
"58.05",5.787,9.726334,
"58.20",5.806,9.751333,
"58.35",5.826,9.776334,
"58.50",5.846,9.801333,
"58.65",5.862,9.826333,
"58.80",5.884,9.851334,
"58.95",5.907,9.876333,
"59.10",5.929,9.901334,
"59.25",5.949,9.926333,
"59.40",5.969,9.951333,
"59.55",5.987,9.976334,
"59.70",6.01,10.00133,
"59.85",6.033,10.02633,
"60.00",6.052,10.05133,
"60.15",6.071,10.07633,
"60.30",6.094,10.10133,
"60.45",6.114,10.12633,
"60.60",6.135,10.15133,
"60.75",6.155,10.17633,
"60.90",6.179,10.20133,
"61.05",6.202,10.22633,
"61.20",6.221,10.25133,
"61.35",6.241,10.27633,
"61.50",6.263,10.30133,
"61.65",6.284,10.32633,
"61.80",6.306,10.35133,
"61.95",6.33,10.37633,
"62.10",6.351,10.40133,
"62.25",6.373,10.42633,
"62.40",6.395,10.45133,
"62.55",6.416,10.47633,
"62.70",6.436,10.50133,
"62.85",6.458,10.52633,
"63.00",6.482,10.55133,
"63.15",6.505,10.57633,
"63.30",6.525,10.60133,
"63.45",6.545,10.62633,
"63.60",6.567,10.65133,
"63.75",6.587,10.67633,
"63.90",6.612,10.70133,
"64.05",6.633,10.72667,
"64.20",6.653,10.75133,
"64.35",6.675,10.77633,
"64.50",6.698,10.80133,
"64.65",6.719,10.82633,
"64.80",6.742,10.85133,
"64.95",6.764,10.87633,
"65.10",6.785,10.90133,
"65.25",6.807,10.92633,
"65.40",6.831,10.95167,
"65.55",6.853,10.97667,
"65.70",6.874,11.00133,
"65.85",6.897,11.02633,
"66.00",6.92,11.05133,
"66.15",6.941,11.07633,
"66.30",6.961,11.10133,
"66.45",6.982,11.12633,
"66.60",7.007,11.15133,
"66.75",7.031,11.17633,
"66.90",7.051,11.20133,
"67.05",7.076,11.22633,
"67.20",7.097,11.25133,
"67.35",7.118,11.27633,
"67.50",7.141,11.30133,
"67.65",7.161,11.32633,
"67.80",7.183,11.35133,
"67.95",7.208,11.37633,
"68.10",7.231,11.40133,
"68.25",7.254,11.42633,
"68.40",7.275,11.45133,
"68.55",7.298,11.47633,
"68.70",7.322,11.50133,
"68.85",7.348,11.52633,
"69.00",7.371,11.55133,
"69.15",7.394,11.57633,
"69.30",7.416,11.60133,
"69.45",7.438,11.62633,
"69.60",7.463,11.65133,
"69.75",7.488,11.67633,
"69.90",7.512,11.70133,
"70.05",7.535,11.72667,
"70.20",7.558,11.75133,
"70.35",7.582,11.77633,
"70.50",7.606,11.80133,
"70.65",7.631,11.82633,
"70.80",7.655,11.85133,
"70.95",7.679,11.87633,
"71.10",7.705,11.90167,
"71.25",7.726,11.92633,
"71.40",7.749,11.95133,
"71.55",7.773,11.97633,
"71.70",7.801,12.00133,
"71.85",7.825,12.02633,
"72.00",7.851,12.05133,
"72.15",7.873,12.07633,
"72.30",7.899,12.10133,
"72.45",7.921,12.12633,
"72.60",7.948,12.15133,
"72.75",7.972,12.17633,
"72.90",7.998,12.20133,
"73.05",8.023,12.22633,
"73.20",8.047,12.25167,
"73.35",8.073,12.27667,
"73.50",8.097,12.30167,
"73.65",8.12,12.32667,
"73.80",8.145,12.35133,
"73.95",8.172,12.37633,
"74.10",8.2,12.40133,
"74.25",8.221,12.42633,
"74.40",8.245,12.45133,
"74.55",8.27,12.47633,
"74.70",8.296,12.50133,
"74.85",8.32,12.52633,
"75.00",8.345,12.55133,
"75.15",8.371,12.57633,
"75.30",8.394,12.60133,
"75.45",8.417,12.62633,
"75.60",8.444,12.65133,
"75.75",8.473,12.67667,
"75.90",8.497,12.70133,
"76.05",8.524,12.72633,
"76.20",8.552,12.75133,
"76.35",8.577,12.77633,
"76.50",8.602,12.80133,
"76.65",8.63,12.82633,
"76.80",8.659,12.85133,
"76.95",8.688,12.87633,
"77.10",8.712,12.90133,
"77.25",8.74,12.92633,
"77.40",8.764,12.95167,
"77.55",8.792,12.97667,
"77.70",8.821,13.00133,
"77.85",8.848,13.02633,
"78.00",8.876,13.05133,
"78.15",8.904,13.07633,
"78.30",8.93,13.10133,
"78.45",8.955,13.12633,
"78.60",8.983,13.15133,
"78.75",9.011,13.17633,
"78.90",9.037,13.20133,
"79.05",9.064,13.22633,
"79.20",9.092,13.25133,
"79.35",9.118,13.27633,
"79.50",9.144,13.30133,
"79.65",9.171,13.32667,
"79.80",9.199,13.35133,
"79.95",9.227,13.37633,
"80.10",9.256,13.40133,
"80.25",9.285,13.42633,
"80.40",9.311,13.45133,
"80.55",9.339,13.47633,
"80.70",9.368,13.50133,
"80.85",9.396,13.52633,
"81.00",9.424,13.55133,
"81.15",9.452,13.57633,
"81.30",9.478,13.60133,
"81.45",9.507,13.62633,
"81.60",9.533,13.65133,
"81.75",9.566,13.67633,
"81.90",9.593,13.70133,
"82.05",9.622,13.72633,
"82.20",9.65,13.75133,
"82.35",9.677,13.77633,
"82.50",9.704,13.80133,
"82.65",9.733,13.82633,
"82.80",9.761,13.85133,
"82.95",9.794,13.87633,
"83.10",9.825,13.90133,
"83.25",9.851,13.92633,
"83.40",9.877,13.95167,
"83.55",9.909,13.97667,
"83.70",9.936,14.00167,
"83.85",9.965,14.02633,
"84.00",9.995,14.05133,
"84.15",10.028,14.07633,
"84.30",10.052,14.10167,
"84.45",10.082,14.12667,
"84.60",10.11,14.15167,
"84.75",10.139,14.17667,
"84.90",10.169,14.20133,
"85.05",10.199,14.22633,
"85.20",10.228,14.25133,
"85.35",10.257,14.27633,
"85.50",10.284,14.30133,
"85.65",10.314,14.32667,
"85.80",10.347,14.35133,
"85.95",10.373,14.37633,
"86.10",10.402,14.40133,
"86.25",10.428,14.42633,
"86.40",10.456,14.45133,
"86.55",10.486,14.47633,
"86.70",10.515,14.50133,
"86.85",10.547,14.52633,
"87.00",10.575,14.55133,
"87.15",10.604,14.57633,
"87.30",10.632,14.60133,
"87.45",10.66,14.62633,
"87.60",10.69,14.65133,
"87.75",10.719,14.67633,
"87.90",10.752,14.70133,
"88.05",10.782,14.72633,
"88.20",10.812,14.751,
"88.35",10.84,14.776,
"88.50",10.866,14.80133,
"88.65",10.895,14.826,
"88.80",10.923,14.851,
"88.95",10.954,14.876,
"89.10",10.986,14.901,
"89.25",11.015,14.92633,
"89.40",11.043,14.95133,
"89.55",11.069,14.97633,
"89.70",11.097,15.00133,
"89.85",11.128,15.02633,
"90.00",11.156,15.05133,
"90.15",11.186,15.07633,
"90.30",11.214,15.10133,
"90.45",11.244,15.126,
"90.60",11.273,15.15133,
"90.75",11.304,15.17633,
"90.90",11.333,15.201,
"91.05",11.363,15.226,
"91.20",11.393,15.25133,
"91.35",11.422,15.27633,
"91.50",11.452,15.30133,
"91.65",11.481,15.32633,
"91.80",11.514,15.35133,
"91.95",11.546,15.376,
"92.10",11.578,15.40133,
"92.25",11.606,15.42633,
"92.40",11.636,15.45133,
"92.55",11.665,15.47633,
"92.70",11.698,15.50133,
"92.85",11.733,15.52633,
"93.00",11.766,15.55133,
"93.15",11.796,15.57633,
"93.30",11.829,15.60133,
"93.45",11.859,15.62633,
"93.60",11.89,15.65133,
"93.75",11.919,15.67633,
"93.90",11.955,15.70133,
"94.05",11.988,15.72633,
"94.20",12.024,15.75133,
"94.35",12.054,15.77633,
"94.50",12.086,15.80133,
"94.65",12.117,15.82633,
"94.80",12.152,15.85133,
"94.95",12.185,15.876,
"95.10",12.22,15.90133,
"95.25",12.251,15.92633,
"95.40",12.281,15.951,
"95.55",12.315,15.97633,
"95.70",12.352,16.00133,
"95.85",12.385,16.026,
"96.00",12.423,16.05133,
"96.15",12.456,16.07633,
"96.30",12.487,16.10133,
"96.45",12.52,16.12633,
"96.60",12.554,16.15133,
"96.75",12.589,16.17633,
"96.90",12.621,16.20133,
"97.05",12.657,16.22633,
"97.20",12.69,16.25133,
"97.35",12.721,16.27633,
"97.50",12.751,16.30133,
"97.65",12.787,16.32633,
"97.80",12.823,16.35133,
"97.95",12.861,16.376,
"98.10",12.897,16.40133,
"98.25",12.932,16.42633,
"98.40",12.969,16.45133,
"98.55",13.001,16.47633,
"98.70",13.033,16.50133,
"98.85",13.07,16.52633,
"99.00",13.107,16.55133,
"99.15",13.144,16.57633,
"99.30",13.179,16.60133,
"99.45",13.213,16.62633,
"99.60",13.251,16.65133,
"99.75",13.286,16.67633,
"99.90",13.321,16.70133,
"100.05",13.356,16.72633,
"100.20",13.393,16.75133,
"100.35",13.428,16.77667,
"100.50",13.465,16.80167,
"100.65",13.5,16.82667,
"100.80",13.539,16.85167,
"100.95",13.578,16.87633,
"101.10",13.617,16.90133,
"101.25",13.652,16.92667,
"101.40",13.686,16.95133,
"101.55",13.721,16.97667,
"101.70",13.759,17.00167,
"101.85",13.796,17.02667,
"102.00",13.834,17.05167,
"102.15",13.872,17.07667,
"102.30",13.903,17.10167,
"102.45",13.937,17.12667,
"102.60",13.975,17.15133,
"102.75",14.012,17.17633,
"102.90",14.048,17.20133,
"103.05",14.088,17.22667,
"103.20",14.126,17.25133,
"103.35",14.163,17.27633,
"103.50",14.195,17.30133,
"103.65",14.233,17.32667,
"103.80",14.267,17.35133,
"103.95",14.305,17.37633,
"104.10",14.339,17.40167,
"104.25",14.376,17.42667,
"104.40",14.414,17.45167,
"104.55",14.447,17.47667,
"104.70",14.479,17.50133,
"104.85",14.516,17.52633,
"105.00",14.552,17.55133,
"105.15",14.586,17.57633,
"105.30",14.618,17.60167,
"105.45",14.651,17.62633,
"105.60",14.687,17.65133,
"105.75",14.724,17.67633,
"105.90",14.757,17.70133,
"106.05",14.793,17.72633,
"106.20",14.824,17.75133,
"106.35",14.859,17.77633,
"106.50",14.893,17.80133,
"106.65",14.928,17.82633,
"106.80",14.966,17.85133,
"106.95",15.003,17.87633,
"107.10",15.041,17.90133,
"107.25",15.073,17.92633,
"107.40",15.105,17.95133,
"107.55",15.141,17.97633,
"107.70",15.179,18.00133,
"107.85",15.216,18.02633,
"108.00",15.252,18.05133,
"108.15",15.292,18.07633,
"108.30",15.324,18.10133,
"108.45",15.364,18.12633,
"108.60",15.4,18.15133,
"108.75",15.437,18.17633,
"108.90",15.474,18.20133,
"109.05",15.517,18.22633,
"109.20",15.555,18.25133,
"109.35",15.593,18.27633,
"109.50",15.629,18.30133,
"109.65",15.666,18.32633,
"109.80",15.707,18.35133,
"109.95",15.744,18.37633,
"110.10",15.785,18.40133,
"110.25",15.824,18.42633,
"110.40",15.86,18.45133,
"110.55",15.897,18.47633,
"110.70",15.938,18.50133,
"110.85",15.978,18.52633,
"111.00",16.015,18.55133,
"111.15",16.053,18.57633,
"111.30",16.087,18.60133,
"111.45",16.13,18.62633,
"111.60",16.17,18.65133,
"111.75",16.208,18.67633,
"111.90",16.245,18.70133,
"112.05",16.285,18.72633,
"112.20",16.319,18.75133,
"112.35",16.357,18.77633,
"112.50",16.392,18.80133,
"112.65",16.432,18.82633,
"112.80",16.468,18.85133,
"112.95",16.509,18.87633,
"113.10",16.545,18.90133,
"113.25",16.581,18.92633,
"113.40",16.616,18.95133,
"113.55",16.655,18.97633,
"113.70",16.691,19.00133,
"113.85",16.727,19.02633,
"114.00",16.768,19.05133,
"114.15",16.806,19.07633,
"114.30",16.843,19.10133,
"114.45",16.878,19.12633,
"114.60",16.914,19.15167,
"114.75",16.952,19.17667,
"114.90",16.989,19.20133,
"115.05",17.028,19.22667,
"115.20",17.068,19.25167,
"115.35",17.105,19.27667,
"115.50",17.141,19.30167,
"115.65",17.177,19.32667,
"115.80",17.218,19.35167,
"115.95",17.258,19.37633,
"116.10",17.294,19.40167,
"116.25",17.331,19.42667,
"116.40",17.37,19.45167,
"116.55",17.405,19.47667,
"116.70",17.444,19.50167,
"116.85",17.485,19.52633,
"117.00",17.527,19.55133,
"117.15",17.564,19.57633,
"117.30",17.6,19.60133,
"117.45",17.633,19.62633,
"117.60",17.669,19.65133,
"117.75",17.71,19.67633,
"117.90",17.749,19.70133,
"118.05",17.79,19.72633,
"118.20",17.823,19.75133,
"118.35",17.862,19.77633,
"118.50",17.896,19.80133,
"118.65",17.935,19.82633,
"118.80",17.971,19.85133,
"118.95",18.012,19.87633,
"119.10",18.048,19.90133,
"119.25",18.085,19.92633,
"119.40",18.122,19.95167,
"119.55",18.158,19.97667,
"119.70",18.195,20.00167,
"119.85",18.231,20.02633,
"120.00",18.266,20.05167,
"120.15",18.302,20.07667,
"120.30",18.337,20.10133,
"120.45",18.373,20.12633,
"120.60",18.41,20.15133,
"120.75",18.444,20.17633,
"120.90",18.485,20.20133,
"121.05",18.52,20.22633,
"121.20",18.553,20.25133,
"121.35",18.585,20.27633,
"121.50",18.625,20.30133,
"121.65",18.657,20.32633,
"121.80",18.694,20.35133,
"121.95",18.729,20.37633,
"122.10",18.765,20.40133,
"122.25",18.798,20.42633,
"122.40",18.83,20.45133,
"122.55",18.861,20.47633,
"122.70",18.896,20.50133,
"122.85",18.932,20.52633,
"123.00",18.968,20.55133,
"123.15",18.999,20.57633,
"123.30",19.033,20.60133,
"123.45",19.064,20.62633,
"123.60",19.098,20.65167,
"123.75",19.13,20.67667,
"123.90",19.168,20.70167,
"124.05",19.206,20.72667,
"124.20",19.238,20.75133,
"124.35",19.269,20.77633,
"124.50",19.304,20.80133,
"124.65",19.34,20.82633,
"124.80",19.373,20.85167,
"124.95",19.406,20.87633,
"125.10",19.442,20.90133,
"125.25",19.476,20.92633,
"125.40",19.505,20.95133,
"125.55",19.542,20.97667,
"125.70",19.576,21.00133,
"125.85",19.613,21.02633,
"126.00",19.645,21.05133,
"126.15",19.68,21.07633,
"126.30",19.712,21.10133,
"126.45",19.744,21.12633,
"126.60",19.777,21.15133,
"126.75",19.813,21.17633,
"126.90",19.848,21.20133,
"127.05",19.883,21.22633,
"127.20",19.92,21.25167,
"127.35",19.949,21.27667,
"127.50",19.982,21.30167,
"127.65",20.016,21.32667,
"127.80",20.051,21.35167,
"127.95",20.084,21.37633,
"128.10",20.122,21.40167,
"128.25",20.154,21.42667,
"128.40",20.183,21.45133,
"128.55",20.211,21.47667,
"128.70",20.243,21.50167,
"128.85",20.277,21.52633,
"129.00",20.311,21.55133,
"129.15",20.341,21.57633,
"129.30",20.369,21.60133,
"129.45",20.4,21.62633,
"129.60",20.43,21.65133,
"129.75",20.461,21.67633,
"129.90",20.491,21.70133,
"130.05",20.523,21.72633,
"130.20",20.554,21.75133,
"130.35",20.584,21.77633,
"130.50",20.611,21.80133,
"130.65",20.643,21.82633,
"130.80",20.67,21.85133,
"130.95",20.7,21.87633,
"131.10",20.731,21.90133,
"131.25",20.758,21.92633,
"131.40",20.787,21.95133,
"131.55",20.816,21.97633,
"131.70",20.843,22.00133,
"131.85",20.876,22.02633,
"132.00",20.907,22.05133,
"132.15",20.931,22.07633,
"132.30",20.951,22.10133,
"132.45",20.979,22.12633,
"132.60",21.005,22.15133,
"132.75",21.038,22.17633,
"132.90",21.068,22.20133,
"133.05",21.098,22.22633,
"133.20",21.127,22.25133,
"133.35",21.152,22.27667,
"133.50",21.178,22.30167,
"133.65",21.207,22.32667,
"133.80",21.236,22.35133,
"133.95",21.264,22.37633,
"134.10",21.291,22.40133,
"134.25",21.318,22.42633,
"134.40",21.343,22.45133,
"134.55",21.368,22.47633,
"134.70",21.393,22.50167,
"134.85",21.424,22.52667,
"135.00",21.45,22.55133,
"135.15",21.474,22.57633,
"135.30",21.499,22.60133,
"135.45",21.524,22.62633,
"135.60",21.551,22.65133,
"135.75",21.575,22.67633,
"135.90",21.601,22.70133,
"136.05",21.626,22.72633,
"136.20",21.646,22.75133,
"136.35",21.671,22.77633,
"136.50",21.693,22.80133,
"136.65",21.72,22.82633,
"136.80",21.743,22.85133,
"136.95",21.769,22.87633,
"137.10",21.792,22.90133,
"137.25",21.814,22.92633,
"137.40",21.835,22.95133,
"137.55",21.86,22.97633,
"137.70",21.882,23.00133,
"137.85",21.912,23.02633,
"138.00",21.941,23.05133,
"138.15",21.963,23.07633,
"138.30",21.986,23.10133,
"138.45",22.01,23.12633,
"138.60",22.034,23.15133,
"138.75",22.061,23.17633,
"138.90",22.087,23.20133,
"139.05",22.115,23.22633,
"139.20",22.139,23.25133,
"139.35",22.163,23.27633,
"139.50",22.186,23.30133,
"139.65",22.211,23.32633,
"139.80",22.234,23.35133,
"139.95",22.26,23.37633,
"140.10",22.283,23.40133,
"140.25",22.304,23.426,
"140.40",22.326,23.451,
"140.55",22.352,23.47633,
"140.70",22.38,23.50133,
"140.85",22.408,23.52633,
"141.00",22.431,23.55133,
"141.15",22.452,23.57633,
"141.30",22.475,23.60133,
"141.45",22.498,23.62633,
"141.60",22.527,23.65133,
"141.75",22.553,23.67633,
"141.90",22.575,23.70133,
"142.05",22.598,23.726,
"142.20",22.618,23.751,
"142.35",22.641,23.776,
"142.50",22.661,23.80133,
"142.65",22.681,23.82633,
"142.80",22.707,23.85133,
"142.95",22.735,23.876,
"143.10",22.756,23.90133,
"143.25",22.779,23.92633,
"143.40",22.798,23.95133,
"143.55",22.819,23.97633,
"143.70",22.843,24.00133,
"143.85",22.869,24.02633,
"144.00",22.894,24.05133,
"144.15",22.918,24.07633,
"144.30",22.935,24.10133,
"144.45",22.957,24.12633,
"144.60",22.977,24.15133,
"144.75",22.997,24.17633,
"144.90",23.024,24.20133,
"145.05",23.044,24.22633,
"145.20",23.064,24.25133,
"145.35",23.086,24.27633,
"145.50",23.105,24.30133,
"145.65",23.127,24.32633,
"145.80",23.156,24.35133,
"145.95",23.176,24.37633,
"146.10",23.195,24.40133,
"146.25",23.214,24.42633,
"146.40",23.235,24.45133,
"146.55",23.257,24.47633,
"146.70",23.279,24.50133,
"146.85",23.3,24.526,
"147.00",23.325,24.55133,
"147.15",23.344,24.57633,
"147.30",23.367,24.60133,
"147.45",23.389,24.62633,
"147.60",23.41,24.65133,
"147.75",23.429,24.67633,
"147.90",23.457,24.70133,
"148.05",23.483,24.72633,
"148.20",23.504,24.75133,
"148.35",23.523,24.776,
"148.50",23.549,24.80133,
"148.65",23.575,24.826,
"148.80",23.598,24.85133,
"148.95",23.622,24.876,
"149.10",23.649,24.901,
"149.25",23.672,24.926,
"149.40",23.693,24.95133,
"149.55",23.719,24.97633,
"149.70",23.744,25.00133,
"149.85",23.768,25.026,
"150.00",23.791,25.05133,
"150.15",23.814,25.07633,
"150.30",23.838,25.101,
"150.45",23.859,25.12633,
"150.60",23.881,25.15133,
"150.75",23.907,25.17633,
"150.90",23.934,25.20133,
"151.05",23.96,25.22633,
"151.20",23.98,25.25133,
"151.35",24,25.27633,
"151.50",24.02,25.301,
"151.65",24.04,25.32633,
"151.80",24.07,25.35133,
"151.95",24.09,25.37633,
"152.10",24.12,25.40133,
"152.25",24.14,25.426,
"152.40",24.16,25.451,
"152.55",24.18,25.47633,
"152.70",24.2,25.50133,
"152.85",24.22,25.526,
"153.00",24.25,25.551,
"153.15",24.27,25.576,
"153.30",24.29,25.601,
"153.45",24.31,25.626,
"153.60",24.33,25.651,
"153.75",24.35,25.67633,
"153.90",24.37,25.701,
"154.05",24.39,25.72633,
"154.20",24.42,25.75133,
"154.35",24.43,25.77633,
"154.50",24.45,25.80133,
"154.65",24.47,25.826,
"154.80",24.49,25.851,
"154.95",24.51,25.876,
"155.10",24.53,25.901,
"155.25",24.55,25.926,
"155.40",24.57,25.951,
"155.55",24.59,25.97633,
"155.70",24.61,26.00133,
"155.85",24.64,26.02633,
"156.00",24.66,26.05133,
"156.15",24.68,26.07633,
"156.30",24.7,26.10133,
"156.45",24.72,26.12633,
"156.60",24.74,26.15133,
"156.75",24.77,26.17633,
"156.90",24.8,26.201,
"157.05",24.82,26.226,
"157.20",24.84,26.251,
"157.35",24.86,26.27633,
"157.50",24.88,26.30133,
"157.65",24.9,26.32633,
"157.80",24.93,26.35133,
"157.95",24.95,26.37633,
"158.10",24.97,26.401,
"158.25",24.99,26.426,
"158.40",25.01,26.451,
"158.55",25.02,26.476,
"158.65",25.024,26.493,