File: load_extensions/pristine_monofilament2.csv
"Test Name","Test Mode","Test Type","Control","Test Speed 1","Test Speed 2","Test Speed 3","Change Point 1","Change Point 2","Disp. Origin","Break and Limit Action","Sensitivity:","Level:"
"","Single","Tensile","Stroke",10,1,1,"Off","Off","Start","Stop",0,1

"Title","Sub title","Comment"
"","",""

"Shape:","Batch Size:","SubBatch Size:"
"Plate",1,1
"Name:","Thickness","Width","Gauge Length",
"Size Unit:","mm","mm","mm",
" 1 - 1","1.0000","1.0000","100.0000",

"Name",
"Parameter",
"Units",
" 1 - 1",

" 1- 1"
"Time","Force","Stroke",
"sec","N","mm",
"0.00",.003,0,
"0.20",.002,3.566667E-02,
"0.40",.003,.073,
"0.60",.011,.11,
"0.80",.025,.1473333,
"1.00",.037,.1843333,
"1.20",.045,.2213333,
"1.40",.055,.2586667,
"1.60",.067,.2956667,
"1.80",.081,.3326667,
"2.00",.092,.3693333,
"2.20",.102,.4053333,
"2.40",.113,.4406667,
"2.60",.122,.476,
"2.80",.134,.5106667,
"3.00",.143,.5453333,
"3.20",.154,.5796667,
"3.40",.165,.6136667,
"3.60",.178,.6476667,
"3.80",.187,.6816667,
"4.00",.195,.7153333,
"4.20",.208,.749,
"4.40",.218,.7826667,
"4.60",.226,.8163334,
"4.80",.24,.8496667,
"5.00",.247,.8833333,
"5.20",.258,.9166667,
"5.40",.269,.95,
"5.60",.281,.9833333,
"5.80",.291,1.016667,
"6.00",.302,1.05,
"6.20",.313,1.083333,
"6.40",.324,1.116667,
"6.60",.334,1.150333,
"6.80",.346,1.183667,
"7.00",.354,1.217,
"7.20",.366,1.250333,
"7.40",.375,1.283667,
"7.60",.388,1.317,
"7.80",.398,1.350333,
"8.00",.409,1.383667,
"8.20",.421,1.417,
"8.40",.43,1.450333,
"8.60",.442,1.483667,
"8.80",.455,1.517,
"9.00",.468,1.550333,
"9.20",.478,1.583667,
"9.40",.488,1.617,
"9.60",.502,1.650333,
"9.80",.516,1.683667,
"10.00",.526,1.717,
"10.20",.532,1.750333,
"10.40",.546,1.783667,
"10.60",.56,1.817,
"10.80",.572,1.850333,
"11.00",.581,1.883667,
"11.20",.593,1.917,
"11.40",.605,1.950333,
"11.60",.618,1.983667,
"11.80",.627,2.017,
"12.00",.64,2.050333,
"12.20",.653,2.083667,
"12.40",.664,2.116667,
"12.60",.677,2.15,
"12.80",.691,2.183667,
"13.00",.706,2.217,
"13.20",.716,2.250333,
"13.40",.729,2.283667,
"13.60",.741,2.317,
"13.80",.753,2.350333,
"14.00",.767,2.383667,
"14.20",.78,2.417,
"14.40",.793,2.450333,
"14.60",.804,2.483667,
"14.80",.816,2.517,
"15.00",.831,2.550333,
"15.20",.845,2.583667,
"15.40",.857,2.617,
"15.60",.87,2.65,
"15.80",.883,2.683667,
"16.00",.899,2.716667,
"16.20",.914,2.750333,
"16.40",.927,2.783667,
"16.60",.939,2.817,
"16.80",.954,2.850333,
"17.00",.968,2.883667,
"17.20",.982,2.917,
"17.40",.996,2.950333,
"17.60",1.01,2.983667,
"17.80",1.024,3.017,
"18.00",1.041,3.050333,
"18.20",1.055,3.083667,
"18.40",1.069,3.117,
"18.60",1.085,3.150333,
"18.80",1.098,3.184,
"19.00",1.116,3.217333,
"19.20",1.131,3.250333,
"19.40",1.144,3.283667,
"19.60",1.16,3.317,
"19.80",1.176,3.350333,
"20.00",1.193,3.384,
"20.20",1.205,3.417333,
"20.40",1.224,3.450667,
"20.60",1.24,3.484,
"20.80",1.255,3.517333,
"21.00",1.275,3.550667,
"21.20",1.291,3.583667,
"21.40",1.305,3.617,
"21.60",1.321,3.650333,
"21.80",1.338,3.683667,
"22.00",1.353,3.717,
"22.20",1.373,3.750667,
"22.40",1.388,3.784,
"22.60",1.406,3.817333,
"22.80",1.425,3.850667,
"23.00",1.442,3.884,
"23.20",1.461,3.917333,
"23.40",1.479,3.950333,
"23.60",1.494,3.984,
"23.80",1.51,4.017,
"24.00",1.528,4.050333,
"24.20",1.546,4.083667,
"24.40",1.566,4.117,
"24.60",1.584,4.150333,
"24.80",1.603,4.183667,
"25.00",1.621,4.217,
"25.20",1.639,4.250333,
"25.40",1.662,4.283667,
"25.60",1.679,4.317,
"25.80",1.698,4.350333,
"26.00",1.718,4.383667,
"26.20",1.736,4.417,
"26.40",1.758,4.450333,
"26.60",1.778,4.483667,
"26.80",1.798,4.517,
"27.00",1.817,4.550333,
"27.20",1.838,4.583667,
"27.40",1.857,4.617,
"27.60",1.882,4.650333,
"27.80",1.902,4.683667,
"28.00",1.923,4.717333,
"28.20",1.945,4.750667,
"28.40",1.965,4.783667,
"28.60",1.989,4.817333,
"28.80",2.01,4.850667,
"29.00",2.033,4.884,
"29.20",2.054,4.917333,
"29.40",2.076,4.950333,
"29.60",2.095,4.983667,
"29.80",2.121,5.017,
"30.00",2.143,5.050333,
"30.20",2.167,5.083667,
"30.40",2.189,5.117,
"30.60",2.211,5.150333,
"30.80",2.232,5.183667,
"31.00",2.257,5.217333,
"31.20",2.281,5.250667,
"31.40",2.306,5.283667,
"31.60",2.332,5.317333,
"31.80",2.353,5.350333,
"32.00",2.382,5.383667,
"32.20",2.406,5.417,
"32.40",2.43,5.450333,
"32.60",2.455,5.483667,
"32.80",2.481,5.517334,
"33.00",2.503,5.550333,
"33.20",2.532,5.583667,
"33.40",2.557,5.617,
"33.60",2.583,5.650333,
"33.80",2.608,5.683667,
"34.00",2.633,5.717,
"34.20",2.662,5.750333,
"34.40",2.686,5.783667,
"34.60",2.716,5.817,
"34.80",2.743,5.850667,
"35.00",2.771,5.884,
"35.20",2.798,5.917333,
"35.40",2.826,5.950667,
"35.60",2.855,5.983667,
"35.80",2.88,6.017,
"36.00",2.907,6.050333,
"36.20",2.936,6.084,
"36.40",2.963,6.117,
"36.60",2.993,6.150667,
"36.80",3.02,6.184,
"37.00",3.048,6.217333,
"37.20",3.074,6.250667,
"37.40",3.107,6.284,
"37.60",3.138,6.317,
"37.80",3.163,6.350333,
"38.00",3.194,6.383667,
"38.20",3.223,6.417,
"38.40",3.254,6.450333,
"38.60",3.285,6.484,
"38.80",3.314,6.517334,
"39.00",3.345,6.550667,
"39.20",3.375,6.584,
"39.40",3.404,6.617333,
"39.60",3.438,6.650667,
"39.80",3.468,6.684,
"40.00",3.496,6.717333,
"40.20",3.526,6.750667,
"40.40",3.559,6.783667,
"40.60",3.589,6.817333,
"40.80",3.621,6.850667,
"41.00",3.65,6.884,
"41.20",3.682,6.917,
"41.40",3.717,6.950333,
"41.60",3.749,6.983667,
"41.80",3.779,7.017,
"42.00",3.809,7.050333,
"42.20",3.84,7.083667,
"42.40",3.873,7.117,
"42.60",3.907,7.150333,
"42.80",3.938,7.183667,
"43.00",3.966,7.217,
"43.20",4.002,7.250667,
"43.40",4.036,7.283667,
"43.60",4.065,7.317,
"43.80",4.099,7.350333,
"44.00",4.128,7.383667,
"44.20",4.164,7.417,
"44.40",4.199,7.450333,
"44.60",4.231,7.483667,
"44.80",4.262,7.517,
"45.00",4.291,7.550333,
"45.20",4.325,7.583667,
"45.40",4.357,7.617,
"45.60",4.39,7.650333,
"45.80",4.421,7.683667,
"46.00",4.452,7.717,
"46.20",4.486,7.750333,
"46.40",4.515,7.783667,
"46.60",4.554,7.817,
"46.80",4.583,7.850333,
"47.00",4.618,7.884,
"47.20",4.65,7.917333,
"47.40",4.678,7.950333,
"47.60",4.701,7.983667,
"47.80",4.732,8.017,
"48.00",4.764,8.050333,
"48.20",4.799,8.084,
"48.40",4.83,8.117,
"48.60",4.863,8.150333,
"48.80",4.895,8.183666,
"49.00",4.929,8.217,
"49.20",4.96,8.250334,
"49.40",4.993,8.283667,
"49.60",5.026,8.317,
"49.80",5.059,8.350333,
"50.00",5.089,8.383667,
"50.20",5.118,8.417,
"50.40",5.151,8.450334,
"50.60",5.182,8.483666,
"50.80",5.214,8.517,
"51.00",5.242,8.550333,
"51.20",5.273,8.583667,
"51.40",5.301,8.617,
"51.60",5.337,8.650333,
"51.80",5.366,8.683666,
"52.00",5.396,8.717,
"52.20",5.425,8.750334,
"52.40",5.455,8.783667,
"52.60",5.486,8.817,
"52.80",5.513,8.850667,
"53.00",5.548,8.883667,
"53.20",5.574,8.917,
"53.40",5.603,8.950334,
"53.60",5.634,8.983666,
"53.80",5.663,9.017,
"54.00",5.688,9.050333,
"54.20",5.72,9.084,
"54.40",5.75,9.117,
"54.60",5.778,9.150333,
"54.80",5.808,9.183666,
"55.00",5.833,9.217334,
"55.20",5.863,9.250334,
"55.40",5.895,9.283667,
"55.60",5.922,9.317,
"55.80",5.949,9.350333,
"56.00",5.98,9.383667,
"56.20",6.006,9.417,
"56.40",6.036,9.450334,
"56.60",6.064,9.483666,
"56.80",6.092,9.517333,
"57.00",6.118,9.550333,
"57.20",6.145,9.583667,
"57.40",6.172,9.617,
"57.60",6.201,9.650666,
"57.80",6.227,9.684,
"58.00",6.258,9.717334,
"58.20",6.284,9.750667,
"58.40",6.312,9.784,
"58.60",6.34,9.817333,
"58.80",6.368,9.850667,
"59.00",6.393,9.883667,
"59.20",6.42,9.917334,
"59.40",6.448,9.950666,
"59.60",6.476,9.984,
"59.80",6.499,10.017,
"60.00",6.526,10.05033,
"60.20",6.55,10.084,
"60.40",6.58,10.11733,
"60.60",6.604,10.15067,
"60.80",6.633,10.184,
"61.00",6.658,10.21733,
"61.20",6.681,10.25067,
"61.40",6.708,10.28367,
"61.60",6.736,10.317,
"61.80",6.762,10.35067,
"62.00",6.785,10.38367,
"62.20",6.814,10.41733,
"62.40",6.84,10.45033,
"62.60",6.87,10.484,
"62.80",6.893,10.51733,
"63.00",6.921,10.55067,
"63.20",6.946,10.58367,
"63.40",6.975,10.61733,
"63.60",6.999,10.65067,
"63.80",7.028,10.684,
"64.00",7.053,10.71733,
"64.20",7.079,10.75033,
"64.40",7.106,10.78367,
"64.60",7.131,10.81733,
"64.80",7.159,10.85033,
"65.00",7.183,10.88367,
"65.20",7.209,10.917,
"65.40",7.234,10.95033,
"65.60",7.261,10.98367,
"65.80",7.288,11.01733,
"66.00",7.312,11.05067,
"66.20",7.338,11.08367,
"66.40",7.366,11.117,
"66.60",7.393,11.15033,
"66.80",7.415,11.18367,
"67.00",7.437,11.217,
"67.20",7.464,11.25067,
"67.40",7.488,11.28367,
"67.60",7.515,11.317,
"67.80",7.539,11.35033,
"68.00",7.562,11.38367,
"68.20",7.591,11.417,
"68.40",7.614,11.45033,
"68.60",7.639,11.48367,
"68.80",7.66,11.517,
"69.00",7.687,11.55033,
"69.20",7.709,11.584,
"69.40",7.736,11.617,
"69.60",7.76,11.65033,
"69.80",7.783,11.68367,
"70.00",7.804,11.717,
"70.20",7.83,11.75033,
"70.40",7.857,11.78367,
"70.60",7.88,11.817,
"70.80",7.902,11.85033,
"71.00",7.923,11.88367,
"71.20",7.945,11.91733,
"71.40",7.969,11.95033,
"71.60",7.991,11.98367,
"71.80",8.016,12.017,
"72.00",8.037,12.05067,
"72.20",8.057,12.084,
"72.40",8.083,12.117,
"72.60",8.103,12.15033,
"72.80",8.126,12.18367,
"73.00",8.148,12.217,
"73.20",8.173,12.25033,
"73.40",8.194,12.28367,
"73.60",8.219,12.317,
"73.80",8.24,12.35033,
"74.00",8.263,12.38367,
"74.20",8.284,12.41733,
"74.40",8.309,12.45033,
"74.60",8.333,12.48367,
"74.80",8.354,12.517,
"75.00",8.377,12.55033,
"75.20",8.401,12.58367,
"75.40",8.426,12.617,
"75.60",8.453,12.65033,
"75.80",8.476,12.68367,
"76.00",8.497,12.717,
"76.20",8.52,12.75033,
"76.40",8.545,12.78367,
"76.60",8.568,12.817,
"76.80",8.593,12.85067,
"77.00",8.613,12.884,
"77.20",8.636,12.91733,
"77.40",8.657,12.95033,
"77.60",8.678,12.98367,
"77.80",8.698,13.017,
"78.00",8.722,13.05033,
"78.20",8.743,13.08367,
"78.40",8.769,13.117,
"78.60",8.789,13.15033,
"78.80",8.809,13.18367,
"79.00",8.827,13.217,
"79.20",8.851,13.25067,
"79.40",8.871,13.284,
"79.60",8.891,13.31733,
"79.80",8.914,13.35067,
"80.00",8.935,13.38367,
"80.20",8.955,13.417,
"80.40",8.975,13.45033,
"80.60",8.998,13.48367,
"80.80",9.023,13.517,
"81.00",9.041,13.55033,
"81.20",9.066,13.58367,
"81.40",9.089,13.617,
"81.60",9.11,13.65033,
"81.80",9.133,13.68367,
"82.00",9.155,13.717,
"82.20",9.175,13.75033,
"82.40",9.197,13.78367,
"82.60",9.221,13.81733,
"82.80",9.241,13.85067,
"83.00",9.261,13.884,
"83.20",9.282,13.91733,
"83.40",9.306,13.95067,
"83.60",9.323,13.98367,
"83.80",9.347,14.017,
"84.00",9.373,14.05067,
"84.20",9.397,14.084,
"84.40",9.423,14.117,
"84.60",9.442,14.15067,
"84.80",9.463,14.18367,
"85.00",9.482,14.217,
"85.20",9.505,14.25033,
"85.40",9.526,14.28367,
"85.60",9.548,14.317,
"85.80",9.566,14.35033,
"86.00",9.585,14.38367,
"86.20",9.602,14.417,
"86.40",9.623,14.45033,
"86.60",9.642,14.48367,
"86.80",9.661,14.51733,
"87.00",9.677,14.55033,
"87.20",9.694,14.58367,
"87.40",9.714,14.617,
"87.60",9.733,14.65033,
"87.80",9.75,14.68367,
"88.00",9.771,14.717,
"88.20",9.793,14.75033,
"88.40",9.814,14.78367,
"88.60",9.836,14.81733,
"88.80",9.856,14.85033,
"89.00",9.876,14.88367,
"89.20",9.896,14.917,
"89.40",9.92,14.95033,
"89.60",9.938,14.98367,
"89.80",9.956,15.017,
"90.00",9.976,15.05067,
"90.20",10.001,15.084,
"90.40",10.024,15.11733,
"90.60",10.047,15.15033,
"90.80",10.067,15.184,
"91.00",10.088,15.217,
"91.20",10.112,15.25033,
"91.40",10.131,15.28367,
"91.60",10.152,15.317,
"91.80",10.172,15.35033,
"92.00",10.193,15.38367,
"92.20",10.212,15.417,
"92.40",10.233,15.45033,
"92.60",10.256,15.48367,
"92.80",10.274,15.517,
"93.00",10.295,15.55033,
"93.20",10.312,15.584,
"93.40",10.333,15.617,
"93.60",10.353,15.65033,
"93.80",10.371,15.68367,
"94.00",10.387,15.717,
"94.20",10.407,15.75067,
"94.40",10.425,15.78367,
"94.60",10.445,15.81733,
"94.80",10.464,15.85067,
"95.00",10.481,15.88367,
"95.20",10.5,15.917,
"95.40",10.519,15.95033,
"95.60",10.537,15.984,
"95.80",10.557,16.01733,
"96.00",10.574,16.05033,
"96.20",10.592,16.084,
"96.40",10.61,16.117,
"96.60",10.631,16.15033,
"96.80",10.651,16.184,
"97.00",10.669,16.217,
"97.20",10.689,16.25033,
"97.40",10.71,16.28367,
"97.60",10.731,16.317,
"97.80",10.748,16.35033,
"98.00",10.769,16.38367,
"98.20",10.789,16.417,
"98.40",10.812,16.45,
"98.60",10.835,16.48367,
"98.80",10.852,16.517,
"99.00",10.872,16.55033,
"99.20",10.889,16.58367,
"99.40",10.911,16.617,
"99.60",10.932,16.65033,
"99.80",10.948,16.68367,
"100.00",10.965,16.717,
"100.20",10.98,16.75033,
"100.40",10.995,16.78367,
"100.60",11.01,16.817,
"100.80",11.027,16.85033,
"101.00",11.042,16.88367,
"101.20",11.062,16.917,
"101.40",11.082,16.95033,
"101.60",11.105,16.98367,
"101.80",11.121,17.017,
"102.00",11.137,17.05033,
"102.20",11.152,17.08367,
"102.40",11.168,17.117,
"102.60",11.185,17.15033,
"102.80",11.199,17.18367,
"103.00",11.216,17.217,
"103.20",11.232,17.25033,
"103.40",11.252,17.28367,
"103.60",11.272,17.31733,
"103.80",11.289,17.35033,
"104.00",11.308,17.38367,
"104.20",11.328,17.417,
"104.40",11.35,17.45033,
"104.60",11.372,17.48367,
"104.80",11.389,17.517,
"105.00",11.404,17.55033,
"105.20",11.423,17.58367,
"105.40",11.442,17.617,
"105.60",11.461,17.65033,
"105.80",11.478,17.68367,
"106.00",11.495,17.717,
"106.20",11.513,17.75033,
"106.40",11.534,17.78367,
"106.60",11.555,17.817,
"106.80",11.572,17.85033,
"107.00",11.591,17.88367,
"107.20",11.612,17.917,
"107.40",11.629,17.95033,
"107.60",11.648,17.98367,
"107.80",11.666,18.017,
"108.00",11.685,18.05033,
"108.20",11.704,18.08367,
"108.40",11.722,18.117,
"108.60",11.742,18.15033,
"108.80",11.758,18.18367,
"109.00",11.774,18.217,
"109.20",11.792,18.25033,
"109.40",11.811,18.28367,
"109.60",11.828,18.317,
"109.80",11.845,18.35033,
"110.00",11.858,18.38367,
"110.20",11.877,18.417,
"110.40",11.895,18.45033,
"110.60",11.914,18.48367,
"110.80",11.931,18.51733,
"111.00",11.946,18.55067,
"111.20",11.963,18.58367,
"111.40",11.981,18.617,
"111.60",12,18.65033,
"111.80",12.015,18.68367,
"112.00",12.033,18.717,
"112.20",12.049,18.75033,
"112.40",12.064,18.78367,
"112.60",12.085,18.817,
"112.80",12.101,18.85067,
"113.00",12.114,18.884,
"113.20",12.13,18.91733,
"113.40",12.143,18.95067,
"113.60",12.159,18.984,
"113.80",12.171,19.017,
"114.00",12.186,19.05033,
"114.20",12.204,19.084,
"114.40",12.22,19.117,
"114.60",12.24,19.15033,
"114.80",12.26,19.18367,
"115.00",12.277,19.217,
"115.20",12.298,19.25033,
"115.40",12.318,19.28367,
"115.60",12.331,19.317,
"115.80",12.353,19.35033,
"116.00",12.37,19.38367,
"116.20",12.388,19.417,
"116.40",12.407,19.45033,
"116.60",12.428,19.48367,
"116.80",12.448,19.51733,
"117.00",12.462,19.55067,
"117.20",12.482,19.58367,
"117.40",12.502,19.61733,
"117.60",12.525,19.65067,
"117.80",12.543,19.68367,
"118.00",12.557,19.717,
"118.20",12.579,19.75033,
"118.40",12.598,19.78367,
"118.60",12.612,19.817,
"118.80",12.629,19.85033,
"119.00",12.641,19.88367,
"119.20",12.659,19.917,
"119.40",12.671,19.95033,
"119.60",12.687,19.98367,
"119.80",12.701,20.017,
"120.00",12.715,20.05033,
"120.20",12.723,20.08367,
"120.40",12.727,20.117,
"120.60",12.742,20.15033,
"120.80",12.757,20.184,
"121.00",12.772,20.217,
"121.20",12.788,20.25033,
"121.40",12.809,20.28367,
"121.60",12.832,20.317,
"121.80",12.844,20.35033,
"122.00",12.86,20.38367,
"122.20",12.876,20.417,
"122.40",12.894,20.45033,
"122.60",12.912,20.48367,
"122.80",12.929,20.517,
"123.00",12.948,20.55033,
"123.20",12.968,20.58367,
"123.40",12.988,20.617,
"123.60",13.008,20.65033,
"123.80",13.028,20.68367,
"124.00",13.046,20.717,
"124.20",13.062,20.75,
"124.40",13.083,20.78333,
"124.60",13.1,20.817,
"124.80",13.117,20.85033,
"125.00",13.131,20.88367,
"125.20",13.147,20.917,
"125.40",13.164,20.95033,
"125.60",13.178,20.98367,
"125.80",13.192,21.017,
"126.00",13.206,21.05033,
"126.20",13.221,21.08367,
"126.40",13.236,21.117,
"126.60",13.253,21.15033,
"126.80",13.269,21.18367,
"127.00",13.282,21.217,
"127.20",13.294,21.25033,
"127.40",13.31,21.28367,
"127.60",13.322,21.317,
"127.80",13.332,21.35033,
"128.00",13.342,21.38367,
"128.20",13.355,21.417,
"128.40",13.367,21.45033,
"128.60",13.379,21.48367,
"128.80",13.392,21.517,
"129.00",13.403,21.55033,
"129.20",13.42,21.58367,
"129.40",13.44,21.617,
"129.60",13.458,21.65033,
"129.80",13.472,21.68367,
"130.00",13.491,21.717,
"130.20",13.503,21.75033,
"130.40",13.524,21.78333,
"130.60",13.541,21.817,
"130.80",13.556,21.85033,
"131.00",13.571,21.88367,
"131.20",13.586,21.917,
"131.40",13.603,21.95033,
"131.60",13.62,21.98367,
"131.80",13.635,22.017,
"132.00",13.649,22.05033,
"132.20",13.66,22.08367,
"132.40",13.674,22.117,
"132.60",13.688,22.15033,
"132.80",13.7,22.18367,
"133.00",13.712,22.217,
"133.20",13.725,22.25033,
"133.40",13.74,22.28367,
"133.60",13.757,22.317,
"133.80",13.777,22.35,
"134.00",13.795,22.38333,
"134.20",13.813,22.41667,
"134.40",13.833,22.45033,
"134.60",13.853,22.48367,
"134.80",13.866,22.517,
"135.00",13.882,22.55033,
"135.20",13.9,22.58367,
"135.40",13.919,22.617,
"135.60",13.937,22.65033,
"135.80",13.949,22.68367,
"136.00",13.959,22.717,
"136.20",13.972,22.75033,
"136.40",13.988,22.78367,
"136.60",14.003,22.817,
"136.80",14.016,22.85033,
"137.00",14.027,22.88367,
"137.20",14.042,22.917,
"137.40",14.059,22.95,
"137.60",14.074,22.98333,
"137.80",14.089,23.01667,
"138.00",14.104,23.05,
"138.20",14.119,23.08333,
"138.40",14.133,23.11667,
"138.60",14.146,23.15,
"138.80",14.156,23.18333,
"139.00",14.171,23.217,
"139.20",14.185,23.25033,
"139.40",14.204,23.28367,
"139.60",14.22,23.317,
"139.80",14.232,23.35033,
"140.00",14.25,23.38367,
"140.20",14.264,23.417,
"140.40",14.286,23.45033,
"140.60",14.306,23.48367,
"140.80",14.319,23.517,
"141.00",14.332,23.55033,
"141.20",14.348,23.58367,
"141.40",14.367,23.617,
"141.60",14.382,23.65033,
"141.80",14.397,23.68367,
"142.00",14.408,23.717,
"142.20",14.419,23.75033,
"142.40",14.432,23.78367,
"142.60",14.449,23.817,
"142.80",14.459,23.85033,
"143.00",14.47,23.88367,
"143.20",14.489,23.917,
"143.40",14.505,23.95,
"143.60",14.52,23.98367,
"143.80",14.536,24.017,
"144.00",14.551,24.05033,
"144.20",14.564,24.08367,
"144.40",14.577,24.11667,
"144.60",14.595,24.15033,
"144.80",14.608,24.18367,
"145.00",14.624,24.21667,
"145.20",14.64,24.25,
"145.40",14.661,24.28333,
"145.60",14.68,24.317,
"145.80",14.699,24.35,
"146.00",14.711,24.38333,
"146.20",14.723,24.417,
"146.40",14.737,24.45,
"146.60",14.753,24.48333,
"146.80",14.761,24.51667,
"147.00",14.769,24.55,
"147.20",14.782,24.58333,
"147.40",14.799,24.617,
"147.60",14.814,24.65033,
"147.80",14.824,24.68367,
"148.00",14.836,24.717,
"148.20",14.848,24.75033,
"148.40",14.866,24.78333,
"148.60",14.876,24.817,
"148.80",14.884,24.85033,
"149.00",14.893,24.88333,
"149.20",14.905,24.917,
"149.40",14.918,24.95,
"149.60",14.921,24.98333,
"149.80",14.928,25.01667,
"150.00",14.933,25.05,
"150.20",14.94,25.08333,
"150.40",14.949,25.11667,
"150.60",14.958,25.15,
"150.80",14.969,25.18367,
"151.00",14.981,25.217,
"151.20",14.995,25.25033,
"151.40",15.01,25.28367,
"151.60",15.026,25.317,
"151.80",15.035,25.35033,
"152.00",15.047,25.38367,
"152.20",15.06,25.417,
"152.40",15.073,25.45033,
"152.60",15.086,25.48367,
"152.80",15.098,25.517,
"153.00",15.111,25.55033,
"153.20",15.124,25.58367,
"153.40",15.137,25.617,
"153.60",15.15,25.65033,
"153.80",15.157,25.68367,
"154.00",15.169,25.717,
"154.20",15.184,25.75033,
"154.40",15.194,25.78367,
"154.60",15.207,25.81667,
"154.80",15.22,25.85,
"155.00",15.235,25.88333,
"155.20",15.257,25.917,
"155.40",15.278,25.95,
"155.60",15.294,25.98333,
"155.80",15.311,26.017,
"156.00",15.327,26.05,
"156.20",15.341,26.08367,
"156.40",15.359,26.11667,
"156.60",15.372,26.15,
"156.80",15.389,26.18333,
"157.00",15.399,26.217,
"157.20",15.407,26.25033,
"157.40",15.421,26.28367,
"157.60",15.432,26.317,
"157.80",15.437,26.35033,
"158.00",15.447,26.38367,
"158.20",15.455,26.417,
"158.40",15.468,26.45033,
"158.60",15.479,26.48367,
"158.80",15.488,26.517,
"159.00",15.497,26.55033,
"159.20",15.507,26.58367,
"159.40",15.518,26.617,
"159.60",15.531,26.65033,
"159.80",15.54,26.68367,
"160.00",15.55,26.717,
"160.20",15.559,26.75033,
"160.40",15.573,26.78333,
"160.60",15.586,26.817,
"160.80",15.598,26.85033,
"161.00",15.604,26.88367,
"161.20",15.613,26.917,
"161.40",15.621,26.95033,
"161.60",15.636,26.98333,
"161.80",15.648,27.017,
"162.00",15.661,27.05033,
"162.20",15.675,27.08367,
"162.40",15.689,27.117,
"162.60",15.701,27.15033,
"162.80",15.711,27.18367,
"163.00",15.72,27.217,
"163.20",15.732,27.25033,
"163.40",15.743,27.28367,
"163.60",15.755,27.317,
"163.80",15.761,27.35033,
"164.00",15.774,27.38367,
"164.20",15.79,27.417,
"164.40",15.808,27.45033,
"164.60",15.822,27.48367,
"164.80",15.84,27.51733,
"165.00",15.854,27.55033,
"165.20",15.871,27.58367,
"165.40",15.89,27.617,
"165.60",15.905,27.65033,
"165.80",15.917,27.68367,
"166.00",15.925,27.717,
"166.20",15.936,27.75033,
"166.40",15.951,27.78367,
"166.60",15.966,27.817,
"166.80",15.976,27.85033,
"167.00",15.986,27.88367,
"167.20",15.991,27.917,
"167.40",16.003,27.95033,
"167.60",16.01,27.98367,
"167.80",16.024,28.017,
"168.00",16.035,28.05033,
"168.20",16.048,28.08367,
"168.40",16.065,28.117,
"168.60",16.075,28.15033,
"168.80",16.08,28.18367,
"169.00",16.089,28.217,
"169.20",16.104,28.25033,
"169.40",16.119,28.28367,
"169.60",16.133,28.317,
"169.80",16.148,28.35033,
"170.00",16.168,28.38367,
"170.20",16.183,28.417,
"170.40",16.206,28.45033,
"170.60",16.223,28.48367,
"170.80",16.239,28.517,
"171.00",16.252,28.55033,
"171.20",16.266,28.58367,
"171.40",16.279,28.617,
"171.60",16.292,28.65033,
"171.80",16.302,28.68333,
"172.00",16.309,28.71667,
"172.20",16.319,28.75033,
"172.40",16.333,28.78367,
"172.60",16.351,28.817,
"172.80",16.363,28.85033,
"173.00",16.379,28.88367,
"173.20",16.392,28.917,
"173.40",16.408,28.95033,
"173.60",16.419,28.98367,
"173.80",16.43,29.017,
"174.00",16.443,29.05033,
"174.20",16.454,29.08367,
"174.40",16.465,29.11667,
"174.60",16.472,29.15033,
"174.80",16.478,29.18367,
"175.00",16.485,29.217,
"175.20",16.493,29.25033,
"175.40",16.505,29.28367,
"175.60",16.515,29.317,
"175.80",16.517,29.35033,
"176.00",16.523,29.38367,
"176.20",16.528,29.417,
"176.40",16.532,29.45033,
"176.60",16.544,29.48367,
"176.80",16.549,29.517,
"177.00",16.557,29.55033,
"177.20",16.567,29.58367,
"177.40",16.577,29.617,
"177.60",16.586,29.65033,
"177.80",16.594,29.68367,
"178.00",16.603,29.717,
"178.20",16.612,29.75033,
"178.40",16.624,29.78367,
"178.60",16.636,29.817,
"178.80",16.646,29.85033,
"179.00",16.656,29.88367,
"179.20",16.668,29.917,
"179.40",16.68,29.95033,
"179.60",16.693,29.98367,
"179.80",16.704,30.017,
"180.00",16.715,30.05033,
"180.20",16.723,30.08367,
"180.40",16.741,30.117,
"180.60",16.756,30.15033,
"180.80",16.765,30.18367,
"181.00",16.772,30.217,
"181.20",16.784,30.25033,
"181.40",16.802,30.28367,
"181.60",16.814,30.317,
"181.80",16.825,30.35033,
"182.00",16.833,30.38367,
"182.20",16.845,30.417,
"182.40",16.859,30.45033,
"182.60",16.87,30.48367,
"182.80",16.88,30.517,
"183.00",16.888,30.55033,
"183.20",16.899,30.58367,
"183.40",16.91,30.617,
"183.60",16.92,30.65033,
"183.80",16.926,30.68333,
"184.00",16.935,30.71667,
"184.20",16.943,30.75033,
"184.40",16.954,30.78367,
"184.60",16.966,30.817,
"184.80",16.975,30.85033,
"185.00",16.983,30.88367,
"185.20",16.993,30.917,
"185.40",17.003,30.95033,
"185.60",17.014,30.98367,
"185.80",17.023,31.017,
"186.00",17.031,31.05033,
"186.20",17.04,31.08367,
"186.40",17.053,31.117,
"186.60",17.067,31.15033,
"186.80",17.074,31.18367,
"187.00",17.081,31.217,
"187.20",17.09,31.25033,
"187.40",17.098,31.28367,
"187.60",17.106,31.317,
"187.80",17.112,31.35033,
"188.00",17.122,31.38367,
"188.20",17.128,31.41733,
"188.40",17.142,31.45033,
"188.60",17.151,31.48367,
"188.80",17.159,31.517,
"189.00",17.163,31.55033,
"189.20",17.169,31.58367,
"189.40",17.181,31.617,
"189.60",17.189,31.65033,
"189.80",17.193,31.68367,
"190.00",17.194,31.717,
"190.20",17.201,31.75033,
"190.40",17.212,31.78367,
"190.60",17.225,31.817,
"190.80",17.236,31.85033,
"191.00",17.245,31.88367,
"191.20",17.256,31.917,
"191.40",17.274,31.95033,
"191.60",17.294,31.98367,
"191.80",17.309,32.017,
"192.00",17.323,32.05033,
"192.20",17.342,32.08367,
"192.40",17.359,32.117,
"192.60",17.375,32.15033,
"192.80",17.388,32.18367,
"193.00",17.402,32.217,
"193.20",17.416,32.25033,
"193.40",17.431,32.28367,
"193.60",17.444,32.317,
"193.80",17.454,32.35033,
"194.00",17.462,32.38367,
"194.20",17.47,32.417,
"194.40",17.481,32.45033,
"194.60",17.492,32.48367,
"194.80",17.498,32.517,
"195.00",17.505,32.55,
"195.20",17.509,32.58333,
"195.40",17.522,32.61666,
"195.60",17.532,32.65,
"195.80",17.537,32.68333,
"196.00",17.54,32.717,
"196.20",17.542,32.75033,
"196.40",17.549,32.78333,
"196.60",17.555,32.81667,
"196.80",17.558,32.85033,
"197.00",17.559,32.88367,
"197.20",17.559,32.91667,
"197.40",17.562,32.95,
"197.60",17.566,32.98367,
"197.80",17.572,33.017,
"198.00",17.579,33.05033,
"198.20",17.588,33.08367,
"198.40",17.6,33.117,
"198.60",17.616,33.15033,
"198.80",17.628,33.18367,
"199.00",17.637,33.217,
"199.20",17.649,33.25,
"199.40",17.663,33.28333,
"199.60",17.674,33.31667,
"199.80",17.685,33.35033,
"200.00",17.695,33.38334,
"200.20",17.706,33.417,
"200.40",17.718,33.45,
"200.60",17.732,33.48333,
"200.80",17.745,33.517,
"201.00",17.755,33.55,
"201.20",17.767,33.58367,
"201.40",17.781,33.617,
"201.60",17.796,33.65033,
"201.80",17.809,33.68367,
"202.00",17.819,33.717,
"202.20",17.829,33.75033,
"202.40",17.838,33.78367,
"202.60",17.844,33.817,
"202.80",17.846,33.85033,
"203.00",17.851,33.88367,
"203.20",17.857,33.917,
"203.40",17.869,33.95033,
"203.60",17.878,33.98367,
"203.80",17.884,34.017,
"204.00",17.891,34.05033,
"204.20",17.901,34.084,
"204.40",17.917,34.11733,
"204.60",17.929,34.15067,
"204.80",17.934,34.184,
"205.00",17.934,34.217,
"205.20",17.942,34.25033,
"205.40",17.953,34.28367,
"205.60",17.963,34.317,
"205.80",17.972,34.35033,
"206.00",17.977,34.38367,
"206.20",17.983,34.417,
"206.40",17.996,34.45033,
"206.60",18.004,34.48367,
"206.80",18.008,34.517,
"207.00",18.016,34.55033,
"207.20",18.023,34.58367,
"207.40",18.034,34.617,
"207.60",18.046,34.65033,
"207.80",18.051,34.68367,
"208.00",18.058,34.717,
"208.20",18.066,34.75033,
"208.40",18.077,34.78367,
"208.60",18.087,34.817,
"208.80",18.097,34.85033,
"209.00",18.102,34.88367,
"209.20",18.109,34.917,
"209.40",18.119,34.95033,
"209.60",18.123,34.98367,
"209.80",18.126,35.017,
"210.00",18.127,35.05,
"210.20",18.129,35.08333,
"210.40",18.14,35.11666,
"210.60",18.149,35.15033,
"210.80",18.153,35.18367,
"211.00",18.159,35.217,
"211.20",18.162,35.25,
"211.40",18.172,35.28333,
"211.60",18.183,35.317,
"211.80",18.192,35.35033,
"212.00",18.198,35.38367,
"212.20",18.198,35.417,
"212.40",18.205,35.45033,
"212.60",18.212,35.48367,
"212.80",18.219,35.517,
"213.00",18.226,35.55033,
"213.20",18.239,35.58367,
"213.40",18.255,35.617,
"213.60",18.271,35.65033,
"213.80",18.283,35.68367,
"214.00",18.292,35.717,
"214.20",18.305,35.75033,
"214.40",18.314,35.78367,
"214.60",18.323,35.817,
"214.80",18.325,35.85033,
"215.00",18.331,35.88367,
"215.20",18.341,35.917,
"215.40",18.349,35.95033,
"215.60",18.355,35.98367,
"215.80",18.364,36.017,
"216.00",18.369,36.05033,
"216.20",18.374,36.08367,
"216.40",18.385,36.117,
"216.60",18.395,36.15033,
"216.80",18.399,36.18367,
"217.00",18.404,36.217,
"217.20",18.41,36.25033,
"217.40",18.421,36.28367,
"217.60",18.432,36.317,
"217.80",18.444,36.35033,
"218.00",18.452,36.38367,
"218.20",18.464,36.417,
"218.40",18.476,36.45033,
"218.60",18.488,36.48333,
"218.80",18.498,36.517,
"219.00",18.513,36.55033,
"219.20",18.526,36.58367,
"219.40",18.541,36.617,
"219.60",18.553,36.65033,
"219.80",18.564,36.68333,
"220.00",18.572,36.717,
"220.20",18.582,36.75033,
"220.40",18.592,36.78367,
"220.60",18.605,36.817,
"220.80",18.618,36.85033,
"221.00",18.629,36.88367,
"221.20",18.641,36.917,
"221.40",18.653,36.95033,
"221.60",18.661,36.98367,
"221.80",18.67,37.017,
"222.00",18.677,37.05033,
"222.20",18.681,37.08367,
"222.40",18.686,37.117,
"222.60",18.69,37.15033,
"222.80",18.694,37.184,
"223.00",18.699,37.21733,
"223.20",18.709,37.25033,
"223.40",18.716,37.28367,
"223.60",18.721,37.317,
"223.80",18.73,37.35033,
"224.00",18.736,37.38367,
"224.20",18.748,37.417,
"224.40",18.76,37.45033,
"224.60",18.773,37.48367,
"224.80",18.786,37.517,
"225.00",18.797,37.55033,
"225.20",18.808,37.58367,
"225.40",18.823,37.617,
"225.60",18.837,37.65033,
"225.80",18.847,37.68367,
"226.00",18.859,37.717,
"226.20",18.867,37.75033,
"226.40",18.88,37.78367,
"226.60",18.892,37.817,
"226.80",18.901,37.85033,
"227.00",18.908,37.88367,
"227.20",18.918,37.917,
"227.40",18.924,37.95033,
"227.60",18.93,37.98367,
"227.80",18.934,38.017,
"228.00",18.936,38.05033,
"228.20",18.936,38.08367,
"228.40",18.939,38.117,
"228.60",18.939,38.15067,
"228.80",18.938,38.184,
"229.00",18.938,38.217,
"229.20",18.942,38.25067,
"229.40",18.951,38.28367,
"229.60",18.957,38.317,
"229.80",18.963,38.35033,
"230.00",18.97,38.38367,
"230.20",18.981,38.417,
"230.40",18.993,38.45033,
"230.60",19.003,38.48367,
"230.80",19.006,38.517,
"231.00",19.009,38.55033,
"231.20",19.013,38.58367,
"231.40",19.024,38.617,
"231.60",19.034,38.65067,
"231.80",19.042,38.684,
"232.00",19.05,38.71733,
"232.20",19.054,38.75067,
"232.40",19.061,38.784,
"232.60",19.067,38.81733,
"232.80",19.07,38.85067,
"233.00",19.071,38.88367,
"233.20",19.072,38.917,
"233.40",19.076,38.95033,
"233.60",19.078,38.98367,
"233.80",19.07,39.017,