File: load_extensions/pristine_monofilament1.csv
"Test Name","Test Mode","Test Type","Control","Test Speed 1","Test Speed 2","Test Speed 3","Change Point 1","Change Point 2","Disp. Origin","Break and Limit Action","Sensitivity:","Level:"
"","Single","Tensile","Stroke",10,1,1,"Off","Off","Start","Stop",0,1

"Title","Sub title","Comment"
"","",""

"Shape:","Batch Size:","SubBatch Size:"
"Plate",1,1
"Name:","Thickness","Width","Gauge Length",
"Size Unit:","mm","mm","mm",
" 1 - 1","1.0000","1.0000","100.0000",

"Name",
"Parameter",
"Units",
" 1 - 1",

" 1- 1"
"Time","Force","Stroke",
"sec","N","mm",
"0.00",0,0,
"0.20",.001,3.733334E-02,
"0.40",.012,7.466666E-02,
"0.60",.022,.1116667,
"0.80",.033,.1486667,
"1.00",.05,.186,
"1.20",.06,.223,
"1.40",.072,.2603334,
"1.60",.083,.2973334,
"1.80",.096,.3346667,
"2.00",.107,.3713334,
"2.20",.118,.407,
"2.40",.131,.4426667,
"2.60",.138,.4776667,
"2.80",.152,.5126667,
"3.00",.162,.547,
"3.20",.171,.5813333,
"3.40",.185,.6153333,
"3.60",.195,.6493334,
"3.80",.204,.6833333,
"4.00",.216,.717,
"4.20",.227,.7506667,
"4.40",.238,.7843333,
"4.60",.248,.8176666,
"4.80",.261,.8513333,
"5.00",.27,.8846667,
"5.20",.282,.9183334,
"5.40",.291,.9516667,
"5.60",.304,.9853333,
"5.80",.315,1.018667,
"6.00",.326,1.052,
"6.20",.335,1.085333,
"6.40",.347,1.118667,
"6.60",.358,1.152,
"6.80",.368,1.185667,
"7.00",.379,1.218667,
"7.20",.39,1.252,
"7.40",.402,1.285667,
"7.60",.413,1.319,
"7.80",.426,1.352333,
"8.00",.437,1.385667,
"8.20",.447,1.419,
"8.40",.46,1.452333,
"8.60",.472,1.485333,
"8.80",.483,1.519,
"9.00",.495,1.552333,
"9.20",.507,1.585667,
"9.40",.519,1.619,
"9.60",.531,1.652333,
"9.80",.54,1.685333,
"10.00",.552,1.718667,
"10.20",.567,1.752,
"10.40",.579,1.785333,
"10.60",.589,1.818667,
"10.80",.602,1.852,
"11.00",.613,1.885333,
"11.20",.625,1.918667,
"11.40",.636,1.952,
"11.60",.65,1.985333,
"11.80",.662,2.018667,
"12.00",.674,2.052,
"12.20",.687,2.085333,
"12.40",.699,2.118667,
"12.60",.714,2.152,
"12.80",.725,2.185333,
"13.00",.738,2.218667,
"13.20",.749,2.252,
"13.40",.764,2.285333,
"13.60",.779,2.318667,
"13.80",.792,2.352,
"14.00",.806,2.385333,
"14.20",.82,2.418667,
"14.40",.832,2.452,
"14.60",.845,2.485333,
"14.80",.859,2.518667,
"15.00",.873,2.552,
"15.20",.885,2.585333,
"15.40",.902,2.619,
"15.60",.915,2.652,
"15.80",.927,2.685333,
"16.00",.94,2.718667,
"16.20",.958,2.752,
"16.40",.971,2.785333,
"16.60",.985,2.818667,
"16.80",1.001,2.852333,
"17.00",1.016,2.885333,
"17.20",1.03,2.918667,
"17.40",1.045,2.952,
"17.60",1.057,2.985333,
"17.80",1.073,3.018667,
"18.00",1.09,3.052,
"18.20",1.104,3.085333,
"18.40",1.119,3.118667,
"18.60",1.135,3.152,
"18.80",1.149,3.185333,
"19.00",1.165,3.218667,
"19.20",1.18,3.252,
"19.40",1.197,3.285333,
"19.60",1.214,3.318667,
"19.80",1.228,3.352,
"20.00",1.245,3.385333,
"20.20",1.263,3.418667,
"20.40",1.278,3.452,
"20.60",1.294,3.485667,
"20.80",1.311,3.519,
"21.00",1.329,3.552,
"21.20",1.347,3.585667,
"21.40",1.364,3.619,
"21.60",1.384,3.652333,
"21.80",1.398,3.685667,
"22.00",1.418,3.718667,
"22.20",1.434,3.752,
"22.40",1.451,3.785333,
"22.60",1.467,3.818667,
"22.80",1.486,3.852,
"23.00",1.505,3.885333,
"23.20",1.523,3.918667,
"23.40",1.541,3.952,
"23.60",1.56,3.985667,
"23.80",1.579,4.018667,
"24.00",1.596,4.052,
"24.20",1.614,4.085333,
"24.40",1.635,4.118667,
"24.60",1.654,4.152,
"24.80",1.673,4.185333,
"25.00",1.692,4.218667,
"25.20",1.71,4.252,
"25.40",1.731,4.285334,
"25.60",1.75,4.319,
"25.80",1.772,4.352334,
"26.00",1.793,4.385334,
"26.20",1.813,4.419,
"26.40",1.832,4.452333,
"26.60",1.853,4.485667,
"26.80",1.874,4.519,
"27.00",1.892,4.552,
"27.20",1.913,4.585333,
"27.40",1.934,4.618667,
"27.60",1.954,4.652,
"27.80",1.979,4.685667,
"28.00",2.001,4.719,
"28.20",2.025,4.752334,
"28.40",2.045,4.785667,
"28.60",2.068,4.819,
"28.80",2.089,4.852334,
"29.00",2.111,4.885334,
"29.20",2.136,4.918667,
"29.40",2.156,4.952,
"29.60",2.176,4.985333,
"29.80",2.202,5.018667,
"30.00",2.224,5.052,
"30.20",2.25,5.085333,
"30.40",2.269,5.118667,
"30.60",2.292,5.152,
"30.80",2.32,5.185667,
"31.00",2.343,5.218667,
"31.20",2.366,5.252,
"31.40",2.391,5.285334,
"31.60",2.416,5.319,
"31.80",2.442,5.352,
"32.00",2.465,5.385334,
"32.20",2.492,5.419,
"32.40",2.519,5.452,
"32.60",2.543,5.485667,
"32.80",2.567,5.519,
"33.00",2.593,5.552,
"33.20",2.617,5.585333,
"33.40",2.644,5.618667,
"33.60",2.668,5.652,
"33.80",2.696,5.685333,
"34.00",2.723,5.718667,
"34.20",2.753,5.752,
"34.40",2.779,5.785334,
"34.60",2.805,5.818667,
"34.80",2.834,5.852,
"35.00",2.861,5.885334,
"35.20",2.889,5.919,
"35.40",2.914,5.952333,
"35.60",2.945,5.985667,
"35.80",2.973,6.019,
"36.00",3.004,6.052333,
"36.20",3.029,6.085333,
"36.40",3.06,6.118667,
"36.60",3.086,6.152,
"36.80",3.117,6.185667,
"37.00",3.146,6.218667,
"37.20",3.174,6.252,
"37.40",3.203,6.285667,
"37.60",3.231,6.319,
"37.80",3.261,6.352334,
"38.00",3.292,6.385667,
"38.20",3.324,6.419,
"38.40",3.349,6.452333,
"38.60",3.379,6.485667,
"38.80",3.409,6.519,
"39.00",3.442,6.552333,
"39.20",3.474,6.585667,
"39.40",3.5,6.619,
"39.60",3.528,6.652333,
"39.80",3.559,6.685667,
"40.00",3.591,6.719,
"40.20",3.621,6.752334,
"40.40",3.651,6.785667,
"40.60",3.682,6.819,
"40.80",3.714,6.852334,
"41.00",3.746,6.885667,
"41.20",3.779,6.919,
"41.40",3.808,6.952333,
"41.60",3.841,6.985667,
"41.80",3.872,7.019,
"42.00",3.904,7.052,
"42.20",3.935,7.085333,
"42.40",3.967,7.118667,
"42.60",3.998,7.152,
"42.80",4.029,7.185333,
"43.00",4.062,7.218667,
"43.20",4.093,7.252,
"43.40",4.125,7.285334,
"43.60",4.157,7.319,
"43.80",4.189,7.352334,
"44.00",4.221,7.385334,
"44.20",4.255,7.418667,
"44.40",4.283,7.452,
"44.60",4.317,7.485333,
"44.80",4.348,7.518667,
"45.00",4.379,7.552,
"45.20",4.411,7.585333,
"45.40",4.441,7.618667,
"45.60",4.474,7.652,
"45.80",4.505,7.685333,
"46.00",4.538,7.718667,
"46.20",4.569,7.752,
"46.40",4.6,7.785334,
"46.60",4.632,7.819,
"46.80",4.665,7.852334,
"47.00",4.698,7.885334,
"47.20",4.728,7.918667,
"47.40",4.757,7.952,
"47.60",4.789,7.985333,
"47.80",4.82,8.018666,
"48.00",4.853,8.052,
"48.20",4.885,8.085333,
"48.40",4.913,8.118667,
"48.60",4.943,8.151999,
"48.80",4.974,8.185333,
"49.00",5.004,8.218666,
"49.20",5.036,8.252,
"49.40",5.066,8.285333,
"49.60",5.095,8.318666,
"49.80",5.127,8.351999,
"50.00",5.158,8.385333,
"50.20",5.191,8.418666,
"50.40",5.218,8.452,
"50.60",5.249,8.485332,
"50.80",5.279,8.518666,
"51.00",5.309,8.552,
"51.20",5.339,8.585333,
"51.40",5.368,8.618667,
"51.60",5.396,8.651999,
"51.80",5.426,8.685333,
"52.00",5.458,8.718666,
"52.20",5.486,8.752,
"52.40",5.515,8.785333,
"52.60",5.543,8.818666,
"52.80",5.573,8.851999,
"53.00",5.602,8.885333,
"53.20",5.631,8.918666,
"53.40",5.656,8.952,
"53.60",5.686,8.985332,
"53.80",5.714,9.018666,
"54.00",5.745,9.052,
"54.20",5.774,9.085667,
"54.40",5.803,9.118999,
"54.60",5.829,9.151999,
"54.80",5.858,9.185666,
"55.00",5.887,9.218666,
"55.20",5.914,9.252333,
"55.40",5.939,9.285666,
"55.60",5.967,9.318999,
"55.80",5.995,9.352333,
"56.00",6.024,9.385333,
"56.20",6.05,9.418666,
"56.40",6.073,9.452,
"56.60",6.103,9.485332,
"56.80",6.131,9.519,
"57.00",6.158,9.552333,
"57.20",6.185,9.585667,
"57.40",6.21,9.618999,
"57.60",6.236,9.652333,
"57.80",6.264,9.685333,
"58.00",6.293,9.719,
"58.20",6.322,9.752333,
"58.40",6.346,9.785666,
"58.60",6.372,9.818666,
"58.80",6.399,9.852333,
"59.00",6.427,9.885333,
"59.20",6.453,9.919,
"59.40",6.477,9.952332,
"59.60",6.503,9.985666,
"59.80",6.531,10.019,
"60.00",6.558,10.05233,
"60.20",6.584,10.08567,
"60.40",6.609,10.119,
"60.60",6.634,10.15233,
"60.80",6.659,10.18567,
"61.00",6.688,10.219,
"61.20",6.712,10.25233,
"61.40",6.738,10.28533,
"61.60",6.76,10.319,
"61.80",6.788,10.35233,
"62.00",6.811,10.38567,
"62.20",6.829,10.419,
"62.40",6.844,10.452,
"62.60",6.873,10.48533,
"62.80",6.897,10.51867,
"63.00",6.925,10.552,
"63.20",6.95,10.58533,
"63.40",6.977,10.61867,
"63.60",6.999,10.65233,
"63.80",7.028,10.68533,
"64.00",7.054,10.71867,
"64.20",7.08,10.752,
"64.40",7.105,10.78533,
"64.60",7.127,10.81867,
"64.80",7.154,10.852,
"65.00",7.181,10.88533,
"65.20",7.206,10.91867,
"65.40",7.231,10.952,
"65.60",7.252,10.98533,
"65.80",7.281,11.019,
"66.00",7.304,11.052,
"66.20",7.33,11.08533,
"66.40",7.352,11.11867,
"66.60",7.377,11.152,
"66.80",7.401,11.18567,
"67.00",7.424,11.219,
"67.20",7.449,11.25233,
"67.40",7.471,11.28533,
"67.60",7.491,11.319,
"67.80",7.516,11.35233,
"68.00",7.539,11.38533,
"68.20",7.564,11.419,
"68.40",7.585,11.452,
"68.60",7.61,11.48533,
"68.80",7.633,11.51867,
"69.00",7.658,11.552,
"69.20",7.683,11.58567,
"69.40",7.705,11.619,
"69.60",7.728,11.65233,
"69.80",7.748,11.68567,
"70.00",7.773,11.719,
"70.20",7.797,11.75233,
"70.40",7.819,11.78567,
"70.60",7.842,11.81867,
"70.80",7.866,11.85233,
"71.00",7.89,11.88567,
"71.20",7.913,11.919,
"71.40",7.933,11.952,
"71.60",7.952,11.98567,
"71.80",7.976,12.019,
"72.00",8,12.052,
"72.20",8.02,12.08567,
"72.40",8.039,12.119,
"72.60",8.062,12.15233,
"72.80",8.085,12.18567,
"73.00",8.107,12.219,
"73.20",8.131,12.25233,
"73.40",8.153,12.28567,
"73.60",8.175,12.319,
"73.80",8.2,12.352,
"74.00",8.222,12.38567,
"74.20",8.244,12.419,
"74.40",8.266,12.452,
"74.60",8.289,12.48567,
"74.80",8.311,12.519,
"75.00",8.332,12.55233,
"75.20",8.353,12.58567,
"75.40",8.375,12.619,
"75.60",8.398,12.65233,
"75.80",8.419,12.68567,
"76.00",8.441,12.719,
"76.20",8.462,12.75233,
"76.40",8.484,12.78567,
"76.60",8.505,12.819,
"76.80",8.528,12.85233,
"77.00",8.548,12.88567,
"77.20",8.571,12.919,
"77.40",8.592,12.95233,
"77.60",8.613,12.98567,
"77.80",8.632,13.019,
"78.00",8.658,13.05233,
"78.20",8.683,13.08567,
"78.40",8.702,13.11867,
"78.60",8.724,13.152,
"78.80",8.745,13.18567,
"79.00",8.77,13.219,
"79.20",8.792,13.25233,
"79.40",8.812,13.28567,
"79.60",8.833,13.319,
"79.80",8.851,13.35233,
"80.00",8.875,13.38567,
"80.20",8.895,13.419,
"80.40",8.918,13.45233,
"80.60",8.939,13.48567,
"80.80",8.959,13.519,
"81.00",8.981,13.55233,
"81.20",9.005,13.58567,
"81.40",9.025,13.619,
"81.60",9.048,13.65233,
"81.80",9.071,13.68567,
"82.00",9.093,13.719,
"82.20",9.114,13.75233,
"82.40",9.134,13.78567,
"82.60",9.153,13.819,
"82.80",9.172,13.85233,
"83.00",9.197,13.88567,
"83.20",9.216,13.919,
"83.40",9.235,13.95233,
"83.60",9.255,13.98567,
"83.80",9.277,14.019,
"84.00",9.299,14.05233,
"84.20",9.32,14.08567,
"84.40",9.335,14.11867,
"84.60",9.356,14.15233,
"84.80",9.376,14.18567,
"85.00",9.398,14.21867,
"85.20",9.418,14.252,
"85.40",9.438,14.28567,
"85.60",9.458,14.319,
"85.80",9.478,14.35233,
"86.00",9.501,14.38567,
"86.20",9.521,14.419,
"86.40",9.542,14.45233,
"86.60",9.559,14.48567,
"86.80",9.581,14.519,
"87.00",9.598,14.552,
"87.20",9.617,14.58533,
"87.40",9.634,14.619,
"87.60",9.654,14.65233,
"87.80",9.674,14.68533,
"88.00",9.694,14.71867,
"88.20",9.714,14.752,
"88.40",9.73,14.78567,
"88.60",9.752,14.819,
"88.80",9.77,14.85233,
"89.00",9.793,14.88533,
"89.20",9.814,14.91867,
"89.40",9.834,14.952,
"89.60",9.852,14.98567,
"89.80",9.873,15.019,
"90.00",9.894,15.05233,
"90.20",9.915,15.08567,
"90.40",9.938,15.119,
"90.60",9.959,15.15233,
"90.80",9.979,15.18567,
"91.00",9.998,15.219,
"91.20",10.015,15.25233,
"91.40",10.033,15.28567,
"91.60",10.053,15.319,
"91.80",10.073,15.35233,
"92.00",10.092,15.38567,
"92.20",10.111,15.419,
"92.40",10.129,15.452,
"92.60",10.144,15.48567,
"92.80",10.165,15.519,
"93.00",10.184,15.552,
"93.20",10.199,15.58567,
"93.40",10.218,15.619,
"93.60",10.232,15.65233,
"93.80",10.251,15.68567,
"94.00",10.273,15.719,
"94.20",10.292,15.75233,
"94.40",10.311,15.78567,
"94.60",10.328,15.819,
"94.80",10.345,15.85233,
"95.00",10.365,15.88567,
"95.20",10.388,15.919,
"95.40",10.406,15.95233,
"95.60",10.422,15.986,
"95.80",10.443,16.019,
"96.00",10.464,16.05233,
"96.20",10.484,16.08567,
"96.40",10.502,16.119,
"96.60",10.52,16.15233,
"96.80",10.54,16.18567,
"97.00",10.561,16.219,
"97.20",10.577,16.25233,
"97.40",10.595,16.28533,
"97.60",10.611,16.319,
"97.80",10.634,16.35233,
"98.00",10.654,16.38567,
"98.20",10.673,16.419,
"98.40",10.693,16.45233,
"98.60",10.71,16.48567,
"98.80",10.727,16.519,
"99.00",10.746,16.55233,
"99.20",10.766,16.58567,
"99.40",10.781,16.619,
"99.60",10.8,16.65233,
"99.80",10.82,16.68567,
"100.00",10.842,16.719,
"100.20",10.857,16.75233,
"100.40",10.877,16.78567,
"100.60",10.894,16.81867,
"100.80",10.913,16.85233,
"101.00",10.934,16.88533,
"101.20",10.95,16.919,
"101.40",10.968,16.952,
"101.60",10.987,16.98567,
"101.80",11.007,17.019,
"102.00",11.029,17.052,
"102.20",11.042,17.08533,
"102.40",11.057,17.11867,
"102.60",11.076,17.15233,
"102.80",11.093,17.18567,
"103.00",11.111,17.21867,
"103.20",11.126,17.252,
"103.40",11.143,17.28567,
"103.60",11.16,17.319,
"103.80",11.176,17.35233,
"104.00",11.194,17.38533,
"104.20",11.21,17.41867,
"104.40",11.228,17.452,
"104.60",11.242,17.48533,
"104.80",11.259,17.51867,
"105.00",11.276,17.552,
"105.20",11.294,17.58533,
"105.40",11.311,17.619,
"105.60",11.33,17.65233,
"105.80",11.346,17.68567,
"106.00",11.368,17.719,
"106.20",11.384,17.75233,
"106.40",11.403,17.78533,
"106.60",11.419,17.819,
"106.80",11.438,17.85233,
"107.00",11.46,17.88567,
"107.20",11.476,17.919,
"107.40",11.492,17.952,
"107.60",11.508,17.98533,
"107.80",11.527,18.01867,
"108.00",11.545,18.052,
"108.20",11.564,18.08533,
"108.40",11.581,18.11867,
"108.60",11.595,18.152,
"108.80",11.613,18.18533,
"109.00",11.63,18.21867,
"109.20",11.65,18.252,
"109.40",11.663,18.28533,
"109.60",11.678,18.31867,
"109.80",11.696,18.352,
"110.00",11.712,18.38533,
"110.20",11.728,18.41867,
"110.40",11.745,18.452,
"110.60",11.762,18.48533,
"110.80",11.779,18.51867,
"111.00",11.798,18.552,
"111.20",11.817,18.58533,
"111.40",11.831,18.619,
"111.60",11.848,18.65233,
"111.80",11.865,18.68533,
"112.00",11.884,18.71867,
"112.20",11.901,18.752,
"112.40",11.915,18.78533,
"112.60",11.931,18.81867,
"112.80",11.949,18.852,
"113.00",11.965,18.88533,
"113.20",11.979,18.91867,
"113.40",11.992,18.952,
"113.60",12.008,18.98533,
"113.80",12.022,19.01867,
"114.00",12.04,19.052,
"114.20",12.059,19.08533,
"114.40",12.073,19.11867,
"114.60",12.089,19.15233,
"114.80",12.106,19.18567,
"115.00",12.126,19.219,
"115.20",12.144,19.252,
"115.40",12.161,19.28567,
"115.60",12.18,19.319,
"115.80",12.201,19.35233,
"116.00",12.22,19.38533,
"116.20",12.232,19.41867,
"116.40",12.25,19.452,
"116.60",12.265,19.48533,
"116.80",12.287,19.519,
"117.00",12.304,19.552,
"117.20",12.318,19.58533,
"117.40",12.331,19.61867,
"117.60",12.347,19.652,
"117.80",12.362,19.68533,
"118.00",12.383,19.71867,
"118.20",12.397,19.752,
"118.40",12.414,19.78533,
"118.60",12.433,19.81867,
"118.80",12.453,19.85233,
"119.00",12.473,19.88533,
"119.20",12.491,19.919,
"119.40",12.508,19.95233,
"119.60",12.524,19.98567,
"119.80",12.544,20.019,
"120.00",12.562,20.052,
"120.20",12.579,20.08533,
"120.40",12.594,20.11867,
"120.60",12.608,20.152,
"120.80",12.626,20.18567,
"121.00",12.641,20.219,
"121.20",12.654,20.25233,
"121.40",12.67,20.28567,
"121.60",12.682,20.319,
"121.80",12.696,20.352,
"122.00",12.708,20.38533,
"122.20",12.721,20.41867,
"122.40",12.731,20.452,
"122.60",12.744,20.48533,
"122.80",12.758,20.51867,
"123.00",12.777,20.552,
"123.20",12.793,20.58533,
"123.40",12.808,20.61867,
"123.60",12.825,20.652,
"123.80",12.843,20.68533,
"124.00",12.862,20.71867,
"124.20",12.88,20.752,
"124.40",12.896,20.78533,
"124.60",12.911,20.81867,
"124.80",12.927,20.852,
"125.00",12.945,20.88533,
"125.20",12.961,20.91833,
"125.40",12.971,20.95167,
"125.60",12.989,20.98533,
"125.80",13.007,21.01867,
"126.00",13.024,21.052,
"126.20",13.041,21.08533,
"126.40",13.056,21.11867,
"126.60",13.067,21.152,
"126.80",13.086,21.18533,
"127.00",13.102,21.21867,
"127.20",13.116,21.252,
"127.40",13.127,21.28533,
"127.60",13.143,21.31867,
"127.80",13.158,21.352,
"128.00",13.177,21.38533,
"128.20",13.19,21.41867,
"128.40",13.202,21.452,
"128.60",13.216,21.48533,
"128.80",13.23,21.51867,
"129.00",13.244,21.552,
"129.20",13.262,21.58533,
"129.40",13.276,21.619,
"129.60",13.29,21.65233,
"129.80",13.305,21.68567,
"130.00",13.321,21.719,
"130.20",13.335,21.752,
"130.40",13.346,21.78533,
"130.60",13.364,21.819,
"130.80",13.376,21.85233,
"131.00",13.392,21.88533,
"131.20",13.406,21.91867,
"131.40",13.421,21.95233,
"131.60",13.437,21.98533,
"131.80",13.453,22.019,
"132.00",13.468,22.052,
"132.20",13.485,22.08533,
"132.40",13.498,22.11867,
"132.60",13.512,22.152,
"132.80",13.529,22.18533,
"133.00",13.548,22.21867,
"133.20",13.564,22.252,
"133.40",13.579,22.28533,
"133.60",13.594,22.319,
"133.80",13.611,22.35233,
"134.00",13.63,22.38533,
"134.20",13.646,22.41867,
"134.40",13.664,22.452,
"134.60",13.679,22.48533,
"134.80",13.694,22.519,
"135.00",13.713,22.55233,
"135.20",13.73,22.58533,
"135.40",13.744,22.619,
"135.60",13.757,22.65233,
"135.80",13.772,22.68533,
"136.00",13.79,22.71867,
"136.20",13.801,22.752,
"136.40",13.813,22.78533,
"136.60",13.828,22.81867,
"136.80",13.844,22.85233,
"137.00",13.86,22.88533,
"137.20",13.875,22.91867,
"137.40",13.883,22.952,
"137.60",13.894,22.98533,
"137.80",13.914,23.01867,
"138.00",13.931,23.052,
"138.20",13.946,23.08533,
"138.40",13.961,23.11867,
"138.60",13.973,23.152,
"138.80",13.989,23.18533,
"139.00",14.005,23.21867,
"139.20",14.016,23.252,
"139.40",14.026,23.28533,
"139.60",14.036,23.31867,
"139.80",14.048,23.352,
"140.00",14.062,23.38533,
"140.20",14.073,23.41867,
"140.40",14.082,23.452,
"140.60",14.097,23.48533,
"140.80",14.109,23.51867,
"141.00",14.125,23.552,
"141.20",14.139,23.58533,
"141.40",14.154,23.61867,
"141.60",14.168,23.652,
"141.80",14.185,23.68533,
"142.00",14.203,23.71867,
"142.20",14.218,23.752,
"142.40",14.226,23.78533,
"142.60",14.238,23.81867,
"142.80",14.252,23.852,
"143.00",14.268,23.88533,
"143.20",14.281,23.91867,
"143.40",14.292,23.952,
"143.60",14.304,23.98567,
"143.80",14.316,24.01867,
"144.00",14.331,24.052,
"144.20",14.346,24.08533,
"144.40",14.362,24.11867,
"144.60",14.374,24.152,
"144.80",14.387,24.18533,
"145.00",14.404,24.21867,
"145.20",14.421,24.252,
"145.40",14.433,24.28533,
"145.60",14.443,24.31867,
"145.80",14.459,24.352,
"146.00",14.468,24.38533,
"146.20",14.477,24.41867,
"146.40",14.484,24.452,
"146.60",14.493,24.48533,
"146.80",14.504,24.51867,
"147.00",14.52,24.552,
"147.20",14.533,24.58533,
"147.40",14.546,24.61867,
"147.60",14.554,24.652,
"147.80",14.567,24.68533,
"148.00",14.583,24.71867,
"148.20",14.598,24.752,
"148.40",14.609,24.78533,
"148.60",14.624,24.81867,
"148.80",14.638,24.852,
"149.00",14.656,24.88533,
"149.20",14.673,24.91867,
"149.40",14.689,24.952,
"149.60",14.7,24.98533,
"149.80",14.718,25.01867,
"150.00",14.732,25.05167,
"150.20",14.744,25.08533,
"150.40",14.758,25.11867,
"150.60",14.773,25.152,
"150.80",14.786,25.18533,
"151.00",14.799,25.21867,
"151.20",14.812,25.252,
"151.40",14.823,25.28533,
"151.60",14.839,25.31867,
"151.80",14.854,25.352,
"152.00",14.871,25.38533,
"152.20",14.887,25.41867,
"152.40",14.896,25.452,
"152.60",14.914,25.485,
"152.80",14.925,25.51867,
"153.00",14.942,25.552,
"153.20",14.955,25.58533,
"153.40",14.968,25.61867,
"153.60",14.983,25.652,
"153.80",14.996,25.68533,
"154.00",15.015,25.71833,
"154.20",15.029,25.752,
"154.40",15.04,25.785,
"154.60",15.056,25.81867,
"154.80",15.069,25.852,
"155.00",15.083,25.885,
"155.20",15.098,25.91833,
"155.40",15.106,25.95167,
"155.60",15.119,25.985,
"155.80",15.133,26.01867,
"156.00",15.145,26.052,
"156.20",15.16,26.08533,
"156.40",15.173,26.11867,
"156.60",15.183,26.152,
"156.80",15.198,26.18533,
"157.00",15.212,26.21867,
"157.20",15.223,26.252,
"157.40",15.232,26.28533,
"157.60",15.244,26.319,
"157.80",15.259,26.352,
"158.00",15.272,26.38533,
"158.20",15.284,26.41867,
"158.40",15.294,26.452,
"158.60",15.308,26.48533,
"158.80",15.317,26.51867,
"159.00",15.331,26.552,
"159.20",15.342,26.58567,
"159.40",15.35,26.619,
"159.60",15.36,26.65233,
"159.80",15.373,26.68567,
"160.00",15.384,26.719,
"160.20",15.396,26.75233,
"160.40",15.407,26.78533,
"160.60",15.416,26.81867,
"160.80",15.432,26.852,
"161.00",15.448,26.88533,
"161.20",15.458,26.91867,
"161.40",15.468,26.952,
"161.60",15.481,26.98533,
"161.80",15.496,27.01867,
"162.00",15.512,27.052,
"162.20",15.528,27.08533,
"162.40",15.535,27.11867,
"162.60",15.547,27.15167,
"162.80",15.558,27.18533,
"163.00",15.572,27.21833,
"163.20",15.584,27.25167,
"163.40",15.591,27.285,
"163.60",15.602,27.31833,
"163.80",15.614,27.352,
"164.00",15.628,27.38533,
"164.20",15.64,27.41867,
"164.40",15.653,27.452,
"164.60",15.661,27.48533,
"164.80",15.673,27.51867,
"165.00",15.689,27.552,
"165.20",15.701,27.58533,
"165.40",15.712,27.61867,
"165.60",15.726,27.652,
"165.80",15.739,27.68533,
"166.00",15.753,27.71867,
"166.20",15.761,27.752,
"166.40",15.77,27.78533,
"166.60",15.78,27.81867,
"166.80",15.789,27.85233,
"167.00",15.799,27.88533,
"167.20",15.812,27.91867,
"167.40",15.816,27.952,
"167.60",15.822,27.98533,
"167.80",15.837,28.01867,
"168.00",15.85,28.052,
"168.20",15.863,28.08533,
"168.40",15.87,28.11867,
"168.60",15.879,28.152,
"168.80",15.889,28.18533,
"169.00",15.906,28.21867,
"169.20",15.919,28.252,
"169.40",15.929,28.28533,
"169.60",15.941,28.31867,
"169.80",15.954,28.352,
"170.00",15.968,28.38533,
"170.20",15.98,28.41867,
"170.40",15.991,28.452,
"170.60",16.004,28.48533,
"170.80",16.016,28.51867,
"171.00",16.028,28.552,
"171.20",16.032,28.58533,
"171.40",16.039,28.61833,
"171.60",16.046,28.652,
"171.80",16.059,28.68533,
"172.00",16.071,28.71867,
"172.20",16.084,28.752,
"172.40",16.092,28.78533,
"172.60",16.105,28.81867,
"172.80",16.124,28.852,
"173.00",16.138,28.885,
"173.20",16.15,28.91833,
"173.40",16.163,28.952,
"173.60",16.172,28.985,
"173.80",16.188,29.01867,
"174.00",16.206,29.05167,
"174.20",16.224,29.08533,
"174.40",16.232,29.11867,
"174.60",16.245,29.152,
"174.80",16.254,29.18533,
"175.00",16.271,29.21833,
"175.20",16.278,29.252,
"175.40",16.29,29.28533,
"175.60",16.302,29.31867,
"175.80",16.314,29.352,
"176.00",16.326,29.38533,
"176.20",16.336,29.41867,
"176.40",16.348,29.452,
"176.60",16.357,29.48533,
"176.80",16.37,29.51867,
"177.00",16.379,29.552,
"177.20",16.39,29.58533,
"177.40",16.394,29.61867,
"177.60",16.405,29.652,
"177.80",16.413,29.68533,
"178.00",16.427,29.71833,
"178.20",16.438,29.752,
"178.40",16.444,29.785,
"178.60",16.452,29.81833,
"178.80",16.462,29.85167,
"179.00",16.468,29.885,
"179.20",16.481,29.91867,
"179.40",16.491,29.952,
"179.60",16.498,29.98533,
"179.80",16.508,30.01867,
"180.00",16.519,30.052,
"180.20",16.526,30.085,
"180.40",16.54,30.11833,
"180.60",16.547,30.15167,
"180.80",16.56,30.185,
"181.00",16.572,30.21833,
"181.20",16.583,30.25167,
"181.40",16.592,30.28533,
"181.60",16.601,30.31867,
"181.80",16.612,30.352,
"182.00",16.621,30.385,
"182.20",16.631,30.41867,
"182.40",16.637,30.452,
"182.60",16.645,30.48533,
"182.80",16.652,30.51867,
"183.00",16.666,30.552,
"183.20",16.677,30.58533,
"183.40",16.685,30.61867,
"183.60",16.69,30.652,
"183.80",16.699,30.68533,
"184.00",16.712,30.71867,
"184.20",16.726,30.752,
"184.40",16.734,30.78533,
"184.60",16.744,30.81867,
"184.80",16.755,30.852,
"185.00",16.767,30.885,
"185.20",16.78,30.91867,
"185.40",16.791,30.952,
"185.60",16.801,30.98533,
"185.80",16.812,31.01867,
"186.00",16.821,31.052,
"186.20",16.832,31.08533,
"186.40",16.84,31.11867,
"186.60",16.852,31.152,
"186.80",16.863,31.18533,
"187.00",16.879,31.21867,
"187.20",16.886,31.252,
"187.40",16.892,31.28533,
"187.60",16.897,31.31867,
"187.80",16.907,31.352,
"188.00",16.915,31.38533,
"188.20",16.927,31.41867,
"188.40",16.93,31.452,
"188.60",16.938,31.48533,
"188.80",16.945,31.51867,
"189.00",16.953,31.55167,
"189.20",16.963,31.585,
"189.40",16.973,31.61867,
"189.60",16.984,31.652,
"189.80",16.996,31.68533,
"190.00",17.012,31.71867,
"190.20",17.026,31.752,
"190.40",17.042,31.78533,
"190.60",17.057,31.81867,
"190.80",17.07,31.852,
"191.00",17.09,31.885,
"191.20",17.103,31.91867,
"191.40",17.116,31.952,
"191.60",17.132,31.98533,
"191.80",17.147,32.01867,
"192.00",17.165,32.052,
"192.20",17.179,32.08533,
"192.40",17.19,32.11867,
"192.60",17.202,32.152,
"192.80",17.215,32.18533,
"193.00",17.231,32.21867,
"193.20",17.245,32.252,
"193.40",17.254,32.28567,
"193.60",17.261,32.319,
"193.80",17.273,32.352,
"194.00",17.287,32.38533,
"194.20",17.3,32.419,
"194.40",17.31,32.452,
"194.60",17.315,32.48533,
"194.80",17.323,32.519,
"195.00",17.328,32.552,
"195.20",17.334,32.58533,
"195.40",17.34,32.61867,
"195.60",17.346,32.652,
"195.80",17.353,32.68567,
"196.00",17.362,32.719,
"196.20",17.366,32.75233,
"196.40",17.37,32.78534,
"196.60",17.371,32.81867,
"196.80",17.376,32.852,
"197.00",17.381,32.88533,
"197.20",17.387,32.91867,
"197.40",17.388,32.952,
"197.60",17.392,32.98533,
"197.80",17.401,33.01867,
"198.00",17.414,33.052,
"198.20",17.427,33.08533,
"198.40",17.437,33.11867,
"198.60",17.448,33.152,
"198.80",17.463,33.18533,
"199.00",17.479,33.21867,
"199.20",17.492,33.252,
"199.40",17.509,33.28534,
"199.60",17.516,33.31867,
"199.80",17.529,33.35167,
"200.00",17.545,33.385,
"200.20",17.557,33.41833,
"200.40",17.565,33.45167,
"200.60",17.582,33.485,
"200.80",17.596,33.51867,
"201.00",17.611,33.55167,
"201.20",17.62,33.58533,
"201.40",17.63,33.61867,
"201.60",17.639,33.652,
"201.80",17.652,33.68533,
"202.00",17.666,33.71867,
"202.20",17.676,33.752,
"202.40",17.684,33.78534,
"202.60",17.691,33.81867,
"202.80",17.701,33.852,
"203.00",17.714,33.88533,
"203.20",17.723,33.91867,
"203.40",17.726,33.952,
"203.60",17.732,33.98533,
"203.80",17.738,34.01867,
"204.00",17.747,34.052,
"204.20",17.754,34.08533,
"204.40",17.756,34.11867,
"204.60",17.761,34.152,
"204.80",17.764,34.18533,
"205.00",17.774,34.21833,
"205.20",17.778,34.252,
"205.40",17.784,34.28534,
"205.60",17.789,34.31867,
"205.80",17.797,34.352,
"206.00",17.806,34.38533,
"206.20",17.813,34.41833,
"206.40",17.816,34.45167,
"206.60",17.822,34.48533,
"206.80",17.829,34.51833,
"207.00",17.838,34.55167,
"207.20",17.842,34.585,
"207.40",17.849,34.61834,
"207.60",17.858,34.652,
"207.80",17.867,34.68533,
"208.00",17.879,34.71867,
"208.20",17.894,34.752,
"208.40",17.901,34.78534,
"208.60",17.909,34.81867,
"208.80",17.92,34.852,
"209.00",17.933,34.885,
"209.20",17.944,34.91867,
"209.40",17.952,34.952,
"209.60",17.961,34.98533,
"209.80",17.97,35.01867,
"210.00",17.98,35.052,
"210.20",17.99,35.08533,
"210.40",17.998,35.11867,
"210.60",18.008,35.152,
"210.80",18.02,35.18533,
"211.00",18.032,35.21867,
"211.20",18.04,35.252,
"211.40",18.047,35.28534,
"211.60",18.057,35.31867,
"211.80",18.069,35.352,
"212.00",18.08,35.38533,
"212.20",18.089,35.41867,
"212.40",18.097,35.452,
"212.60",18.108,35.48533,
"212.80",18.119,35.51867,
"213.00",18.136,35.552,
"213.20",18.146,35.58533,
"213.40",18.153,35.61867,
"213.60",18.162,35.65233,
"213.80",18.173,35.68567,
"214.00",18.186,35.719,
"214.20",18.196,35.75233,
"214.40",18.201,35.78567,
"214.60",18.204,35.81867,
"214.80",18.208,35.852,
"215.00",18.215,35.885,
"215.20",18.221,35.91867,
"215.40",18.226,35.952,
"215.60",18.233,35.985,
"215.80",18.24,36.01867,
"216.00",18.247,36.05167,
"216.20",18.255,36.08533,
"216.40",18.262,36.11834,
"216.60",18.27,36.152,
"216.80",18.281,36.18533,
"217.00",18.288,36.21867,
"217.20",18.294,36.25167,
"217.40",18.3,36.28534,
"217.60",18.305,36.31867,
"217.80",18.312,36.352,
"218.00",18.325,36.38533,
"218.20",18.331,36.41867,
"218.40",18.335,36.452,
"218.60",18.336,36.48533,
"218.80",18.343,36.51867,
"219.00",18.354,36.552,
"219.20",18.362,36.58533,
"219.40",18.367,36.619,
"219.60",18.372,36.65233,
"219.80",18.375,36.68533,
"220.00",18.384,36.71867,
"220.20",18.393,36.752,
"220.40",18.397,36.78534,
"220.60",18.402,36.81867,
"220.80",18.409,36.852,
"221.00",18.42,36.88533,
"221.20",18.43,36.91867,
"221.40",18.435,36.952,
"221.60",18.443,36.98533,
"221.80",18.449,37.01867,
"222.00",18.459,37.052,
"222.20",18.467,37.08533,
"222.40",18.475,37.11867,
"222.60",18.483,37.15167,
"222.80",18.494,37.18533,
"223.00",18.508,37.21867,
"223.20",18.519,37.252,
"223.40",18.528,37.28534,
"223.60",18.538,37.31867,
"223.80",18.552,37.352,
"224.00",18.567,37.38533,
"224.20",18.579,37.41867,
"224.40",18.585,37.452,
"224.60",18.594,37.48533,
"224.80",18.606,37.51867,
"225.00",18.618,37.552,
"225.20",18.63,37.58533,
"225.40",18.638,37.61867,
"225.60",18.643,37.652,
"225.80",18.651,37.68533,
"226.00",18.656,37.71867,
"226.20",18.663,37.752,
"226.40",18.668,37.78534,
"226.60",18.671,37.81867,
"226.80",18.68,37.852,
"227.00",18.688,37.88533,
"227.20",18.698,37.91867,
"227.40",18.705,37.952,
"227.60",18.713,37.98533,
"227.80",18.723,38.01867,
"228.00",18.735,38.052,
"228.20",18.749,38.08533,
"228.40",18.753,38.11867,
"228.60",18.76,38.152,
"228.80",18.769,38.18533,
"229.00",18.78,38.21867,
"229.20",18.792,38.252,
"229.40",18.797,38.285,
"229.60",18.805,38.31867,
"229.80",18.814,38.352,
"230.00",18.827,38.38533,
"230.20",18.835,38.41867,
"230.40",18.845,38.452,
"230.60",18.852,38.48533,
"230.80",18.858,38.51867,
"231.00",18.867,38.552,
"231.20",18.873,38.58533,
"231.40",18.875,38.61867,
"231.60",18.878,38.652,
"231.80",18.882,38.68533,
"232.00",18.893,38.71867,
"232.20",18.9,38.752,
"232.40",18.909,38.785,
"232.60",18.915,38.81833,
"232.80",18.923,38.85167,
"233.00",18.937,38.88533,
"233.20",18.946,38.91867,
"233.40",18.952,38.952,
"233.60",18.954,38.98533,
"233.80",18.963,39.01867,
"234.00",18.972,39.052,
"234.20",18.975,39.08533,
"234.40",18.985,39.11867,
"234.60",18.989,39.152,
"234.80",18.996,39.18533,
"235.00",19.008,39.21867,
"235.20",19.012,39.252,
"235.40",19.022,39.28534,
"235.60",19.029,39.31867,
"235.80",19.034,39.352,
"236.00",19.043,39.38533,
"236.20",19.045,39.41867,
"236.40",19.049,39.452,
"236.60",19.051,39.48533,
"236.80",19.057,39.51867,
"237.00",19.067,39.552,
"237.20",19.071,39.58533,
"237.40",19.073,39.61867,
"237.60",19.079,39.652,
"237.80",19.092,39.68533,
"238.00",19.104,39.71867,
"238.20",19.113,39.752,
"238.40",19.122,39.78534,
"238.60",19.126,39.81867,
"238.80",19.136,39.852,
"239.00",19.148,39.88533,
"239.20",19.156,39.91867,
"239.40",19.165,39.952,
"239.60",19.173,39.98533,
"239.80",19.184,40.01867,
"240.00",19.194,40.052,
"240.20",19.204,40.08533,
"240.40",19.21,40.11867,
"240.60",19.214,40.152,
"240.75",19.214,40.177,