File: load_extensions/pristine_flourocarbon1.csv
"Test Name","Test Mode","Test Type","Control","Test Speed 1","Test Speed 2","Test Speed 3","Change Point 1","Change Point 2","Disp. Origin","Break and Limit Action","Sensitivity:","Level:"
"","Single","Tensile","Stroke",10,1,1,"Off","Off","Start","Stop",0,1

"Title","Sub title","Comment"
"","",""

"Shape:","Batch Size:","SubBatch Size:"
"Plate",1,1
"Name:","Thickness","Width","Gauge Length",
"Size Unit:","mm","mm","mm",
" 1 - 1","1.0000","1.0000","100.0000",

"Name",
"Parameter",
"Units",
" 1 - 1",

" 1- 1"
"Time","Force","Stroke",
"sec","N","mm",
"0.00",-.003,0,
"0.15",0,.028,
"0.30",.014,5.566667E-02,
"0.45",.035,8.366667E-02,
"0.60",.061,.1113333,
"0.75",.086,.1393333,
"0.90",.111,.167,
"1.05",.135,.195,
"1.20",.163,.2226667,
"1.35",.188,.2503333,
"1.50",.211,.2783333,
"1.65",.237,.306,
"1.80",.262,.3336667,
"1.95",.287,.3613333,
"2.10",.313,.3883333,
"2.25",.337,.4153333,
"2.40",.36,.442,
"2.55",.386,.4683333,
"2.70",.408,.4946667,
"2.85",.434,.5206667,
"3.00",.457,.5463333,
"3.15",.478,.5723333,
"3.30",.503,.5976667,
"3.45",.524,.6233333,
"3.60",.549,.6486667,
"3.75",.57,.6743333,
"3.90",.59,.6996667,
"4.05",.614,.725,
"4.20",.637,.75,
"4.35",.66,.7753333,
"4.50",.684,.8006666,
"4.65",.704,.8256667,
"4.80",.726,.851,
"4.95",.747,.876,
"5.10",.768,.901,
"5.25",.789,.926,
"5.40",.808,.9513333,
"5.55",.831,.9763333,
"5.70",.853,1.001333,
"5.85",.874,1.026333,
"6.00",.893,1.051333,
"6.15",.912,1.076333,
"6.30",.935,1.101333,
"6.45",.954,1.126333,
"6.60",.974,1.151333,
"6.75",.993,1.176667,
"6.90",1.014,1.201333,
"7.05",1.033,1.226667,
"7.20",1.052,1.251667,
"7.35",1.072,1.276667,
"7.50",1.092,1.301667,
"7.65",1.111,1.326667,
"7.80",1.128,1.351333,
"7.95",1.145,1.376333,
"8.10",1.166,1.401667,
"8.25",1.184,1.426667,
"8.40",1.203,1.451667,
"8.55",1.22,1.476667,
"8.70",1.237,1.501667,
"8.85",1.256,1.526667,
"9.00",1.274,1.551667,
"9.15",1.293,1.576667,
"9.30",1.309,1.601667,
"9.45",1.327,1.626667,
"9.60",1.343,1.651667,
"9.75",1.361,1.676667,
"9.90",1.378,1.701667,
"10.05",1.391,1.726667,
"10.20",1.409,1.751667,
"10.35",1.426,1.776333,
"10.50",1.441,1.801667,
"10.65",1.457,1.826667,
"10.80",1.473,1.851333,
"10.95",1.488,1.876333,
"11.10",1.504,1.901333,
"11.25",1.518,1.926667,
"11.40",1.533,1.951667,
"11.55",1.548,1.976667,
"11.70",1.565,2.001667,
"11.85",1.577,2.026667,
"12.00",1.594,2.051666,
"12.15",1.61,2.076667,
"12.30",1.624,2.101667,
"12.45",1.637,2.126667,
"12.60",1.652,2.151667,
"12.75",1.665,2.176666,
"12.90",1.679,2.201333,
"13.05",1.691,2.226667,
"13.20",1.706,2.251667,
"13.35",1.72,2.276333,
"13.50",1.735,2.301333,
"13.65",1.747,2.326333,
"13.80",1.761,2.351667,
"13.95",1.775,2.376667,
"14.10",1.786,2.401667,
"14.25",1.798,2.426666,
"14.40",1.811,2.451667,
"14.55",1.824,2.476667,
"14.70",1.837,2.501667,
"14.85",1.848,2.526667,
"15.00",1.861,2.551666,
"15.15",1.872,2.576667,
"15.30",1.885,2.601667,
"15.45",1.898,2.626667,
"15.60",1.912,2.651667,
"15.75",1.923,2.676666,
"15.90",1.935,2.701333,
"16.05",1.947,2.726333,
"16.20",1.958,2.751667,
"16.35",1.973,2.776667,
"16.50",1.983,2.801666,
"16.65",1.997,2.826667,
"16.80",2.007,2.851667,
"16.95",2.018,2.876667,
"17.10",2.029,2.901667,
"17.25",2.041,2.926666,
"17.40",2.051,2.951667,
"17.55",2.062,2.976667,
"17.70",2.073,3.001667,
"17.85",2.087,3.026667,
"18.00",2.098,3.051666,
"18.15",2.107,3.076667,
"18.30",2.119,3.101667,
"18.45",2.132,3.126667,
"18.60",2.145,3.152,
"18.75",2.155,3.176666,
"18.90",2.168,3.201667,
"19.05",2.177,3.226667,
"19.20",2.188,3.251667,
"19.35",2.201,3.276667,
"19.50",2.212,3.301666,
"19.65",2.224,3.326667,
"19.80",2.237,3.351667,
"19.95",2.248,3.376667,
"20.10",2.257,3.401667,
"20.25",2.267,3.426666,
"20.40",2.28,3.451667,
"20.55",2.293,3.476667,
"20.70",2.306,3.501667,
"20.85",2.314,3.526667,
"21.00",2.327,3.551666,
"21.15",2.337,3.576667,
"21.30",2.348,3.601667,
"21.45",2.359,3.626667,
"21.60",2.37,3.651667,
"21.75",2.38,3.676666,
"21.90",2.391,3.701667,
"22.05",2.404,3.726667,
"22.20",2.417,3.751667,
"22.35",2.428,3.776667,
"22.50",2.437,3.801666,
"22.65",2.448,3.826667,
"22.80",2.459,3.851667,
"22.95",2.469,3.876667,
"23.10",2.477,3.901667,
"23.25",2.491,3.926666,
"23.40",2.504,3.951667,
"23.55",2.514,3.976667,
"23.70",2.522,4.001667,
"23.85",2.533,4.026667,
"24.00",2.546,4.051667,
"24.15",2.558,4.076667,
"24.30",2.57,4.101667,
"24.45",2.584,4.126667,
"24.60",2.593,4.151667,
"24.75",2.604,4.176667,
"24.90",2.617,4.201667,
"25.05",2.627,4.226667,
"25.20",2.641,4.251667,
"25.35",2.652,4.276667,
"25.50",2.664,4.301667,
"25.65",2.676,4.326667,
"25.80",2.688,4.351667,
"25.95",2.699,4.376667,
"26.10",2.711,4.401667,
"26.25",2.722,4.426667,
"26.40",2.734,4.451667,
"26.55",2.748,4.476667,
"26.70",2.76,4.501667,
"26.85",2.77,4.526667,
"27.00",2.784,4.551667,
"27.15",2.795,4.576667,
"27.30",2.81,4.601667,
"27.45",2.823,4.626667,
"27.60",2.835,4.651667,
"27.75",2.846,4.676667,
"27.90",2.859,4.701667,
"28.05",2.873,4.726667,
"28.20",2.883,4.751667,
"28.35",2.896,4.776333,
"28.50",2.909,4.801667,
"28.65",2.92,4.826667,
"28.80",2.934,4.851667,
"28.95",2.947,4.876667,
"29.10",2.958,4.901667,
"29.25",2.973,4.926667,
"29.40",2.986,4.951667,
"29.55",2.997,4.976667,
"29.70",3.007,5.001667,
"29.85",3.022,5.026667,
"30.00",3.033,5.051667,
"30.15",3.043,5.076667,
"30.30",3.057,5.101667,
"30.45",3.071,5.126667,
"30.60",3.084,5.151667,
"30.75",3.096,5.176667,
"30.90",3.107,5.201667,
"31.05",3.12,5.226667,
"31.20",3.133,5.251667,
"31.35",3.147,5.276667,
"31.50",3.16,5.302,
"31.65",3.175,5.326667,
"31.80",3.187,5.351667,
"31.95",3.199,5.376667,
"32.10",3.211,5.401667,
"32.25",3.225,5.426667,
"32.40",3.237,5.451667,
"32.55",3.251,5.476667,
"32.70",3.263,5.501667,
"32.85",3.278,5.526667,
"33.00",3.291,5.551667,
"33.15",3.304,5.576667,
"33.30",3.321,5.601667,
"33.45",3.334,5.626667,
"33.60",3.345,5.651667,
"33.75",3.359,5.676667,
"33.90",3.373,5.701667,
"34.05",3.389,5.726667,
"34.20",3.401,5.751667,
"34.35",3.414,5.776667,
"34.50",3.428,5.801667,
"34.65",3.443,5.826667,
"34.80",3.456,5.851667,
"34.95",3.469,5.877,
"35.10",3.483,5.902,
"35.25",3.499,5.926667,
"35.40",3.514,5.951667,
"35.55",3.529,5.976667,
"35.70",3.542,6.001667,
"35.85",3.553,6.026667,
"36.00",3.568,6.052,
"36.15",3.582,6.077,
"36.30",3.597,6.101667,
"36.45",3.613,6.126667,
"36.60",3.628,6.151667,
"36.75",3.641,6.176667,
"36.90",3.655,6.201667,
"37.05",3.668,6.227,
"37.20",3.681,6.252,
"37.35",3.697,6.276667,
"37.50",3.709,6.301667,
"37.65",3.725,6.326667,
"37.80",3.739,6.351667,
"37.95",3.753,6.376667,
"38.10",3.77,6.401667,
"38.25",3.782,6.426667,
"38.40",3.796,6.451667,
"38.55",3.81,6.476667,
"38.70",3.825,6.501667,
"38.85",3.839,6.526667,
"39.00",3.856,6.551667,
"39.15",3.872,6.576667,
"39.30",3.887,6.601667,
"39.45",3.903,6.626667,
"39.60",3.918,6.651667,
"39.75",3.932,6.676667,
"39.90",3.944,6.701667,
"40.05",3.961,6.726667,
"40.20",3.975,6.751667,
"40.35",3.991,6.776667,
"40.50",4.006,6.801667,
"40.65",4.021,6.827,
"40.80",4.039,6.852,
"40.95",4.05,6.876667,
"41.10",4.064,6.901667,
"41.25",4.082,6.927,
"41.40",4.101,6.951667,
"41.55",4.117,6.976667,
"41.70",4.132,7.001667,
"41.85",4.146,7.026667,
"42.00",4.162,7.051667,
"42.15",4.176,7.076667,
"42.30",4.192,7.101667,
"42.45",4.211,7.126667,
"42.60",4.226,7.151667,
"42.75",4.242,7.176667,
"42.90",4.257,7.201667,
"43.05",4.273,7.226667,
"43.20",4.29,7.251667,
"43.35",4.307,7.276667,
"43.50",4.324,7.301667,
"43.65",4.34,7.326667,
"43.80",4.356,7.351667,
"43.95",4.371,7.376667,
"44.10",4.388,7.401667,
"44.25",4.405,7.426667,
"44.40",4.423,7.451667,
"44.55",4.44,7.476667,
"44.70",4.456,7.501667,
"44.85",4.468,7.526667,
"45.00",4.486,7.551667,
"45.15",4.504,7.576667,
"45.30",4.521,7.601667,
"45.45",4.537,7.626667,
"45.60",4.555,7.651667,
"45.75",4.571,7.676667,
"45.90",4.585,7.701667,
"46.05",4.602,7.726667,
"46.20",4.619,7.751667,
"46.35",4.636,7.776667,
"46.50",4.654,7.801667,
"46.65",4.67,7.826667,
"46.80",4.685,7.851667,
"46.95",4.699,7.876667,
"47.10",4.719,7.901667,
"47.25",4.734,7.926667,
"47.40",4.752,7.951667,
"47.55",4.767,7.976667,
"47.70",4.783,8.001666,
"47.85",4.801,8.026667,
"48.00",4.816,8.051666,
"48.15",4.836,8.076667,
"48.30",4.851,8.101666,
"48.45",4.868,8.126666,
"48.60",4.884,8.151999,
"48.75",4.898,8.177,
"48.90",4.914,8.201667,
"49.05",4.931,8.226666,
"49.20",4.948,8.251666,
"49.35",4.966,8.276667,
"49.50",4.981,8.301666,
"49.65",4.996,8.326667,
"49.80",5.014,8.351666,
"49.95",5.03,8.376666,
"50.10",5.047,8.401667,
"50.25",5.066,8.426666,
"50.40",5.083,8.451667,
"50.55",5.097,8.476666,
"50.70",5.115,8.502,
"50.85",5.132,8.526667,
"51.00",5.15,8.551666,
"51.15",5.165,8.576667,
"51.30",5.184,8.601666,
"51.45",5.2,8.626666,
"51.60",5.218,8.651667,
"51.75",5.236,8.676666,
"51.90",5.252,8.701667,
"52.05",5.266,8.726666,
"52.20",5.285,8.752,
"52.35",5.305,8.776667,
"52.50",5.321,8.801666,
"52.65",5.341,8.827,
"52.80",5.356,8.851666,
"52.95",5.375,8.877,
"53.10",5.392,8.901999,
"53.25",5.413,8.927,
"53.40",5.432,8.951667,
"53.55",5.45,8.976666,
"53.70",5.466,9.001666,
"53.85",5.486,9.026667,
"54.00",5.507,9.051666,
"54.15",5.524,9.077,
"54.30",5.541,9.101666,
"54.45",5.562,9.127,
"54.60",5.58,9.151999,
"54.75",5.599,9.177,
"54.90",5.612,9.202,
"55.05",5.63,9.226666,
"55.20",5.65,9.251666,
"55.35",5.67,9.276667,
"55.50",5.688,9.301666,
"55.65",5.708,9.326667,
"55.80",5.727,9.351666,
"55.95",5.748,9.376666,
"56.10",5.762,9.401667,
"56.25",5.782,9.426666,
"56.40",5.804,9.451667,
"56.55",5.821,9.476666,
"56.70",5.839,9.501666,
"56.85",5.858,9.526667,
"57.00",5.876,9.551666,
"57.15",5.895,9.576667,
"57.30",5.912,9.601666,
"57.45",5.933,9.626666,
"57.60",5.952,9.651667,
"57.75",5.97,9.676666,
"57.90",5.989,9.701667,
"58.05",6.008,9.726666,
"58.20",6.028,9.751666,
"58.35",6.049,9.776667,
"58.50",6.068,9.801666,
"58.65",6.09,9.826667,
"58.80",6.107,9.851666,
"58.95",6.128,9.876666,
"59.10",6.146,9.901667,
"59.25",6.165,9.926666,
"59.40",6.187,9.951667,
"59.55",6.208,9.976666,
"59.70",6.225,10.00167,
"59.85",6.243,10.02667,
"60.00",6.263,10.05167,
"60.15",6.283,10.07667,
"60.30",6.302,10.10167,
"60.45",6.324,10.12667,
"60.60",6.343,10.15167,
"60.75",6.361,10.17667,
"60.90",6.381,10.20167,
"61.05",6.401,10.22667,
"61.20",6.422,10.25167,
"61.35",6.443,10.27667,
"61.50",6.466,10.30167,
"61.65",6.485,10.32667,
"61.80",6.503,10.35167,
"61.95",6.522,10.37633,
"62.10",6.542,10.40167,
"62.25",6.565,10.42667,
"62.40",6.589,10.45167,
"62.55",6.608,10.47667,
"62.70",6.628,10.50167,
"62.85",6.649,10.52667,
"63.00",6.672,10.55167,
"63.15",6.69,10.57667,
"63.30",6.71,10.60167,
"63.45",6.735,10.62667,
"63.60",6.755,10.65167,
"63.75",6.775,10.67667,
"63.90",6.795,10.70167,
"64.05",6.815,10.72667,
"64.20",6.836,10.75167,
"64.35",6.861,10.77667,
"64.50",6.884,10.80167,
"64.65",6.904,10.82667,
"64.80",6.923,10.85167,
"64.95",6.943,10.87667,
"65.10",6.964,10.90167,
"65.25",6.989,10.92667,
"65.40",7.013,10.95167,
"65.55",7.034,10.97667,
"65.70",7.055,11.00167,
"65.85",7.077,11.02667,
"66.00",7.097,11.05167,
"66.15",7.117,11.07667,
"66.30",7.142,11.10167,
"66.45",7.165,11.12667,
"66.60",7.188,11.15167,
"66.75",7.208,11.17667,
"66.90",7.227,11.20167,
"67.05",7.252,11.22667,
"67.20",7.274,11.25167,
"67.35",7.298,11.27667,
"67.50",7.321,11.30167,
"67.65",7.345,11.32667,
"67.80",7.367,11.35167,
"67.95",7.388,11.37633,
"68.10",7.412,11.40167,
"68.25",7.436,11.42633,
"68.40",7.458,11.45167,
"68.55",7.482,11.47667,
"68.70",7.501,11.50167,
"68.85",7.524,11.52667,
"69.00",7.547,11.55167,
"69.15",7.571,11.57667,
"69.30",7.594,11.60167,
"69.45",7.616,11.62667,
"69.60",7.64,11.65167,
"69.75",7.666,11.67667,
"69.90",7.687,11.70167,
"70.05",7.709,11.72667,
"70.20",7.734,11.75167,
"70.35",7.759,11.77667,
"70.50",7.781,11.80167,
"70.65",7.803,11.82667,
"70.80",7.825,11.85167,
"70.95",7.848,11.87667,
"71.10",7.871,11.90167,
"71.25",7.896,11.92667,
"71.40",7.921,11.95167,
"71.55",7.944,11.97667,
"71.70",7.968,12.00167,
"71.85",7.992,12.02633,
"72.00",8.014,12.05167,
"72.15",8.038,12.07667,
"72.30",8.06,12.10167,
"72.45",8.085,12.12667,
"72.60",8.108,12.15167,
"72.75",8.131,12.17667,
"72.90",8.154,12.20167,
"73.05",8.178,12.22667,
"73.20",8.201,12.25167,
"73.35",8.227,12.27667,
"73.50",8.252,12.30167,
"73.65",8.275,12.32667,
"73.80",8.3,12.35167,
"73.95",8.323,12.37667,
"74.10",8.345,12.40167,
"74.25",8.373,12.42667,
"74.40",8.397,12.45167,
"74.55",8.419,12.47667,
"74.70",8.441,12.50167,
"74.85",8.467,12.52667,
"75.00",8.493,12.55167,
"75.15",8.519,12.57667,
"75.30",8.543,12.60167,
"75.45",8.566,12.62667,
"75.60",8.591,12.65133,
"75.75",8.616,12.67667,
"75.90",8.641,12.70167,
"76.05",8.664,12.72667,
"76.20",8.687,12.75167,
"76.35",8.713,12.77633,
"76.50",8.739,12.80167,
"76.65",8.765,12.82667,
"76.80",8.79,12.85167,
"76.95",8.813,12.87667,
"77.10",8.839,12.90167,
"77.25",8.866,12.92667,
"77.40",8.892,12.95167,
"77.55",8.918,12.97667,
"77.70",8.942,13.00167,
"77.85",8.968,13.02667,
"78.00",8.994,13.05167,
"78.15",9.02,13.07667,
"78.30",9.053,13.10133,
"78.45",9.079,13.12667,
"78.60",9.105,13.15167,
"78.75",9.129,13.17667,
"78.90",9.155,13.20167,
"79.05",9.184,13.22667,
"79.20",9.211,13.25167,
"79.35",9.239,13.27667,
"79.50",9.266,13.30167,
"79.65",9.29,13.32667,
"79.80",9.317,13.35167,
"79.95",9.339,13.37667,
"80.10",9.367,13.40167,
"80.25",9.396,13.42667,
"80.40",9.424,13.45167,
"80.55",9.452,13.47667,
"80.70",9.476,13.50167,
"80.85",9.502,13.52667,
"81.00",9.528,13.55167,
"81.15",9.557,13.57667,
"81.30",9.583,13.60167,
"81.45",9.61,13.62667,
"81.60",9.64,13.65167,
"81.75",9.668,13.67667,
"81.90",9.693,13.70167,
"82.05",9.717,13.72667,
"82.20",9.748,13.75167,
"82.35",9.774,13.77667,
"82.50",9.801,13.80167,
"82.65",9.831,13.82667,
"82.80",9.857,13.85167,
"82.95",9.885,13.87667,
"83.10",9.912,13.90167,
"83.25",9.941,13.92667,
"83.40",9.971,13.95167,
"83.55",10,13.97667,
"83.70",10.03,14.00167,
"83.85",10.057,14.02667,
"84.00",10.086,14.05167,
"84.15",10.119,14.07667,
"84.30",10.151,14.10167,
"84.45",10.177,14.12667,
"84.60",10.206,14.15167,
"84.75",10.232,14.17667,
"84.90",10.26,14.20167,
"85.05",10.292,14.22667,
"85.20",10.32,14.25167,
"85.35",10.354,14.27667,
"85.50",10.385,14.30167,
"85.65",10.413,14.32667,
"85.80",10.441,14.35167,
"85.95",10.469,14.37667,
"86.10",10.502,14.40167,
"86.25",10.532,14.42667,
"86.40",10.565,14.45167,
"86.55",10.594,14.47667,
"86.70",10.622,14.50167,
"86.85",10.651,14.52667,
"87.00",10.678,14.55167,
"87.15",10.709,14.57667,
"87.30",10.742,14.60167,
"87.45",10.771,14.62667,
"87.60",10.799,14.65167,
"87.75",10.827,14.67667,
"87.90",10.858,14.70167,
"88.05",10.89,14.72667,
"88.20",10.92,14.75167,
"88.35",10.952,14.77667,
"88.50",10.981,14.80167,
"88.65",11.001,14.82667,
"88.80",11.027,14.85167,
"88.95",11.06,14.87667,
"89.10",11.09,14.90167,
"89.25",11.124,14.92667,
"89.40",11.155,14.95167,
"89.55",11.185,14.97667,
"89.70",11.216,15.00167,
"89.85",11.247,15.02667,
"90.00",11.279,15.05167,
"90.15",11.309,15.07667,
"90.30",11.342,15.10167,
"90.45",11.376,15.12667,
"90.60",11.408,15.15167,
"90.75",11.436,15.17667,
"90.90",11.465,15.20167,
"91.05",11.493,15.22667,
"91.20",11.526,15.25167,
"91.35",11.559,15.27667,
"91.50",11.594,15.30167,
"91.65",11.623,15.32667,
"91.80",11.652,15.35167,
"91.95",11.684,15.37667,
"92.10",11.719,15.40167,
"92.25",11.751,15.42667,
"92.40",11.782,15.45167,
"92.55",11.813,15.47667,
"92.70",11.847,15.50167,
"92.85",11.878,15.52667,
"93.00",11.91,15.55167,
"93.15",11.945,15.57633,
"93.30",11.979,15.60133,
"93.45",12.013,15.62633,
"93.60",12.044,15.65133,
"93.75",12.074,15.67667,
"93.90",12.108,15.70167,
"94.05",12.141,15.72633,
"94.20",12.176,15.75133,
"94.35",12.21,15.77633,
"94.50",12.243,15.80167,
"94.65",12.275,15.82667,
"94.80",12.31,15.85167,
"94.95",12.343,15.87633,
"95.10",12.376,15.90133,
"95.25",12.41,15.92633,
"95.40",12.446,15.95133,
"95.55",12.483,15.97633,
"95.70",12.518,16.00133,
"95.85",12.549,16.02633,
"96.00",12.578,16.05133,
"96.15",12.615,16.07667,
"96.30",12.65,16.10133,
"96.45",12.685,16.12667,
"96.60",12.721,16.15167,
"96.75",12.748,16.17667,
"96.90",12.778,16.20167,
"97.05",12.812,16.22667,
"97.20",12.848,16.25167,
"97.35",12.883,16.27667,
"97.50",12.915,16.30167,
"97.65",12.947,16.32633,
"97.80",12.979,16.35167,
"97.95",13.013,16.37667,
"98.10",13.048,16.40167,
"98.25",13.084,16.42667,
"98.40",13.117,16.45167,
"98.55",13.155,16.47667,
"98.70",13.186,16.50167,
"98.85",13.215,16.52667,
"99.00",13.249,16.55167,
"99.15",13.284,16.57667,
"99.30",13.322,16.60167,
"99.45",13.36,16.62667,
"99.60",13.394,16.65167,
"99.75",13.425,16.67667,
"99.90",13.46,16.70133,
"100.05",13.493,16.72667,
"100.20",13.529,16.75167,
"100.35",13.57,16.77633,
"100.50",13.602,16.80167,
"100.65",13.637,16.82667,
"100.80",13.672,16.85167,
"100.95",13.706,16.87667,
"101.10",13.74,16.90167,
"101.25",13.776,16.92667,
"101.40",13.812,16.95167,
"101.55",13.847,16.97667,
"101.70",13.884,17.00167,
"101.85",13.917,17.02667,
"102.00",13.954,17.05167,
"102.15",13.988,17.07667,
"102.30",14.022,17.10167,
"102.45",14.061,17.12667,
"102.60",14.095,17.15167,
"102.75",14.129,17.17667,
"102.90",14.164,17.20167,
"103.05",14.2,17.22667,
"103.20",14.237,17.25167,
"103.35",14.278,17.277,
"103.50",14.314,17.302,
"103.65",14.349,17.32667,
"103.80",14.383,17.35167,
"103.95",14.419,17.37667,
"104.10",14.457,17.40167,
"104.25",14.494,17.42667,
"104.40",14.534,17.45167,
"104.55",14.568,17.47667,
"104.70",14.604,17.502,
"104.85",14.639,17.52667,
"105.00",14.674,17.55167,
"105.15",14.711,17.57667,
"105.30",14.75,17.60167,
"105.45",14.79,17.62667,
"105.60",14.826,17.65167,
"105.75",14.86,17.67667,
"105.90",14.902,17.70167,
"106.05",14.938,17.72667,
"106.20",14.974,17.75167,
"106.35",15.015,17.77667,
"106.50",15.053,17.80167,
"106.65",15.088,17.82667,
"106.80",15.124,17.85167,
"106.95",15.159,17.87667,
"107.10",15.198,17.90167,
"107.25",15.237,17.92667,
"107.40",15.276,17.95167,
"107.55",15.314,17.97633,
"107.70",15.349,18.00133,
"107.85",15.386,18.02633,
"108.00",15.424,18.05133,
"108.15",15.466,18.07667,
"108.30",15.504,18.10133,
"108.45",15.543,18.12667,
"108.60",15.58,18.15167,
"108.75",15.614,18.17667,
"108.90",15.652,18.20167,
"109.05",15.694,18.22667,
"109.20",15.733,18.25167,
"109.35",15.771,18.27667,
"109.50",15.813,18.30167,
"109.65",15.846,18.32667,
"109.80",15.883,18.35167,
"109.95",15.921,18.37667,
"110.10",15.958,18.40167,
"110.25",15.996,18.42667,
"110.40",16.04,18.45167,
"110.55",16.075,18.47667,
"110.70",16.111,18.50167,
"110.85",16.147,18.52633,
"111.00",16.183,18.55133,
"111.15",16.222,18.57633,
"111.30",16.263,18.60133,
"111.45",16.302,18.62633,
"111.60",16.34,18.65133,
"111.75",16.376,18.67667,
"111.90",16.412,18.70167,
"112.05",16.449,18.72667,
"112.20",16.485,18.75133,
"112.35",16.526,18.77667,
"112.50",16.564,18.80167,
"112.65",16.603,18.82667,
"112.80",16.641,18.85167,
"112.95",16.676,18.87667,
"113.10",16.716,18.90167,
"113.25",16.756,18.92667,
"113.40",16.795,18.95167,
"113.55",16.833,18.97667,
"113.70",16.868,19.00167,
"113.85",16.904,19.02667,
"114.00",16.944,19.052,
"114.15",16.985,19.077,
"114.30",17.026,19.102,
"114.45",17.062,19.12667,
"114.60",17.098,19.15167,
"114.75",17.134,19.17667,
"114.90",17.17,19.20167,
"115.05",17.208,19.22667,
"115.20",17.248,19.25167,
"115.35",17.288,19.27667,
"115.50",17.327,19.30167,
"115.65",17.365,19.32667,
"115.80",17.403,19.35167,
"115.95",17.44,19.37667,
"116.10",17.477,19.40167,
"116.25",17.514,19.42667,
"116.40",17.556,19.45167,
"116.55",17.596,19.47667,
"116.70",17.633,19.50167,
"116.85",17.669,19.52667,
"117.00",17.709,19.55167,
"117.15",17.741,19.57667,
"117.30",17.78,19.60167,
"117.45",17.821,19.62667,
"117.60",17.858,19.65167,
"117.75",17.892,19.67667,
"117.90",17.929,19.70133,
"118.05",17.966,19.72633,
"118.20",18.006,19.75167,
"118.35",18.047,19.77667,
"118.50",18.084,19.80167,
"118.65",18.117,19.82667,
"118.80",18.152,19.85167,
"118.95",18.19,19.87667,
"119.10",18.228,19.90167,
"119.25",18.269,19.92667,
"119.40",18.304,19.95167,
"119.55",18.341,19.97667,
"119.70",18.376,20.00167,
"119.85",18.409,20.02667,
"120.00",18.443,20.05167,
"120.15",18.48,20.07667,
"120.30",18.519,20.10167,
"120.45",18.555,20.12667,
"120.60",18.592,20.15167,
"120.75",18.627,20.17667,
"120.90",18.659,20.20167,
"121.05",18.692,20.22667,
"121.20",18.73,20.25167,
"121.35",18.766,20.27667,
"121.50",18.804,20.30167,
"121.65",18.838,20.32667,
"121.80",18.868,20.35167,
"121.95",18.899,20.37667,
"122.10",18.933,20.40167,
"122.25",18.97,20.42667,
"122.40",19.007,20.45167,
"122.55",19.04,20.47667,
"122.70",19.072,20.50167,
"122.85",19.103,20.52667,
"123.00",19.138,20.55167,
"123.15",19.172,20.57667,
"123.30",19.207,20.60167,
"123.45",19.244,20.62667,
"123.60",19.274,20.65167,
"123.75",19.307,20.67667,
"123.90",19.34,20.70167,
"124.05",19.377,20.72667,
"124.20",19.41,20.75167,
"124.35",19.444,20.77667,
"124.50",19.475,20.80167,
"124.65",19.506,20.82667,
"124.80",19.538,20.85167,
"124.95",19.575,20.87667,
"125.10",19.606,20.90167,
"125.25",19.643,20.92667,
"125.40",19.678,20.95167,
"125.55",19.714,20.97667,
"125.70",19.746,21.00167,
"125.85",19.776,21.02667,
"126.00",19.81,21.05167,
"126.15",19.841,21.07667,
"126.30",19.876,21.10167,
"126.45",19.914,21.12667,
"126.60",19.949,21.15167,
"126.75",19.981,21.17667,
"126.90",20.011,21.20167,
"127.05",20.042,21.22667,
"127.20",20.072,21.25167,
"127.35",20.105,21.27633,
"127.50",20.137,21.30167,
"127.65",20.168,21.32633,
"127.80",20.2,21.35167,
"127.95",20.229,21.37667,
"128.10",20.26,21.40167,
"128.25",20.295,21.42667,
"128.40",20.329,21.45167,
"128.55",20.359,21.47667,
"128.70",20.388,21.50133,
"128.85",20.415,21.52633,
"129.00",20.446,21.55167,
"129.15",20.476,21.57667,
"129.30",20.51,21.60167,
"129.45",20.541,21.62667,
"129.60",20.568,21.65167,
"129.75",20.596,21.67667,
"129.90",20.622,21.70133,
"130.05",20.649,21.72667,
"130.20",20.682,21.75167,
"130.35",20.715,21.77667,
"130.50",20.744,21.80167,
"130.65",20.772,21.82667,
"130.80",20.795,21.85167,
"130.95",20.826,21.87667,
"131.10",20.854,21.90167,
"131.25",20.882,21.92667,
"131.40",20.911,21.95167,
"131.55",20.942,21.97667,
"131.70",20.971,22.00167,
"131.85",21.001,22.02667,
"132.00",21.026,22.05167,
"132.15",21.056,22.07667,
"132.30",21.086,22.10167,
"132.45",21.115,22.12667,
"132.60",21.143,22.15167,
"132.75",21.168,22.17667,
"132.90",21.197,22.20167,
"133.05",21.223,22.22667,
"133.20",21.252,22.25167,
"133.35",21.281,22.27633,
"133.50",21.31,22.30167,
"133.65",21.336,22.32633,
"133.80",21.359,22.35133,
"133.95",21.388,22.37633,
"134.10",21.409,22.40133,
"134.25",21.434,22.42633,
"134.40",21.464,22.45133,
"134.55",21.488,22.47667,
"134.70",21.511,22.50167,
"134.85",21.532,22.52667,
"135.00",21.553,22.55167,
"135.15",21.58,22.57667,
"135.30",21.61,22.60167,
"135.45",21.635,22.62667,
"135.60",21.659,22.65133,
"135.75",21.681,22.67633,
"135.90",21.704,22.70133,
"136.05",21.726,22.72633,
"136.20",21.751,22.75133,
"136.35",21.774,22.77633,
"136.50",21.802,22.80167,
"136.65",21.829,22.82667,
"136.80",21.851,22.85133,
"136.95",21.872,22.87667,
"137.10",21.902,22.90167,
"137.25",21.928,22.92633,
"137.40",21.95,22.95133,
"137.55",21.977,22.97633,
"137.70",22.001,23.00133,
"137.85",22.025,23.02633,
"138.00",22.05,23.05167,
"138.15",22.076,23.07667,
"138.30",22.108,23.10167,
"138.45",22.131,23.12667,
"138.60",22.152,23.15167,
"138.75",22.174,23.17667,
"138.90",22.2,23.20167,
"139.05",22.223,23.22667,
"139.20",22.248,23.25167,
"139.35",22.274,23.27667,
"139.50",22.298,23.30167,
"139.65",22.322,23.32667,
"139.80",22.342,23.35133,
"139.95",22.365,23.37633,
"140.10",22.392,23.40167,
"140.25",22.417,23.42667,
"140.40",22.444,23.45167,
"140.55",22.467,23.47667,
"140.70",22.489,23.50167,
"140.85",22.509,23.52667,
"141.00",22.529,23.55167,
"141.15",22.55,23.57667,
"141.30",22.576,23.60167,
"141.45",22.603,23.62667,
"141.60",22.625,23.65167,
"141.75",22.648,23.67667,
"141.90",22.667,23.70167,
"142.05",22.69,23.727,
"142.20",22.714,23.752,
"142.35",22.74,23.777,
"142.50",22.761,23.802,
"142.65",22.784,23.827,
"142.80",22.808,23.85167,
"142.95",22.825,23.87667,
"143.10",22.849,23.90167,
"143.25",22.877,23.92667,
"143.40",22.901,23.95167,
"143.55",22.924,23.97667,
"143.70",22.946,24.00167,
"143.85",22.968,24.02667,
"144.00",22.994,24.05167,
"144.15",23.019,24.07667,
"144.30",23.043,24.10167,
"144.45",23.062,24.12667,
"144.60",23.086,24.15167,
"144.75",23.106,24.17633,
"144.90",23.128,24.20167,
"145.05",23.153,24.22667,
"145.20",23.178,24.25167,
"145.35",23.201,24.27667,
"145.50",23.225,24.30167,
"145.65",23.251,24.32633,
"145.80",23.272,24.35167,
"145.95",23.292,24.37667,
"146.10",23.316,24.40167,
"146.25",23.342,24.42667,
"146.40",23.367,24.45167,
"146.55",23.391,24.47667,
"146.70",23.416,24.50167,
"146.85",23.435,24.52667,
"147.00",23.46,24.55167,
"147.15",23.482,24.57667,
"147.30",23.508,24.60167,
"147.45",23.534,24.62667,
"147.60",23.554,24.65167,
"147.75",23.575,24.67633,
"147.90",23.601,24.70133,
"148.05",23.625,24.72633,
"148.20",23.653,24.75133,
"148.35",23.679,24.77633,
"148.50",23.703,24.80133,
"148.65",23.724,24.82633,
"148.80",23.749,24.85133,
"148.95",23.771,24.87633,
"149.10",23.796,24.90167,
"149.25",23.822,24.92633,
"149.40",23.853,24.95133,
"149.55",23.878,24.97633,
"149.70",23.899,25.00133,
"149.85",23.925,25.02633,
"150.00",23.947,25.05167,
"150.15",23.976,25.07667,
"150.30",24,25.10133,
"150.45",24.03,25.12667,
"150.60",24.05,25.15167,
"150.75",24.08,25.17667,
"150.90",24.1,25.20167,
"151.05",24.13,25.22667,
"151.20",24.16,25.25167,
"151.35",24.19,25.27633,
"151.50",24.21,25.30133,
"151.65",24.24,25.32633,
"151.80",24.26,25.35133,
"151.95",24.28,25.37633,
"152.10",24.31,25.40133,
"152.25",24.34,25.42667,
"152.40",24.37,25.45167,
"152.55",24.39,25.47667,
"152.70",24.42,25.50167,
"152.85",24.44,25.52667,
"153.00",24.47,25.55167,
"153.15",24.5,25.57667,
"153.30",24.52,25.60167,
"153.45",24.55,25.62667,
"153.60",24.58,25.65133,
"153.75",24.6,25.67633,
"153.90",24.62,25.70133,
"154.05",24.64,25.72667,
"154.20",24.67,25.75167,
"154.35",24.7,25.77667,
"154.50",24.73,25.80167,
"154.65",24.75,25.82667,
"154.80",24.77,25.85167,
"154.95",24.79,25.87667,
"155.10",24.82,25.90167,
"155.25",24.85,25.92667,
"155.40",24.88,25.95167,
"155.55",24.91,25.97667,
"155.70",24.93,26.00167,
"155.85",24.95,26.02667,
"156.00",24.97,26.05167,
"156.15",25,26.07667,
"156.30",25.02,26.10167,
"156.45",25.05,26.12667,
"156.60",25.07,26.15167,
"156.75",25.1,26.17667,
"156.90",25.12,26.20167,
"157.05",25.15,26.22667,
"157.20",25.17,26.25133,
"157.35",25.19,26.27633,
"157.50",25.22,26.30133,
"157.65",25.24,26.32633,
"157.80",25.27,26.35133,
"157.95",25.29,26.37633,
"158.10",25.32,26.40167,
"158.25",25.34,26.42667,
"158.40",25.37,26.45167,
"158.55",25.39,26.47667,
"158.70",25.42,26.50167,
"158.85",25.44,26.52667,
"159.00",25.46,26.55167,
"159.15",25.49,26.57667,
"159.30",25.52,26.60167,
"159.45",25.54,26.62667,
"159.60",25.57,26.65133,
"159.75",25.59,26.67633,
"159.90",25.61,26.70133,
"160.05",25.63,26.72633,
"160.20",25.66,26.75167,
"160.35",25.69,26.77667,
"160.50",25.71,26.80167,
"160.65",25.74,26.82667,
"160.80",25.76,26.85133,
"160.95",25.78,26.87633,
"161.10",25.81,26.90133,
"161.25",25.83,26.92633,
"161.40",25.86,26.95133,
"161.55",25.88,26.97633,
"161.70",25.91,27.00133,
"161.85",25.93,27.02633,
"162.00",25.95,27.05167,
"162.15",25.97,27.07633,
"162.30",26,27.10133,
"162.45",26.02,27.12667,
"162.60",26.05,27.15133,
"162.75",26.07,27.17667,
"162.90",26.1,27.20133,
"163.05",26.12,27.22667,
"163.20",26.15,27.25133,
"163.35",26.17,27.27633,
"163.50",26.19,27.30133,
"163.65",26.22,27.32633,
"163.80",26.24,27.35133,
"163.95",26.26,27.37633,
"164.10",26.29,27.40133,
"164.25",26.31,27.42633,
"164.40",26.34,27.45133,
"164.55",26.36,27.47667,
"164.70",26.38,27.50167,
"164.85",26.4,27.52667,
"165.00",26.42,27.55167,
"165.15",26.45,27.57667,
"165.30",26.47,27.60167,
"165.45",26.5,27.62667,
"165.60",26.52,27.65133,
"165.75",26.54,27.67633,
"165.90",26.55,27.70133,
"166.05",26.57,27.72633,
"166.20",26.59,27.75133,
"166.35",26.62,27.77633,
"166.50",26.64,27.80133,
"166.65",26.66,27.82633,
"166.80",26.68,27.85133,
"166.95",26.7,27.87633,
"167.10",26.72,27.90133,
"167.25",26.75,27.92633,
"167.40",26.77,27.95133,
"167.55",26.8,27.97633,
"167.70",26.82,28.00133,
"167.85",26.84,28.02633,
"168.00",26.87,28.05133,
"168.15",26.89,28.07633,
"168.30",26.92,28.10133,
"168.45",26.94,28.12633,
"168.60",26.97,28.15167,
"168.75",26.99,28.17667,
"168.90",27.01,28.20133,
"169.05",27.03,28.22633,
"169.20",27.05,28.25133,
"169.35",27.07,28.27633,
"169.50",27.08,28.30167,
"169.65",27.08,28.32633,
"169.75",27.08,28.343,