File: data i dont like/pristine_flourocarbon_10cm_3mmpm_4.csv
"Test Name","Test Mode","Test Type","Control","Test Speed 1","Test Speed 2","Test Speed 3","Change Point 1","Change Point 2","Disp. Origin","Break and Limit Action","Sensitivity:","Level:"
"","Single","Tensile","Stroke",3,1,1,"Off","Off","Start","Stop",0,1

"Title","Sub title","Comment"
"","",""

"Shape:","Batch Size:","SubBatch Size:"
"Plate",1,1
"Name:","Thickness","Width","Gauge Length",
"Size Unit:","mm","mm","mm",
" 1 - 1","1.0000","1.0000","100.0000",

"Name",
"Parameter",
"Units",
" 1 - 1",

" 1- 1"
"Time","Force","Stroke",
"sec","N","mm",
"0.00",.001,0,
"0.50",.012,2.733333E-02,
"1.00",.038,.055,
"1.50",.06,8.333334E-02,
"2.00",.087,.111,
"2.50",.11,.1376667,
"3.00",.136,.164,
"3.50",.161,.1896667,
"4.00",.186,.215,
"4.50",.207,.2403333,
"5.00",.231,.2656667,
"5.50",.251,.2906667,
"6.00",.275,.316,
"6.50",.297,.341,
"7.00",.318,.366,
"7.50",.343,.391,
"8.00",.368,.4156667,
"8.50",.384,.441,
"9.00",.411,.466,
"9.50",.432,.491,
"10.00",.454,.516,
"10.50",.474,.541,
"11.00",.498,.566,
"11.50",.518,.591,
"12.00",.54,.616,
"12.50",.563,.641,
"13.00",.582,.6656666,
"13.50",.605,.691,
"14.00",.626,.7156667,
"14.50",.647,.7406667,
"15.00",.669,.7656667,
"15.50",.687,.7906666,
"16.00",.71,.8156667,
"16.50",.727,.841,
"17.00",.748,.866,
"17.50",.767,.891,
"18.00",.786,.916,
"18.50",.807,.941,
"19.00",.829,.966,
"19.50",.846,.991,
"20.00",.867,1.016,
"20.50",.883,1.041,
"21.00",.903,1.066,
"21.50",.923,1.091,
"22.00",.943,1.116,
"22.50",.958,1.141,
"23.00",.976,1.166,
"23.50",.995,1.191,
"24.00",1.011,1.216,
"24.50",1.029,1.241,
"25.00",1.05,1.266,
"25.50",1.063,1.291,
"26.00",1.081,1.316,
"26.50",1.096,1.341,
"27.00",1.113,1.366,
"27.50",1.132,1.391,
"28.00",1.15,1.416,
"28.50",1.164,1.441,
"29.00",1.181,1.466,
"29.50",1.196,1.491,
"30.00",1.212,1.516,
"30.50",1.227,1.541,
"31.00",1.248,1.566,
"31.50",1.258,1.591,
"32.00",1.274,1.616,
"32.50",1.288,1.640667,
"33.00",1.304,1.666,
"33.50",1.318,1.691,
"34.00",1.334,1.716,
"34.50",1.348,1.741,
"35.00",1.365,1.766,
"35.50",1.376,1.791,
"36.00",1.394,1.816,
"36.50",1.407,1.841,
"37.00",1.421,1.866,
"37.50",1.435,1.891,
"38.00",1.447,1.916,
"38.50",1.461,1.941,
"39.00",1.476,1.966,
"39.50",1.487,1.991,
"40.00",1.502,2.016,
"40.50",1.517,2.041,
"41.00",1.533,2.066,
"41.50",1.542,2.091,
"42.00",1.555,2.116,
"42.50",1.568,2.141,
"43.00",1.582,2.166,
"43.50",1.596,2.191,
"44.00",1.61,2.216,
"44.50",1.621,2.241,
"45.00",1.634,2.266,
"45.50",1.645,2.291,
"46.00",1.66,2.316,
"46.50",1.669,2.341,
"47.00",1.684,2.366,
"47.50",1.695,2.391,
"48.00",1.708,2.416,
"48.50",1.723,2.441,
"49.00",1.736,2.466,
"49.50",1.745,2.491,
"50.00",1.758,2.516,
"50.50",1.772,2.541,
"51.00",1.782,2.566,
"51.50",1.795,2.591,
"52.00",1.806,2.616,
"52.50",1.817,2.641,
"53.00",1.832,2.666,
"53.50",1.84,2.691,
"54.00",1.858,2.716,
"54.50",1.868,2.741,
"55.00",1.882,2.766,
"55.50",1.894,2.791,
"56.00",1.906,2.816,
"56.50",1.917,2.841,
"57.00",1.929,2.866,
"57.50",1.942,2.891,
"58.00",1.954,2.916,
"58.50",1.963,2.941,
"59.00",1.978,2.966,
"59.50",1.989,2.991,
"60.00",2.001,3.016,
"60.50",2.013,3.041,
"61.00",2.024,3.066,
"61.50",2.037,3.091,
"62.00",2.049,3.116,
"62.50",2.06,3.141,
"63.00",2.073,3.166,
"63.50",2.084,3.191,
"64.00",2.098,3.216,
"64.50",2.107,3.241,
"65.00",2.119,3.266,
"65.50",2.128,3.291,
"66.00",2.142,3.316,
"66.50",2.152,3.341,
"67.00",2.166,3.366,
"67.50",2.177,3.390667,
"68.00",2.192,3.415667,
"68.50",2.202,3.440667,
"69.00",2.215,3.465667,
"69.50",2.224,3.491,
"70.00",2.238,3.516,
"70.50",2.249,3.541,
"71.00",2.263,3.566,
"71.50",2.273,3.591,
"72.00",2.286,3.616,
"72.50",2.295,3.641,
"73.00",2.307,3.666,
"73.50",2.319,3.691,
"74.00",2.334,3.716,
"74.50",2.343,3.741,
"75.00",2.356,3.766,
"75.50",2.366,3.791,
"76.00",2.378,3.816,
"76.50",2.39,3.841,
"77.00",2.405,3.866,
"77.50",2.414,3.891,
"78.00",2.428,3.916,
"78.50",2.437,3.941,
"79.00",2.452,3.966,
"79.50",2.465,3.991,
"80.00",2.474,4.016,
"80.50",2.486,4.041,
"81.00",2.502,4.066,
"81.50",2.51,4.091,
"82.00",2.524,4.115667,
"82.50",2.535,4.141,
"83.00",2.547,4.166,
"83.50",2.559,4.191,
"84.00",2.572,4.216,
"84.50",2.583,4.241,
"85.00",2.597,4.266,
"85.50",2.606,4.291,
"86.00",2.62,4.316,
"86.50",2.628,4.341,
"87.00",2.645,4.366,
"87.50",2.655,4.391,
"88.00",2.668,4.416,
"88.50",2.678,4.441,
"89.00",2.693,4.466,
"89.50",2.705,4.491,
"90.00",2.716,4.516,
"90.50",2.728,4.541,
"91.00",2.745,4.566,
"91.50",2.755,4.591,
"92.00",2.766,4.616,
"92.50",2.778,4.641,
"93.00",2.793,4.666,
"93.50",2.802,4.691,
"94.00",2.817,4.716,
"94.50",2.828,4.741,
"95.00",2.84,4.766,
"95.50",2.853,4.791,
"96.00",2.866,4.816,
"96.50",2.879,4.841,
"97.00",2.891,4.866,
"97.50",2.903,4.891,
"98.00",2.917,4.916,
"98.50",2.929,4.941,
"99.00",2.942,4.966,
"99.50",2.954,4.991,
"100.00",2.969,5.016,
"100.50",2.982,5.041,
"101.00",2.995,5.066,
"101.50",3.008,5.091,
"102.00",3.018,5.116,
"102.50",3.029,5.141,
"103.00",3.042,5.166,
"103.50",3.057,5.191,
"104.00",3.07,5.216,
"104.50",3.082,5.241,
"105.00",3.095,5.266,
"105.50",3.108,5.291,
"106.00",3.12,5.316,
"106.50",3.134,5.341,
"107.00",3.147,5.366,
"107.50",3.162,5.391,
"108.00",3.175,5.416,
"108.50",3.188,5.441,
"109.00",3.201,5.466,
"109.50",3.214,5.491,
"110.00",3.228,5.516,
"110.50",3.241,5.541,
"111.00",3.255,5.566,
"111.50",3.269,5.591,
"112.00",3.28,5.616,
"112.50",3.291,5.641,
"113.00",3.309,5.666,
"113.50",3.318,5.691,
"114.00",3.333,5.716,
"114.50",3.344,5.741,
"115.00",3.361,5.766,
"115.50",3.373,5.791,
"116.00",3.385,5.816,
"116.50",3.401,5.841,
"117.00",3.415,5.866,
"117.50",3.426,5.891,
"118.00",3.438,5.916,
"118.50",3.452,5.941,
"119.00",3.466,5.966,
"119.50",3.478,5.991,
"120.00",3.492,6.016,
"120.50",3.498,6.041,
"121.00",3.505,6.066,
"121.50",3.516,6.091,
"122.00",3.526,6.115667,
"122.50",3.53,6.141,
"123.00",3.537,6.165667,
"123.50",3.548,6.191,
"124.00",3.556,6.216,
"124.50",3.561,6.241,
"125.00",3.574,6.266,
"125.50",3.59,6.291,
"126.00",3.601,6.316,
"126.50",3.619,6.341,
"127.00",3.634,6.366,
"127.50",3.647,6.391,
"128.00",3.656,6.416,
"128.50",3.662,6.441,
"129.00",3.679,6.466,
"129.50",3.69,6.491,
"130.00",3.705,6.516,
"130.50",3.719,6.541,
"131.00",3.739,6.566,
"131.50",3.752,6.591,
"132.00",3.768,6.616,
"132.50",3.784,6.641,
"133.00",3.802,6.666,
"133.50",3.815,6.691,
"134.00",3.832,6.716,
"134.50",3.844,6.740667,
"135.00",3.86,6.766,
"135.50",3.874,6.791,
"136.00",3.887,6.816,
"136.50",3.903,6.841,
"137.00",3.921,6.866,
"137.50",3.933,6.891,
"138.00",3.949,6.916,
"138.50",3.962,6.941,
"139.00",3.976,6.966,
"139.50",3.991,6.991,
"140.00",4.01,7.016,
"140.50",4.022,7.041,
"141.00",4.04,7.066,
"141.50",4.055,7.091,
"142.00",4.071,7.116,
"142.50",4.084,7.141,
"143.00",4.102,7.166,
"143.50",4.114,7.191,
"144.00",4.132,7.216,
"144.50",4.147,7.241,
"145.00",4.161,7.266,
"145.50",4.175,7.291,
"146.00",4.191,7.316,
"146.50",4.206,7.341,
"147.00",4.221,7.366,
"147.50",4.236,7.391,
"148.00",4.253,7.416,
"148.50",4.269,7.441,
"149.00",4.282,7.466,
"149.50",4.299,7.491,
"150.00",4.314,7.516,
"150.50",4.331,7.541,
"151.00",4.348,7.566,
"151.50",4.359,7.591,
"152.00",4.376,7.616,
"152.50",4.391,7.640666,
"153.00",4.406,7.666,
"153.50",4.423,7.691,
"154.00",4.441,7.716,
"154.50",4.457,7.741,
"155.00",4.472,7.766,
"155.50",4.485,7.791,
"156.00",4.503,7.816,
"156.50",4.518,7.841,
"157.00",4.536,7.866,
"157.50",4.548,7.891,
"158.00",4.567,7.916,
"158.50",4.581,7.941,
"159.00",4.599,7.966,
"159.50",4.615,7.991,
"160.00",4.63,8.016334,
"160.50",4.648,8.041,
"161.00",4.667,8.066,
"161.50",4.68,8.091,
"162.00",4.7,8.116,
"162.50",4.712,8.141,
"163.00",4.73,8.166,
"163.50",4.746,8.191,
"164.00",4.765,8.216,
"164.50",4.781,8.241,
"165.00",4.796,8.266,
"165.50",4.81,8.291,
"166.00",4.829,8.316,
"166.50",4.846,8.341,
"167.00",4.864,8.366,
"167.50",4.879,8.391,
"168.00",4.897,8.416,
"168.50",4.915,8.441,
"169.00",4.932,8.466,
"169.50",4.949,8.491,
"170.00",4.968,8.516,
"170.50",4.983,8.541,
"171.00",5.002,8.566,
"171.50",5.018,8.591,
"172.00",5.036,8.616,
"172.50",5.051,8.641,
"173.00",5.065,8.666,
"173.50",5.086,8.691,
"174.00",5.104,8.716,
"174.50",5.121,8.741,
"175.00",5.139,8.766,
"175.50",5.155,8.791,
"176.00",5.173,8.816,
"176.50",5.188,8.841,
"177.00",5.207,8.866,
"177.50",5.227,8.891,
"178.00",5.244,8.916,
"178.50",5.262,8.941,
"179.00",5.279,8.966,
"179.50",5.295,8.991,
"180.00",5.315,9.016,
"180.50",5.332,9.041,
"181.00",5.35,9.066,
"181.50",5.367,9.091,
"182.00",5.386,9.116,
"182.50",5.403,9.141,
"183.00",5.42,9.166,
"183.50",5.439,9.191,
"184.00",5.459,9.216,
"184.50",5.475,9.241,
"185.00",5.494,9.266,
"185.50",5.51,9.291,
"186.00",5.529,9.316,
"186.50",5.549,9.341,
"187.00",5.567,9.366,
"187.50",5.585,9.391,
"188.00",5.606,9.416,
"188.50",5.621,9.441,
"189.00",5.64,9.466,
"189.50",5.659,9.491,
"190.00",5.674,9.516,
"190.50",5.694,9.541,
"191.00",5.714,9.565666,
"191.50",5.732,9.590667,
"192.00",5.75,9.615666,
"192.50",5.771,9.640667,
"193.00",5.788,9.666,
"193.50",5.809,9.691,
"194.00",5.827,9.715667,
"194.50",5.846,9.740666,
"195.00",5.866,9.765667,
"195.50",5.883,9.790667,
"196.00",5.903,9.815666,
"196.50",5.922,9.840667,
"197.00",5.941,9.866,
"197.50",5.962,9.890667,
"198.00",5.983,9.916,
"198.50",5.998,9.941,
"199.00",6.019,9.966,
"199.50",6.039,9.991,
"200.00",6.058,10.016,
"200.50",6.078,10.041,
"201.00",6.1,10.066,
"201.50",6.117,10.091,
"202.00",6.139,10.116,
"202.50",6.157,10.141,
"203.00",6.176,10.166,
"203.50",6.198,10.191,
"204.00",6.218,10.216,
"204.50",6.239,10.241,
"205.00",6.257,10.266,
"205.50",6.275,10.291,
"206.00",6.297,10.316,
"206.50",6.314,10.341,
"207.00",6.337,10.366,
"207.50",6.358,10.391,
"208.00",6.38,10.416,
"208.50",6.397,10.441,
"209.00",6.418,10.466,
"209.50",6.438,10.491,
"210.00",6.456,10.516,
"210.50",6.479,10.541,
"211.00",6.5,10.566,
"211.50",6.522,10.591,
"212.00",6.539,10.616,
"212.50",6.561,10.641,
"213.00",6.579,10.666,
"213.50",6.602,10.691,
"214.00",6.623,10.716,
"214.50",6.646,10.741,
"215.00",6.667,10.766,
"215.50",6.687,10.79067,
"216.00",6.709,10.81567,
"216.50",6.729,10.84067,
"217.00",6.75,10.866,
"217.50",6.772,10.891,
"218.00",6.794,10.916,
"218.50",6.816,10.941,
"219.00",6.836,10.96567,
"219.50",6.857,10.99067,
"220.00",6.878,11.016,
"220.50",6.9,11.041,
"221.00",6.924,11.066,
"221.50",6.945,11.091,
"222.00",6.967,11.116,
"222.50",6.985,11.141,
"223.00",7.007,11.166,
"223.50",7.028,11.191,
"224.00",7.052,11.216,
"224.50",7.074,11.241,
"225.00",7.096,11.266,
"225.50",7.115,11.291,
"226.00",7.138,11.316,
"226.50",7.16,11.341,
"227.00",7.183,11.366,
"227.50",7.207,11.391,
"228.00",7.23,11.416,
"228.50",7.253,11.441,
"229.00",7.272,11.466,
"229.50",7.295,11.491,
"230.00",7.315,11.516,
"230.50",7.34,11.541,
"231.00",7.361,11.566,
"231.50",7.386,11.591,
"232.00",7.406,11.616,
"232.50",7.427,11.641,
"233.00",7.451,11.666,
"233.50",7.475,11.691,
"234.00",7.499,11.716,
"234.50",7.519,11.741,
"235.00",7.543,11.766,
"235.50",7.565,11.791,
"236.00",7.588,11.816,
"236.50",7.609,11.841,
"237.00",7.635,11.866,
"237.50",7.658,11.891,
"238.00",7.682,11.916,
"238.50",7.704,11.941,
"239.00",7.727,11.966,
"239.50",7.75,11.991,
"240.00",7.772,12.016,
"240.50",7.796,12.041,
"241.00",7.826,12.066,
"241.50",7.845,12.091,
"242.00",7.868,12.116,
"242.50",7.891,12.141,
"243.00",7.913,12.166,
"243.50",7.937,12.191,
"244.00",7.964,12.216,
"244.50",7.988,12.241,
"245.00",8.013,12.266,
"245.50",8.036,12.291,
"246.00",8.06,12.316,
"246.50",8.081,12.341,
"247.00",8.106,12.366,
"247.50",8.131,12.391,
"248.00",8.157,12.416,
"248.50",8.18,12.441,
"249.00",8.205,12.466,
"249.50",8.228,12.491,
"250.00",8.254,12.516,
"250.50",8.278,12.541,
"251.00",8.306,12.566,
"251.50",8.328,12.591,
"252.00",8.353,12.616,
"252.50",8.378,12.641,
"253.00",8.403,12.666,
"253.50",8.425,12.691,
"254.00",8.455,12.716,
"254.50",8.477,12.741,
"255.00",8.504,12.766,
"255.50",8.526,12.791,
"256.00",8.552,12.816,
"256.50",8.577,12.841,
"257.00",8.604,12.866,
"257.50",8.632,12.891,
"258.00",8.656,12.916,
"258.50",8.679,12.941,
"259.00",8.703,12.966,
"259.50",8.728,12.991,
"260.00",8.756,13.016,
"260.50",8.783,13.041,
"261.00",8.809,13.066,
"261.50",8.835,13.091,
"262.00",8.863,13.116,
"262.50",8.885,13.141,
"263.00",8.911,13.166,
"263.50",8.937,13.191,
"264.00",8.963,13.216,
"264.50",8.988,13.241,
"265.00",9.016,13.266,
"265.50",9.041,13.291,
"266.00",9.069,13.316,
"266.50",9.097,13.341,
"267.00",9.124,13.366,
"267.50",9.154,13.391,
"268.00",9.181,13.416,
"268.50",9.204,13.441,
"269.00",9.231,13.466,
"269.50",9.26,13.491,
"270.00",9.288,13.516,
"270.50",9.317,13.541,
"271.00",9.343,13.566,
"271.50",9.37,13.591,
"272.00",9.397,13.616,
"272.50",9.421,13.641,
"273.00",9.451,13.666,
"273.50",9.479,13.691,
"274.00",9.508,13.716,
"274.50",9.538,13.741,
"275.00",9.566,13.766,
"275.50",9.592,13.791,
"276.00",9.617,13.816,
"276.50",9.645,13.841,
"277.00",9.674,13.866,
"277.50",9.705,13.891,
"278.00",9.732,13.916,
"278.50",9.76,13.941,
"279.00",9.786,13.966,
"279.50",9.814,13.991,
"280.00",9.848,14.016,
"280.50",9.874,14.041,
"281.00",9.903,14.066,
"281.50",9.935,14.091,
"282.00",9.96,14.116,
"282.50",9.99,14.141,
"283.00",10.022,14.166,
"283.50",10.05,14.19133,
"284.00",10.081,14.216,
"284.50",10.11,14.241,
"285.00",10.137,14.266,
"285.50",10.164,14.291,
"286.00",10.195,14.316,
"286.50",10.224,14.341,
"287.00",10.257,14.366,
"287.50",10.289,14.391,
"288.00",10.32,14.416,
"288.50",10.347,14.441,
"289.00",10.377,14.466,
"289.50",10.406,14.491,
"290.00",10.44,14.516,
"290.50",10.469,14.541,
"291.00",10.499,14.566,
"291.50",10.531,14.591,
"292.00",10.563,14.616,
"292.50",10.592,14.641,
"293.00",10.622,14.666,
"293.50",10.652,14.691,
"294.00",10.683,14.716,
"294.50",10.718,14.741,
"295.00",10.749,14.766,
"295.50",10.779,14.791,
"296.00",10.808,14.816,
"296.50",10.837,14.841,
"297.00",10.869,14.866,
"297.50",10.902,14.891,
"298.00",10.932,14.916,
"298.50",10.962,14.941,
"299.00",10.992,14.966,
"299.50",11.023,14.991,
"300.00",11.057,15.016,
"300.50",11.09,15.041,
"301.00",11.123,15.066,
"301.50",11.156,15.091,
"302.00",11.188,15.116,
"302.50",11.217,15.141,
"303.00",11.249,15.166,
"303.50",11.281,15.191,
"304.00",11.318,15.216,
"304.50",11.35,15.241,
"305.00",11.382,15.266,
"305.50",11.411,15.291,
"306.00",11.444,15.316,
"306.50",11.476,15.341,
"307.00",11.509,15.366,
"307.50",11.548,15.391,
"308.00",11.578,15.416,
"308.50",11.613,15.441,
"309.00",11.643,15.466,
"309.50",11.676,15.491,
"310.00",11.708,15.516,
"310.50",11.745,15.541,
"311.00",11.777,15.566,
"311.50",11.81,15.591,
"312.00",11.843,15.616,
"312.50",11.878,15.641,
"313.00",11.909,15.666,
"313.50",11.943,15.691,
"314.00",11.978,15.716,
"314.50",12.01,15.741,
"315.00",12.045,15.766,
"315.50",12.076,15.791,
"316.00",12.113,15.816,
"316.50",12.147,15.841,
"317.00",12.182,15.866,
"317.50",12.22,15.891,
"318.00",12.254,15.916,
"318.50",12.287,15.941,
"319.00",12.317,15.966,
"319.50",12.354,15.991,
"320.00",12.389,16.016,
"320.50",12.424,16.041,
"321.00",12.46,16.066,
"321.50",12.494,16.091,
"322.00",12.528,16.116,
"322.50",12.562,16.141,
"323.00",12.596,16.166,
"323.50",12.631,16.191,
"324.00",12.671,16.216,
"324.50",12.707,16.241,
"325.00",12.74,16.266,
"325.50",12.773,16.291,
"326.00",12.807,16.316,
"326.50",12.839,16.341,
"327.00",12.877,16.366,
"327.50",12.914,16.391,
"328.00",12.951,16.416,
"328.50",12.986,16.441,
"329.00",13.02,16.466,
"329.50",13.053,16.491,
"330.00",13.089,16.516,
"330.50",13.125,16.541,
"331.00",13.161,16.566,
"331.50",13.197,16.591,
"332.00",13.235,16.616,
"332.50",13.269,16.641,
"333.00",13.306,16.666,
"333.50",13.341,16.691,
"334.00",13.379,16.716,
"334.50",13.416,16.741,
"335.00",13.451,16.766,
"335.50",13.486,16.791,
"336.00",13.521,16.816,
"336.50",13.558,16.841,
"337.00",13.596,16.866,
"337.50",13.635,16.891,
"338.00",13.668,16.916,
"338.50",13.702,16.941,
"339.00",13.74,16.966,
"339.50",13.773,16.991,
"340.00",13.812,17.016,
"340.50",13.851,17.041,
"341.00",13.892,17.066,
"341.50",13.927,17.091,
"342.00",13.962,17.11567,
"342.50",13.995,17.141,
"343.00",14.031,17.166,
"343.50",14.072,17.191,
"344.00",14.111,17.216,
"344.50",14.15,17.241,
"345.00",14.188,17.266,
"345.50",14.223,17.291,
"346.00",14.257,17.316,
"346.50",14.292,17.341,
"347.00",14.331,17.366,
"347.50",14.369,17.39067,
"348.00",14.404,17.416,
"348.50",14.442,17.44067,
"349.00",14.476,17.46567,
"349.50",14.513,17.49067,
"350.00",14.55,17.51567,
"350.50",14.591,17.54067,
"351.00",14.628,17.56567,
"351.50",14.666,17.59067,
"352.00",14.699,17.61567,
"352.50",14.738,17.64067,
"353.00",14.777,17.66567,
"353.50",14.816,17.69067,
"354.00",14.854,17.71567,
"354.50",14.891,17.74067,
"355.00",14.929,17.76567,
"355.50",14.962,17.79067,
"356.00",14.997,17.81567,
"356.50",15.034,17.84067,
"357.00",15.074,17.86567,
"357.50",15.113,17.89067,
"358.00",15.152,17.916,
"358.50",15.187,17.94067,
"359.00",15.222,17.96567,
"359.50",15.259,17.99067,
"360.00",15.297,18.01567,
"360.50",15.334,18.04067,
"361.00",15.375,18.06567,
"361.50",15.414,18.09067,
"362.00",15.449,18.11567,
"362.50",15.481,18.14067,
"363.00",15.517,18.16567,
"363.50",15.554,18.19067,
"364.00",15.593,18.216,
"364.50",15.63,18.241,
"365.00",15.664,18.266,
"365.50",15.702,18.29067,
"366.00",15.734,18.31567,
"366.50",15.774,18.34067,
"367.00",15.812,18.36567,
"367.50",15.848,18.39067,
"368.00",15.884,18.41567,
"368.50",15.918,18.44067,
"369.00",15.951,18.46567,
"369.50",15.986,18.49067,
"370.00",16.02,18.51567,
"370.50",16.058,18.54067,
"371.00",16.094,18.56567,
"371.50",16.122,18.59067,
"372.00",16.156,18.61567,
"372.50",16.185,18.64067,
"373.00",16.221,18.66567,
"373.50",16.259,18.69067,
"374.00",16.297,18.716,
"374.50",16.331,18.741,
"375.00",16.368,18.766,
"375.50",16.4,18.791,
"376.00",16.435,18.816,
"376.50",16.465,18.841,
"377.00",16.503,18.866,
"377.50",16.542,18.891,
"378.00",16.58,18.916,
"378.50",16.612,18.941,
"379.00",16.644,18.966,
"379.50",16.678,18.991,
"380.00",16.713,19.016,
"380.50",16.748,19.041,
"381.00",16.78,19.066,
"381.50",16.813,19.091,
"382.00",16.844,19.116,
"382.50",16.876,19.141,
"383.00",16.908,19.166,
"383.50",16.942,19.191,
"384.00",16.976,19.216,
"384.50",17.012,19.241,
"385.00",17.045,19.26633,
"385.50",17.076,19.291,
"386.00",17.108,19.31567,
"386.50",17.145,19.341,
"387.00",17.179,19.366,
"387.50",17.215,19.391,
"388.00",17.248,19.416,
"388.50",17.281,19.441,
"389.00",17.311,19.466,
"389.50",17.342,19.491,
"390.00",17.376,19.51567,
"390.50",17.404,19.541,
"391.00",17.436,19.566,
"391.50",17.458,19.591,
"392.00",17.479,19.616,
"392.50",17.497,19.641,
"393.00",17.515,19.666,
"393.50",17.527,19.691,
"394.00",17.535,19.716,
"394.50",17.539,19.741,
"395.00",17.549,19.766,
"395.50",17.554,19.791,
"396.00",17.569,19.816,
"396.50",17.582,19.841,
"397.00",17.603,19.866,
"397.50",17.623,19.891,
"398.00",17.639,19.916,
"398.50",17.652,19.941,
"399.00",17.669,19.966,
"399.50",17.688,19.991,
"400.00",17.711,20.016,
"400.50",17.735,20.041,
"401.00",17.76,20.066,
"401.50",17.783,20.091,
"402.00",17.808,20.116,
"402.50",17.831,20.141,
"403.00",17.855,20.166,
"403.50",17.878,20.191,
"404.00",17.907,20.216,
"404.50",17.936,20.241,
"405.00",17.961,20.266,
"405.50",17.989,20.291,
"406.00",18.019,20.316,
"406.50",18.048,20.341,
"407.00",18.082,20.366,
"407.50",18.112,20.391,
"408.00",18.143,20.416,
"408.50",18.173,20.441,
"409.00",18.202,20.466,
"409.50",18.233,20.491,
"410.00",18.254,20.516,
"410.50",18.283,20.541,
"411.00",18.306,20.566,
"411.50",18.323,20.591,
"412.00",18.342,20.616,
"412.50",18.359,20.641,
"413.00",18.38,20.666,
"413.50",18.395,20.691,
"414.00",18.412,20.716,
"414.50",18.432,20.741,
"415.00",18.446,20.766,
"415.50",18.46,20.791,
"416.00",18.478,20.816,
"416.50",18.496,20.841,
"417.00",18.516,20.866,
"417.50",18.535,20.891,
"418.00",18.559,20.916,
"418.50",18.58,20.941,
"419.00",18.603,20.966,
"419.50",18.628,20.991,
"420.00",18.661,21.016,
"420.50",18.691,21.041,
"421.00",18.719,21.066,
"421.50",18.748,21.091,
"422.00",18.777,21.116,
"422.50",18.804,21.141,
"423.00",18.834,21.166,
"423.50",18.861,21.191,
"424.00",18.898,21.216,
"424.50",18.926,21.241,
"425.00",18.955,21.26567,
"425.50",18.983,21.29067,
"426.00",19.013,21.31567,
"426.50",19.042,21.34067,
"427.00",19.075,21.36567,
"427.50",19.103,21.39067,
"428.00",19.136,21.41567,
"428.50",19.163,21.44067,
"429.00",19.191,21.46567,
"429.50",19.219,21.49067,
"430.00",19.25,21.51567,
"430.50",19.281,21.541,
"431.00",19.309,21.56567,
"431.50",19.336,21.591,
"432.00",19.363,21.616,
"432.50",19.39,21.641,
"433.00",19.42,21.666,
"433.50",19.45,21.691,
"434.00",19.48,21.716,
"434.50",19.508,21.74067,
"435.00",19.533,21.766,
"435.50",19.558,21.791,
"436.00",19.585,21.816,
"436.50",19.609,21.841,
"437.00",19.647,21.866,
"437.50",19.673,21.891,
"438.00",19.698,21.916,
"438.50",19.724,21.941,
"439.00",19.746,21.966,
"439.50",19.771,21.991,
"440.00",19.8,22.016,
"440.50",19.827,22.041,
"441.00",19.857,22.066,
"441.50",19.879,22.091,
"442.00",19.902,22.116,
"442.50",19.923,22.141,
"443.00",19.946,22.166,
"443.50",19.976,22.191,
"444.00",20.005,22.216,
"444.50",20.032,22.241,
"445.00",20.06,22.266,
"445.50",20.084,22.291,
"446.00",20.106,22.316,
"446.50",20.131,22.341,
"447.00",20.154,22.366,
"447.50",20.184,22.391,
"448.00",20.206,22.416,
"448.50",20.227,22.441,
"449.00",20.251,22.466,
"449.50",20.276,22.491,
"450.00",20.297,22.516,
"450.50",20.322,22.541,
"451.00",20.349,22.566,
"451.50",20.372,22.591,
"452.00",20.393,22.616,
"452.50",20.415,22.641,
"453.00",20.439,22.666,
"453.50",20.465,22.691,
"454.00",20.494,22.716,
"454.50",20.518,22.741,
"455.00",20.539,22.766,
"455.50",20.561,22.791,
"456.00",20.587,22.816,
"456.50",20.605,22.841,
"457.00",20.632,22.866,
"457.50",20.656,22.891,
"458.00",20.686,22.916,
"458.50",20.703,22.941,
"459.00",20.728,22.966,
"459.50",20.752,22.991,
"460.00",20.774,23.016,
"460.50",20.799,23.041,
"461.00",20.821,23.066,
"461.50",20.843,23.091,
"462.00",20.866,23.116,
"462.50",20.888,23.141,
"463.00",20.91,23.16567,
"463.50",20.931,23.191,
"464.00",20.958,23.216,
"464.50",20.983,23.241,
"465.00",21.009,23.266,
"465.50",21.026,23.291,
"466.00",21.047,23.316,
"466.50",21.067,23.341,
"467.00",21.092,23.366,
"467.50",21.112,23.39067,
"468.00",21.134,23.41567,
"468.50",21.152,23.44067,
"469.00",21.176,23.46567,
"469.50",21.195,23.49067,
"470.00",21.215,23.51567,
"470.50",21.239,23.54067,
"471.00",21.262,23.56567,
"471.50",21.285,23.59067,
"472.00",21.298,23.61567,
"472.50",21.318,23.64067,
"473.00",21.339,23.66567,
"473.50",21.36,23.69067,
"474.00",21.385,23.716,
"474.50",21.405,23.74067,
"475.00",21.425,23.76567,
"475.50",21.442,23.79067,
"476.00",21.46,23.81567,
"476.50",21.477,23.84067,
"477.00",21.5,23.86567,
"477.50",21.522,23.89067,
"478.00",21.544,23.916,
"478.50",21.561,23.94067,
"479.00",21.576,23.966,
"479.50",21.593,23.991,
"480.00",21.611,24.016,
"480.50",21.632,24.041,
"481.00",21.649,24.066,
"481.50",21.663,24.09067,
"482.00",21.682,24.116,
"482.50",21.692,24.14067,
"483.00",21.712,24.16567,
"483.50",21.729,24.19067,
"484.00",21.745,24.21567,
"484.50",21.76,24.24067,
"485.00",21.773,24.26567,
"485.50",21.785,24.291,
"486.00",21.803,24.31567,
"486.50",21.82,24.341,
"487.00",21.839,24.366,
"487.50",21.858,24.391,
"488.00",21.877,24.416,
"488.50",21.887,24.441,
"489.00",21.902,24.466,
"489.50",21.919,24.49067,
"490.00",21.937,24.51567,
"490.50",21.958,24.54067,
"491.00",21.981,24.56567,
"491.50",21.999,24.59067,
"492.00",22.021,24.61567,
"492.50",22.035,24.64067,
"493.00",22.052,24.66567,
"493.50",22.071,24.69067,
"494.00",22.096,24.71567,
"494.50",22.113,24.74067,
"495.00",22.137,24.76567,
"495.50",22.151,24.79067,
"496.00",22.175,24.81567,
"496.50",22.194,24.84067,
"497.00",22.216,24.86567,
"497.50",22.24,24.89067,
"498.00",22.263,24.91567,
"498.50",22.287,24.94067,
"499.00",22.309,24.966,
"499.50",22.33,24.991,
"500.00",22.354,25.016,
"500.50",22.375,25.041,
"501.00",22.401,25.066,
"501.50",22.42,25.09067,
"502.00",22.44,25.11567,
"502.50",22.459,25.14067,
"503.00",22.482,25.16567,
"503.50",22.508,25.19067,
"504.00",22.532,25.21567,
"504.50",22.557,25.24067,
"505.00",22.577,25.26567,
"505.50",22.596,25.29067,
"506.00",22.616,25.31567,
"506.50",22.638,25.34067,
"507.00",22.665,25.36567,
"507.50",22.691,25.39067,
"508.00",22.711,25.41567,
"508.50",22.734,25.44067,
"509.00",22.754,25.46567,
"509.50",22.773,25.49067,
"510.00",22.795,25.51567,
"510.50",22.823,25.54067,
"511.00",22.85,25.56567,
"511.50",22.87,25.59067,
"512.00",22.894,25.61567,
"512.50",22.913,25.641,
"513.00",22.935,25.66567,
"513.50",22.957,25.691,
"514.00",22.983,25.71567,
"514.50",23.008,25.74067,
"515.00",23.03,25.76567,
"515.50",23.052,25.79067,
"516.00",23.075,25.81567,
"516.50",23.096,25.84067,
"517.00",23.119,25.86567,
"517.50",23.144,25.89067,
"518.00",23.166,25.91567,
"518.50",23.183,25.94067,
"519.00",23.206,25.96567,
"519.50",23.229,25.99067,
"520.00",23.25,26.016,
"520.50",23.275,26.041,
"521.00",23.298,26.066,
"521.50",23.32,26.091,
"522.00",23.34,26.116,
"522.50",23.358,26.141,
"523.00",23.383,26.166,
"523.50",23.409,26.191,
"524.00",23.431,26.21567,
"524.50",23.453,26.241,
"525.00",23.477,26.266,
"525.50",23.493,26.291,
"526.00",23.516,26.31567,
"526.50",23.537,26.341,
"527.00",23.562,26.366,
"527.50",23.589,26.391,
"528.00",23.609,26.416,
"528.50",23.632,26.441,
"529.00",23.652,26.46567,
"529.50",23.67,26.49067,
"530.00",23.69,26.51567,
"530.50",23.718,26.54067,
"531.00",23.741,26.56567,
"531.50",23.76,26.59067,
"532.00",23.782,26.61567,
"532.50",23.801,26.64067,
"533.00",23.824,26.66567,
"533.50",23.85,26.69067,
"534.00",23.875,26.71567,
"534.50",23.899,26.74067,
"535.00",23.92,26.76567,
"535.50",23.941,26.79067,
"536.00",23.964,26.81567,
"536.50",23.99,26.84067,
"537.00",24.01,26.866,
"537.50",24.04,26.89067,
"538.00",24.06,26.916,
"538.50",24.08,26.941,
"539.00",24.1,26.966,
"539.50",24.11,26.99067,
"540.00",24.14,27.01567,
"540.50",24.17,27.04067,
"541.00",24.19,27.06567,
"541.50",24.21,27.09067,
"542.00",24.23,27.11567,
"542.50",24.25,27.14067,
"543.00",24.27,27.16567,
"543.50",24.29,27.19067,
"544.00",24.32,27.21567,
"544.50",24.34,27.24067,
"545.00",24.36,27.26567,
"545.50",24.38,27.29067,
"546.00",24.41,27.31567,
"546.50",24.43,27.341,
"547.00",24.45,27.366,
"547.50",24.48,27.39067,
"548.00",24.5,27.41567,
"548.50",24.52,27.44067,
"549.00",24.54,27.46567,
"549.50",24.57,27.49067,
"550.00",24.59,27.51567,
"550.50",24.61,27.54067,
"551.00",24.64,27.56567,
"551.50",24.66,27.59067,
"552.00",24.68,27.61567,
"552.50",24.7,27.64067,
"553.00",24.73,27.66567,
"553.50",24.75,27.69067,
"554.00",24.78,27.71567,
"554.50",24.8,27.74067,
"555.00",24.83,27.76567,
"555.50",24.84,27.79067,
"556.00",24.87,27.81567,
"556.50",24.89,27.84067,
"557.00",24.91,27.86567,
"557.50",24.94,27.89067,
"558.00",24.96,27.91567,
"558.50",24.98,27.94067,
"559.00",25,27.96567,
"559.50",25.03,27.99067,
"560.00",25.05,28.01567,
"560.50",25.08,28.04067,
"561.00",25.1,28.06567,
"561.50",25.12,28.09067,
"562.00",25.14,28.11567,
"562.50",25.16,28.14067,
"563.00",25.18,28.16567,
"563.50",25.21,28.19067,
"564.00",25.23,28.21567,
"564.50",25.26,28.24067,
"565.00",25.28,28.26567,
"565.50",25.3,28.29067,
"566.00",25.32,28.31567,
"566.50",25.34,28.341,
"567.00",25.37,28.366,
"567.50",25.39,28.391,
"568.00",25.41,28.416,
"568.50",25.43,28.441,
"569.00",25.45,28.466,
"569.50",25.47,28.491,
"570.00",25.5,28.51567,
"570.50",25.53,28.541,
"571.00",25.55,28.56567,
"571.50",25.57,28.591,
"572.00",25.59,28.616,
"572.50",25.61,28.64067,
"573.00",25.63,28.66567,
"573.50",25.66,28.691,
"574.00",25.68,28.716,
"574.50",25.71,28.74067,
"575.00",25.73,28.76567,
"575.50",25.75,28.79067,
"576.00",25.77,28.81567,
"576.50",25.79,28.84067,
"577.00",25.82,28.86567,
"577.50",25.84,28.89067,
"578.00",25.87,28.91567,
"578.50",25.89,28.941,
"579.00",25.91,28.966,
"579.50",25.93,28.991,
"580.00",25.95,29.01567,
"580.50",25.97,29.04067,
"581.00",25.99,29.06567,
"581.50",26.02,29.091,
"582.00",26.04,29.11567,
"582.50",26.06,29.14067,
"583.00",26.08,29.16567,
"583.50",26.1,29.191,
"584.00",26.13,29.216,
"584.50",26.15,29.24067,
"585.00",26.17,29.26567,
"585.50",26.19,29.29067,
"586.00",26.21,29.31567,
"586.50",26.23,29.34067,
"587.00",26.25,29.36567,
"587.50",26.28,29.39067,
"588.00",26.3,29.41567,
"588.50",26.32,29.44067,
"589.00",26.34,29.46567,
"589.50",26.36,29.49067,
"590.00",26.39,29.51567,
"590.50",26.41,29.54067,
"591.00",26.44,29.56567,
"591.50",26.46,29.59067,
"592.00",26.48,29.61567,
"592.50",26.5,29.64067,
"593.00",26.53,29.66567,
"593.50",26.55,29.69067,
"594.00",26.57,29.71567,
"594.50",26.6,29.74067,
"595.00",26.62,29.76567,
"595.50",26.64,29.79067,
"596.00",26.66,29.81567,
"596.50",26.68,29.84067,
"597.00",26.7,29.86567,
"597.50",26.72,29.89067,
"598.00",26.74,29.91567,
"598.50",26.76,29.94067,
"599.00",26.78,29.96567,
"599.50",26.8,29.99067,
"600.00",26.83,30.01567,
"600.50",26.85,30.04067,
"601.00",26.88,30.06567,
"601.50",26.9,30.09067,
"602.00",26.92,30.11567,
"602.50",26.94,30.14067,
"603.00",26.96,30.16567,
"603.50",26.99,30.191,
"604.00",27.02,30.216,
"604.50",27.04,30.241,
"605.00",27.06,30.26567,
"605.50",27.07,30.29067,
"606.00",27.1,30.316,
"606.50",27.12,30.341,
"607.00",27.14,30.36567,
"607.50",27.17,30.39067,
"608.00",27.19,30.41567,
"608.50",27.21,30.44067,
"609.00",27.23,30.46567,
"609.50",27.25,30.49067,
"610.00",27.27,30.51567,
"610.50",27.3,30.541,
"611.00",27.33,30.56567,
"611.50",27.35,30.59067,
"612.00",27.37,30.61567,
"612.50",27.39,30.64067,
"613.00",27.41,30.66567,
"613.50",27.43,30.69067,
"614.00",27.45,30.71567,
"614.50",27.48,30.74067,
"615.00",27.49,30.76567,
"615.50",27.51,30.79067,
"616.00",27.53,30.81567,
"616.50",27.55,30.84067,
"617.00",27.58,30.86567,
"617.50",27.6,30.89067,
"618.00",27.62,30.91567,
"618.50",27.64,30.94067,
"619.00",27.66,30.96567,
"619.50",27.68,30.99067,
"620.00",27.71,31.01567,
"620.50",27.72,31.04067,
"621.00",27.75,31.06567,
"621.50",27.77,31.09067,
"622.00",27.79,31.11567,
"622.50",27.81,31.14067,
"623.00",27.82,31.16567,
"623.50",27.84,31.19067,
"624.00",27.87,31.21567,
"624.50",27.89,31.24067,
"625.00",27.91,31.26567,
"625.50",27.92,31.29067,
"626.00",27.94,31.31567,
"626.50",27.96,31.34067,
"627.00",27.98,31.36567,
"627.50",28.01,31.39067,
"628.00",28.03,31.416,
"628.50",28.04,31.44067,
"629.00",28.06,31.46567,
"629.50",28.08,31.49067,
"630.00",28.1,31.51567,
"630.50",28.12,31.54067,
"631.00",28.14,31.56567,
"631.50",28.16,31.59067,
"632.00",28.18,31.61567,
"632.50",28.2,31.64067,
"633.00",28.22,31.66567,
"633.50",28.24,31.69067,
"634.00",28.26,31.71567,
"634.50",28.28,31.74067,
"635.00",28.3,31.76567,
"635.50",28.32,31.79067,
"636.00",28.34,31.81567,
"636.50",28.36,31.841,
"637.00",28.38,31.866,
"637.50",28.4,31.891,
"638.00",28.42,31.916,
"638.50",28.44,31.941,
"639.00",28.45,31.966,
"639.50",28.47,31.991,
"640.00",28.5,32.016,
"640.50",28.52,32.04067,
"641.00",28.54,32.06567,
"641.50",28.56,32.09067,
"642.00",28.58,32.11567,
"642.50",28.6,32.14067,
"643.00",28.62,32.16567,
"643.50",28.64,32.19067,
"644.00",28.66,32.216,
"644.50",28.68,32.24067,
"645.00",28.71,32.266,
"645.50",28.72,32.291,
"646.00",28.74,32.316,
"646.50",28.76,32.341,
"647.00",28.78,32.366,
"647.50",28.8,32.391,
"648.00",28.82,32.416,
"648.50",28.84,32.441,
"649.00",28.86,32.46567,
"649.50",28.88,32.49067,
"650.00",28.89,32.51567,
"650.50",28.91,32.541,
"651.00",28.93,32.56567,
"651.50",28.95,32.591,
"652.00",28.97,32.616,
"652.50",28.99,32.641,
"653.00",29.01,32.666,
"653.50",29.03,32.691,
"654.00",29.05,32.716,
"654.50",29.07,32.74067,
"655.00",29.09,32.76567,
"655.50",29.1,32.79067,
"656.00",29.12,32.81567,
"656.50",29.14,32.84067,
"657.00",29.16,32.86567,
"657.50",29.19,32.89067,
"658.00",29.21,32.91567,
"658.50",29.22,32.94067,
"659.00",29.24,32.96567,
"659.50",29.26,32.99067,
"660.00",29.28,33.01567,
"660.50",29.3,33.04067,
"661.00",29.32,33.06567,
"661.50",29.35,33.09067,
"662.00",29.37,33.11567,
"662.50",29.38,33.14067,
"663.00",29.4,33.16567,
"663.50",29.42,33.19067,
"664.00",29.44,33.21567,
"664.50",29.47,33.24067,
"665.00",29.48,33.26567,
"665.50",29.5,33.29067,
"666.00",29.52,33.31567,
"666.50",29.54,33.34067,
"667.00",29.56,33.36567,
"667.50",29.59,33.39067,
"668.00",29.61,33.41567,
"668.50",29.62,33.44033,
"669.00",29.65,33.46567,
"669.50",29.66,33.49067,
"670.00",29.68,33.51567,
"670.50",29.71,33.54067,
"671.00",29.73,33.56567,
"671.50",29.74,33.59067,
"672.00",29.76,33.61567,
"672.50",29.78,33.64067,
"673.00",29.79,33.66567,
"673.50",29.81,33.69067,
"674.00",29.84,33.71567,
"674.50",29.86,33.74067,
"675.00",29.88,33.76567,
"675.50",29.89,33.79067,
"676.00",29.91,33.81567,
"676.50",29.93,33.84067,
"677.00",29.95,33.86567,
"677.50",29.97,33.89067,
"678.00",30,33.91567,
"678.50",30.01,33.94067,
"679.00",30.03,33.96567,
"679.50",30.04,33.99067,
"680.00",30.07,34.01567,
"680.50",30.09,34.04067,
"681.00",30.11,34.06567,
"681.50",30.12,34.09067,
"682.00",30.14,34.11567,
"682.50",30.16,34.14067,
"683.00",30.18,34.16567,
"683.50",30.2,34.19067,
"684.00",30.22,34.21567,
"684.50",30.24,34.24067,
"685.00",30.26,34.26567,
"685.50",30.27,34.29067,
"686.00",30.29,34.31567,
"686.50",30.31,34.34067,
"687.00",30.33,34.36567,
"687.50",30.35,34.39067,
"688.00",30.37,34.41567,
"688.50",30.38,34.44067,
"689.00",30.4,34.46567,
"689.50",30.41,34.49067,
"690.00",30.43,34.51567,
"690.50",30.45,34.54067,
"691.00",30.47,34.56567,
"691.50",30.48,34.59067,
"692.00",30.48,34.61567,
"692.10",30.47,34.62067,