File: data i dont like/pristine_monofilament_10cm_3mmpm_4.csv
"Test Name","Test Mode","Test Type","Control","Test Speed 1","Test Speed 2","Test Speed 3","Change Point 1","Change Point 2","Disp. Origin","Break and Limit Action","Sensitivity:","Level:"
"","Single","Tensile","Stroke",3,1,1,"Off","Off","Start","Stop",0,1

"Title","Sub title","Comment"
"","",""

"Shape:","Batch Size:","SubBatch Size:"
"Plate",1,1
"Name:","Thickness","Width","Gauge Length",
"Size Unit:","mm","mm","mm",
" 1 - 1","1.0000","1.0000","100.0000",

"Name",
"Parameter",
"Units",
" 1 - 1",

" 1- 1"
"Time","Force","Stroke",
"sec","N","mm",
"0.00",.001,0,
"0.60",.004,.033,
"1.20",.012,6.666667E-02,
"1.80",.024,.1006667,
"2.40",.037,.133,
"3.00",.044,.1646667,
"3.60",.054,.1953333,
"4.20",.065,.226,
"4.80",.072,.2563333,
"5.40",.083,.2863333,
"6.00",.094,.3163333,
"6.60",.103,.3466667,
"7.20",.112,.3763333,
"7.80",.121,.4066667,
"8.40",.129,.4366667,
"9.00",.139,.4663333,
"9.60",.152,.4966667,
"10.20",.16,.5266666,
"10.80",.17,.5566667,
"11.40",.18,.5863333,
"12.00",.19,.6166667,
"12.60",.199,.6466666,
"13.20",.207,.6766667,
"13.80",.219,.7063333,
"14.40",.227,.7363333,
"15.00",.236,.7666667,
"15.60",.246,.7963333,
"16.20",.257,.8266667,
"16.80",.268,.8566667,
"17.40",.277,.8866667,
"18.00",.287,.9166667,
"18.60",.297,.9466667,
"19.20",.309,.9763333,
"19.80",.317,1.006333,
"20.40",.328,1.036333,
"21.00",.339,1.066667,
"21.60",.347,1.096667,
"22.20",.358,1.126667,
"22.80",.365,1.156667,
"23.40",.376,1.186667,
"24.00",.388,1.216333,
"24.60",.397,1.246667,
"25.20",.41,1.276667,
"25.80",.418,1.306333,
"26.40",.427,1.336333,
"27.00",.437,1.366333,
"27.60",.451,1.396333,
"28.20",.46,1.426333,
"28.80",.471,1.456333,
"29.40",.483,1.486667,
"30.00",.492,1.516667,
"30.60",.501,1.546333,
"31.20",.511,1.576667,
"31.80",.519,1.606667,
"32.40",.531,1.636333,
"33.00",.543,1.666333,
"33.60",.553,1.696333,
"34.20",.563,1.726333,
"34.80",.573,1.756333,
"35.40",.584,1.786333,
"36.00",.595,1.816333,
"36.60",.606,1.846333,
"37.20",.62,1.876333,
"37.80",.63,1.906667,
"38.40",.64,1.936333,
"39.00",.65,1.966333,
"39.60",.661,1.996333,
"40.20",.673,2.026333,
"40.80",.684,2.056333,
"41.40",.695,2.086333,
"42.00",.705,2.116333,
"42.60",.715,2.146333,
"43.20",.728,2.176333,
"43.80",.739,2.206667,
"44.40",.75,2.236333,
"45.00",.76,2.266667,
"45.60",.774,2.296333,
"46.20",.783,2.326333,
"46.80",.796,2.356333,
"47.40",.807,2.386333,
"48.00",.819,2.416333,
"48.60",.83,2.446333,
"49.20",.842,2.476333,
"49.80",.853,2.506333,
"50.40",.866,2.536333,
"51.00",.876,2.566667,
"51.60",.889,2.596667,
"52.20",.901,2.626333,
"52.80",.911,2.656333,
"53.40",.926,2.686333,
"54.00",.936,2.716333,
"54.60",.949,2.746333,
"55.20",.96,2.776667,
"55.80",.972,2.806333,
"56.40",.985,2.836333,
"57.00",.997,2.866333,
"57.60",1.009,2.896333,
"58.20",1.022,2.926333,
"58.80",1.037,2.956,
"59.40",1.047,2.986333,
"60.00",1.062,3.016333,
"60.60",1.074,3.046333,
"61.20",1.086,3.076333,
"61.80",1.1,3.106,
"62.40",1.114,3.136333,
"63.00",1.126,3.166333,
"63.60",1.141,3.196333,
"64.20",1.153,3.226333,
"64.80",1.166,3.256333,
"65.40",1.179,3.286333,
"66.00",1.193,3.316667,
"66.60",1.208,3.346333,
"67.20",1.221,3.376667,
"67.80",1.236,3.406333,
"68.40",1.249,3.436333,
"69.00",1.264,3.466,
"69.60",1.277,3.496333,
"70.20",1.293,3.526333,
"70.80",1.307,3.556667,
"71.40",1.318,3.586333,
"72.00",1.333,3.616667,
"72.60",1.348,3.646333,
"73.20",1.363,3.676333,
"73.80",1.376,3.706333,
"74.40",1.391,3.736667,
"75.00",1.407,3.766333,
"75.60",1.423,3.796333,
"76.20",1.438,3.826667,
"76.80",1.451,3.856333,
"77.40",1.466,3.886333,
"78.00",1.481,3.916333,
"78.60",1.497,3.946333,
"79.20",1.512,3.976333,
"79.80",1.527,4.006333,
"80.40",1.544,4.036334,
"81.00",1.56,4.066333,
"81.60",1.575,4.096667,
"82.20",1.591,4.126333,
"82.80",1.605,4.156333,
"83.40",1.623,4.186666,
"84.00",1.638,4.216333,
"84.60",1.657,4.246333,
"85.20",1.672,4.276667,
"85.80",1.689,4.306334,
"86.40",1.705,4.336333,
"87.00",1.724,4.366333,
"87.60",1.74,4.396333,
"88.20",1.757,4.426333,
"88.80",1.773,4.456333,
"89.40",1.788,4.486333,
"90.00",1.806,4.516333,
"90.60",1.826,4.546333,
"91.20",1.843,4.576334,
"91.80",1.86,4.606333,
"92.40",1.878,4.636333,
"93.00",1.895,4.666333,
"93.60",1.914,4.696333,
"94.20",1.932,4.726333,
"94.80",1.949,4.756667,
"95.40",1.967,4.786334,
"96.00",1.988,4.816333,
"96.60",2.009,4.846334,
"97.20",2.027,4.876333,
"97.80",2.046,4.906667,
"98.40",2.064,4.936666,
"99.00",2.08,4.966333,
"99.60",2.102,4.996333,
"100.20",2.121,5.026667,
"100.80",2.142,5.056334,
"101.40",2.161,5.086333,
"102.00",2.181,5.116333,
"102.60",2.198,5.146333,
"103.20",2.22,5.176333,
"103.80",2.241,5.206333,
"104.40",2.258,5.236333,
"105.00",2.28,5.266333,
"105.60",2.3,5.296333,
"106.20",2.323,5.326667,
"106.80",2.343,5.356333,
"107.40",2.364,5.386667,
"108.00",2.384,5.416333,
"108.60",2.405,5.446333,
"109.20",2.427,5.476333,
"109.80",2.448,5.506333,
"110.40",2.472,5.536334,
"111.00",2.49,5.566667,
"111.60",2.511,5.596667,
"112.20",2.533,5.626333,
"112.80",2.557,5.656667,
"113.40",2.58,5.686666,
"114.00",2.6,5.716667,
"114.60",2.622,5.746666,
"115.20",2.644,5.776333,
"115.80",2.664,5.806334,
"116.40",2.689,5.836667,
"117.00",2.712,5.866667,
"117.60",2.733,5.896667,
"118.20",2.757,5.926667,
"118.80",2.778,5.956666,
"119.40",2.803,5.986667,
"120.00",2.825,6.016667,
"120.60",2.85,6.046667,
"121.20",2.873,6.076667,
"121.80",2.896,6.106667,
"122.40",2.921,6.136667,
"123.00",2.942,6.166667,
"123.60",2.967,6.196667,
"124.20",2.99,6.226333,
"124.80",3.014,6.256667,
"125.40",3.038,6.286667,
"126.00",3.061,6.316667,
"126.60",3.087,6.346667,
"127.20",3.112,6.376667,
"127.80",3.137,6.406667,
"128.40",3.162,6.436333,
"129.00",3.186,6.466333,
"129.60",3.21,6.496333,
"130.20",3.234,6.526667,
"130.80",3.26,6.556334,
"131.40",3.282,6.586667,
"132.00",3.306,6.616667,
"132.60",3.334,6.646667,
"133.20",3.358,6.676667,
"133.80",3.383,6.706666,
"134.40",3.408,6.736667,
"135.00",3.433,6.766333,
"135.60",3.458,6.796667,
"136.20",3.478,6.826334,
"136.80",3.502,6.856667,
"137.40",3.518,6.886333,
"138.00",3.521,6.916667,
"138.60",3.538,6.946333,
"139.20",3.561,6.976333,
"139.80",3.582,7.006667,
"140.40",3.607,7.036334,
"141.00",3.628,7.066333,
"141.60",3.651,7.096667,
"142.20",3.673,7.126333,
"142.80",3.698,7.156667,
"143.40",3.726,7.186666,
"144.00",3.755,7.216333,
"144.60",3.779,7.246333,
"145.20",3.803,7.276333,
"145.80",3.832,7.306334,
"146.40",3.857,7.336333,
"147.00",3.886,7.366333,
"147.60",3.915,7.396333,
"148.20",3.937,7.426333,
"148.80",3.964,7.456333,
"149.40",3.989,7.486333,
"150.00",4.018,7.516667,
"150.60",4.046,7.546333,
"151.20",4.071,7.576334,
"151.80",4.096,7.606333,
"152.40",4.117,7.636333,
"153.00",4.144,7.666333,
"153.60",4.168,7.696333,
"154.20",4.196,7.726333,
"154.80",4.223,7.756333,
"155.40",4.248,7.786334,
"156.00",4.274,7.816333,
"156.60",4.302,7.846334,
"157.20",4.327,7.876333,
"157.80",4.351,7.906333,
"158.40",4.376,7.936333,
"159.00",4.4,7.966333,
"159.60",4.43,7.996333,
"160.20",4.456,8.026334,
"160.80",4.481,8.056334,
"161.40",4.505,8.086333,
"162.00",4.531,8.116333,
"162.60",4.558,8.146334,
"163.20",4.583,8.176333,
"163.80",4.61,8.206333,
"164.40",4.636,8.236333,
"165.00",4.662,8.266334,
"165.60",4.685,8.296333,
"166.20",4.71,8.326333,
"166.80",4.737,8.356334,
"167.40",4.765,8.386333,
"168.00",4.788,8.416333,
"168.60",4.812,8.446333,
"169.20",4.839,8.476334,
"169.80",4.864,8.506333,
"170.40",4.892,8.536333,
"171.00",4.915,8.566334,
"171.60",4.94,8.596334,
"172.20",4.961,8.626333,
"172.80",4.989,8.656333,
"173.40",5.013,8.686334,
"174.00",5.039,8.716333,
"174.60",5.062,8.746333,
"175.20",5.087,8.776334,
"175.80",5.111,8.806334,
"176.40",5.136,8.836333,
"177.00",5.162,8.866667,
"177.60",5.189,8.896667,
"178.20",5.209,8.926666,
"178.80",5.234,8.956333,
"179.40",5.255,8.986667,
"180.00",5.281,9.016666,
"180.60",5.305,9.046333,
"181.20",5.329,9.076333,
"181.80",5.352,9.106334,
"182.40",5.376,9.136333,
"183.00",5.396,9.166333,
"183.60",5.423,9.196333,
"184.20",5.446,9.226666,
"184.80",5.473,9.256333,
"185.40",5.496,9.286333,
"186.00",5.514,9.316334,
"186.60",5.537,9.346334,
"187.20",5.563,9.376333,
"187.80",5.587,9.406333,
"188.40",5.608,9.436666,
"189.00",5.629,9.466333,
"189.60",5.653,9.496333,
"190.20",5.674,9.526334,
"190.80",5.697,9.556334,
"191.40",5.722,9.586333,
"192.00",5.743,9.616333,
"192.60",5.766,9.646667,
"193.20",5.79,9.676333,
"193.80",5.813,9.706333,
"194.40",5.834,9.736333,
"195.00",5.856,9.766334,
"195.60",5.877,9.796333,
"196.20",5.898,9.826333,
"196.80",5.922,9.856334,
"197.40",5.945,9.886333,
"198.00",5.967,9.916333,
"198.60",5.987,9.946333,
"199.20",6.009,9.976334,
"199.80",6.031,10.00633,
"200.40",6.051,10.036,
"201.00",6.074,10.06633,
"201.60",6.098,10.096,
"202.20",6.115,10.126,
"202.80",6.141,10.15633,
"203.40",6.161,10.18633,
"204.00",6.185,10.21633,
"204.60",6.206,10.24633,
"205.20",6.227,10.27633,
"205.80",6.246,10.30633,
"206.40",6.268,10.33633,
"207.00",6.29,10.36633,
"207.60",6.308,10.39633,
"208.20",6.328,10.426,
"208.80",6.352,10.45633,
"209.40",6.37,10.48633,
"210.00",6.391,10.51633,
"210.60",6.413,10.54633,
"211.20",6.433,10.57633,
"211.80",6.453,10.60633,
"212.40",6.473,10.63633,
"213.00",6.495,10.66633,
"213.60",6.516,10.69633,
"214.20",6.538,10.72633,
"214.80",6.557,10.75667,
"215.40",6.575,10.78633,
"216.00",6.595,10.81633,
"216.60",6.617,10.84633,
"217.20",6.638,10.87633,
"217.80",6.662,10.90667,
"218.40",6.68,10.93667,
"219.00",6.698,10.96633,
"219.60",6.717,10.99667,
"220.20",6.736,11.02667,
"220.80",6.757,11.05633,
"221.40",6.775,11.08633,
"222.00",6.796,11.11633,
"222.60",6.813,11.14633,
"223.20",6.832,11.17633,
"223.80",6.853,11.20633,
"224.40",6.872,11.23633,
"225.00",6.894,11.26633,
"225.60",6.913,11.29633,
"226.20",6.932,11.32633,
"226.80",6.951,11.35633,
"227.40",6.971,11.38633,
"228.00",6.99,11.41633,
"228.60",7.008,11.44633,
"229.20",7.026,11.47633,
"229.80",7.047,11.50633,
"230.40",7.067,11.53633,
"231.00",7.085,11.56633,
"231.60",7.106,11.59667,
"232.20",7.121,11.62633,
"232.80",7.139,11.65633,
"233.40",7.156,11.68667,
"234.00",7.177,11.71633,
"234.60",7.196,11.74633,
"235.20",7.213,11.77633,
"235.80",7.234,11.80633,
"236.40",7.248,11.83633,
"237.00",7.273,11.86633,
"237.60",7.29,11.89667,
"238.20",7.308,11.92667,
"238.80",7.325,11.95633,
"239.40",7.345,11.98667,
"240.00",7.363,12.01633,
"240.60",7.38,12.04633,
"241.20",7.4,12.07633,
"241.80",7.417,12.10633,
"242.40",7.436,12.13633,
"243.00",7.455,12.16633,
"243.60",7.474,12.19633,
"244.20",7.492,12.22633,
"244.80",7.51,12.25633,
"245.40",7.528,12.28633,
"246.00",7.544,12.31633,
"246.60",7.565,12.34633,
"247.20",7.583,12.37633,
"247.80",7.598,12.40633,
"248.40",7.615,12.43633,
"249.00",7.635,12.46633,
"249.60",7.651,12.49633,
"250.20",7.671,12.52633,
"250.80",7.688,12.55633,
"251.40",7.706,12.58633,
"252.00",7.724,12.61633,
"252.60",7.739,12.64633,
"253.20",7.758,12.67633,
"253.80",7.775,12.70633,
"254.40",7.793,12.73633,
"255.00",7.811,12.76633,
"255.60",7.829,12.79633,
"256.20",7.845,12.82633,
"256.80",7.864,12.85667,
"257.40",7.882,12.88633,
"258.00",7.899,12.91633,
"258.60",7.914,12.94633,
"259.20",7.932,12.976,
"259.80",7.951,13.00633,
"260.40",7.971,13.03633,
"261.00",7.988,13.06633,
"261.60",8.001,13.09633,
"262.20",8.02,13.12633,
"262.80",8.036,13.15633,
"263.40",8.059,13.18633,
"264.00",8.073,13.21633,
"264.60",8.092,13.24633,
"265.20",8.106,13.27633,
"265.80",8.123,13.30633,
"266.40",8.14,13.33633,
"267.00",8.16,13.36633,
"267.60",8.174,13.39633,
"268.20",8.194,13.42633,
"268.80",8.209,13.45633,
"269.40",8.223,13.48633,
"270.00",8.241,13.51633,
"270.60",8.26,13.546,
"271.20",8.277,13.57633,
"271.80",8.294,13.606,
"272.40",8.304,13.63633,
"273.00",8.324,13.66633,
"273.60",8.342,13.69633,
"274.20",8.362,13.72633,
"274.80",8.375,13.75633,
"275.40",8.392,13.78633,
"276.00",8.41,13.81667,
"276.60",8.428,13.84633,
"277.20",8.446,13.87633,
"277.80",8.463,13.90633,
"278.40",8.477,13.93633,
"279.00",8.491,13.96633,
"279.60",8.508,13.996,
"280.20",8.528,14.02633,
"280.80",8.544,14.056,
"281.40",8.561,14.08633,
"282.00",8.574,14.11633,
"282.60",8.592,14.14633,
"283.20",8.609,14.17633,
"283.80",8.625,14.20633,
"284.40",8.641,14.23633,
"285.00",8.657,14.26633,
"285.60",8.674,14.29633,
"286.20",8.691,14.32633,
"286.80",8.708,14.35633,
"287.40",8.727,14.38633,
"288.00",8.741,14.41633,
"288.60",8.757,14.44633,
"289.20",8.773,14.47633,
"289.80",8.789,14.50633,
"290.40",8.807,14.53633,
"291.00",8.822,14.56633,
"291.60",8.837,14.59633,
"292.20",8.85,14.62633,
"292.80",8.867,14.65633,
"293.40",8.886,14.68633,
"294.00",8.906,14.71633,
"294.60",8.921,14.74633,
"295.20",8.932,14.77633,
"295.80",8.947,14.80633,
"296.40",8.964,14.83633,
"297.00",8.983,14.86633,
"297.60",8.998,14.89633,
"298.20",9.011,14.92633,
"298.80",9.023,14.95633,
"299.40",9.039,14.98633,
"300.00",9.056,15.016,
"300.60",9.076,15.04633,
"301.20",9.09,15.076,
"301.80",9.105,15.10633,
"302.40",9.119,15.136,
"303.00",9.133,15.166,
"303.60",9.152,15.19633,
"304.20",9.168,15.226,
"304.80",9.186,15.256,
"305.40",9.2,15.286,
"306.00",9.215,15.31633,
"306.60",9.231,15.34633,
"307.20",9.248,15.376,
"307.80",9.265,15.40633,
"308.40",9.278,15.43633,
"309.00",9.292,15.46633,
"309.60",9.311,15.49633,
"310.20",9.326,15.52633,
"310.80",9.343,15.55633,
"311.40",9.357,15.58633,
"312.00",9.369,15.61633,
"312.60",9.388,15.64633,
"313.20",9.404,15.67633,
"313.80",9.42,15.706,
"314.40",9.432,15.736,
"315.00",9.447,15.766,
"315.60",9.462,15.796,
"316.20",9.475,15.826,
"316.80",9.492,15.85633,
"317.40",9.507,15.886,
"318.00",9.524,15.916,
"318.60",9.538,15.946,
"319.20",9.552,15.976,
"319.80",9.568,16.00633,
"320.40",9.585,16.03633,
"321.00",9.599,16.06633,
"321.60",9.613,16.096,
"322.20",9.628,16.126,
"322.80",9.643,16.15633,
"323.40",9.656,16.18633,
"324.00",9.673,16.216,
"324.60",9.689,16.246,
"325.20",9.702,16.27633,
"325.80",9.717,16.306,
"326.40",9.734,16.336,
"327.00",9.749,16.366,
"327.60",9.763,16.39633,
"328.20",9.781,16.426,
"328.80",9.796,16.45633,
"329.40",9.813,16.48633,
"330.00",9.825,16.51633,
"330.60",9.84,16.546,
"331.20",9.853,16.57633,
"331.80",9.866,16.606,
"332.40",9.88,16.636,
"333.00",9.893,16.666,
"333.60",9.908,16.696,
"334.20",9.925,16.72633,
"334.80",9.937,16.75633,
"335.40",9.951,16.786,
"336.00",9.965,16.816,
"336.60",9.98,16.84633,
"337.20",9.993,16.87633,
"337.80",10.011,16.90633,
"338.40",10.023,16.93633,
"339.00",10.035,16.96633,
"339.60",10.05,16.99633,
"340.20",10.065,17.02633,
"340.80",10.081,17.056,
"341.40",10.091,17.086,
"342.00",10.109,17.11633,
"342.60",10.122,17.14633,
"343.20",10.138,17.17633,
"343.80",10.15,17.206,
"344.40",10.164,17.23633,
"345.00",10.178,17.26633,
"345.60",10.189,17.29633,
"346.20",10.204,17.32633,
"346.80",10.219,17.35633,
"347.40",10.235,17.38633,
"348.00",10.248,17.41633,
"348.60",10.259,17.44633,
"349.20",10.272,17.47633,
"349.80",10.288,17.506,
"350.40",10.304,17.53633,
"351.00",10.32,17.56633,
"351.60",10.332,17.59633,
"352.20",10.342,17.62633,
"352.80",10.355,17.65633,
"353.40",10.372,17.68633,
"354.00",10.385,17.716,
"354.60",10.4,17.746,
"355.20",10.41,17.776,
"355.80",10.422,17.806,
"356.40",10.436,17.83633,
"357.00",10.451,17.86633,
"357.60",10.467,17.89633,
"358.20",10.481,17.92633,
"358.80",10.495,17.956,
"359.40",10.506,17.986,
"360.00",10.522,18.01633,
"360.60",10.537,18.04633,
"361.20",10.552,18.07633,
"361.80",10.561,18.10633,
"362.40",10.578,18.136,
"363.00",10.591,18.16633,
"363.60",10.602,18.196,
"364.20",10.618,18.22633,
"364.80",10.629,18.256,
"365.40",10.643,18.286,
"366.00",10.654,18.316,
"366.60",10.668,18.34633,
"367.20",10.68,18.376,
"367.80",10.696,18.40633,
"368.40",10.707,18.43633,
"369.00",10.72,18.466,
"369.60",10.733,18.496,
"370.20",10.749,18.52633,
"370.80",10.764,18.55633,
"371.40",10.775,18.58633,
"372.00",10.788,18.61633,
"372.60",10.8,18.64633,
"373.20",10.811,18.67633,
"373.80",10.826,18.70633,
"374.40",10.839,18.73633,
"375.00",10.853,18.766,
"375.60",10.866,18.796,
"376.20",10.878,18.82633,
"376.80",10.891,18.85633,
"377.40",10.903,18.886,
"378.00",10.916,18.91633,
"378.60",10.929,18.94633,
"379.20",10.943,18.976,
"379.80",10.957,19.00633,
"380.40",10.969,19.03633,
"381.00",10.984,19.06633,
"381.60",10.994,19.09633,
"382.20",11.005,19.126,
"382.80",11.018,19.156,
"383.40",11.036,19.18633,
"384.00",11.051,19.216,
"384.60",11.062,19.24633,
"385.20",11.074,19.27633,
"385.80",11.085,19.30633,
"386.40",11.096,19.33633,
"387.00",11.111,19.366,
"387.60",11.123,19.39633,
"388.20",11.134,19.42633,
"388.80",11.147,19.456,
"389.40",11.158,19.486,
"390.00",11.171,19.516,
"390.60",11.187,19.546,
"391.20",11.2,19.57633,
"391.80",11.21,19.60633,
"392.40",11.221,19.636,
"393.00",11.236,19.66633,
"393.60",11.249,19.69633,
"394.20",11.261,19.72633,
"394.80",11.274,19.75633,
"395.40",11.286,19.78633,
"396.00",11.296,19.816,
"396.60",11.31,19.84633,
"397.20",11.323,19.87633,
"397.80",11.336,19.90633,
"398.40",11.345,19.93633,
"399.00",11.357,19.966,
"399.60",11.368,19.996,
"400.20",11.381,20.02633,
"400.80",11.397,20.05633,
"401.40",11.411,20.08633,
"402.00",11.419,20.11633,
"402.60",11.431,20.14633,
"403.20",11.447,20.17633,
"403.80",11.458,20.206,
"404.40",11.47,20.23633,
"405.00",11.48,20.26633,
"405.60",11.495,20.29633,
"406.20",11.505,20.32633,
"406.80",11.516,20.35633,
"407.40",11.53,20.38633,
"408.00",11.541,20.41633,
"408.60",11.552,20.44633,
"409.20",11.563,20.47633,
"409.80",11.577,20.50633,
"410.40",11.588,20.53633,
"411.00",11.6,20.56633,
"411.60",11.61,20.59633,
"412.20",11.621,20.62633,
"412.80",11.635,20.65633,
"413.40",11.649,20.68633,
"414.00",11.666,20.71633,
"414.60",11.678,20.74633,
"415.20",11.688,20.77633,
"415.80",11.698,20.80633,
"416.40",11.71,20.83633,
"417.00",11.723,20.86633,
"417.60",11.736,20.89633,
"418.20",11.748,20.92633,
"418.80",11.759,20.95633,
"419.40",11.77,20.98633,
"420.00",11.783,21.01633,
"420.60",11.795,21.04633,
"421.20",11.807,21.07633,
"421.80",11.819,21.10633,
"422.40",11.83,21.13633,
"423.00",11.843,21.16633,
"423.60",11.853,21.19633,
"424.20",11.87,21.22633,
"424.80",11.88,21.25633,
"425.40",11.89,21.28633,
"426.00",11.905,21.31633,
"426.60",11.918,21.34633,
"427.20",11.927,21.37633,
"427.80",11.94,21.40633,
"428.40",11.948,21.43633,
"429.00",11.963,21.46633,
"429.60",11.973,21.49633,
"430.20",11.987,21.52633,
"430.80",11.996,21.556,
"431.40",12.008,21.58633,
"432.00",12.021,21.61633,
"432.60",12.028,21.64633,
"433.20",12.042,21.676,
"433.80",12.057,21.706,
"434.40",12.068,21.736,
"435.00",12.076,21.766,
"435.60",12.09,21.79633,
"436.20",12.097,21.826,
"436.80",12.112,21.85633,
"437.40",12.124,21.88633,
"438.00",12.138,21.91633,
"438.60",12.146,21.94633,
"439.20",12.158,21.976,
"439.80",12.169,22.00633,
"440.40",12.182,22.036,
"441.00",12.197,22.06633,
"441.60",12.205,22.09633,
"442.20",12.214,22.12633,
"442.80",12.229,22.15633,
"443.40",12.244,22.18633,
"444.00",12.255,22.21633,
"444.60",12.264,22.24633,
"445.20",12.275,22.27633,
"445.80",12.287,22.30633,
"446.40",12.299,22.33633,
"447.00",12.312,22.36633,
"447.60",12.324,22.39633,
"448.20",12.334,22.42633,
"448.80",12.345,22.45633,
"449.40",12.357,22.48633,
"450.00",12.369,22.51633,
"450.60",12.384,22.54633,
"451.20",12.394,22.57633,
"451.80",12.402,22.606,
"452.40",12.412,22.63633,
"453.00",12.425,22.66633,
"453.60",12.437,22.69633,
"454.20",12.449,22.72633,
"454.80",12.461,22.756,
"455.40",12.471,22.78633,
"456.00",12.482,22.81633,
"456.60",12.496,22.84633,
"457.20",12.507,22.87633,
"457.80",12.517,22.90633,
"458.40",12.528,22.93633,
"459.00",12.536,22.96633,
"459.60",12.547,22.99633,
"460.20",12.56,23.02633,
"460.80",12.571,23.05633,
"461.40",12.578,23.08633,
"462.00",12.592,23.11633,
"462.60",12.603,23.14633,
"463.20",12.615,23.17633,
"463.80",12.63,23.20633,
"464.40",12.641,23.23633,
"465.00",12.648,23.26633,
"465.60",12.657,23.29633,
"466.20",12.671,23.32633,
"466.80",12.684,23.35633,
"467.40",12.695,23.38633,
"468.00",12.706,23.41633,
"468.60",12.714,23.44633,
"469.20",12.726,23.47633,
"469.80",12.735,23.50633,
"470.40",12.749,23.53633,
"471.00",12.76,23.56633,
"471.60",12.769,23.59633,
"472.20",12.781,23.62633,
"472.80",12.789,23.65633,
"473.40",12.802,23.68633,
"474.00",12.814,23.71633,
"474.60",12.824,23.74633,
"475.20",12.833,23.77633,
"475.80",12.846,23.80633,
"476.40",12.856,23.83633,
"477.00",12.871,23.86633,
"477.60",12.881,23.89633,
"478.20",12.89,23.92633,
"478.80",12.901,23.956,
"479.40",12.911,23.98633,
"480.00",12.927,24.01633,
"480.60",12.938,24.04633,
"481.20",12.949,24.07633,
"481.80",12.954,24.10633,
"482.40",12.968,24.13633,
"483.00",12.98,24.16633,
"483.60",12.991,24.19633,
"484.20",13.007,24.22633,
"484.80",13.013,24.25667,
"485.40",13.024,24.28667,
"486.00",13.031,24.31633,
"486.60",13.047,24.34633,
"487.20",13.054,24.37633,
"487.80",13.067,24.40633,
"488.40",13.076,24.43633,
"489.00",13.087,24.46633,
"489.60",13.097,24.49633,
"490.20",13.108,24.52633,
"490.80",13.117,24.55633,
"491.40",13.125,24.58633,
"492.00",13.137,24.61633,
"492.60",13.148,24.646,
"493.20",13.157,24.676,
"493.80",13.17,24.706,
"494.40",13.178,24.73633,
"495.00",13.189,24.766,
"495.60",13.199,24.79633,
"496.20",13.212,24.82633,
"496.80",13.225,24.85633,
"497.40",13.236,24.88633,
"498.00",13.247,24.91633,
"498.60",13.253,24.94633,
"499.20",13.264,24.97633,
"499.80",13.275,25.00633,
"500.40",13.29,25.03633,
"501.00",13.299,25.06633,
"501.60",13.306,25.096,
"502.20",13.315,25.12633,
"502.80",13.325,25.15633,
"503.40",13.336,25.18633,
"504.00",13.349,25.216,
"504.60",13.36,25.24633,
"505.20",13.37,25.27633,
"505.80",13.378,25.306,
"506.40",13.387,25.33633,
"507.00",13.397,25.366,
"507.60",13.408,25.396,
"508.20",13.419,25.42633,
"508.80",13.432,25.45633,
"509.40",13.442,25.48633,
"510.00",13.452,25.51633,
"510.60",13.458,25.546,
"511.20",13.469,25.57633,
"511.80",13.479,25.606,
"512.40",13.487,25.636,
"513.00",13.501,25.66633,
"513.60",13.512,25.696,
"514.20",13.52,25.726,
"514.80",13.532,25.756,
"515.40",13.541,25.78633,
"516.00",13.55,25.81633,
"516.60",13.562,25.84633,
"517.20",13.576,25.876,
"517.80",13.583,25.906,
"518.40",13.59,25.936,
"519.00",13.601,25.966,
"519.60",13.61,25.996,
"520.20",13.626,26.026,
"520.80",13.635,26.056,
"521.40",13.644,26.086,
"522.00",13.65,26.11633,
"522.60",13.659,26.146,
"523.20",13.67,26.17633,
"523.80",13.685,26.20633,
"524.40",13.692,26.236,
"525.00",13.703,26.26633,
"525.60",13.712,26.296,
"526.20",13.721,26.32633,
"526.80",13.734,26.35633,
"527.40",13.744,26.38633,
"528.00",13.753,26.41633,
"528.60",13.759,26.44633,
"529.20",13.771,26.476,
"529.80",13.782,26.50633,
"530.40",13.79,26.536,
"531.00",13.801,26.566,
"531.60",13.809,26.596,
"532.20",13.818,26.62633,
"532.80",13.826,26.65633,
"533.40",13.84,26.686,
"534.00",13.85,26.716,
"534.60",13.86,26.746,
"535.20",13.868,26.77633,
"535.80",13.879,26.806,
"536.40",13.886,26.83633,
"537.00",13.901,26.86633,
"537.60",13.909,26.89633,
"538.20",13.919,26.92633,
"538.80",13.928,26.95633,
"539.40",13.935,26.98633,
"540.00",13.944,27.01633,
"540.60",13.957,27.04633,
"541.20",13.965,27.07633,
"541.80",13.974,27.10633,
"542.40",13.981,27.13633,
"543.00",13.992,27.16633,
"543.60",14.003,27.19633,
"544.20",14.011,27.22633,
"544.80",14.019,27.25633,
"545.40",14.029,27.286,
"546.00",14.038,27.31633,
"546.60",14.05,27.34633,
"547.20",14.059,27.376,
"547.80",14.07,27.406,
"548.40",14.077,27.43633,
"549.00",14.086,27.466,
"549.60",14.096,27.496,
"550.20",14.108,27.52633,
"550.80",14.119,27.556,
"551.40",14.126,27.586,
"552.00",14.132,27.616,
"552.60",14.141,27.646,
"553.20",14.15,27.676,
"553.80",14.161,27.706,
"554.40",14.171,27.73633,
"555.00",14.181,27.766,
"555.60",14.188,27.796,
"556.20",14.196,27.82633,
"556.80",14.209,27.85633,
"557.40",14.217,27.886,
"558.00",14.225,27.91633,
"558.60",14.234,27.946,
"559.20",14.243,27.976,
"559.80",14.253,28.006,
"560.40",14.263,28.036,
"561.00",14.274,28.06633,
"561.60",14.282,28.09633,
"562.20",14.29,28.126,
"562.80",14.302,28.156,
"563.40",14.314,28.18633,
"564.00",14.326,28.21633,
"564.60",14.334,28.24633,
"565.20",14.341,28.27633,
"565.80",14.347,28.306,
"566.40",14.358,28.336,
"567.00",14.371,28.366,
"567.60",14.38,28.396,
"568.20",14.389,28.426,
"568.80",14.395,28.45633,
"569.40",14.402,28.486,
"570.00",14.412,28.516,
"570.60",14.424,28.546,
"571.20",14.432,28.57633,
"571.80",14.439,28.60633,
"572.40",14.45,28.63633,
"573.00",14.457,28.66633,
"573.60",14.467,28.69633,
"574.20",14.478,28.726,
"574.80",14.483,28.756,
"575.40",14.491,28.786,
"576.00",14.501,28.81633,
"576.60",14.512,28.84633,
"577.20",14.523,28.876,
"577.80",14.531,28.90633,
"578.40",14.54,28.93633,
"579.00",14.546,28.966,
"579.60",14.555,28.99633,
"580.20",14.569,29.02633,
"580.80",14.575,29.056,
"581.40",14.584,29.086,
"582.00",14.588,29.11633,
"582.60",14.597,29.146,
"583.20",14.605,29.17633,
"583.80",14.616,29.20633,
"584.40",14.628,29.23633,
"585.00",14.637,29.26633,
"585.60",14.646,29.29633,
"586.20",14.653,29.32633,
"586.80",14.665,29.35667,
"587.40",14.675,29.38667,
"588.00",14.684,29.41633,
"588.60",14.686,29.44633,
"589.20",14.695,29.47633,
"589.80",14.706,29.50633,
"590.40",14.717,29.53633,
"591.00",14.725,29.56633,
"591.60",14.734,29.59633,
"592.20",14.741,29.62633,
"592.80",14.751,29.656,
"593.40",14.759,29.68633,
"594.00",14.773,29.716,
"594.60",14.779,29.746,
"595.20",14.786,29.776,
"595.80",14.796,29.80633,
"596.40",14.809,29.83633,
"597.00",14.818,29.866,
"597.60",14.828,29.89633,
"598.20",14.833,29.92633,
"598.80",14.841,29.956,
"599.40",14.846,29.98633,
"600.00",14.858,30.01633,
"600.60",14.87,30.04633,
"601.20",14.879,30.076,
"601.80",14.887,30.10633,
"602.40",14.893,30.13633,
"603.00",14.9,30.166,
"603.60",14.911,30.196,
"604.20",14.923,30.22633,
"604.80",14.927,30.256,
"605.40",14.936,30.28633,
"606.00",14.941,30.31633,
"606.60",14.948,30.346,
"607.20",14.96,30.37633,
"607.80",14.968,30.40633,
"608.40",14.977,30.436,
"609.00",14.985,30.466,
"609.60",14.995,30.496,
"610.20",15.004,30.526,
"610.80",15.013,30.556,
"611.40",15.022,30.58633,
"612.00",15.03,30.61633,
"612.60",15.041,30.64633,
"613.20",15.05,30.67633,
"613.80",15.06,30.706,
"614.40",15.067,30.736,
"615.00",15.077,30.766,
"615.60",15.08,30.796,
"616.20",15.09,30.826,
"616.80",15.101,30.85633,
"617.40",15.112,30.88633,
"618.00",15.119,30.916,
"618.60",15.125,30.946,
"619.20",15.132,30.976,
"619.80",15.139,31.006,
"620.40",15.152,31.036,
"621.00",15.163,31.066,
"621.60",15.17,31.09633,
"622.20",15.178,31.126,
"622.80",15.181,31.156,
"623.40",15.191,31.18633,
"624.00",15.201,31.216,
"624.60",15.208,31.246,
"625.20",15.214,31.27633,
"625.80",15.224,31.306,
"626.40",15.232,31.33633,
"627.00",15.244,31.366,
"627.60",15.252,31.39633,
"628.20",15.259,31.42633,
"628.80",15.269,31.456,
"629.40",15.275,31.486,
"630.00",15.284,31.51633,
"630.60",15.293,31.546,
"631.20",15.301,31.57633,
"631.80",15.306,31.60633,
"632.40",15.313,31.636,
"633.00",15.322,31.66633,
"633.60",15.332,31.69633,
"634.20",15.341,31.726,
"634.80",15.348,31.75633,
"635.40",15.354,31.786,
"636.00",15.364,31.81633,
"636.60",15.373,31.846,
"637.20",15.383,31.876,
"637.80",15.391,31.90633,
"638.40",15.4,31.93633,
"639.00",15.404,31.966,
"639.60",15.41,31.996,
"640.20",15.421,32.026,
"640.80",15.431,32.05633,
"641.40",15.437,32.08633,
"642.00",15.443,32.116,
"642.60",15.454,32.146,
"643.20",15.461,32.176,
"643.80",15.472,32.206,
"644.40",15.48,32.236,
"645.00",15.485,32.26633,
"645.60",15.493,32.296,
"646.20",15.501,32.32633,
"646.80",15.513,32.35633,
"647.40",15.52,32.386,
"648.00",15.525,32.41633,
"648.60",15.533,32.446,
"649.20",15.537,32.476,
"649.80",15.546,32.506,
"650.40",15.555,32.536,
"651.00",15.563,32.566,
"651.60",15.573,32.596,
"652.20",15.575,32.626,
"652.80",15.582,32.65633,
"653.40",15.592,32.68633,
"654.00",15.604,32.716,
"654.60",15.613,32.74633,
"655.20",15.62,32.776,
"655.80",15.624,32.806,
"656.40",15.633,32.836,
"657.00",15.642,32.86633,
"657.60",15.65,32.89633,
"658.20",15.656,32.92633,
"658.80",15.662,32.956,
"659.40",15.672,32.986,
"660.00",15.68,33.016,
"660.60",15.69,33.046,
"661.20",15.697,33.07633,
"661.80",15.706,33.106,
"662.40",15.712,33.136,
"663.00",15.719,33.16633,
"663.60",15.733,33.19633,
"664.20",15.743,33.22633,
"664.80",15.745,33.256,
"665.40",15.751,33.286,
"666.00",15.757,33.316,
"666.60",15.766,33.346,
"667.20",15.779,33.37634,
"667.80",15.785,33.406,
"668.40",15.791,33.43633,
"669.00",15.798,33.466,
"669.60",15.803,33.496,
"670.20",15.815,33.52633,
"670.80",15.821,33.556,
"671.40",15.831,33.58633,
"672.00",15.838,33.61633,
"672.60",15.846,33.646,
"673.20",15.852,33.67633,
"673.80",15.859,33.706,
"674.40",15.868,33.73633,
"675.00",15.873,33.766,
"675.60",15.882,33.79633,
"676.20",15.893,33.82633,
"676.80",15.902,33.85633,
"677.40",15.909,33.88633,
"678.00",15.914,33.91633,
"678.60",15.918,33.946,
"679.20",15.929,33.976,
"679.80",15.94,34.006,
"680.40",15.947,34.036,
"681.00",15.955,34.06633,
"681.60",15.96,34.096,
"682.20",15.966,34.126,
"682.80",15.973,34.15633,
"683.40",15.984,34.18633,
"684.00",15.989,34.216,
"684.60",15.998,34.246,
"685.20",16.004,34.27633,
"685.80",16.01,34.306,
"686.40",16.018,34.33633,
"687.00",16.029,34.36633,
"687.60",16.038,34.39633,
"688.20",16.043,34.426,
"688.80",16.05,34.45633,
"689.40",16.055,34.486,
"690.00",16.063,34.51633,
"690.60",16.071,34.54633,
"691.20",16.08,34.57633,
"691.80",16.087,34.60633,
"692.40",16.094,34.636,
"693.00",16.101,34.66633,
"693.60",16.112,34.69633,
"694.20",16.12,34.72633,
"694.80",16.126,34.756,
"695.40",16.133,34.786,
"696.00",16.14,34.81633,
"696.60",16.152,34.84633,
"697.20",16.159,34.87634,
"697.80",16.161,34.90633,
"698.40",16.167,34.93633,
"699.00",16.174,34.966,
"699.60",16.18,34.996,
"700.20",16.19,35.02633,
"700.80",16.199,35.05633,
"701.40",16.208,35.086,
"702.00",16.213,35.11633,
"702.60",16.22,35.14633,
"703.20",16.229,35.176,
"703.80",16.238,35.206,
"704.40",16.246,35.23633,
"705.00",16.253,35.26633,
"705.60",16.258,35.29633,
"706.20",16.268,35.32633,
"706.80",16.276,35.35633,
"707.40",16.283,35.386,
"708.00",16.288,35.416,
"708.60",16.296,35.446,
"709.20",16.304,35.476,
"709.80",16.312,35.506,
"710.40",16.324,35.536,
"711.00",16.33,35.56633,
"711.60",16.332,35.59633,
"712.20",16.337,35.626,
"712.80",16.347,35.65633,
"713.40",16.358,35.68633,
"714.00",16.364,35.71633,
"714.60",16.369,35.746,
"715.20",16.377,35.776,
"715.80",16.38,35.806,
"716.40",16.388,35.83633,
"717.00",16.402,35.86633,
"717.60",16.41,35.89633,
"718.20",16.412,35.926,
"718.80",16.417,35.956,
"719.40",16.423,35.986,
"720.00",16.431,36.01633,
"720.60",16.439,36.04633,
"721.20",16.447,36.07633,
"721.80",16.452,36.10633,
"722.40",16.457,36.136,
"723.00",16.466,36.166,
"723.60",16.472,36.196,
"724.20",16.482,36.22633,
"724.80",16.488,36.25633,
"725.40",16.49,36.28633,
"726.00",16.499,36.316,
"726.60",16.506,36.34633,
"727.20",16.516,36.37634,
"727.80",16.526,36.40633,
"728.40",16.532,36.436,
"729.00",16.534,36.466,
"729.60",16.544,36.49633,
"730.20",16.554,36.52633,
"730.80",16.561,36.556,
"731.40",16.567,36.586,
"732.00",16.569,36.616,
"732.60",16.577,36.64633,
"733.20",16.58,36.67633,
"733.80",16.593,36.706,
"734.40",16.604,36.73633,
"735.00",16.606,36.766,
"735.60",16.612,36.796,
"736.20",16.617,36.82633,
"736.80",16.626,36.85633,
"737.40",16.634,36.88633,
"738.00",16.639,36.916,
"738.60",16.646,36.94633,
"739.20",16.654,36.976,
"739.80",16.658,37.006,
"740.40",16.668,37.036,
"741.00",16.677,37.066,
"741.60",16.684,37.09633,
"742.20",16.691,37.12634,
"742.80",16.694,37.156,
"743.40",16.703,37.18633,
"744.00",16.711,37.216,
"744.60",16.716,37.24633,
"745.20",16.719,37.27633,
"745.80",16.727,37.30633,
"746.40",16.732,37.33633,
"747.00",16.742,37.366,
"747.60",16.746,37.396,
"748.20",16.751,37.426,
"748.80",16.758,37.45633,
"749.40",16.76,37.48633,
"750.00",16.771,37.51633,
"750.60",16.78,37.546,
"751.20",16.788,37.57633,
"751.80",16.793,37.606,
"752.40",16.798,37.636,
"753.00",16.807,37.666,
"753.60",16.816,37.696,
"754.20",16.824,37.726,
"754.80",16.831,37.75633,
"755.40",16.841,37.786,
"756.00",16.845,37.816,
"756.60",16.852,37.846,
"757.20",16.862,37.876,
"757.80",16.866,37.906,
"758.40",16.874,37.936,
"759.00",16.879,37.966,
"759.60",16.886,37.99633,
"760.20",16.898,38.02633,
"760.80",16.904,38.05633,
"761.40",16.906,38.08633,
"762.00",16.912,38.116,
"762.60",16.919,38.14633,
"763.20",16.927,38.17633,
"763.80",16.935,38.20633,
"764.40",16.942,38.23633,
"765.00",16.945,38.26633,
"765.60",16.948,38.29633,
"766.20",16.955,38.32633,
"766.80",16.963,38.35633,
"767.40",16.971,38.38633,
"768.00",16.978,38.41633,
"768.60",16.983,38.44633,
"769.20",16.987,38.47633,
"769.80",16.996,38.506,
"770.40",17.005,38.536,
"771.00",17.013,38.566,
"771.60",17.017,38.59633,
"772.20",17.021,38.626,
"772.80",17.026,38.65633,
"773.40",17.036,38.68633,
"774.00",17.041,38.716,
"774.60",17.048,38.746,
"775.20",17.052,38.776,
"775.80",17.059,38.80633,
"776.40",17.065,38.83633,
"777.00",17.074,38.86633,
"777.60",17.081,38.896,
"778.20",17.087,38.92633,
"778.80",17.092,38.956,
"779.40",17.099,38.98633,
"780.00",17.109,39.01633,
"780.60",17.117,39.04633,
"781.20",17.122,39.07633,
"781.80",17.127,39.10633,
"782.40",17.131,39.13633,
"783.00",17.136,39.16633,
"783.60",17.145,39.19633,
"784.20",17.153,39.22633,
"784.80",17.159,39.25633,
"785.40",17.162,39.286,
"786.00",17.165,39.31633,
"786.60",17.175,39.346,
"787.20",17.186,39.376,
"787.80",17.188,39.40633,
"788.40",17.194,39.436,
"789.00",17.198,39.466,
"789.60",17.204,39.496,
"790.20",17.212,39.52633,
"790.80",17.221,39.556,
"791.40",17.226,39.586,
"792.00",17.229,39.61633,
"792.60",17.235,39.646,
"793.20",17.244,39.67633,
"793.80",17.251,39.706,
"794.40",17.259,39.736,
"795.00",17.263,39.766,
"795.60",17.271,39.796,
"796.20",17.277,39.82633,
"796.80",17.287,39.85633,
"797.40",17.292,39.886,
"798.00",17.296,39.916,
"798.60",17.302,39.94633,
"799.20",17.306,39.97633,
"799.80",17.315,40.00633,
"800.40",17.326,40.036,
"801.00",17.333,40.066,
"801.60",17.337,40.09633,
"802.20",17.342,40.12634,
"802.80",17.349,40.156,
"803.40",17.355,40.18633,
"804.00",17.365,40.216,
"804.60",17.371,40.246,
"805.20",17.375,40.276,
"805.80",17.378,40.306,
"806.40",17.385,40.336,
"807.00",17.393,40.366,
"807.60",17.396,40.396,
"808.20",17.404,40.426,
"808.80",17.41,40.456,
"809.40",17.413,40.486,
"810.00",17.419,40.516,
"810.60",17.429,40.546,
"811.20",17.431,40.576,
"811.80",17.435,40.606,
"812.40",17.441,40.636,
"813.00",17.446,40.666,
"813.60",17.457,40.69633,
"814.20",17.461,40.72633,
"814.80",17.468,40.75633,
"815.40",17.471,40.786,
"816.00",17.476,40.81633,
"816.60",17.482,40.84633,
"817.20",17.491,40.87634,
"817.80",17.495,40.90633,
"818.40",17.498,40.936,
"819.00",17.499,40.966,
"819.60",17.508,40.996,
"820.20",17.515,41.026,
"820.80",17.524,41.056,
"821.40",17.53,41.08633,
"822.00",17.533,41.11633,
"822.60",17.535,41.146,
"823.20",17.543,41.17633,
"823.80",17.549,41.20633,
"824.40",17.553,41.23633,
"825.00",17.556,41.266,
"825.60",17.56,41.29633,
"826.20",17.567,41.32633,
"826.80",17.576,41.356,
"827.40",17.583,41.386,
"828.00",17.584,41.416,
"828.60",17.587,41.446,
"829.20",17.592,41.476,
"829.80",17.601,41.506,
"830.40",17.606,41.536,
"831.00",17.611,41.566,
"831.60",17.614,41.59633,
"832.20",17.618,41.626,
"832.80",17.621,41.65633,
"833.40",17.628,41.686,
"834.00",17.635,41.716,
"834.60",17.641,41.746,
"835.20",17.642,41.776,
"835.80",17.646,41.806,
"836.40",17.649,41.836,
"837.00",17.659,41.866,
"837.60",17.667,41.896,
"838.20",17.67,41.926,
"838.80",17.673,41.956,
"839.40",17.677,41.986,
"840.00",17.682,42.01633,
"840.60",17.691,42.04633,
"841.20",17.692,42.07633,
"841.80",17.698,42.106,
"842.40",17.705,42.13633,
"843.00",17.709,42.16633,
"843.60",17.718,42.196,
"844.20",17.721,42.226,
"844.80",17.729,42.256,
"845.40",17.731,42.286,
"846.00",17.735,42.316,
"846.60",17.741,42.346,
"847.20",17.75,42.376,
"847.80",17.754,42.406,
"848.40",17.757,42.436,
"849.00",17.764,42.46633,
"849.60",17.767,42.49633,
"850.20",17.777,42.526,
"850.80",17.785,42.556,
"851.40",17.789,42.586,
"852.00",17.794,42.616,
"852.60",17.799,42.646,
"853.20",17.805,42.676,
"853.80",17.812,42.706,
"854.40",17.82,42.736,
"855.00",17.825,42.766,
"855.60",17.83,42.796,
"856.20",17.835,42.826,
"856.80",17.842,42.856,
"857.40",17.849,42.88633,
"858.00",17.853,42.916,
"858.60",17.858,42.946,
"859.20",17.863,42.97633,
"859.80",17.872,43.00633,
"860.40",17.879,43.036,
"861.00",17.883,43.06633,
"861.60",17.886,43.096,
"862.20",17.888,43.126,
"862.80",17.894,43.15633,
"863.40",17.906,43.18633,
"864.00",17.914,43.216,
"864.60",17.916,43.246,
"865.20",17.916,43.27633,
"865.80",17.921,43.30633,
"866.40",17.928,43.33633,
"867.00",17.938,43.366,
"867.60",17.946,43.39633,
"868.20",17.949,43.426,
"868.80",17.95,43.45633,
"869.40",17.956,43.48633,
"870.00",17.96,43.51633,
"870.60",17.97,43.546,
"871.20",17.977,43.576,
"871.80",17.977,43.60633,
"872.40",17.979,43.636,
"873.00",17.988,43.666,
"873.60",17.991,43.696,
"874.20",17.996,43.72633,
"874.80",18.002,43.756,
"875.40",18.004,43.78633,
"876.00",18.012,43.816,
"876.60",18.018,43.846,
"877.20",18.025,43.876,
"877.80",18.027,43.90633,
"878.40",18.031,43.936,
"879.00",18.034,43.966,
"879.50",18.025,43.99133,