File: load_extensions/exposure1/exposed_monofilament_3.csv
"Test Name","Test Mode","Test Type","Control","Test Speed 1","Test Speed 2","Test Speed 3","Change Point 1","Change Point 2","Disp. Origin","Break and Limit Action","Sensitivity:","Level:"
"","Single","Tensile","Stroke",10,1,1,"Off","Off","Start","Stop",0,1

"Title","Sub title","Comment"
"","",""

"Shape:","Batch Size:","SubBatch Size:"
"Plate",1,1
"Name:","Thickness","Width","Gauge Length",
"Size Unit:","mm","mm","mm",
" 1 - 1","1.0000","1.0000","100.0000",

"Name",
"Parameter",
"Units",
" 1 - 1",

" 1- 1"
"Time","Force","Stroke",
"sec","N","mm",
"0.00",.002,0,
"0.20",.004,.037,
"0.40",.017,7.366666E-02,
"0.60",.032,.1106667,
"0.80",.047,.1473333,
"1.00",.065,.1843333,
"1.20",.081,.221,
"1.40",.099,.2576667,
"1.60",.112,.2946667,
"1.80",.131,.3313333,
"2.00",.146,.368,
"2.20",.161,.4036667,
"2.40",.174,.4393333,
"2.60",.19,.4743333,
"2.80",.204,.509,
"3.00",.219,.5433334,
"3.20",.231,.5776667,
"3.40",.247,.6116667,
"3.60",.259,.6456667,
"3.80",.275,.6793334,
"4.00",.289,.7133334,
"4.20",.302,.747,
"4.40",.313,.7806667,
"4.60",.329,.814,
"4.80",.344,.8476667,
"5.00",.356,.881,
"5.20",.371,.9143333,
"5.40",.384,.948,
"5.60",.397,.9813334,
"5.80",.41,1.014667,
"6.00",.421,1.048,
"6.20",.437,1.081333,
"6.40",.451,1.114667,
"6.60",.462,1.148333,
"6.80",.476,1.181667,
"7.00",.493,1.215,
"7.20",.506,1.248333,
"7.40",.52,1.281667,
"7.60",.531,1.315,
"7.80",.543,1.348333,
"8.00",.558,1.381667,
"8.20",.571,1.415,
"8.40",.583,1.448333,
"8.60",.599,1.481667,
"8.80",.609,1.515,
"9.00",.621,1.548,
"9.20",.637,1.581667,
"9.40",.649,1.615,
"9.60",.662,1.648333,
"9.80",.676,1.681667,
"10.00",.688,1.715,
"10.20",.703,1.748,
"10.40",.714,1.781333,
"10.60",.727,1.814667,
"10.80",.74,1.848,
"11.00",.753,1.881333,
"11.20",.766,1.915,
"11.40",.78,1.948333,
"11.60",.792,1.981667,
"11.80",.806,2.015,
"12.00",.818,2.048333,
"12.20",.832,2.081667,
"12.40",.846,2.115,
"12.60",.857,2.148333,
"12.80",.871,2.181667,
"13.00",.886,2.215,
"13.20",.899,2.248333,
"13.40",.912,2.281667,
"13.60",.925,2.315,
"13.80",.937,2.348333,
"14.00",.953,2.381667,
"14.20",.967,2.415,
"14.40",.981,2.448,
"14.60",.995,2.481667,
"14.80",1.007,2.515,
"15.00",1.024,2.548,
"15.20",1.037,2.581667,
"15.40",1.049,2.615,
"15.60",1.063,2.648333,
"15.80",1.078,2.681667,
"16.00",1.093,2.715,
"16.20",1.108,2.748333,
"16.40",1.12,2.781667,
"16.60",1.135,2.815,
"16.80",1.15,2.848333,
"17.00",1.165,2.881667,
"17.20",1.18,2.915,
"17.40",1.195,2.948333,
"17.60",1.209,2.981667,
"17.80",1.223,3.015,
"18.00",1.239,3.048333,
"18.20",1.253,3.081667,
"18.40",1.269,3.115,
"18.60",1.285,3.148333,
"18.80",1.299,3.181667,
"19.00",1.313,3.214667,
"19.20",1.331,3.248333,
"19.40",1.345,3.281667,
"19.60",1.361,3.315,
"19.80",1.375,3.348333,
"20.00",1.394,3.381667,
"20.20",1.408,3.415,
"20.40",1.424,3.448333,
"20.60",1.44,3.481333,
"20.80",1.454,3.514667,
"21.00",1.473,3.548,
"21.20",1.49,3.581333,
"21.40",1.504,3.614667,
"21.60",1.521,3.648,
"21.80",1.537,3.681667,
"22.00",1.558,3.714667,
"22.20",1.573,3.748333,
"22.40",1.591,3.781333,
"22.60",1.608,3.814667,
"22.80",1.626,3.848,
"23.00",1.642,3.881333,
"23.20",1.661,3.914667,
"23.40",1.677,3.948,
"23.60",1.698,3.981333,
"23.80",1.714,4.014667,
"24.00",1.731,4.048,
"24.20",1.749,4.081666,
"24.40",1.769,4.114666,
"24.60",1.789,4.148,
"24.80",1.807,4.181333,
"25.00",1.823,4.215,
"25.20",1.847,4.248333,
"25.40",1.864,4.281666,
"25.60",1.883,4.315,
"25.80",1.902,4.348333,
"26.00",1.922,4.381667,
"26.20",1.941,4.415,
"26.40",1.959,4.448333,
"26.60",1.982,4.481667,
"26.80",2.001,4.515,
"27.00",2.022,4.548333,
"27.20",2.042,4.581666,
"27.40",2.061,4.615,
"27.60",2.081,4.648333,
"27.80",2.102,4.681666,
"28.00",2.124,4.715,
"28.20",2.143,4.748333,
"28.40",2.163,4.781666,
"28.60",2.187,4.814666,
"28.80",2.206,4.848333,
"29.00",2.226,4.881667,
"29.20",2.25,4.915,
"29.40",2.272,4.948333,
"29.60",2.292,4.981667,
"29.80",2.315,5.015,
"30.00",2.338,5.048333,
"30.20",2.359,5.081666,
"30.40",2.385,5.115,
"30.60",2.407,5.148333,
"30.80",2.428,5.181666,
"31.00",2.453,5.215,
"31.20",2.479,5.248333,
"31.40",2.501,5.281666,
"31.60",2.524,5.315,
"31.80",2.547,5.348333,
"32.00",2.573,5.381667,
"32.20",2.596,5.415,
"32.40",2.618,5.448333,
"32.60",2.643,5.481667,
"32.80",2.671,5.515,
"33.00",2.696,5.548333,
"33.20",2.721,5.581666,
"33.40",2.744,5.615,
"33.60",2.768,5.648333,
"33.80",2.795,5.681666,
"34.00",2.821,5.715,
"34.20",2.846,5.748333,
"34.40",2.871,5.781666,
"34.60",2.897,5.815,
"34.80",2.925,5.848333,
"35.00",2.95,5.881667,
"35.20",2.98,5.915,
"35.40",3.008,5.948333,
"35.60",3.034,5.981667,
"35.80",3.062,6.015,
"36.00",3.087,6.048333,
"36.20",3.117,6.081666,
"36.40",3.141,6.115,
"36.60",3.17,6.148333,
"36.80",3.199,6.181666,
"37.00",3.228,6.215,
"37.20",3.255,6.248333,
"37.40",3.28,6.281666,
"37.60",3.309,6.315,
"37.80",3.337,6.348333,
"38.00",3.366,6.381667,
"38.20",3.396,6.415,
"38.40",3.425,6.448333,
"38.60",3.454,6.481667,
"38.80",3.483,6.515,
"39.00",3.514,6.548333,
"39.20",3.547,6.581666,
"39.40",3.574,6.615,
"39.60",3.603,6.648333,
"39.80",3.634,6.681666,
"40.00",3.664,6.715,
"40.20",3.696,6.748333,
"40.40",3.725,6.781666,
"40.60",3.756,6.815,
"40.80",3.783,6.848333,
"41.00",3.816,6.881333,
"41.20",3.846,6.915,
"41.40",3.877,6.948333,
"41.60",3.907,6.981333,
"41.80",3.937,7.015,
"42.00",3.971,7.048333,
"42.20",4.006,7.081666,
"42.40",4.035,7.115,
"42.60",4.066,7.148333,
"42.80",4.097,7.181666,
"43.00",4.131,7.215,
"43.20",4.161,7.248333,
"43.40",4.196,7.281666,
"43.60",4.227,7.315,
"43.80",4.262,7.348333,
"44.00",4.293,7.381667,
"44.20",4.33,7.415,
"44.40",4.36,7.448333,
"44.60",4.395,7.481667,
"44.80",4.426,7.515,
"45.00",4.462,7.548333,
"45.20",4.492,7.581666,
"45.40",4.525,7.615,
"45.60",4.56,7.648333,
"45.80",4.591,7.681666,
"46.00",4.627,7.715,
"46.20",4.659,7.748333,
"46.40",4.695,7.781666,
"46.60",4.727,7.815,
"46.80",4.762,7.848,
"47.00",4.798,7.881333,
"47.20",4.828,7.914667,
"47.40",4.864,7.948,
"47.60",4.897,7.981333,
"47.80",4.933,8.014999,
"48.00",4.968,8.048333,
"48.20",5.005,8.081666,
"48.40",5.036,8.115,
"48.60",5.07,8.148334,
"48.80",5.104,8.181666,
"49.00",5.143,8.215,
"49.20",5.176,8.248333,
"49.40",5.208,8.281667,
"49.60",5.244,8.315,
"49.80",5.278,8.348333,
"50.00",5.31,8.381333,
"50.20",5.345,8.415,
"50.40",5.38,8.448333,
"50.60",5.412,8.481667,
"50.80",5.449,8.514999,
"51.00",5.482,8.547999,
"51.20",5.513,8.581666,
"51.40",5.549,8.615,
"51.60",5.583,8.648,
"51.80",5.617,8.681666,
"52.00",5.653,8.715,
"52.20",5.685,8.748333,
"52.40",5.719,8.781667,
"52.60",5.752,8.814667,
"52.80",5.786,8.848333,
"53.00",5.824,8.881333,
"53.20",5.856,8.915,
"53.40",5.889,8.948,
"53.60",5.92,8.981333,
"53.80",5.954,9.014667,
"54.00",5.988,9.047999,
"54.20",6.022,9.081666,
"54.40",6.056,9.115,
"54.60",6.085,9.148334,
"54.80",6.121,9.181666,
"55.00",6.151,9.214666,
"55.20",6.183,9.248,
"55.40",6.216,9.281333,
"55.60",6.248,9.314667,
"55.80",6.279,9.348,
"56.00",6.31,9.381333,
"56.20",6.343,9.414666,
"56.40",6.375,9.448,
"56.60",6.405,9.481333,
"56.80",6.437,9.514999,
"57.00",6.468,9.547999,
"57.20",6.498,9.581666,
"57.40",6.527,9.615,
"57.60",6.558,9.648334,
"57.80",6.589,9.681666,
"58.00",6.619,9.715,
"58.20",6.647,9.748,
"58.40",6.673,9.781333,
"58.60",6.701,9.814667,
"58.80",6.728,9.848,
"59.00",6.758,9.881333,
"59.20",6.785,9.914666,
"59.40",6.809,9.948,
"59.60",6.837,9.981333,
"59.80",6.864,10.01467,
"60.00",6.895,10.048,
"60.20",6.924,10.08133,
"60.40",6.952,10.11467,
"60.60",6.979,10.148,
"60.80",7.006,10.18133,
"61.00",7.035,10.21467,
"61.20",7.063,10.24833,
"61.40",7.087,10.28167,
"61.60",7.109,10.315,
"61.80",7.132,10.34833,
"62.00",7.148,10.38167,
"62.20",7.161,10.415,
"62.40",7.171,10.44833,
"62.60",7.193,10.48167,
"62.80",7.211,10.515,
"63.00",7.234,10.54833,
"63.20",7.254,10.58167,
"63.40",7.277,10.615,
"63.60",7.299,10.648,
"63.80",7.323,10.68133,
"64.00",7.354,10.71467,
"64.20",7.38,10.74833,
"64.40",7.409,10.78167,
"64.60",7.44,10.81467,
"64.80",7.468,10.848,
"65.00",7.499,10.88133,
"65.20",7.527,10.915,
"65.40",7.561,10.94833,
"65.60",7.591,10.98167,
"65.80",7.618,11.015,
"66.00",7.65,11.048,
"66.20",7.679,11.08167,
"66.40",7.709,11.11467,
"66.60",7.736,11.14833,
"66.80",7.767,11.18167,
"67.00",7.794,11.21467,
"67.20",7.822,11.24833,
"67.40",7.85,11.28133,
"67.60",7.878,11.315,
"67.80",7.905,11.34833,
"68.00",7.934,11.38167,
"68.20",7.958,11.415,
"68.40",7.983,11.44833,
"68.60",8.009,11.48167,
"68.80",8.033,11.515,
"69.00",8.064,11.54833,
"69.20",8.092,11.58167,
"69.40",8.117,11.615,
"69.60",8.144,11.64833,
"69.80",8.171,11.68167,
"70.00",8.197,11.71467,
"70.20",8.225,11.74833,
"70.40",8.252,11.78167,
"70.60",8.276,11.81467,
"70.80",8.302,11.848,
"71.00",8.327,11.88133,
"71.20",8.355,11.915,
"71.40",8.38,11.948,
"71.60",8.405,11.98133,
"71.80",8.431,12.01467,
"72.00",8.456,12.048,
"72.20",8.479,12.08133,
"72.40",8.502,12.11467,
"72.60",8.524,12.148,
"72.80",8.548,12.18133,
"73.00",8.574,12.21467,
"73.20",8.595,12.248,
"73.40",8.618,12.28167,
"73.60",8.641,12.315,
"73.80",8.662,12.34833,
"74.00",8.69,12.38167,
"74.20",8.714,12.415,
"74.40",8.738,12.448,
"74.60",8.76,12.48167,
"74.80",8.781,12.515,
"75.00",8.808,12.548,
"75.20",8.831,12.58167,
"75.40",8.854,12.615,
"75.60",8.877,12.648,
"75.80",8.903,12.68133,
"76.00",8.927,12.71467,
"76.20",8.953,12.748,
"76.40",8.977,12.78167,
"76.60",9.003,12.815,
"76.80",9.029,12.84833,
"77.00",9.054,12.88167,
"77.20",9.08,12.915,
"77.40",9.104,12.94833,
"77.60",9.127,12.98167,
"77.80",9.151,13.015,
"78.00",9.179,13.048,
"78.20",9.204,13.08167,
"78.40",9.227,13.115,
"78.60",9.251,13.14833,
"78.80",9.274,13.18167,
"79.00",9.303,13.215,
"79.20",9.328,13.24833,
"79.40",9.353,13.28133,
"79.60",9.376,13.315,
"79.80",9.399,13.34833,
"80.00",9.425,13.38167,
"80.20",9.451,13.415,
"80.40",9.473,13.448,
"80.60",9.495,13.48167,
"80.80",9.519,13.515,
"81.00",9.545,13.548,
"81.20",9.569,13.58167,
"81.40",9.592,13.615,
"81.60",9.612,13.64833,
"81.80",9.637,13.68167,
"82.00",9.664,13.715,
"82.20",9.688,13.74833,
"82.40",9.708,13.78167,
"82.60",9.731,13.815,
"82.80",9.753,13.84833,
"83.00",9.776,13.88167,
"83.20",9.802,13.915,
"83.40",9.82,13.94833,
"83.60",9.844,13.98167,
"83.80",9.862,14.015,
"84.00",9.885,14.04833,
"84.20",9.911,14.08167,
"84.40",9.935,14.115,
"84.60",9.954,14.14833,
"84.80",9.978,14.18167,
"85.00",10.002,14.215,
"85.20",10.025,14.24833,
"85.40",10.047,14.28167,
"85.60",10.065,14.315,
"85.80",10.09,14.34833,
"86.00",10.113,14.38167,
"86.20",10.134,14.415,
"86.40",10.156,14.44833,
"86.60",10.18,14.48167,
"86.80",10.201,14.515,
"87.00",10.224,14.54833,
"87.20",10.248,14.58167,
"87.40",10.27,14.615,
"87.60",10.291,14.64833,
"87.80",10.317,14.68167,
"88.00",10.337,14.71467,
"88.20",10.362,14.748,
"88.40",10.384,14.78133,
"88.60",10.406,14.81467,
"88.80",10.43,14.84833,
"89.00",10.453,14.88167,
"89.20",10.477,14.915,
"89.40",10.498,14.94833,
"89.60",10.519,14.98133,
"89.80",10.537,15.015,
"90.00",10.561,15.048,
"90.20",10.584,15.08167,
"90.40",10.605,15.115,
"90.60",10.627,15.14833,
"90.80",10.648,15.18167,
"91.00",10.668,15.21467,
"91.20",10.692,15.24833,
"91.40",10.713,15.28133,
"91.60",10.732,15.31467,
"91.80",10.755,15.34833,
"92.00",10.779,15.38167,
"92.20",10.802,15.415,
"92.40",10.82,15.44833,
"92.60",10.841,15.48167,
"92.80",10.861,15.515,
"93.00",10.886,15.54833,
"93.20",10.91,15.58167,
"93.40",10.928,15.615,
"93.60",10.946,15.64833,
"93.80",10.968,15.68167,
"94.00",10.988,15.71467,
"94.20",11.009,15.748,
"94.40",11.028,15.78133,
"94.60",11.047,15.81467,
"94.80",11.066,15.84833,
"95.00",11.089,15.88133,
"95.20",11.11,15.915,
"95.40",11.127,15.94833,
"95.60",11.147,15.98167,
"95.80",11.164,16.015,
"96.00",11.187,16.04833,
"96.20",11.208,16.08167,
"96.40",11.225,16.11467,
"96.60",11.246,16.148,
"96.80",11.264,16.18133,
"97.00",11.285,16.21467,
"97.20",11.308,16.24833,
"97.40",11.325,16.28133,
"97.60",11.342,16.31467,
"97.80",11.366,16.34833,
"98.00",11.388,16.38167,
"98.20",11.409,16.41467,
"98.40",11.428,16.44833,
"98.60",11.447,16.48167,
"98.80",11.467,16.515,
"99.00",11.491,16.548,
"99.20",11.512,16.58133,
"99.40",11.532,16.61467,
"99.60",11.55,16.648,
"99.80",11.572,16.68133,
"100.00",11.595,16.71467,
"100.20",11.619,16.748,
"100.40",11.637,16.78133,
"100.60",11.653,16.81467,
"100.80",11.674,16.848,
"101.00",11.696,16.88133,
"101.20",11.715,16.91467,
"101.40",11.735,16.948,
"101.60",11.756,16.98133,
"101.80",11.776,17.01467,
"102.00",11.798,17.048,
"102.20",11.816,17.08167,
"102.40",11.836,17.115,
"102.60",11.855,17.148,
"102.80",11.873,17.18167,
"103.00",11.891,17.21467,
"103.20",11.91,17.24833,
"103.40",11.926,17.28133,
"103.60",11.943,17.31467,
"103.80",11.963,17.348,
"104.00",11.987,17.38133,
"104.20",12.005,17.41467,
"104.40",12.025,17.448,
"104.60",12.042,17.48133,
"104.80",12.06,17.51467,
"105.00",12.084,17.548,
"105.20",12.1,17.58133,
"105.40",12.117,17.615,
"105.60",12.136,17.64833,
"105.80",12.153,17.68167,
"106.00",12.171,17.71467,
"106.20",12.191,17.74833,
"106.40",12.211,17.78133,
"106.60",12.228,17.81467,
"106.80",12.251,17.848,
"107.00",12.272,17.88167,
"107.20",12.291,17.915,
"107.40",12.313,17.94833,
"107.60",12.332,17.98167,
"107.80",12.353,18.015,
"108.00",12.373,18.04833,
"108.20",12.396,18.08167,
"108.40",12.411,18.115,
"108.60",12.43,18.148,
"108.80",12.451,18.18133,
"109.00",12.475,18.21467,
"109.20",12.497,18.248,
"109.40",12.516,18.28167,
"109.60",12.534,18.315,
"109.80",12.556,18.34833,
"110.00",12.576,18.38133,
"110.20",12.594,18.415,
"110.40",12.612,18.44833,
"110.60",12.63,18.48167,
"110.80",12.647,18.51467,
"111.00",12.668,18.548,
"111.20",12.687,18.58133,
"111.40",12.702,18.615,
"111.60",12.719,18.64833,
"111.80",12.74,18.68167,
"112.00",12.759,18.715,
"112.20",12.777,18.74833,
"112.40",12.789,18.78133,
"112.60",12.811,18.81467,
"112.80",12.829,18.84833,
"113.00",12.85,18.88133,
"113.20",12.87,18.915,
"113.40",12.886,18.94833,
"113.60",12.904,18.98133,
"113.80",12.919,19.015,
"114.00",12.941,19.04833,
"114.20",12.961,19.08167,
"114.40",12.977,19.115,
"114.60",12.994,19.14833,
"114.80",13.009,19.18167,
"115.00",13.029,19.215,
"115.20",13.048,19.24833,
"115.40",13.066,19.28167,
"115.60",13.079,19.31467,
"115.80",13.098,19.34833,
"116.00",13.118,19.38167,
"116.20",13.134,19.415,
"116.40",13.15,19.44833,
"116.60",13.167,19.48167,
"116.80",13.186,19.515,
"117.00",13.205,19.548,
"117.20",13.222,19.58167,
"117.40",13.239,19.615,
"117.60",13.256,19.64833,
"117.80",13.275,19.68167,
"118.00",13.296,19.715,
"118.20",13.314,19.74833,
"118.40",13.333,19.78167,
"118.60",13.35,19.815,
"118.80",13.37,19.84833,
"119.00",13.39,19.88167,
"119.20",13.411,19.915,
"119.40",13.426,19.94833,
"119.60",13.442,19.98167,
"119.80",13.458,20.015,
"120.00",13.481,20.04833,
"120.20",13.499,20.08167,
"120.40",13.515,20.11467,
"120.60",13.532,20.14833,
"120.80",13.549,20.18167,
"121.00",13.566,20.215,
"121.20",13.584,20.24833,
"121.40",13.597,20.28167,
"121.60",13.613,20.315,
"121.80",13.632,20.34833,
"122.00",13.651,20.38133,
"122.20",13.663,20.41467,
"122.40",13.677,20.448,
"122.60",13.693,20.48133,
"122.80",13.711,20.515,
"123.00",13.73,20.548,
"123.20",13.743,20.58167,
"123.40",13.759,20.615,
"123.60",13.773,20.64833,
"123.80",13.787,20.68167,
"124.00",13.807,20.715,
"124.20",13.82,20.74833,
"124.40",13.836,20.78133,
"124.60",13.848,20.81467,
"124.80",13.861,20.84833,
"125.00",13.88,20.88133,
"125.20",13.896,20.91467,
"125.40",13.913,20.948,
"125.60",13.927,20.98133,
"125.80",13.947,21.01467,
"126.00",13.963,21.048,
"126.20",13.981,21.08133,
"126.40",13.997,21.11467,
"126.60",14.016,21.14833,
"126.80",14.035,21.18167,
"127.00",14.055,21.215,
"127.20",14.069,21.24833,
"127.40",14.09,21.28167,
"127.60",14.105,21.315,
"127.80",14.125,21.34833,
"128.00",14.145,21.38167,
"128.20",14.165,21.415,
"128.40",14.182,21.448,
"128.60",14.198,21.48133,
"128.80",14.214,21.51467,
"129.00",14.236,21.548,
"129.20",14.255,21.58167,
"129.40",14.272,21.615,
"129.60",14.285,21.64833,
"129.80",14.303,21.68167,
"130.00",14.32,21.71467,
"130.20",14.337,21.74833,
"130.40",14.353,21.78133,
"130.60",14.366,21.81467,
"130.80",14.381,21.848,
"131.00",14.397,21.88133,
"131.20",14.41,21.91467,
"131.40",14.426,21.948,
"131.60",14.439,21.98133,
"131.80",14.455,22.015,
"132.00",14.472,22.04833,
"132.20",14.488,22.08133,
"132.40",14.502,22.11467,
"132.60",14.513,22.148,
"132.80",14.532,22.18133,
"133.00",14.55,22.21467,
"133.20",14.566,22.248,
"133.40",14.582,22.28133,
"133.60",14.595,22.31467,
"133.80",14.612,22.348,
"134.00",14.626,22.38133,
"134.20",14.644,22.41467,
"134.40",14.658,22.448,
"134.60",14.675,22.48133,
"134.80",14.689,22.51467,
"135.00",14.704,22.548,
"135.20",14.721,22.58133,
"135.40",14.736,22.61467,
"135.60",14.748,22.648,
"135.80",14.758,22.68133,
"136.00",14.776,22.71467,
"136.20",14.794,22.748,
"136.40",14.808,22.78133,
"136.60",14.823,22.81467,
"136.80",14.841,22.848,
"137.00",14.857,22.88133,
"137.20",14.875,22.91467,
"137.40",14.889,22.948,
"137.60",14.902,22.98133,
"137.80",14.916,23.015,
"138.00",14.932,23.04833,
"138.20",14.949,23.08167,
"138.40",14.963,23.115,
"138.60",14.977,23.14833,
"138.80",14.991,23.18167,
"139.00",15.01,23.215,
"139.20",15.028,23.24833,
"139.40",15.042,23.28167,
"139.60",15.053,23.31467,
"139.80",15.07,23.348,
"140.00",15.088,23.38133,
"140.20",15.104,23.41467,
"140.40",15.118,23.448,
"140.60",15.13,23.48133,
"140.80",15.143,23.51467,
"141.00",15.158,23.548,
"141.20",15.176,23.58167,
"141.40",15.19,23.615,
"141.60",15.203,23.64833,
"141.80",15.218,23.68167,
"142.00",15.237,23.715,
"142.20",15.251,23.74833,
"142.40",15.264,23.78133,
"142.60",15.281,23.815,
"142.80",15.293,23.84833,
"143.00",15.313,23.88133,
"143.20",15.324,23.915,
"143.40",15.339,23.948,
"143.60",15.349,23.98133,
"143.80",15.365,24.01467,
"144.00",15.381,24.04833,
"144.20",15.403,24.08167,
"144.40",15.417,24.115,
"144.60",15.428,24.14833,
"144.80",15.442,24.18167,
"145.00",15.461,24.215,
"145.20",15.476,24.24833,
"145.40",15.489,24.28167,
"145.60",15.499,24.31467,
"145.80",15.51,24.348,
"146.00",15.524,24.38133,
"146.20",15.542,24.41467,
"146.40",15.555,24.448,
"146.60",15.567,24.48133,
"146.80",15.584,24.51467,
"147.00",15.6,24.548,
"147.20",15.612,24.58167,
"147.40",15.623,24.615,
"147.60",15.636,24.64833,
"147.80",15.65,24.68167,
"148.00",15.662,24.71467,
"148.20",15.677,24.748,
"148.40",15.688,24.78167,
"148.60",15.702,24.81467,
"148.80",15.714,24.848,
"149.00",15.728,24.88167,
"149.20",15.749,24.915,
"149.40",15.762,24.94833,
"149.60",15.775,24.98167,
"149.80",15.789,25.015,
"150.00",15.803,25.048,
"150.20",15.818,25.08167,
"150.40",15.833,25.11467,
"150.60",15.846,25.14833,
"150.80",15.853,25.18167,
"151.00",15.868,25.21467,
"151.20",15.884,25.24833,
"151.40",15.898,25.28167,
"151.60",15.91,25.315,
"151.80",15.922,25.34833,
"152.00",15.941,25.38167,
"152.20",15.955,25.415,
"152.40",15.963,25.44833,
"152.60",15.977,25.48167,
"152.80",15.99,25.515,
"153.00",16.009,25.54833,
"153.20",16.022,25.58167,
"153.40",16.035,25.615,
"153.60",16.045,25.64833,
"153.80",16.06,25.68167,
"154.00",16.078,25.715,
"154.20",16.097,25.74833,
"154.40",16.111,25.78167,
"154.60",16.125,25.815,
"154.80",16.138,25.84833,
"155.00",16.152,25.88167,
"155.20",16.168,25.915,
"155.40",16.183,25.94867,
"155.60",16.191,25.98167,
"155.80",16.202,26.015,
"156.00",16.214,26.04833,
"156.20",16.226,26.08167,
"156.40",16.237,26.115,
"156.60",16.248,26.14833,
"156.80",16.261,26.18167,
"157.00",16.276,26.215,
"157.20",16.296,26.24833,
"157.40",16.305,26.28133,
"157.60",16.318,26.31467,
"157.80",16.332,26.34833,
"158.00",16.344,26.38167,
"158.20",16.36,26.415,
"158.40",16.373,26.44833,
"158.60",16.383,26.48167,
"158.80",16.4,26.515,
"159.00",16.417,26.54833,
"159.20",16.433,26.58167,
"159.40",16.447,26.615,
"159.60",16.461,26.64833,
"159.80",16.474,26.68167,
"160.00",16.492,26.71467,
"160.20",16.507,26.74833,
"160.40",16.519,26.78167,
"160.60",16.535,26.815,
"160.80",16.549,26.84833,
"161.00",16.563,26.88167,
"161.20",16.579,26.915,
"161.40",16.591,26.948,
"161.60",16.602,26.98133,
"161.80",16.619,27.01467,
"162.00",16.633,27.04833,
"162.20",16.645,27.08167,
"162.40",16.656,27.11467,
"162.60",16.667,27.14833,
"162.80",16.68,27.18167,
"163.00",16.695,27.215,
"163.20",16.709,27.24833,
"163.40",16.715,27.28167,
"163.60",16.727,27.315,
"163.80",16.739,27.34833,
"164.00",16.754,27.38133,
"164.20",16.766,27.415,
"164.40",16.775,27.44833,
"164.60",16.783,27.48167,
"164.80",16.791,27.515,
"165.00",16.807,27.54833,
"165.20",16.82,27.58167,
"165.40",16.828,27.615,
"165.60",16.837,27.64833,
"165.80",16.848,27.68167,
"166.00",16.856,27.715,
"166.20",16.867,27.74833,
"166.40",16.88,27.78133,
"166.60",16.89,27.815,
"166.80",16.902,27.84833,
"167.00",16.914,27.88167,
"167.20",16.927,27.915,
"167.40",16.935,27.94833,
"167.60",16.945,27.98167,
"167.80",16.956,28.015,
"168.00",16.966,28.04833,
"168.20",16.978,28.08167,
"168.40",16.988,28.115,
"168.60",16.996,28.14833,
"168.80",17.004,28.18167,
"169.00",17.02,28.215,
"169.20",17.035,28.24833,
"169.40",17.045,28.28167,
"169.60",17.051,28.315,
"169.80",17.06,28.34833,
"170.00",17.071,28.38167,
"170.20",17.086,28.415,
"170.40",17.095,28.44833,
"170.60",17.104,28.48133,
"170.80",17.117,28.51467,
"171.00",17.131,28.548,
"171.20",17.142,28.58133,
"171.40",17.153,28.61467,
"171.60",17.167,28.648,
"171.80",17.18,28.68167,
"172.00",17.192,28.715,
"172.20",17.204,28.74833,
"172.40",17.212,28.78167,
"172.60",17.224,28.815,
"172.80",17.235,28.84833,
"173.00",17.251,28.88167,
"173.20",17.262,28.915,
"173.40",17.274,28.94833,
"173.60",17.282,28.98133,
"173.80",17.294,29.015,
"174.00",17.313,29.04833,
"174.20",17.326,29.08167,
"174.40",17.339,29.11467,
"174.60",17.349,29.148,
"174.80",17.363,29.18167,
"175.00",17.38,29.21467,
"175.20",17.393,29.24833,
"175.40",17.403,29.28167,
"175.60",17.415,29.315,
"175.80",17.43,29.34833,
"176.00",17.443,29.38167,
"176.20",17.455,29.415,
"176.40",17.466,29.44833,
"176.60",17.475,29.48167,
"176.80",17.488,29.515,
"177.00",17.501,29.54833,
"177.20",17.516,29.58167,
"177.40",17.524,29.615,
"177.60",17.53,29.64833,
"177.80",17.542,29.68133,
"178.00",17.556,29.71467,
"178.20",17.571,29.748,
"178.40",17.582,29.78133,
"178.60",17.591,29.81467,
"178.80",17.606,29.84833,
"179.00",17.62,29.88133,
"179.20",17.632,29.91467,
"179.40",17.645,29.948,
"179.60",17.651,29.98167,
"179.80",17.66,30.01467,
"180.00",17.67,30.048,
"180.20",17.682,30.08133,
"180.40",17.692,30.11467,
"180.60",17.701,30.148,
"180.80",17.705,30.18167,
"181.00",17.715,30.215,
"181.20",17.724,30.24833,
"181.40",17.739,30.28167,
"181.60",17.745,30.315,
"181.80",17.758,30.34833,
"182.00",17.772,30.38167,
"182.20",17.783,30.415,
"182.40",17.792,30.448,
"182.60",17.803,30.48133,
"182.80",17.814,30.51467,
"183.00",17.827,30.548,
"183.20",17.839,30.58167,
"183.40",17.849,30.615,
"183.60",17.86,30.64833,
"183.80",17.87,30.68167,
"184.00",17.886,30.715,
"184.20",17.897,30.74833,
"184.40",17.906,30.78133,
"184.60",17.912,30.81467,
"184.80",17.918,30.848,
"185.00",17.933,30.88167,
"185.20",17.946,30.915,
"185.40",17.955,30.94833,
"185.60",17.961,30.98133,
"185.80",17.97,31.015,
"186.00",17.983,31.048,
"186.20",17.994,31.08167,
"186.40",18.003,31.115,
"186.60",18.018,31.14833,
"186.80",18.027,31.18167,
"187.00",18.042,31.215,
"187.20",18.056,31.24833,
"187.40",18.065,31.28167,
"187.60",18.075,31.315,
"187.80",18.09,31.34833,
"188.00",18.104,31.38167,
"188.20",18.113,31.415,
"188.40",18.12,31.448,
"188.60",18.126,31.48133,
"188.80",18.134,31.51467,
"189.00",18.144,31.548,
"189.20",18.153,31.58133,
"189.40",18.161,31.61467,
"189.60",18.168,31.648,
"189.80",18.178,31.68167,
"190.00",18.191,31.715,
"190.20",18.203,31.74833,
"190.40",18.212,31.78133,
"190.60",18.218,31.81467,
"190.80",18.228,31.848,
"191.00",18.24,31.88133,
"191.20",18.252,31.91467,
"191.40",18.261,31.948,
"191.60",18.275,31.98133,
"191.80",18.287,32.01467,
"192.00",18.306,32.048,
"192.20",18.318,32.08167,
"192.40",18.329,32.11467,
"192.60",18.341,32.14833,
"192.80",18.357,32.18167,
"193.00",18.373,32.21467,
"193.20",18.384,32.24833,
"193.40",18.396,32.28167,
"193.60",18.402,32.31467,
"193.80",18.414,32.34834,
"194.00",18.429,32.38167,
"194.20",18.442,32.415,
"194.40",18.454,32.44833,
"194.60",18.464,32.48167,
"194.80",18.475,32.515,
"195.00",18.485,32.548,
"195.20",18.498,32.58167,
"195.40",18.509,32.615,
"195.60",18.517,32.648,
"195.80",18.526,32.68167,
"196.00",18.539,32.715,
"196.20",18.549,32.74833,
"196.40",18.559,32.78167,
"196.60",18.57,32.815,
"196.80",18.581,32.84834,
"197.00",18.596,32.88167,
"197.20",18.608,32.91467,
"197.40",18.613,32.94833,
"197.60",18.624,32.98167,
"197.80",18.635,33.015,
"198.00",18.647,33.048,
"198.20",18.655,33.08133,
"198.40",18.66,33.11467,
"198.60",18.665,33.148,
"198.80",18.674,33.18134,
"199.00",18.685,33.21467,
"199.20",18.696,33.24833,
"199.40",18.703,33.28133,
"199.60",18.71,33.31467,
"199.80",18.718,33.34834,
"200.00",18.729,33.38133,
"200.20",18.735,33.415,
"200.40",18.74,33.44833,
"200.60",18.745,33.48167,
"200.80",18.747,33.515,
"201.00",18.75,33.54833,
"201.20",18.749,33.58167,
"201.40",18.738,33.615,
"201.60",18.726,33.64833,
"201.80",18.711,33.68167,
"202.00",18.694,33.715,
"202.20",18.672,33.74833,
"202.40",18.634,33.78167,
"202.60",18.577,33.81467,
"202.80",18.536,33.848,
"203.00",18.496,33.88133,
"203.20",18.47,33.915,
"203.40",18.451,33.948,
"203.60",18.445,33.98133,
"203.80",18.452,34.01467,
"204.00",18.466,34.048,
"204.20",18.483,34.08133,
"204.40",18.497,34.11467,
"204.60",18.514,34.148,
"204.80",18.526,34.18134,
"205.00",18.541,34.21467,
"205.20",18.56,34.24833,
"205.40",18.581,34.28167,
"205.60",18.599,34.315,
"205.80",18.621,34.34834,
"206.00",18.645,34.38167,
"206.20",18.662,34.415,
"206.40",18.684,34.44833,
"206.60",18.707,34.48167,
"206.80",18.726,34.515,
"207.00",18.74,34.548,
"207.20",18.748,34.58133,
"207.40",18.759,34.61467,
"207.60",18.765,34.648,
"207.80",18.776,34.68134,
"208.00",18.79,34.71467,
"208.20",18.803,34.748,
"208.40",18.809,34.78133,
"208.60",18.816,34.81467,
"208.80",18.822,34.84834,
"209.00",18.828,34.88133,
"209.20",18.828,34.91467,
"209.40",18.817,34.948,
"209.60",18.798,34.98133,
"209.80",18.787,35.01467,
"210.00",18.783,35.048,
"210.20",18.788,35.08133,
"210.40",18.797,35.11467,
"210.60",18.802,35.148,
"210.80",18.813,35.18134,
"211.00",18.827,35.215,
"211.20",18.837,35.24833,
"211.40",18.845,35.28133,
"211.60",18.853,35.315,
"211.80",18.869,35.34834,
"212.00",18.888,35.38167,
"212.20",18.902,35.41467,
"212.40",18.917,35.448,
"212.60",18.93,35.48167,
"212.80",18.942,35.51467,
"213.00",18.955,35.548,
"213.20",18.961,35.58133,
"213.40",18.968,35.61467,
"213.60",18.976,35.648,
"213.80",18.985,35.68134,
"214.00",18.999,35.71467,
"214.20",19.012,35.748,
"214.40",19.022,35.78133,
"214.60",19.033,35.81467,
"214.80",19.043,35.84834,
"215.00",19.058,35.88133,
"215.20",19.072,35.915,
"215.40",19.087,35.94833,
"215.60",19.095,35.98167,
"215.80",19.107,36.015,
"216.00",19.123,36.04833,
"216.20",19.132,36.08167,
"216.40",19.141,36.115,
"216.60",19.149,36.148,
"216.80",19.156,36.18134,
"217.00",19.165,36.21467,
"217.20",19.177,36.248,
"217.40",19.182,36.28167,
"217.60",19.189,36.31467,
"217.80",19.196,36.34834,
"218.00",19.204,36.38167,
"218.20",19.21,36.415,
"218.40",19.212,36.44833,
"218.60",19.212,36.48167,
"218.80",19.218,36.515,
"219.00",19.226,36.54833,
"219.20",19.231,36.58167,
"219.40",19.236,36.615,
"219.60",19.242,36.648,
"219.80",19.246,36.68167,
"220.00",19.258,36.71467,
"220.20",19.267,36.74833,
"220.40",19.273,36.78167,
"220.60",19.279,36.815,
"220.80",19.285,36.84834,
"221.00",19.297,36.88167,
"221.20",19.307,36.915,
"221.40",19.314,36.94833,
"221.60",19.32,36.98133,
"221.80",19.331,37.015,
"222.00",19.344,37.048,
"222.20",19.353,37.08167,
"222.40",19.36,37.11467,
"222.60",19.371,37.148,
"222.80",19.38,37.18134,
"223.00",19.393,37.21467,
"223.20",19.402,37.24833,
"223.40",19.41,37.28167,
"223.60",19.418,37.31467,
"223.80",19.425,37.348,
"224.00",19.438,37.38133,
"224.20",19.448,37.415,
"224.40",19.461,37.44833,
"224.60",19.466,37.48167,
"224.80",19.475,37.515,
"225.00",19.488,37.548,
"225.20",19.494,37.58133,
"225.40",19.502,37.615,
"225.60",19.508,37.64833,
"225.80",19.513,37.68167,
"226.00",19.521,37.71467,
"226.20",19.53,37.74833,
"226.40",19.53,37.78167,
"226.60",19.531,37.815,
"226.80",19.54,37.848,
"227.00",19.546,37.88167,
"227.20",19.551,37.915,
"227.40",19.559,37.94833,
"227.60",19.559,37.98167,
"227.80",19.566,38.015,
"228.00",19.573,38.048,
"228.20",19.579,38.08167,
"228.40",19.583,38.115,
"228.60",19.59,38.14833,
"228.80",19.599,38.18167,
"229.00",19.607,38.21467,
"229.20",19.618,38.24833,
"229.40",19.625,38.28167,
"229.60",19.631,38.315,
"229.80",19.635,38.34834,
"230.00",19.641,38.38133,
"230.20",19.65,38.415,
"230.40",19.646,38.44833,
"230.60",19.631,38.48167,
"230.80",19.615,38.515,
"231.00",19.602,38.54833,
"231.20",19.591,38.58167,
"231.40",19.581,38.615,
"231.60",19.573,38.64833,
"231.80",19.572,38.68134,
"232.00",19.573,38.71467,
"232.20",19.574,38.748,
"232.40",19.573,38.78133,
"232.60",19.576,38.81467,
"232.80",19.583,38.848,
"233.00",19.591,38.88133,
"233.20",19.598,38.915,
"233.40",19.605,38.94833,
"233.60",19.611,38.98133,
"233.80",19.621,39.01467,
"234.00",19.634,39.048,
"234.20",19.647,39.08167,
"234.40",19.658,39.11467,
"234.60",19.668,39.14833,
"234.80",19.678,39.18167,
"235.00",19.693,39.215,
"235.20",19.703,39.24833,
"235.40",19.713,39.28167,
"235.60",19.724,39.315,
"235.80",19.735,39.34834,
"236.00",19.749,39.38133,
"236.20",19.766,39.415,
"236.40",19.782,39.448,
"236.60",19.794,39.48167,
"236.80",19.81,39.515,
"237.00",19.825,39.548,
"237.20",19.838,39.58167,
"237.40",19.85,39.615,
"237.60",19.861,39.648,
"237.80",19.875,39.68167,
"238.00",19.89,39.715,
"238.20",19.9,39.74833,
"238.40",19.908,39.78133,
"238.60",19.916,39.815,
"238.80",19.925,39.84834,
"239.00",19.939,39.88167,
"239.20",19.95,39.915,
"239.40",19.957,39.94833,
"239.60",19.962,39.98133,
"239.80",19.966,40.015,
"240.00",19.976,40.048,
"240.20",19.984,40.08167,
"240.40",19.994,40.11467,
"240.60",19.998,40.148,
"240.80",20.004,40.18134,
"241.00",20.015,40.21467,
"241.20",20.027,40.24833,
"241.40",20.035,40.28133,
"241.60",20.042,40.315,
"241.80",20.051,40.34834,
"242.00",20.061,40.38133,
"242.20",20.066,40.41467,
"242.40",20.07,40.448,
"242.60",20.076,40.48133,
"242.80",20.083,40.51467,
"243.00",20.093,40.548,
"243.20",20.097,40.58167,
"243.40",20.102,40.61467,
"243.60",20.103,40.648,
"243.80",20.109,40.68134,
"244.00",20.119,40.71467,
"244.20",20.124,40.748,
"244.40",20.126,40.78167,
"244.60",20.129,40.815,
"244.80",20.133,40.84834,
"245.00",20.139,40.88167,
"245.20",20.148,40.915,
"245.40",20.152,40.948,
"245.60",20.155,40.98133,
"245.80",20.162,41.015,
"246.00",20.168,41.04833,
"246.20",20.171,41.08133,
"246.40",20.179,41.11467,
"246.60",20.183,41.148,
"246.80",20.186,41.18134,
"247.00",20.193,41.21467,
"247.20",20.2,41.24833,
"247.40",20.201,41.28167,
"247.60",20.203,41.31467,
"247.80",20.205,41.348,
"248.00",20.21,41.38133,
"248.20",20.214,41.415,
"248.40",20.217,41.44833,
"248.60",20.22,41.48167,
"248.80",20.224,41.515,
"249.00",20.232,41.54833,
"249.20",20.239,41.58167,
"249.40",20.245,41.615,
"249.60",20.25,41.64833,
"249.80",20.256,41.68134,
"250.00",20.264,41.71467,
"250.20",20.271,41.74833,
"250.40",20.281,41.78167,
"250.60",20.288,41.81467,
"250.80",20.297,41.84834,
"251.00",20.309,41.88133,
"251.20",20.318,41.91467,
"251.40",20.323,41.94833,
"251.60",20.332,41.98133,
"251.80",20.34,42.01467,
"252.00",20.35,42.048,
"252.20",20.357,42.08167,
"252.40",20.363,42.115,
"252.60",20.362,42.14833,
"252.70",20.361,42.165,